{
  "version": 8,
  "blockIdVersion": 11,
  "anchorX": 1,
  "anchorY": 5,
  "anchorZ": 0,
  "blocks": [
    {
      "x": -24,
      "y": 2,
      "z": -16,
      "name": "Rock_Slate"
    },
    {
      "x": -24,
      "y": 3,
      "z": -16,
      "name": "Rock_Slate"
    },
    {
      "x": -24,
      "y": 4,
      "z": -16,
      "name": "Rock_Slate"
    },
    {
      "x": -24,
      "y": 2,
      "z": -15,
      "name": "Rock_Slate"
    },
    {
      "x": -24,
      "y": 3,
      "z": -15,
      "name": "Rock_Slate"
    },
    {
      "x": -24,
      "y": 5,
      "z": -15,
      "name": "Rock_Slate"
    },
    {
      "x": -24,
      "y": 2,
      "z": -14,
      "name": "Rock_Slate"
    },
    {
      "x": -24,
      "y": 3,
      "z": -14,
      "name": "Rock_Slate"
    },
    {
      "x": -24,
      "y": 4,
      "z": -14,
      "name": "Rock_Slate"
    },
    {
      "x": -24,
      "y": 5,
      "z": -14,
      "name": "Rock_Slate"
    },
    {
      "x": -24,
      "y": 2,
      "z": -13,
      "name": "Rock_Slate"
    },
    {
      "x": -24,
      "y": 3,
      "z": -13,
      "name": "Rock_Slate"
    },
    {
      "x": -24,
      "y": 5,
      "z": -13,
      "name": "Rock_Slate"
    },
    {
      "x": -24,
      "y": 1,
      "z": -12,
      "name": "Rock_Slate"
    },
    {
      "x": -24,
      "y": 2,
      "z": -12,
      "name": "Rock_Slate"
    },
    {
      "x": -24,
      "y": 4,
      "z": -12,
      "name": "Rock_Slate"
    },
    {
      "x": -24,
      "y": 5,
      "z": -12,
      "name": "Rock_Slate"
    },
    {
      "x": -24,
      "y": 3,
      "z": -11,
      "name": "Rock_Slate"
    },
    {
      "x": -24,
      "y": 4,
      "z": -11,
      "name": "Rock_Slate"
    },
    {
      "x": -24,
      "y": 5,
      "z": -11,
      "name": "Rock_Slate"
    },
    {
      "x": -24,
      "y": 6,
      "z": -11,
      "name": "Rock_Slate"
    },
    {
      "x": -24,
      "y": 3,
      "z": -10,
      "name": "Rock_Slate"
    },
    {
      "x": -24,
      "y": 4,
      "z": -10,
      "name": "Rock_Slate"
    },
    {
      "x": -24,
      "y": 5,
      "z": -10,
      "name": "Rock_Slate"
    },
    {
      "x": -24,
      "y": 3,
      "z": -9,
      "name": "Rock_Slate"
    },
    {
      "x": -24,
      "y": 4,
      "z": -9,
      "name": "Rock_Slate"
    },
    {
      "x": -24,
      "y": 5,
      "z": -9,
      "name": "Rock_Slate"
    },
    {
      "x": -24,
      "y": 3,
      "z": -8,
      "name": "Rock_Slate"
    },
    {
      "x": -24,
      "y": 4,
      "z": -8,
      "name": "Rock_Slate"
    },
    {
      "x": -24,
      "y": 5,
      "z": -8,
      "name": "Rock_Slate"
    },
    {
      "x": -24,
      "y": 2,
      "z": -7,
      "name": "Rock_Slate"
    },
    {
      "x": -24,
      "y": 3,
      "z": -7,
      "name": "Rock_Slate"
    },
    {
      "x": -24,
      "y": 4,
      "z": -7,
      "name": "Rock_Slate"
    },
    {
      "x": -24,
      "y": 6,
      "z": -7,
      "name": "Rock_Slate"
    },
    {
      "x": -24,
      "y": 2,
      "z": -6,
      "name": "Rock_Slate"
    },
    {
      "x": -24,
      "y": 3,
      "z": -6,
      "name": "Rock_Slate"
    },
    {
      "x": -24,
      "y": 4,
      "z": -6,
      "name": "Rock_Slate"
    },
    {
      "x": -24,
      "y": 5,
      "z": -6,
      "name": "Rock_Slate"
    },
    {
      "x": -24,
      "y": 4,
      "z": -5,
      "name": "Rock_Slate"
    },
    {
      "x": -24,
      "y": 5,
      "z": -4,
      "name": "Rock_Slate"
    },
    {
      "x": -24,
      "y": 6,
      "z": -4,
      "name": "Rock_Slate"
    },
    {
      "x": -24,
      "y": 4,
      "z": -3,
      "name": "Rock_Slate"
    },
    {
      "x": -24,
      "y": 5,
      "z": -3,
      "name": "Rock_Slate"
    },
    {
      "x": -24,
      "y": 5,
      "z": -1,
      "name": "Rock_Slate"
    },
    {
      "x": -24,
      "y": 2,
      "z": 0,
      "name": "Rock_Slate"
    },
    {
      "x": -24,
      "y": 4,
      "z": 0,
      "name": "Rock_Slate"
    },
    {
      "x": -24,
      "y": 5,
      "z": 0,
      "name": "Rock_Slate"
    },
    {
      "x": -24,
      "y": 2,
      "z": 1,
      "name": "Rock_Slate"
    },
    {
      "x": -24,
      "y": 3,
      "z": 1,
      "name": "Rock_Slate"
    },
    {
      "x": -24,
      "y": 4,
      "z": 1,
      "name": "Rock_Slate"
    },
    {
      "x": -24,
      "y": 4,
      "z": 2,
      "name": "Rock_Slate"
    },
    {
      "x": -24,
      "y": 5,
      "z": 2,
      "name": "Rock_Slate"
    },
    {
      "x": -24,
      "y": 2,
      "z": 3,
      "name": "Rock_Slate"
    },
    {
      "x": -24,
      "y": 3,
      "z": 3,
      "name": "Rock_Slate"
    },
    {
      "x": -24,
      "y": 4,
      "z": 3,
      "name": "Rock_Slate"
    },
    {
      "x": -24,
      "y": 4,
      "z": 4,
      "name": "Rock_Slate"
    },
    {
      "x": -24,
      "y": 5,
      "z": 4,
      "name": "Rock_Slate"
    },
    {
      "x": -24,
      "y": 2,
      "z": 5,
      "name": "Rock_Slate"
    },
    {
      "x": -24,
      "y": 3,
      "z": 5,
      "name": "Rock_Slate"
    },
    {
      "x": -24,
      "y": 4,
      "z": 5,
      "name": "Rock_Slate"
    },
    {
      "x": -24,
      "y": 5,
      "z": 5,
      "name": "Rock_Slate"
    },
    {
      "x": -24,
      "y": 5,
      "z": 6,
      "name": "Rock_Slate"
    },
    {
      "x": -24,
      "y": 2,
      "z": 7,
      "name": "Rock_Slate"
    },
    {
      "x": -24,
      "y": 5,
      "z": 7,
      "name": "Rock_Slate"
    },
    {
      "x": -24,
      "y": 2,
      "z": 8,
      "name": "Rock_Slate"
    },
    {
      "x": -24,
      "y": 3,
      "z": 8,
      "name": "Rock_Slate"
    },
    {
      "x": -24,
      "y": 4,
      "z": 8,
      "name": "Rock_Slate"
    },
    {
      "x": -24,
      "y": 5,
      "z": 8,
      "name": "Rock_Slate"
    },
    {
      "x": -24,
      "y": 6,
      "z": 8,
      "name": "Rock_Slate"
    },
    {
      "x": -24,
      "y": 2,
      "z": 9,
      "name": "Rock_Slate"
    },
    {
      "x": -24,
      "y": 3,
      "z": 9,
      "name": "Rock_Slate"
    },
    {
      "x": -24,
      "y": 5,
      "z": 9,
      "name": "Rock_Slate"
    },
    {
      "x": -24,
      "y": 3,
      "z": 10,
      "name": "Rock_Slate"
    },
    {
      "x": -24,
      "y": 2,
      "z": 12,
      "name": "Rock_Slate"
    },
    {
      "x": -24,
      "y": 3,
      "z": 12,
      "name": "Rock_Slate"
    },
    {
      "x": -24,
      "y": 3,
      "z": 13,
      "name": "Rock_Slate"
    },
    {
      "x": -24,
      "y": 4,
      "z": 13,
      "name": "Rock_Slate"
    },
    {
      "x": -24,
      "y": 2,
      "z": 14,
      "name": "Rock_Slate"
    },
    {
      "x": -24,
      "y": 3,
      "z": 14,
      "name": "Rock_Slate"
    },
    {
      "x": -24,
      "y": 4,
      "z": 14,
      "name": "Rock_Slate"
    },
    {
      "x": -24,
      "y": 5,
      "z": 14,
      "name": "Rock_Slate"
    },
    {
      "x": -24,
      "y": 2,
      "z": 15,
      "name": "Rock_Slate"
    },
    {
      "x": -24,
      "y": 3,
      "z": 15,
      "name": "Rock_Slate"
    },
    {
      "x": -24,
      "y": 4,
      "z": 15,
      "name": "Rock_Slate"
    },
    {
      "x": -24,
      "y": 3,
      "z": 16,
      "name": "Rock_Slate"
    },
    {
      "x": -24,
      "y": 4,
      "z": 16,
      "name": "Rock_Slate"
    },
    {
      "x": -24,
      "y": 3,
      "z": 17,
      "name": "Rock_Slate"
    },
    {
      "x": -24,
      "y": 4,
      "z": 17,
      "name": "Rock_Slate"
    },
    {
      "x": -24,
      "y": 3,
      "z": 18,
      "name": "Rock_Slate"
    },
    {
      "x": -24,
      "y": 4,
      "z": 18,
      "name": "Rock_Slate"
    },
    {
      "x": -23,
      "y": 2,
      "z": -16,
      "name": "Rock_Slate"
    },
    {
      "x": -23,
      "y": 3,
      "z": -16,
      "name": "Rock_Slate"
    },
    {
      "x": -23,
      "y": 4,
      "z": -16,
      "name": "Rock_Slate"
    },
    {
      "x": -23,
      "y": 5,
      "z": -16,
      "name": "Rock_Slate"
    },
    {
      "x": -23,
      "y": 3,
      "z": -15,
      "name": "Rock_Slate"
    },
    {
      "x": -23,
      "y": 4,
      "z": -15,
      "name": "Rock_Slate"
    },
    {
      "x": -23,
      "y": 5,
      "z": -15,
      "name": "Rock_Slate"
    },
    {
      "x": -23,
      "y": 6,
      "z": -15,
      "name": "Rock_Slate"
    },
    {
      "x": -23,
      "y": 3,
      "z": -14,
      "name": "Rock_Slate"
    },
    {
      "x": -23,
      "y": 4,
      "z": -14,
      "name": "Rock_Slate"
    },
    {
      "x": -23,
      "y": 5,
      "z": -14,
      "name": "Rock_Slate"
    },
    {
      "x": -23,
      "y": 3,
      "z": -13,
      "name": "Rock_Slate"
    },
    {
      "x": -23,
      "y": 4,
      "z": -13,
      "name": "Rock_Slate"
    },
    {
      "x": -23,
      "y": 5,
      "z": -13,
      "name": "Rock_Slate"
    },
    {
      "x": -23,
      "y": 3,
      "z": -12,
      "name": "Rock_Slate"
    },
    {
      "x": -23,
      "y": 4,
      "z": -12,
      "name": "Rock_Slate"
    },
    {
      "x": -23,
      "y": 5,
      "z": -12,
      "name": "Rock_Slate"
    },
    {
      "x": -23,
      "y": 6,
      "z": -12,
      "name": "Rock_Slate"
    },
    {
      "x": -23,
      "y": 3,
      "z": -11,
      "name": "Rock_Slate"
    },
    {
      "x": -23,
      "y": 4,
      "z": -11,
      "name": "Rock_Slate"
    },
    {
      "x": -23,
      "y": 5,
      "z": -11,
      "name": "Rock_Slate"
    },
    {
      "x": -23,
      "y": 3,
      "z": -10,
      "name": "Rock_Slate"
    },
    {
      "x": -23,
      "y": 4,
      "z": -10,
      "name": "Rock_Slate"
    },
    {
      "x": -23,
      "y": 5,
      "z": -10,
      "name": "Rock_Slate"
    },
    {
      "x": -23,
      "y": 2,
      "z": -9,
      "name": "Rock_Slate"
    },
    {
      "x": -23,
      "y": 3,
      "z": -9,
      "name": "Rock_Slate"
    },
    {
      "x": -23,
      "y": 4,
      "z": -9,
      "name": "Rock_Slate"
    },
    {
      "x": -23,
      "y": 5,
      "z": -9,
      "name": "Rock_Slate"
    },
    {
      "x": -23,
      "y": 6,
      "z": -9,
      "name": "Rock_Slate"
    },
    {
      "x": -23,
      "y": 3,
      "z": -8,
      "name": "Rock_Slate"
    },
    {
      "x": -23,
      "y": 4,
      "z": -8,
      "name": "Rock_Slate"
    },
    {
      "x": -23,
      "y": 5,
      "z": -8,
      "name": "Rock_Slate"
    },
    {
      "x": -23,
      "y": 6,
      "z": -8,
      "name": "Rock_Slate"
    },
    {
      "x": -23,
      "y": 2,
      "z": -7,
      "name": "Rock_Slate"
    },
    {
      "x": -23,
      "y": 3,
      "z": -7,
      "name": "Rock_Slate"
    },
    {
      "x": -23,
      "y": 4,
      "z": -7,
      "name": "Rock_Slate"
    },
    {
      "x": -23,
      "y": 5,
      "z": -7,
      "name": "Rock_Slate"
    },
    {
      "x": -23,
      "y": 6,
      "z": -7,
      "name": "Rock_Slate"
    },
    {
      "x": -23,
      "y": 2,
      "z": -6,
      "name": "Rock_Slate"
    },
    {
      "x": -23,
      "y": 3,
      "z": -6,
      "name": "Rock_Slate"
    },
    {
      "x": -23,
      "y": 4,
      "z": -6,
      "name": "Rock_Slate"
    },
    {
      "x": -23,
      "y": 5,
      "z": -6,
      "name": "Rock_Slate"
    },
    {
      "x": -23,
      "y": 6,
      "z": -6,
      "name": "Rock_Slate"
    },
    {
      "x": -23,
      "y": 3,
      "z": -5,
      "name": "Rock_Slate"
    },
    {
      "x": -23,
      "y": 4,
      "z": -5,
      "name": "Rock_Slate"
    },
    {
      "x": -23,
      "y": 5,
      "z": -5,
      "name": "Rock_Slate"
    },
    {
      "x": -23,
      "y": 6,
      "z": -5,
      "name": "Rock_Slate"
    },
    {
      "x": -23,
      "y": 2,
      "z": -4,
      "name": "Rock_Slate"
    },
    {
      "x": -23,
      "y": 3,
      "z": -4,
      "name": "Rock_Slate"
    },
    {
      "x": -23,
      "y": 5,
      "z": -4,
      "name": "Rock_Slate"
    },
    {
      "x": -23,
      "y": 6,
      "z": -4,
      "name": "Rock_Slate"
    },
    {
      "x": -23,
      "y": 2,
      "z": -3,
      "name": "Rock_Slate"
    },
    {
      "x": -23,
      "y": 3,
      "z": -3,
      "name": "Rock_Slate"
    },
    {
      "x": -23,
      "y": 4,
      "z": -3,
      "name": "Rock_Slate"
    },
    {
      "x": -23,
      "y": 5,
      "z": -3,
      "name": "Rock_Slate"
    },
    {
      "x": -23,
      "y": 6,
      "z": -3,
      "name": "Rock_Slate"
    },
    {
      "x": -23,
      "y": 2,
      "z": -2,
      "name": "Rock_Slate"
    },
    {
      "x": -23,
      "y": 3,
      "z": -2,
      "name": "Rock_Slate"
    },
    {
      "x": -23,
      "y": 4,
      "z": -2,
      "name": "Rock_Slate"
    },
    {
      "x": -23,
      "y": 5,
      "z": -2,
      "name": "Rock_Slate"
    },
    {
      "x": -23,
      "y": 6,
      "z": -2,
      "name": "Rock_Slate"
    },
    {
      "x": -23,
      "y": 2,
      "z": -1,
      "name": "Rock_Slate"
    },
    {
      "x": -23,
      "y": 3,
      "z": -1,
      "name": "Rock_Slate"
    },
    {
      "x": -23,
      "y": 4,
      "z": -1,
      "name": "Rock_Slate"
    },
    {
      "x": -23,
      "y": 5,
      "z": -1,
      "name": "Rock_Slate"
    },
    {
      "x": -23,
      "y": 6,
      "z": -1,
      "name": "Rock_Slate"
    },
    {
      "x": -23,
      "y": 2,
      "z": 0,
      "name": "Rock_Slate"
    },
    {
      "x": -23,
      "y": 3,
      "z": 0,
      "name": "Rock_Slate"
    },
    {
      "x": -23,
      "y": 4,
      "z": 0,
      "name": "Rock_Slate"
    },
    {
      "x": -23,
      "y": 5,
      "z": 0,
      "name": "Rock_Slate"
    },
    {
      "x": -23,
      "y": 6,
      "z": 0,
      "name": "Rock_Slate"
    },
    {
      "x": -23,
      "y": 2,
      "z": 1,
      "name": "Rock_Slate"
    },
    {
      "x": -23,
      "y": 3,
      "z": 1,
      "name": "Rock_Slate"
    },
    {
      "x": -23,
      "y": 4,
      "z": 1,
      "name": "Rock_Slate"
    },
    {
      "x": -23,
      "y": 5,
      "z": 1,
      "name": "Rock_Slate"
    },
    {
      "x": -23,
      "y": 2,
      "z": 2,
      "name": "Rock_Slate"
    },
    {
      "x": -23,
      "y": 3,
      "z": 2,
      "name": "Rock_Slate"
    },
    {
      "x": -23,
      "y": 4,
      "z": 2,
      "name": "Rock_Slate"
    },
    {
      "x": -23,
      "y": 5,
      "z": 2,
      "name": "Rock_Slate"
    },
    {
      "x": -23,
      "y": 2,
      "z": 3,
      "name": "Rock_Slate"
    },
    {
      "x": -23,
      "y": 3,
      "z": 3,
      "name": "Rock_Slate"
    },
    {
      "x": -23,
      "y": 4,
      "z": 3,
      "name": "Rock_Slate"
    },
    {
      "x": -23,
      "y": 5,
      "z": 3,
      "name": "Rock_Slate"
    },
    {
      "x": -23,
      "y": 6,
      "z": 3,
      "name": "Rock_Slate"
    },
    {
      "x": -23,
      "y": 3,
      "z": 4,
      "name": "Rock_Slate"
    },
    {
      "x": -23,
      "y": 4,
      "z": 4,
      "name": "Rock_Slate"
    },
    {
      "x": -23,
      "y": 5,
      "z": 4,
      "name": "Rock_Slate"
    },
    {
      "x": -23,
      "y": 3,
      "z": 5,
      "name": "Rock_Slate"
    },
    {
      "x": -23,
      "y": 4,
      "z": 5,
      "name": "Rock_Slate"
    },
    {
      "x": -23,
      "y": 5,
      "z": 5,
      "name": "Rock_Slate"
    },
    {
      "x": -23,
      "y": 6,
      "z": 5,
      "name": "Rock_Slate"
    },
    {
      "x": -23,
      "y": 2,
      "z": 6,
      "name": "Rock_Slate"
    },
    {
      "x": -23,
      "y": 3,
      "z": 6,
      "name": "Rock_Slate"
    },
    {
      "x": -23,
      "y": 4,
      "z": 6,
      "name": "Rock_Slate"
    },
    {
      "x": -23,
      "y": 5,
      "z": 6,
      "name": "Rock_Slate"
    },
    {
      "x": -23,
      "y": 6,
      "z": 6,
      "name": "Rock_Slate"
    },
    {
      "x": -23,
      "y": 2,
      "z": 7,
      "name": "Rock_Slate"
    },
    {
      "x": -23,
      "y": 3,
      "z": 7,
      "name": "Rock_Slate"
    },
    {
      "x": -23,
      "y": 4,
      "z": 7,
      "name": "Rock_Slate"
    },
    {
      "x": -23,
      "y": 5,
      "z": 7,
      "name": "Rock_Slate"
    },
    {
      "x": -23,
      "y": 6,
      "z": 7,
      "name": "Rock_Slate"
    },
    {
      "x": -23,
      "y": 2,
      "z": 8,
      "name": "Rock_Slate"
    },
    {
      "x": -23,
      "y": 3,
      "z": 8,
      "name": "Rock_Slate"
    },
    {
      "x": -23,
      "y": 4,
      "z": 8,
      "name": "Rock_Slate"
    },
    {
      "x": -23,
      "y": 5,
      "z": 8,
      "name": "Rock_Slate"
    },
    {
      "x": -23,
      "y": 2,
      "z": 9,
      "name": "Rock_Slate"
    },
    {
      "x": -23,
      "y": 3,
      "z": 9,
      "name": "Rock_Slate"
    },
    {
      "x": -23,
      "y": 4,
      "z": 9,
      "name": "Rock_Slate"
    },
    {
      "x": -23,
      "y": 5,
      "z": 9,
      "name": "Rock_Slate"
    },
    {
      "x": -23,
      "y": 2,
      "z": 10,
      "name": "Rock_Slate"
    },
    {
      "x": -23,
      "y": 3,
      "z": 10,
      "name": "Rock_Slate"
    },
    {
      "x": -23,
      "y": 4,
      "z": 10,
      "name": "Rock_Slate"
    },
    {
      "x": -23,
      "y": 5,
      "z": 10,
      "name": "Rock_Slate"
    },
    {
      "x": -23,
      "y": 3,
      "z": 11,
      "name": "Rock_Slate"
    },
    {
      "x": -23,
      "y": 4,
      "z": 11,
      "name": "Rock_Slate"
    },
    {
      "x": -23,
      "y": 5,
      "z": 11,
      "name": "Rock_Slate"
    },
    {
      "x": -23,
      "y": 2,
      "z": 12,
      "name": "Rock_Slate"
    },
    {
      "x": -23,
      "y": 3,
      "z": 12,
      "name": "Rock_Slate"
    },
    {
      "x": -23,
      "y": 4,
      "z": 12,
      "name": "Rock_Slate"
    },
    {
      "x": -23,
      "y": 5,
      "z": 12,
      "name": "Rock_Slate"
    },
    {
      "x": -23,
      "y": 6,
      "z": 12,
      "name": "Rock_Slate"
    },
    {
      "x": -23,
      "y": 2,
      "z": 13,
      "name": "Rock_Slate"
    },
    {
      "x": -23,
      "y": 3,
      "z": 13,
      "name": "Rock_Slate"
    },
    {
      "x": -23,
      "y": 4,
      "z": 13,
      "name": "Rock_Slate"
    },
    {
      "x": -23,
      "y": 5,
      "z": 13,
      "name": "Rock_Slate"
    },
    {
      "x": -23,
      "y": 6,
      "z": 13,
      "name": "Rock_Slate"
    },
    {
      "x": -23,
      "y": 2,
      "z": 14,
      "name": "Rock_Slate"
    },
    {
      "x": -23,
      "y": 3,
      "z": 14,
      "name": "Rock_Slate"
    },
    {
      "x": -23,
      "y": 4,
      "z": 14,
      "name": "Rock_Slate"
    },
    {
      "x": -23,
      "y": 5,
      "z": 14,
      "name": "Rock_Slate"
    },
    {
      "x": -23,
      "y": 6,
      "z": 14,
      "name": "Rock_Slate"
    },
    {
      "x": -23,
      "y": 3,
      "z": 15,
      "name": "Rock_Slate"
    },
    {
      "x": -23,
      "y": 4,
      "z": 15,
      "name": "Rock_Slate"
    },
    {
      "x": -23,
      "y": 5,
      "z": 15,
      "name": "Rock_Slate"
    },
    {
      "x": -23,
      "y": 6,
      "z": 15,
      "name": "Rock_Slate"
    },
    {
      "x": -23,
      "y": 2,
      "z": 16,
      "name": "Rock_Slate"
    },
    {
      "x": -23,
      "y": 3,
      "z": 16,
      "name": "Rock_Slate"
    },
    {
      "x": -23,
      "y": 4,
      "z": 16,
      "name": "Rock_Slate"
    },
    {
      "x": -23,
      "y": 5,
      "z": 16,
      "name": "Rock_Slate"
    },
    {
      "x": -23,
      "y": 3,
      "z": 17,
      "name": "Rock_Slate"
    },
    {
      "x": -23,
      "y": 4,
      "z": 17,
      "name": "Rock_Slate"
    },
    {
      "x": -23,
      "y": 5,
      "z": 17,
      "name": "Rock_Slate"
    },
    {
      "x": -22,
      "y": 2,
      "z": -21,
      "name": "Rock_Slate"
    },
    {
      "x": -22,
      "y": 4,
      "z": -19,
      "name": "Rock_Slate"
    },
    {
      "x": -22,
      "y": 2,
      "z": -18,
      "name": "Rock_Slate"
    },
    {
      "x": -22,
      "y": 3,
      "z": -18,
      "name": "Rock_Slate"
    },
    {
      "x": -22,
      "y": 2,
      "z": -17,
      "name": "Rock_Slate"
    },
    {
      "x": -22,
      "y": 3,
      "z": -17,
      "name": "Rock_Slate"
    },
    {
      "x": -22,
      "y": 4,
      "z": -17,
      "name": "Rock_Slate"
    },
    {
      "x": -22,
      "y": 5,
      "z": -17,
      "name": "Rock_Slate"
    },
    {
      "x": -22,
      "y": 2,
      "z": -16,
      "name": "Rock_Slate"
    },
    {
      "x": -22,
      "y": 3,
      "z": -16,
      "name": "Rock_Slate"
    },
    {
      "x": -22,
      "y": 4,
      "z": -16,
      "name": "Rock_Slate"
    },
    {
      "x": -22,
      "y": 5,
      "z": -16,
      "name": "Rock_Slate"
    },
    {
      "x": -22,
      "y": 1,
      "z": -15,
      "name": "Rock_Slate"
    },
    {
      "x": -22,
      "y": 2,
      "z": -15,
      "name": "Rock_Slate"
    },
    {
      "x": -22,
      "y": 3,
      "z": -15,
      "name": "Rock_Slate"
    },
    {
      "x": -22,
      "y": 4,
      "z": -15,
      "name": "Rock_Slate"
    },
    {
      "x": -22,
      "y": 5,
      "z": -15,
      "name": "Rock_Slate"
    },
    {
      "x": -22,
      "y": 2,
      "z": -14,
      "name": "Rock_Slate"
    },
    {
      "x": -22,
      "y": 3,
      "z": -14,
      "name": "Rock_Slate"
    },
    {
      "x": -22,
      "y": 4,
      "z": -14,
      "name": "Rock_Slate"
    },
    {
      "x": -22,
      "y": 5,
      "z": -14,
      "name": "Rock_Slate"
    },
    {
      "x": -22,
      "y": 6,
      "z": -14,
      "name": "Rock_Slate"
    },
    {
      "x": -22,
      "y": 2,
      "z": -13,
      "name": "Rock_Slate"
    },
    {
      "x": -22,
      "y": 3,
      "z": -13,
      "name": "Rock_Slate"
    },
    {
      "x": -22,
      "y": 4,
      "z": -13,
      "name": "Rock_Slate"
    },
    {
      "x": -22,
      "y": 5,
      "z": -13,
      "name": "Rock_Slate"
    },
    {
      "x": -22,
      "y": 3,
      "z": -12,
      "name": "Rock_Slate"
    },
    {
      "x": -22,
      "y": 4,
      "z": -12,
      "name": "Rock_Slate"
    },
    {
      "x": -22,
      "y": 5,
      "z": -12,
      "name": "Rock_Slate"
    },
    {
      "x": -22,
      "y": 6,
      "z": -12,
      "name": "Rock_Slate"
    },
    {
      "x": -22,
      "y": 2,
      "z": -11,
      "name": "Rock_Slate"
    },
    {
      "x": -22,
      "y": 3,
      "z": -11,
      "name": "Rock_Slate"
    },
    {
      "x": -22,
      "y": 4,
      "z": -11,
      "name": "Rock_Slate"
    },
    {
      "x": -22,
      "y": 5,
      "z": -11,
      "name": "Rock_Slate"
    },
    {
      "x": -22,
      "y": 6,
      "z": -11,
      "name": "Rock_Slate"
    },
    {
      "x": -22,
      "y": 3,
      "z": -10,
      "name": "Rock_Slate"
    },
    {
      "x": -22,
      "y": 4,
      "z": -10,
      "name": "Rock_Slate"
    },
    {
      "x": -22,
      "y": 5,
      "z": -10,
      "name": "Rock_Slate"
    },
    {
      "x": -22,
      "y": 3,
      "z": -9,
      "name": "Rock_Slate"
    },
    {
      "x": -22,
      "y": 4,
      "z": -9,
      "name": "Rock_Slate"
    },
    {
      "x": -22,
      "y": 5,
      "z": -9,
      "name": "Rock_Slate"
    },
    {
      "x": -22,
      "y": 6,
      "z": -9,
      "name": "Rock_Slate"
    },
    {
      "x": -22,
      "y": 3,
      "z": -8,
      "name": "Rock_Slate"
    },
    {
      "x": -22,
      "y": 4,
      "z": -8,
      "name": "Rock_Slate"
    },
    {
      "x": -22,
      "y": 5,
      "z": -8,
      "name": "Rock_Slate"
    },
    {
      "x": -22,
      "y": 6,
      "z": -8,
      "name": "Rock_Slate"
    },
    {
      "x": -22,
      "y": 2,
      "z": -7,
      "name": "Rock_Slate"
    },
    {
      "x": -22,
      "y": 3,
      "z": -7,
      "name": "Rock_Slate"
    },
    {
      "x": -22,
      "y": 4,
      "z": -7,
      "name": "Rock_Slate"
    },
    {
      "x": -22,
      "y": 5,
      "z": -7,
      "name": "Rock_Slate"
    },
    {
      "x": -22,
      "y": 6,
      "z": -7,
      "name": "Rock_Slate"
    },
    {
      "x": -22,
      "y": 3,
      "z": -6,
      "name": "Rock_Slate"
    },
    {
      "x": -22,
      "y": 4,
      "z": -6,
      "name": "Rock_Slate"
    },
    {
      "x": -22,
      "y": 5,
      "z": -6,
      "name": "Rock_Slate"
    },
    {
      "x": -22,
      "y": 6,
      "z": -6,
      "name": "Rock_Slate"
    },
    {
      "x": -22,
      "y": 1,
      "z": -5,
      "name": "Rock_Slate"
    },
    {
      "x": -22,
      "y": 2,
      "z": -5,
      "name": "Rock_Slate"
    },
    {
      "x": -22,
      "y": 3,
      "z": -5,
      "name": "Rock_Slate"
    },
    {
      "x": -22,
      "y": 4,
      "z": -5,
      "name": "Rock_Slate"
    },
    {
      "x": -22,
      "y": 5,
      "z": -5,
      "name": "Rock_Slate"
    },
    {
      "x": -22,
      "y": 6,
      "z": -5,
      "name": "Rock_Slate"
    },
    {
      "x": -22,
      "y": 3,
      "z": -4,
      "name": "Rock_Slate"
    },
    {
      "x": -22,
      "y": 4,
      "z": -4,
      "name": "Rock_Slate"
    },
    {
      "x": -22,
      "y": 5,
      "z": -4,
      "name": "Rock_Slate"
    },
    {
      "x": -22,
      "y": 6,
      "z": -4,
      "name": "Rock_Slate"
    },
    {
      "x": -22,
      "y": 3,
      "z": -3,
      "name": "Rock_Slate"
    },
    {
      "x": -22,
      "y": 4,
      "z": -3,
      "name": "Rock_Slate"
    },
    {
      "x": -22,
      "y": 5,
      "z": -3,
      "name": "Rock_Slate"
    },
    {
      "x": -22,
      "y": 6,
      "z": -3,
      "name": "Rock_Slate"
    },
    {
      "x": -22,
      "y": 1,
      "z": -2,
      "name": "Rock_Slate"
    },
    {
      "x": -22,
      "y": 2,
      "z": -2,
      "name": "Rock_Slate"
    },
    {
      "x": -22,
      "y": 3,
      "z": -2,
      "name": "Rock_Slate"
    },
    {
      "x": -22,
      "y": 4,
      "z": -2,
      "name": "Rock_Slate"
    },
    {
      "x": -22,
      "y": 5,
      "z": -2,
      "name": "Rock_Slate"
    },
    {
      "x": -22,
      "y": 2,
      "z": -1,
      "name": "Rock_Slate"
    },
    {
      "x": -22,
      "y": 3,
      "z": -1,
      "name": "Rock_Slate"
    },
    {
      "x": -22,
      "y": 4,
      "z": -1,
      "name": "Rock_Slate"
    },
    {
      "x": -22,
      "y": 5,
      "z": -1,
      "name": "Rock_Slate"
    },
    {
      "x": -22,
      "y": 6,
      "z": -1,
      "name": "Rock_Slate"
    },
    {
      "x": -22,
      "y": 2,
      "z": 0,
      "name": "Rock_Slate"
    },
    {
      "x": -22,
      "y": 3,
      "z": 0,
      "name": "Rock_Slate"
    },
    {
      "x": -22,
      "y": 4,
      "z": 0,
      "name": "Rock_Slate"
    },
    {
      "x": -22,
      "y": 5,
      "z": 0,
      "name": "Rock_Slate"
    },
    {
      "x": -22,
      "y": 6,
      "z": 0,
      "name": "Rock_Slate"
    },
    {
      "x": -22,
      "y": 1,
      "z": 1,
      "name": "Rock_Slate"
    },
    {
      "x": -22,
      "y": 2,
      "z": 1,
      "name": "Rock_Slate"
    },
    {
      "x": -22,
      "y": 3,
      "z": 1,
      "name": "Rock_Slate"
    },
    {
      "x": -22,
      "y": 4,
      "z": 1,
      "name": "Rock_Slate"
    },
    {
      "x": -22,
      "y": 5,
      "z": 1,
      "name": "Rock_Slate"
    },
    {
      "x": -22,
      "y": 1,
      "z": 2,
      "name": "Rock_Slate"
    },
    {
      "x": -22,
      "y": 2,
      "z": 2,
      "name": "Rock_Slate"
    },
    {
      "x": -22,
      "y": 3,
      "z": 2,
      "name": "Rock_Slate"
    },
    {
      "x": -22,
      "y": 4,
      "z": 2,
      "name": "Rock_Slate"
    },
    {
      "x": -22,
      "y": 5,
      "z": 2,
      "name": "Rock_Slate"
    },
    {
      "x": -22,
      "y": 6,
      "z": 2,
      "name": "Rock_Slate"
    },
    {
      "x": -22,
      "y": 1,
      "z": 3,
      "name": "Rock_Slate"
    },
    {
      "x": -22,
      "y": 2,
      "z": 3,
      "name": "Rock_Slate"
    },
    {
      "x": -22,
      "y": 3,
      "z": 3,
      "name": "Rock_Slate"
    },
    {
      "x": -22,
      "y": 4,
      "z": 3,
      "name": "Rock_Slate"
    },
    {
      "x": -22,
      "y": 5,
      "z": 3,
      "name": "Rock_Slate"
    },
    {
      "x": -22,
      "y": 6,
      "z": 3,
      "name": "Rock_Slate"
    },
    {
      "x": -22,
      "y": 2,
      "z": 4,
      "name": "Rock_Slate"
    },
    {
      "x": -22,
      "y": 3,
      "z": 4,
      "name": "Rock_Slate"
    },
    {
      "x": -22,
      "y": 4,
      "z": 4,
      "name": "Rock_Slate"
    },
    {
      "x": -22,
      "y": 5,
      "z": 4,
      "name": "Rock_Slate"
    },
    {
      "x": -22,
      "y": 6,
      "z": 4,
      "name": "Rock_Slate"
    },
    {
      "x": -22,
      "y": 1,
      "z": 5,
      "name": "Rock_Slate"
    },
    {
      "x": -22,
      "y": 2,
      "z": 5,
      "name": "Rock_Slate"
    },
    {
      "x": -22,
      "y": 3,
      "z": 5,
      "name": "Rock_Slate"
    },
    {
      "x": -22,
      "y": 4,
      "z": 5,
      "name": "Rock_Slate"
    },
    {
      "x": -22,
      "y": 5,
      "z": 5,
      "name": "Rock_Slate"
    },
    {
      "x": -22,
      "y": 6,
      "z": 5,
      "name": "Rock_Slate"
    },
    {
      "x": -22,
      "y": 2,
      "z": 6,
      "name": "Rock_Slate"
    },
    {
      "x": -22,
      "y": 3,
      "z": 6,
      "name": "Rock_Slate"
    },
    {
      "x": -22,
      "y": 4,
      "z": 6,
      "name": "Rock_Slate"
    },
    {
      "x": -22,
      "y": 5,
      "z": 6,
      "name": "Rock_Slate"
    },
    {
      "x": -22,
      "y": 6,
      "z": 6,
      "name": "Rock_Slate"
    },
    {
      "x": -22,
      "y": 3,
      "z": 7,
      "name": "Rock_Slate"
    },
    {
      "x": -22,
      "y": 4,
      "z": 7,
      "name": "Rock_Slate"
    },
    {
      "x": -22,
      "y": 5,
      "z": 7,
      "name": "Rock_Slate"
    },
    {
      "x": -22,
      "y": 6,
      "z": 7,
      "name": "Rock_Slate"
    },
    {
      "x": -22,
      "y": 2,
      "z": 8,
      "name": "Rock_Slate"
    },
    {
      "x": -22,
      "y": 3,
      "z": 8,
      "name": "Rock_Slate"
    },
    {
      "x": -22,
      "y": 4,
      "z": 8,
      "name": "Rock_Slate"
    },
    {
      "x": -22,
      "y": 5,
      "z": 8,
      "name": "Rock_Slate"
    },
    {
      "x": -22,
      "y": 6,
      "z": 8,
      "name": "Rock_Slate"
    },
    {
      "x": -22,
      "y": 2,
      "z": 9,
      "name": "Rock_Slate"
    },
    {
      "x": -22,
      "y": 3,
      "z": 9,
      "name": "Rock_Slate"
    },
    {
      "x": -22,
      "y": 4,
      "z": 9,
      "name": "Rock_Slate"
    },
    {
      "x": -22,
      "y": 2,
      "z": 10,
      "name": "Rock_Slate"
    },
    {
      "x": -22,
      "y": 3,
      "z": 10,
      "name": "Rock_Slate"
    },
    {
      "x": -22,
      "y": 4,
      "z": 10,
      "name": "Rock_Slate"
    },
    {
      "x": -22,
      "y": 5,
      "z": 10,
      "name": "Rock_Slate"
    },
    {
      "x": -22,
      "y": 6,
      "z": 10,
      "name": "Rock_Slate"
    },
    {
      "x": -22,
      "y": 2,
      "z": 11,
      "name": "Rock_Slate"
    },
    {
      "x": -22,
      "y": 3,
      "z": 11,
      "name": "Rock_Slate"
    },
    {
      "x": -22,
      "y": 4,
      "z": 11,
      "name": "Rock_Slate"
    },
    {
      "x": -22,
      "y": 5,
      "z": 11,
      "name": "Rock_Slate"
    },
    {
      "x": -22,
      "y": 6,
      "z": 11,
      "name": "Rock_Slate"
    },
    {
      "x": -22,
      "y": 2,
      "z": 12,
      "name": "Rock_Slate"
    },
    {
      "x": -22,
      "y": 3,
      "z": 12,
      "name": "Rock_Slate"
    },
    {
      "x": -22,
      "y": 4,
      "z": 12,
      "name": "Rock_Slate"
    },
    {
      "x": -22,
      "y": 5,
      "z": 12,
      "name": "Rock_Slate"
    },
    {
      "x": -22,
      "y": 6,
      "z": 12,
      "name": "Rock_Slate"
    },
    {
      "x": -22,
      "y": 2,
      "z": 13,
      "name": "Rock_Slate"
    },
    {
      "x": -22,
      "y": 3,
      "z": 13,
      "name": "Rock_Slate"
    },
    {
      "x": -22,
      "y": 4,
      "z": 13,
      "name": "Rock_Slate"
    },
    {
      "x": -22,
      "y": 5,
      "z": 13,
      "name": "Rock_Slate"
    },
    {
      "x": -22,
      "y": 2,
      "z": 14,
      "name": "Rock_Slate"
    },
    {
      "x": -22,
      "y": 3,
      "z": 14,
      "name": "Rock_Slate"
    },
    {
      "x": -22,
      "y": 4,
      "z": 14,
      "name": "Rock_Slate"
    },
    {
      "x": -22,
      "y": 5,
      "z": 14,
      "name": "Rock_Slate"
    },
    {
      "x": -22,
      "y": 3,
      "z": 15,
      "name": "Rock_Slate"
    },
    {
      "x": -22,
      "y": 4,
      "z": 15,
      "name": "Rock_Slate"
    },
    {
      "x": -22,
      "y": 5,
      "z": 15,
      "name": "Rock_Slate"
    },
    {
      "x": -22,
      "y": 2,
      "z": 16,
      "name": "Rock_Slate"
    },
    {
      "x": -22,
      "y": 3,
      "z": 16,
      "name": "Rock_Slate"
    },
    {
      "x": -22,
      "y": 4,
      "z": 16,
      "name": "Rock_Slate"
    },
    {
      "x": -22,
      "y": 5,
      "z": 16,
      "name": "Rock_Slate"
    },
    {
      "x": -22,
      "y": 2,
      "z": 17,
      "name": "Rock_Slate"
    },
    {
      "x": -22,
      "y": 3,
      "z": 17,
      "name": "Rock_Slate"
    },
    {
      "x": -22,
      "y": 4,
      "z": 17,
      "name": "Rock_Slate"
    },
    {
      "x": -22,
      "y": 5,
      "z": 17,
      "name": "Rock_Slate"
    },
    {
      "x": -22,
      "y": 6,
      "z": 17,
      "name": "Rock_Slate"
    },
    {
      "x": -22,
      "y": 2,
      "z": 18,
      "name": "Rock_Slate"
    },
    {
      "x": -22,
      "y": 4,
      "z": 18,
      "name": "Rock_Slate"
    },
    {
      "x": -22,
      "y": 5,
      "z": 18,
      "name": "Rock_Slate"
    },
    {
      "x": -22,
      "y": 6,
      "z": 18,
      "name": "Rock_Slate"
    },
    {
      "x": -22,
      "y": 4,
      "z": 19,
      "name": "Rock_Slate"
    },
    {
      "x": -22,
      "y": 5,
      "z": 19,
      "name": "Rock_Slate"
    },
    {
      "x": -22,
      "y": 4,
      "z": 20,
      "name": "Rock_Slate"
    },
    {
      "x": -22,
      "y": 5,
      "z": 20,
      "name": "Rock_Slate"
    },
    {
      "x": -21,
      "y": 2,
      "z": -22,
      "name": "Rock_Slate"
    },
    {
      "x": -21,
      "y": 4,
      "z": -22,
      "name": "Rock_Slate"
    },
    {
      "x": -21,
      "y": 2,
      "z": -21,
      "name": "Rock_Slate"
    },
    {
      "x": -21,
      "y": 3,
      "z": -21,
      "name": "Rock_Slate"
    },
    {
      "x": -21,
      "y": 4,
      "z": -21,
      "name": "Rock_Slate"
    },
    {
      "x": -21,
      "y": 3,
      "z": -20,
      "name": "Rock_Slate"
    },
    {
      "x": -21,
      "y": 4,
      "z": -20,
      "name": "Rock_Slate"
    },
    {
      "x": -21,
      "y": 5,
      "z": -20,
      "name": "Rock_Slate"
    },
    {
      "x": -21,
      "y": 3,
      "z": -19,
      "name": "Rock_Slate"
    },
    {
      "x": -21,
      "y": 4,
      "z": -19,
      "name": "Rock_Slate"
    },
    {
      "x": -21,
      "y": 5,
      "z": -19,
      "name": "Rock_Slate"
    },
    {
      "x": -21,
      "y": 6,
      "z": -19,
      "name": "Rock_Slate"
    },
    {
      "x": -21,
      "y": 3,
      "z": -18,
      "name": "Rock_Slate"
    },
    {
      "x": -21,
      "y": 4,
      "z": -18,
      "name": "Rock_Slate"
    },
    {
      "x": -21,
      "y": 5,
      "z": -18,
      "name": "Rock_Slate"
    },
    {
      "x": -21,
      "y": 2,
      "z": -17,
      "name": "Rock_Slate"
    },
    {
      "x": -21,
      "y": 3,
      "z": -17,
      "name": "Rock_Slate"
    },
    {
      "x": -21,
      "y": 4,
      "z": -17,
      "name": "Rock_Slate"
    },
    {
      "x": -21,
      "y": 5,
      "z": -17,
      "name": "Rock_Slate"
    },
    {
      "x": -21,
      "y": 3,
      "z": -16,
      "name": "Rock_Slate"
    },
    {
      "x": -21,
      "y": 4,
      "z": -16,
      "name": "Rock_Slate"
    },
    {
      "x": -21,
      "y": 5,
      "z": -16,
      "name": "Rock_Slate"
    },
    {
      "x": -21,
      "y": 6,
      "z": -16,
      "name": "Rock_Slate"
    },
    {
      "x": -21,
      "y": 1,
      "z": -15,
      "name": "Rock_Slate"
    },
    {
      "x": -21,
      "y": 2,
      "z": -15,
      "name": "Rock_Slate"
    },
    {
      "x": -21,
      "y": 3,
      "z": -15,
      "name": "Rock_Slate"
    },
    {
      "x": -21,
      "y": 4,
      "z": -15,
      "name": "Rock_Slate"
    },
    {
      "x": -21,
      "y": 5,
      "z": -15,
      "name": "Rock_Slate"
    },
    {
      "x": -21,
      "y": 6,
      "z": -15,
      "name": "Rock_Slate"
    },
    {
      "x": -21,
      "y": 3,
      "z": -14,
      "name": "Rock_Slate"
    },
    {
      "x": -21,
      "y": 4,
      "z": -14,
      "name": "Rock_Slate"
    },
    {
      "x": -21,
      "y": 5,
      "z": -14,
      "name": "Rock_Slate"
    },
    {
      "x": -21,
      "y": 6,
      "z": -14,
      "name": "Rock_Slate"
    },
    {
      "x": -21,
      "y": 3,
      "z": -13,
      "name": "Rock_Slate"
    },
    {
      "x": -21,
      "y": 4,
      "z": -13,
      "name": "Rock_Slate"
    },
    {
      "x": -21,
      "y": 5,
      "z": -13,
      "name": "Rock_Slate"
    },
    {
      "x": -21,
      "y": 6,
      "z": -13,
      "name": "Rock_Slate"
    },
    {
      "x": -21,
      "y": 2,
      "z": -12,
      "name": "Rock_Slate"
    },
    {
      "x": -21,
      "y": 3,
      "z": -12,
      "name": "Rock_Slate"
    },
    {
      "x": -21,
      "y": 4,
      "z": -12,
      "name": "Rock_Slate"
    },
    {
      "x": -21,
      "y": 5,
      "z": -12,
      "name": "Rock_Slate"
    },
    {
      "x": -21,
      "y": 6,
      "z": -12,
      "name": "Rock_Slate"
    },
    {
      "x": -21,
      "y": 3,
      "z": -11,
      "name": "Rock_Slate"
    },
    {
      "x": -21,
      "y": 4,
      "z": -11,
      "name": "Rock_Slate"
    },
    {
      "x": -21,
      "y": 5,
      "z": -11,
      "name": "Rock_Slate"
    },
    {
      "x": -21,
      "y": 6,
      "z": -11,
      "name": "Rock_Slate"
    },
    {
      "x": -21,
      "y": 1,
      "z": -10,
      "name": "Rock_Slate"
    },
    {
      "x": -21,
      "y": 2,
      "z": -10,
      "name": "Rock_Slate"
    },
    {
      "x": -21,
      "y": 3,
      "z": -10,
      "name": "Rock_Slate"
    },
    {
      "x": -21,
      "y": 4,
      "z": -10,
      "name": "Rock_Slate"
    },
    {
      "x": -21,
      "y": 5,
      "z": -10,
      "name": "Rock_Slate"
    },
    {
      "x": -21,
      "y": 6,
      "z": -10,
      "name": "Rock_Slate"
    },
    {
      "x": -21,
      "y": 3,
      "z": -9,
      "name": "Rock_Slate"
    },
    {
      "x": -21,
      "y": 4,
      "z": -9,
      "name": "Rock_Slate"
    },
    {
      "x": -21,
      "y": 5,
      "z": -9,
      "name": "Rock_Slate"
    },
    {
      "x": -21,
      "y": 6,
      "z": -9,
      "name": "Rock_Slate"
    },
    {
      "x": -21,
      "y": 3,
      "z": -8,
      "name": "Rock_Slate"
    },
    {
      "x": -21,
      "y": 4,
      "z": -8,
      "name": "Rock_Slate"
    },
    {
      "x": -21,
      "y": 5,
      "z": -8,
      "name": "Rock_Slate"
    },
    {
      "x": -21,
      "y": 6,
      "z": -8,
      "name": "Rock_Slate"
    },
    {
      "x": -21,
      "y": 2,
      "z": -7,
      "name": "Rock_Slate"
    },
    {
      "x": -21,
      "y": 3,
      "z": -7,
      "name": "Rock_Slate"
    },
    {
      "x": -21,
      "y": 4,
      "z": -7,
      "name": "Rock_Slate"
    },
    {
      "x": -21,
      "y": 5,
      "z": -7,
      "name": "Rock_Slate"
    },
    {
      "x": -21,
      "y": 6,
      "z": -7,
      "name": "Rock_Slate"
    },
    {
      "x": -21,
      "y": 2,
      "z": -6,
      "name": "Rock_Slate"
    },
    {
      "x": -21,
      "y": 3,
      "z": -6,
      "name": "Rock_Slate"
    },
    {
      "x": -21,
      "y": 4,
      "z": -6,
      "name": "Rock_Slate"
    },
    {
      "x": -21,
      "y": 5,
      "z": -6,
      "name": "Rock_Slate"
    },
    {
      "x": -21,
      "y": 6,
      "z": -6,
      "name": "Rock_Slate"
    },
    {
      "x": -21,
      "y": 2,
      "z": -5,
      "name": "Rock_Slate"
    },
    {
      "x": -21,
      "y": 3,
      "z": -5,
      "name": "Rock_Slate"
    },
    {
      "x": -21,
      "y": 4,
      "z": -5,
      "name": "Rock_Slate"
    },
    {
      "x": -21,
      "y": 5,
      "z": -5,
      "name": "Rock_Slate"
    },
    {
      "x": -21,
      "y": 6,
      "z": -5,
      "name": "Rock_Slate"
    },
    {
      "x": -21,
      "y": 3,
      "z": -4,
      "name": "Rock_Slate"
    },
    {
      "x": -21,
      "y": 4,
      "z": -4,
      "name": "Rock_Slate"
    },
    {
      "x": -21,
      "y": 5,
      "z": -4,
      "name": "Rock_Slate"
    },
    {
      "x": -21,
      "y": 6,
      "z": -4,
      "name": "Rock_Slate"
    },
    {
      "x": -21,
      "y": 2,
      "z": -3,
      "name": "Rock_Slate"
    },
    {
      "x": -21,
      "y": 3,
      "z": -3,
      "name": "Rock_Slate"
    },
    {
      "x": -21,
      "y": 4,
      "z": -3,
      "name": "Rock_Slate"
    },
    {
      "x": -21,
      "y": 5,
      "z": -3,
      "name": "Rock_Slate"
    },
    {
      "x": -21,
      "y": 6,
      "z": -3,
      "name": "Rock_Slate"
    },
    {
      "x": -21,
      "y": 3,
      "z": -2,
      "name": "Rock_Slate"
    },
    {
      "x": -21,
      "y": 4,
      "z": -2,
      "name": "Rock_Slate"
    },
    {
      "x": -21,
      "y": 5,
      "z": -2,
      "name": "Rock_Slate"
    },
    {
      "x": -21,
      "y": 6,
      "z": -2,
      "name": "Rock_Slate"
    },
    {
      "x": -21,
      "y": 3,
      "z": -1,
      "name": "Rock_Slate"
    },
    {
      "x": -21,
      "y": 4,
      "z": -1,
      "name": "Rock_Slate"
    },
    {
      "x": -21,
      "y": 5,
      "z": -1,
      "name": "Rock_Slate"
    },
    {
      "x": -21,
      "y": 6,
      "z": -1,
      "name": "Rock_Slate"
    },
    {
      "x": -21,
      "y": 3,
      "z": 0,
      "name": "Rock_Slate"
    },
    {
      "x": -21,
      "y": 4,
      "z": 0,
      "name": "Rock_Slate"
    },
    {
      "x": -21,
      "y": 5,
      "z": 0,
      "name": "Rock_Slate"
    },
    {
      "x": -21,
      "y": 6,
      "z": 0,
      "name": "Rock_Slate"
    },
    {
      "x": -21,
      "y": 3,
      "z": 1,
      "name": "Rock_Slate"
    },
    {
      "x": -21,
      "y": 4,
      "z": 1,
      "name": "Rock_Slate"
    },
    {
      "x": -21,
      "y": 5,
      "z": 1,
      "name": "Rock_Slate"
    },
    {
      "x": -21,
      "y": 6,
      "z": 1,
      "name": "Rock_Slate"
    },
    {
      "x": -21,
      "y": 4,
      "z": 2,
      "name": "Rock_Slate"
    },
    {
      "x": -21,
      "y": 5,
      "z": 2,
      "name": "Rock_Slate"
    },
    {
      "x": -21,
      "y": 6,
      "z": 2,
      "name": "Rock_Slate"
    },
    {
      "x": -21,
      "y": 2,
      "z": 3,
      "name": "Rock_Slate"
    },
    {
      "x": -21,
      "y": 3,
      "z": 3,
      "name": "Rock_Slate"
    },
    {
      "x": -21,
      "y": 4,
      "z": 3,
      "name": "Rock_Slate"
    },
    {
      "x": -21,
      "y": 5,
      "z": 3,
      "name": "Rock_Slate"
    },
    {
      "x": -21,
      "y": 6,
      "z": 3,
      "name": "Rock_Slate"
    },
    {
      "x": -21,
      "y": 3,
      "z": 4,
      "name": "Rock_Slate"
    },
    {
      "x": -21,
      "y": 4,
      "z": 4,
      "name": "Rock_Slate"
    },
    {
      "x": -21,
      "y": 5,
      "z": 4,
      "name": "Rock_Slate"
    },
    {
      "x": -21,
      "y": 6,
      "z": 4,
      "name": "Rock_Slate"
    },
    {
      "x": -21,
      "y": 4,
      "z": 5,
      "name": "Rock_Slate"
    },
    {
      "x": -21,
      "y": 5,
      "z": 5,
      "name": "Rock_Slate"
    },
    {
      "x": -21,
      "y": 6,
      "z": 5,
      "name": "Rock_Slate"
    },
    {
      "x": -21,
      "y": 4,
      "z": 6,
      "name": "Rock_Slate"
    },
    {
      "x": -21,
      "y": 5,
      "z": 6,
      "name": "Rock_Slate"
    },
    {
      "x": -21,
      "y": 6,
      "z": 6,
      "name": "Rock_Slate"
    },
    {
      "x": -21,
      "y": 1,
      "z": 7,
      "name": "Rock_Slate"
    },
    {
      "x": -21,
      "y": 2,
      "z": 7,
      "name": "Rock_Slate"
    },
    {
      "x": -21,
      "y": 3,
      "z": 7,
      "name": "Rock_Slate"
    },
    {
      "x": -21,
      "y": 4,
      "z": 7,
      "name": "Rock_Slate"
    },
    {
      "x": -21,
      "y": 5,
      "z": 7,
      "name": "Rock_Slate"
    },
    {
      "x": -21,
      "y": 6,
      "z": 7,
      "name": "Rock_Slate"
    },
    {
      "x": -21,
      "y": 2,
      "z": 8,
      "name": "Rock_Slate"
    },
    {
      "x": -21,
      "y": 3,
      "z": 8,
      "name": "Rock_Slate"
    },
    {
      "x": -21,
      "y": 4,
      "z": 8,
      "name": "Rock_Slate"
    },
    {
      "x": -21,
      "y": 5,
      "z": 8,
      "name": "Rock_Slate"
    },
    {
      "x": -21,
      "y": 6,
      "z": 8,
      "name": "Rock_Slate"
    },
    {
      "x": -21,
      "y": 2,
      "z": 9,
      "name": "Rock_Slate"
    },
    {
      "x": -21,
      "y": 3,
      "z": 9,
      "name": "Rock_Slate"
    },
    {
      "x": -21,
      "y": 4,
      "z": 9,
      "name": "Rock_Slate"
    },
    {
      "x": -21,
      "y": 5,
      "z": 9,
      "name": "Rock_Slate"
    },
    {
      "x": -21,
      "y": 6,
      "z": 9,
      "name": "Rock_Slate"
    },
    {
      "x": -21,
      "y": 0,
      "z": 10,
      "name": "Rock_Slate"
    },
    {
      "x": -21,
      "y": 1,
      "z": 10,
      "name": "Rock_Slate"
    },
    {
      "x": -21,
      "y": 2,
      "z": 10,
      "name": "Rock_Slate"
    },
    {
      "x": -21,
      "y": 3,
      "z": 10,
      "name": "Rock_Slate"
    },
    {
      "x": -21,
      "y": 4,
      "z": 10,
      "name": "Rock_Slate"
    },
    {
      "x": -21,
      "y": 5,
      "z": 10,
      "name": "Rock_Slate"
    },
    {
      "x": -21,
      "y": 6,
      "z": 10,
      "name": "Rock_Slate"
    },
    {
      "x": -21,
      "y": 3,
      "z": 11,
      "name": "Rock_Slate"
    },
    {
      "x": -21,
      "y": 4,
      "z": 11,
      "name": "Rock_Slate"
    },
    {
      "x": -21,
      "y": 5,
      "z": 11,
      "name": "Rock_Slate"
    },
    {
      "x": -21,
      "y": 6,
      "z": 11,
      "name": "Rock_Slate"
    },
    {
      "x": -21,
      "y": 2,
      "z": 12,
      "name": "Rock_Slate"
    },
    {
      "x": -21,
      "y": 3,
      "z": 12,
      "name": "Rock_Slate"
    },
    {
      "x": -21,
      "y": 4,
      "z": 12,
      "name": "Rock_Slate"
    },
    {
      "x": -21,
      "y": 5,
      "z": 12,
      "name": "Rock_Slate"
    },
    {
      "x": -21,
      "y": 6,
      "z": 12,
      "name": "Rock_Slate"
    },
    {
      "x": -21,
      "y": 3,
      "z": 13,
      "name": "Rock_Slate"
    },
    {
      "x": -21,
      "y": 4,
      "z": 13,
      "name": "Rock_Slate"
    },
    {
      "x": -21,
      "y": 5,
      "z": 13,
      "name": "Rock_Slate"
    },
    {
      "x": -21,
      "y": 6,
      "z": 13,
      "name": "Rock_Slate"
    },
    {
      "x": -21,
      "y": 2,
      "z": 14,
      "name": "Rock_Slate"
    },
    {
      "x": -21,
      "y": 3,
      "z": 14,
      "name": "Rock_Slate"
    },
    {
      "x": -21,
      "y": 4,
      "z": 14,
      "name": "Rock_Slate"
    },
    {
      "x": -21,
      "y": 5,
      "z": 14,
      "name": "Rock_Slate"
    },
    {
      "x": -21,
      "y": 6,
      "z": 14,
      "name": "Rock_Slate"
    },
    {
      "x": -21,
      "y": 3,
      "z": 15,
      "name": "Rock_Slate"
    },
    {
      "x": -21,
      "y": 4,
      "z": 15,
      "name": "Rock_Slate"
    },
    {
      "x": -21,
      "y": 5,
      "z": 15,
      "name": "Rock_Slate"
    },
    {
      "x": -21,
      "y": 6,
      "z": 15,
      "name": "Rock_Slate"
    },
    {
      "x": -21,
      "y": 2,
      "z": 16,
      "name": "Rock_Slate"
    },
    {
      "x": -21,
      "y": 3,
      "z": 16,
      "name": "Rock_Slate"
    },
    {
      "x": -21,
      "y": 4,
      "z": 16,
      "name": "Rock_Slate"
    },
    {
      "x": -21,
      "y": 1,
      "z": 17,
      "name": "Rock_Slate"
    },
    {
      "x": -21,
      "y": 2,
      "z": 17,
      "name": "Rock_Slate"
    },
    {
      "x": -21,
      "y": 3,
      "z": 17,
      "name": "Rock_Slate"
    },
    {
      "x": -21,
      "y": 4,
      "z": 17,
      "name": "Rock_Slate"
    },
    {
      "x": -21,
      "y": 5,
      "z": 17,
      "name": "Rock_Slate"
    },
    {
      "x": -21,
      "y": 6,
      "z": 17,
      "name": "Rock_Slate"
    },
    {
      "x": -21,
      "y": 3,
      "z": 18,
      "name": "Rock_Slate"
    },
    {
      "x": -21,
      "y": 4,
      "z": 18,
      "name": "Rock_Slate"
    },
    {
      "x": -21,
      "y": 5,
      "z": 18,
      "name": "Rock_Slate"
    },
    {
      "x": -21,
      "y": 6,
      "z": 18,
      "name": "Rock_Slate"
    },
    {
      "x": -21,
      "y": 6,
      "z": 19,
      "name": "Rock_Slate"
    },
    {
      "x": -20,
      "y": 2,
      "z": -22,
      "name": "Rock_Slate"
    },
    {
      "x": -20,
      "y": 5,
      "z": -22,
      "name": "Rock_Slate"
    },
    {
      "x": -20,
      "y": 2,
      "z": -21,
      "name": "Rock_Slate"
    },
    {
      "x": -20,
      "y": 3,
      "z": -21,
      "name": "Rock_Slate"
    },
    {
      "x": -20,
      "y": 5,
      "z": -21,
      "name": "Rock_Slate"
    },
    {
      "x": -20,
      "y": 6,
      "z": -21,
      "name": "Rock_Slate"
    },
    {
      "x": -20,
      "y": 2,
      "z": -20,
      "name": "Rock_Slate"
    },
    {
      "x": -20,
      "y": 3,
      "z": -20,
      "name": "Rock_Slate"
    },
    {
      "x": -20,
      "y": 4,
      "z": -20,
      "name": "Rock_Slate"
    },
    {
      "x": -20,
      "y": 5,
      "z": -20,
      "name": "Rock_Slate"
    },
    {
      "x": -20,
      "y": 2,
      "z": -19,
      "name": "Rock_Slate"
    },
    {
      "x": -20,
      "y": 3,
      "z": -19,
      "name": "Rock_Slate"
    },
    {
      "x": -20,
      "y": 4,
      "z": -19,
      "name": "Rock_Slate"
    },
    {
      "x": -20,
      "y": 5,
      "z": -19,
      "name": "Rock_Slate"
    },
    {
      "x": -20,
      "y": 6,
      "z": -19,
      "name": "Rock_Slate"
    },
    {
      "x": -20,
      "y": 3,
      "z": -18,
      "name": "Rock_Slate"
    },
    {
      "x": -20,
      "y": 4,
      "z": -18,
      "name": "Rock_Slate"
    },
    {
      "x": -20,
      "y": 5,
      "z": -18,
      "name": "Rock_Slate"
    },
    {
      "x": -20,
      "y": 3,
      "z": -17,
      "name": "Rock_Slate"
    },
    {
      "x": -20,
      "y": 4,
      "z": -17,
      "name": "Rock_Slate"
    },
    {
      "x": -20,
      "y": 5,
      "z": -17,
      "name": "Rock_Slate"
    },
    {
      "x": -20,
      "y": 3,
      "z": -16,
      "name": "Rock_Slate"
    },
    {
      "x": -20,
      "y": 4,
      "z": -16,
      "name": "Rock_Slate"
    },
    {
      "x": -20,
      "y": 5,
      "z": -16,
      "name": "Rock_Slate"
    },
    {
      "x": -20,
      "y": 6,
      "z": -16,
      "name": "Rock_Slate"
    },
    {
      "x": -20,
      "y": 4,
      "z": -15,
      "name": "Rock_Slate"
    },
    {
      "x": -20,
      "y": 5,
      "z": -15,
      "name": "Rock_Slate"
    },
    {
      "x": -20,
      "y": 6,
      "z": -15,
      "name": "Rock_Slate"
    },
    {
      "x": -20,
      "y": 2,
      "z": -14,
      "name": "Rock_Slate"
    },
    {
      "x": -20,
      "y": 3,
      "z": -14,
      "name": "Rock_Slate"
    },
    {
      "x": -20,
      "y": 4,
      "z": -14,
      "name": "Rock_Slate"
    },
    {
      "x": -20,
      "y": 5,
      "z": -14,
      "name": "Rock_Slate"
    },
    {
      "x": -20,
      "y": 6,
      "z": -14,
      "name": "Rock_Slate"
    },
    {
      "x": -20,
      "y": 0,
      "z": -13,
      "name": "Rock_Slate"
    },
    {
      "x": -20,
      "y": 1,
      "z": -13,
      "name": "Rock_Slate"
    },
    {
      "x": -20,
      "y": 2,
      "z": -13,
      "name": "Rock_Slate"
    },
    {
      "x": -20,
      "y": 3,
      "z": -13,
      "name": "Rock_Slate"
    },
    {
      "x": -20,
      "y": 4,
      "z": -13,
      "name": "Rock_Slate"
    },
    {
      "x": -20,
      "y": 5,
      "z": -13,
      "name": "Rock_Slate"
    },
    {
      "x": -20,
      "y": 6,
      "z": -13,
      "name": "Rock_Slate"
    },
    {
      "x": -20,
      "y": 3,
      "z": -12,
      "name": "Rock_Slate"
    },
    {
      "x": -20,
      "y": 4,
      "z": -12,
      "name": "Rock_Slate"
    },
    {
      "x": -20,
      "y": 5,
      "z": -12,
      "name": "Rock_Slate"
    },
    {
      "x": -20,
      "y": 6,
      "z": -12,
      "name": "Rock_Slate"
    },
    {
      "x": -20,
      "y": 2,
      "z": -11,
      "name": "Rock_Slate"
    },
    {
      "x": -20,
      "y": 3,
      "z": -11,
      "name": "Rock_Slate"
    },
    {
      "x": -20,
      "y": 4,
      "z": -11,
      "name": "Rock_Slate"
    },
    {
      "x": -20,
      "y": 5,
      "z": -11,
      "name": "Rock_Slate"
    },
    {
      "x": -20,
      "y": 6,
      "z": -11,
      "name": "Rock_Slate"
    },
    {
      "x": -20,
      "y": 3,
      "z": -10,
      "name": "Rock_Slate"
    },
    {
      "x": -20,
      "y": 4,
      "z": -10,
      "name": "Rock_Slate"
    },
    {
      "x": -20,
      "y": 5,
      "z": -10,
      "name": "Rock_Slate"
    },
    {
      "x": -20,
      "y": 6,
      "z": -10,
      "name": "Rock_Slate"
    },
    {
      "x": -20,
      "y": 3,
      "z": -9,
      "name": "Rock_Slate"
    },
    {
      "x": -20,
      "y": 4,
      "z": -9,
      "name": "Rock_Slate"
    },
    {
      "x": -20,
      "y": 5,
      "z": -9,
      "name": "Rock_Slate"
    },
    {
      "x": -20,
      "y": 6,
      "z": -9,
      "name": "Rock_Slate"
    },
    {
      "x": -20,
      "y": 3,
      "z": -8,
      "name": "Rock_Slate"
    },
    {
      "x": -20,
      "y": 4,
      "z": -8,
      "name": "Rock_Slate"
    },
    {
      "x": -20,
      "y": 5,
      "z": -8,
      "name": "Rock_Slate"
    },
    {
      "x": -20,
      "y": 6,
      "z": -8,
      "name": "Rock_Slate"
    },
    {
      "x": -20,
      "y": 2,
      "z": -7,
      "name": "Rock_Slate"
    },
    {
      "x": -20,
      "y": 3,
      "z": -7,
      "name": "Rock_Slate"
    },
    {
      "x": -20,
      "y": 4,
      "z": -7,
      "name": "Rock_Slate"
    },
    {
      "x": -20,
      "y": 5,
      "z": -7,
      "name": "Rock_Slate"
    },
    {
      "x": -20,
      "y": 6,
      "z": -7,
      "name": "Rock_Slate"
    },
    {
      "x": -20,
      "y": 4,
      "z": -6,
      "name": "Rock_Slate"
    },
    {
      "x": -20,
      "y": 5,
      "z": -6,
      "name": "Rock_Slate"
    },
    {
      "x": -20,
      "y": 6,
      "z": -6,
      "name": "Rock_Slate"
    },
    {
      "x": -20,
      "y": 3,
      "z": -5,
      "name": "Rock_Slate"
    },
    {
      "x": -20,
      "y": 4,
      "z": -5,
      "name": "Rock_Slate"
    },
    {
      "x": -20,
      "y": 5,
      "z": -5,
      "name": "Rock_Slate"
    },
    {
      "x": -20,
      "y": 6,
      "z": -5,
      "name": "Rock_Slate"
    },
    {
      "x": -20,
      "y": 4,
      "z": -4,
      "name": "Rock_Slate"
    },
    {
      "x": -20,
      "y": 5,
      "z": -4,
      "name": "Rock_Slate"
    },
    {
      "x": -20,
      "y": 6,
      "z": -4,
      "name": "Rock_Slate"
    },
    {
      "x": -20,
      "y": 4,
      "z": -3,
      "name": "Rock_Slate"
    },
    {
      "x": -20,
      "y": 5,
      "z": -3,
      "name": "Rock_Slate"
    },
    {
      "x": -20,
      "y": 6,
      "z": -3,
      "name": "Rock_Slate"
    },
    {
      "x": -20,
      "y": 2,
      "z": -2,
      "name": "Rock_Slate"
    },
    {
      "x": -20,
      "y": 3,
      "z": -2,
      "name": "Rock_Slate"
    },
    {
      "x": -20,
      "y": 4,
      "z": -2,
      "name": "Rock_Slate"
    },
    {
      "x": -20,
      "y": 5,
      "z": -2,
      "name": "Rock_Slate"
    },
    {
      "x": -20,
      "y": 6,
      "z": -2,
      "name": "Rock_Slate"
    },
    {
      "x": -20,
      "y": 2,
      "z": -1,
      "name": "Rock_Slate"
    },
    {
      "x": -20,
      "y": 3,
      "z": -1,
      "name": "Rock_Slate"
    },
    {
      "x": -20,
      "y": 4,
      "z": -1,
      "name": "Rock_Slate"
    },
    {
      "x": -20,
      "y": 5,
      "z": -1,
      "name": "Rock_Slate"
    },
    {
      "x": -20,
      "y": 6,
      "z": -1,
      "name": "Rock_Slate"
    },
    {
      "x": -20,
      "y": 0,
      "z": 0,
      "name": "Rock_Slate"
    },
    {
      "x": -20,
      "y": 1,
      "z": 0,
      "name": "Rock_Slate"
    },
    {
      "x": -20,
      "y": 2,
      "z": 0,
      "name": "Rock_Slate"
    },
    {
      "x": -20,
      "y": 3,
      "z": 0,
      "name": "Rock_Slate"
    },
    {
      "x": -20,
      "y": 4,
      "z": 0,
      "name": "Rock_Slate"
    },
    {
      "x": -20,
      "y": 5,
      "z": 0,
      "name": "Rock_Slate"
    },
    {
      "x": -20,
      "y": 6,
      "z": 0,
      "name": "Rock_Slate"
    },
    {
      "x": -20,
      "y": 2,
      "z": 1,
      "name": "Rock_Slate"
    },
    {
      "x": -20,
      "y": 3,
      "z": 1,
      "name": "Rock_Slate"
    },
    {
      "x": -20,
      "y": 4,
      "z": 1,
      "name": "Rock_Slate"
    },
    {
      "x": -20,
      "y": 5,
      "z": 1,
      "name": "Rock_Slate"
    },
    {
      "x": -20,
      "y": 6,
      "z": 1,
      "name": "Rock_Slate"
    },
    {
      "x": -20,
      "y": 2,
      "z": 2,
      "name": "Rock_Slate"
    },
    {
      "x": -20,
      "y": 4,
      "z": 2,
      "name": "Rock_Slate"
    },
    {
      "x": -20,
      "y": 5,
      "z": 2,
      "name": "Rock_Slate"
    },
    {
      "x": -20,
      "y": 6,
      "z": 2,
      "name": "Rock_Slate"
    },
    {
      "x": -20,
      "y": 3,
      "z": 3,
      "name": "Rock_Slate"
    },
    {
      "x": -20,
      "y": 4,
      "z": 3,
      "name": "Rock_Slate"
    },
    {
      "x": -20,
      "y": 5,
      "z": 3,
      "name": "Rock_Slate"
    },
    {
      "x": -20,
      "y": 6,
      "z": 3,
      "name": "Rock_Slate"
    },
    {
      "x": -20,
      "y": 2,
      "z": 4,
      "name": "Rock_Slate"
    },
    {
      "x": -20,
      "y": 3,
      "z": 4,
      "name": "Rock_Slate"
    },
    {
      "x": -20,
      "y": 4,
      "z": 4,
      "name": "Rock_Slate"
    },
    {
      "x": -20,
      "y": 5,
      "z": 4,
      "name": "Rock_Slate"
    },
    {
      "x": -20,
      "y": 6,
      "z": 4,
      "name": "Rock_Slate"
    },
    {
      "x": -20,
      "y": 2,
      "z": 5,
      "name": "Rock_Slate"
    },
    {
      "x": -20,
      "y": 3,
      "z": 5,
      "name": "Rock_Slate"
    },
    {
      "x": -20,
      "y": 4,
      "z": 5,
      "name": "Rock_Slate"
    },
    {
      "x": -20,
      "y": 5,
      "z": 5,
      "name": "Rock_Slate"
    },
    {
      "x": -20,
      "y": 6,
      "z": 5,
      "name": "Rock_Slate"
    },
    {
      "x": -20,
      "y": 3,
      "z": 6,
      "name": "Rock_Slate"
    },
    {
      "x": -20,
      "y": 4,
      "z": 6,
      "name": "Rock_Slate"
    },
    {
      "x": -20,
      "y": 5,
      "z": 6,
      "name": "Rock_Slate"
    },
    {
      "x": -20,
      "y": 6,
      "z": 6,
      "name": "Rock_Slate"
    },
    {
      "x": -20,
      "y": 3,
      "z": 7,
      "name": "Rock_Slate"
    },
    {
      "x": -20,
      "y": 4,
      "z": 7,
      "name": "Rock_Slate"
    },
    {
      "x": -20,
      "y": 5,
      "z": 7,
      "name": "Rock_Slate"
    },
    {
      "x": -20,
      "y": 6,
      "z": 7,
      "name": "Rock_Slate"
    },
    {
      "x": -20,
      "y": 2,
      "z": 8,
      "name": "Rock_Slate"
    },
    {
      "x": -20,
      "y": 3,
      "z": 8,
      "name": "Rock_Slate"
    },
    {
      "x": -20,
      "y": 4,
      "z": 8,
      "name": "Rock_Slate"
    },
    {
      "x": -20,
      "y": 5,
      "z": 8,
      "name": "Rock_Slate"
    },
    {
      "x": -20,
      "y": 6,
      "z": 8,
      "name": "Rock_Slate"
    },
    {
      "x": -20,
      "y": 3,
      "z": 9,
      "name": "Rock_Slate"
    },
    {
      "x": -20,
      "y": 4,
      "z": 9,
      "name": "Rock_Slate"
    },
    {
      "x": -20,
      "y": 5,
      "z": 9,
      "name": "Rock_Slate"
    },
    {
      "x": -20,
      "y": 6,
      "z": 9,
      "name": "Rock_Slate"
    },
    {
      "x": -20,
      "y": 3,
      "z": 10,
      "name": "Rock_Slate"
    },
    {
      "x": -20,
      "y": 4,
      "z": 10,
      "name": "Rock_Slate"
    },
    {
      "x": -20,
      "y": 5,
      "z": 10,
      "name": "Rock_Slate"
    },
    {
      "x": -20,
      "y": 6,
      "z": 10,
      "name": "Rock_Slate"
    },
    {
      "x": -20,
      "y": 2,
      "z": 11,
      "name": "Rock_Slate"
    },
    {
      "x": -20,
      "y": 3,
      "z": 11,
      "name": "Rock_Slate"
    },
    {
      "x": -20,
      "y": 4,
      "z": 11,
      "name": "Rock_Slate"
    },
    {
      "x": -20,
      "y": 5,
      "z": 11,
      "name": "Rock_Slate"
    },
    {
      "x": -20,
      "y": 6,
      "z": 11,
      "name": "Rock_Slate"
    },
    {
      "x": -20,
      "y": 2,
      "z": 12,
      "name": "Rock_Slate"
    },
    {
      "x": -20,
      "y": 3,
      "z": 12,
      "name": "Rock_Slate"
    },
    {
      "x": -20,
      "y": 4,
      "z": 12,
      "name": "Rock_Slate"
    },
    {
      "x": -20,
      "y": 5,
      "z": 12,
      "name": "Rock_Slate"
    },
    {
      "x": -20,
      "y": 6,
      "z": 12,
      "name": "Rock_Slate"
    },
    {
      "x": -20,
      "y": 3,
      "z": 13,
      "name": "Rock_Slate"
    },
    {
      "x": -20,
      "y": 4,
      "z": 13,
      "name": "Rock_Slate"
    },
    {
      "x": -20,
      "y": 5,
      "z": 13,
      "name": "Rock_Slate"
    },
    {
      "x": -20,
      "y": 2,
      "z": 14,
      "name": "Rock_Slate"
    },
    {
      "x": -20,
      "y": 3,
      "z": 14,
      "name": "Rock_Slate"
    },
    {
      "x": -20,
      "y": 4,
      "z": 14,
      "name": "Rock_Slate"
    },
    {
      "x": -20,
      "y": 5,
      "z": 14,
      "name": "Rock_Slate"
    },
    {
      "x": -20,
      "y": 6,
      "z": 14,
      "name": "Rock_Slate"
    },
    {
      "x": -20,
      "y": 1,
      "z": 15,
      "name": "Rock_Slate"
    },
    {
      "x": -20,
      "y": 3,
      "z": 15,
      "name": "Rock_Slate"
    },
    {
      "x": -20,
      "y": 4,
      "z": 15,
      "name": "Rock_Slate"
    },
    {
      "x": -20,
      "y": 5,
      "z": 15,
      "name": "Rock_Slate"
    },
    {
      "x": -20,
      "y": 6,
      "z": 15,
      "name": "Rock_Slate"
    },
    {
      "x": -20,
      "y": 1,
      "z": 16,
      "name": "Rock_Slate"
    },
    {
      "x": -20,
      "y": 2,
      "z": 16,
      "name": "Rock_Slate"
    },
    {
      "x": -20,
      "y": 3,
      "z": 16,
      "name": "Rock_Slate"
    },
    {
      "x": -20,
      "y": 4,
      "z": 16,
      "name": "Rock_Slate"
    },
    {
      "x": -20,
      "y": 5,
      "z": 16,
      "name": "Rock_Slate"
    },
    {
      "x": -20,
      "y": 6,
      "z": 16,
      "name": "Rock_Slate"
    },
    {
      "x": -20,
      "y": 2,
      "z": 17,
      "name": "Rock_Slate"
    },
    {
      "x": -20,
      "y": 3,
      "z": 17,
      "name": "Rock_Slate"
    },
    {
      "x": -20,
      "y": 4,
      "z": 17,
      "name": "Rock_Slate"
    },
    {
      "x": -20,
      "y": 5,
      "z": 17,
      "name": "Rock_Slate"
    },
    {
      "x": -20,
      "y": 2,
      "z": 18,
      "name": "Rock_Slate"
    },
    {
      "x": -20,
      "y": 3,
      "z": 18,
      "name": "Rock_Slate"
    },
    {
      "x": -20,
      "y": 4,
      "z": 18,
      "name": "Rock_Slate"
    },
    {
      "x": -20,
      "y": 5,
      "z": 18,
      "name": "Rock_Slate"
    },
    {
      "x": -20,
      "y": 6,
      "z": 18,
      "name": "Rock_Slate"
    },
    {
      "x": -20,
      "y": 3,
      "z": 19,
      "name": "Rock_Slate"
    },
    {
      "x": -20,
      "y": 4,
      "z": 19,
      "name": "Rock_Slate"
    },
    {
      "x": -20,
      "y": 5,
      "z": 19,
      "name": "Rock_Slate"
    },
    {
      "x": -20,
      "y": 4,
      "z": 20,
      "name": "Rock_Slate"
    },
    {
      "x": -20,
      "y": 5,
      "z": 20,
      "name": "Rock_Slate"
    },
    {
      "x": -19,
      "y": 4,
      "z": -22,
      "name": "Rock_Slate"
    },
    {
      "x": -19,
      "y": 5,
      "z": -22,
      "name": "Rock_Slate"
    },
    {
      "x": -19,
      "y": 2,
      "z": -21,
      "name": "Rock_Slate"
    },
    {
      "x": -19,
      "y": 3,
      "z": -21,
      "name": "Rock_Slate"
    },
    {
      "x": -19,
      "y": 4,
      "z": -21,
      "name": "Rock_Slate"
    },
    {
      "x": -19,
      "y": 5,
      "z": -21,
      "name": "Rock_Slate"
    },
    {
      "x": -19,
      "y": 2,
      "z": -20,
      "name": "Rock_Slate"
    },
    {
      "x": -19,
      "y": 3,
      "z": -20,
      "name": "Rock_Slate"
    },
    {
      "x": -19,
      "y": 4,
      "z": -20,
      "name": "Rock_Slate"
    },
    {
      "x": -19,
      "y": 5,
      "z": -20,
      "name": "Rock_Slate"
    },
    {
      "x": -19,
      "y": 6,
      "z": -20,
      "name": "Rock_Slate"
    },
    {
      "x": -19,
      "y": 2,
      "z": -19,
      "name": "Rock_Slate"
    },
    {
      "x": -19,
      "y": 3,
      "z": -19,
      "name": "Rock_Slate"
    },
    {
      "x": -19,
      "y": 4,
      "z": -19,
      "name": "Rock_Slate"
    },
    {
      "x": -19,
      "y": 5,
      "z": -19,
      "name": "Rock_Slate"
    },
    {
      "x": -19,
      "y": 6,
      "z": -19,
      "name": "Rock_Slate"
    },
    {
      "x": -19,
      "y": 3,
      "z": -18,
      "name": "Rock_Slate"
    },
    {
      "x": -19,
      "y": 4,
      "z": -18,
      "name": "Rock_Slate"
    },
    {
      "x": -19,
      "y": 5,
      "z": -18,
      "name": "Rock_Slate"
    },
    {
      "x": -19,
      "y": 6,
      "z": -18,
      "name": "Rock_Slate"
    },
    {
      "x": -19,
      "y": 3,
      "z": -17,
      "name": "Rock_Slate"
    },
    {
      "x": -19,
      "y": 4,
      "z": -17,
      "name": "Rock_Slate"
    },
    {
      "x": -19,
      "y": 5,
      "z": -17,
      "name": "Rock_Slate"
    },
    {
      "x": -19,
      "y": 6,
      "z": -17,
      "name": "Rock_Slate"
    },
    {
      "x": -19,
      "y": 4,
      "z": -16,
      "name": "Rock_Slate"
    },
    {
      "x": -19,
      "y": 5,
      "z": -16,
      "name": "Rock_Slate"
    },
    {
      "x": -19,
      "y": 4,
      "z": -15,
      "name": "Rock_Slate"
    },
    {
      "x": -19,
      "y": 5,
      "z": -15,
      "name": "Rock_Slate"
    },
    {
      "x": -19,
      "y": 6,
      "z": -15,
      "name": "Rock_Slate"
    },
    {
      "x": -19,
      "y": 3,
      "z": -14,
      "name": "Rock_Slate"
    },
    {
      "x": -19,
      "y": 4,
      "z": -14,
      "name": "Rock_Slate"
    },
    {
      "x": -19,
      "y": 5,
      "z": -14,
      "name": "Rock_Slate"
    },
    {
      "x": -19,
      "y": 6,
      "z": -14,
      "name": "Rock_Slate"
    },
    {
      "x": -19,
      "y": 0,
      "z": -13,
      "name": "Rock_Slate"
    },
    {
      "x": -19,
      "y": 1,
      "z": -13,
      "name": "Rock_Slate"
    },
    {
      "x": -19,
      "y": 2,
      "z": -13,
      "name": "Rock_Slate"
    },
    {
      "x": -19,
      "y": 3,
      "z": -13,
      "name": "Rock_Slate"
    },
    {
      "x": -19,
      "y": 4,
      "z": -13,
      "name": "Rock_Slate"
    },
    {
      "x": -19,
      "y": 5,
      "z": -13,
      "name": "Rock_Slate"
    },
    {
      "x": -19,
      "y": 6,
      "z": -13,
      "name": "Rock_Slate"
    },
    {
      "x": -19,
      "y": 3,
      "z": -12,
      "name": "Rock_Slate"
    },
    {
      "x": -19,
      "y": 4,
      "z": -12,
      "name": "Rock_Slate"
    },
    {
      "x": -19,
      "y": 5,
      "z": -12,
      "name": "Rock_Slate"
    },
    {
      "x": -19,
      "y": 6,
      "z": -12,
      "name": "Rock_Slate"
    },
    {
      "x": -19,
      "y": 2,
      "z": -11,
      "name": "Rock_Slate"
    },
    {
      "x": -19,
      "y": 3,
      "z": -11,
      "name": "Rock_Slate"
    },
    {
      "x": -19,
      "y": 4,
      "z": -11,
      "name": "Rock_Slate"
    },
    {
      "x": -19,
      "y": 5,
      "z": -11,
      "name": "Rock_Slate"
    },
    {
      "x": -19,
      "y": 6,
      "z": -11,
      "name": "Rock_Slate"
    },
    {
      "x": -19,
      "y": 3,
      "z": -10,
      "name": "Rock_Slate"
    },
    {
      "x": -19,
      "y": 4,
      "z": -10,
      "name": "Rock_Slate"
    },
    {
      "x": -19,
      "y": 5,
      "z": -10,
      "name": "Rock_Slate"
    },
    {
      "x": -19,
      "y": 6,
      "z": -10,
      "name": "Rock_Slate"
    },
    {
      "x": -19,
      "y": 2,
      "z": -9,
      "name": "Rock_Slate"
    },
    {
      "x": -19,
      "y": 3,
      "z": -9,
      "name": "Rock_Slate"
    },
    {
      "x": -19,
      "y": 4,
      "z": -9,
      "name": "Rock_Slate"
    },
    {
      "x": -19,
      "y": 5,
      "z": -9,
      "name": "Rock_Slate"
    },
    {
      "x": -19,
      "y": 6,
      "z": -9,
      "name": "Rock_Slate"
    },
    {
      "x": -19,
      "y": 2,
      "z": -8,
      "name": "Rock_Slate"
    },
    {
      "x": -19,
      "y": 3,
      "z": -8,
      "name": "Rock_Slate"
    },
    {
      "x": -19,
      "y": 4,
      "z": -8,
      "name": "Rock_Slate"
    },
    {
      "x": -19,
      "y": 5,
      "z": -8,
      "name": "Rock_Slate"
    },
    {
      "x": -19,
      "y": 6,
      "z": -8,
      "name": "Rock_Slate"
    },
    {
      "x": -19,
      "y": 7,
      "z": -8,
      "name": "Rock_Shale_Brick_Ornate"
    },
    {
      "x": -19,
      "y": 8,
      "z": -8,
      "name": "Rock_Shale_Brick_Ornate"
    },
    {
      "x": -19,
      "y": 9,
      "z": -8,
      "name": "Rock_Shale_Brick_Stairs",
      "rotation": 3
    },
    {
      "x": -19,
      "y": 19,
      "z": -8,
      "name": "Rock_Shale_Brick_Ornate"
    },
    {
      "x": -19,
      "y": 2,
      "z": -7,
      "name": "Rock_Slate"
    },
    {
      "x": -19,
      "y": 3,
      "z": -7,
      "name": "Rock_Slate"
    },
    {
      "x": -19,
      "y": 4,
      "z": -7,
      "name": "Rock_Slate"
    },
    {
      "x": -19,
      "y": 5,
      "z": -7,
      "name": "Rock_Slate"
    },
    {
      "x": -19,
      "y": 6,
      "z": -7,
      "name": "Rock_Slate"
    },
    {
      "x": -19,
      "y": 7,
      "z": -7,
      "name": "Rock_Shale_Brick_Ornate"
    },
    {
      "x": -19,
      "y": 8,
      "z": -7,
      "name": "Rock_Shale_Brick_Ornate"
    },
    {
      "x": -19,
      "y": 9,
      "z": -7,
      "name": "Rock_Shale_Brick"
    },
    {
      "x": -19,
      "y": 10,
      "z": -7,
      "name": "Rock_Shale_Brick"
    },
    {
      "x": -19,
      "y": 11,
      "z": -7,
      "name": "Rock_Shale_Brick"
    },
    {
      "x": -19,
      "y": 12,
      "z": -7,
      "name": "Rock_Shale_Brick"
    },
    {
      "x": -19,
      "y": 13,
      "z": -7,
      "name": "Rock_Shale_Brick"
    },
    {
      "x": -19,
      "y": 14,
      "z": -7,
      "name": "Rock_Shale_Brick"
    },
    {
      "x": -19,
      "y": 15,
      "z": -7,
      "name": "Rock_Shale_Brick"
    },
    {
      "x": -19,
      "y": 16,
      "z": -7,
      "name": "Rock_Shale_Brick"
    },
    {
      "x": -19,
      "y": 17,
      "z": -7,
      "name": "Rock_Shale_Brick"
    },
    {
      "x": -19,
      "y": 18,
      "z": -7,
      "name": "Rock_Shale_Brick"
    },
    {
      "x": -19,
      "y": 19,
      "z": -7,
      "name": "Rock_Shale_Brick_Ornate"
    },
    {
      "x": -19,
      "y": 20,
      "z": -7,
      "name": "Rock_Shale_Brick_Ornate"
    },
    {
      "x": -19,
      "y": 2,
      "z": -6,
      "name": "Rock_Slate"
    },
    {
      "x": -19,
      "y": 3,
      "z": -6,
      "name": "Rock_Slate"
    },
    {
      "x": -19,
      "y": 4,
      "z": -6,
      "name": "Rock_Slate"
    },
    {
      "x": -19,
      "y": 5,
      "z": -6,
      "name": "Rock_Slate"
    },
    {
      "x": -19,
      "y": 6,
      "z": -6,
      "name": "Rock_Slate"
    },
    {
      "x": -19,
      "y": 7,
      "z": -6,
      "name": "Rock_Shale_Brick_Ornate"
    },
    {
      "x": -19,
      "y": 8,
      "z": -6,
      "name": "Rock_Shale_Brick_Ornate"
    },
    {
      "x": -19,
      "y": 9,
      "z": -6,
      "name": "Rock_Shale_Brick"
    },
    {
      "x": -19,
      "y": 10,
      "z": -6,
      "name": "Rock_Shale_Brick"
    },
    {
      "x": -19,
      "y": 16,
      "z": -6,
      "name": "Rock_Shale_Brick"
    },
    {
      "x": -19,
      "y": 17,
      "z": -6,
      "name": "Rock_Shale_Brick"
    },
    {
      "x": -19,
      "y": 18,
      "z": -6,
      "name": "Rock_Shale_Brick"
    },
    {
      "x": -19,
      "y": 19,
      "z": -6,
      "name": "Rock_Shale_Brick_Ornate"
    },
    {
      "x": -19,
      "y": 20,
      "z": -6,
      "name": "Rock_Shale_Brick_Ornate"
    },
    {
      "x": -19,
      "y": 2,
      "z": -5,
      "name": "Rock_Slate"
    },
    {
      "x": -19,
      "y": 3,
      "z": -5,
      "name": "Rock_Slate"
    },
    {
      "x": -19,
      "y": 4,
      "z": -5,
      "name": "Rock_Slate"
    },
    {
      "x": -19,
      "y": 5,
      "z": -5,
      "name": "Rock_Slate"
    },
    {
      "x": -19,
      "y": 6,
      "z": -5,
      "name": "Rock_Slate"
    },
    {
      "x": -19,
      "y": 7,
      "z": -5,
      "name": "Rock_Shale_Brick_Ornate"
    },
    {
      "x": -19,
      "y": 19,
      "z": -5,
      "name": "Rock_Shale_Brick_Ornate"
    },
    {
      "x": -19,
      "y": 20,
      "z": -5,
      "name": "Rock_Shale_Brick_Ornate"
    },
    {
      "x": -19,
      "y": 2,
      "z": -4,
      "name": "Rock_Slate"
    },
    {
      "x": -19,
      "y": 3,
      "z": -4,
      "name": "Rock_Slate"
    },
    {
      "x": -19,
      "y": 4,
      "z": -4,
      "name": "Rock_Slate"
    },
    {
      "x": -19,
      "y": 5,
      "z": -4,
      "name": "Rock_Slate"
    },
    {
      "x": -19,
      "y": 6,
      "z": -4,
      "name": "Rock_Slate"
    },
    {
      "x": -19,
      "y": 2,
      "z": -3,
      "name": "Rock_Slate"
    },
    {
      "x": -19,
      "y": 3,
      "z": -3,
      "name": "Rock_Slate"
    },
    {
      "x": -19,
      "y": 4,
      "z": -3,
      "name": "Rock_Slate"
    },
    {
      "x": -19,
      "y": 5,
      "z": -3,
      "name": "Rock_Slate"
    },
    {
      "x": -19,
      "y": 6,
      "z": -3,
      "name": "Rock_Slate"
    },
    {
      "x": -19,
      "y": 3,
      "z": -2,
      "name": "Rock_Slate"
    },
    {
      "x": -19,
      "y": 4,
      "z": -2,
      "name": "Rock_Slate"
    },
    {
      "x": -19,
      "y": 5,
      "z": -2,
      "name": "Rock_Slate"
    },
    {
      "x": -19,
      "y": 6,
      "z": -2,
      "name": "Rock_Slate"
    },
    {
      "x": -19,
      "y": 2,
      "z": -1,
      "name": "Rock_Slate"
    },
    {
      "x": -19,
      "y": 3,
      "z": -1,
      "name": "Rock_Slate"
    },
    {
      "x": -19,
      "y": 4,
      "z": -1,
      "name": "Rock_Slate"
    },
    {
      "x": -19,
      "y": 5,
      "z": -1,
      "name": "Rock_Slate"
    },
    {
      "x": -19,
      "y": 6,
      "z": -1,
      "name": "Rock_Slate"
    },
    {
      "x": -19,
      "y": 3,
      "z": 0,
      "name": "Rock_Slate"
    },
    {
      "x": -19,
      "y": 4,
      "z": 0,
      "name": "Rock_Slate"
    },
    {
      "x": -19,
      "y": 5,
      "z": 0,
      "name": "Rock_Slate"
    },
    {
      "x": -19,
      "y": 6,
      "z": 0,
      "name": "Rock_Slate"
    },
    {
      "x": -19,
      "y": 2,
      "z": 1,
      "name": "Rock_Slate"
    },
    {
      "x": -19,
      "y": 3,
      "z": 1,
      "name": "Rock_Slate"
    },
    {
      "x": -19,
      "y": 4,
      "z": 1,
      "name": "Rock_Slate"
    },
    {
      "x": -19,
      "y": 5,
      "z": 1,
      "name": "Rock_Slate"
    },
    {
      "x": -19,
      "y": 6,
      "z": 1,
      "name": "Rock_Slate"
    },
    {
      "x": -19,
      "y": 4,
      "z": 2,
      "name": "Rock_Slate"
    },
    {
      "x": -19,
      "y": 5,
      "z": 2,
      "name": "Rock_Slate"
    },
    {
      "x": -19,
      "y": 6,
      "z": 2,
      "name": "Rock_Slate"
    },
    {
      "x": -19,
      "y": 4,
      "z": 3,
      "name": "Rock_Slate"
    },
    {
      "x": -19,
      "y": 5,
      "z": 3,
      "name": "Rock_Slate"
    },
    {
      "x": -19,
      "y": 6,
      "z": 3,
      "name": "Rock_Slate"
    },
    {
      "x": -19,
      "y": 3,
      "z": 4,
      "name": "Rock_Slate"
    },
    {
      "x": -19,
      "y": 4,
      "z": 4,
      "name": "Rock_Slate"
    },
    {
      "x": -19,
      "y": 5,
      "z": 4,
      "name": "Rock_Slate"
    },
    {
      "x": -19,
      "y": 6,
      "z": 4,
      "name": "Rock_Slate"
    },
    {
      "x": -19,
      "y": 3,
      "z": 5,
      "name": "Rock_Slate"
    },
    {
      "x": -19,
      "y": 4,
      "z": 5,
      "name": "Rock_Slate"
    },
    {
      "x": -19,
      "y": 5,
      "z": 5,
      "name": "Rock_Slate"
    },
    {
      "x": -19,
      "y": 6,
      "z": 5,
      "name": "Rock_Slate"
    },
    {
      "x": -19,
      "y": 7,
      "z": 5,
      "name": "Rock_Shale_Brick_Ornate"
    },
    {
      "x": -19,
      "y": 8,
      "z": 5,
      "name": "Rock_Shale_Brick_Ornate"
    },
    {
      "x": -19,
      "y": 19,
      "z": 5,
      "name": "Rock_Shale_Brick_Ornate"
    },
    {
      "x": -19,
      "y": 2,
      "z": 6,
      "name": "Rock_Slate"
    },
    {
      "x": -19,
      "y": 3,
      "z": 6,
      "name": "Rock_Slate"
    },
    {
      "x": -19,
      "y": 4,
      "z": 6,
      "name": "Rock_Slate"
    },
    {
      "x": -19,
      "y": 5,
      "z": 6,
      "name": "Rock_Slate"
    },
    {
      "x": -19,
      "y": 6,
      "z": 6,
      "name": "Rock_Slate"
    },
    {
      "x": -19,
      "y": 7,
      "z": 6,
      "name": "Rock_Shale_Brick_Ornate"
    },
    {
      "x": -19,
      "y": 8,
      "z": 6,
      "name": "Rock_Shale_Brick_Ornate"
    },
    {
      "x": -19,
      "y": 9,
      "z": 6,
      "name": "Rock_Shale_Brick"
    },
    {
      "x": -19,
      "y": 10,
      "z": 6,
      "name": "Rock_Shale_Brick"
    },
    {
      "x": -19,
      "y": 11,
      "z": 6,
      "name": "Rock_Shale_Brick"
    },
    {
      "x": -19,
      "y": 12,
      "z": 6,
      "name": "Rock_Shale_Brick"
    },
    {
      "x": -19,
      "y": 13,
      "z": 6,
      "name": "Rock_Shale_Brick"
    },
    {
      "x": -19,
      "y": 14,
      "z": 6,
      "name": "Rock_Shale_Brick"
    },
    {
      "x": -19,
      "y": 15,
      "z": 6,
      "name": "Rock_Shale_Brick"
    },
    {
      "x": -19,
      "y": 16,
      "z": 6,
      "name": "Rock_Shale_Brick"
    },
    {
      "x": -19,
      "y": 17,
      "z": 6,
      "name": "Rock_Shale_Brick"
    },
    {
      "x": -19,
      "y": 18,
      "z": 6,
      "name": "Rock_Shale_Brick"
    },
    {
      "x": -19,
      "y": 19,
      "z": 6,
      "name": "Rock_Shale_Brick_Ornate"
    },
    {
      "x": -19,
      "y": 20,
      "z": 6,
      "name": "Rock_Shale_Brick_Ornate"
    },
    {
      "x": -19,
      "y": 3,
      "z": 7,
      "name": "Rock_Slate"
    },
    {
      "x": -19,
      "y": 4,
      "z": 7,
      "name": "Rock_Slate"
    },
    {
      "x": -19,
      "y": 5,
      "z": 7,
      "name": "Rock_Slate"
    },
    {
      "x": -19,
      "y": 6,
      "z": 7,
      "name": "Rock_Slate"
    },
    {
      "x": -19,
      "y": 7,
      "z": 7,
      "name": "Rock_Shale_Brick_Ornate"
    },
    {
      "x": -19,
      "y": 8,
      "z": 7,
      "name": "Rock_Shale_Brick_Ornate"
    },
    {
      "x": -19,
      "y": 9,
      "z": 7,
      "name": "Rock_Shale_Brick"
    },
    {
      "x": -19,
      "y": 10,
      "z": 7,
      "name": "Rock_Shale_Brick"
    },
    {
      "x": -19,
      "y": 16,
      "z": 7,
      "name": "Rock_Shale_Brick"
    },
    {
      "x": -19,
      "y": 17,
      "z": 7,
      "name": "Rock_Shale_Brick"
    },
    {
      "x": -19,
      "y": 18,
      "z": 7,
      "name": "Rock_Shale_Brick"
    },
    {
      "x": -19,
      "y": 19,
      "z": 7,
      "name": "Rock_Shale_Brick_Ornate"
    },
    {
      "x": -19,
      "y": 20,
      "z": 7,
      "name": "Rock_Shale_Brick_Ornate"
    },
    {
      "x": -19,
      "y": 2,
      "z": 8,
      "name": "Rock_Slate"
    },
    {
      "x": -19,
      "y": 3,
      "z": 8,
      "name": "Rock_Slate"
    },
    {
      "x": -19,
      "y": 4,
      "z": 8,
      "name": "Rock_Slate"
    },
    {
      "x": -19,
      "y": 5,
      "z": 8,
      "name": "Rock_Slate"
    },
    {
      "x": -19,
      "y": 6,
      "z": 8,
      "name": "Rock_Slate"
    },
    {
      "x": -19,
      "y": 7,
      "z": 8,
      "name": "Rock_Shale_Brick_Ornate"
    },
    {
      "x": -19,
      "y": 19,
      "z": 8,
      "name": "Rock_Shale_Brick_Ornate"
    },
    {
      "x": -19,
      "y": 20,
      "z": 8,
      "name": "Rock_Shale_Brick_Ornate"
    },
    {
      "x": -19,
      "y": 3,
      "z": 9,
      "name": "Rock_Slate"
    },
    {
      "x": -19,
      "y": 4,
      "z": 9,
      "name": "Rock_Slate"
    },
    {
      "x": -19,
      "y": 5,
      "z": 9,
      "name": "Rock_Slate"
    },
    {
      "x": -19,
      "y": 6,
      "z": 9,
      "name": "Rock_Slate"
    },
    {
      "x": -19,
      "y": 2,
      "z": 10,
      "name": "Rock_Slate"
    },
    {
      "x": -19,
      "y": 3,
      "z": 10,
      "name": "Rock_Slate"
    },
    {
      "x": -19,
      "y": 4,
      "z": 10,
      "name": "Rock_Slate"
    },
    {
      "x": -19,
      "y": 5,
      "z": 10,
      "name": "Rock_Slate"
    },
    {
      "x": -19,
      "y": 6,
      "z": 10,
      "name": "Rock_Slate"
    },
    {
      "x": -19,
      "y": 3,
      "z": 11,
      "name": "Rock_Slate"
    },
    {
      "x": -19,
      "y": 4,
      "z": 11,
      "name": "Rock_Slate"
    },
    {
      "x": -19,
      "y": 5,
      "z": 11,
      "name": "Rock_Slate"
    },
    {
      "x": -19,
      "y": 6,
      "z": 11,
      "name": "Rock_Slate"
    },
    {
      "x": -19,
      "y": 3,
      "z": 12,
      "name": "Rock_Slate"
    },
    {
      "x": -19,
      "y": 4,
      "z": 12,
      "name": "Rock_Slate"
    },
    {
      "x": -19,
      "y": 5,
      "z": 12,
      "name": "Rock_Slate"
    },
    {
      "x": -19,
      "y": 6,
      "z": 12,
      "name": "Rock_Slate"
    },
    {
      "x": -19,
      "y": 2,
      "z": 13,
      "name": "Rock_Slate"
    },
    {
      "x": -19,
      "y": 3,
      "z": 13,
      "name": "Rock_Slate"
    },
    {
      "x": -19,
      "y": 4,
      "z": 13,
      "name": "Rock_Slate"
    },
    {
      "x": -19,
      "y": 5,
      "z": 13,
      "name": "Rock_Slate"
    },
    {
      "x": -19,
      "y": 6,
      "z": 13,
      "name": "Rock_Slate"
    },
    {
      "x": -19,
      "y": 2,
      "z": 14,
      "name": "Rock_Slate"
    },
    {
      "x": -19,
      "y": 3,
      "z": 14,
      "name": "Rock_Slate"
    },
    {
      "x": -19,
      "y": 4,
      "z": 14,
      "name": "Rock_Slate"
    },
    {
      "x": -19,
      "y": 5,
      "z": 14,
      "name": "Rock_Slate"
    },
    {
      "x": -19,
      "y": 6,
      "z": 14,
      "name": "Rock_Slate"
    },
    {
      "x": -19,
      "y": 2,
      "z": 15,
      "name": "Rock_Slate"
    },
    {
      "x": -19,
      "y": 3,
      "z": 15,
      "name": "Rock_Slate"
    },
    {
      "x": -19,
      "y": 4,
      "z": 15,
      "name": "Rock_Slate"
    },
    {
      "x": -19,
      "y": 5,
      "z": 15,
      "name": "Rock_Slate"
    },
    {
      "x": -19,
      "y": 6,
      "z": 15,
      "name": "Rock_Slate"
    },
    {
      "x": -19,
      "y": 2,
      "z": 16,
      "name": "Rock_Slate"
    },
    {
      "x": -19,
      "y": 3,
      "z": 16,
      "name": "Rock_Slate"
    },
    {
      "x": -19,
      "y": 4,
      "z": 16,
      "name": "Rock_Slate"
    },
    {
      "x": -19,
      "y": 5,
      "z": 16,
      "name": "Rock_Slate"
    },
    {
      "x": -19,
      "y": 6,
      "z": 16,
      "name": "Rock_Slate"
    },
    {
      "x": -19,
      "y": 3,
      "z": 17,
      "name": "Rock_Slate"
    },
    {
      "x": -19,
      "y": 4,
      "z": 17,
      "name": "Rock_Slate"
    },
    {
      "x": -19,
      "y": 5,
      "z": 17,
      "name": "Rock_Slate"
    },
    {
      "x": -19,
      "y": 6,
      "z": 17,
      "name": "Rock_Slate"
    },
    {
      "x": -19,
      "y": 1,
      "z": 18,
      "name": "Rock_Slate"
    },
    {
      "x": -19,
      "y": 2,
      "z": 18,
      "name": "Rock_Slate"
    },
    {
      "x": -19,
      "y": 3,
      "z": 18,
      "name": "Rock_Slate"
    },
    {
      "x": -19,
      "y": 4,
      "z": 18,
      "name": "Rock_Slate"
    },
    {
      "x": -19,
      "y": 5,
      "z": 18,
      "name": "Rock_Slate"
    },
    {
      "x": -19,
      "y": 6,
      "z": 18,
      "name": "Rock_Slate"
    },
    {
      "x": -19,
      "y": 2,
      "z": 19,
      "name": "Rock_Slate"
    },
    {
      "x": -19,
      "y": 3,
      "z": 19,
      "name": "Rock_Slate"
    },
    {
      "x": -19,
      "y": 4,
      "z": 19,
      "name": "Rock_Slate"
    },
    {
      "x": -19,
      "y": 5,
      "z": 19,
      "name": "Rock_Slate"
    },
    {
      "x": -19,
      "y": 6,
      "z": 19,
      "name": "Rock_Slate"
    },
    {
      "x": -19,
      "y": 3,
      "z": 20,
      "name": "Rock_Slate"
    },
    {
      "x": -19,
      "y": 4,
      "z": 20,
      "name": "Rock_Slate"
    },
    {
      "x": -18,
      "y": 3,
      "z": -22,
      "name": "Rock_Slate"
    },
    {
      "x": -18,
      "y": 2,
      "z": -21,
      "name": "Rock_Slate"
    },
    {
      "x": -18,
      "y": 3,
      "z": -21,
      "name": "Rock_Slate"
    },
    {
      "x": -18,
      "y": 4,
      "z": -21,
      "name": "Rock_Slate"
    },
    {
      "x": -18,
      "y": 5,
      "z": -21,
      "name": "Rock_Slate"
    },
    {
      "x": -18,
      "y": 2,
      "z": -20,
      "name": "Rock_Slate"
    },
    {
      "x": -18,
      "y": 3,
      "z": -20,
      "name": "Rock_Slate"
    },
    {
      "x": -18,
      "y": 4,
      "z": -20,
      "name": "Rock_Slate"
    },
    {
      "x": -18,
      "y": 5,
      "z": -20,
      "name": "Rock_Slate"
    },
    {
      "x": -18,
      "y": 6,
      "z": -20,
      "name": "Rock_Slate"
    },
    {
      "x": -18,
      "y": 2,
      "z": -19,
      "name": "Rock_Slate"
    },
    {
      "x": -18,
      "y": 3,
      "z": -19,
      "name": "Rock_Slate"
    },
    {
      "x": -18,
      "y": 4,
      "z": -19,
      "name": "Rock_Slate"
    },
    {
      "x": -18,
      "y": 5,
      "z": -19,
      "name": "Rock_Slate"
    },
    {
      "x": -18,
      "y": 2,
      "z": -18,
      "name": "Rock_Slate"
    },
    {
      "x": -18,
      "y": 3,
      "z": -18,
      "name": "Rock_Slate"
    },
    {
      "x": -18,
      "y": 4,
      "z": -18,
      "name": "Rock_Slate"
    },
    {
      "x": -18,
      "y": 5,
      "z": -18,
      "name": "Rock_Slate"
    },
    {
      "x": -18,
      "y": 6,
      "z": -18,
      "name": "Rock_Slate"
    },
    {
      "x": -18,
      "y": 3,
      "z": -17,
      "name": "Rock_Slate"
    },
    {
      "x": -18,
      "y": 4,
      "z": -17,
      "name": "Rock_Slate"
    },
    {
      "x": -18,
      "y": 5,
      "z": -17,
      "name": "Rock_Slate"
    },
    {
      "x": -18,
      "y": 6,
      "z": -17,
      "name": "Rock_Slate"
    },
    {
      "x": -18,
      "y": 3,
      "z": -16,
      "name": "Rock_Slate"
    },
    {
      "x": -18,
      "y": 4,
      "z": -16,
      "name": "Rock_Slate"
    },
    {
      "x": -18,
      "y": 5,
      "z": -16,
      "name": "Rock_Slate"
    },
    {
      "x": -18,
      "y": 6,
      "z": -16,
      "name": "Rock_Slate"
    },
    {
      "x": -18,
      "y": 2,
      "z": -15,
      "name": "Rock_Slate"
    },
    {
      "x": -18,
      "y": 3,
      "z": -15,
      "name": "Rock_Slate"
    },
    {
      "x": -18,
      "y": 4,
      "z": -15,
      "name": "Rock_Slate"
    },
    {
      "x": -18,
      "y": 5,
      "z": -15,
      "name": "Rock_Slate"
    },
    {
      "x": -18,
      "y": 6,
      "z": -15,
      "name": "Rock_Slate"
    },
    {
      "x": -18,
      "y": 3,
      "z": -14,
      "name": "Rock_Slate"
    },
    {
      "x": -18,
      "y": 4,
      "z": -14,
      "name": "Rock_Slate"
    },
    {
      "x": -18,
      "y": 5,
      "z": -14,
      "name": "Rock_Slate"
    },
    {
      "x": -18,
      "y": 6,
      "z": -14,
      "name": "Rock_Slate"
    },
    {
      "x": -18,
      "y": 3,
      "z": -13,
      "name": "Rock_Slate"
    },
    {
      "x": -18,
      "y": 4,
      "z": -13,
      "name": "Rock_Slate"
    },
    {
      "x": -18,
      "y": 5,
      "z": -13,
      "name": "Rock_Slate"
    },
    {
      "x": -18,
      "y": 6,
      "z": -13,
      "name": "Rock_Slate"
    },
    {
      "x": -18,
      "y": 2,
      "z": -12,
      "name": "Rock_Slate"
    },
    {
      "x": -18,
      "y": 3,
      "z": -12,
      "name": "Rock_Slate"
    },
    {
      "x": -18,
      "y": 4,
      "z": -12,
      "name": "Rock_Slate"
    },
    {
      "x": -18,
      "y": 5,
      "z": -12,
      "name": "Rock_Slate"
    },
    {
      "x": -18,
      "y": 6,
      "z": -12,
      "name": "Rock_Slate"
    },
    {
      "x": -18,
      "y": 2,
      "z": -11,
      "name": "Rock_Slate"
    },
    {
      "x": -18,
      "y": 3,
      "z": -11,
      "name": "Rock_Slate"
    },
    {
      "x": -18,
      "y": 4,
      "z": -11,
      "name": "Rock_Slate"
    },
    {
      "x": -18,
      "y": 5,
      "z": -11,
      "name": "Rock_Slate"
    },
    {
      "x": -18,
      "y": 6,
      "z": -11,
      "name": "Rock_Slate"
    },
    {
      "x": -18,
      "y": 2,
      "z": -10,
      "name": "Rock_Slate"
    },
    {
      "x": -18,
      "y": 3,
      "z": -10,
      "name": "Rock_Slate"
    },
    {
      "x": -18,
      "y": 4,
      "z": -10,
      "name": "Rock_Slate"
    },
    {
      "x": -18,
      "y": 5,
      "z": -10,
      "name": "Rock_Slate"
    },
    {
      "x": -18,
      "y": 6,
      "z": -10,
      "name": "Rock_Slate"
    },
    {
      "x": -18,
      "y": 3,
      "z": -9,
      "name": "Rock_Slate"
    },
    {
      "x": -18,
      "y": 4,
      "z": -9,
      "name": "Rock_Slate"
    },
    {
      "x": -18,
      "y": 5,
      "z": -9,
      "name": "Rock_Slate"
    },
    {
      "x": -18,
      "y": 6,
      "z": -9,
      "name": "Rock_Slate"
    },
    {
      "x": -18,
      "y": 2,
      "z": -8,
      "name": "Rock_Slate"
    },
    {
      "x": -18,
      "y": 3,
      "z": -8,
      "name": "Rock_Slate"
    },
    {
      "x": -18,
      "y": 4,
      "z": -8,
      "name": "Rock_Slate"
    },
    {
      "x": -18,
      "y": 5,
      "z": -8,
      "name": "Rock_Slate"
    },
    {
      "x": -18,
      "y": 6,
      "z": -8,
      "name": "Rock_Slate"
    },
    {
      "x": -18,
      "y": 7,
      "z": -8,
      "name": "Rock_Shale_Brick_Ornate"
    },
    {
      "x": -18,
      "y": 8,
      "z": -8,
      "name": "Rock_Shale_Brick_Ornate"
    },
    {
      "x": -18,
      "y": 9,
      "z": -8,
      "name": "Rock_Shale_Brick"
    },
    {
      "x": -18,
      "y": 10,
      "z": -8,
      "name": "Rock_Shale_Brick"
    },
    {
      "x": -18,
      "y": 11,
      "z": -8,
      "name": "Rock_Shale_Brick"
    },
    {
      "x": -18,
      "y": 12,
      "z": -8,
      "name": "Rock_Shale_Brick"
    },
    {
      "x": -18,
      "y": 17,
      "z": -8,
      "name": "Rock_Shale_Brick"
    },
    {
      "x": -18,
      "y": 18,
      "z": -8,
      "name": "Rock_Shale_Brick"
    },
    {
      "x": -18,
      "y": 19,
      "z": -8,
      "name": "Rock_Shale_Brick_Ornate"
    },
    {
      "x": -18,
      "y": 20,
      "z": -8,
      "name": "Rock_Shale_Brick_Ornate"
    },
    {
      "x": -18,
      "y": 3,
      "z": -7,
      "name": "Rock_Slate"
    },
    {
      "x": -18,
      "y": 4,
      "z": -7,
      "name": "Rock_Slate"
    },
    {
      "x": -18,
      "y": 5,
      "z": -7,
      "name": "Rock_Slate"
    },
    {
      "x": -18,
      "y": 6,
      "z": -7,
      "name": "Rock_Slate"
    },
    {
      "x": -18,
      "y": 7,
      "z": -7,
      "name": "Rock_Shale_Brick_Ornate"
    },
    {
      "x": -18,
      "y": 8,
      "z": -7,
      "name": "Rock_Shale_Brick"
    },
    {
      "x": -18,
      "y": 9,
      "z": -7,
      "name": "Rock_Shale_Brick"
    },
    {
      "x": -18,
      "y": 10,
      "z": -7,
      "name": "Rock_Shale_Brick"
    },
    {
      "x": -18,
      "y": 11,
      "z": -7,
      "name": "Rock_Shale_Brick"
    },
    {
      "x": -18,
      "y": 12,
      "z": -7,
      "name": "Rock_Shale_Brick"
    },
    {
      "x": -18,
      "y": 13,
      "z": -7,
      "name": "Rock_Shale_Brick"
    },
    {
      "x": -18,
      "y": 14,
      "z": -7,
      "name": "Rock_Shale_Brick"
    },
    {
      "x": -18,
      "y": 15,
      "z": -7,
      "name": "Rock_Shale_Brick"
    },
    {
      "x": -18,
      "y": 16,
      "z": -7,
      "name": "Rock_Shale_Brick"
    },
    {
      "x": -18,
      "y": 17,
      "z": -7,
      "name": "Rock_Shale_Brick"
    },
    {
      "x": -18,
      "y": 18,
      "z": -7,
      "name": "Rock_Shale_Brick"
    },
    {
      "x": -18,
      "y": 19,
      "z": -7,
      "name": "Rock_Shale_Brick_Ornate"
    },
    {
      "x": -18,
      "y": 20,
      "z": -7,
      "name": "Rock_Shale_Brick_Ornate"
    },
    {
      "x": -18,
      "y": 2,
      "z": -6,
      "name": "Rock_Slate"
    },
    {
      "x": -18,
      "y": 3,
      "z": -6,
      "name": "Rock_Slate"
    },
    {
      "x": -18,
      "y": 4,
      "z": -6,
      "name": "Rock_Slate"
    },
    {
      "x": -18,
      "y": 5,
      "z": -6,
      "name": "Rock_Slate"
    },
    {
      "x": -18,
      "y": 6,
      "z": -6,
      "name": "Rock_Slate"
    },
    {
      "x": -18,
      "y": 7,
      "z": -6,
      "name": "Rock_Shale_Brick_Ornate"
    },
    {
      "x": -18,
      "y": 8,
      "z": -6,
      "name": "Rock_Shale_Brick"
    },
    {
      "x": -18,
      "y": 9,
      "z": -6,
      "name": "Rock_Shale_Brick"
    },
    {
      "x": -18,
      "y": 10,
      "z": -6,
      "name": "Rock_Shale_Brick"
    },
    {
      "x": -18,
      "y": 11,
      "z": -6,
      "name": "Rock_Shale_Brick"
    },
    {
      "x": -18,
      "y": 12,
      "z": -6,
      "name": "Rock_Shale_Brick"
    },
    {
      "x": -18,
      "y": 13,
      "z": -6,
      "name": "Rock_Shale_Brick"
    },
    {
      "x": -18,
      "y": 14,
      "z": -6,
      "name": "Rock_Shale_Brick"
    },
    {
      "x": -18,
      "y": 15,
      "z": -6,
      "name": "Rock_Shale_Brick"
    },
    {
      "x": -18,
      "y": 16,
      "z": -6,
      "name": "Rock_Shale_Brick"
    },
    {
      "x": -18,
      "y": 17,
      "z": -6,
      "name": "Rock_Shale_Brick"
    },
    {
      "x": -18,
      "y": 18,
      "z": -6,
      "name": "Rock_Shale_Brick"
    },
    {
      "x": -18,
      "y": 19,
      "z": -6,
      "name": "Rock_Shale_Brick_Ornate"
    },
    {
      "x": -18,
      "y": 20,
      "z": -6,
      "name": "Rock_Shale_Brick_Ornate"
    },
    {
      "x": -18,
      "y": 2,
      "z": -5,
      "name": "Rock_Slate"
    },
    {
      "x": -18,
      "y": 3,
      "z": -5,
      "name": "Rock_Slate"
    },
    {
      "x": -18,
      "y": 4,
      "z": -5,
      "name": "Rock_Slate"
    },
    {
      "x": -18,
      "y": 5,
      "z": -5,
      "name": "Rock_Slate"
    },
    {
      "x": -18,
      "y": 6,
      "z": -5,
      "name": "Rock_Slate"
    },
    {
      "x": -18,
      "y": 7,
      "z": -5,
      "name": "Rock_Shale_Brick_Ornate"
    },
    {
      "x": -18,
      "y": 8,
      "z": -5,
      "name": "Rock_Volcanic_Brick_Stairs",
      "rotation": 2
    },
    {
      "x": -18,
      "y": 9,
      "z": -5,
      "name": "Rock_Volcanic_Brick"
    },
    {
      "x": -18,
      "y": 10,
      "z": -5,
      "name": "Rock_Volcanic_Brick_Stairs",
      "rotation": 8
    },
    {
      "x": -18,
      "y": 11,
      "z": -5,
      "name": "Rock_Volcanic_Brick_Stairs",
      "rotation": 8
    },
    {
      "x": -18,
      "y": 15,
      "z": -5,
      "name": "Rock_Shale_Brick"
    },
    {
      "x": -18,
      "y": 16,
      "z": -5,
      "name": "Rock_Shale_Brick"
    },
    {
      "x": -18,
      "y": 17,
      "z": -5,
      "name": "Rock_Shale_Brick"
    },
    {
      "x": -18,
      "y": 18,
      "z": -5,
      "name": "Rock_Shale_Brick"
    },
    {
      "x": -18,
      "y": 19,
      "z": -5,
      "name": "Rock_Shale_Brick_Ornate"
    },
    {
      "x": -18,
      "y": 20,
      "z": -5,
      "name": "Rock_Shale_Brick_Ornate"
    },
    {
      "x": -18,
      "y": 2,
      "z": -4,
      "name": "Rock_Slate"
    },
    {
      "x": -18,
      "y": 3,
      "z": -4,
      "name": "Rock_Slate"
    },
    {
      "x": -18,
      "y": 4,
      "z": -4,
      "name": "Rock_Slate"
    },
    {
      "x": -18,
      "y": 5,
      "z": -4,
      "name": "Rock_Slate"
    },
    {
      "x": -18,
      "y": 6,
      "z": -4,
      "name": "Rock_Slate"
    },
    {
      "x": -18,
      "y": 7,
      "z": -4,
      "name": "Rock_Volcanic_Brick"
    },
    {
      "x": -18,
      "y": 8,
      "z": -4,
      "name": "Rock_Volcanic_Brick"
    },
    {
      "x": -18,
      "y": 10,
      "z": -4,
      "name": "Rock_Volcanic_Brick"
    },
    {
      "x": -18,
      "y": 11,
      "z": -4,
      "name": "Rock_Volcanic_Brick"
    },
    {
      "x": -18,
      "y": 12,
      "z": -4,
      "name": "Rock_Volcanic_Brick_Stairs",
      "rotation": 8
    },
    {
      "x": -18,
      "y": 2,
      "z": -3,
      "name": "Rock_Slate"
    },
    {
      "x": -18,
      "y": 3,
      "z": -3,
      "name": "Rock_Slate"
    },
    {
      "x": -18,
      "y": 4,
      "z": -3,
      "name": "Rock_Slate"
    },
    {
      "x": -18,
      "y": 5,
      "z": -3,
      "name": "Rock_Slate"
    },
    {
      "x": -18,
      "y": 6,
      "z": -3,
      "name": "Rock_Slate"
    },
    {
      "x": -18,
      "y": 8,
      "z": -3,
      "name": "Rock_Volcanic_Brick_Stairs",
      "rotation": 10
    },
    {
      "x": -18,
      "y": 9,
      "z": -3,
      "name": "Rock_Volcanic_Brick"
    },
    {
      "x": -18,
      "y": 10,
      "z": -3,
      "name": "Rock_Volcanic_Brick_Stairs"
    },
    {
      "x": -18,
      "y": 12,
      "z": -3,
      "name": "Rock_Volcanic_Brick_Stairs",
      "rotation": 10
    },
    {
      "x": -18,
      "y": 13,
      "z": -3,
      "name": "Rock_Volcanic_Brick_Stairs"
    },
    {
      "x": -18,
      "y": 2,
      "z": -2,
      "name": "Rock_Slate"
    },
    {
      "x": -18,
