{
  "version": 8,
  "blockIdVersion": 11,
  "anchorX": 0,
  "anchorY": 0,
  "anchorZ": 0,
  "blocks": [
    {
      "x": -33,
      "y": 5,
      "z": 8,
      "name": "Rock_Slate"
    },
    {
      "x": -33,
      "y": 6,
      "z": 10,
      "name": "Rock_Slate"
    },
    {
      "x": -32,
      "y": 6,
      "z": -5,
      "name": "Rock_Slate"
    },
    {
      "x": -32,
      "y": 6,
      "z": 2,
      "name": "Rock_Slate"
    },
    {
      "x": -32,
      "y": 5,
      "z": 3,
      "name": "Rock_Slate"
    },
    {
      "x": -32,
      "y": 6,
      "z": 3,
      "name": "Rock_Slate"
    },
    {
      "x": -32,
      "y": 5,
      "z": 4,
      "name": "Rock_Slate"
    },
    {
      "x": -32,
      "y": 6,
      "z": 4,
      "name": "Rock_Slate"
    },
    {
      "x": -32,
      "y": 5,
      "z": 5,
      "name": "Rock_Slate"
    },
    {
      "x": -32,
      "y": 6,
      "z": 6,
      "name": "Rock_Slate"
    },
    {
      "x": -32,
      "y": 6,
      "z": 7,
      "name": "Rock_Slate"
    },
    {
      "x": -32,
      "y": 5,
      "z": 8,
      "name": "Rock_Slate"
    },
    {
      "x": -32,
      "y": 6,
      "z": 10,
      "name": "Rock_Slate"
    },
    {
      "x": -31,
      "y": 6,
      "z": -7,
      "name": "Rock_Slate"
    },
    {
      "x": -31,
      "y": 5,
      "z": -6,
      "name": "Rock_Slate"
    },
    {
      "x": -31,
      "y": 6,
      "z": -6,
      "name": "Rock_Slate"
    },
    {
      "x": -31,
      "y": 5,
      "z": -5,
      "name": "Rock_Slate"
    },
    {
      "x": -31,
      "y": 6,
      "z": -5,
      "name": "Rock_Slate"
    },
    {
      "x": -31,
      "y": 5,
      "z": 1,
      "name": "Rock_Slate"
    },
    {
      "x": -31,
      "y": 6,
      "z": 1,
      "name": "Rock_Slate"
    },
    {
      "x": -31,
      "y": 4,
      "z": 2,
      "name": "Rock_Slate"
    },
    {
      "x": -31,
      "y": 5,
      "z": 2,
      "name": "Rock_Slate"
    },
    {
      "x": -31,
      "y": 6,
      "z": 2,
      "name": "Rock_Slate"
    },
    {
      "x": -31,
      "y": 3,
      "z": 3,
      "name": "Rock_Slate"
    },
    {
      "x": -31,
      "y": 4,
      "z": 3,
      "name": "Rock_Slate"
    },
    {
      "x": -31,
      "y": 5,
      "z": 3,
      "name": "Rock_Slate"
    },
    {
      "x": -31,
      "y": 6,
      "z": 3,
      "name": "Rock_Slate"
    },
    {
      "x": -31,
      "y": 3,
      "z": 4,
      "name": "Rock_Slate"
    },
    {
      "x": -31,
      "y": 4,
      "z": 4,
      "name": "Rock_Slate"
    },
    {
      "x": -31,
      "y": 5,
      "z": 4,
      "name": "Rock_Slate"
    },
    {
      "x": -31,
      "y": 6,
      "z": 4,
      "name": "Rock_Slate"
    },
    {
      "x": -31,
      "y": 5,
      "z": 5,
      "name": "Rock_Slate"
    },
    {
      "x": -31,
      "y": 6,
      "z": 5,
      "name": "Rock_Slate"
    },
    {
      "x": -31,
      "y": 6,
      "z": 6,
      "name": "Rock_Slate"
    },
    {
      "x": -31,
      "y": 4,
      "z": 7,
      "name": "Rock_Slate"
    },
    {
      "x": -31,
      "y": 5,
      "z": 7,
      "name": "Rock_Slate"
    },
    {
      "x": -31,
      "y": 6,
      "z": 7,
      "name": "Rock_Slate"
    },
    {
      "x": -31,
      "y": 5,
      "z": 8,
      "name": "Rock_Slate"
    },
    {
      "x": -31,
      "y": 6,
      "z": 8,
      "name": "Rock_Slate"
    },
    {
      "x": -31,
      "y": 6,
      "z": 9,
      "name": "Rock_Slate"
    },
    {
      "x": -31,
      "y": 6,
      "z": 10,
      "name": "Rock_Slate"
    },
    {
      "x": -30,
      "y": 5,
      "z": -8,
      "name": "Rock_Slate"
    },
    {
      "x": -30,
      "y": 6,
      "z": -8,
      "name": "Rock_Slate"
    },
    {
      "x": -30,
      "y": 5,
      "z": -7,
      "name": "Rock_Slate"
    },
    {
      "x": -30,
      "y": 6,
      "z": -7,
      "name": "Rock_Slate"
    },
    {
      "x": -30,
      "y": 4,
      "z": -6,
      "name": "Rock_Slate"
    },
    {
      "x": -30,
      "y": 5,
      "z": -6,
      "name": "Rock_Slate"
    },
    {
      "x": -30,
      "y": 6,
      "z": -6,
      "name": "Rock_Slate"
    },
    {
      "x": -30,
      "y": 3,
      "z": -5,
      "name": "Rock_Slate"
    },
    {
      "x": -30,
      "y": 4,
      "z": -5,
      "name": "Rock_Slate"
    },
    {
      "x": -30,
      "y": 5,
      "z": -5,
      "name": "Rock_Slate"
    },
    {
      "x": -30,
      "y": 6,
      "z": -5,
      "name": "Rock_Slate"
    },
    {
      "x": -30,
      "y": 3,
      "z": -4,
      "name": "Rock_Slate"
    },
    {
      "x": -30,
      "y": 4,
      "z": -4,
      "name": "Rock_Slate"
    },
    {
      "x": -30,
      "y": 5,
      "z": -4,
      "name": "Rock_Slate"
    },
    {
      "x": -30,
      "y": 6,
      "z": -4,
      "name": "Rock_Slate"
    },
    {
      "x": -30,
      "y": 3,
      "z": -3,
      "name": "Rock_Slate"
    },
    {
      "x": -30,
      "y": 4,
      "z": -3,
      "name": "Rock_Slate"
    },
    {
      "x": -30,
      "y": 5,
      "z": -3,
      "name": "Rock_Slate"
    },
    {
      "x": -30,
      "y": 3,
      "z": -2,
      "name": "Rock_Slate"
    },
    {
      "x": -30,
      "y": 2,
      "z": -1,
      "name": "Rock_Slate"
    },
    {
      "x": -30,
      "y": 3,
      "z": -1,
      "name": "Rock_Slate"
    },
    {
      "x": -30,
      "y": 4,
      "z": -1,
      "name": "Rock_Slate"
    },
    {
      "x": -30,
      "y": 2,
      "z": 0,
      "name": "Rock_Slate"
    },
    {
      "x": -30,
      "y": 3,
      "z": 0,
      "name": "Rock_Slate"
    },
    {
      "x": -30,
      "y": 4,
      "z": 0,
      "name": "Rock_Slate"
    },
    {
      "x": -30,
      "y": 2,
      "z": 1,
      "name": "Rock_Slate"
    },
    {
      "x": -30,
      "y": 3,
      "z": 1,
      "name": "Rock_Slate"
    },
    {
      "x": -30,
      "y": 4,
      "z": 1,
      "name": "Rock_Slate"
    },
    {
      "x": -30,
      "y": 5,
      "z": 1,
      "name": "Rock_Slate"
    },
    {
      "x": -30,
      "y": 2,
      "z": 2,
      "name": "Rock_Slate"
    },
    {
      "x": -30,
      "y": 3,
      "z": 2,
      "name": "Rock_Slate"
    },
    {
      "x": -30,
      "y": 4,
      "z": 2,
      "name": "Rock_Slate"
    },
    {
      "x": -30,
      "y": 5,
      "z": 2,
      "name": "Rock_Slate"
    },
    {
      "x": -30,
      "y": 6,
      "z": 2,
      "name": "Rock_Slate"
    },
    {
      "x": -30,
      "y": 2,
      "z": 3,
      "name": "Rock_Slate"
    },
    {
      "x": -30,
      "y": 3,
      "z": 3,
      "name": "Rock_Slate"
    },
    {
      "x": -30,
      "y": 4,
      "z": 3,
      "name": "Rock_Slate"
    },
    {
      "x": -30,
      "y": 5,
      "z": 3,
      "name": "Rock_Slate"
    },
    {
      "x": -30,
      "y": 6,
      "z": 3,
      "name": "Rock_Slate"
    },
    {
      "x": -30,
      "y": 2,
      "z": 4,
      "name": "Rock_Slate"
    },
    {
      "x": -30,
      "y": 3,
      "z": 4,
      "name": "Rock_Slate"
    },
    {
      "x": -30,
      "y": 4,
      "z": 4,
      "name": "Rock_Slate"
    },
    {
      "x": -30,
      "y": 5,
      "z": 4,
      "name": "Rock_Slate"
    },
    {
      "x": -30,
      "y": 6,
      "z": 4,
      "name": "Rock_Slate"
    },
    {
      "x": -30,
      "y": 3,
      "z": 5,
      "name": "Rock_Slate"
    },
    {
      "x": -30,
      "y": 4,
      "z": 5,
      "name": "Rock_Slate"
    },
    {
      "x": -30,
      "y": 5,
      "z": 5,
      "name": "Rock_Slate"
    },
    {
      "x": -30,
      "y": 6,
      "z": 5,
      "name": "Rock_Slate"
    },
    {
      "x": -30,
      "y": 3,
      "z": 6,
      "name": "Rock_Slate"
    },
    {
      "x": -30,
      "y": 4,
      "z": 6,
      "name": "Rock_Slate"
    },
    {
      "x": -30,
      "y": 5,
      "z": 6,
      "name": "Rock_Slate"
    },
    {
      "x": -30,
      "y": 6,
      "z": 6,
      "name": "Rock_Slate"
    },
    {
      "x": -30,
      "y": 4,
      "z": 7,
      "name": "Rock_Slate"
    },
    {
      "x": -30,
      "y": 5,
      "z": 7,
      "name": "Rock_Slate"
    },
    {
      "x": -30,
      "y": 6,
      "z": 7,
      "name": "Rock_Slate"
    },
    {
      "x": -30,
      "y": 3,
      "z": 8,
      "name": "Rock_Slate"
    },
    {
      "x": -30,
      "y": 5,
      "z": 8,
      "name": "Rock_Slate"
    },
    {
      "x": -30,
      "y": 6,
      "z": 8,
      "name": "Rock_Slate"
    },
    {
      "x": -30,
      "y": 5,
      "z": 9,
      "name": "Rock_Slate"
    },
    {
      "x": -30,
      "y": 6,
      "z": 9,
      "name": "Rock_Slate"
    },
    {
      "x": -30,
      "y": 6,
      "z": 10,
      "name": "Rock_Slate"
    },
    {
      "x": -29,
      "y": 5,
      "z": -9,
      "name": "Rock_Slate"
    },
    {
      "x": -29,
      "y": 6,
      "z": -9,
      "name": "Rock_Slate"
    },
    {
      "x": -29,
      "y": 5,
      "z": -8,
      "name": "Rock_Slate"
    },
    {
      "x": -29,
      "y": 6,
      "z": -8,
      "name": "Rock_Slate"
    },
    {
      "x": -29,
      "y": 4,
      "z": -7,
      "name": "Rock_Slate"
    },
    {
      "x": -29,
      "y": 5,
      "z": -7,
      "name": "Rock_Slate"
    },
    {
      "x": -29,
      "y": 6,
      "z": -7,
      "name": "Rock_Slate"
    },
    {
      "x": -29,
      "y": 7,
      "z": -7,
      "name": "Rock_Shale_Brick_Stairs",
      "rotation": 3
    },
    {
      "x": -29,
      "y": 3,
      "z": -6,
      "name": "Rock_Slate"
    },
    {
      "x": -29,
      "y": 4,
      "z": -6,
      "name": "Rock_Slate"
    },
    {
      "x": -29,
      "y": 5,
      "z": -6,
      "name": "Rock_Slate"
    },
    {
      "x": -29,
      "y": 6,
      "z": -6,
      "name": "Rock_Slate"
    },
    {
      "x": -29,
      "y": 3,
      "z": -5,
      "name": "Rock_Slate"
    },
    {
      "x": -29,
      "y": 4,
      "z": -5,
      "name": "Rock_Slate"
    },
    {
      "x": -29,
      "y": 5,
      "z": -5,
      "name": "Rock_Slate"
    },
    {
      "x": -29,
      "y": 6,
      "z": -5,
      "name": "Rock_Slate"
    },
    {
      "x": -29,
      "y": 3,
      "z": -4,
      "name": "Rock_Slate"
    },
    {
      "x": -29,
      "y": 4,
      "z": -4,
      "name": "Rock_Slate"
    },
    {
      "x": -29,
      "y": 5,
      "z": -4,
      "name": "Rock_Slate"
    },
    {
      "x": -29,
      "y": 6,
      "z": -4,
      "name": "Rock_Slate"
    },
    {
      "x": -29,
      "y": 3,
      "z": -3,
      "name": "Rock_Slate"
    },
    {
      "x": -29,
      "y": 4,
      "z": -3,
      "name": "Rock_Slate"
    },
    {
      "x": -29,
      "y": 5,
      "z": -3,
      "name": "Rock_Slate"
    },
    {
      "x": -29,
      "y": 6,
      "z": -3,
      "name": "Rock_Slate"
    },
    {
      "x": -29,
      "y": 3,
      "z": -2,
      "name": "Rock_Slate"
    },
    {
      "x": -29,
      "y": 4,
      "z": -2,
      "name": "Rock_Slate"
    },
    {
      "x": -29,
      "y": 2,
      "z": -1,
      "name": "Rock_Slate"
    },
    {
      "x": -29,
      "y": 3,
      "z": -1,
      "name": "Rock_Slate"
    },
    {
      "x": -29,
      "y": 4,
      "z": -1,
      "name": "Rock_Slate"
    },
    {
      "x": -29,
      "y": 5,
      "z": -1,
      "name": "Rock_Slate"
    },
    {
      "x": -29,
      "y": 2,
      "z": 0,
      "name": "Rock_Slate"
    },
    {
      "x": -29,
      "y": 3,
      "z": 0,
      "name": "Rock_Slate"
    },
    {
      "x": -29,
      "y": 4,
      "z": 0,
      "name": "Rock_Slate"
    },
    {
      "x": -29,
      "y": 5,
      "z": 0,
      "name": "Rock_Slate"
    },
    {
      "x": -29,
      "y": 6,
      "z": 0,
      "name": "Rock_Slate"
    },
    {
      "x": -29,
      "y": 2,
      "z": 1,
      "name": "Rock_Slate"
    },
    {
      "x": -29,
      "y": 3,
      "z": 1,
      "name": "Rock_Slate"
    },
    {
      "x": -29,
      "y": 4,
      "z": 1,
      "name": "Rock_Slate"
    },
    {
      "x": -29,
      "y": 5,
      "z": 1,
      "name": "Rock_Slate"
    },
    {
      "x": -29,
      "y": 6,
      "z": 1,
      "name": "Rock_Slate"
    },
    {
      "x": -29,
      "y": 2,
      "z": 2,
      "name": "Rock_Slate"
    },
    {
      "x": -29,
      "y": 3,
      "z": 2,
      "name": "Rock_Slate"
    },
    {
      "x": -29,
      "y": 4,
      "z": 2,
      "name": "Rock_Slate"
    },
    {
      "x": -29,
      "y": 5,
      "z": 2,
      "name": "Rock_Slate"
    },
    {
      "x": -29,
      "y": 6,
      "z": 2,
      "name": "Rock_Slate"
    },
    {
      "x": -29,
      "y": 2,
      "z": 3,
      "name": "Rock_Slate"
    },
    {
      "x": -29,
      "y": 3,
      "z": 3,
      "name": "Rock_Slate"
    },
    {
      "x": -29,
      "y": 4,
      "z": 3,
      "name": "Rock_Slate"
    },
    {
      "x": -29,
      "y": 5,
      "z": 3,
      "name": "Rock_Slate"
    },
    {
      "x": -29,
      "y": 6,
      "z": 3,
      "name": "Rock_Slate"
    },
    {
      "x": -29,
      "y": 2,
      "z": 4,
      "name": "Rock_Slate"
    },
    {
      "x": -29,
      "y": 3,
      "z": 4,
      "name": "Rock_Slate"
    },
    {
      "x": -29,
      "y": 4,
      "z": 4,
      "name": "Rock_Slate"
    },
    {
      "x": -29,
      "y": 5,
      "z": 4,
      "name": "Rock_Slate"
    },
    {
      "x": -29,
      "y": 6,
      "z": 4,
      "name": "Rock_Slate"
    },
    {
      "x": -29,
      "y": 3,
      "z": 5,
      "name": "Rock_Slate"
    },
    {
      "x": -29,
      "y": 4,
      "z": 5,
      "name": "Rock_Slate"
    },
    {
      "x": -29,
      "y": 5,
      "z": 5,
      "name": "Rock_Slate"
    },
    {
      "x": -29,
      "y": 6,
      "z": 5,
      "name": "Rock_Slate"
    },
    {
      "x": -29,
      "y": 3,
      "z": 6,
      "name": "Rock_Slate"
    },
    {
      "x": -29,
      "y": 4,
      "z": 6,
      "name": "Rock_Slate"
    },
    {
      "x": -29,
      "y": 5,
      "z": 6,
      "name": "Rock_Slate"
    },
    {
      "x": -29,
      "y": 6,
      "z": 6,
      "name": "Rock_Slate"
    },
    {
      "x": -29,
      "y": 3,
      "z": 7,
      "name": "Rock_Slate"
    },
    {
      "x": -29,
      "y": 4,
      "z": 7,
      "name": "Rock_Slate"
    },
    {
      "x": -29,
      "y": 5,
      "z": 7,
      "name": "Rock_Slate"
    },
    {
      "x": -29,
      "y": 6,
      "z": 7,
      "name": "Rock_Slate"
    },
    {
      "x": -29,
      "y": 3,
      "z": 8,
      "name": "Rock_Slate"
    },
    {
      "x": -29,
      "y": 4,
      "z": 8,
      "name": "Rock_Slate"
    },
    {
      "x": -29,
      "y": 5,
      "z": 8,
      "name": "Rock_Slate"
    },
    {
      "x": -29,
      "y": 6,
      "z": 8,
      "name": "Rock_Slate"
    },
    {
      "x": -29,
      "y": 3,
      "z": 9,
      "name": "Rock_Slate"
    },
    {
      "x": -29,
      "y": 4,
      "z": 9,
      "name": "Rock_Slate"
    },
    {
      "x": -29,
      "y": 5,
      "z": 9,
      "name": "Rock_Slate"
    },
    {
      "x": -29,
      "y": 6,
      "z": 9,
      "name": "Rock_Slate"
    },
    {
      "x": -29,
      "y": 3,
      "z": 10,
      "name": "Rock_Slate"
    },
    {
      "x": -29,
      "y": 4,
      "z": 10,
      "name": "Rock_Slate"
    },
    {
      "x": -29,
      "y": 5,
      "z": 10,
      "name": "Rock_Slate"
    },
    {
      "x": -29,
      "y": 6,
      "z": 10,
      "name": "Rock_Slate"
    },
    {
      "x": -29,
      "y": 5,
      "z": 11,
      "name": "Rock_Slate"
    },
    {
      "x": -29,
      "y": 6,
      "z": 11,
      "name": "Rock_Slate"
    },
    {
      "x": -29,
      "y": 5,
      "z": 12,
      "name": "Rock_Slate"
    },
    {
      "x": -28,
      "y": 5,
      "z": -10,
      "name": "Rock_Slate"
    },
    {
      "x": -28,
      "y": 6,
      "z": -10,
      "name": "Rock_Slate"
    },
    {
      "x": -28,
      "y": 5,
      "z": -9,
      "name": "Rock_Slate"
    },
    {
      "x": -28,
      "y": 6,
      "z": -9,
      "name": "Rock_Slate"
    },
    {
      "x": -28,
      "y": 4,
      "z": -8,
      "name": "Rock_Slate"
    },
    {
      "x": -28,
      "y": 5,
      "z": -8,
      "name": "Rock_Slate"
    },
    {
      "x": -28,
      "y": 6,
      "z": -8,
      "name": "Rock_Slate"
    },
    {
      "x": -28,
      "y": 4,
      "z": -7,
      "name": "Rock_Slate"
    },
    {
      "x": -28,
      "y": 5,
      "z": -7,
      "name": "Rock_Slate"
    },
    {
      "x": -28,
      "y": 6,
      "z": -7,
      "name": "Rock_Slate"
    },
    {
      "x": -28,
      "y": 7,
      "z": -7,
      "name": "Rock_Shale_Brick"
    },
    {
      "x": -28,
      "y": 3,
      "z": -6,
      "name": "Rock_Slate"
    },
    {
      "x": -28,
      "y": 4,
      "z": -6,
      "name": "Rock_Slate"
    },
    {
      "x": -28,
      "y": 5,
      "z": -6,
      "name": "Rock_Slate"
    },
    {
      "x": -28,
      "y": 6,
      "z": -6,
      "name": "Rock_Slate"
    },
    {
      "x": -28,
      "y": 4,
      "z": -5,
      "name": "Rock_Slate"
    },
    {
      "x": -28,
      "y": 5,
      "z": -5,
      "name": "Rock_Slate"
    },
    {
      "x": -28,
      "y": 6,
      "z": -5,
      "name": "Rock_Slate"
    },
    {
      "x": -28,
      "y": 3,
      "z": -4,
      "name": "Rock_Slate"
    },
    {
      "x": -28,
      "y": 4,
      "z": -4,
      "name": "Rock_Slate"
    },
    {
      "x": -28,
      "y": 5,
      "z": -4,
      "name": "Rock_Slate"
    },
    {
      "x": -28,
      "y": 6,
      "z": -4,
      "name": "Rock_Slate"
    },
    {
      "x": -28,
      "y": 2,
      "z": -3,
      "name": "Rock_Slate"
    },
    {
      "x": -28,
      "y": 3,
      "z": -3,
      "name": "Rock_Slate"
    },
    {
      "x": -28,
      "y": 4,
      "z": -3,
      "name": "Rock_Slate"
    },
    {
      "x": -28,
      "y": 5,
      "z": -3,
      "name": "Rock_Slate"
    },
    {
      "x": -28,
      "y": 6,
      "z": -3,
      "name": "Rock_Slate"
    },
    {
      "x": -28,
      "y": 2,
      "z": -2,
      "name": "Rock_Slate"
    },
    {
      "x": -28,
      "y": 3,
      "z": -2,
      "name": "Rock_Slate"
    },
    {
      "x": -28,
      "y": 4,
      "z": -2,
      "name": "Rock_Slate"
    },
    {
      "x": -28,
      "y": 5,
      "z": -2,
      "name": "Rock_Slate"
    },
    {
      "x": -28,
      "y": 6,
      "z": -2,
      "name": "Rock_Slate"
    },
    {
      "x": -28,
      "y": 2,
      "z": -1,
      "name": "Rock_Slate"
    },
    {
      "x": -28,
      "y": 3,
      "z": -1,
      "name": "Rock_Slate"
    },
    {
      "x": -28,
      "y": 4,
      "z": -1,
      "name": "Rock_Slate"
    },
    {
      "x": -28,
      "y": 5,
      "z": -1,
      "name": "Rock_Slate"
    },
    {
      "x": -28,
      "y": 6,
      "z": -1,
      "name": "Rock_Slate"
    },
    {
      "x": -28,
      "y": 2,
      "z": 0,
      "name": "Rock_Slate"
    },
    {
      "x": -28,
      "y": 3,
      "z": 0,
      "name": "Rock_Slate"
    },
    {
      "x": -28,
      "y": 4,
      "z": 0,
      "name": "Rock_Slate"
    },
    {
      "x": -28,
      "y": 5,
      "z": 0,
      "name": "Rock_Slate"
    },
    {
      "x": -28,
      "y": 6,
      "z": 0,
      "name": "Rock_Slate"
    },
    {
      "x": -28,
      "y": 2,
      "z": 1,
      "name": "Rock_Slate"
    },
    {
      "x": -28,
      "y": 3,
      "z": 1,
      "name": "Rock_Slate"
    },
    {
      "x": -28,
      "y": 4,
      "z": 1,
      "name": "Rock_Slate"
    },
    {
      "x": -28,
      "y": 5,
      "z": 1,
      "name": "Rock_Slate"
    },
    {
      "x": -28,
      "y": 6,
      "z": 1,
      "name": "Rock_Slate"
    },
    {
      "x": -28,
      "y": 2,
      "z": 2,
      "name": "Rock_Slate"
    },
    {
      "x": -28,
      "y": 3,
      "z": 2,
      "name": "Rock_Slate"
    },
    {
      "x": -28,
      "y": 4,
      "z": 2,
      "name": "Rock_Slate"
    },
    {
      "x": -28,
      "y": 5,
      "z": 2,
      "name": "Rock_Slate"
    },
    {
      "x": -28,
      "y": 6,
      "z": 2,
      "name": "Rock_Slate"
    },
    {
      "x": -28,
      "y": 2,
      "z": 3,
      "name": "Rock_Slate"
    },
    {
      "x": -28,
      "y": 3,
      "z": 3,
      "name": "Rock_Slate"
    },
    {
      "x": -28,
      "y": 4,
      "z": 3,
      "name": "Rock_Slate"
    },
    {
      "x": -28,
      "y": 5,
      "z": 3,
      "name": "Rock_Slate"
    },
    {
      "x": -28,
      "y": 6,
      "z": 3,
      "name": "Rock_Slate"
    },
    {
      "x": -28,
      "y": 2,
      "z": 4,
      "name": "Rock_Slate"
    },
    {
      "x": -28,
      "y": 3,
      "z": 4,
      "name": "Rock_Slate"
    },
    {
      "x": -28,
      "y": 4,
      "z": 4,
      "name": "Rock_Slate"
    },
    {
      "x": -28,
      "y": 5,
      "z": 4,
      "name": "Rock_Slate"
    },
    {
      "x": -28,
      "y": 6,
      "z": 4,
      "name": "Rock_Slate"
    },
    {
      "x": -28,
      "y": 2,
      "z": 5,
      "name": "Rock_Slate"
    },
    {
      "x": -28,
      "y": 3,
      "z": 5,
      "name": "Rock_Slate"
    },
    {
      "x": -28,
      "y": 4,
      "z": 5,
      "name": "Rock_Slate"
    },
    {
      "x": -28,
      "y": 5,
      "z": 5,
      "name": "Rock_Slate"
    },
    {
      "x": -28,
      "y": 6,
      "z": 5,
      "name": "Rock_Slate"
    },
    {
      "x": -28,
      "y": 3,
      "z": 6,
      "name": "Rock_Slate"
    },
    {
      "x": -28,
      "y": 4,
      "z": 6,
      "name": "Rock_Slate"
    },
    {
      "x": -28,
      "y": 5,
      "z": 6,
      "name": "Rock_Slate"
    },
    {
      "x": -28,
      "y": 6,
      "z": 6,
      "name": "Rock_Slate"
    },
    {
      "x": -28,
      "y": 2,
      "z": 7,
      "name": "Rock_Slate"
    },
    {
      "x": -28,
      "y": 3,
      "z": 7,
      "name": "Rock_Slate"
    },
    {
      "x": -28,
      "y": 4,
      "z": 7,
      "name": "Rock_Slate"
    },
    {
      "x": -28,
      "y": 5,
      "z": 7,
      "name": "Rock_Slate"
    },
    {
      "x": -28,
      "y": 6,
      "z": 7,
      "name": "Rock_Slate"
    },
    {
      "x": -28,
      "y": 2,
      "z": 8,
      "name": "Rock_Slate"
    },
    {
      "x": -28,
      "y": 3,
      "z": 8,
      "name": "Rock_Slate"
    },
    {
      "x": -28,
      "y": 4,
      "z": 8,
      "name": "Rock_Slate"
    },
    {
      "x": -28,
      "y": 5,
      "z": 8,
      "name": "Rock_Slate"
    },
    {
      "x": -28,
      "y": 6,
      "z": 8,
      "name": "Rock_Slate"
    },
    {
      "x": -28,
      "y": 3,
      "z": 9,
      "name": "Rock_Slate"
    },
    {
      "x": -28,
      "y": 4,
      "z": 9,
      "name": "Rock_Slate"
    },
    {
      "x": -28,
      "y": 5,
      "z": 9,
      "name": "Rock_Slate"
    },
    {
      "x": -28,
      "y": 6,
      "z": 9,
      "name": "Rock_Slate"
    },
    {
      "x": -28,
      "y": 7,
      "z": 9,
      "name": "Rock_Shale_Brick_Stairs",
      "rotation": 9
    },
    {
      "x": -28,
      "y": 3,
      "z": 10,
      "name": "Rock_Slate"
    },
    {
      "x": -28,
      "y": 4,
      "z": 10,
      "name": "Rock_Slate"
    },
    {
      "x": -28,
      "y": 5,
      "z": 10,
      "name": "Rock_Slate"
    },
    {
      "x": -28,
      "y": 6,
      "z": 10,
      "name": "Rock_Slate"
    },
    {
      "x": -28,
      "y": 4,
      "z": 11,
      "name": "Rock_Slate"
    },
    {
      "x": -28,
      "y": 5,
      "z": 11,
      "name": "Rock_Slate"
    },
    {
      "x": -28,
      "y": 6,
      "z": 11,
      "name": "Rock_Slate"
    },
    {
      "x": -28,
      "y": 5,
      "z": 12,
      "name": "Rock_Slate"
    },
    {
      "x": -28,
      "y": 6,
      "z": 12,
      "name": "Rock_Slate"
    },
    {
      "x": -27,
      "y": 6,
      "z": -11,
      "name": "Rock_Slate"
    },
    {
      "x": -27,
      "y": 7,
      "z": -11,
      "name": "Rock_Slate"
    },
    {
      "x": -27,
      "y": 5,
      "z": -10,
      "name": "Rock_Slate"
    },
    {
      "x": -27,
      "y": 6,
      "z": -10,
      "name": "Rock_Slate"
    },
    {
      "x": -27,
      "y": 3,
      "z": -9,
      "name": "Rock_Slate"
    },
    {
      "x": -27,
      "y": 4,
      "z": -9,
      "name": "Rock_Slate"
    },
    {
      "x": -27,
      "y": 5,
      "z": -9,
      "name": "Rock_Slate"
    },
    {
      "x": -27,
      "y": 6,
      "z": -9,
      "name": "Rock_Slate"
    },
    {
      "x": -27,
      "y": 3,
      "z": -8,
      "name": "Rock_Slate"
    },
    {
      "x": -27,
      "y": 4,
      "z": -8,
      "name": "Rock_Slate"
    },
    {
      "x": -27,
      "y": 5,
      "z": -8,
      "name": "Rock_Slate"
    },
    {
      "x": -27,
      "y": 6,
      "z": -8,
      "name": "Rock_Slate"
    },
    {
      "x": -27,
      "y": 3,
      "z": -7,
      "name": "Rock_Slate"
    },
    {
      "x": -27,
      "y": 4,
      "z": -7,
      "name": "Rock_Slate"
    },
    {
      "x": -27,
      "y": 5,
      "z": -7,
      "name": "Rock_Slate"
    },
    {
      "x": -27,
      "y": 6,
      "z": -7,
      "name": "Rock_Slate"
    },
    {
      "x": -27,
      "y": 7,
      "z": -7,
      "name": "Rock_Shale_Brick"
    },
    {
      "x": -27,
      "y": 3,
      "z": -6,
      "name": "Rock_Slate"
    },
    {
      "x": -27,
      "y": 4,
      "z": -6,
      "name": "Rock_Slate"
    },
    {
      "x": -27,
      "y": 5,
      "z": -6,
      "name": "Rock_Slate"
    },
    {
      "x": -27,
      "y": 6,
      "z": -6,
      "name": "Rock_Slate"
    },
    {
      "x": -27,
      "y": 3,
      "z": -5,
      "name": "Rock_Slate"
    },
    {
      "x": -27,
      "y": 4,
      "z": -5,
      "name": "Rock_Slate"
    },
    {
      "x": -27,
      "y": 5,
      "z": -5,
      "name": "Rock_Slate"
    },
    {
      "x": -27,
      "y": 6,
      "z": -5,
      "name": "Rock_Slate"
    },
    {
      "x": -27,
      "y": 2,
      "z": -4,
      "name": "Rock_Slate"
    },
    {
      "x": -27,
      "y": 3,
      "z": -4,
      "name": "Rock_Slate"
    },
    {
      "x": -27,
      "y": 4,
      "z": -4,
      "name": "Rock_Slate"
    },
    {
      "x": -27,
      "y": 5,
      "z": -4,
      "name": "Rock_Slate"
    },
    {
      "x": -27,
      "y": 6,
      "z": -4,
      "name": "Rock_Slate"
    },
    {
      "x": -27,
      "y": 3,
      "z": -3,
      "name": "Rock_Slate"
    },
    {
      "x": -27,
      "y": 4,
      "z": -3,
      "name": "Rock_Slate"
    },
    {
      "x": -27,
      "y": 5,
      "z": -3,
      "name": "Rock_Slate"
    },
    {
      "x": -27,
      "y": 6,
      "z": -3,
      "name": "Rock_Slate"
    },
    {
      "x": -27,
      "y": 2,
      "z": -2,
      "name": "Rock_Slate"
    },
    {
      "x": -27,
      "y": 3,
      "z": -2,
      "name": "Rock_Slate"
    },
    {
      "x": -27,
      "y": 4,
      "z": -2,
      "name": "Rock_Slate"
    },
    {
      "x": -27,
      "y": 5,
      "z": -2,
      "name": "Rock_Slate"
    },
    {
      "x": -27,
      "y": 6,
      "z": -2,
      "name": "Rock_Slate"
    },
    {
      "x": -27,
      "y": 2,
      "z": -1,
      "name": "Rock_Slate"
    },
    {
      "x": -27,
      "y": 3,
      "z": -1,
      "name": "Rock_Slate"
    },
    {
      "x": -27,
      "y": 4,
      "z": -1,
      "name": "Rock_Slate"
    },
    {
      "x": -27,
      "y": 5,
      "z": -1,
      "name": "Rock_Slate"
    },
    {
      "x": -27,
      "y": 6,
      "z": -1,
      "name": "Rock_Slate"
    },
    {
      "x": -27,
      "y": 2,
      "z": 0,
      "name": "Rock_Slate"
    },
    {
      "x": -27,
      "y": 3,
      "z": 0,
      "name": "Rock_Slate"
    },
    {
      "x": -27,
      "y": 4,
      "z": 0,
      "name": "Rock_Slate"
    },
    {
      "x": -27,
      "y": 5,
      "z": 0,
      "name": "Rock_Slate"
    },
    {
      "x": -27,
      "y": 6,
      "z": 0,
      "name": "Rock_Slate"
    },
    {
      "x": -27,
      "y": 2,
      "z": 1,
      "name": "Rock_Slate"
    },
    {
      "x": -27,
      "y": 3,
      "z": 1,
      "name": "Rock_Slate"
    },
    {
      "x": -27,
      "y": 4,
      "z": 1,
      "name": "Rock_Slate"
    },
    {
      "x": -27,
      "y": 5,
      "z": 1,
      "name": "Rock_Slate"
    },
    {
      "x": -27,
      "y": 6,
      "z": 1,
      "name": "Rock_Slate"
    },
    {
      "x": -27,
      "y": 3,
      "z": 2,
      "name": "Rock_Slate"
    },
    {
      "x": -27,
      "y": 4,
      "z": 2,
      "name": "Rock_Slate"
    },
    {
      "x": -27,
      "y": 5,
      "z": 2,
      "name": "Rock_Slate"
    },
    {
      "x": -27,
      "y": 6,
      "z": 2,
      "name": "Rock_Slate"
    },
    {
      "x": -27,
      "y": 3,
      "z": 3,
      "name": "Rock_Slate"
    },
    {
      "x": -27,
      "y": 4,
      "z": 3,
      "name": "Rock_Slate"
    },
    {
      "x": -27,
      "y": 5,
      "z": 3,
      "name": "Rock_Slate"
    },
    {
      "x": -27,
      "y": 6,
      "z": 3,
      "name": "Rock_Slate"
    },
    {
      "x": -27,
      "y": 2,
      "z": 4,
      "name": "Rock_Slate"
    },
    {
      "x": -27,
      "y": 3,
      "z": 4,
      "name": "Rock_Slate"
    },
    {
      "x": -27,
      "y": 4,
      "z": 4,
      "name": "Rock_Slate"
    },
    {
      "x": -27,
      "y": 5,
      "z": 4,
      "name": "Rock_Slate"
    },
    {
      "x": -27,
      "y": 6,
      "z": 4,
      "name": "Rock_Slate"
    },
    {
      "x": -27,
      "y": 2,
      "z": 5,
      "name": "Rock_Slate"
    },
    {
      "x": -27,
      "y": 3,
      "z": 5,
      "name": "Rock_Slate"
    },
    {
      "x": -27,
      "y": 4,
      "z": 5,
      "name": "Rock_Slate"
    },
    {
      "x": -27,
      "y": 5,
      "z": 5,
      "name": "Rock_Slate"
    },
    {
      "x": -27,
      "y": 6,
      "z": 5,
      "name": "Rock_Slate"
    },
    {
      "x": -27,
      "y": 2,
      "z": 6,
      "name": "Rock_Slate"
    },
    {
      "x": -27,
      "y": 3,
      "z": 6,
      "name": "Rock_Slate"
    },
    {
      "x": -27,
      "y": 4,
      "z": 6,
      "name": "Rock_Slate"
    },
    {
      "x": -27,
      "y": 5,
      "z": 6,
      "name": "Rock_Slate"
    },
    {
      "x": -27,
      "y": 6,
      "z": 6,
      "name": "Rock_Slate"
    },
    {
      "x": -27,
      "y": 2,
      "z": 7,
      "name": "Rock_Slate"
    },
    {
      "x": -27,
      "y": 3,
      "z": 7,
      "name": "Rock_Slate"
    },
    {
      "x": -27,
      "y": 4,
      "z": 7,
      "name": "Rock_Slate"
    },
    {
      "x": -27,
      "y": 5,
      "z": 7,
      "name": "Rock_Slate"
    },
    {
      "x": -27,
      "y": 6,
      "z": 7,
      "name": "Rock_Slate"
    },
    {
      "x": -27,
      "y": 2,
      "z": 8,
      "name": "Rock_Slate"
    },
    {
      "x": -27,
      "y": 3,
      "z": 8,
      "name": "Rock_Slate"
    },
    {
      "x": -27,
      "y": 4,
      "z": 8,
      "name": "Rock_Slate"
    },
    {
      "x": -27,
      "y": 5,
      "z": 8,
      "name": "Rock_Slate"
    },
    {
      "x": -27,
      "y": 6,
      "z": 8,
      "name": "Rock_Slate"
    },
    {
      "x": -27,
      "y": 3,
      "z": 9,
      "name": "Rock_Slate"
    },
    {
      "x": -27,
      "y": 4,
      "z": 9,
      "name": "Rock_Slate"
    },
    {
      "x": -27,
      "y": 5,
      "z": 9,
      "name": "Rock_Slate"
    },
    {
      "x": -27,
      "y": 6,
      "z": 9,
      "name": "Rock_Slate"
    },
    {
      "x": -27,
      "y": 7,
      "z": 9,
      "name": "Rock_Shale_Brick"
    },
    {
      "x": -27,
      "y": 3,
      "z": 10,
      "name": "Rock_Slate"
    },
    {
      "x": -27,
      "y": 4,
      "z": 10,
      "name": "Rock_Slate"
    },
    {
      "x": -27,
      "y": 5,
      "z": 10,
      "name": "Rock_Slate"
    },
    {
      "x": -27,
      "y": 6,
      "z": 10,
      "name": "Rock_Slate"
    },
    {
      "x": -27,
      "y": 4,
      "z": 11,
      "name": "Rock_Slate"
    },
    {
      "x": -27,
      "y": 5,
      "z": 11,
      "name": "Rock_Slate"
    },
    {
      "x": -27,
      "y": 6,
      "z": 11,
      "name": "Rock_Slate"
    },
    {
      "x": -27,
      "y": 4,
      "z": 12,
      "name": "Rock_Slate"
    },
    {
      "x": -26,
      "y": 5,
      "z": -12,
      "name": "Rock_Slate"
    },
    {
      "x": -26,
      "y": 6,
      "z": -12,
      "name": "Rock_Slate"
    },
    {
      "x": -26,
      "y": 5,
      "z": -11,
      "name": "Rock_Slate"
    },
    {
      "x": -26,
      "y": 6,
      "z": -11,
      "name": "Rock_Slate"
    },
    {
      "x": -26,
      "y": 3,
      "z": -10,
      "name": "Rock_Slate"
    },
    {
      "x": -26,
      "y": 5,
      "z": -10,
      "name": "Rock_Slate"
    },
    {
      "x": -26,
      "y": 6,
      "z": -10,
      "name": "Rock_Slate"
    },
    {
      "x": -26,
      "y": 4,
      "z": -9,
      "name": "Rock_Slate"
    },
    {
      "x": -26,
      "y": 5,
      "z": -9,
      "name": "Rock_Slate"
    },
    {
      "x": -26,
      "y": 6,
      "z": -9,
      "name": "Rock_Slate"
    },
    {
      "x": -26,
      "y": 3,
      "z": -8,
      "name": "Rock_Slate"
    },
    {
      "x": -26,
      "y": 4,
      "z": -8,
      "name": "Rock_Slate"
    },
    {
      "x": -26,
      "y": 5,
      "z": -8,
      "name": "Rock_Slate"
    },
    {
      "x": -26,
      "y": 6,
      "z": -8,
      "name": "Rock_Slate"
    },
    {
      "x": -26,
      "y": 3,
      "z": -7,
      "name": "Rock_Slate"
    },
    {
      "x": -26,
      "y": 4,
      "z": -7,
      "name": "Rock_Slate"
    },
    {
      "x": -26,
      "y": 5,
      "z": -7,
      "name": "Rock_Slate"
    },
    {
      "x": -26,
      "y": 6,
      "z": -7,
      "name": "Rock_Slate"
    },
    {
      "x": -26,
      "y": 7,
      "z": -7,
      "name": "Rock_Shale_Brick"
    },
    {
      "x": -26,
      "y": 8,
      "z": -7,
      "name": "Rock_Shale_Brick_Wall"
    },
    {
      "x": -26,
      "y": 3,
      "z": -6,
      "name": "Rock_Slate"
    },
    {
      "x": -26,
      "y": 4,
      "z": -6,
      "name": "Rock_Slate"
    },
    {
      "x": -26,
      "y": 5,
      "z": -6,
      "name": "Rock_Slate"
    },
    {
      "x": -26,
      "y": 6,
      "z": -6,
      "name": "Rock_Slate"
    },
    {
      "x": -26,
      "y": 2,
      "z": -5,
      "name": "Rock_Slate"
    },
    {
      "x": -26,
      "y": 3,
      "z": -5,
      "name": "Rock_Slate"
    },
    {
      "x": -26,
      "y": 4,
      "z": -5,
      "name": "Rock_Slate"
    },
    {
      "x": -26,
      "y": 5,
      "z": -5,
      "name": "Rock_Slate"
    },
    {
      "x": -26,
      "y": 6,
      "z": -5,
      "name": "Rock_Slate"
    },
    {
      "x": -26,
      "y": 3,
      "z": -4,
      "name": "Rock_Slate"
    },
    {
      "x": -26,
      "y": 4,
      "z": -4,
      "name": "Rock_Slate"
    },
    {
      "x": -26,
      "y": 5,
      "z": -4,
      "name": "Rock_Slate"
    },
    {
      "x": -26,
      "y": 6,
      "z": -4,
      "name": "Rock_Slate"
    },
    {
      "x": -26,
      "y": 3,
      "z": -3,
      "name": "Rock_Slate"
    },
    {
      "x": -26,
      "y": 4,
      "z": -3,
      "name": "Rock_Slate"
    },
    {
      "x": -26,
      "y": 5,
      "z": -3,
      "name": "Rock_Slate"
    },
    {
      "x": -26,
      "y": 6,
      "z": -3,
      "name": "Rock_Slate"
    },
    {
      "x": -26,
      "y": 2,
      "z": -2,
      "name": "Rock_Slate"
    },
    {
      "x": -26,
      "y": 3,
      "z": -2,
      "name": "Rock_Slate"
    },
    {
      "x": -26,
      "y": 4,
      "z": -2,
      "name": "Rock_Slate"
    },
    {
      "x": -26,
      "y": 5,
      "z": -2,
      "name": "Rock_Slate"
    },
    {
      "x": -26,
      "y": 6,
      "z": -2,
      "name": "Rock_Slate"
    },
    {
      "x": -26,
      "y": 2,
      "z": -1,
      "name": "Rock_Slate"
    },
    {
      "x": -26,
      "y": 3,
      "z": -1,
      "name": "Rock_Slate"
    },
    {
      "x": -26,
      "y": 4,
      "z": -1,
      "name": "Rock_Slate"
    },
    {
      "x": -26,
      "y": 5,
      "z": -1,
      "name": "Rock_Slate"
    },
    {
      "x": -26,
      "y": 6,
      "z": -1,
      "name": "Rock_Slate"
    },
    {
      "x": -26,
      "y": 2,
      "z": 0,
      "name": "Rock_Slate"
    },
    {
      "x": -26,
      "y": 3,
      "z": 0,
      "name": "Rock_Slate"
    },
    {
      "x": -26,
      "y": 4,
      "z": 0,
      "name": "Rock_Slate"
    },
    {
      "x": -26,
      "y": 5,
      "z": 0,
      "name": "Rock_Slate"
    },
    {
      "x": -26,
      "y": 6,
      "z": 0,
      "name": "Rock_Slate"
    },
    {
      "x": -26,
      "y": 2,
      "z": 1,
      "name": "Rock_Slate"
    },
    {
      "x": -26,
      "y": 3,
      "z": 1,
      "name": "Rock_Slate"
    },
    {
      "x": -26,
      "y": 4,
      "z": 1,
      "name": "Rock_Slate"
    },
    {
      "x": -26,
      "y": 5,
      "z": 1,
      "name": "Rock_Slate"
    },
    {
      "x": -26,
      "y": 6,
      "z": 1,
      "name": "Rock_Slate"
    },
    {
      "x": -26,
      "y": 1,
      "z": 2,
      "name": "Rock_Slate"
    },
    {
      "x": -26,
      "y": 2,
      "z": 2,
      "name": "Rock_Slate"
    },
    {
      "x": -26,
      "y": 3,
      "z": 2,
      "name": "Rock_Slate"
    },
    {
      "x": -26,
      "y": 4,
      "z": 2,
      "name": "Rock_Slate"
    },
    {
      "x": -26,
      "y": 5,
      "z": 2,
      "name": "Rock_Slate"
    },
    {
      "x": -26,
      "y": 6,
      "z": 2,
      "name": "Rock_Slate"
    },
    {
      "x": -26,
      "y": 2,
      "z": 3,
      "name": "Rock_Slate"
    },
    {
      "x": -26,
      "y": 3,
      "z": 3,
      "name": "Rock_Slate"
    },
    {
      "x": -26,
      "y": 4,
      "z": 3,
      "name": "Rock_Slate"
    },
    {
      "x": -26,
      "y": 5,
      "z": 3,
      "name": "Rock_Slate"
    },
    {
      "x": -26,
      "y": 6,
      "z": 3,
      "name": "Rock_Slate"
    },
    {
      "x": -26,
      "y": 2,
      "z": 4,
      "name": "Rock_Slate"
    },
    {
      "x": -26,
      "y": 3,
      "z": 4,
      "name": "Rock_Slate"
    },
    {
      "x": -26,
      "y": 4,
      "z": 4,
      "name": "Rock_Slate"
    },
    {
      "x": -26,
      "y": 5,
      "z": 4,
      "name": "Rock_Slate"
    },
    {
      "x": -26,
      "y": 6,
      "z": 4,
      "name": "Rock_Slate"
    },
    {
      "x": -26,
      "y": 2,
      "z": 5,
      "name": "Rock_Slate"
    },
    {
      "x": -26,
      "y": 3,
      "z": 5,
      "name": "Rock_Slate"
    },
    {
      "x": -26,
      "y": 4,
      "z": 5,
      "name": "Rock_Slate"
    },
    {
      "x": -26,
      "y": 5,
      "z": 5,
      "name": "Rock_Slate"
    },
    {
      "x": -26,
      "y": 6,
      "z": 5,
      "name": "Rock_Slate"
    },
    {
      "x": -26,
      "y": 2,
      "z": 6,
      "name": "Rock_Slate"
    },
    {
      "x": -26,
      "y": 3,
      "z": 6,
      "name": "Rock_Slate"
    },
    {
      "x": -26,
      "y": 4,
      "z": 6,
      "name": "Rock_Slate"
    },
    {
      "x": -26,
      "y": 5,
      "z": 6,
      "name": "Rock_Slate"
    },
    {
      "x": -26,
      "y": 6,
      "z": 6,
      "name": "Rock_Slate"
    },
    {
      "x": -26,
      "y": 2,
      "z": 7,
      "name": "Rock_Slate"
    },
    {
      "x": -26,
      "y": 3,
      "z": 7,
      "name": "Rock_Slate"
    },
    {
      "x": -26,
      "y": 4,
      "z": 7,
      "name": "Rock_Slate"
    },
    {
      "x": -26,
      "y": 5,
      "z": 7,
      "name": "Rock_Slate"
    },
    {
      "x": -26,
      "y": 6,
      "z": 7,
      "name": "Rock_Slate"
    },
    {
      "x": -26,
      "y": 2,
      "z": 8,
      "name": "Rock_Slate"
    },
    {
      "x": -26,
      "y": 3,
      "z": 8,
      "name": "Rock_Slate"
    },
    {
      "x": -26,
      "y": 4,
      "z": 8,
      "name": "Rock_Slate"
    },
    {
      "x": -26,
      "y": 5,
      "z": 8,
      "name": "Rock_Slate"
    },
    {
      "x": -26,
      "y": 6,
      "z": 8,
      "name": "Rock_Slate"
    },
    {
      "x": -26,
      "y": 2,
      "z": 9,
      "name": "Rock_Slate"
    },
    {
      "x": -26,
      "y": 3,
      "z": 9,
      "name": "Rock_Slate"
    },
    {
      "x": -26,
      "y": 4,
      "z": 9,
      "name": "Rock_Slate"
    },
    {
      "x": -26,
      "y": 5,
      "z": 9,
      "name": "Rock_Slate"
    },
    {
      "x": -26,
      "y": 6,
      "z": 9,
      "name": "Rock_Slate"
    },
    {
      "x": -26,
      "y": 7,
      "z": 9,
      "name": "Rock_Shale_Brick"
    },
    {
      "x": -26,
      "y": 8,
      "z": 9,
      "name": "Rock_Shale_Brick_Wall"
    },
    {
      "x": -26,
      "y": 3,
      "z": 10,
      "name": "Rock_Slate"
    },
    {
      "x": -26,
      "y": 4,
      "z": 10,
      "name": "Rock_Slate"
    },
    {
      "x": -26,
      "y": 5,
      "z": 10,
      "name": "Rock_Slate"
    },
    {
      "x": -26,
      "y": 6,
      "z": 10,
      "name": "Rock_Slate"
    },
    {
      "x": -26,
      "y": 3,
      "z": 11,
      "name": "Rock_Slate"
    },
    {
      "x": -26,
      "y": 4,
      "z": 11,
      "name": "Rock_Slate"
    },
    {
      "x": -26,
      "y": 5,
      "z": 11,
      "name": "Rock_Slate"
    },
    {
      "x": -26,
      "y": 6,
      "z": 11,
      "name": "Rock_Slate"
    },
    {
      "x": -26,
      "y": 4,
      "z": 12,
      "name": "Rock_Slate"
    },
    {
      "x": -26,
      "y": 5,
      "z": 12,
      "name": "Rock_Slate"
    },
    {
      "x": -25,
      "y": 5,
      "z": -11,
      "name": "Rock_Slate"
    },
    {
      "x": -25,
      "y": 6,
      "z": -11,
      "name": "Rock_Slate"
    },
    {
      "x": -25,
      "y": 4,
      "z": -10,
      "name": "Rock_Slate"
    },
    {
      "x": -25,
      "y": 5,
      "z": -10,
      "name": "Rock_Slate"
    },
    {
      "x": -25,
      "y": 6,
      "z": -10,
      "name": "Rock_Slate"
    },
    {
      "x": -25,
      "y": 3,
      "z": -9,
      "name": "Rock_Slate"
    },
    {
      "x": -25,
      "y": 4,
      "z": -9,
      "name": "Rock_Slate"
    },
    {
      "x": -25,
      "y": 5,
      "z": -9,
      "name": "Rock_Slate"
    },
    {
      "x": -25,
      "y": 6,
      "z": -9,
      "name": "Rock_Slate"
    },
    {
      "x": -25,
      "y": 3,
      "z": -8,
      "name": "Rock_Slate"
    },
    {
      "x": -25,
      "y": 4,
      "z": -8,
      "name": "Rock_Slate"
    },
    {
      "x": -25,
      "y": 5,
      "z": -8,
      "name": "Rock_Slate"
    },
    {
      "x": -25,
      "y": 6,
      "z": -8,
      "name": "Rock_Slate"
    },
    {
      "x": -25,
      "y": 7,
      "z": -8,
      "name": "Rock_Shale_Brick_Ornate"
    },
    {
      "x": -25,
      "y": 8,
      "z": -8,
      "name": "Rock_Shale_Brick_Ornate"
    },
    {
      "x": -25,
      "y": 3,
      "z": -7,
      "name": "Rock_Slate"
    },
    {
      "x": -25,
      "y": 4,
      "z": -7,
      "name": "Rock_Slate"
    },
    {
      "x": -25,
      "y": 5,
      "z": -7,
      "name": "Rock_Slate"
    },
    {
      "x": -25,
      "y": 6,
      "z": -7,
      "name": "Rock_Slate"
    },
    {
      "x": -25,
      "y": 7,
      "z": -7,
      "name": "Rock_Shale_Brick_Ornate"
    },
    {
      "x": -25,
      "y": 8,
      "z": -7,
      "name": "Rock_Shale_Brick_Ornate"
    },
    {
      "x": -25,
      "y": 9,
      "z": -7,
      "name": "Rock_Shale_Brick"
    },
    {
      "x": -25,
      "y": 10,
      "z": -7,
      "name": "Rock_Shale_Brick"
    },
    {
      "x": -25,
      "y": 11,
      "z": -7,
      "name": "Rock_Shale_Brick"
    },
    {
      "x": -25,
      "y": 12,
      "z": -7,
      "name": "Rock_Shale_Brick"
    },
    {
      "x": -25,
      "y": 13,
      "z": -7,
      "name": "Rock_Shale_Brick"
    },
    {
      "x": -25,
      "y": 14,
      "z": -7,
      "name": "Rock_Shale_Brick"
    },
    {
      "x": -25,
      "y": 15,
      "z": -7,
      "name": "Rock_Shale_Brick"
    },
    {
      "x": -25,
      "y": 16,
      "z": -7,
      "name": "Rock_Shale_Brick"
    },
    {
      "x": -25,
      "y": 2,
      "z": -6,
      "name": "Rock_Slate"
    },
    {
      "x": -25,
      "y": 3,
      "z": -6,
      "name": "Rock_Slate"
    },
    {
      "x": -25,
      "y": 4,
      "z": -6,
      "name": "Rock_Slate"
    },
    {
      "x": -25,
      "y": 5,
      "z": -6,
      "name": "Rock_Slate"
    },
    {
      "x": -25,
      "y": 6,
      "z": -6,
      "name": "Rock_Slate"
    },
    {
      "x": -25,
      "y": 7,
      "z": -6,
      "name": "Rock_Shale_Brick_Ornate"
    },
    {
      "x": -25,
      "y": 8,
      "z": -6,
      "name": "Rock_Shale_Brick_Ornate"
    },
    {
      "x": -25,
      "y": 11,
      "z": -6,
      "name": "Rock_Shale_Brick_Stairs",
      "rotation": 10
    },
    {
      "x": -25,
      "y": 3,
      "z": -5,
      "name": "Rock_Slate"
    },
    {
      "x": -25,
      "y": 4,
      "z": -5,
      "name": "Rock_Slate"
    },
    {
      "x": -25,
      "y": 5,
      "z": -5,
      "name": "Rock_Slate"
    },
    {
      "x": -25,
      "y": 6,
      "z": -5,
      "name": "Rock_Slate"
    },
    {
      "x": -25,
      "y": 3,
      "z": -4,
      "name": "Rock_Slate"
    },
    {
      "x": -25,
      "y": 4,
      "z": -4,
      "name": "Rock_Slate"
    },
    {
      "x": -25,
      "y": 5,
      "z": -4,
      "name": "Rock_Slate"
    },
    {
      "x": -25,
      "y": 6,
      "z": -4,
      "name": "Rock_Slate"
    },
    {
      "x": -25,
      "y": 2,
      "z": -3,
      "name": "Rock_Slate"
    },
    {
      "x": -25,
      "y": 3,
      "z": -3,
      "name": "Rock_Slate"
    },
    {
      "x": -25,
      "y": 4,
      "z": -3,
      "name": "Rock_Slate"
    },
    {
      "x": -25,
      "y": 5,
      "z": -3,
      "name": "Rock_Slate"
    },
    {
      "x": -25,
      "y": 6,
      "z": -3,
      "name": "Rock_Slate"
    },
    {
      "x": -25,
      "y": 2,
      "z": -2,
      "name": "Rock_Slate"
    },
    {
      "x": -25,
      "y": 3,
      "z": -2,
      "name": "Rock_Slate"
    },
    {
      "x": -25,
      "y": 4,
      "z": -2,
      "name": "Rock_Slate"
    },
    {
      "x": -25,
      "y": 5,
      "z": -2,
      "name": "Rock_Slate"
    },
    {
      "x": -25,
      "y": 6,
      "z": -2,
      "name": "Rock_Slate"
    },
    {
      "x": -25,
      "y": 3,
      "z": -1,
      "name": "Rock_Slate"
    },
    {
      "x": -25,
      "y": 4,
      "z": -1,
      "name": "Rock_Slate"
    },
    {
      "x": -25,
      "y": 5,
      "z": -1,
      "name": "Rock_Slate"
    },
    {
      "x": -25,
      "y": 6,
      "z": -1,
      "name": "Rock_Slate"
    },
    {
      "x": -25,
      "y": 2,
      "z": 0,
      "name": "Rock_Slate"
    },
    {
      "x": -25,
      "y": 3,
      "z": 0,
      "name": "Rock_Slate"
    },
    {
      "x": -25,
      "y": 4,
      "z": 0,
      "name": "Rock_Slate"
    },
    {
      "x": -25,
      "y": 5,
      "z": 0,
      "name": "Rock_Slate"
    },
    {
      "x": -25,
      "y": 6,
      "z": 0,
      "name": "Rock_Slate"
    },
    {
      "x": -25,
      "y": 3,
      "z": 1,
      "name": "Rock_Slate"
    },
    {
      "x": -25,
      "y": 4,
      "z": 1,
      "name": "Rock_Slate"
    },
    {
      "x": -25,
      "y": 5,
      "z": 1,
      "name": "Rock_Slate"
    },
    {
      "x": -25,
      "y": 6,
      "z": 1,
      "name": "Rock_Slate"
    },
    {
      "x": -25,
      "y": 3,
      "z": 2,
      "name": "Rock_Slate"
    },
    {
      "x": -25,
      "y": 4,
      "z": 2,
      "name": "Rock_Slate"
    },
    {
      "x": -25,
      "y": 5,
      "z": 2,
      "name": "Rock_Slate"
    },
    {
      "x": -25,
      "y": 6,
      "z": 2,
      "name": "Rock_Slate"
    },
    {
      "x": -25,
      "y": 1,
      "z": 3,
      "name": "Rock_Slate"
    },
    {
      "x": -25,
      "y": 2,
      "z": 3,
      "name": "Rock_Slate"
    },
    {
      "x": -25,
      "y": 3,
      "z": 3,
      "name": "Rock_Slate"
    },
    {
      "x": -25,
      "y": 4,
      "z": 3,
      "name": "Rock_Slate"
    },
    {
      "x": -25,
      "y": 5,
      "z": 3,
      "name": "Rock_Slate"
    },
    {
      "x": -25,
      "y": 6,
      "z": 3,
      "name": "Rock_Slate"
    },
    {
      "x": -25,
      "y": 0,
      "z": 4,
      "name": "Rock_Slate"
    },
    {
      "x": -25,
      "y": 1,
      "z": 4,
      "name": "Rock_Slate"
    },
    {
      "x": -25,
      "y": 2,
      "z": 4,
      "name": "Rock_Slate"
    },
    {
      "x": -25,
      "y": 3,
      "z": 4,
      "name": "Rock_Slate"
    },
    {
      "x": -25,
      "y": 4,
      "z": 4,
      "name": "Rock_Slate"
    },
    {
      "x": -25,
      "y": 5,
      "z": 4,
      "name": "Rock_Slate"
    },
    {
      "x": -25,
      "y": 6,
      "z": 4,
      "name": "Rock_Slate"
    },
    {
      "x": -25,
      "y": 2,
      "z": 5,
      "name": "Rock_Slate"
    },
    {
      "x": -25,
      "y": 3,
      "z": 5,
      "name": "Rock_Slate"
    },
    {
      "x": -25,
      "y": 4,
      "z": 5,
      "name": "Rock_Slate"
    },
    {
      "x": -25,
      "y": 5,
      "z": 5,
      "name": "Rock_Slate"
    },
    {
      "x": -25,
      "y": 6,
      "z": 5,
      "name": "Rock_Slate"
    },
    {
      "x": -25,
      "y": 2,
      "z": 6,
      "name": "Rock_Slate"
    },
    {
      "x": -25,
      "y": 3,
      "z": 6,
      "name": "Rock_Slate"
    },
    {
      "x": -25,
      "y": 4,
      "z": 6,
      "name": "Rock_Slate"
    },
    {
      "x": -25,
      "y": 5,
      "z": 6,
      "name": "Rock_Slate"
    },
    {
      "x": -25,
      "y": 6,
      "z": 6,
      "name": "Rock_Slate"
    },
    {
      "x": -25,
      "y": 2,
      "z": 7,
      "name": "Rock_Slate"
    },
    {
      "x": -25,
      "y": 3,
      "z": 7,
      "name": "Rock_Slate"
    },
    {
      "x": -25,
      "y": 4,
      "z": 7,
      "name": "Rock_Slate"
    },
    {
      "x": -25,
      "y": 5,
      "z": 7,
      "name": "Rock_Slate"
    },
    {
      "x": -25,
      "y": 6,
      "z": 7,
      "name": "Rock_Slate"
    },
    {
      "x": -25,
      "y": 3,
      "z": 8,
      "name": "Rock_Slate"
    },
    {
      "x": -25,
      "y": 4,
      "z": 8,
      "name": "Rock_Slate"
    },
    {
      "x": -25,
      "y": 5,
      "z": 8,
      "name": "Rock_Slate"
    },
    {
      "x": -25,
      "y": 6,
      "z": 8,
      "name": "Rock_Slate"
    },
    {
      "x": -25,
      "y": 7,
      "z": 8,
      "name": "Rock_Shale_Brick_Ornate"
    },
    {
      "x": -25,
      "y": 8,
      "z": 8,
      "name": "Rock_Shale_Brick_Ornate"
    },
    {
      "x": -25,
      "y": 11,
      "z": 8,
      "name": "Rock_Shale_Brick_Stairs",
      "rotation": 8
    },
    {
      "x": -25,
      "y": 2,
      "z": 9,
      "name": "Rock_Slate"
    },
    {
      "x": -25,
      "y": 3,
      "z": 9,
      "name": "Rock_Slate"
    },
    {
      "x": -25,
      "y": 4,
      "z": 9,
      "name": "Rock_Slate"
    },
    {
      "x": -25,
      "y": 5,
      "z": 9,
      "name": "Rock_Slate"
    },
    {
      "x": -25,
      "y": 6,
      "z": 9,
      "name": "Rock_Slate"
    },
    {
      "x": -25,
      "y": 7,
      "z": 9,
      "name": "Rock_Shale_Brick_Ornate"
    },
    {
      "x": -25,
      "y": 8,
      "z": 9,
      "name": "Rock_Shale_Brick_Ornate"
    },
    {
      "x": -25,
      "y": 9,
      "z": 9,
      "name": "Rock_Shale_Brick"
    },
    {
      "x": -25,
      "y": 10,
      "z": 9,
      "name": "Rock_Shale_Brick"
    },
    {
      "x": -25,
      "y": 11,
      "z": 9,
      "name": "Rock_Shale_Brick"
    },
    {
      "x": -25,
      "y": 12,
      "z": 9,
      "name": "Rock_Shale_Brick"
    },
    {
      "x": -25,
      "y": 13,
      "z": 9,
      "name": "Rock_Shale_Brick"
    },
    {
      "x": -25,
      "y": 14,
      "z": 9,
      "name": "Rock_Shale_Brick"
    },
    {
      "x": -25,
      "y": 15,
      "z": 9,
      "name": "Rock_Shale_Brick"
    },
    {
      "x": -25,
      "y": 16,
      "z": 9,
      "name": "Rock_Shale_Brick"
    },
    {
      "x": -25,
      "y": 17,
      "z": 9,
      "name": "Rock_Shale_Brick"
    },
    {
      "x": -25,
      "y": 3,
      "z": 10,
      "name": "Rock_Slate"
    },
    {
      "x": -25,
      "y": 4,
      "z": 10,
      "name": "Rock_Slate"
    },
    {
      "x": -25,
      "y": 5,
      "z": 10,
      "name": "Rock_Slate"
    },
    {
      "x": -25,
      "y": 6,
      "z": 10,
      "name": "Rock_Slate"
    },
    {
      "x": -25,
      "y": 7,
      "z": 10,
      "name": "Rock_Shale_Brick_Ornate"
    },
    {
      "x": -25,
      "y": 8,
      "z": 10,
      "name": "Rock_Shale_Brick_Ornate"
    },
    {
      "x": -25,
      "y": 11,
      "z": 10,
      "name": "Rock_Shale_Brick_Stairs",
      "rotation": 10
    },
    {
      "x": -25,
      "y": 3,
      "z": 11,
      "name": "Rock_Slate"
    },
    {
      "x": -25,
      "y": 4,
      "z": 11,
      "name": "Rock_Slate"
    },
    {
      "x": -25,
      "y": 5,
      "z": 11,
      "name": "Rock_Slate"
    },
    {
      "x": -25,
      "y": 6,
      "z": 11,
      "name": "Rock_Slate"
    },
    {
      "x": -25,
      "y": 4,
      "z": 12,
      "name": "Rock_Slate"
    },
    {
      "x": -25,
      "y": 5,
      "z": 12,
      "name": "Rock_Slate"
    },
    {
      "x": -25,
      "y": 6,
      "z": 12,
      "name": "Rock_Slate"
    },
    {
      "x": -25,
      "y": 6,
      "z": 13,
      "name": "Rock_Slate"
    },
    {
      "x": -24,
      "y": 6,
      "z": -11,
      "name": "Rock_Slate"
    },
    {
      "x": -24,
      "y": 4,
      "z": -10,
      "name": "Rock_Slate"
    },
    {
      "x": -24,
      "y": 5,
      "z": -10,
      "name": "Rock_Slate"
    },
    {
      "x": -24,
      "y": 6,
      "z": -10,
      "name": "Rock_Slate"
    },
    {
      "x": -24,
      "y": 4,
      "z": -9,
      "name": "Rock_Slate"
    },
    {
      "x": -24,
      "y": 5,
      "z": -9,
      "name": "Rock_Slate"
    },
    {
      "x": -24,
      "y": 6,
      "z": -9,
      "name": "Rock_Slate"
    },
    {
      "x": -24,
      "y": 4,
      "z": -8,
      "name": "Rock_Slate"
    },
    {
      "x": -24,
      "y": 5,
      "z": -8,
      "name": "Rock_Slate"
    },
    {
      "x": -24,
      "y": 6,
      "z": -8,
      "name": "Rock_Slate"
    },
    {
      "x": -24,
      "y": 7,
      "z": -8,
      "name": "Rock_Shale_Brick_Ornate"
    },
    {
      "x": -24,
      "y": 8,
      "z": -8,
      "name": "Rock_Shale_Brick_Ornate"
    },
    {
      "x": -24,
      "y": 9,
      "z": -8,
      "name": "Rock_Shale_Brick"
    },
    {
      "x": -24,
      "y": 10,
      "z": -8,
      "name": "Rock_Shale_Brick"
    },
    {
      "x": -24,
      "y": 11,
      "z": -8,
      "name": "Rock_Shale_Brick"
    },
    {
      "x": -24,
      "y": 12,
      "z": -8,
      "name": "Rock_Shale_Brick"
    },
    {
      "x": -24,
      "y": 13,
      "z": -8,
      "name": "Rock_Shale_Brick"
    },
    {
      "x": -24,
      "y": 14,
      "z": -8,
      "name": "Rock_Shale_Brick"
    },
    {
      "x": -24,
      "y": 15,
      "z": -8,
      "name": "Rock_Shale_Brick"
    },
    {
      "x": -24,
      "y": 16,
      "z": -8,
      "name": "Rock_Shale_Brick"
    },
    {
      "x": -24,
      "y": 17,
      "z": -8,
      "name": "Rock_Shale_Brick"
    },
    {
      "x": -24,
      "y": 3,
      "z": -7,
      "name": "Rock_Slate"
    },
    {
      "x": -24,
      "y": 4,
      "z": -7,
      "name": "Rock_Slate"
    },
    {
      "x": -24,
      "y": 5,
      "z": -7,
      "name": "Rock_Slate"
    },
    {
      "x": -24,
      "y": 6,
      "z": -7,
      "name": "Rock_Slate"
    },
    {
      "x": -24,
      "y": 7,
      "z": -7,
      "name": "Rock_Shale_Brick"
    },
    {
      "x": -24,
      "y": 8,
      "z": -7,
      "name": "Rock_Shale_Brick"
    },
    {
      "x": -24,
      "y": 9,
      "z": -7,
      "name": "Rock_Shale_Brick"
    },
    {
      "x": -24,
      "y": 10,
      "z": -7,
      "name": "Rock_Shale_Brick"
    },
    {
      "x": -24,
      "y": 11,
      "z": -7,
      "name": "Rock_Shale_Brick"
    },
    {
      "x": -24,
      "y": 12,
      "z": -7,
      "name": "Rock_Shale_Brick"
    },
    {
      "x": -24,
      "y": 13,
      "z": -7,
      "name": "Rock_Shale_Brick"
    },
    {
      "x": -24,
      "y": 14,
      "z": -7,
      "name": "Rock_Shale_Brick"
    },
    {
      "x": -24,
      "y": 15,
      "z": -7,
      "name": "Rock_Shale_Brick"
    },
    {
      "x": -24,
      "y": 16,
      "z": -7,
      "name": "Rock_Shale_Brick"
    },
    {
      "x": -24,
      "y": 17,
      "z": -7,
      "name": "Rock_Shale_Brick"
    },
    {
      "x": -24,
      "y": 18,
      "z": -7,
      "name": "Rock_Shale_Brick"
    },
    {
      "x": -24,
      "y": 19,
      "z": -7,
      "name": "Rock_Shale_Brick"
    },
    {
      "x": -24,
      "y": 20,
      "z": -7,
      "name": "Rock_Shale_Brick"
    },
    {
      "x": -24,
      "y": 21,
      "z": -7,
      "name": "Rock_Shale_Brick"
    },
    {
      "x": -24,
      "y": 3,
      "z": -6,
      "name": "Rock_Slate"
    },
    {
      "x": -24,
      "y": 4,
      "z": -6,
      "name": "Rock_Slate"
    },
    {
      "x": -24,
      "y": 5,
      "z": -6,
      "name": "Rock_Slate"
    },
    {
      "x": -24,
      "y": 6,
      "z": -6,
      "name": "Rock_Slate"
    },
    {
      "x": -24,
      "y": 7,
      "z": -6,
      "name": "Rock_Shale_Brick_Ornate"
    },
    {
      "x": -24,
      "y": 8,
      "z": -6,
      "name": "Rock_Shale_Brick_Ornate"
    },
    {
      "x": -24,
      "y": 9,
      "z": -6,
      "name": "Rock_Shale_Brick"
    },
    {
      "x": -24,
      "y": 10,
      "z": -6,
      "name": "Rock_Shale_Brick"
    },
    {
      "x": -24,
      "y": 11,
      "z": -6,
      "name": "Rock_Shale_Brick"
    },
    {
      "x": -24,
      "y": 12,
      "z": -6,
      "name": "Rock_Shale_Brick"
    },
    {
      "x": -24,
      "y": 13,
      "z": -6,
      "name": "Rock_Shale_Brick"
    },
    {
      "x": -24,
      "y": 14,
      "z": -6,
      "name": "Furniture_Human_Ruins_Brazier"
    },
    {
      "x": -24,
      "y": 17,
      "z": -6,
      "name": "Rock_Shale_Brick_Stairs",
      "rotation": 10
    },
    {
      "x": -24,
      "y": 18,
      "z": -6,
      "name": "Rock_Shale_Brick"
    },
    {
      "x": -24,
      "y": 19,
      "z": -6,
      "name": "Rock_Shale_Brick"
    },
    {
      "x": -24,
      "y": 20,
      "z": -6,
      "name": "Rock_Shale_Brick"
    },
    {
      "x": -24,
      "y": 21,
      "z": -6,
      "name": "Rock_Shale_Brick"
    },
    {
      "x": -24,
      "y": 22,
      "z": -6,
      "name": "Rock_Shale_Brick"
    },
    {
      "x": -24,
      "y": 2,
      "z": -5,
      "name": "Rock_Slate"
    },
    {
      "x": -24,
      "y": 3,
      "z": -5,
      "name": "Rock_Slate"
    },
    {
      "x": -24,
      "y": 4,
      "z": -5,
      "name": "Rock_Slate"
    },
    {
      "x": -24,
      "y": 5,
      "z": -5,
      "name": "Rock_Slate"
    },
    {
      "x": -24,
      "y": 6,
      "z": -5,
      "name": "Rock_Slate"
    },
    {
      "x": -24,
      "y": 22,
      "z": -5,
      "name": "Rock_Shale_Brick"
    },
    {
      "x": -24,
      "y": 23,
      "z": -5,
      "name": "Rock_Shale_Brick"
    },
    {
      "x": -24,
      "y": 1,
      "z": -4,
      "name": "Rock_Slate"
    },
    {
      "x": -24,
      "y": 2,
      "z": -4,
      "name": "Rock_Slate"
    },
    {
      "x": -24,
      "y": 3,
      "z": -4,
      "name": "Rock_Slate"
    },
    {
      "x": -24,
      "y": 4,
      "z": -4,
      "name": "Rock_Slate"
    },
    {
      "x": -24,
      "y": 5,
      "z": -4,
      "name": "Rock_Slate"
    },
    {
      "x": -24,
      "y": 6,
      "z": -4,
      "name": "Rock_Slate"
    },
    {
      "x": -24,
      "y": 22,
      "z": -4,
      "name": "Rock_Shale_Brick_Stairs",
      "rotation": 10
    },
    {
      "x": -24,
      "y": 23,
      "z": -4,
      "name": "Rock_Shale_Brick"
    },
    {
      "x": -24,
      "y": 24,
      "z": -4,
      "name": "Rock_Shale_Brick"
    },
    {
      "x": -24,
      "y": 2,
      "z": -3,
      "name": "Rock_Slate"
    },
    {
      "x": -24,
      "y": 3,
      "z": -3,
      "name": "Rock_Slate"
    },
    {
      "x": -24,
      "y": 4,
      "z": -3,
      "name": "Rock_Slate"
    },
    {
      "x": -24,
      "y": 5,
      "z": -3,
      "name": "Rock_Slate"
    },
    {
      "x": -24,
      "y": 6,
      "z": -3,
      "name": "Rock_Slate"
    },
    {
      "x": -24,
      "y": 24,
      "z": -3,
      "name": "Rock_Shale_Brick"
    },
    {
      "x": -24,
      "y": 25,
      "z": -3,
      "name": "Rock_Shale_Brick"
    },
    {
      "x": -24,
      "y": 3,
      "z": -2,
      "name": "Rock_Slate"
    },
    {
      "x": -24,
      "y": 4,
      "z": -2,
      "name": "Rock_Slate"
    },
    {
      "x": -24,
      "y": 5,
      "z": -2,
      "name": "Rock_Slate"
    },
    {
      "x": -24,
      "y": 6,
      "z": -2,
      "name": "Rock_Slate"
    },
    {
      "x": -24,
      "y": 24,
      "z": -2,
      "name": "Rock_Shale_Brick"
    },
    {
      "x": -24,
      "y": 25,
      "z": -2,
      "name": "Rock_Shale_Brick"
    },
    {
      "x": -24,
      "y": 1,
      "z": -1,
      "name": "Rock_Slate"
    },
    {
      "x": -24,
      "y": 2,
      "z": -1,
      "name": "Rock_Slate"
    },
    {
      "x": -24,
      "y": 3,
      "z": -1,
      "name": "Rock_Slate"
    },
    {
      "x": -24,
      "y": 4,
      "z": -1,
      "name": "Rock_Slate"
    },
    {
      "x": -24,
      "y": 5,
      "z": -1,
      "name": "Rock_Slate"
    },
    {
      "x": -24,
      "y": 6,
      "z": -1,
      "name": "Rock_Slate"
    },
    {
      "x": -24,
      "y": 25,
      "z": -1,
      "name": "Rock_Shale_Brick"
    },
    {
      "x": -24,
      "y": 26,
      "z": -1,
      "name": "Rock_Shale_Brick"
    },
    {
      "x": -24,
      "y": 2,
      "z": 0,
      "name": "Rock_Slate"
    },
    {
      "x": -24,
      "y": 3,
      "z": 0,
      "name": "Rock_Slate"
    },
    {
      "x": -24,
      "y": 4,
      "z": 0,
      "name": "Rock_Slate"
    },
    {
      "x": -24,
      "y": 5,
      "z": 0,
      "name": "Rock_Slate"
    },
    {
      "x": -24,
      "y": 6,
      "z": 0,
      "name": "Rock_Slate"
    },
    {
      "x": -24,
      "y": 25,
      "z": 0,
      "name": "Rock_Shale_Brick"
    },
    {
      "x": -24,
      "y": 26,
      "z": 0,
      "name": "Rock_Shale_Brick"
    },
    {
      "x": -24,
      "y": 3,
      "z": 1,
      "name": "Rock_Slate"
    },
    {
      "x": -24,
      "y": 4,
      "z": 1,
      "name": "Rock_Slate"
    },
    {
      "x": -24,
      "y": 5,
      "z": 1,
      "name": "Rock_Slate"
    },
    {
      "x": -24,
      "y": 6,
      "z": 1,
      "name": "Rock_Slate"
    },
    {
      "x": -24,
      "y": 26,
      "z": 1,
      "name": "Rock_Shale_Brick"
    },
    {
      "x": -24,
      "y": 2,
      "z": 2,
      "name": "Rock_Slate"
    },
    {
      "x": -24,
      "y": 3,
      "z": 2,
      "name": "Rock_Slate"
    },
    {
      "x": -24,
      "y": 4,
      "z": 2,
      "name": "Rock_Slate"
    },
    {
      "x": -24,
      "y": 5,
      "z": 2,
      "name": "Rock_Slate"
    },
    {
      "x": -24,
      "y": 6,
      "z": 2,
      "name": "Rock_Slate"
    },
    {
      "x": -24,
      "y": 26,
      "z": 2,
      "name": "Rock_Shale_Brick"
    },
    {
      "x": -24,
      "y": 2,
      "z": 3,
      "name": "Rock_Slate"
    },
    {
      "x": -24,
      "y": 3,
      "z": 3,
      "name": "Rock_Slate"
    },
    {
      "x": -24,
      "y": 4,
      "z": 3,
      "name": "Rock_Slate"
    },
    {
      "x": -24,
      "y": 5,
      "z": 3,
      "name": "Rock_Slate"
    },
    {
      "x": -24,
      "y": 6,
      "z": 3,
      "name": "Rock_Slate"
    },
    {
      "x": -24,
      "y": 26,
      "z": 3,
      "name": "Rock_Shale_Brick_Stairs",
      "rotation": 10
    },
    {
      "x": -24,
      "y": 1,
      "z": 4,
      "name": "Rock_Slate"
    },
    {
      "x": -24,
      "y": 2,
      "z": 4,
      "name": "Rock_Slate"
    },
    {
      "x": -24,
      "y": 3,
      "z": 4,
      "name": "Rock_Slate"
    },
    {
      "x": -24,
      "y": 4,
      "z": 4,
      "name": "Rock_Slate"
    },
    {
      "x": -24,
      "y": 5,
      "z": 4,
      "name": "Rock_Slate"
    },
    {
      "x": -24,
      "y": 6,
      "z": 4,
      "name": "Rock_Slate"
    },
    {
      "x": -24,
      "y": 3,
      "z": 5,
      "name": "Rock_Slate"
    },
    {
      "x": -24,
      "y": 4,
      "z": 5,
      "name": "Rock_Slate"
    },
    {
      "x": -24,
      "y": 5,
      "z": 5,
      "name": "Rock_Slate"
    },
    {
      "x": -24,
      "y": 6,
      "z": 5,
      "name": "Rock_Slate"
    },
    {
      "x": -24,
      "y": 2,
      "z": 6,
      "name": "Rock_Slate"
    },
    {
      "x": -24,
      "y": 3,
      "z": 6,
      "name": "Rock_Slate"
    },
    {
      "x": -24,
      "y": 4,
      "z": 6,
      "name": "Rock_Slate"
    },
    {
      "x": -24,
      "y": 5,
      "z": 6,
      "name": "Rock_Slate"
    },
    {
      "x": -24,
      "y": 6,
      "z": 6,
      "name": "Rock_Slate"
    },
    {
      "x": -24,
      "y": 3,
      "z": 7,
      "name": "Rock_Slate"
    },
    {
      "x": -24,
      "y": 4,
      "z": 7,
      "name": "Rock_Slate"
    },
    {
      "x": -24,
      "y": 5,
      "z": 7,
      "name": "Rock_Slate"
    },
    {
      "x": -24,
      "y": 6,
      "z": 7,
      "name": "Rock_Slate"
    },
    {
      "x": -24,
      "y": 23,
      "z": 7,
      "name": "Rock_Shale_Brick"
    },
    {
      "x": -24,
      "y": 3,
      "z": 8,
      "name": "Rock_Slate"
    },
    {
      "x": -24,
      "y": 4,
      "z": 8,
      "name": "Rock_Slate"
    },
    {
      "x": -24,
      "y": 5,
      "z": 8,
      "name": "Rock_Slate"
    },
    {
      "x": -24,
      "y": 6,
      "z": 8,
      "name": "Rock_Slate"
    },
    {
      "x": -24,
      "y": 7,
      "z": 8,
      "name": "Rock_Shale_Brick_Ornate"
    },
    {
      "x": -24,
      "y": 8,
      "z": 8,
      "name": "Rock_Shale_Brick_Ornate"
    },
    {
      "x": -24,
      "y": 9,
      "z": 8,
      "name": "Rock_Shale_Brick"
    },
    {
      "x": -24,
      "y": 10,
      "z": 8,
      "name": "Rock_Shale_Brick"
    },
    {
      "x": -24,
      "y": 11,
      "z": 8,
      "name": "Rock_Shale_Brick"
    },
    {
      "x": -24,
      "y": 12,
      "z": 8,
      "name": "Rock_Shale_Brick"
    },
    {
      "x": -24,
      "y": 13,
      "z": 8,
      "name": "Rock_Shale_Brick"
    },
    {
      "x": -24,
      "y": 14,
      "z": 8,
      "name": "Furniture_Human_Ruins_Brazier"
    },
    {
      "x": -24,
      "y": 21,
      "z": 8,
      "name": "Rock_Shale_Brick"
    },
    {
      "x": -24,
      "y": 22,
      "z": 8,
      "name": "Rock_Shale_Brick"
    },
    {
      "x": -24,
      "y": 2,
      "z": 9,
      "name": "Rock_Slate"
    },
    {
      "x": -24,
      "y": 3,
      "z": 9,
      "name": "Rock_Slate"
    },
    {
      "x": -24,
      "y": 4,
      "z": 9,
      "name": "Rock_Slate"
    },
    {
      "x": -24,
      "y": 5,
      "z": 9,
      "name": "Rock_Slate"
    },
    {
      "x": -24,
      "y": 6,
      "z": 9,
      "name": "Rock_Slate"
    },
    {
      "x": -24,
      "y": 7,
      "z": 9,
      "name": "Rock_Shale_Brick"
    },
    {
      "x": -24,
      "y": 8,
      "z": 9,
      "name": "Rock_Shale_Brick"
    },
    {
      "x": -24,
      "y": 9,
      "z": 9,
      "name": "Rock_Shale_Brick"
    },
    {
      "x": -24,
      "y": 10,
      "z": 9,
      "name": "Rock_Shale_Brick"
    },
    {
      "x": -24,
      "y": 11,
      "z": 9,
      "name": "Rock_Shale_Brick"
    },
    {
      "x": -24,
      "y": 12,
      "z": 9,
      "name": "Rock_Shale_Brick"
    },
    {
      "x": -24,
      "y": 13,
      "z": 9,
      "name": "Rock_Shale_Brick"
    },
    {
      "x": -24,
      "y": 14,
      "z": 9,
      "name": "Rock_Shale_Brick"
    },
    {
      "x": -24,
      "y": 15,
      "z": 9,
      "name": "Rock_Shale_Brick"
    },
    {
      "x": -24,
      "y": 16,
      "z": 9,
      "name": "Rock_Shale_Brick"
    },
    {
      "x": -24,
      "y": 17,
      "z": 9,
      "name": "Rock_Shale_Brick"
    },
    {
      "x": -24,
      "y": 18,
      "z": 9,
      "name": "Rock_Shale_Brick"
    },
    {
      "x": -24,
      "y": 19,
      "z": 9,
      "name": "Rock_Shale_Brick"
    },
    {
      "x": -24,
      "y": 20,
      "z": 9,
      "name": "Rock_Shale_Brick"
    },
    {
      "x": -24,
      "y": 21,
      "z": 9,
      "name": "Rock_Shale_Brick"
    },
    {
      "x": -24,
      "y": 3,
      "z": 10,
      "name": "Rock_Slate"
    },
    {
      "x": -24,
      "y": 4,
      "z": 10,
      "name": "Rock_Slate"
    },
    {
      "x": -24,
      "y": 5,
      "z": 10,
      "name": "Rock_Slate"
    },
    {
      "x": -24,
      "y": 6,
      "z": 10,
      "name": "Rock_Slate"
    },
    {
      "x": -24,
      "y": 7,
      "z": 10,
      "name": "Rock_Shale_Brick_Ornate"
    },
    {
      "x": -24,
      "y": 8,
      "z": 10,
      "name": "Rock_Shale_Brick_Ornate"
    },
    {
      "x": -24,
      "y": 9,
      "z": 10,
      "name": "Rock_Shale_Brick"
    },
    {
      "x": -24,
      "y": 10,
      "z": 10,
      "name": "Rock_Shale_Brick"
    },
    {
      "x": -24,
      "y": 11,
      "z": 10,
      "name": "Rock_Shale_Brick"
    },
    {
      "x": -24,
      "y": 12,
      "z": 10,
      "name": "Rock_Shale_Brick"
    },
    {
      "x": -24,
      "y": 13,
      "z": 10,
      "name": "Rock_Shale_Brick"
    },
    {
      "x": -24,
      "y": 14,
      "z": 10,
      "name": "Rock_Shale_Brick"
    },
    {
      "x": -24,
      "y": 15,
      "z": 10,
      "name": "Rock_Shale_Brick"
    },
    {
      "x": -24,
      "y": 16,
      "z": 10,
      "name": "Rock_Shale_Brick"
    },
    {
      "x": -24,
      "y": 17,
      "z": 10,
      "name": "Rock_Shale_Brick"
    },
    {
      "x": -24,
      "y": 18,
      "z": 10,
      "name": "Rock_Shale_Brick"
    },
    {
      "x": -24,
      "y": 19,
      "z": 10,
      "name": "Rock_Shale_Brick"
    },
    {
      "x": -24,
      "y": 3,
      "z": 11,
      "name": "Rock_Slate"
    },
    {
      "x": -24,
      "y": 4,
      "z": 11,
      "name": "Rock_Slate"
    },
    {
      "x": -24,
      "y": 5,
      "z": 11,
      "name": "Rock_Slate"
    },
    {
      "x": -24,
      "y": 6,
      "z": 11,
      "name": "Rock_Slate"
    },
    {
      "x": -24,
      "y": 3,
      "z": 12,
      "name": "Rock_Slate"
    },
    {
      "x": -24,
      "y": 4,
      "z": 12,
      "name": "Rock_Slate"
    },
    {
      "x": -24,
      "y": 5,
      "z": 12,
      "name": "Rock_Slate"
    },
    {
      "x": -24,
      "y": 6,
      "z": 12,
      "name": "Rock_Slate"
    },
    {
      "x": -24,
      "y": 5,
      "z": 13,
      "name": "Rock_Slate"
    },
    {
      "x": -24,
      "y": 6,
      "z": 13,
      "name": "Rock_Slate"
    },
    {
      "x": -23,
      "y": 3,
      "z": -10,
      "name": "Rock_Slate"
    },
    {
      "x": -23,
      "y": 4,
      "z": -10,
      "name": "Rock_Slate"
    },
    {
      "x": -23,
      "y": 5,
      "z": -10,
      "name": "Rock_Slate"
    },
    {
      "x": -23,
      "y": 6,
      "z": -10,
      "name": "Rock_Slate"
    },
    {
      "x": -23,
      "y": 4,
      "z": -9,
      "name": "Rock_Slate"
    },
    {
      "x": -23,
      "y": 5,
      "z": -9,
      "name": "Rock_Slate"
    },
    {
      "x": -23,
      "y": 6,
      "z": -9,
      "name": "Rock_Slate"
    },
    {
      "x": -23,
      "y": 3,
      "z": -8,
      "name": "Rock_Slate"
    },
    {
      "x": -23,
      "y": 4,
      "z": -8,
      "name": "Rock_Slate"
    },
    {
      "x": -23,
      "y": 5,
      "z": -8,
      "name": "Rock_Slate"
    },
    {
      "x": -23,
      "y": 6,
      "z": -8,
      "name": "Rock_Slate"
    },
    {
      "x": -23,
      "y": 7,
      "z": -8,
      "name": "Rock_Shale_Brick_Ornate"
    },
    {
      "x": -23,
      "y": 8,
      "z": -8,
      "name": "Rock_Shale_Brick_Ornate"
    },
    {
      "x": -23,
      "y": 11,
      "z": -8,
      "name": "Rock_Shale_Brick_Stairs",
      "rotation": 8
    },
    {
      "x": -23,
      "y": 2,
      "z": -7,
      "name": "Rock_Slate"
    },
    {
      "x": -23,
      "y": 3,
      "z": -7,
      "name": "Rock_Slate"
    },
    {
      "x": -23,
      "y": 4,
      "z": -7,
      "name": "Rock_Slate"
    },
    {
      "x": -23,
      "y": 5,
      "z": -7,
      "name": "Rock_Slate"
    },
    {
      "x": -23,
      "y": 6,
      "z": -7,
      "name": "Rock_Slate"
    },
    {
      "x": -23,
      "y": 7,
      "z": -7,
      "name": "Rock_Shale_Brick_Ornate"
    },
    {
      "x": -23,
      "y": 8,
      "z": -7,
      "name": "Rock_Shale_Brick_Ornate"
    },
    {
      "x": -23,
      "y": 9,
      "z": -7,
      "name": "Rock_Shale_Brick"
    },
    {
      "x": -23,
      "y": 10,
      "z": -7,
      "name": "Rock_Shale_Brick"
    },
    {
      "x": -23,
      "y": 11,
      "z": -7,
      "name": "Rock_Shale_Brick"
    },
    {
      "x": -23,
      "y": 12,
      "z": -7,
      "name": "Rock_Shale_Brick"
    },
    {
      "x": -23,
      "y": 13,
      "z": -7,
      "name": "Rock_Shale_Brick"
    },
    {
      "x": -23,
      "y": 21,
      "z": -7,
      "name": "Rock_Shale_Brick"
    },
    {
      "x": -23,
      "y": 22,
      "z": -7,
      "name": "Rock_Shale_Brick"
    },
    {
      "x": -23,
      "y": 1,
      "z": -6,
      "name": "Rock_Slate"
    },
    {
      "x": -23,
      "y": 2,
      "z": -6,
      "name": "Rock_Slate"
    },
    {
      "x": -23,
      "y": 3,
      "z": -6,
      "name": "Rock_Slate"
    },
    {
      "x": -23,
      "y": 4,
      "z": -6,
      "name": "Rock_Slate"
    },
    {
      "x": -23,
      "y": 5,
      "z": -6,
      "name": "Rock_Slate"
    },
    {
      "x": -23,
      "y": 6,
      "z": -6,
      "name": "Rock_Slate"
    },
    {
      "x": -23,
      "y": 7,
      "z": -6,
      "name": "Rock_Shale_Brick_Ornate"
    },
    {
      "x": -23,
      "y": 8,
      "z": -6,
      "name": "Rock_Shale_Brick_Ornate"
    },
    {
      "x": -23,
      "y": 11,
      "z": -6,
      "name": "Rock_Shale_Brick_Stairs",
      "rotation": 10
    },
    {
      "x": -23,
      "y": 2,
      "z": -5,
      "name": "Rock_Slate"
    },
    {
      "x": -23,
      "y": 3,
      "z": -5,
      "name": "Rock_Slate"
    },
    {
      "x": -23,
      "y": 4,
      "z": -5,
      "name": "Rock_Slate"
    },
    {
      "x": -23,
      "y": 5,
      "z": -5,
      "name": "Rock_Slate"
    },
    {
      "x": -23,
      "y": 6,
      "z": -5,
      "name": "Rock_Slate"
    },
    {
      "x": -23,
      "y": 3,
      "z": -4,
      "name": "Rock_Slate"
    },
    {
      "x": -23,
      "y": 4,
      "z": -4,
      "name": "Rock_Slate"
    },
    {
      "x": -23,
      "y": 5,
      "z": -4,
      "name": "Rock_Slate"
    },
    {
      "x": -23,
      "y": 6,
      "z": -4,
      "name": "Rock_Slate"
    },
    {
      "x": -23,
      "y": 2,
      "z": -3,
      "name": "Rock_Slate"
    },
    {
      "x": -23,
      "y": 3,
      "z": -3,
      "name": "Rock_Slate"
    },
    {
      "x": -23,
      "y": 4,
      "z": -3,
      "name": "Rock_Slate"
    },
    {
      "x": -23,
      "y": 5,
      "z": -3,
      "name": "Rock_Slate"
    },
    {
      "x": -23,
      "y": 6,
      "z": -3,
      "name": "Rock_Slate"
    },
    {
      "x": -23,
      "y": 3,
      "z": -2,
      "name": "Rock_Slate"
    },
    {
      "x": -23,
      "y": 4,
      "z": -2,
      "name": "Rock_Slate"
    },
    {
      "x": -23,
      "y": 5,
      "z": -2,
      "name": "Rock_Slate"
    },
    {
      "x": -23,
      "y": 6,
      "z": -2,
      "name": "Rock_Slate"
    },
    {
      "x": -23,
      "y": 3,
      "z": -1,
      "name": "Rock_Slate"
    },
    {
      "x": -23,
      "y": 4,
      "z": -1,
      "name": "Rock_Slate"
    },
    {
      "x": -23,
      "y": 5,
      "z": -1,
      "name": "Rock_Slate"
    },
    {
      "x": -23,
      "y": 6,
      "z": -1,
      "name": "Rock_Slate"
    },
    {
      "x": -23,
      "y": 3,
      "z": 0,
      "name": "Rock_Slate"
    },
    {
      "x": -23,
      "y": 4,
      "z": 0,
      "name": "Rock_Slate"
    },
    {
      "x": -23,
      "y": 5,
      "z": 0,
      "name": "Rock_Slate"
    },
    {
      "x": -23,
      "y": 6,
      "z": 0,
      "name": "Rock_Slate"
    },
    {
      "x": -23,
      "y": 3,
      "z": 1,
      "name": "Rock_Slate"
    },
    {
      "x": -23,
      "y": 4,
      "z": 1,
      "name": "Rock_Slate"
    },
    {
      "x": -23,
      "y": 5,
      "z": 1,
      "name": "Rock_Slate"
    },
    {
      "x": -23,
      "y": 6,
      "z": 1,
      "name": "Rock_Slate"
    },
    {
      "x": -23,
      "y": 1,
      "z": 2,
      "name": "Rock_Slate"
    },
    {
      "x": -23,
      "y": 2,
      "z": 2,
      "name": "Rock_Slate"
    },
    {
      "x": -23,
      "y": 3,
      "z": 2,
      "name": "Rock_Slate"
    },
    {
      "x": -23,
      "y": 4,
      "z": 2,
      "name": "Rock_Slate"
    },
    {
      "x": -23,
      "y": 5,
      "z": 2,
      "name": "Rock_Slate"
    },
    {
      "x": -23,
      "y": 6,
      "z": 2,
      "name": "Rock_Slate"
    },
    {
      "x": -23,
      "y": 2,
      "z": 3,
      "name": "Rock_Slate"
    },
    {
      "x": -23,
      "y": 3,
      "z": 3,
      "name": "Rock_Slate"
    },
    {
      "x": -23,
      "y": 4,
      "z": 3,
      "name": "Rock_Slate"
    },
    {
      "x": -23,
      "y": 5,
      "z": 3,
      "name": "Rock_Slate"
    },
    {
      "x": -23,
      "y": 6,
      "z": 3,
      "name": "Rock_Slate"
    },
    {
      "x": -23,
      "y": 3,
      "z": 4,
      "name": "Rock_Slate"
    },
    {
      "x": -23,
      "y": 4,
      "z": 4,
      "name": "Rock_Slate"
    },
    {
      "x": -23,
      "y": 5,
      "z": 4,
      "name": "Rock_Slate"
    },
    {
      "x": -23,
      "y": 6,
      "z": 4,
      "name": "Rock_Slate"
    },
    {
      "x": -23,
      "y": 2,
      "z": 5,
      "name": "Rock_Slate"
    },
    {
      "x": -23,
      "y": 3,
      "z": 5,
      "name": "Rock_Slate"
    },
    {
      "x": -23,
      "y": 4,
      "z": 5,
      "name": "Rock_Slate"
    },
    {
      "x": -23,
      "y": 5,
      "z": 5,
      "name": "Rock_Slate"
    },
    {
      "x": -23,
      "y": 6,
      "z": 5,
      "name": "Rock_Slate"
    },
    {
      "x": -23,
      "y": 3,
      "z": 6,
      "name": "Rock_Slate"
    },
    {
      "x": -23,
      "y": 4,
      "z": 6,
      "name": "Rock_Slate"
    },
    {
      "x": -23,
      "y": 5,
      "z": 6,
      "name": "Rock_Slate"
    },
    {
      "x": -23,
      "y": 6,
      "z": 6,
      "name": "Rock_Slate"
    },
    {
      "x": -23,
      "y": 2,
      "z": 7,
      "name": "Rock_Slate"
    },
    {
      "x": -23,
      "y": 3,
      "z": 7,
      "name": "Rock_Slate"
    },
    {
      "x": -23,
      "y": 4,
      "z": 7,
      "name": "Rock_Slate"
    },
    {
      "x": -23,
      "y": 5,
      "z": 7,
      "name": "Rock_Slate"
    },
    {
      "x": -23,
      "y": 6,
      "z": 7,
      "name": "Rock_Slate"
    },
    {
      "x": -23,
      "y": 2,
      "z": 8,
      "name": "Rock_Slate"
    },
    {
      "x": -23,
      "y": 3,
      "z": 8,
      "name": "Rock_Slate"
    },
    {
      "x": -23,
      "y": 4,
      "z": 8,
      "name": "Rock_Slate"
    },
    {
      "x": -23,
      "y": 5,
      "z": 8,
      "name": "Rock_Slate"
    },
    {
      "x": -23,
      "y": 6,
      "z": 8,
      "name": "Rock_Slate"
    },
    {
      "x": -23,
      "y": 7,
      "z": 8,
      "name": "Rock_Shale_Brick_Ornate"
    },
    {
      "x": -23,
      "y": 8,
      "z": 8,
      "name": "Rock_Shale_Brick_Ornate"
    },
    {
      "x": -23,
      "y": 11,
      "z": 8,
      "name": "Rock_Shale_Brick_Stairs",
      "rotation": 8
    },
    {
      "x": -23,
      "y": 3,
      "z": 9,
      "name": "Rock_Slate"
    },
    {
      "x": -23,
      "y": 4,
      "z": 9,
      "name": "Rock_Slate"
    },
    {
      "x": -23,
      "y": 5,
      "z": 9,
      "name": "Rock_Slate"
    },
    {
      "x": -23,
      "y": 6,
      "z": 9,
      "name": "Rock_Slate"
    },
    {
      "x": -23,
      "y": 7,
      "z": 9,
      "name": "Rock_Shale_Brick_Ornate"
    },
    {
      "x": -23,
      "y": 8,
      "z": 9,
      "name": "Rock_Shale_Brick_Ornate"
    },
    {
      "x": -23,
      "y": 9,
      "z": 9,
      "name": "Rock_Shale_Brick"
    },
    {
      "x": -23,
      "y": 10,
      "z": 9,
      "name": "Rock_Shale_Brick"
    },
    {
      "x": -23,
      "y": 11,
      "z": 9,
      "name": "Rock_Shale_Brick"
    },
    {
      "x": -23,
      "y": 12,
      "z": 9,
      "name": "Rock_Shale_Brick"
    },
    {
      "x": -23,
      "y": 13,
      "z": 9,
      "name": "Rock_Shale_Brick"
    },
    {
      "x": -23,
      "y": 14,
      "z": 9,
      "name": "Rock_Shale_Brick"
    },
    {
      "x": -23,
      "y": 15,
      "z": 9,
      "name": "Rock_Shale_Brick"
    },
    {
      "x": -23,
      "y": 21,
      "z": 9,
      "name": "Rock_Shale_Brick"
    },
    {
      "x": -23,
      "y": 22,
      "z": 9,
      "name": "Rock_Shale_Brick"
    },
    {
      "x": -23,
      "y": 2,
      "z": 10,
      "name": "Rock_Slate"
    },
    {
      "x": -23,
      "y": 3,
      "z": 10,
      "name": "Rock_Slate"
    },
    {
      "x": -23,
      "y": 4,
      "z": 10,
      "name": "Rock_Slate"
    },
    {
      "x": -23,
      "y": 5,
      "z": 10,
      "name": "Rock_Slate"
    },
    {
      "x": -23,
      "y": 6,
      "z": 10,
      "name": "Rock_Slate"
    },
    {
      "x": -23,
      "y": 7,
      "z": 10,
      "name": "Rock_Shale_Brick_Ornate"
    },
    {
      "x": -23,
      "y": 8,
      "z": 10,
      "name": "Rock_Shale_Brick_Ornate"
    },
    {
      "x": -23,
      "y": 11,
      "z": 10,
      "name": "Rock_Shale_Brick_Stairs",
      "rotation": 10
    },
    {
      "x": -23,
      "y": 3,
      "z": 11,
      "name": "Rock_Slate"
    },
    {
      "x": -23,
      "y": 4,
      "z": 11,
      "name": "Rock_Slate"
    },
    {
      "x": -23,
      "y": 5,
      "z": 11,
      "name": "Rock_Slate"
    },
    {
      "x": -23,
      "y": 6,
      "z": 11,
      "name": "Rock_Slate"
    },
    {
      "x": -23,
      "y": 3,
      "z": 12,
      "name": "Rock_Slate"
    },
    {
      "x": -23,
      "y": 4,
      "z": 12,
      "name": "Rock_Slate"
    },
    {
      "x": -23,
      "y": 5,
      "z": 12,
      "name": "Rock_Slate"
    },
    {
      "x": -23,
      "y": 6,
      "z": 12,
      "name": "Rock_Slate"
    },
    {
      "x": -23,
      "y": 5,
      "z": 13,
      "name": "Rock_Slate"
    },
    {
      "x": -23,
      "y": 6,
      "z": 13,
      "name": "Rock_Slate"
    },
    {
      "x": -23,
      "y": 5,
      "z": 14,
      "name": "Rock_Slate"
    },
    {
      "x": -22,
      "y": 4,
      "z": -10,
      "name": "Rock_Slate"
    },
    {
      "x": -22,
      "y": 5,
      "z": -10,
      "name": "Rock_Slate"
    },
    {
      "x": -22,
      "y": 3,
      "z": -9,
      "name": "Rock_Slate"
    },
    {
      "x": -22,
      "y": 4,
      "z": -9,
      "name": "Rock_Slate"
    },
    {
      "x": -22,
      "y": 5,
      "z": -9,
      "name": "Rock_Slate"
    },
    {
      "x": -22,
      "y": 6,
      "z": -9,
      "name": "Rock_Slate"
    },
    {
      "x": -22,
      "y": 2,
      "z": -8,
      "name": "Rock_Slate"
    },
    {
      "x": -22,
      "y": 3,
      "z": -8,
      "name": "Rock_Slate"
    },
    {
      "x": -22,
      "y": 4,
      "z": -8,
      "name": "Rock_Slate"
    },
    {
      "x": -22,
      "y": 5,
      "z": -8,
      "name": "Rock_Slate"
    },
    {
      "x": -22,
      "y": 6,
      "z": -8,
      "name": "Rock_Slate"
    },
    {
      "x": -22,
      "y": 2,
      "z": -7,
      "name": "Rock_Slate"
    },
    {
      "x": -22,
      "y": 3,
      "z": -7,
      "name": "Rock_Slate"
    },
    {
      "x": -22,
      "y": 4,
      "z": -7,
      "name": "Rock_Slate"
    },
    {
      "x": -22,
      "y": 5,
      "z": -7,
      "name": "Rock_Slate"
    },
    {
      "x": -22,
      "y": 6,
      "z": -7,
      "name": "Rock_Slate"
    },
    {
      "x": -22,
      "y": 7,
      "z": -7,
      "name": "Rock_Shale_Brick"
    },
    {
      "x": -22,
      "y": 8,
      "z": -7,
      "name": "Rock_Shale_Brick_Wall"
    },
    {
      "x": -22,
      "y": 23,
      "z": -7,
      "name": "Rock_Shale_Brick"
    },
    {
      "x": -22,
      "y": 24,
      "z": -7,
      "name": "Rock_Shale_Brick"
    },
    {
      "x": -22,
      "y": 2,
      "z": -6,
      "name": "Rock_Slate"
    },
    {
      "x": -22,
      "y": 3,
      "z": -6,
      "name": "Rock_Slate"
    },
    {
      "x": -22,
      "y": 4,
      "z": -6,
      "name": "Rock_Slate"
    },
    {
      "x": -22,
      "y": 5,
      "z": -6,
      "name": "Rock_Slate"
    },
    {
      "x": -22,
      "y": 6,
      "z": -6,
      "name": "Rock_Slate"
    },
    {
      "x": -22,
      "y": 2,
      "z": -5,
      "name": "Rock_Slate"
    },
    {
      "x": -22,
      "y": 3,
      "z": -5,
      "name": "Rock_Slate"
    },
    {
      "x": -22,
      "y": 4,
      "z": -5,
      "name": "Rock_Slate"
    },
    {
      "x": -22,
      "y": 5,
      "z": -5,
      "name": "Rock_Slate"
    },
    {
      "x": -22,
      "y": 6,
      "z": -5,
      "name": "Rock_Slate"
    },
    {
      "x": -22,
      "y": 3,
      "z": -4,
      "name": "Rock_Slate"
    },
    {
      "x": -22,
      "y": 4,
      "z": -4,
      "name": "Rock_Slate"
    },
    {
      "x": -22,
      "y": 5,
      "z": -4,
      "name": "Rock_Slate"
    },
    {
      "x": -22,
      "y": 6,
      "z": -4,
      "name": "Rock_Slate"
    },
    {
      "x": -22,
      "y": 3,
      "z": -3,
      "name": "Rock_Slate"
    },
    {
      "x": -22,
      "y": 4,
      "z": -3,
      "name": "Rock_Slate"
    },
    {
      "x": -22,
      "y": 5,
      "z": -3,
      "name": "Rock_Slate"
    },
    {
      "x": -22,
      "y": 6,
      "z": -3,
      "name": "Rock_Slate"
    },
    {
      "x": -22,
      "y": 1,
      "z": -2,
      "name": "Rock_Slate"
    },
    {
      "x": -22,
      "y": 2,
      "z": -2,
      "name": "Rock_Slate"
    },
    {
      "x": -22,
      "y": 3,
      "z": -2,
      "name": "Rock_Slate"
    },
    {
      "x": -22,
      "y": 4,
      "z": -2,
      "name": "Rock_Slate"
    },
    {
      "x": -22,
      "y": 5,
      "z": -2,
      "name": "Rock_Slate"
    },
    {
      "x": -22,
      "y": 6,
      "z": -2,
      "name": "Rock_Slate"
    },
    {
      "x": -22,
      "y": 3,
      "z": -1,
      "name": "Rock_Slate"
    },
    {
      "x": -22,
      "y": 4,
      "z": -1,
      "name": "Rock_Slate"
    },
    {
      "x": -22,
      "y": 5,
      "z": -1,
      "name": "Rock_Slate"
    },
    {
      "x": -22,
      "y": 6,
      "z": -1,
      "name": "Rock_Slate"
    },
    {
      "x": -22,
      "y": 2,
      "z": 0,
      "name": "Rock_Slate"
    },
    {
      "x": -22,
      "y": 3,
      "z": 0,
      "name": "Rock_Slate"
    },
    {
      "x": -22,
      "y": 4,
      "z": 0,
      "name": "Rock_Slate"
    },
    {
      "x": -22,
      "y": 5,
      "z": 0,
      "name": "Rock_Slate"
    },
    {
      "x": -22,
      "y": 6,
      "z": 0,
      "name": "Rock_Slate"
    },
    {
      "x": -22,
      "y": 1,
      "z": 1,
      "name": "Rock_Slate"
    },
    {
      "x": -22,
      "y": 2,
      "z": 1,
      "name": "Rock_Slate"
    },
    {
      "x": -22,
      "y": 3,
      "z": 1,
      "name": "Rock_Slate"
    },
    {
      "x": -22,
      "y": 4,
      "z": 1,
      "name": "Rock_Slate"
    },
    {
      "x": -22,
      "y": 5,
      "z": 1,
      "name": "Rock_Slate"
    },
    {
      "x": -22,
      "y": 6,
      "z": 1,
      "name": "Rock_Slate"
    },
    {
      "x": -22,
      "y": 3,
      "z": 2,
      "name": "Rock_Slate"
    },
    {
      "x": -22,
      "y": 4,
      "z": 2,
      "name": "Rock_Slate"
    },
    {
      "x": -22,
      "y": 5,
      "z": 2,
      "name": "Rock_Slate"
    },
    {
      "x": -22,
      "y": 6,
      "z": 2,
      "name": "Rock_Slate"
    },
    {
      "x": -22,
      "y": 2,
      "z": 3,
      "name": "Rock_Slate"
    },
    {
      "x": -22,
      "y": 3,
      "z": 3,
      "name": "Rock_Slate"
    },
    {
      "x": -22,
      "y": 4,
      "z": 3,
      "name": "Rock_Slate"
    },
    {
      "x": -22,
      "y": 5,
      "z": 3,
      "name": "Rock_Slate"
    },
    {
      "x": -22,
      "y": 6,
      "z": 3,
      "name": "Rock_Slate"
    },
    {
      "x": -22,
      "y": 3,
      "z": 4,
      "name": "Rock_Slate"
    },
    {
      "x": -22,
      "y": 4,
      "z": 4,
      "name": "Rock_Slate"
    },
    {
      "x": -22,
      "y": 5,
      "z": 4,
      "name": "Rock_Slate"
    },
    {
      "x": -22,
      "y": 6,
      "z": 4,
      "name": "Rock_Slate"
    },
    {
      "x": -22,
      "y": 2,
      "z": 5,
      "name": "Rock_Slate"
    },
    {
      "x": -22,
      "y": 3,
      "z": 5,
      "name": "Rock_Slate"
    },
    {
      "x": -22,
      "y": 4,
      "z": 5,
      "name": "Rock_Slate"
    },
    {
      "x": -22,
      "y": 5,
      "z": 5,
      "name": "Rock_Slate"
    },
    {
      "x": -22,
      "y": 6,
      "z": 5,
      "name": "Rock_Slate"
    },
    {
      "x": -22,
      "y": 3,
      "z": 6,
      "name": "Rock_Slate"
    },
    {
      "x": -22,
      "y": 4,
      "z": 6,
      "name": "Rock_Slate"
    },
    {
      "x": -22,
      "y": 5,
      "z": 6,
      "name": "Rock_Slate"
    },
    {
      "x": -22,
      "y": 6,
      "z": 6,
      "name": "Rock_Slate"
    },
    {
      "x": -22,
      "y": 2,
      "z": 7,
      "name": "Rock_Slate"
    },
    {
      "x": -22,
      "y": 3,
      "z": 7,
      "name": "Rock_Slate"
    },
    {
      "x": -22,
      "y": 4,
      "z": 7,
      "name": "Rock_Slate"
    },
    {
      "x": -22,
      "y": 5,
      "z": 7,
      "name": "Rock_Slate"
    },
    {
      "x": -22,
      "y": 6,
      "z": 7,
      "name": "Rock_Slate"
    },
    {
      "x": -22,
      "y": 1,
      "z": 8,
      "name": "Rock_Slate"
    },
    {
      "x": -22,
      "y": 2,
      "z": 8,
      "name": "Rock_Slate"
    },
    {
      "x": -22,
      "y": 3,
      "z": 8,
      "name": "Rock_Slate"
    },
    {
      "x": -22,
      "y": 4,
      "z": 8,
      "name": "Rock_Slate"
    },
    {
      "x": -22,
      "y": 5,
      "z": 8,
      "name": "Rock_Slate"
    },
    {
      "x": -22,
      "y": 6,
      "z": 8,
      "name": "Rock_Slate"
    },
    {
      "x": -22,
      "y": 2,
      "z": 9,
      "name": "Rock_Slate"
    },
    {
      "x": -22,
      "y": 3,
      "z": 9,
      "name": "Rock_Slate"
    },
    {
      "x": -22,
      "y": 4,
      "z": 9,
      "name": "Rock_Slate"
    },
    {
      "x": -22,
      "y": 5,
      "z": 9,
      "name": "Rock_Slate"
    },
    {
      "x": -22,
      "y": 6,
      "z": 9,
      "name": "Rock_Slate"
    },
    {
      "x": -22,
      "y": 7,
      "z": 9,
      "name": "Rock_Shale_Brick"
    },
    {
      "x": -22,
      "y": 8,
      "z": 9,
      "name": "Rock_Shale_Brick_Wall"
    },
    {
      "x": -22,
      "y": 23,
      "z": 9,
      "name": "Rock_Shale_Brick"
    },
    {
      "x": -22,
      "y": 24,
      "z": 9,
      "name": "Rock_Shale_Brick"
    },
    {
      "x": -22,
      "y": 3,
      "z": 10,
      "name": "Rock_Slate"
    },
    {
      "x": -22,
      "y": 4,
      "z": 10,
      "name": "Rock_Slate"
    },
    {
      "x": -22,
      "y": 5,
      "z": 10,
      "name": "Rock_Slate"
    },
    {
      "x": -22,
      "y": 6,
      "z": 10,
      "name": "Rock_Slate"
    },
    {
      "x": -22,
      "y": 3,
      "z": 11,
      "name": "Rock_Slate"
    },
    {
      "x": -22,
      "y": 4,
      "z": 11,
      "name": "Rock_Slate"
    },
    {
      "x": -22,
      "y": 5,
      "z": 11,
      "name": "Rock_Slate"
    },
    {
      "x": -22,
      "y": 6,
      "z": 11,
      "name": "Rock_Slate"
    },
    {
      "x": -22,
      "y": 3,
      "z": 12,
      "name": "Rock_Slate"
    },
    {
      "x": -22,
      "y": 4,
      "z": 12,
      "name": "Rock_Slate"
    },
    {
      "x": -22,
      "y": 5,
      "z": 12,
      "name": "Rock_Slate"
    },
    {
      "x": -22,
      "y": 6,
      "z": 12,
      "name": "Rock_Slate"
    },
    {
      "x": -22,
      "y": 6,
      "z": 13,
      "name": "Rock_Slate"
    },
    {
      "x": -22,
      "y": 6,
      "z": 14,
      "name": "Rock_Slate"
    },
    {
      "x": -21,
      "y": 5,
      "z": -11,
      "name": "Rock_Slate"
    },
    {
      "x": -21,
      "y": 6,
      "z": -11,
      "name": "Rock_Slate"
    },
    {
      "x": -21,
      "y": 4,
      "z": -10,
      "name": "Rock_Slate"
    },
    {
      "x": -21,
      "y": 5,
      "z": -10,
      "name": "Rock_Slate"
    },
    {
      "x": -21,
      "y": 6,
      "z": -10,
      "name": "Rock_Slate"
    },
    {
      "x": -21,
      "y": 3,
      "z": -9,
      "name": "Rock_Slate"
    },
    {
      "x": -21,
      "y": 4,
      "z": -9,
      "name": "Rock_Slate"
    },
    {
      "x": -21,
      "y": 5,
      "z": -9,
      "name": "Rock_Slate"
    },
    {
      "x": -21,
      "y": 6,
      "z": -9,
      "name": "Rock_Slate"
    },
    {
      "x": -21,
      "y": 2,
      "z": -8,
      "name": "Rock_Slate"
    },
    {
      "x": -21,
      "y": 3,
      "z": -8,
      "name": "Rock_Slate"
    },
    {
      "x": -21,
      "y": 4,
      "z": -8,
      "name": "Rock_Slate"
    },
    {
      "x": -21,
      "y": 5,
      "z": -8,
      "name": "Rock_Slate"
    },
    {
      "x": -21,
      "y": 6,
      "z": -8,
      "name": "Rock_Slate"
    },
    {
      "x": -21,
      "y": 2,
      "z": -7,
      "name": "Rock_Slate"
    },
    {
      "x": -21,
      "y": 3,
      "z": -7,
      "name": "Rock_Slate"
    },
    {
      "x": -21,
      "y": 4,
      "z": -7,
      "name": "Rock_Slate"
    },
    {
      "x": -21,
      "y": 5,
      "z": -7,
      "name": "Rock_Slate"
    },
    {
      "x": -21,
      "y": 6,
      "z": -7,
      "name": "Rock_Slate"
    },
    {
      "x": -21,
      "y": 7,
      "z": -7,
      "name": "Rock_Shale_Brick"
    },
    {
      "x": -21,
      "y": 3,
      "z": -6,
      "name": "Rock_Slate"
    },
    {
      "x": -21,
      "y": 4,
      "z": -6,
      "name": "Rock_Slate"
    },
    {
      "x": -21,
      "y": 5,
      "z": -6,
      "name": "Rock_Slate"
    },
    {
      "x": -21,
      "y": 6,
      "z": -6,
      "name": "Rock_Slate"
    },
    {
      "x": -21,
      "y": 2,
      "z": -5,
      "name": "Rock_Slate"
    },
    {
      "x": -21,
      "y": 3,
      "z": -5,
      "name": "Rock_Slate"
    },
    {
      "x": -21,
      "y": 4,
      "z": -5,
      "name": "Rock_Slate"
    },
    {
      "x": -21,
      "y": 5,
      "z": -5,
      "name": "Rock_Slate"
    },
    {
      "x": -21,
      "y": 6,
      "z": -5,
      "name": "Rock_Slate"
    },
    {
      "x": -21,
      "y": 3,
      "z": -4,
      "name": "Rock_Slate"
    },
    {
      "x": -21,
      "y": 4,
      "z": -4,
      "name": "Rock_Slate"
    },
    {
      "x": -21,
      "y": 5,
      "z": -4,
      "name": "Rock_Slate"
    },
    {
      "x": -21,
      "y": 6,
      "z": -4,
      "name": "Rock_Slate"
    },
    {
      "x": -21,
      "y": 3,
      "z": -3,
      "name": "Rock_Slate"
    },
    {
      "x": -21,
      "y": 4,
      "z": -3,
      "name": "Rock_Slate"
    },
    {
      "x": -21,
      "y": 5,
      "z": -3,
      "name": "Rock_Slate"
    },
    {
      "x": -21,
      "y": 6,
      "z": -3,
      "name": "Rock_Slate"
    },
    {
      "x": -21,
      "y": 1,
      "z": -2,
      "name": "Rock_Slate"
    },
    {
      "x": -21,
      "y": 2,
      "z": -2,
      "name": "Rock_Slate"
    },
    {
      "x": -21,
      "y": 3,
      "z": -2,
      "name": "Rock_Slate"
    },
    {
      "x": -21,
      "y": 4,
      "z": -2,
      "name": "Rock_Slate"
    },
    {
      "x": -21,
      "y": 5,
      "z": -2,
      "name": "Rock_Slate"
    },
    {
      "x": -21,
      "y": 6,
      "z": -2,
      "name": "Rock_Slate"
    },
    {
      "x": -21,
      "y": 3,
      "z": -1,
      "name": "Rock_Slate"
    },
    {
      "x": -21,
      "y": 4,
      "z": -1,
      "name": "Rock_Slate"
    },
    {
      "x": -21,
      "y": 5,
      "z": -1,
      "name": "Rock_Slate"
    },
    {
      "x": -21,
      "y": 6,
      "z": -1,
      "name": "Rock_Slate"
    },
    {
      "x": -21,
      "y": 1,
      "z": 0,
      "name": "Rock_Slate"
    },
    {
      "x": -21,
      "y": 2,
      "z": 0,
      "name": "Rock_Slate"
    },
    {
      "x": -21,
      "y": 3,
      "z": 0,
      "name": "Rock_Slate"
    },
    {
      "x": -21,
      "y": 4,
      "z": 0,
      "name": "Rock_Slate"
    },
    {
      "x": -21,
      "y": 5,
      "z": 0,
      "name": "Rock_Slate"
    },
    {
      "x": -21,
      "y": 6,
      "z": 0,
      "name": "Rock_Slate"
    },
    {
      "x": -21,
      "y": 3,
      "z": 1,
      "name": "Rock_Slate"
    },
    {
      "x": -21,
      "y": 4,
      "z": 1,
      "name": "Rock_Slate"
    },
    {
      "x": -21,
      "y": 5,
      "z": 1,
      "name": "Rock_Slate"
    },
    {
      "x": -21,
      "y": 6,
      "z": 1,
      "name": "Rock_Slate"
    },
    {
      "x": -21,
      "y": 3,
      "z": 2,
      "name": "Rock_Slate"
    },
    {
      "x": -21,
      "y": 4,
      "z": 2,
      "name": "Rock_Slate"
    },
    {
      "x": -21,
      "y": 5,
      "z": 2,
      "name": "Rock_Slate"
    },
    {
      "x": -21,
      "y": 6,
      "z": 2,
      "name": "Rock_Slate"
    },
    {
      "x": -21,
      "y": 2,
      "z": 3,
      "name": "Rock_Slate"
    },
    {
      "x": -21,
      "y": 3,
      "z": 3,
      "name": "Rock_Slate"
    },
    {
      "x": -21,
      "y": 4,
      "z": 3,
      "name": "Rock_Slate"
    },
    {
      "x": -21,
      "y": 5,
      "z": 3,
      "name": "Rock_Slate"
    },
    {
      "x": -21,
      "y": 6,
      "z": 3,
      "name": "Rock_Slate"
    },
    {
      "x": -21,
      "y": 3,
      "z": 4,
      "name": "Rock_Slate"
    },
    {
      "x": -21,
      "y": 4,
      "z": 4,
      "name": "Rock_Slate"
    },
    {
      "x": -21,
      "y": 5,
      "z": 4,
      "name": "Rock_Slate"
    },
    {
      "x": -21,
      "y": 6,
      "z": 4,
      "name": "Rock_Slate"
    },
    {
      "x": -21,
      "y": 2,
      "z": 5,
      "name": "Rock_Slate"
    },
    {
      "x": -21,
      "y": 3,
      "z": 5,
      "name": "Rock_Slate"
    },
    {
      "x": -21,
      "y": 4,
      "z": 5,
      "name": "Rock_Slate"
    },
    {
      "x": -21,
      "y": 5,
      "z": 5,
      "name": "Rock_Slate"
    },
    {
      "x": -21,
      "y": 6,
      "z": 5,
      "name": "Rock_Slate"
    },
    {
      "x": -21,
      "y": 3,
      "z": 6,
      "name": "Rock_Slate"
    },
    {
      "x": -21,
      "y": 4,
      "z": 6,
      "name": "Rock_Slate"
    },
    {
      "x": -21,
      "y": 5,
      "z": 6,
      "name": "Rock_Slate"
    },
    {
      "x": -21,
      "y": 6,
      "z": 6,
      "name": "Rock_Slate"
    },
    {
      "x": -21,
      "y": 3,
      "z": 7,
      "name": "Rock_Slate"
    },
    {
      "x": -21,
