{
  "version": 8,
  "blockIdVersion": 11,
  "anchorX": 0,
  "anchorY": 0,
  "anchorZ": 0,
  "blocks": [
    {
      "x": -22,
      "y": 0,
      "z": -4,
      "name": "Rock_Shale_Brick_Ornate"
    },
    {
      "x": -22,
      "y": 1,
      "z": -4,
      "name": "Rock_Shale_Brick_Ornate"
    },
    {
      "x": -22,
      "y": 2,
      "z": -4,
      "name": "Rock_Shale_Brick_Ornate"
    },
    {
      "x": -22,
      "y": 27,
      "z": -4,
      "name": "Rock_Shale_Brick_Ornate"
    },
    {
      "x": -22,
      "y": 0,
      "z": -3,
      "name": "Rock_Shale_Brick_Ornate"
    },
    {
      "x": -22,
      "y": 1,
      "z": -3,
      "name": "Rock_Shale_Brick_Ornate"
    },
    {
      "x": -22,
      "y": 2,
      "z": -3,
      "name": "Rock_Shale_Brick_Ornate"
    },
    {
      "x": -22,
      "y": 3,
      "z": -3,
      "name": "Rock_Shale_Brick_Ornate"
    },
    {
      "x": -22,
      "y": 4,
      "z": -3,
      "name": "Rock_Shale_Brick_Ornate"
    },
    {
      "x": -22,
      "y": 27,
      "z": -3,
      "name": "Rock_Shale_Brick_Ornate"
    },
    {
      "x": -22,
      "y": 28,
      "z": -3,
      "name": "Rock_Shale_Brick_Ornate"
    },
    {
      "x": -22,
      "y": 0,
      "z": -2,
      "name": "Rock_Shale_Brick_Ornate"
    },
    {
      "x": -22,
      "y": 1,
      "z": -2,
      "name": "Rock_Shale_Brick_Ornate"
    },
    {
      "x": -22,
      "y": 2,
      "z": -2,
      "name": "Rock_Shale_Brick_Ornate"
    },
    {
      "x": -22,
      "y": 3,
      "z": -2,
      "name": "Rock_Shale_Brick_Ornate"
    },
    {
      "x": -22,
      "y": 4,
      "z": -2,
      "name": "Rock_Shale_Brick_Ornate"
    },
    {
      "x": -22,
      "y": 27,
      "z": -2,
      "name": "Rock_Shale_Brick_Ornate"
    },
    {
      "x": -22,
      "y": 28,
      "z": -2,
      "name": "Rock_Shale_Brick_Ornate"
    },
    {
      "x": -22,
      "y": 29,
      "z": -2,
      "name": "Rock_Shale_Brick_Ornate"
    },
    {
      "x": -22,
      "y": 30,
      "z": -2,
      "name": "Rock_Shale_Brick_Ornate"
    },
    {
      "x": -22,
      "y": 0,
      "z": -1,
      "name": "Rock_Shale_Brick_Ornate"
    },
    {
      "x": -22,
      "y": 1,
      "z": -1,
      "name": "Rock_Shale_Brick_Ornate"
    },
    {
      "x": -22,
      "y": 2,
      "z": -1,
      "name": "Rock_Shale_Brick_Ornate"
    },
    {
      "x": -22,
      "y": 3,
      "z": -1,
      "name": "Rock_Shale_Brick_Ornate"
    },
    {
      "x": -22,
      "y": 4,
      "z": -1,
      "name": "Rock_Shale_Brick_Ornate"
    },
    {
      "x": -22,
      "y": 27,
      "z": -1,
      "name": "Rock_Shale_Brick_Ornate"
    },
    {
      "x": -22,
      "y": 28,
      "z": -1,
      "name": "Rock_Shale_Brick_Ornate"
    },
    {
      "x": -22,
      "y": 29,
      "z": -1,
      "name": "Rock_Shale_Brick_Ornate"
    },
    {
      "x": -22,
      "y": 30,
      "z": -1,
      "name": "Rock_Shale_Brick_Ornate"
    },
    {
      "x": -22,
      "y": 31,
      "z": -1,
      "name": "Rock_Shale_Brick_Ornate"
    },
    {
      "x": -22,
      "y": 0,
      "z": 0,
      "name": "Rock_Shale_Brick_Ornate"
    },
    {
      "x": -22,
      "y": 1,
      "z": 0,
      "name": "Rock_Shale_Brick_Ornate"
    },
    {
      "x": -22,
      "y": 2,
      "z": 0,
      "name": "Rock_Shale_Brick_Ornate"
    },
    {
      "x": -22,
      "y": 3,
      "z": 0,
      "name": "Rock_Shale_Brick_Ornate"
    },
    {
      "x": -22,
      "y": 4,
      "z": 0,
      "name": "Rock_Shale_Brick_Ornate"
    },
    {
      "x": -22,
      "y": 27,
      "z": 0,
      "name": "Rock_Shale_Brick_Ornate"
    },
    {
      "x": -22,
      "y": 28,
      "z": 0,
      "name": "Rock_Shale_Brick_Ornate"
    },
    {
      "x": -22,
      "y": 29,
      "z": 0,
      "name": "Rock_Shale_Brick_Ornate"
    },
    {
      "x": -22,
      "y": 30,
      "z": 0,
      "name": "Rock_Shale_Brick_Ornate"
    },
    {
      "x": -22,
      "y": 31,
      "z": 0,
      "name": "Rock_Shale_Brick_Ornate"
    },
    {
      "x": -22,
      "y": 0,
      "z": 1,
      "name": "Rock_Shale_Brick_Ornate"
    },
    {
      "x": -22,
      "y": 1,
      "z": 1,
      "name": "Rock_Shale_Brick_Ornate"
    },
    {
      "x": -22,
      "y": 2,
      "z": 1,
      "name": "Rock_Shale_Brick_Ornate"
    },
    {
      "x": -22,
      "y": 3,
      "z": 1,
      "name": "Rock_Shale_Brick_Ornate"
    },
    {
      "x": -22,
      "y": 4,
      "z": 1,
      "name": "Rock_Shale_Brick_Ornate"
    },
    {
      "x": -22,
      "y": 27,
      "z": 1,
      "name": "Rock_Shale_Brick_Ornate"
    },
    {
      "x": -22,
      "y": 28,
      "z": 1,
      "name": "Rock_Shale_Brick_Ornate"
    },
    {
      "x": -22,
      "y": 29,
      "z": 1,
      "name": "Rock_Shale_Brick_Ornate"
    },
    {
      "x": -22,
      "y": 30,
      "z": 1,
      "name": "Rock_Shale_Brick_Ornate"
    },
    {
      "x": -22,
      "y": 31,
      "z": 1,
      "name": "Rock_Shale_Brick_Ornate"
    },
    {
      "x": -22,
      "y": 0,
      "z": 2,
      "name": "Rock_Shale_Brick_Ornate"
    },
    {
      "x": -22,
      "y": 1,
      "z": 2,
      "name": "Rock_Shale_Brick_Ornate"
    },
    {
      "x": -22,
      "y": 2,
      "z": 2,
      "name": "Rock_Shale_Brick_Ornate"
    },
    {
      "x": -22,
      "y": 3,
      "z": 2,
      "name": "Rock_Shale_Brick_Ornate"
    },
    {
      "x": -22,
      "y": 4,
      "z": 2,
      "name": "Rock_Shale_Brick_Ornate"
    },
    {
      "x": -22,
      "y": 27,
      "z": 2,
      "name": "Rock_Shale_Brick_Ornate"
    },
    {
      "x": -22,
      "y": 28,
      "z": 2,
      "name": "Rock_Shale_Brick_Ornate"
    },
    {
      "x": -22,
      "y": 29,
      "z": 2,
      "name": "Rock_Shale_Brick_Ornate"
    },
    {
      "x": -22,
      "y": 30,
      "z": 2,
      "name": "Rock_Shale_Brick_Ornate"
    },
    {
      "x": -22,
      "y": 31,
      "z": 2,
      "name": "Rock_Shale_Brick_Ornate"
    },
    {
      "x": -22,
      "y": 0,
      "z": 3,
      "name": "Rock_Shale_Brick_Ornate"
    },
    {
      "x": -22,
      "y": 1,
      "z": 3,
      "name": "Rock_Shale_Brick_Ornate"
    },
    {
      "x": -22,
      "y": 2,
      "z": 3,
      "name": "Rock_Shale_Brick_Ornate"
    },
    {
      "x": -22,
      "y": 3,
      "z": 3,
      "name": "Rock_Shale_Brick_Ornate"
    },
    {
      "x": -22,
      "y": 4,
      "z": 3,
      "name": "Rock_Shale_Brick_Ornate"
    },
    {
      "x": -22,
      "y": 27,
      "z": 3,
      "name": "Rock_Shale_Brick_Ornate"
    },
    {
      "x": -22,
      "y": 28,
      "z": 3,
      "name": "Rock_Shale_Brick_Ornate"
    },
    {
      "x": -22,
      "y": 29,
      "z": 3,
      "name": "Rock_Shale_Brick_Ornate"
    },
    {
      "x": -22,
      "y": 30,
      "z": 3,
      "name": "Rock_Shale_Brick_Ornate"
    },
    {
      "x": -22,
      "y": 31,
      "z": 3,
      "name": "Rock_Shale_Brick_Ornate"
    },
    {
      "x": -22,
      "y": 0,
      "z": 4,
      "name": "Rock_Shale_Brick_Ornate"
    },
    {
      "x": -22,
      "y": 1,
      "z": 4,
      "name": "Rock_Shale_Brick_Ornate"
    },
    {
      "x": -22,
      "y": 2,
      "z": 4,
      "name": "Rock_Shale_Brick_Ornate"
    },
    {
      "x": -22,
      "y": 27,
      "z": 4,
      "name": "Rock_Shale_Brick_Ornate"
    },
    {
      "x": -22,
      "y": 28,
      "z": 4,
      "name": "Rock_Shale_Brick_Ornate"
    },
    {
      "x": -22,
      "y": 29,
      "z": 4,
      "name": "Rock_Shale_Brick_Ornate"
    },
    {
      "x": -22,
      "y": 30,
      "z": 4,
      "name": "Rock_Shale_Brick_Ornate"
    },
    {
      "x": -22,
      "y": 31,
      "z": 4,
      "name": "Rock_Shale_Brick_Ornate"
    },
    {
      "x": -22,
      "y": 0,
      "z": 5,
      "name": "Rock_Shale_Brick_Ornate"
    },
    {
      "x": -22,
      "y": 1,
      "z": 5,
      "name": "Rock_Shale_Brick_Ornate"
    },
    {
      "x": -22,
      "y": 27,
      "z": 5,
      "name": "Rock_Shale_Brick_Ornate"
    },
    {
      "x": -22,
      "y": 28,
      "z": 5,
      "name": "Rock_Shale_Brick_Ornate"
    },
    {
      "x": -22,
      "y": 29,
      "z": 5,
      "name": "Rock_Shale_Brick_Ornate"
    },
    {
      "x": -22,
      "y": 30,
      "z": 5,
      "name": "Rock_Shale_Brick_Ornate"
    },
    {
      "x": -22,
      "y": 31,
      "z": 5,
      "name": "Rock_Shale_Brick_Ornate"
    },
    {
      "x": -21,
      "y": 0,
      "z": -4,
      "name": "Rock_Shale_Brick_Ornate"
    },
    {
      "x": -21,
      "y": 1,
      "z": -4,
      "name": "Rock_Shale_Brick_Ornate"
    },
    {
      "x": -21,
      "y": 2,
      "z": -4,
      "name": "Rock_Shale_Brick_Ornate"
    },
    {
      "x": -21,
      "y": 3,
      "z": -4,
      "name": "Rock_Shale_Brick_Ornate"
    },
    {
      "x": -21,
      "y": 27,
      "z": -4,
      "name": "Rock_Shale_Brick_Ornate"
    },
    {
      "x": -21,
      "y": 28,
      "z": -4,
      "name": "Rock_Shale_Brick_Ornate"
    },
    {
      "x": -21,
      "y": 0,
      "z": -3,
      "name": "Rock_Shale_Brick_Ornate"
    },
    {
      "x": -21,
      "y": 1,
      "z": -3,
      "name": "Rock_Shale_Brick_Ornate"
    },
    {
      "x": -21,
      "y": 2,
      "z": -3,
      "name": "Rock_Shale_Brick_Ornate"
    },
    {
      "x": -21,
      "y": 3,
      "z": -3,
      "name": "Rock_Shale_Brick_Ornate"
    },
    {
      "x": -21,
      "y": 4,
      "z": -3,
      "name": "Rock_Shale_Brick_Ornate"
    },
    {
      "x": -21,
      "y": 5,
      "z": -3,
      "name": "Rock_Shale_Brick"
    },
    {
      "x": -21,
      "y": 6,
      "z": -3,
      "name": "Rock_Shale_Brick"
    },
    {
      "x": -21,
      "y": 7,
      "z": -3,
      "name": "Rock_Shale_Brick"
    },
    {
      "x": -21,
      "y": 8,
      "z": -3,
      "name": "Rock_Shale_Brick"
    },
    {
      "x": -21,
      "y": 9,
      "z": -3,
      "name": "Rock_Shale_Brick"
    },
    {
      "x": -21,
      "y": 10,
      "z": -3,
      "name": "Rock_Shale_Brick"
    },
    {
      "x": -21,
      "y": 11,
      "z": -3,
      "name": "Rock_Shale_Brick"
    },
    {
      "x": -21,
      "y": 12,
      "z": -3,
      "name": "Rock_Shale_Brick"
    },
    {
      "x": -21,
      "y": 13,
      "z": -3,
      "name": "Rock_Shale_Brick"
    },
    {
      "x": -21,
      "y": 14,
      "z": -3,
      "name": "Rock_Shale_Brick"
    },
    {
      "x": -21,
      "y": 15,
      "z": -3,
      "name": "Rock_Shale_Brick"
    },
    {
      "x": -21,
      "y": 16,
      "z": -3,
      "name": "Rock_Shale_Brick"
    },
    {
      "x": -21,
      "y": 17,
      "z": -3,
      "name": "Rock_Shale_Brick"
    },
    {
      "x": -21,
      "y": 18,
      "z": -3,
      "name": "Rock_Shale_Brick"
    },
    {
      "x": -21,
      "y": 19,
      "z": -3,
      "name": "Rock_Shale_Brick"
    },
    {
      "x": -21,
      "y": 20,
      "z": -3,
      "name": "Rock_Shale_Brick"
    },
    {
      "x": -21,
      "y": 21,
      "z": -3,
      "name": "Rock_Shale_Brick"
    },
    {
      "x": -21,
      "y": 22,
      "z": -3,
      "name": "Rock_Shale_Brick"
    },
    {
      "x": -21,
      "y": 23,
      "z": -3,
      "name": "Rock_Shale_Brick"
    },
    {
      "x": -21,
      "y": 24,
      "z": -3,
      "name": "Rock_Shale_Brick"
    },
    {
      "x": -21,
      "y": 25,
      "z": -3,
      "name": "Rock_Shale_Brick"
    },
    {
      "x": -21,
      "y": 26,
      "z": -3,
      "name": "Rock_Shale_Brick"
    },
    {
      "x": -21,
      "y": 27,
      "z": -3,
      "name": "Rock_Shale_Brick_Ornate"
    },
    {
      "x": -21,
      "y": 28,
      "z": -3,
      "name": "Rock_Shale_Brick_Ornate"
    },
    {
      "x": -21,
      "y": 29,
      "z": -3,
      "name": "Rock_Shale_Brick_Ornate"
    },
    {
      "x": -21,
      "y": 0,
      "z": -2,
      "name": "Rock_Shale_Brick_Ornate"
    },
    {
      "x": -21,
      "y": 1,
      "z": -2,
      "name": "Rock_Shale_Brick_Ornate"
    },
    {
      "x": -21,
      "y": 2,
      "z": -2,
      "name": "Rock_Shale_Brick_Ornate"
    },
    {
      "x": -21,
      "y": 3,
      "z": -2,
      "name": "Rock_Shale_Brick_Ornate"
    },
    {
      "x": -21,
      "y": 4,
      "z": -2,
      "name": "Rock_Shale_Brick_Ornate"
    },
    {
      "x": -21,
      "y": 5,
      "z": -2,
      "name": "Rock_Shale_Brick"
    },
    {
      "x": -21,
      "y": 6,
      "z": -2,
      "name": "Rock_Shale_Brick"
    },
    {
      "x": -21,
      "y": 7,
      "z": -2,
      "name": "Rock_Shale_Brick"
    },
    {
      "x": -21,
      "y": 8,
      "z": -2,
      "name": "Rock_Shale_Brick"
    },
    {
      "x": -21,
      "y": 9,
      "z": -2,
      "name": "Rock_Shale_Brick"
    },
    {
      "x": -21,
      "y": 10,
      "z": -2,
      "name": "Rock_Shale_Brick"
    },
    {
      "x": -21,
      "y": 11,
      "z": -2,
      "name": "Rock_Shale_Brick"
    },
    {
      "x": -21,
      "y": 12,
      "z": -2,
      "name": "Rock_Shale_Brick"
    },
    {
      "x": -21,
      "y": 13,
      "z": -2,
      "name": "Rock_Shale_Brick"
    },
    {
      "x": -21,
      "y": 14,
      "z": -2,
      "name": "Rock_Shale_Brick"
    },
    {
      "x": -21,
      "y": 15,
      "z": -2,
      "name": "Rock_Shale_Brick"
    },
    {
      "x": -21,
      "y": 16,
      "z": -2,
      "name": "Rock_Shale_Brick"
    },
    {
      "x": -21,
      "y": 17,
      "z": -2,
      "name": "Rock_Shale_Brick"
    },
    {
      "x": -21,
      "y": 18,
      "z": -2,
      "name": "Rock_Shale_Brick"
    },
    {
      "x": -21,
      "y": 19,
      "z": -2,
      "name": "Rock_Shale_Brick"
    },
    {
      "x": -21,
      "y": 20,
      "z": -2,
      "name": "Rock_Shale_Brick"
    },
    {
      "x": -21,
      "y": 21,
      "z": -2,
      "name": "Rock_Shale_Brick"
    },
    {
      "x": -21,
      "y": 22,
      "z": -2,
      "name": "Rock_Shale_Brick"
    },
    {
      "x": -21,
      "y": 23,
      "z": -2,
      "name": "Rock_Shale_Brick"
    },
    {
      "x": -21,
      "y": 24,
      "z": -2,
      "name": "Rock_Shale_Brick"
    },
    {
      "x": -21,
      "y": 25,
      "z": -2,
      "name": "Rock_Shale_Brick"
    },
    {
      "x": -21,
      "y": 26,
      "z": -2,
      "name": "Rock_Shale_Brick"
    },
    {
      "x": -21,
      "y": 27,
      "z": -2,
      "name": "Rock_Shale_Brick_Ornate"
    },
    {
      "x": -21,
      "y": 28,
      "z": -2,
      "name": "Rock_Shale_Brick_Ornate"
    },
    {
      "x": -21,
      "y": 29,
      "z": -2,
      "name": "Rock_Shale_Brick_Ornate"
    },
    {
      "x": -21,
      "y": 30,
      "z": -2,
      "name": "Rock_Shale_Brick_Ornate"
    },
    {
      "x": -21,
      "y": 0,
      "z": -1,
      "name": "Rock_Shale_Brick_Ornate"
    },
    {
      "x": -21,
      "y": 1,
      "z": -1,
      "name": "Rock_Shale_Brick_Ornate"
    },
    {
      "x": -21,
      "y": 2,
      "z": -1,
      "name": "Rock_Shale_Brick_Ornate"
    },
    {
      "x": -21,
      "y": 3,
      "z": -1,
      "name": "Rock_Shale_Brick_Ornate"
    },
    {
      "x": -21,
      "y": 4,
      "z": -1,
      "name": "Rock_Shale_Brick_Ornate"
    },
    {
      "x": -21,
      "y": 5,
      "z": -1,
      "name": "Rock_Shale_Brick"
    },
    {
      "x": -21,
      "y": 6,
      "z": -1,
      "name": "Rock_Shale_Brick"
    },
    {
      "x": -21,
      "y": 7,
      "z": -1,
      "name": "Rock_Shale_Brick"
    },
    {
      "x": -21,
      "y": 8,
      "z": -1,
      "name": "Rock_Shale_Brick"
    },
    {
      "x": -21,
      "y": 9,
      "z": -1,
      "name": "Rock_Shale_Brick"
    },
    {
      "x": -21,
      "y": 10,
      "z": -1,
      "name": "Rock_Shale_Brick"
    },
    {
      "x": -21,
      "y": 11,
      "z": -1,
      "name": "Rock_Shale_Brick"
    },
    {
      "x": -21,
      "y": 12,
      "z": -1,
      "name": "Rock_Shale_Brick"
    },
    {
      "x": -21,
      "y": 13,
      "z": -1,
      "name": "Rock_Shale_Brick"
    },
    {
      "x": -21,
      "y": 14,
      "z": -1,
      "name": "Rock_Shale_Brick"
    },
    {
      "x": -21,
      "y": 15,
      "z": -1,
      "name": "Rock_Shale_Brick"
    },
    {
      "x": -21,
      "y": 16,
      "z": -1,
      "name": "Rock_Shale_Brick"
    },
    {
      "x": -21,
      "y": 17,
      "z": -1,
      "name": "Rock_Shale_Brick"
    },
    {
      "x": -21,
      "y": 18,
      "z": -1,
      "name": "Rock_Shale_Brick"
    },
    {
      "x": -21,
      "y": 19,
      "z": -1,
      "name": "Rock_Shale_Brick"
    },
    {
      "x": -21,
      "y": 20,
      "z": -1,
      "name": "Rock_Shale_Brick"
    },
    {
      "x": -21,
      "y": 21,
      "z": -1,
      "name": "Rock_Shale_Brick"
    },
    {
      "x": -21,
      "y": 22,
      "z": -1,
      "name": "Rock_Shale_Brick"
    },
    {
      "x": -21,
      "y": 23,
      "z": -1,
      "name": "Rock_Shale_Brick"
    },
    {
      "x": -21,
      "y": 24,
      "z": -1,
      "name": "Rock_Shale_Brick"
    },
    {
      "x": -21,
      "y": 25,
      "z": -1,
      "name": "Rock_Shale_Brick"
    },
    {
      "x": -21,
      "y": 26,
      "z": -1,
      "name": "Rock_Shale_Brick"
    },
    {
      "x": -21,
      "y": 27,
      "z": -1,
      "name": "Rock_Shale_Brick_Ornate"
    },
    {
      "x": -21,
      "y": 28,
      "z": -1,
      "name": "Rock_Shale_Brick_Ornate"
    },
    {
      "x": -21,
      "y": 29,
      "z": -1,
      "name": "Rock_Shale_Brick_Ornate"
    },
    {
      "x": -21,
      "y": 30,
      "z": -1,
      "name": "Rock_Shale_Brick_Ornate"
    },
    {
      "x": -21,
      "y": 31,
      "z": -1,
      "name": "Rock_Shale_Brick_Ornate"
    },
    {
      "x": -21,
      "y": 0,
      "z": 0,
      "name": "Rock_Shale_Brick_Ornate"
    },
    {
      "x": -21,
      "y": 1,
      "z": 0,
      "name": "Rock_Shale_Brick_Ornate"
    },
    {
      "x": -21,
      "y": 2,
      "z": 0,
      "name": "Rock_Shale_Brick_Ornate"
    },
    {
      "x": -21,
      "y": 3,
      "z": 0,
      "name": "Rock_Shale_Brick_Ornate"
    },
    {
      "x": -21,
      "y": 4,
      "z": 0,
      "name": "Rock_Shale_Brick_Ornate"
    },
    {
      "x": -21,
      "y": 5,
      "z": 0,
      "name": "Rock_Shale_Brick"
    },
    {
      "x": -21,
      "y": 6,
      "z": 0,
      "name": "Rock_Shale_Brick"
    },
    {
      "x": -21,
      "y": 7,
      "z": 0,
      "name": "Rock_Shale_Brick"
    },
    {
      "x": -21,
      "y": 8,
      "z": 0,
      "name": "Rock_Shale_Brick"
    },
    {
      "x": -21,
      "y": 9,
      "z": 0,
      "name": "Rock_Shale_Brick"
    },
    {
      "x": -21,
      "y": 10,
      "z": 0,
      "name": "Rock_Shale_Brick"
    },
    {
      "x": -21,
      "y": 11,
      "z": 0,
      "name": "Rock_Shale_Brick"
    },
    {
      "x": -21,
      "y": 12,
      "z": 0,
      "name": "Rock_Shale_Brick"
    },
    {
      "x": -21,
      "y": 13,
      "z": 0,
      "name": "Rock_Shale_Brick"
    },
    {
      "x": -21,
      "y": 14,
      "z": 0,
      "name": "Rock_Shale_Brick"
    },
    {
      "x": -21,
      "y": 15,
      "z": 0,
      "name": "Rock_Shale_Brick"
    },
    {
      "x": -21,
      "y": 16,
      "z": 0,
      "name": "Rock_Shale_Brick"
    },
    {
      "x": -21,
      "y": 17,
      "z": 0,
      "name": "Rock_Shale_Brick"
    },
    {
      "x": -21,
      "y": 18,
      "z": 0,
      "name": "Rock_Shale_Brick"
    },
    {
      "x": -21,
      "y": 19,
      "z": 0,
      "name": "Rock_Shale_Brick"
    },
    {
      "x": -21,
      "y": 20,
      "z": 0,
      "name": "Rock_Shale_Brick"
    },
    {
      "x": -21,
      "y": 21,
      "z": 0,
      "name": "Rock_Shale_Brick"
    },
    {
      "x": -21,
      "y": 22,
      "z": 0,
      "name": "Rock_Shale_Brick"
    },
    {
      "x": -21,
      "y": 23,
      "z": 0,
      "name": "Rock_Shale_Brick"
    },
    {
      "x": -21,
      "y": 24,
      "z": 0,
      "name": "Rock_Shale_Brick"
    },
    {
      "x": -21,
      "y": 25,
      "z": 0,
      "name": "Rock_Shale_Brick"
    },
    {
      "x": -21,
      "y": 26,
      "z": 0,
      "name": "Rock_Shale_Brick"
    },
    {
      "x": -21,
      "y": 27,
      "z": 0,
      "name": "Rock_Shale_Brick_Ornate"
    },
    {
      "x": -21,
      "y": 28,
      "z": 0,
      "name": "Rock_Shale_Brick_Ornate"
    },
    {
      "x": -21,
      "y": 29,
      "z": 0,
      "name": "Rock_Shale_Brick_Ornate"
    },
    {
      "x": -21,
      "y": 30,
      "z": 0,
      "name": "Rock_Shale_Brick_Ornate"
    },
    {
      "x": -21,
      "y": 31,
      "z": 0,
      "name": "Rock_Shale_Brick_Ornate"
    },
    {
      "x": -21,
      "y": 0,
      "z": 1,
      "name": "Rock_Shale_Brick_Ornate"
    },
    {
      "x": -21,
      "y": 1,
      "z": 1,
      "name": "Rock_Shale_Brick_Ornate"
    },
    {
      "x": -21,
      "y": 2,
      "z": 1,
      "name": "Rock_Shale_Brick_Ornate"
    },
    {
      "x": -21,
      "y": 3,
      "z": 1,
      "name": "Rock_Shale_Brick_Ornate"
    },
    {
      "x": -21,
      "y": 4,
      "z": 1,
      "name": "Rock_Shale_Brick_Ornate"
    },
    {
      "x": -21,
      "y": 5,
      "z": 1,
      "name": "Rock_Shale_Brick"
    },
    {
      "x": -21,
      "y": 6,
      "z": 1,
      "name": "Rock_Shale_Brick"
    },
    {
      "x": -21,
      "y": 7,
      "z": 1,
      "name": "Rock_Shale_Brick"
    },
    {
      "x": -21,
      "y": 8,
      "z": 1,
      "name": "Rock_Shale_Brick"
    },
    {
      "x": -21,
      "y": 9,
      "z": 1,
      "name": "Rock_Shale_Brick"
    },
    {
      "x": -21,
      "y": 10,
      "z": 1,
      "name": "Rock_Shale_Brick"
    },
    {
      "x": -21,
      "y": 11,
      "z": 1,
      "name": "Rock_Shale_Brick"
    },
    {
      "x": -21,
      "y": 12,
      "z": 1,
      "name": "Rock_Shale_Brick"
    },
    {
      "x": -21,
      "y": 13,
      "z": 1,
      "name": "Rock_Shale_Brick"
    },
    {
      "x": -21,
      "y": 14,
      "z": 1,
      "name": "Rock_Shale_Brick"
    },
    {
      "x": -21,
      "y": 15,
      "z": 1,
      "name": "Rock_Shale_Brick"
    },
    {
      "x": -21,
      "y": 16,
      "z": 1,
      "name": "Rock_Shale_Brick"
    },
    {
      "x": -21,
      "y": 17,
      "z": 1,
      "name": "Rock_Shale_Brick"
    },
    {
      "x": -21,
      "y": 18,
      "z": 1,
      "name": "Rock_Shale_Brick"
    },
    {
      "x": -21,
      "y": 19,
      "z": 1,
      "name": "Rock_Shale_Brick"
    },
    {
      "x": -21,
      "y": 20,
      "z": 1,
      "name": "Rock_Shale_Brick"
    },
    {
      "x": -21,
      "y": 21,
      "z": 1,
      "name": "Rock_Shale_Brick"
    },
    {
      "x": -21,
      "y": 22,
      "z": 1,
      "name": "Rock_Shale_Brick"
    },
    {
      "x": -21,
      "y": 23,
      "z": 1,
      "name": "Rock_Shale_Brick"
    },
    {
      "x": -21,
      "y": 24,
      "z": 1,
      "name": "Rock_Shale_Brick"
    },
    {
      "x": -21,
      "y": 25,
      "z": 1,
      "name": "Rock_Shale_Brick"
    },
    {
      "x": -21,
      "y": 26,
      "z": 1,
      "name": "Rock_Shale_Brick"
    },
    {
      "x": -21,
      "y": 27,
      "z": 1,
      "name": "Rock_Shale_Brick_Ornate"
    },
    {
      "x": -21,
      "y": 28,
      "z": 1,
      "name": "Rock_Shale_Brick_Ornate"
    },
    {
      "x": -21,
      "y": 29,
      "z": 1,
      "name": "Rock_Shale_Brick_Ornate"
    },
    {
      "x": -21,
      "y": 30,
      "z": 1,
      "name": "Rock_Shale_Brick_Ornate"
    },
    {
      "x": -21,
      "y": 31,
      "z": 1,
      "name": "Rock_Shale_Brick_Ornate"
    },
    {
      "x": -21,
      "y": 0,
      "z": 2,
      "name": "Rock_Shale_Brick_Ornate"
    },
    {
      "x": -21,
      "y": 1,
      "z": 2,
      "name": "Rock_Shale_Brick_Ornate"
    },
    {
      "x": -21,
      "y": 2,
      "z": 2,
      "name": "Rock_Shale_Brick_Ornate"
    },
    {
      "x": -21,
      "y": 3,
      "z": 2,
      "name": "Rock_Shale_Brick_Ornate"
    },
    {
      "x": -21,
      "y": 4,
      "z": 2,
      "name": "Rock_Shale_Brick_Ornate"
    },
    {
      "x": -21,
      "y": 5,
      "z": 2,
      "name": "Rock_Shale_Brick"
    },
    {
      "x": -21,
      "y": 6,
      "z": 2,
      "name": "Rock_Shale_Brick"
    },
    {
      "x": -21,
      "y": 7,
      "z": 2,
      "name": "Rock_Shale_Brick"
    },
    {
      "x": -21,
      "y": 8,
      "z": 2,
      "name": "Rock_Shale_Brick"
    },
    {
      "x": -21,
      "y": 9,
      "z": 2,
      "name": "Rock_Shale_Brick"
    },
    {
      "x": -21,
      "y": 10,
      "z": 2,
      "name": "Rock_Shale_Brick"
    },
    {
      "x": -21,
      "y": 11,
      "z": 2,
      "name": "Rock_Shale_Brick"
    },
    {
      "x": -21,
      "y": 12,
      "z": 2,
      "name": "Rock_Shale_Brick"
    },
    {
      "x": -21,
      "y": 13,
      "z": 2,
      "name": "Rock_Shale_Brick"
    },
    {
      "x": -21,
      "y": 14,
      "z": 2,
      "name": "Rock_Shale_Brick"
    },
    {
      "x": -21,
      "y": 15,
      "z": 2,
      "name": "Rock_Shale_Brick"
    },
    {
      "x": -21,
      "y": 16,
      "z": 2,
      "name": "Rock_Shale_Brick"
    },
    {
      "x": -21,
      "y": 17,
      "z": 2,
      "name": "Rock_Shale_Brick"
    },
    {
      "x": -21,
      "y": 18,
      "z": 2,
      "name": "Rock_Shale_Brick"
    },
    {
      "x": -21,
      "y": 20,
      "z": 2,
      "name": "Rock_Shale_Brick"
    },
    {
      "x": -21,
      "y": 21,
      "z": 2,
      "name": "Rock_Shale_Brick"
    },
    {
      "x": -21,
      "y": 22,
      "z": 2,
      "name": "Rock_Shale_Brick"
    },
    {
      "x": -21,
      "y": 23,
      "z": 2,
      "name": "Rock_Shale_Brick"
    },
    {
      "x": -21,
      "y": 24,
      "z": 2,
      "name": "Rock_Shale_Brick"
    },
    {
      "x": -21,
      "y": 25,
      "z": 2,
      "name": "Rock_Shale_Brick"
    },
    {
      "x": -21,
      "y": 26,
      "z": 2,
      "name": "Rock_Shale_Brick"
    },
    {
      "x": -21,
      "y": 27,
      "z": 2,
      "name": "Rock_Shale_Brick_Ornate"
    },
    {
      "x": -21,
      "y": 28,
      "z": 2,
      "name": "Rock_Shale_Brick_Ornate"
    },
    {
      "x": -21,
      "y": 29,
      "z": 2,
      "name": "Rock_Shale_Brick_Ornate"
    },
    {
      "x": -21,
      "y": 30,
      "z": 2,
      "name": "Rock_Shale_Brick_Ornate"
    },
    {
      "x": -21,
      "y": 31,
      "z": 2,
      "name": "Rock_Shale_Brick_Ornate"
    },
    {
      "x": -21,
      "y": 0,
      "z": 3,
      "name": "Rock_Shale_Brick_Ornate"
    },
    {
      "x": -21,
      "y": 1,
      "z": 3,
      "name": "Rock_Shale_Brick_Ornate"
    },
    {
      "x": -21,
      "y": 2,
      "z": 3,
      "name": "Rock_Shale_Brick_Ornate"
    },
    {
      "x": -21,
      "y": 3,
      "z": 3,
      "name": "Rock_Shale_Brick"
    },
    {
      "x": -21,
      "y": 4,
      "z": 3,
      "name": "Rock_Shale_Brick"
    },
    {
      "x": -21,
      "y": 5,
      "z": 3,
      "name": "Rock_Shale_Brick"
    },
    {
      "x": -21,
      "y": 6,
      "z": 3,
      "name": "Rock_Shale_Brick"
    },
    {
      "x": -21,
      "y": 7,
      "z": 3,
      "name": "Rock_Shale_Brick"
    },
    {
      "x": -21,
      "y": 8,
      "z": 3,
      "name": "Rock_Shale_Brick"
    },
    {
      "x": -21,
      "y": 9,
      "z": 3,
      "name": "Rock_Shale_Brick"
    },
    {
      "x": -21,
      "y": 10,
      "z": 3,
      "name": "Rock_Shale_Brick"
    },
    {
      "x": -21,
      "y": 11,
      "z": 3,
      "name": "Rock_Shale_Brick"
    },
    {
      "x": -21,
      "y": 12,
      "z": 3,
      "name": "Rock_Shale_Brick"
    },
    {
      "x": -21,
      "y": 13,
      "z": 3,
      "name": "Rock_Shale_Brick"
    },
    {
      "x": -21,
      "y": 20,
      "z": 3,
      "name": "Rock_Shale_Brick"
    },
    {
      "x": -21,
      "y": 21,
      "z": 3,
      "name": "Rock_Shale_Brick"
    },
    {
      "x": -21,
      "y": 22,
      "z": 3,
      "name": "Rock_Shale_Brick"
    },
    {
      "x": -21,
      "y": 23,
      "z": 3,
      "name": "Rock_Shale_Brick"
    },
    {
      "x": -21,
      "y": 24,
      "z": 3,
      "name": "Rock_Shale_Brick"
    },
    {
      "x": -21,
      "y": 25,
      "z": 3,
      "name": "Rock_Shale_Brick"
    },
    {
      "x": -21,
      "y": 26,
      "z": 3,
      "name": "Rock_Shale_Brick"
    },
    {
      "x": -21,
      "y": 27,
      "z": 3,
      "name": "Rock_Shale_Brick_Ornate"
    },
    {
      "x": -21,
      "y": 28,
      "z": 3,
      "name": "Rock_Shale_Brick_Ornate"
    },
    {
      "x": -21,
      "y": 29,
      "z": 3,
      "name": "Rock_Shale_Brick_Ornate"
    },
    {
      "x": -21,
      "y": 30,
      "z": 3,
      "name": "Rock_Shale_Brick_Ornate"
    },
    {
      "x": -21,
      "y": 31,
      "z": 3,
      "name": "Rock_Shale_Brick_Ornate"
    },
    {
      "x": -21,
      "y": 0,
      "z": 4,
      "name": "Rock_Shale_Brick_Ornate"
    },
    {
      "x": -21,
      "y": 1,
      "z": 4,
      "name": "Rock_Shale_Brick_Ornate"
    },
    {
      "x": -21,
      "y": 2,
      "z": 4,
      "name": "Rock_Shale_Brick"
    },
    {
      "x": -21,
      "y": 3,
      "z": 4,
      "name": "Rock_Shale_Brick"
    },
    {
      "x": -21,
      "y": 4,
      "z": 4,
      "name": "Rock_Shale_Brick"
    },
    {
      "x": -21,
      "y": 5,
      "z": 4,
      "name": "Rock_Shale_Brick"
    },
    {
      "x": -21,
      "y": 6,
      "z": 4,
      "name": "Rock_Shale_Brick"
    },
    {
      "x": -21,
      "y": 7,
      "z": 4,
      "name": "Rock_Shale_Brick"
    },
    {
      "x": -21,
      "y": 8,
      "z": 4,
      "name": "Rock_Shale_Brick"
    },
    {
      "x": -21,
      "y": 9,
      "z": 4,
      "name": "Rock_Shale_Brick"
    },
    {
      "x": -21,
      "y": 10,
      "z": 4,
      "name": "Rock_Shale_Brick"
    },
    {
      "x": -21,
      "y": 22,
      "z": 4,
      "name": "Rock_Shale_Brick"
    },
    {
      "x": -21,
      "y": 23,
      "z": 4,
      "name": "Rock_Shale_Brick"
    },
    {
      "x": -21,
      "y": 24,
      "z": 4,
      "name": "Rock_Shale_Brick"
    },
    {
      "x": -21,
      "y": 25,
      "z": 4,
      "name": "Rock_Shale_Brick"
    },
    {
      "x": -21,
      "y": 26,
      "z": 4,
      "name": "Rock_Shale_Brick"
    },
    {
      "x": -21,
      "y": 27,
      "z": 4,
      "name": "Rock_Shale_Brick_Ornate"
    },
    {
      "x": -21,
      "y": 28,
      "z": 4,
      "name": "Rock_Shale_Brick_Ornate"
    },
    {
      "x": -21,
      "y": 29,
      "z": 4,
      "name": "Rock_Shale_Brick_Ornate"
    },
    {
      "x": -21,
      "y": 30,
      "z": 4,
      "name": "Rock_Shale_Brick_Ornate"
    },
    {
      "x": -21,
      "y": 31,
      "z": 4,
      "name": "Rock_Shale_Brick_Ornate"
    },
    {
      "x": -21,
      "y": 0,
      "z": 5,
      "name": "Rock_Shale_Brick_Ornate"
    },
    {
      "x": -21,
      "y": 1,
      "z": 5,
      "name": "Rock_Shale_Brick_Ornate"
    },
    {
      "x": -21,
      "y": 2,
      "z": 5,
      "name": "Rock_Shale_Brick_Ornate"
    },
    {
      "x": -21,
      "y": 3,
      "z": 5,
      "name": "Rock_Shale_Brick_Ornate"
    },
    {
      "x": -21,
      "y": 27,
      "z": 5,
      "name": "Rock_Shale_Brick_Ornate"
    },
    {
      "x": -21,
      "y": 28,
      "z": 5,
      "name": "Rock_Shale_Brick_Ornate"
    },
    {
      "x": -21,
      "y": 29,
      "z": 5,
      "name": "Rock_Shale_Brick_Ornate"
    },
    {
      "x": -21,
      "y": 30,
      "z": 5,
      "name": "Rock_Shale_Brick_Ornate"
    },
    {
      "x": -21,
      "y": 31,
      "z": 5,
      "name": "Rock_Shale_Brick_Ornate"
    },
    {
      "x": -20,
      "y": 0,
      "z": -4,
      "name": "Rock_Shale_Brick_Ornate"
    },
    {
      "x": -20,
      "y": 1,
      "z": -4,
      "name": "Rock_Shale_Brick_Ornate"
    },
    {
      "x": -20,
      "y": 2,
      "z": -4,
      "name": "Rock_Shale_Brick_Ornate"
    },
    {
      "x": -20,
      "y": 3,
      "z": -4,
      "name": "Rock_Shale_Brick_Ornate"
    },
    {
      "x": -20,
      "y": 4,
      "z": -4,
      "name": "Rock_Shale_Brick_Ornate"
    },
    {
      "x": -20,
      "y": 27,
      "z": -4,
      "name": "Rock_Shale_Brick_Ornate"
    },
    {
      "x": -20,
      "y": 28,
      "z": -4,
      "name": "Rock_Shale_Brick_Ornate"
    },
    {
      "x": -20,
      "y": 29,
      "z": -4,
      "name": "Rock_Shale_Brick_Ornate"
    },
    {
      "x": -20,
      "y": 30,
      "z": -4,
      "name": "Rock_Shale_Brick_Ornate"
    },
    {
      "x": -20,
      "y": 0,
      "z": -3,
      "name": "Rock_Shale_Brick_Ornate"
    },
    {
      "x": -20,
      "y": 1,
      "z": -3,
      "name": "Rock_Shale_Brick_Ornate"
    },
    {
      "x": -20,
      "y": 2,
      "z": -3,
      "name": "Rock_Shale_Brick_Ornate"
    },
    {
      "x": -20,
      "y": 3,
      "z": -3,
      "name": "Rock_Shale_Brick_Ornate"
    },
    {
      "x": -20,
      "y": 4,
      "z": -3,
      "name": "Rock_Shale_Brick_Ornate"
    },
    {
      "x": -20,
      "y": 5,
      "z": -3,
      "name": "Rock_Shale_Brick"
    },
    {
      "x": -20,
      "y": 6,
      "z": -3,
      "name": "Rock_Shale_Brick"
    },
    {
      "x": -20,
      "y": 7,
      "z": -3,
      "name": "Rock_Shale_Brick"
    },
    {
      "x": -20,
      "y": 8,
      "z": -3,
      "name": "Rock_Shale_Brick"
    },
    {
      "x": -20,
      "y": 9,
      "z": -3,
      "name": "Rock_Shale_Brick"
    },
    {
      "x": -20,
      "y": 10,
      "z": -3,
      "name": "Rock_Shale_Brick"
    },
    {
      "x": -20,
      "y": 11,
      "z": -3,
      "name": "Rock_Shale_Brick"
    },
    {
      "x": -20,
      "y": 12,
      "z": -3,
      "name": "Rock_Shale_Brick"
    },
    {
      "x": -20,
      "y": 13,
      "z": -3,
      "name": "Rock_Shale_Brick"
    },
    {
      "x": -20,
      "y": 14,
      "z": -3,
      "name": "Rock_Shale_Brick"
    },
    {
      "x": -20,
      "y": 15,
      "z": -3,
      "name": "Rock_Shale_Brick"
    },
    {
      "x": -20,
      "y": 16,
      "z": -3,
      "name": "Rock_Shale_Brick"
    },
    {
      "x": -20,
      "y": 17,
      "z": -3,
      "name": "Rock_Shale_Brick"
    },
    {
      "x": -20,
      "y": 18,
      "z": -3,
      "name": "Rock_Shale_Brick"
    },
    {
      "x": -20,
      "y": 19,
      "z": -3,
      "name": "Rock_Shale_Brick"
    },
    {
      "x": -20,
      "y": 20,
      "z": -3,
      "name": "Rock_Shale_Brick"
    },
    {
      "x": -20,
      "y": 21,
      "z": -3,
      "name": "Rock_Shale_Brick"
    },
    {
      "x": -20,
      "y": 22,
      "z": -3,
      "name": "Rock_Shale_Brick"
    },
    {
      "x": -20,
      "y": 23,
      "z": -3,
      "name": "Rock_Shale_Brick"
    },
    {
      "x": -20,
      "y": 24,
      "z": -3,
      "name": "Rock_Shale_Brick"
    },
    {
      "x": -20,
      "y": 25,
      "z": -3,
      "name": "Rock_Shale_Brick"
    },
    {
      "x": -20,
      "y": 26,
      "z": -3,
      "name": "Rock_Shale_Brick"
    },
    {
      "x": -20,
      "y": 27,
      "z": -3,
      "name": "Rock_Shale_Brick_Ornate"
    },
    {
      "x": -20,
      "y": 28,
      "z": -3,
      "name": "Rock_Shale_Brick_Ornate"
    },
    {
      "x": -20,
      "y": 29,
      "z": -3,
      "name": "Rock_Shale_Brick_Ornate"
    },
    {
      "x": -20,
      "y": 30,
      "z": -3,
      "name": "Rock_Shale_Brick_Ornate"
    },
    {
      "x": -20,
      "y": 31,
      "z": -3,
      "name": "Rock_Shale_Brick_Ornate"
    },
    {
      "x": -20,
      "y": 0,
      "z": -2,
      "name": "Rock_Shale_Brick_Ornate"
    },
    {
      "x": -20,
      "y": 1,
      "z": -2,
      "name": "Rock_Shale_Brick_Ornate"
    },
    {
      "x": -20,
      "y": 2,
      "z": -2,
      "name": "Rock_Shale_Brick_Ornate"
    },
    {
      "x": -20,
      "y": 3,
      "z": -2,
      "name": "Rock_Shale_Brick_Ornate"
    },
    {
      "x": -20,
      "y": 4,
      "z": -2,
      "name": "Rock_Shale_Brick_Ornate"
    },
    {
      "x": -20,
      "y": 5,
      "z": -2,
      "name": "Rock_Shale_Brick"
    },
    {
      "x": -20,
      "y": 6,
      "z": -2,
      "name": "Rock_Shale_Brick"
    },
    {
      "x": -20,
      "y": 7,
      "z": -2,
      "name": "Rock_Shale_Brick"
    },
    {
      "x": -20,
      "y": 8,
      "z": -2,
      "name": "Rock_Shale_Brick"
    },
    {
      "x": -20,
      "y": 9,
      "z": -2,
      "name": "Rock_Shale_Brick"
    },
    {
      "x": -20,
      "y": 10,
      "z": -2,
      "name": "Rock_Shale_Brick"
    },
    {
      "x": -20,
      "y": 11,
      "z": -2,
      "name": "Rock_Shale_Brick"
    },
    {
      "x": -20,
      "y": 12,
      "z": -2,
      "name": "Rock_Shale_Brick"
    },
    {
      "x": -20,
      "y": 13,
      "z": -2,
      "name": "Rock_Shale_Brick"
    },
    {
      "x": -20,
      "y": 14,
      "z": -2,
      "name": "Rock_Shale_Brick"
    },
    {
      "x": -20,
      "y": 15,
      "z": -2,
      "name": "Rock_Shale_Brick"
    },
    {
      "x": -20,
      "y": 16,
      "z": -2,
      "name": "Rock_Shale_Brick"
    },
    {
      "x": -20,
      "y": 17,
      "z": -2,
      "name": "Rock_Shale_Brick"
    },
    {
      "x": -20,
      "y": 18,
      "z": -2,
      "name": "Rock_Shale_Brick"
    },
    {
      "x": -20,
      "y": 19,
      "z": -2,
      "name": "Rock_Shale_Brick"
    },
    {
      "x": -20,
      "y": 20,
      "z": -2,
      "name": "Rock_Shale_Brick"
    },
    {
      "x": -20,
      "y": 21,
      "z": -2,
      "name": "Rock_Shale_Brick"
    },
    {
      "x": -20,
      "y": 22,
      "z": -2,
      "name": "Rock_Shale_Brick"
    },
    {
      "x": -20,
      "y": 23,
      "z": -2,
      "name": "Rock_Shale_Brick"
    },
    {
      "x": -20,
      "y": 24,
      "z": -2,
      "name": "Rock_Shale_Brick"
    },
    {
      "x": -20,
      "y": 25,
      "z": -2,
      "name": "Rock_Shale_Brick"
    },
    {
      "x": -20,
      "y": 26,
      "z": -2,
      "name": "Rock_Shale_Brick"
    },
    {
      "x": -20,
      "y": 27,
      "z": -2,
      "name": "Rock_Shale_Brick_Ornate"
    },
    {
      "x": -20,
      "y": 28,
      "z": -2,
      "name": "Rock_Shale_Brick_Ornate"
    },
    {
      "x": -20,
      "y": 29,
      "z": -2,
      "name": "Rock_Shale_Brick_Ornate"
    },
    {
      "x": -20,
      "y": 30,
      "z": -2,
      "name": "Rock_Shale_Brick_Ornate"
    },
    {
      "x": -20,
      "y": 31,
      "z": -2,
      "name": "Rock_Shale_Brick_Ornate"
    },
    {
      "x": -20,
      "y": 0,
      "z": -1,
      "name": "Rock_Shale_Brick_Ornate"
    },
    {
      "x": -20,
      "y": 1,
      "z": -1,
      "name": "Rock_Shale_Brick_Ornate"
    },
    {
      "x": -20,
      "y": 2,
      "z": -1,
      "name": "Rock_Shale_Brick_Ornate"
    },
    {
      "x": -20,
      "y": 3,
      "z": -1,
      "name": "Rock_Shale_Brick_Ornate"
    },
    {
      "x": -20,
      "y": 4,
      "z": -1,
      "name": "Rock_Shale_Brick_Ornate"
    },
    {
      "x": -20,
      "y": 5,
      "z": -1,
      "name": "Rock_Shale_Brick"
    },
    {
      "x": -20,
      "y": 6,
      "z": -1,
      "name": "Rock_Shale_Brick"
    },
    {
      "x": -20,
      "y": 7,
      "z": -1,
      "name": "Rock_Shale_Brick"
    },
    {
      "x": -20,
      "y": 8,
      "z": -1,
      "name": "Rock_Shale_Brick"
    },
    {
      "x": -20,
      "y": 9,
      "z": -1,
      "name": "Rock_Shale_Brick"
    },
    {
      "x": -20,
      "y": 10,
      "z": -1,
      "name": "Rock_Shale_Brick"
    },
    {
      "x": -20,
      "y": 11,
      "z": -1,
      "name": "Rock_Shale_Brick"
    },
    {
      "x": -20,
      "y": 12,
      "z": -1,
      "name": "Rock_Shale_Brick"
    },
    {
      "x": -20,
      "y": 13,
      "z": -1,
      "name": "Rock_Shale_Brick"
    },
    {
      "x": -20,
      "y": 14,
      "z": -1,
      "name": "Rock_Shale_Brick"
    },
    {
      "x": -20,
      "y": 15,
      "z": -1,
      "name": "Rock_Shale_Brick"
    },
    {
      "x": -20,
      "y": 16,
      "z": -1,
      "name": "Rock_Shale_Brick"
    },
    {
      "x": -20,
      "y": 17,
      "z": -1,
      "name": "Rock_Shale_Brick"
    },
    {
      "x": -20,
      "y": 18,
      "z": -1,
      "name": "Rock_Shale_Brick"
    },
    {
      "x": -20,
      "y": 19,
      "z": -1,
      "name": "Rock_Shale_Brick"
    },
    {
      "x": -20,
      "y": 20,
      "z": -1,
      "name": "Rock_Shale_Brick"
    },
    {
      "x": -20,
      "y": 21,
      "z": -1,
      "name": "Rock_Shale_Brick"
    },
    {
      "x": -20,
      "y": 22,
      "z": -1,
      "name": "Rock_Shale_Brick"
    },
    {
      "x": -20,
      "y": 23,
      "z": -1,
      "name": "Rock_Shale_Brick"
    },
    {
      "x": -20,
      "y": 24,
      "z": -1,
      "name": "Rock_Shale_Brick"
    },
    {
      "x": -20,
      "y": 25,
      "z": -1,
      "name": "Rock_Shale_Brick"
    },
    {
      "x": -20,
      "y": 26,
      "z": -1,
      "name": "Rock_Shale_Brick"
    },
    {
      "x": -20,
      "y": 27,
      "z": -1,
      "name": "Rock_Shale_Brick_Ornate"
    },
    {
      "x": -20,
      "y": 28,
      "z": -1,
      "name": "Rock_Shale_Brick_Ornate"
    },
    {
      "x": -20,
      "y": 29,
      "z": -1,
      "name": "Rock_Shale_Brick_Ornate"
    },
    {
      "x": -20,
      "y": 30,
      "z": -1,
      "name": "Rock_Shale_Brick_Ornate"
    },
    {
      "x": -20,
      "y": 31,
      "z": -1,
      "name": "Rock_Shale_Brick_Ornate"
    },
    {
      "x": -20,
      "y": 0,
      "z": 0,
      "name": "Rock_Shale_Brick_Ornate"
    },
    {
      "x": -20,
      "y": 1,
      "z": 0,
      "name": "Rock_Shale_Brick_Ornate"
    },
    {
      "x": -20,
      "y": 2,
      "z": 0,
      "name": "Rock_Shale_Brick_Ornate"
    },
    {
      "x": -20,
      "y": 3,
      "z": 0,
      "name": "Rock_Shale_Brick_Ornate"
    },
    {
      "x": -20,
      "y": 4,
      "z": 0,
      "name": "Rock_Shale_Brick_Ornate"
    },
    {
      "x": -20,
      "y": 5,
      "z": 0,
      "name": "Rock_Shale_Brick"
    },
    {
      "x": -20,
      "y": 6,
      "z": 0,
      "name": "Rock_Shale_Brick"
    },
    {
      "x": -20,
      "y": 7,
      "z": 0,
      "name": "Rock_Shale_Brick"
    },
    {
      "x": -20,
      "y": 8,
      "z": 0,
      "name": "Rock_Shale_Brick"
    },
    {
      "x": -20,
      "y": 9,
      "z": 0,
      "name": "Rock_Shale_Brick"
    },
    {
      "x": -20,
      "y": 10,
      "z": 0,
      "name": "Rock_Shale_Brick"
    },
    {
      "x": -20,
      "y": 11,
      "z": 0,
      "name": "Rock_Shale_Brick"
    },
    {
      "x": -20,
      "y": 12,
      "z": 0,
      "name": "Rock_Shale_Brick"
    },
    {
      "x": -20,
      "y": 13,
      "z": 0,
      "name": "Rock_Shale_Brick"
    },
    {
      "x": -20,
      "y": 14,
      "z": 0,
      "name": "Rock_Shale_Brick"
    },
    {
      "x": -20,
      "y": 15,
      "z": 0,
      "name": "Rock_Shale_Brick"
    },
    {
      "x": -20,
      "y": 16,
      "z": 0,
      "name": "Rock_Shale_Brick"
    },
    {
      "x": -20,
      "y": 17,
      "z": 0,
      "name": "Rock_Shale_Brick"
    },
    {
      "x": -20,
      "y": 18,
      "z": 0,
      "name": "Rock_Shale_Brick"
    },
    {
      "x": -20,
      "y": 19,
      "z": 0,
      "name": "Rock_Shale_Brick"
    },
    {
      "x": -20,
      "y": 20,
      "z": 0,
      "name": "Rock_Shale_Brick"
    },
    {
      "x": -20,
      "y": 21,
      "z": 0,
      "name": "Rock_Shale_Brick"
    },
    {
      "x": -20,
      "y": 22,
      "z": 0,
      "name": "Rock_Shale_Brick"
    },
    {
      "x": -20,
      "y": 23,
      "z": 0,
      "name": "Rock_Shale_Brick"
    },
    {
      "x": -20,
      "y": 24,
      "z": 0,
      "name": "Rock_Shale_Brick"
    },
    {
      "x": -20,
      "y": 25,
      "z": 0,
      "name": "Rock_Shale_Brick"
    },
    {
      "x": -20,
      "y": 26,
      "z": 0,
      "name": "Rock_Shale_Brick"
    },
    {
      "x": -20,
      "y": 27,
      "z": 0,
      "name": "Rock_Shale_Brick_Ornate"
    },
    {
      "x": -20,
      "y": 28,
      "z": 0,
      "name": "Rock_Shale_Brick_Ornate"
    },
    {
      "x": -20,
      "y": 29,
      "z": 0,
      "name": "Rock_Shale_Brick_Ornate"
    },
    {
      "x": -20,
      "y": 30,
      "z": 0,
      "name": "Rock_Shale_Brick_Ornate"
    },
    {
      "x": -20,
      "y": 31,
      "z": 0,
      "name": "Rock_Shale_Brick_Ornate"
    },
    {
      "x": -20,
      "y": 0,
      "z": 1,
      "name": "Rock_Shale_Brick_Ornate"
    },
    {
      "x": -20,
      "y": 1,
      "z": 1,
      "name": "Rock_Shale_Brick_Ornate"
    },
    {
      "x": -20,
      "y": 2,
      "z": 1,
      "name": "Rock_Shale_Brick_Ornate"
    },
    {
      "x": -20,
      "y": 3,
      "z": 1,
      "name": "Rock_Shale_Brick_Ornate"
    },
    {
      "x": -20,
      "y": 4,
      "z": 1,
      "name": "Rock_Shale_Brick_Ornate"
    },
    {
      "x": -20,
      "y": 5,
      "z": 1,
      "name": "Rock_Shale_Brick"
    },
    {
      "x": -20,
      "y": 6,
      "z": 1,
      "name": "Rock_Shale_Brick"
    },
    {
      "x": -20,
      "y": 7,
      "z": 1,
      "name": "Rock_Shale_Brick"
    },
    {
      "x": -20,
      "y": 8,
      "z": 1,
      "name": "Rock_Shale_Brick"
    },
    {
      "x": -20,
      "y": 9,
      "z": 1,
      "name": "Rock_Shale_Brick"
    },
    {
      "x": -20,
      "y": 10,
      "z": 1,
      "name": "Rock_Shale_Brick"
    },
    {
      "x": -20,
      "y": 11,
      "z": 1,
      "name": "Rock_Shale_Brick"
    },
    {
      "x": -20,
      "y": 12,
      "z": 1,
      "name": "Rock_Shale_Brick"
    },
    {
      "x": -20,
      "y": 13,
      "z": 1,
      "name": "Rock_Shale_Brick"
    },
    {
      "x": -20,
      "y": 14,
      "z": 1,
      "name": "Rock_Shale_Brick"
    },
    {
      "x": -20,
      "y": 15,
      "z": 1,
      "name": "Rock_Shale_Brick"
    },
    {
      "x": -20,
      "y": 16,
      "z": 1,
      "name": "Rock_Shale_Brick"
    },
    {
      "x": -20,
      "y": 17,
      "z": 1,
      "name": "Rock_Shale_Brick"
    },
    {
      "x": -20,
      "y": 18,
      "z": 1,
      "name": "Rock_Shale_Brick"
    },
    {
      "x": -20,
      "y": 19,
      "z": 1,
      "name": "Rock_Shale_Brick"
    },
    {
      "x": -20,
      "y": 20,
      "z": 1,
      "name": "Rock_Shale_Brick"
    },
    {
      "x": -20,
      "y": 21,
      "z": 1,
      "name": "Rock_Shale_Brick"
    },
    {
      "x": -20,
      "y": 22,
      "z": 1,
      "name": "Rock_Shale_Brick"
    },
    {
      "x": -20,
      "y": 23,
      "z": 1,
      "name": "Rock_Shale_Brick"
    },
    {
      "x": -20,
      "y": 24,
      "z": 1,
      "name": "Rock_Shale_Brick"
    },
    {
      "x": -20,
      "y": 25,
      "z": 1,
      "name": "Rock_Shale_Brick"
    },
    {
      "x": -20,
      "y": 26,
      "z": 1,
      "name": "Rock_Shale_Brick"
    },
    {
      "x": -20,
      "y": 27,
      "z": 1,
      "name": "Rock_Shale_Brick_Ornate"
    },
    {
      "x": -20,
      "y": 28,
      "z": 1,
      "name": "Rock_Shale_Brick_Ornate"
    },
    {
      "x": -20,
      "y": 29,
      "z": 1,
      "name": "Rock_Shale_Brick_Ornate"
    },
    {
      "x": -20,
      "y": 30,
      "z": 1,
      "name": "Rock_Shale_Brick_Ornate"
    },
    {
      "x": -20,
      "y": 31,
      "z": 1,
      "name": "Rock_Shale_Brick_Ornate"
    },
    {
      "x": -20,
      "y": 0,
      "z": 2,
      "name": "Rock_Shale_Brick_Ornate"
    },
    {
      "x": -20,
      "y": 1,
      "z": 2,
      "name": "Rock_Shale_Brick_Ornate"
    },
    {
      "x": -20,
      "y": 2,
      "z": 2,
      "name": "Rock_Shale_Brick_Ornate"
    },
    {
      "x": -20,
      "y": 3,
      "z": 2,
      "name": "Rock_Shale_Brick_Ornate"
    },
    {
      "x": -20,
      "y": 4,
      "z": 2,
      "name": "Rock_Shale_Brick_Ornate"
    },
    {
      "x": -20,
      "y": 5,
      "z": 2,
      "name": "Rock_Shale_Brick"
    },
    {
      "x": -20,
      "y": 6,
      "z": 2,
      "name": "Rock_Shale_Brick"
    },
    {
      "x": -20,
      "y": 7,
      "z": 2,
      "name": "Rock_Shale_Brick"
    },
    {
      "x": -20,
      "y": 8,
      "z": 2,
      "name": "Rock_Shale_Brick"
    },
    {
      "x": -20,
      "y": 9,
      "z": 2,
      "name": "Rock_Shale_Brick"
    },
    {
      "x": -20,
      "y": 10,
      "z": 2,
      "name": "Rock_Shale_Brick"
    },
    {
      "x": -20,
      "y": 11,
      "z": 2,
      "name": "Rock_Shale_Brick"
    },
    {
      "x": -20,
      "y": 12,
      "z": 2,
      "name": "Rock_Shale_Brick"
    },
    {
      "x": -20,
      "y": 13,
      "z": 2,
      "name": "Rock_Shale_Brick"
    },
    {
      "x": -20,
      "y": 14,
      "z": 2,
      "name": "Rock_Shale_Brick"
    },
    {
      "x": -20,
      "y": 15,
      "z": 2,
      "name": "Rock_Shale_Brick"
    },
    {
      "x": -20,
      "y": 16,
      "z": 2,
      "name": "Rock_Shale_Brick"
    },
    {
      "x": -20,
      "y": 17,
      "z": 2,
      "name": "Rock_Shale_Brick"
    },
    {
      "x": -20,
      "y": 18,
      "z": 2,
      "name": "Rock_Shale_Brick"
    },
    {
      "x": -20,
      "y": 19,
      "z": 2,
      "name": "Rock_Shale_Brick"
    },
    {
      "x": -20,
      "y": 20,
      "z": 2,
      "name": "Rock_Shale_Brick"
    },
    {
      "x": -20,
      "y": 21,
      "z": 2,
      "name": "Rock_Shale_Brick"
    },
    {
      "x": -20,
      "y": 22,
      "z": 2,
      "name": "Rock_Shale_Brick"
    },
    {
      "x": -20,
      "y": 23,
      "z": 2,
      "name": "Rock_Shale_Brick"
    },
    {
      "x": -20,
      "y": 24,
      "z": 2,
      "name": "Rock_Shale_Brick"
    },
    {
      "x": -20,
      "y": 25,
      "z": 2,
      "name": "Rock_Shale_Brick"
    },
    {
      "x": -20,
      "y": 26,
      "z": 2,
      "name": "Rock_Shale_Brick"
    },
    {
      "x": -20,
      "y": 27,
      "z": 2,
      "name": "Rock_Shale_Brick_Ornate"
    },
    {
      "x": -20,
      "y": 28,
      "z": 2,
      "name": "Rock_Shale_Brick_Ornate"
    },
    {
      "x": -20,
      "y": 29,
      "z": 2,
      "name": "Rock_Shale_Brick_Ornate"
    },
    {
      "x": -20,
      "y": 30,
      "z": 2,
      "name": "Rock_Shale_Brick_Ornate"
    },
    {
      "x": -20,
      "y": 31,
      "z": 2,
      "name": "Rock_Shale_Brick_Ornate"
    },
    {
      "x": -20,
      "y": 0,
      "z": 3,
      "name": "Rock_Shale_Brick_Ornate"
    },
    {
      "x": -20,
      "y": 1,
      "z": 3,
      "name": "Rock_Shale_Brick_Ornate"
    },
    {
      "x": -20,
      "y": 2,
      "z": 3,
      "name": "Rock_Shale_Brick_Ornate"
    },
    {
      "x": -20,
      "y": 3,
      "z": 3,
      "name": "Rock_Shale_Brick_Ornate"
    },
    {
      "x": -20,
      "y": 4,
      "z": 3,
      "name": "Rock_Shale_Brick_Ornate"
    },
    {
      "x": -20,
      "y": 5,
      "z": 3,
      "name": "Rock_Shale_Brick"
    },
    {
      "x": -20,
      "y": 6,
      "z": 3,
      "name": "Rock_Shale_Brick"
    },
    {
      "x": -20,
      "y": 7,
      "z": 3,
      "name": "Rock_Shale_Brick"
    },
    {
      "x": -20,
      "y": 8,
      "z": 3,
      "name": "Rock_Shale_Brick"
    },
    {
      "x": -20,
      "y": 9,
      "z": 3,
      "name": "Rock_Shale_Brick"
    },
    {
      "x": -20,
      "y": 10,
      "z": 3,
      "name": "Rock_Shale_Brick"
    },
    {
      "x": -20,
      "y": 11,
      "z": 3,
      "name": "Rock_Shale_Brick"
    },
    {
      "x": -20,
      "y": 12,
      "z": 3,
      "name": "Rock_Shale_Brick"
    },
    {
      "x": -20,
      "y": 13,
      "z": 3,
      "name": "Rock_Shale_Brick"
    },
    {
      "x": -20,
      "y": 14,
      "z": 3,
      "name": "Rock_Shale_Brick"
    },
    {
      "x": -20,
      "y": 15,
      "z": 3,
      "name": "Rock_Shale_Brick"
    },
    {
      "x": -20,
      "y": 16,
      "z": 3,
      "name": "Rock_Shale_Brick"
    },
    {
      "x": -20,
      "y": 17,
      "z": 3,
      "name": "Rock_Shale_Brick"
    },
    {
      "x": -20,
      "y": 18,
      "z": 3,
      "name": "Rock_Shale_Brick"
    },
    {
      "x": -20,
      "y": 19,
      "z": 3,
      "name": "Rock_Shale_Brick"
    },
    {
      "x": -20,
      "y": 20,
      "z": 3,
      "name": "Rock_Shale_Brick"
    },
    {
      "x": -20,
      "y": 21,
      "z": 3,
      "name": "Rock_Shale_Brick"
    },
    {
      "x": -20,
      "y": 22,
      "z": 3,
      "name": "Rock_Shale_Brick"
    },
    {
      "x": -20,
      "y": 23,
      "z": 3,
      "name": "Rock_Shale_Brick"
    },
    {
      "x": -20,
      "y": 24,
      "z": 3,
      "name": "Rock_Shale_Brick"
    },
    {
      "x": -20,
      "y": 25,
      "z": 3,
      "name": "Rock_Shale_Brick"
    },
    {
      "x": -20,
      "y": 26,
      "z": 3,
      "name": "Rock_Shale_Brick"
    },
    {
      "x": -20,
      "y": 27,
      "z": 3,
      "name": "Rock_Shale_Brick_Ornate"
    },
    {
      "x": -20,
      "y": 28,
      "z": 3,
      "name": "Rock_Shale_Brick_Ornate"
    },
    {
      "x": -20,
      "y": 29,
      "z": 3,
      "name": "Rock_Shale_Brick_Ornate"
    },
    {
      "x": -20,
      "y": 30,
      "z": 3,
      "name": "Rock_Shale_Brick_Ornate"
    },
    {
      "x": -20,
      "y": 31,
      "z": 3,
      "name": "Rock_Shale_Brick_Ornate"
    },
    {
      "x": -20,
      "y": 0,
      "z": 4,
      "name": "Rock_Shale_Brick_Ornate"
    },
    {
      "x": -20,
      "y": 1,
      "z": 4,
      "name": "Rock_Shale_Brick_Ornate"
    },
    {
      "x": -20,
      "y": 2,
      "z": 4,
      "name": "Rock_Shale_Brick_Ornate"
    },
    {
      "x": -20,
      "y": 3,
      "z": 4,
      "name": "Rock_Shale_Brick_Ornate"
    },
    {
      "x": -20,
      "y": 4,
      "z": 4,
      "name": "Rock_Shale_Brick"
    },
    {
      "x": -20,
      "y": 5,
      "z": 4,
      "name": "Rock_Shale_Brick"
    },
    {
      "x": -20,
      "y": 6,
      "z": 4,
      "name": "Rock_Shale_Brick"
    },
    {
      "x": -20,
      "y": 7,
      "z": 4,
      "name": "Rock_Shale_Brick"
    },
    {
      "x": -20,
      "y": 8,
      "z": 4,
      "name": "Rock_Shale_Brick"
    },
    {
      "x": -20,
      "y": 9,
      "z": 4,
      "name": "Rock_Shale_Brick"
    },
    {
      "x": -20,
      "y": 10,
      "z": 4,
      "name": "Rock_Shale_Brick"
    },
    {
      "x": -20,
      "y": 11,
      "z": 4,
      "name": "Rock_Shale_Brick"
    },
    {
      "x": -20,
      "y": 12,
      "z": 4,
      "name": "Rock_Shale_Brick"
    },
    {
      "x": -20,
      "y": 13,
      "z": 4,
      "name": "Rock_Shale_Brick"
    },
    {
      "x": -20,
      "y": 14,
      "z": 4,
      "name": "Rock_Shale_Brick"
    },
    {
      "x": -20,
      "y": 15,
      "z": 4,
      "name": "Rock_Shale_Brick"
    },
    {
      "x": -20,
      "y": 16,
      "z": 4,
      "name": "Rock_Shale_Brick"
    },
    {
      "x": -20,
      "y": 21,
      "z": 4,
      "name": "Rock_Shale_Brick"
    },
    {
      "x": -20,
      "y": 22,
      "z": 4,
      "name": "Rock_Shale_Brick"
    },
    {
      "x": -20,
      "y": 23,
      "z": 4,
      "name": "Rock_Shale_Brick"
    },
    {
      "x": -20,
      "y": 24,
      "z": 4,
      "name": "Rock_Shale_Brick"
    },
    {
      "x": -20,
      "y": 25,
      "z": 4,
      "name": "Rock_Shale_Brick"
    },
    {
      "x": -20,
      "y": 26,
      "z": 4,
      "name": "Rock_Shale_Brick"
    },
    {
      "x": -20,
      "y": 27,
      "z": 4,
      "name": "Rock_Shale_Brick_Ornate"
    },
    {
      "x": -20,
      "y": 28,
      "z": 4,
      "name": "Rock_Shale_Brick_Ornate"
    },
    {
      "x": -20,
      "y": 29,
      "z": 4,
      "name": "Rock_Shale_Brick_Ornate"
    },
    {
      "x": -20,
      "y": 30,
      "z": 4,
      "name": "Rock_Shale_Brick_Ornate"
    },
    {
      "x": -20,
      "y": 31,
      "z": 4,
      "name": "Rock_Shale_Brick_Ornate"
    },
    {
      "x": -20,
      "y": 0,
      "z": 5,
      "name": "Rock_Shale_Brick_Ornate"
    },
    {
      "x": -20,
      "y": 1,
      "z": 5,
      "name": "Rock_Shale_Brick_Ornate"
    },
    {
      "x": -20,
      "y": 2,
      "z": 5,
      "name": "Rock_Shale_Brick_Ornate"
    },
    {
      "x": -20,
      "y": 3,
      "z": 5,
      "name": "Rock_Shale_Brick_Ornate"
    },
    {
      "x": -20,
      "y": 27,
      "z": 5,
      "name": "Rock_Shale_Brick_Ornate"
    },
    {
      "x": -20,
      "y": 28,
      "z": 5,
      "name": "Rock_Shale_Brick_Ornate"
    },
    {
      "x": -20,
      "y": 29,
      "z": 5,
      "name": "Rock_Shale_Brick_Ornate"
    },
    {
      "x": -20,
      "y": 30,
      "z": 5,
      "name": "Rock_Shale_Brick_Ornate"
    },
    {
      "x": -20,
      "y": 31,
      "z": 5,
      "name": "Rock_Shale_Brick_Ornate"
    },
    {
      "x": -19,
      "y": 0,
      "z": -4,
      "name": "Rock_Shale_Brick_Ornate"
    },
    {
      "x": -19,
      "y": 1,
      "z": -4,
      "name": "Rock_Shale_Brick_Ornate"
    },
    {
      "x": -19,
      "y": 2,
      "z": -4,
      "name": "Rock_Shale_Brick_Ornate"
    },
    {
      "x": -19,
      "y": 3,
      "z": -4,
      "name": "Rock_Shale_Brick_Ornate"
    },
    {
      "x": -19,
      "y": 4,
      "z": -4,
      "name": "Rock_Shale_Brick_Ornate"
    },
    {
      "x": -19,
      "y": 27,
      "z": -4,
      "name": "Rock_Shale_Brick_Ornate"
    },
    {
      "x": -19,
      "y": 28,
      "z": -4,
      "name": "Rock_Shale_Brick_Ornate"
    },
    {
      "x": -19,
      "y": 29,
      "z": -4,
      "name": "Rock_Shale_Brick_Ornate"
    },
    {
      "x": -19,
      "y": 30,
      "z": -4,
      "name": "Rock_Shale_Brick_Ornate"
    },
    {
      "x": -19,
      "y": 31,
      "z": -4,
      "name": "Rock_Shale_Brick_Ornate"
    },
    {
      "x": -19,
      "y": 0,
      "z": -3,
      "name": "Rock_Shale_Brick_Ornate"
    },
    {
      "x": -19,
      "y": 1,
      "z": -3,
      "name": "Rock_Shale_Brick_Ornate"
    },
    {
      "x": -19,
      "y": 2,
      "z": -3,
      "name": "Rock_Shale_Brick_Ornate"
    },
    {
      "x": -19,
      "y": 3,
      "z": -3,
      "name": "Rock_Shale_Brick_Ornate"
    },
    {
      "x": -19,
      "y": 4,
      "z": -3,
      "name": "Rock_Shale_Brick_Ornate"
    },
    {
      "x": -19,
      "y": 5,
      "z": -3,
      "name": "Rock_Shale_Brick"
    },
    {
      "x": -19,
      "y": 6,
      "z": -3,
      "name": "Rock_Shale_Brick"
    },
    {
      "x": -19,
      "y": 7,
      "z": -3,
      "name": "Rock_Shale_Brick"
    },
    {
      "x": -19,
      "y": 8,
      "z": -3,
      "name": "Rock_Shale_Brick"
    },
    {
      "x": -19,
      "y": 9,
      "z": -3,
      "name": "Rock_Shale_Brick"
    },
    {
      "x": -19,
      "y": 10,
      "z": -3,
      "name": "Rock_Shale_Brick"
    },
    {
      "x": -19,
      "y": 11,
      "z": -3,
      "name": "Rock_Shale_Brick"
    },
    {
      "x": -19,
      "y": 12,
      "z": -3,
      "name": "Rock_Shale_Brick"
    },
    {
      "x": -19,
      "y": 13,
      "z": -3,
      "name": "Rock_Shale_Brick"
    },
    {
      "x": -19,
      "y": 14,
      "z": -3,
      "name": "Rock_Shale_Brick"
    },
    {
      "x": -19,
      "y": 15,
      "z": -3,
      "name": "Rock_Shale_Brick"
    },
    {
      "x": -19,
      "y": 19,
      "z": -3,
      "name": "Rock_Shale_Brick"
    },
    {
      "x": -19,
      "y": 20,
      "z": -3,
      "name": "Rock_Shale_Brick"
    },
    {
      "x": -19,
      "y": 21,
      "z": -3,
      "name": "Rock_Shale_Brick"
    },
    {
      "x": -19,
      "y": 22,
      "z": -3,
      "name": "Rock_Shale_Brick"
    },
    {
      "x": -19,
      "y": 23,
      "z": -3,
      "name": "Rock_Shale_Brick"
    },
    {
      "x": -19,
      "y": 24,
      "z": -3,
      "name": "Rock_Shale_Brick"
    },
    {
      "x": -19,
      "y": 25,
      "z": -3,
      "name": "Rock_Shale_Brick"
    },
    {
      "x": -19,
      "y": 26,
      "z": -3,
      "name": "Rock_Shale_Brick"
    },
    {
      "x": -19,
      "y": 27,
      "z": -3,
      "name": "Rock_Shale_Brick_Ornate"
    },
    {
      "x": -19,
      "y": 28,
      "z": -3,
      "name": "Rock_Shale_Brick_Ornate"
    },
    {
      "x": -19,
      "y": 29,
      "z": -3,
      "name": "Rock_Shale_Brick_Ornate"
    },
    {
      "x": -19,
      "y": 30,
      "z": -3,
      "name": "Rock_Shale_Brick_Ornate"
    },
    {
      "x": -19,
      "y": 31,
      "z": -3,
      "name": "Rock_Shale_Brick_Ornate"
    },
    {
      "x": -19,
      "y": 0,
      "z": -2,
      "name": "Rock_Shale_Brick_Ornate"
    },
    {
      "x": -19,
      "y": 1,
      "z": -2,
      "name": "Rock_Shale_Brick_Ornate"
    },
    {
      "x": -19,
      "y": 2,
      "z": -2,
      "name": "Rock_Shale_Brick_Ornate"
    },
    {
      "x": -19,
      "y": 3,
      "z": -2,
      "name": "Rock_Shale_Brick_Ornate"
    },
    {
      "x": -19,
      "y": 4,
      "z": -2,
      "name": "Rock_Shale_Brick_Ornate"
    },
    {
      "x": -19,
      "y": 5,
      "z": -2,
      "name": "Rock_Shale_Brick"
    },
    {
      "x": -19,
      "y": 6,
      "z": -2,
      "name": "Rock_Shale_Brick"
    },
    {
      "x": -19,
      "y": 7,
      "z": -2,
      "name": "Rock_Shale_Brick"
    },
    {
      "x": -19,
      "y": 8,
      "z": -2,
      "name": "Rock_Shale_Brick"
    },
    {
      "x": -19,
      "y": 9,
      "z": -2,
      "name": "Rock_Shale_Brick"
    },
    {
      "x": -19,
      "y": 10,
      "z": -2,
      "name": "Rock_Shale_Brick"
    },
    {
      "x": -19,
      "y": 11,
      "z": -2,
      "name": "Rock_Shale_Brick"
    },
    {
      "x": -19,
      "y": 12,
      "z": -2,
      "name": "Rock_Shale_Brick"
    },
    {
      "x": -19,
      "y": 13,
      "z": -2,
      "name": "Rock_Shale_Brick"
    },
    {
      "x": -19,
      "y": 14,
      "z": -2,
      "name": "Rock_Shale_Brick"
    },
    {
      "x": -19,
      "y": 15,
      "z": -2,
      "name": "Rock_Shale_Brick"
    },
    {
      "x": -19,
      "y": 16,
      "z": -2,
      "name": "Rock_Shale_Brick"
    },
    {
      "x": -19,
      "y": 17,
      "z": -2,
      "name": "Rock_Shale_Brick"
    },
    {
      "x": -19,
      "y": 18,
      "z": -2,
      "name": "Rock_Shale_Brick"
    },
    {
      "x": -19,
      "y": 19,
      "z": -2,
      "name": "Rock_Shale_Brick"
    },
    {
      "x": -19,
      "y": 20,
      "z": -2,
      "name": "Rock_Shale_Brick"
    },
    {
      "x": -19,
      "y": 21,
      "z": -2,
      "name": "Rock_Shale_Brick"
    },
    {
      "x": -19,
      "y": 22,
      "z": -2,
      "name": "Rock_Shale_Brick"
    },
    {
      "x": -19,
      "y": 23,
      "z": -2,
      "name": "Rock_Shale_Brick"
    },
    {
      "x": -19,
      "y": 24,
      "z": -2,
      "name": "Rock_Shale_Brick"
    },
    {
      "x": -19,
      "y": 25,
      "z": -2,
      "name": "Rock_Shale_Brick"
    },
    {
      "x": -19,
      "y": 26,
      "z": -2,
      "name": "Rock_Shale_Brick"
    },
    {
      "x": -19,
      "y": 27,
      "z": -2,
      "name": "Rock_Shale_Brick_Ornate"
    },
    {
      "x": -19,
      "y": 28,
      "z": -2,
      "name": "Rock_Shale_Brick_Ornate"
    },
    {
      "x": -19,
      "y": 29,
      "z": -2,
      "name": "Rock_Shale_Brick_Ornate"
    },
    {
      "x": -19,
      "y": 30,
      "z": -2,
      "name": "Rock_Shale_Brick_Ornate"
    },
    {
      "x": -19,
      "y": 31,
      "z": -2,
      "name": "Rock_Shale_Brick_Ornate"
    },
    {
      "x": -19,
      "y": 0,
      "z": -1,
      "name": "Rock_Shale_Brick_Ornate"
    },
    {
      "x": -19,
      "y": 1,
      "z": -1,
      "name": "Rock_Shale_Brick_Ornate"
    },
    {
      "x": -19,
      "y": 2,
      "z": -1,
      "name": "Rock_Shale_Brick_Ornate"
    },
    {
      "x": -19,
      "y": 3,
      "z": -1,
      "name": "Rock_Shale_Brick_Ornate"
    },
    {
      "x": -19,
      "y": 4,
      "z": -1,
      "name": "Rock_Shale_Brick_Ornate"
    },
    {
      "x": -19,
      "y": 5,
      "z": -1,
      "name": "Rock_Shale_Brick"
    },
    {
      "x": -19,
      "y": 6,
      "z": -1,
      "name": "Rock_Shale_Brick"
    },
    {
      "x": -19,
      "y": 7,
      "z": -1,
      "name": "Rock_Shale_Brick"
    },
    {
      "x": -19,
      "y": 8,
      "z": -1,
      "name": "Rock_Shale_Brick"
    },
    {
      "x": -19,
      "y": 9,
      "z": -1,
      "name": "Rock_Shale_Brick"
    },
    {
      "x": -19,
      "y": 10,
      "z": -1,
      "name": "Rock_Shale_Brick"
    },
    {
      "x": -19,
      "y": 11,
      "z": -1,
      "name": "Rock_Shale_Brick"
    },
    {
      "x": -19,
      "y": 12,
      "z": -1,
      "name": "Rock_Shale_Brick"
    },
    {
      "x": -19,
      "y": 13,
      "z": -1,
      "name": "Rock_Shale_Brick"
    },
    {
      "x": -19,
      "y": 14,
      "z": -1,
      "name": "Rock_Shale_Brick"
    },
    {
      "x": -19,
      "y": 15,
      "z": -1,
      "name": "Rock_Shale_Brick"
    },
    {
      "x": -19,
      "y": 16,
      "z": -1,
      "name": "Rock_Shale_Brick"
    },
    {
      "x": -19,
      "y": 17,
      "z": -1,
      "name": "Rock_Shale_Brick"
    },
    {
      "x": -19,
      "y": 18,
      "z": -1,
      "name": "Rock_Shale_Brick"
    },
    {
      "x": -19,
      "y": 19,
      "z": -1,
      "name": "Rock_Shale_Brick"
    },
    {
      "x": -19,
      "y": 20,
      "z": -1,
      "name": "Rock_Shale_Brick"
    },
    {
      "x": -19,
      "y": 21,
      "z": -1,
      "name": "Rock_Shale_Brick"
    },
    {
      "x": -19,
      "y": 22,
      "z": -1,
      "name": "Rock_Shale_Brick"
    },
    {
      "x": -19,
      "y": 23,
      "z": -1,
      "name": "Rock_Shale_Brick"
    },
    {
      "x": -19,
      "y": 24,
      "z": -1,
      "name": "Rock_Shale_Brick"
    },
    {
      "x": -19,
      "y": 25,
      "z": -1,
      "name": "Rock_Shale_Brick"
    },
    {
      "x": -19,
      "y": 26,
      "z": -1,
      "name": "Rock_Shale_Brick"
    },
    {
      "x": -19,
      "y": 27,
      "z": -1,
      "name": "Rock_Shale_Brick_Ornate"
    },
    {
      "x": -19,
      "y": 28,
      "z": -1,
      "name": "Rock_Shale_Brick_Ornate"
    },
    {
      "x": -19,
      "y": 29,
      "z": -1,
      "name": "Rock_Shale_Brick_Ornate"
    },
    {
      "x": -19,
      "y": 30,
      "z": -1,
      "name": "Rock_Shale_Brick_Ornate"
    },
    {
      "x": -19,
      "y": 31,
      "z": -1,
      "name": "Rock_Shale_Brick_Ornate"
    },
    {
      "x": -19,
      "y": 0,
      "z": 0,
      "name": "Rock_Shale_Brick_Ornate"
    },
    {
      "x": -19,
      "y": 1,
      "z": 0,
      "name": "Rock_Shale_Brick_Ornate"
    },
    {
      "x": -19,
      "y": 2,
      "z": 0,
      "name": "Rock_Shale_Brick_Ornate"
    },
    {
      "x": -19,
      "y": 3,
      "z": 0,
      "name": "Rock_Shale_Brick_Ornate"
    },
    {
      "x": -19,
      "y": 4,
      "z": 0,
      "name": "Rock_Shale_Brick_Ornate"
    },
    {
      "x": -19,
      "y": 5,
      "z": 0,
      "name": "Rock_Shale_Brick"
    },
    {
      "x": -19,
      "y": 6,
      "z": 0,
      "name": "Rock_Shale_Brick"
    },
    {
      "x": -19,
      "y": 7,
      "z": 0,
      "name": "Rock_Shale_Brick"
    },
    {
      "x": -19,
      "y": 8,
      "z": 0,
      "name": "Rock_Shale_Brick"
    },
    {
      "x": -19,
      "y": 9,
      "z": 0,
      "name": "Rock_Shale_Brick"
    },
    {
      "x": -19,
      "y": 10,
      "z": 0,
      "name": "Rock_Shale_Brick"
    },
    {
      "x": -19,
      "y": 11,
      "z": 0,
      "name": "Rock_Shale_Brick"
    },
    {
      "x": -19,
      "y": 12,
      "z": 0,
      "name": "Rock_Shale_Brick"
    },
    {
      "x": -19,
      "y": 13,
      "z": 0,
      "name": "Rock_Shale_Brick"
    },
    {
      "x": -19,
      "y": 14,
      "z": 0,
      "name": "Rock_Shale_Brick"
    },
    {
      "x": -19,
      "y": 15,
      "z": 0,
      "name": "Rock_Shale_Brick"
    },
    {
      "x": -19,
      "y": 16,
      "z": 0,
      "name": "Rock_Shale_Brick"
    },
    {
      "x": -19,
      "y": 17,
      "z": 0,
      "name": "Rock_Shale_Brick"
    },
    {
      "x": -19,
      "y": 18,
      "z": 0,
      "name": "Rock_Shale_Brick"
    },
    {
      "x": -19,
      "y": 19,
      "z": 0,
      "name": "Rock_Shale_Brick"
    },
    {
      "x": -19,
      "y": 20,
      "z": 0,
      "name": "Rock_Shale_Brick"
    },
    {
      "x": -19,
      "y": 21,
      "z": 0,
      "name": "Rock_Shale_Brick"
    },
    {
      "x": -19,
      "y": 22,
      "z": 0,
      "name": "Rock_Shale_Brick"
    },
    {
      "x": -19,
      "y": 23,
      "z": 0,
      "name": "Rock_Shale_Brick"
    },
    {
      "x": -19,
      "y": 24,
      "z": 0,
      "name": "Rock_Shale_Brick"
    },
    {
      "x": -19,
      "y": 25,
      "z": 0,
      "name": "Rock_Shale_Brick"
    },
    {
      "x": -19,
      "y": 26,
      "z": 0,
      "name": "Rock_Shale_Brick"
    },
    {
      "x": -19,
      "y": 27,
      "z": 0,
      "name": "Rock_Shale_Brick_Ornate"
    },
    {
      "x": -19,
      "y": 28,
      "z": 0,
      "name": "Rock_Shale_Brick_Ornate"
    },
    {
      "x": -19,
      "y": 29,
      "z": 0,
      "name": "Rock_Shale_Brick_Ornate"
    },
    {
      "x": -19,
      "y": 30,
      "z": 0,
      "name": "Rock_Shale_Brick_Ornate"
    },
    {
      "x": -19,
      "y": 31,
      "z": 0,
      "name": "Rock_Shale_Brick_Ornate"
    },
    {
      "x": -19,
      "y": 0,
      "z": 1,
      "name": "Rock_Shale_Brick_Ornate",
      "rotation": 2
    },
    {
      "x": -19,
      "y": 1,
      "z": 1,
      "name": "Rock_Shale_Brick_Ornate",
      "rotation": 2
    },
    {
      "x": -19,
      "y": 2,
      "z": 1,
      "name": "Rock_Shale_Brick_Ornate",
      "rotation": 2
    },
    {
      "x": -19,
      "y": 3,
      "z": 1,
      "name": "Rock_Shale_Brick_Ornate",
      "rotation": 2
    },
    {
      "x": -19,
      "y": 4,
      "z": 1,
      "name": "Rock_Shale_Brick_Ornate",
      "rotation": 2
    },
    {
      "x": -19,
      "y": 5,
      "z": 1,
      "name": "Rock_Shale_Brick",
      "rotation": 2
    },
    {
      "x": -19,
      "y": 6,
      "z": 1,
      "name": "Rock_Shale_Brick",
      "rotation": 2
    },
    {
      "x": -19,
      "y": 7,
      "z": 1,
      "name": "Rock_Shale_Brick",
      "rotation": 2
    },
    {
      "x": -19,
      "y": 8,
      "z": 1,
      "name": "Rock_Shale_Brick",
      "rotation": 2
    },
    {
      "x": -19,
      "y": 9,
      "z": 1,
      "name": "Rock_Shale_Brick",
      "rotation": 2
    },
    {
      "x": -19,
      "y": 10,
      "z": 1,
      "name": "Rock_Shale_Brick",
      "rotation": 2
    },
    {
      "x": -19,
      "y": 11,
      "z": 1,
      "name": "Rock_Shale_Brick",
      "rotation": 2
    },
    {
      "x": -19,
      "y": 12,
      "z": 1,
      "name": "Rock_Shale_Brick",
      "rotation": 2
    },
    {
      "x": -19,
      "y": 13,
      "z": 1,
      "name": "Rock_Shale_Brick",
      "rotation": 2
    },
    {
      "x": -19,
      "y": 14,
      "z": 1,
      "name": "Rock_Shale_Brick",
      "rotation": 2
    },
    {
      "x": -19,
      "y": 15,
      "z": 1,
      "name": "Rock_Shale_Brick",
      "rotation": 2
    },
    {
      "x": -19,
      "y": 16,
      "z": 1,
      "name": "Rock_Shale_Brick",
      "rotation": 2
    },
    {
      "x": -19,
      "y": 17,
      "z": 1,
      "name": "Rock_Shale_Brick",
      "rotation": 2
    },
    {
      "x": -19,
      "y": 18,
      "z": 1,
      "name": "Rock_Shale_Brick",
      "rotation": 2
    },
    {
      "x": -19,
      "y": 19,
      "z": 1,
      "name": "Rock_Shale_Brick",
      "rotation": 2
    },
    {
      "x": -19,
      "y": 20,
      "z": 1,
      "name": "Rock_Shale_Brick",
      "rotation": 2
    },
    {
      "x": -19,
      "y": 21,
      "z": 1,
      "name": "Rock_Shale_Brick",
      "rotation": 2
    },
    {
      "x": -19,
      "y": 22,
      "z": 1,
      "name": "Rock_Shale_Brick",
      "rotation": 2
    },
    {
      "x": -19,
      "y": 23,
      "z": 1,
      "name": "Rock_Shale_Brick",
      "rotation": 2
    },
    {
      "x": -19,
      "y": 24,
      "z": 1,
      "name": "Rock_Shale_Brick",
      "rotation": 2
    },
    {
      "x": -19,
      "y": 25,
      "z": 1,
      "name": "Rock_Shale_Brick",
      "rotation": 2
    },
    {
      "x": -19,
      "y": 26,
      "z": 1,
      "name": "Rock_Shale_Brick",
      "rotation": 2
    },
    {
      "x": -19,
      "y": 27,
      "z": 1,
      "name": "Rock_Shale_Brick_Ornate"
    },
    {
      "x": -19,
      "y": 28,
      "z": 1,
      "name": "Rock_Shale_Brick_Ornate"
    },
    {
      "x": -19,
      "y": 29,
      "z": 1,
      "name": "Rock_Shale_Brick_Ornate"
    },
    {
      "x": -19,
      "y": 30,
      "z": 1,
      "name": "Rock_Shale_Brick_Ornate"
    },
    {
      "x": -19,
      "y": 31,
      "z": 1,
      "name": "Rock_Shale_Brick_Ornate"
    },
    {
      "x": -19,
      "y": 0,
      "z": 2,
      "name": "Rock_Shale_Brick_Ornate",
      "rotation": 2
    },
    {
      "x": -19,
      "y": 1,
      "z": 2,
      "name": "Rock_Shale_Brick_Ornate",
      "rotation": 2
    },
    {
      "x": -19,
      "y": 2,
      "z": 2,
      "name": "Rock_Shale_Brick_Ornate",
      "rotation": 2
    },
    {
      "x": -19,
      "y": 3,
      "z": 2,
      "name": "Rock_Shale_Brick_Ornate",
      "rotation": 2
    },
    {
      "x": -19,
      "y": 4,
      "z": 2,
      "name": "Rock_Shale_Brick_Ornate",
      "rotation": 2
    },
    {
      "x": -19,
      "y": 5,
      "z": 2,
      "name": "Rock_Shale_Brick",
      "rotation": 2
    },
    {
      "x": -19,
      "y": 6,
      "z": 2,
      "name": "Rock_Shale_Brick",
      "rotation": 2
    },
    {
      "x": -19,
      "y": 7,
      "z": 2,
      "name": "Rock_Shale_Brick",
      "rotation": 2
    },
    {
      "x": -19,
      "y": 8,
      "z": 2,
      "name": "Rock_Shale_Brick",
      "rotation": 2
    },
    {
      "x": -19,
      "y": 9,
      "z": 2,
      "name": "Rock_Shale_Brick",
      "rotation": 2
    },
    {
      "x": -19,
      "y": 10,
      "z": 2,
      "name": "Rock_Shale_Brick",
      "rotation": 2
    },
    {
      "x": -19,
      "y": 11,
      "z": 2,
      "name": "Rock_Shale_Brick",
      "rotation": 2
    },
    {
      "x": -19,
      "y": 12,
      "z": 2,
      "name": "Rock_Shale_Brick",
      "rotation": 2
    },
    {
      "x": -19,
      "y": 13,
      "z": 2,
      "name": "Rock_Shale_Brick",
      "rotation": 2
    },
    {
      "x": -19,
      "y": 14,
      "z": 2,
      "name": "Rock_Shale_Brick",
      "rotation": 2
    },
    {
      "x": -19,
      "y": 15,
      "z": 2,
      "name": "Rock_Shale_Brick",
      "rotation": 2
    },
    {
      "x": -19,
      "y": 16,
      "z": 2,
      "name": "Rock_Shale_Brick",
      "rotation": 2
    },
    {
      "x": -19,
      "y": 17,
      "z": 2,
      "name": "Rock_Shale_Brick",
      "rotation": 2
    },
    {
      "x": -19,
      "y": 18,
      "z": 2,
      "name": "Rock_Shale_Brick",
      "rotation": 2
    },
    {
      "x": -19,
      "y": 19,
      "z": 2,
      "name": "Rock_Shale_Brick",
      "rotation": 2
    },
    {
      "x": -19,
      "y": 20,
      "z": 2,
      "name": "Rock_Shale_Brick",
      "rotation": 2
    },
    {
      "x": -19,
      "y": 21,
      "z": 2,
      "name": "Rock_Shale_Brick",
      "rotation": 2
    },
    {
      "x": -19,
      "y": 22,
      "z": 2,
      "name": "Rock_Shale_Brick",
      "rotation": 2
    },
    {
      "x": -19,
      "y": 23,
      "z": 2,
      "name": "Rock_Shale_Brick",
      "rotation": 2
    },
    {
      "x": -19,
      "y": 24,
      "z": 2,
      "name": "Rock_Shale_Brick",
      "rotation": 2
    },
    {
      "x": -19,
      "y": 25,
      "z": 2,
      "name": "Rock_Shale_Brick",
      "rotation": 2
    },
    {
      "x": -19,
      "y": 26,
      "z": 2,
      "name": "Rock_Shale_Brick",
      "rotation": 2
    },
    {
      "x": -19,
      "y": 27,
      "z": 2,
      "name": "Rock_Shale_Brick_Ornate"
    },
    {
      "x": -19,
      "y": 28,
      "z": 2,
      "name": "Rock_Shale_Brick_Ornate"
    },
    {
      "x": -19,
      "y": 29,
      "z": 2,
      "name": "Rock_Shale_Brick_Ornate"
    },
    {
      "x": -19,
      "y": 30,
      "z": 2,
      "name": "Rock_Shale_Brick_Ornate"
    },
    {
      "x": -19,
      "y": 31,
      "z": 2,
      "name": "Rock_Shale_Brick_Ornate"
    },
    {
      "x": -19,
      "y": 0,
      "z": 3,
      "name": "Rock_Shale_Brick_Ornate",
      "rotation": 2
    },
    {
      "x": -19,
      "y": 1,
      "z": 3,
      "name": "Rock_Shale_Brick_Ornate",
      "rotation": 2
    },
    {
      "x": -19,
      "y": 2,
      "z": 3,
      "name": "Rock_Shale_Brick_Ornate",
      "rotation": 2
    },
    {
      "x": -19,
      "y": 3,
      "z": 3,
      "name": "Rock_Shale_Brick_Ornate",
      "rotation": 2
    },
    {
      "x": -19,
      "y": 4,
      "z": 3,
      "name": "Rock_Shale_Brick_Ornate",
      "rotation": 2
    },
    {
      "x": -19,
      "y": 5,
      "z": 3,
      "name": "Rock_Shale_Brick",
      "rotation": 2
    },
    {
      "x": -19,
      "y": 6,
      "z": 3,
      "name": "Rock_Shale_Brick",
      "rotation": 2
    },
    {
      "x": -19,
      "y": 7,
      "z": 3,
      "name": "Rock_Shale_Brick",
      "rotation": 2
    },
    {
      "x": -19,
      "y": 8,
      "z": 3,
      "name": "Rock_Shale_Brick",
      "rotation": 2
    },
    {
      "x": -19,
      "y": 9,
      "z": 3,
      "name": "Rock_Shale_Brick",
      "rotation": 2
    },
    {
      "x": -19,
      "y": 10,
      "z": 3,
      "name": "Rock_Shale_Brick",
      "rotation": 2
    },
    {
      "x": -19,
      "y": 11,
      "z": 3,
      "name": "Rock_Shale_Brick",
      "rotation": 2
    },
    {
      "x": -19,
      "y": 12,
      "z": 3,
      "name": "Rock_Shale_Brick",
      "rotation": 2
    },
    {
      "x": -19,
      "y": 13,
      "z": 3,
      "name": "Rock_Shale_Brick",
      "rotation": 2
    },
    {
      "x": -19,
      "y": 14,
      "z": 3,
      "name": "Rock_Shale_Brick",
      "rotation": 2
    },
    {
      "x": -19,
      "y": 15,
      "z": 3,
      "name": "Rock_Shale_Brick",
      "rotation": 2
    },
    {
      "x": -19,
      "y": 16,
      "z": 3,
      "name": "Rock_Shale_Brick",
      "rotation": 2
    },
    {
      "x": -19,
      "y": 17,
      "z": 3,
      "name": "Rock_Shale_Brick",
      "rotation": 2
    },
    {
      "x": -19,
      "y": 18,
      "z": 3,
      "name": "Rock_Shale_Brick",
      "rotation": 2
    },
    {
      "x": -19,
      "y": 19,
      "z": 3,
      "name": "Rock_Shale_Brick",
      "rotation": 2
    },
    {
      "x": -19,
      "y": 20,
      "z": 3,
      "name": "Rock_Shale_Brick",
      "rotation": 2
    },
    {
      "x": -19,
      "y": 21,
      "z": 3,
      "name": "Rock_Shale_Brick",
      "rotation": 2
    },
    {
      "x": -19,
      "y": 22,
      "z": 3,
      "name": "Rock_Shale_Brick",
      "rotation": 2
    },
    {
      "x": -19,
      "y": 23,
      "z": 3,
      "name": "Rock_Shale_Brick",
      "rotation": 2
    },
    {
      "x": -19,
      "y": 24,
      "z": 3,
      "name": "Rock_Shale_Brick",
      "rotation": 2
    },
    {
      "x": -19,
      "y": 25,
      "z": 3,
      "name": "Rock_Shale_Brick",
      "rotation": 2
    },
    {
      "x": -19,
      "y": 26,
      "z": 3,
      "name": "Rock_Shale_Brick",
      "rotation": 2
    },
    {
      "x": -19,
      "y": 27,
      "z": 3,
      "name": "Rock_Shale_Brick_Ornate"
    },
    {
      "x": -19,
      "y": 28,
      "z": 3,
      "name": "Rock_Shale_Brick_Ornate"
    },
    {
      "x": -19,
      "y": 29,
      "z": 3,
      "name": "Rock_Shale_Brick_Ornate"
    },
    {
      "x": -19,
      "y": 30,
      "z": 3,
      "name": "Rock_Shale_Brick_Ornate"
    },
    {
      "x": -19,
      "y": 31,
      "z": 3,
      "name": "Rock_Shale_Brick_Ornate"
    },
    {
      "x": -19,
      "y": 0,
      "z": 4,
      "name": "Rock_Shale_Brick_Ornate",
      "rotation": 2
    },
    {
      "x": -19,
      "y": 1,
      "z": 4,
      "name": "Rock_Shale_Brick_Ornate",
      "rotation": 2
    },
    {
      "x": -19,
      "y": 2,
      "z": 4,
      "name": "Rock_Shale_Brick_Ornate",
      "rotation": 2
    },
    {
      "x": -19,
      "y": 3,
      "z": 4,
      "name": "Rock_Shale_Brick_Ornate",
      "rotation": 2
    },
    {
      "x": -19,
      "y": 4,
      "z": 4,
      "name": "Rock_Shale_Brick_Ornate",
      "rotation": 2
    },
    {
      "x": -19,
      "y": 5,
      "z": 4,
      "name": "Rock_Shale_Brick",
      "rotation": 2
    },
    {
      "x": -19,
      "y": 6,
      "z": 4,
      "name": "Rock_Shale_Brick",
      "rotation": 2
    },
    {
      "x": -19,
      "y": 7,
      "z": 4,
      "name": "Rock_Shale_Brick",
      "rotation": 2
    },
    {
      "x": -19,
      "y": 8,
      "z": 4,
      "name": "Rock_Shale_Brick",
      "rotation": 2
    },
    {
      "x": -19,
      "y": 9,
      "z": 4,
      "name": "Rock_Shale_Brick",
      "rotation": 2
    },
    {
      "x": -19,
      "y": 10,
      "z": 4,
      "name": "Rock_Shale_Brick",
      "rotation": 2
    },
    {
      "x": -19,
      "y": 11,
      "z": 4,
      "name": "Rock_Shale_Brick",
      "rotation": 2
    },
    {
      "x": -19,
      "y": 12,
      "z": 4,
      "name": "Rock_Shale_Brick",
      "rotation": 2
    },
    {
      "x": -19,
      "y": 13,
      "z": 4,
      "name": "Rock_Shale_Brick",
      "rotation": 2
    },
    {
      "x": -19,
      "y": 14,
      "z": 4,
      "name": "Rock_Shale_Brick",
      "rotation": 2
    },
    {
      "x": -19,
      "y": 15,
      "z": 4,
      "name": "Rock_Shale_Brick",
      "rotation": 2
    },
    {
      "x": -19,
      "y": 16,
      "z": 4,
      "name": "Rock_Shale_Brick",
      "rotation": 2
    },
    {
      "x": -19,
      "y": 17,
      "z": 4,
      "name": "Rock_Shale_Brick",
      "rotation": 2
    },
    {
      "x": -19,
      "y": 18,
      "z": 4,
      "name": "Rock_Shale_Brick",
      "rotation": 2
    },
    {
      "x": -19,
      "y": 19,
      "z": 4,
      "name": "Rock_Shale_Brick",
      "rotation": 2
    },
    {
      "x": -19,
      "y": 20,
      "z": 4,
      "name": "Rock_Shale_Brick",
      "rotation": 2
    },
    {
      "x": -19,
      "y": 21,
      "z": 4,
      "name": "Rock_Shale_Brick",
      "rotation": 2
    },
    {
      "x": -19,
      "y": 22,
      "z": 4,
      "name": "Rock_Shale_Brick",
      "rotation": 2
    },
    {
      "x": -19,
      "y": 23,
      "z": 4,
      "name": "Rock_Shale_Brick",
      "rotation": 2
    },
    {
      "x": -19,
      "y": 24,
      "z": 4,
      "name": "Rock_Shale_Brick",
      "rotation": 2
    },
    {
      "x": -19,
      "y": 25,
      "z": 4,
      "name": "Rock_Shale_Brick",
      "rotation": 2
    },
    {
      "x": -19,
      "y": 26,
      "z": 4,
      "name": "Rock_Shale_Brick",
      "rotation": 2
    },
    {
      "x": -19,
      "y": 27,
      "z": 4,
      "name": "Rock_Shale_Brick_Ornate"
    },
    {
      "x": -19,
      "y": 28,
      "z": 4,
      "name": "Rock_Shale_Brick_Ornate"
    },
    {
      "x": -19,
      "y": 29,
      "z": 4,
      "name": "Rock_Shale_Brick_Ornate"
    },
    {
      "x": -19,
      "y": 30,
      "z": 4,
      "name": "Rock_Shale_Brick_Ornate"
    },
    {
      "x": -19,
      "y": 31,
      "z": 4,
      "name": "Rock_Shale_Brick_Ornate"
    },
    {
      "x": -19,
      "y": 0,
      "z": 5,
      "name": "Rock_Shale_Brick_Ornate",
      "rotation": 2
    },
    {
      "x": -19,
      "y": 1,
      "z": 5,
      "name": "Rock_Shale_Brick_Ornate",
      "rotation": 2
    },
    {
      "x": -19,
      "y": 2,
      "z": 5,
      "name": "Rock_Shale_Brick_Ornate",
      "rotation": 2
    },
    {
      "x": -19,
      "y": 3,
      "z": 5,
      "name": "Rock_Shale_Brick_Ornate",
      "rotation": 2
    },
    {
      "x": -19,
      "y": 4,
      "z": 5,
      "name": "Rock_Shale_Brick_Ornate",
      "rotation": 2
    },
    {
      "x": -19,
      "y": 27,
      "z": 5,
      "name": "Rock_Shale_Brick_Ornate"
    },
    {
      "x": -19,
      "y": 28,
      "z": 5,
      "name": "Rock_Shale_Brick_Ornate"
    },
    {
      "x": -19,
      "y": 29,
      "z": 5,
      "name": "Rock_Shale_Brick_Ornate"
    },
    {
      "x": -19,
      "y": 30,
      "z": 5,
      "name": "Rock_Shale_Brick_Ornate"
    },
    {
      "x": -19,
      "y": 31,
      "z": 5,
      "name": "Rock_Shale_Brick_Ornate"
    },
    {
      "x": -18,
      "y": 0,
      "z": -4,
      "name": "Rock_Shale_Brick_Ornate"
    },
    {
      "x": -18,
      "y": 1,
      "z": -4,
      "name": "Rock_Shale_Brick_Ornate"
    },
    {
      "x": -18,
      "y": 2,
      "z": -4,
      "name": "Rock_Shale_Brick_Ornate"
    },
    {
      "x": -18,
      "y": 3,
      "z": -4,
      "name": "Rock_Shale_Brick_Ornate"
    },
    {
      "x": -18,
      "y": 4,
      "z": -4,
      "name": "Rock_Shale_Brick_Ornate"
    },
    {
      "x": -18,
      "y": 27,
      "z": -4,
      "name": "Rock_Shale_Brick_Ornate"
    },
    {
      "x": -18,
      "y": 28,
      "z": -4,
      "name": "Rock_Shale_Brick_Ornate"
    },
    {
      "x": -18,
      "y": 29,
      "z": -4,
      "name": "Rock_Shale_Brick_Ornate"
    },
    {
      "x": -18,
      "y": 30,
      "z": -4,
      "name": "Rock_Shale_Brick_Ornate"
    },
    {
      "x": -18,
      "y": 31,
      "z": -4,
      "name": "Rock_Shale_Brick_Ornate"
    },
    {
      "x": -18,
      "y": 0,
      "z": -3,
      "name": "Rock_Shale_Brick_Ornate"
    },
    {
      "x": -18,
      "y": 1,
      "z": -3,
      "name": "Rock_Shale_Brick_Ornate"
    },
    {
      "x": -18,
      "y": 2,
      "z": -3,
      "name": "Rock_Shale_Brick_Ornate"
    },
    {
      "x": -18,
      "y": 3,
      "z": -3,
      "name": "Rock_Shale_Brick_Ornate"
    },
    {
      "x": -18,
      "y": 4,
      "z": -3,
      "name": "Rock_Shale_Brick_Ornate"
    },
    {
      "x": -18,
      "y": 5,
      "z": -3,
      "name": "Rock_Shale_Brick"
    },
    {
      "x": -18,
      "y": 6,
      "z": -3,
      "name": "Rock_Shale_Brick"
    },
    {
      "x": -18,
      "y": 7,
      "z": -3,
      "name": "Rock_Shale_Brick"
    },
    {
      "x": -18,
      "y": 8,
      "z": -3,
      "name": "Rock_Shale_Brick"
    },
    {
      "x": -18,
      "y": 9,
      "z": -3,
      "name": "Rock_Shale_Brick"
    },
    {
      "x": -18,
      "y": 10,
      "z": -3,
      "name": "Rock_Shale_Brick"
    },
    {
      "x": -18,
      "y": 11,
      "z": -3,
      "name": "Rock_Shale_Brick"
    },
    {
      "x": -18,
      "y": 12,
      "z": -3,
      "name": "Rock_Shale_Brick"
    },
    {
      "x": -18,
      "y": 13,
      "z": -3,
      "name": "Rock_Shale_Brick"
    },
    {
      "x": -18,
      "y": 22,
      "z": -3,
      "name": "Rock_Shale_Brick"
    },
    {
      "x": -18,
      "y": 23,
      "z": -3,
      "name": "Rock_Shale_Brick"
    },
    {
      "x": -18,
      "y": 24,
      "z": -3,
      "name": "Rock_Shale_Brick"
    },
    {
      "x": -18,
      "y": 25,
      "z": -3,
      "name": "Rock_Shale_Brick"
    },
    {
      "x": -18,
      "y": 26,
      "z": -3,
      "name": "Rock_Shale_Brick"
    },
    {
      "x": -18,
      "y": 27,
      "z": -3,
      "name": "Rock_Shale_Brick_Ornate"
    },
    {
      "x": -18,
      "y": 28,
      "z": -3,
      "name": "Rock_Shale_Brick_Ornate"
    },
    {
      "x": -18,
      "y": 29,
      "z": -3,
      "name": "Rock_Shale_Brick_Ornate"
    },
    {
      "x": -18,
      "y": 30,
      "z": -3,
      "name": "Rock_Shale_Brick_Ornate"
    },
    {
      "x": -18,
      "y": 31,
      "z": -3,
      "name": "Rock_Shale_Brick_Ornate"
    },
    {
      "x": -18,
      "y": 0,
      "z": -2,
      "name": "Rock_Shale_Brick_Ornate"
    },
    {
      "x": -18,
      "y": 1,
      "z": -2,
      "name": "Rock_Shale_Brick_Ornate"
    },
    {
      "x": -18,
      "y": 2,
      "z": -2,
      "name": "Rock_Shale_Brick_Ornate"
    },
    {
      "x": -18,
      "y": 3,
      "z": -2,
      "name": "Rock_Shale_Brick_Ornate"
    },
    {
      "x": -18,
      "y": 4,
      "z": -2,
      "name": "Rock_Shale_Brick_Ornate"
    },
    {
      "x": -18,
      "y": 5,
      "z": -2,
      "name": "Rock_Shale_Brick"
    },
    {
      "x": -18,
      "y": 6,
      "z": -2,
      "name": "Rock_Shale_Brick"
    },
    {
      "x": -18,
      "y": 7,
      "z": -2,
      "name": "Rock_Shale_Brick"
    },
    {
      "x": -18,
      "y": 8,
      "z": -2,
      "name": "Rock_Shale_Brick"
    },
    {
      "x": -18,
      "y": 9,
      "z": -2,
      "name": "Rock_Shale_Brick"
    },
    {
      "x": -18,
      "y": 10,
      "z": -2,
      "name": "Rock_Shale_Brick"
    },
    {
      "x": -18,
      "y": 11,
      "z": -2,
      "name": "Rock_Shale_Brick"
    },
    {
      "x": -18,
      "y": 12,
      "z": -2,
      "name": "Rock_Shale_Brick"
    },
    {
      "x": -18,
      "y": 13,
      "z": -2,
      "name": "Rock_Shale_Brick"
    },
    {
      "x": -18,
      "y": 14,
      "z": -2,
      "name": "Rock_Shale_Brick"
    },
    {
      "x": -18,
      "y": 15,
      "z": -2,
      "name": "Rock_Shale_Brick"
    },
    {
      "x": -18,
      "y": 19,
      "z": -2,
      "name": "Rock_Shale_Brick"
    },
    {
      "x": -18,
      "y": 20,
      "z": -2,
      "name": "Rock_Shale_Brick"
    },
    {
      "x": -18,
      "y": 21,
      "z": -2,
      "name": "Rock_Shale_Brick"
    },
    {
      "x": -18,
      "y": 22,
      "z": -2,
      "name": "Rock_Shale_Brick"
    },
    {
      "x": -18,
      "y": 23,
      "z": -2,
      "name": "Rock_Shale_Brick"
    },
    {
      "x": -18,
      "y": 24,
      "z": -2,
      "name": "Rock_Shale_Brick"
    },
    {
      "x": -18,
      "y": 25,
      "z": -2,
      "name": "Rock_Shale_Brick"
    },
    {
      "x": -18,
      "y": 26,
      "z": -2,
      "name": "Rock_Shale_Brick"
    },
    {
      "x": -18,
      "y": 27,
      "z": -2,
      "name": "Rock_Shale_Brick_Ornate"
    },
    {
      "x": -18,
      "y": 28,
      "z": -2,
      "name": "Rock_Shale_Brick_Ornate"
    },
    {
      "x": -18,
      "y": 29,
      "z": -2,
      "name": "Rock_Shale_Brick_Ornate"
    },
    {
      "x": -18,
      "y": 30,
      "z": -2,
      "name": "Rock_Shale_Brick_Ornate"
    },
    {
      "x": -18,
      "y": 31,
      "z": -2,
      "name": "Rock_Shale_Brick_Ornate"
    },
    {
      "x": -18,
      "y": 0,
      "z": -1,
      "name": "Rock_Shale_Brick_Ornate"
    },
    {
      "x": -18,
      "y": 1,
      "z": -1,
      "name": "Rock_Shale_Brick_Ornate"
    },
    {
      "x": -18,
      "y": 2,
      "z": -1,
      "name": "Rock_Shale_Brick_Ornate"
    },
    {
      "x": -18,
      "y": 3,
      "z": -1,
      "name": "Rock_Shale_Brick_Ornate"
    },
    {
      "x": -18,
      "y": 4,
      "z": -1,
      "name": "Rock_Shale_Brick_Ornate"
    },
    {
      "x": -18,
      "y": 5,
      "z": -1,
      "name": "Rock_Shale_Brick"
    },
    {
      "x": -18,
      "y": 6,
      "z": -1,
      "name": "Rock_Shale_Brick"
    },
    {
      "x": -18,
      "y": 7,
      "z": -1,
      "name": "Rock_Shale_Brick"
    },
    {
      "x": -18,
      "y": 8,
      "z": -1,
      "name": "Rock_Shale_Brick"
    },
    {
      "x": -18,
      "y": 9,
      "z": -1,
      "name": "Rock_Shale_Brick"
    },
    {
      "x": -18,
      "y": 10,
      "z": -1,
      "name": "Rock_Shale_Brick"
    },
    {
      "x": -18,
      "y": 11,
      "z": -1,
      "name": "Rock_Shale_Brick"
    },
    {
      "x": -18,
      "y": 12,
      "z": -1,
      "name": "Rock_Shale_Brick"
    },
    {
      "x": -18,
      "y": 13,
      "z": -1,
      "name": "Rock_Shale_Brick"
    },
    {
      "x": -18,
      "y": 14,
      "z": -1,
      "name": "Rock_Shale_Brick"
    },
    {
      "x": -18,
      "y": 15,
      "z": -1,
      "name": "Rock_Shale_Brick"
    },
    {
      "x": -18,
      "y": 16,
      "z": -1,
      "name": "Rock_Shale_Brick"
    },
    {
      "x": -18,
      "y": 17,
      "z": -1,
      "name": "Rock_Shale_Brick"
    },
    {
      "x": -18,
      "y": 18,
      "z": -1,
      "name": "Rock_Shale_Brick"
    },
    {
      "x": -18,
      "y": 19,
      "z": -1,
      "name": "Rock_Shale_Brick"
    },
    {
      "x": -18,
      "y": 20,
      "z": -1,
      "name": "Rock_Shale_Brick"
    },
    {
      "x": -18,
      "y": 21,
      "z": -1,
      "name": "Rock_Shale_Brick"
    },
    {
      "x": -18,
      "y": 22,
      "z": -1,
      "name": "Rock_Shale_Brick"
    },
    {
      "x": -18,
      "y": 23,
      "z": -1,
      "name": "Rock_Shale_Brick"
    },
    {
      "x": -18,
      "y": 24,
      "z": -1,
      "name": "Rock_Shale_Brick"
    },
    {
      "x": -18,
      "y": 25,
      "z": -1,
      "name": "Rock_Shale_Brick"
    },
    {
      "x": -18,
      "y": 26,
      "z": -1,
      "name": "Rock_Shale_Brick"
    },
    {
      "x": -18,
      "y": 27,
      "z": -1,
      "name": "Rock_Shale_Brick_Ornate"
    },
    {
      "x": -18,
      "y": 28,
      "z": -1,
      "name": "Rock_Shale_Brick_Ornate"
    },
    {
      "x": -18,
      "y": 29,
      "z": -1,
      "name": "Rock_Shale_Brick_Ornate"
    },
    {
      "x": -18,
      "y": 30,
      "z": -1,
      "name": "Rock_Shale_Brick_Ornate"
    },
    {
      "x": -18,
      "y": 31,
      "z": -1,
      "name": "Rock_Shale_Brick_Ornate"
    },
    {
      "x": -18,
      "y": 0,
      "z": 0,
      "name": "Rock_Shale_Brick_Ornate"
    },
    {
      "x": -18,
      "y": 1,
      "z": 0,
      "name": "Rock_Shale_Brick_Ornate"
    },
    {
      "x": -18,
      "y": 2,
      "z": 0,
      "name": "Rock_Shale_Brick_Ornate"
    },
    {
      "x": -18,
      "y": 3,
      "z": 0,
      "name": "Rock_Shale_Brick_Ornate"
    },
    {
      "x": -18,
      "y": 4,
      "z": 0,
      "name": "Rock_Shale_Brick_Ornate"
    },
    {
      "x": -18,
      "y": 5,
      "z": 0,
      "name": "Rock_Shale_Brick"
    },
    {
      "x": -18,
      "y": 6,
      "z": 0,
      "name": "Rock_Shale_Brick"
    },
    {
      "x": -18,
      "y": 7,
      "z": 0,
      "name": "Rock_Shale_Brick"
    },
    {
      "x": -18,
      "y": 8,
      "z": 0,
      "name": "Rock_Shale_Brick"
    },
    {
      "x": -18,
      "y": 9,
      "z": 0,
      "name": "Rock_Shale_Brick"
    },
    {
      "x": -18,
      "y": 10,
      "z": 0,
      "name": "Rock_Shale_Brick"
    },
    {
      "x": -18,
      "y": 11,
      "z": 0,
      "name": "Rock_Shale_Brick"
    },
    {
      "x": -18,
      "y": 12,
      "z": 0,
      "name": "Rock_Shale_Brick"
    },
    {
      "x": -18,
      "y": 13,
      "z": 0,
      "name": "Rock_Shale_Brick"
    },
    {
      "x": -18,
      "y": 14,
      "z": 0,
      "name": "Rock_Shale_Brick"
    },
    {
      "x": -18,
      "y": 15,
      "z": 0,
      "name": "Rock_Shale_Brick"
    },
    {
      "x": -18,
      "y": 16,
      "z": 0,
      "name": "Rock_Shale_Brick"
    },
    {
      "x": -18,
      "y": 17,
      "z": 0,
      "name": "Rock_Shale_Brick"
    },
    {
      "x": -18,
      "y": 18,
      "z": 0,
      "name": "Rock_Shale_Brick"
    },
    {
      "x": -18,
      "y": 19,
      "z": 0,
      "name": "Rock_Shale_Brick"
    },
    {
      "x": -18,
      "y": 20,
      "z": 0,
      "name": "Rock_Shale_Brick"
    },
    {
      "x": -18,
      "y": 21,
      "z": 0,
      "name": "Rock_Shale_Brick"
    },
    {
      "x": -18,
      "y": 22,
      "z": 0,
      "name": "Rock_Shale_Brick"
    },
    {
      "x": -18,
      "y": 23,
      "z": 0,
      "name": "Rock_Shale_Brick"
    },
    {
      "x": -18,
      "y": 24,
      "z": 0,
      "name": "Rock_Shale_Brick"
    },
    {
      "x": -18,
      "y": 25,
      "z": 0,
      "name": "Rock_Shale_Brick"
    },
    {
      "x": -18,
      "y": 26,
      "z": 0,
      "name": "Rock_Shale_Brick"
    },
    {
      "x": -18,
      "y": 27,
      "z": 0,
      "name": "Rock_Shale_Brick_Ornate"
    },
    {
      "x": -18,
      "y": 28,
      "z": 0,
      "name": "Rock_Shale_Brick_Ornate"
    },
    {
      "x": -18,
      "y": 29,
      "z": 0,
      "name": "Rock_Shale_Brick_Ornate"
    },
    {
      "x": -18,
      "y": 30,
      "z": 0,
      "name": "Rock_Shale_Brick_Ornate"
    },
    {
      "x": -18,
      "y": 31,
      "z": 0,
      "name": "Rock_Shale_Brick_Ornate"
    },
    {
      "x": -18,
      "y": 0,
      "z": 1,
      "name": "Rock_Shale_Brick_Ornate",
      "rotation": 2
    },
    {
      "x": -18,
      "y": 1,
      "z": 1,
      "name": "Rock_Shale_Brick_Ornate",
      "rotation": 2
    },
    {
      "x": -18,
      "y": 2,
      "z": 1,
      "name": "Rock_Shale_Brick_Ornate",
      "rotation": 2
    },
    {
      "x": -18,
      "y": 3,
      "z": 1,
      "name": "Rock_Shale_Brick_Ornate",
      "rotation": 2
    },
    {
      "x": -18,
      "y": 4,
      "z": 1,
      "name": "Rock_Shale_Brick_Ornate",
      "rotation": 2
    },
    {
      "x": -18,
      "y": 5,
      "z": 1,
      "name": "Rock_Shale_Brick",
      "rotation": 2
    },
    {
      "x": -18,
      "y": 6,
      "z": 1,
      "name": "Rock_Shale_Brick",
      "rotation": 2
    },
    {
      "x": -18,
      "y": 7,
      "z": 1,
      "name": "Rock_Shale_Brick",
      "rotation": 2
    },
    {
      "x": -18,
      "y": 8,
      "z": 1,
      "name": "Rock_Shale_Brick",
      "rotation": 2
    },
    {
      "x": -18,
      "y": 9,
      "z": 1,
      "name": "Rock_Shale_Brick",
      "rotation": 2
    },
    {
      "x": -18,
      "y": 10,
      "z": 1,
      "name": "Rock_Shale_Brick",
      "rotation": 2
    },
    {
      "x": -18,
      "y": 11,
      "z": 1,
      "name": "Rock_Shale_Brick",
      "rotation": 2
    },
    {
      "x": -18,
      "y": 12,
      "z": 1,
      "name": "Rock_Shale_Brick",
      "rotation": 2
    },
    {
      "x": -18,
      "y": 13,
      "z": 1,
      "name": "Rock_Shale_Brick",
      "rotation": 2
    },
    {
      "x": -18,
      "y": 14,
      "z": 1,
      "name": "Rock_Shale_Brick",
      "rotation": 2
    },
    {
      "x": -18,
      "y": 15,
      "z": 1,
      "name": "Rock_Shale_Brick",
      "rotation": 2
    },
    {
      "x": -18,
      "y": 16,
      "z": 1,
      "name": "Rock_Shale_Brick",
      "rotation": 2
    },
    {
      "x": -18,
      "y": 17,
      "z": 1,
      "name": "Rock_Shale_Brick",
      "rotation": 2
    },
    {
      "x": -18,
      "y": 18,
      "z": 1,
      "name": "Rock_Shale_Brick",
      "rotation": 2
    },
    {
      "x": -18,
      "y": 19,
      "z": 1,
      "name": "Rock_Shale_Brick",
      "rotation": 2
    },
    {
      "x": -18,
      "y": 20,
      "z": 1,
      "name": "Rock_Shale_Brick",
      "rotation": 2
    },
    {
      "x": -18,
      "y": 21,
      "z": 1,
      "name": "Rock_Shale_Brick",
      "rotation": 2
    },
    {
      "x": -18,
      "y": 22,
      "z": 1,
      "name": "Rock_Shale_Brick",
      "rotation": 2
    },
    {
      "x": -18,
      "y": 23,
      "z": 1,
      "name": "Rock_Shale_Brick",
      "rotation": 2
    },
    {
      "x": -18,
      "y": 24,
      "z": 1,
      "name": "Rock_Shale_Brick",
      "rotation": 2
    },
    {
      "x": -18,
      "y": 25,
      "z": 1,
      "name": "Rock_Shale_Brick",
      "rotation": 2
    },
    {
      "x": -18,
      "y": 26,
      "z": 1,
      "name": "Rock_Shale_Brick",
      "rotation": 2
    },
    {
