{
  "version": 8,
  "blockIdVersion": 11,
  "anchorX": 0,
  "anchorY": 0,
  "anchorZ": 0,
  "blocks": [
    {
      "x": -43,
      "y": 0,
      "z": -4,
      "name": "Rock_Shale_Brick_Ornate"
    },
    {
      "x": -43,
      "y": 1,
      "z": -4,
      "name": "Rock_Shale_Brick_Ornate"
    },
    {
      "x": -43,
      "y": 2,
      "z": -4,
      "name": "Rock_Shale_Brick_Ornate"
    },
    {
      "x": -43,
      "y": 27,
      "z": -4,
      "name": "Rock_Shale_Brick_Ornate"
    },
    {
      "x": -43,
      "y": 0,
      "z": -3,
      "name": "Rock_Shale_Brick_Ornate"
    },
    {
      "x": -43,
      "y": 1,
      "z": -3,
      "name": "Rock_Shale_Brick_Ornate"
    },
    {
      "x": -43,
      "y": 2,
      "z": -3,
      "name": "Rock_Shale_Brick_Ornate"
    },
    {
      "x": -43,
      "y": 3,
      "z": -3,
      "name": "Rock_Shale_Brick_Ornate"
    },
    {
      "x": -43,
      "y": 4,
      "z": -3,
      "name": "Rock_Shale_Brick_Ornate"
    },
    {
      "x": -43,
      "y": 27,
      "z": -3,
      "name": "Rock_Shale_Brick_Ornate"
    },
    {
      "x": -43,
      "y": 28,
      "z": -3,
      "name": "Rock_Shale_Brick_Ornate"
    },
    {
      "x": -43,
      "y": 0,
      "z": -2,
      "name": "Rock_Shale_Brick_Ornate"
    },
    {
      "x": -43,
      "y": 1,
      "z": -2,
      "name": "Rock_Shale_Brick_Ornate"
    },
    {
      "x": -43,
      "y": 2,
      "z": -2,
      "name": "Rock_Shale_Brick_Ornate"
    },
    {
      "x": -43,
      "y": 3,
      "z": -2,
      "name": "Rock_Shale_Brick_Ornate"
    },
    {
      "x": -43,
      "y": 4,
      "z": -2,
      "name": "Rock_Shale_Brick_Ornate"
    },
    {
      "x": -43,
      "y": 27,
      "z": -2,
      "name": "Rock_Shale_Brick_Ornate"
    },
    {
      "x": -43,
      "y": 28,
      "z": -2,
      "name": "Rock_Shale_Brick_Ornate"
    },
    {
      "x": -43,
      "y": 29,
      "z": -2,
      "name": "Rock_Shale_Brick_Ornate"
    },
    {
      "x": -43,
      "y": 30,
      "z": -2,
      "name": "Rock_Shale_Brick_Ornate"
    },
    {
      "x": -43,
      "y": 0,
      "z": -1,
      "name": "Rock_Shale_Brick_Ornate"
    },
    {
      "x": -43,
      "y": 1,
      "z": -1,
      "name": "Rock_Shale_Brick_Ornate"
    },
    {
      "x": -43,
      "y": 2,
      "z": -1,
      "name": "Rock_Shale_Brick_Ornate"
    },
    {
      "x": -43,
      "y": 3,
      "z": -1,
      "name": "Rock_Shale_Brick_Ornate"
    },
    {
      "x": -43,
      "y": 4,
      "z": -1,
      "name": "Rock_Shale_Brick_Ornate"
    },
    {
      "x": -43,
      "y": 27,
      "z": -1,
      "name": "Rock_Shale_Brick_Ornate"
    },
    {
      "x": -43,
      "y": 28,
      "z": -1,
      "name": "Rock_Shale_Brick_Ornate"
    },
    {
      "x": -43,
      "y": 29,
      "z": -1,
      "name": "Rock_Shale_Brick_Ornate"
    },
    {
      "x": -43,
      "y": 30,
      "z": -1,
      "name": "Rock_Shale_Brick_Ornate"
    },
    {
      "x": -43,
      "y": 31,
      "z": -1,
      "name": "Rock_Shale_Brick_Ornate"
    },
    {
      "x": -43,
      "y": 0,
      "z": 0,
      "name": "Rock_Shale_Brick_Ornate"
    },
    {
      "x": -43,
      "y": 1,
      "z": 0,
      "name": "Rock_Shale_Brick_Ornate"
    },
    {
      "x": -43,
      "y": 2,
      "z": 0,
      "name": "Rock_Shale_Brick_Ornate"
    },
    {
      "x": -43,
      "y": 3,
      "z": 0,
      "name": "Rock_Shale_Brick_Ornate"
    },
    {
      "x": -43,
      "y": 4,
      "z": 0,
      "name": "Rock_Shale_Brick_Ornate"
    },
    {
      "x": -43,
      "y": 27,
      "z": 0,
      "name": "Rock_Shale_Brick_Ornate"
    },
    {
      "x": -43,
      "y": 28,
      "z": 0,
      "name": "Rock_Shale_Brick_Ornate"
    },
    {
      "x": -43,
      "y": 29,
      "z": 0,
      "name": "Rock_Shale_Brick_Ornate"
    },
    {
      "x": -43,
      "y": 30,
      "z": 0,
      "name": "Rock_Shale_Brick_Ornate"
    },
    {
      "x": -43,
      "y": 31,
      "z": 0,
      "name": "Rock_Shale_Brick_Ornate"
    },
    {
      "x": -43,
      "y": 0,
      "z": 1,
      "name": "Rock_Shale_Brick_Ornate"
    },
    {
      "x": -43,
      "y": 1,
      "z": 1,
      "name": "Rock_Shale_Brick_Ornate"
    },
    {
      "x": -43,
      "y": 2,
      "z": 1,
      "name": "Rock_Shale_Brick_Ornate"
    },
    {
      "x": -43,
      "y": 3,
      "z": 1,
      "name": "Rock_Shale_Brick_Ornate"
    },
    {
      "x": -43,
      "y": 4,
      "z": 1,
      "name": "Rock_Shale_Brick_Ornate"
    },
    {
      "x": -43,
      "y": 27,
      "z": 1,
      "name": "Rock_Shale_Brick_Ornate"
    },
    {
      "x": -43,
      "y": 28,
      "z": 1,
      "name": "Rock_Shale_Brick_Ornate"
    },
    {
      "x": -43,
      "y": 29,
      "z": 1,
      "name": "Rock_Shale_Brick_Ornate"
    },
    {
      "x": -43,
      "y": 30,
      "z": 1,
      "name": "Rock_Shale_Brick_Ornate"
    },
    {
      "x": -43,
      "y": 31,
      "z": 1,
      "name": "Rock_Shale_Brick_Ornate"
    },
    {
      "x": -43,
      "y": 0,
      "z": 2,
      "name": "Rock_Shale_Brick_Ornate"
    },
    {
      "x": -43,
      "y": 1,
      "z": 2,
      "name": "Rock_Shale_Brick_Ornate"
    },
    {
      "x": -43,
      "y": 2,
      "z": 2,
      "name": "Rock_Shale_Brick_Ornate"
    },
    {
      "x": -43,
      "y": 3,
      "z": 2,
      "name": "Rock_Shale_Brick_Ornate"
    },
    {
      "x": -43,
      "y": 4,
      "z": 2,
      "name": "Rock_Shale_Brick_Ornate"
    },
    {
      "x": -43,
      "y": 27,
      "z": 2,
      "name": "Rock_Shale_Brick_Ornate"
    },
    {
      "x": -43,
      "y": 28,
      "z": 2,
      "name": "Rock_Shale_Brick_Ornate"
    },
    {
      "x": -43,
      "y": 29,
      "z": 2,
      "name": "Rock_Shale_Brick_Ornate"
    },
    {
      "x": -43,
      "y": 30,
      "z": 2,
      "name": "Rock_Shale_Brick_Ornate"
    },
    {
      "x": -43,
      "y": 31,
      "z": 2,
      "name": "Rock_Shale_Brick_Ornate"
    },
    {
      "x": -43,
      "y": 0,
      "z": 3,
      "name": "Rock_Shale_Brick_Ornate"
    },
    {
      "x": -43,
      "y": 1,
      "z": 3,
      "name": "Rock_Shale_Brick_Ornate"
    },
    {
      "x": -43,
      "y": 2,
      "z": 3,
      "name": "Rock_Shale_Brick_Ornate"
    },
    {
      "x": -43,
      "y": 3,
      "z": 3,
      "name": "Rock_Shale_Brick_Ornate"
    },
    {
      "x": -43,
      "y": 4,
      "z": 3,
      "name": "Rock_Shale_Brick_Ornate"
    },
    {
      "x": -43,
      "y": 27,
      "z": 3,
      "name": "Rock_Shale_Brick_Ornate"
    },
    {
      "x": -43,
      "y": 28,
      "z": 3,
      "name": "Rock_Shale_Brick_Ornate"
    },
    {
      "x": -43,
      "y": 29,
      "z": 3,
      "name": "Rock_Shale_Brick_Ornate"
    },
    {
      "x": -43,
      "y": 30,
      "z": 3,
      "name": "Rock_Shale_Brick_Ornate"
    },
    {
      "x": -43,
      "y": 31,
      "z": 3,
      "name": "Rock_Shale_Brick_Ornate"
    },
    {
      "x": -43,
      "y": 0,
      "z": 4,
      "name": "Rock_Shale_Brick_Ornate"
    },
    {
      "x": -43,
      "y": 1,
      "z": 4,
      "name": "Rock_Shale_Brick_Ornate"
    },
    {
      "x": -43,
      "y": 2,
      "z": 4,
      "name": "Rock_Shale_Brick_Ornate"
    },
    {
      "x": -43,
      "y": 27,
      "z": 4,
      "name": "Rock_Shale_Brick_Ornate"
    },
    {
      "x": -43,
      "y": 28,
      "z": 4,
      "name": "Rock_Shale_Brick_Ornate"
    },
    {
      "x": -43,
      "y": 29,
      "z": 4,
      "name": "Rock_Shale_Brick_Ornate"
    },
    {
      "x": -43,
      "y": 30,
      "z": 4,
      "name": "Rock_Shale_Brick_Ornate"
    },
    {
      "x": -43,
      "y": 31,
      "z": 4,
      "name": "Rock_Shale_Brick_Ornate"
    },
    {
      "x": -43,
      "y": 0,
      "z": 5,
      "name": "Rock_Shale_Brick_Ornate"
    },
    {
      "x": -43,
      "y": 1,
      "z": 5,
      "name": "Rock_Shale_Brick_Ornate"
    },
    {
      "x": -43,
      "y": 27,
      "z": 5,
      "name": "Rock_Shale_Brick_Ornate"
    },
    {
      "x": -43,
      "y": 28,
      "z": 5,
      "name": "Rock_Shale_Brick_Ornate"
    },
    {
      "x": -43,
      "y": 29,
      "z": 5,
      "name": "Rock_Shale_Brick_Ornate"
    },
    {
      "x": -43,
      "y": 30,
      "z": 5,
      "name": "Rock_Shale_Brick_Ornate"
    },
    {
      "x": -43,
      "y": 31,
      "z": 5,
      "name": "Rock_Shale_Brick_Ornate"
    },
    {
      "x": -42,
      "y": 0,
      "z": -4,
      "name": "Rock_Shale_Brick_Ornate"
    },
    {
      "x": -42,
      "y": 1,
      "z": -4,
      "name": "Rock_Shale_Brick_Ornate"
    },
    {
      "x": -42,
      "y": 2,
      "z": -4,
      "name": "Rock_Shale_Brick_Ornate"
    },
    {
      "x": -42,
      "y": 3,
      "z": -4,
      "name": "Rock_Shale_Brick_Ornate"
    },
    {
      "x": -42,
      "y": 27,
      "z": -4,
      "name": "Rock_Shale_Brick_Ornate"
    },
    {
      "x": -42,
      "y": 28,
      "z": -4,
      "name": "Rock_Shale_Brick_Ornate"
    },
    {
      "x": -42,
      "y": 0,
      "z": -3,
      "name": "Rock_Shale_Brick_Ornate"
    },
    {
      "x": -42,
      "y": 1,
      "z": -3,
      "name": "Rock_Shale_Brick_Ornate"
    },
    {
      "x": -42,
      "y": 2,
      "z": -3,
      "name": "Rock_Shale_Brick_Ornate"
    },
    {
      "x": -42,
      "y": 3,
      "z": -3,
      "name": "Rock_Shale_Brick_Ornate"
    },
    {
      "x": -42,
      "y": 4,
      "z": -3,
      "name": "Rock_Shale_Brick_Ornate"
    },
    {
      "x": -42,
      "y": 5,
      "z": -3,
      "name": "Rock_Shale_Brick"
    },
    {
      "x": -42,
      "y": 6,
      "z": -3,
      "name": "Rock_Shale_Brick"
    },
    {
      "x": -42,
      "y": 7,
      "z": -3,
      "name": "Rock_Shale_Brick"
    },
    {
      "x": -42,
      "y": 8,
      "z": -3,
      "name": "Rock_Shale_Brick"
    },
    {
      "x": -42,
      "y": 9,
      "z": -3,
      "name": "Rock_Shale_Brick"
    },
    {
      "x": -42,
      "y": 10,
      "z": -3,
      "name": "Rock_Shale_Brick"
    },
    {
      "x": -42,
      "y": 11,
      "z": -3,
      "name": "Rock_Shale_Brick"
    },
    {
      "x": -42,
      "y": 12,
      "z": -3,
      "name": "Rock_Shale_Brick"
    },
    {
      "x": -42,
      "y": 13,
      "z": -3,
      "name": "Rock_Shale_Brick"
    },
    {
      "x": -42,
      "y": 14,
      "z": -3,
      "name": "Rock_Shale_Brick"
    },
    {
      "x": -42,
      "y": 15,
      "z": -3,
      "name": "Rock_Shale_Brick"
    },
    {
      "x": -42,
      "y": 16,
      "z": -3,
      "name": "Rock_Shale_Brick"
    },
    {
      "x": -42,
      "y": 17,
      "z": -3,
      "name": "Rock_Shale_Brick"
    },
    {
      "x": -42,
      "y": 18,
      "z": -3,
      "name": "Rock_Shale_Brick"
    },
    {
      "x": -42,
      "y": 19,
      "z": -3,
      "name": "Rock_Shale_Brick"
    },
    {
      "x": -42,
      "y": 20,
      "z": -3,
      "name": "Rock_Shale_Brick"
    },
    {
      "x": -42,
      "y": 21,
      "z": -3,
      "name": "Rock_Shale_Brick"
    },
    {
      "x": -42,
      "y": 22,
      "z": -3,
      "name": "Rock_Shale_Brick"
    },
    {
      "x": -42,
      "y": 23,
      "z": -3,
      "name": "Rock_Shale_Brick"
    },
    {
      "x": -42,
      "y": 24,
      "z": -3,
      "name": "Rock_Shale_Brick"
    },
    {
      "x": -42,
      "y": 25,
      "z": -3,
      "name": "Rock_Shale_Brick"
    },
    {
      "x": -42,
      "y": 26,
      "z": -3,
      "name": "Rock_Shale_Brick"
    },
    {
      "x": -42,
      "y": 27,
      "z": -3,
      "name": "Rock_Shale_Brick_Ornate"
    },
    {
      "x": -42,
      "y": 28,
      "z": -3,
      "name": "Rock_Shale_Brick_Ornate"
    },
    {
      "x": -42,
      "y": 29,
      "z": -3,
      "name": "Rock_Shale_Brick_Ornate"
    },
    {
      "x": -42,
      "y": 0,
      "z": -2,
      "name": "Rock_Shale_Brick_Ornate"
    },
    {
      "x": -42,
      "y": 1,
      "z": -2,
      "name": "Rock_Shale_Brick_Ornate"
    },
    {
      "x": -42,
      "y": 2,
      "z": -2,
      "name": "Rock_Shale_Brick_Ornate"
    },
    {
      "x": -42,
      "y": 3,
      "z": -2,
      "name": "Rock_Shale_Brick_Ornate"
    },
    {
      "x": -42,
      "y": 4,
      "z": -2,
      "name": "Rock_Shale_Brick_Ornate"
    },
    {
      "x": -42,
      "y": 5,
      "z": -2,
      "name": "Rock_Shale_Brick"
    },
    {
      "x": -42,
      "y": 6,
      "z": -2,
      "name": "Rock_Shale_Brick"
    },
    {
      "x": -42,
      "y": 7,
      "z": -2,
      "name": "Rock_Shale_Brick"
    },
    {
      "x": -42,
      "y": 8,
      "z": -2,
      "name": "Rock_Shale_Brick"
    },
    {
      "x": -42,
      "y": 9,
      "z": -2,
      "name": "Rock_Shale_Brick"
    },
    {
      "x": -42,
      "y": 10,
      "z": -2,
      "name": "Rock_Shale_Brick"
    },
    {
      "x": -42,
      "y": 11,
      "z": -2,
      "name": "Rock_Shale_Brick"
    },
    {
      "x": -42,
      "y": 12,
      "z": -2,
      "name": "Rock_Shale_Brick"
    },
    {
      "x": -42,
      "y": 13,
      "z": -2,
      "name": "Rock_Shale_Brick"
    },
    {
      "x": -42,
      "y": 14,
      "z": -2,
      "name": "Rock_Shale_Brick"
    },
    {
      "x": -42,
      "y": 15,
      "z": -2,
      "name": "Rock_Shale_Brick"
    },
    {
      "x": -42,
      "y": 16,
      "z": -2,
      "name": "Rock_Shale_Brick"
    },
    {
      "x": -42,
      "y": 17,
      "z": -2,
      "name": "Rock_Shale_Brick"
    },
    {
      "x": -42,
      "y": 18,
      "z": -2,
      "name": "Rock_Shale_Brick"
    },
    {
      "x": -42,
      "y": 19,
      "z": -2,
      "name": "Rock_Shale_Brick"
    },
    {
      "x": -42,
      "y": 20,
      "z": -2,
      "name": "Rock_Shale_Brick"
    },
    {
      "x": -42,
      "y": 21,
      "z": -2,
      "name": "Rock_Shale_Brick"
    },
    {
      "x": -42,
      "y": 22,
      "z": -2,
      "name": "Rock_Shale_Brick"
    },
    {
      "x": -42,
      "y": 23,
      "z": -2,
      "name": "Rock_Shale_Brick"
    },
    {
      "x": -42,
      "y": 24,
      "z": -2,
      "name": "Rock_Shale_Brick"
    },
    {
      "x": -42,
      "y": 25,
      "z": -2,
      "name": "Rock_Shale_Brick"
    },
    {
      "x": -42,
      "y": 26,
      "z": -2,
      "name": "Rock_Shale_Brick"
    },
    {
      "x": -42,
      "y": 27,
      "z": -2,
      "name": "Rock_Shale_Brick_Ornate"
    },
    {
      "x": -42,
      "y": 28,
      "z": -2,
      "name": "Rock_Shale_Brick_Ornate"
    },
    {
      "x": -42,
      "y": 29,
      "z": -2,
      "name": "Rock_Shale_Brick_Ornate"
    },
    {
      "x": -42,
      "y": 30,
      "z": -2,
      "name": "Rock_Shale_Brick_Ornate"
    },
    {
      "x": -42,
      "y": 0,
      "z": -1,
      "name": "Rock_Shale_Brick_Ornate"
    },
    {
      "x": -42,
      "y": 1,
      "z": -1,
      "name": "Rock_Shale_Brick_Ornate"
    },
    {
      "x": -42,
      "y": 2,
      "z": -1,
      "name": "Rock_Shale_Brick_Ornate"
    },
    {
      "x": -42,
      "y": 3,
      "z": -1,
      "name": "Rock_Shale_Brick_Ornate"
    },
    {
      "x": -42,
      "y": 4,
      "z": -1,
      "name": "Rock_Shale_Brick_Ornate"
    },
    {
      "x": -42,
      "y": 5,
      "z": -1,
      "name": "Rock_Shale_Brick"
    },
    {
      "x": -42,
      "y": 6,
      "z": -1,
      "name": "Rock_Shale_Brick"
    },
    {
      "x": -42,
      "y": 7,
      "z": -1,
      "name": "Rock_Shale_Brick"
    },
    {
      "x": -42,
      "y": 8,
      "z": -1,
      "name": "Rock_Shale_Brick"
    },
    {
      "x": -42,
      "y": 9,
      "z": -1,
      "name": "Rock_Shale_Brick"
    },
    {
      "x": -42,
      "y": 10,
      "z": -1,
      "name": "Rock_Shale_Brick"
    },
    {
      "x": -42,
      "y": 11,
      "z": -1,
      "name": "Rock_Shale_Brick"
    },
    {
      "x": -42,
      "y": 12,
      "z": -1,
      "name": "Rock_Shale_Brick"
    },
    {
      "x": -42,
      "y": 13,
      "z": -1,
      "name": "Rock_Shale_Brick"
    },
    {
      "x": -42,
      "y": 14,
      "z": -1,
      "name": "Rock_Shale_Brick"
    },
    {
      "x": -42,
      "y": 15,
      "z": -1,
      "name": "Rock_Shale_Brick"
    },
    {
      "x": -42,
      "y": 16,
      "z": -1,
      "name": "Rock_Shale_Brick"
    },
    {
      "x": -42,
      "y": 17,
      "z": -1,
      "name": "Rock_Shale_Brick"
    },
    {
      "x": -42,
      "y": 18,
      "z": -1,
      "name": "Rock_Shale_Brick"
    },
    {
      "x": -42,
      "y": 19,
      "z": -1,
      "name": "Rock_Shale_Brick"
    },
    {
      "x": -42,
      "y": 20,
      "z": -1,
      "name": "Rock_Shale_Brick"
    },
    {
      "x": -42,
      "y": 21,
      "z": -1,
      "name": "Rock_Shale_Brick"
    },
    {
      "x": -42,
      "y": 22,
      "z": -1,
      "name": "Rock_Shale_Brick"
    },
    {
      "x": -42,
      "y": 23,
      "z": -1,
      "name": "Rock_Shale_Brick"
    },
    {
      "x": -42,
      "y": 24,
      "z": -1,
      "name": "Rock_Shale_Brick"
    },
    {
      "x": -42,
      "y": 25,
      "z": -1,
      "name": "Rock_Shale_Brick"
    },
    {
      "x": -42,
      "y": 26,
      "z": -1,
      "name": "Rock_Shale_Brick"
    },
    {
      "x": -42,
      "y": 27,
      "z": -1,
      "name": "Rock_Shale_Brick_Ornate"
    },
    {
      "x": -42,
      "y": 28,
      "z": -1,
      "name": "Rock_Shale_Brick_Ornate"
    },
    {
      "x": -42,
      "y": 29,
      "z": -1,
      "name": "Rock_Shale_Brick_Ornate"
    },
    {
      "x": -42,
      "y": 30,
      "z": -1,
      "name": "Rock_Shale_Brick_Ornate"
    },
    {
      "x": -42,
      "y": 31,
      "z": -1,
      "name": "Rock_Shale_Brick_Ornate"
    },
    {
      "x": -42,
      "y": 0,
      "z": 0,
      "name": "Rock_Shale_Brick_Ornate"
    },
    {
      "x": -42,
      "y": 1,
      "z": 0,
      "name": "Rock_Shale_Brick_Ornate"
    },
    {
      "x": -42,
      "y": 2,
      "z": 0,
      "name": "Rock_Shale_Brick_Ornate"
    },
    {
      "x": -42,
      "y": 3,
      "z": 0,
      "name": "Rock_Shale_Brick_Ornate"
    },
    {
      "x": -42,
      "y": 4,
      "z": 0,
      "name": "Rock_Shale_Brick_Ornate"
    },
    {
      "x": -42,
      "y": 5,
      "z": 0,
      "name": "Rock_Shale_Brick"
    },
    {
      "x": -42,
      "y": 6,
      "z": 0,
      "name": "Rock_Shale_Brick"
    },
    {
      "x": -42,
      "y": 7,
      "z": 0,
      "name": "Rock_Shale_Brick"
    },
    {
      "x": -42,
      "y": 8,
      "z": 0,
      "name": "Rock_Shale_Brick"
    },
    {
      "x": -42,
      "y": 9,
      "z": 0,
      "name": "Rock_Shale_Brick"
    },
    {
      "x": -42,
      "y": 10,
      "z": 0,
      "name": "Rock_Shale_Brick"
    },
    {
      "x": -42,
      "y": 11,
      "z": 0,
      "name": "Rock_Shale_Brick"
    },
    {
      "x": -42,
      "y": 12,
      "z": 0,
      "name": "Rock_Shale_Brick"
    },
    {
      "x": -42,
      "y": 13,
      "z": 0,
      "name": "Rock_Shale_Brick"
    },
    {
      "x": -42,
      "y": 14,
      "z": 0,
      "name": "Rock_Shale_Brick"
    },
    {
      "x": -42,
      "y": 15,
      "z": 0,
      "name": "Rock_Shale_Brick"
    },
    {
      "x": -42,
      "y": 16,
      "z": 0,
      "name": "Rock_Shale_Brick"
    },
    {
      "x": -42,
      "y": 17,
      "z": 0,
      "name": "Rock_Shale_Brick"
    },
    {
      "x": -42,
      "y": 18,
      "z": 0,
      "name": "Rock_Shale_Brick"
    },
    {
      "x": -42,
      "y": 19,
      "z": 0,
      "name": "Rock_Shale_Brick"
    },
    {
      "x": -42,
      "y": 20,
      "z": 0,
      "name": "Rock_Shale_Brick"
    },
    {
      "x": -42,
      "y": 21,
      "z": 0,
      "name": "Rock_Shale_Brick"
    },
    {
      "x": -42,
      "y": 22,
      "z": 0,
      "name": "Rock_Shale_Brick"
    },
    {
      "x": -42,
      "y": 23,
      "z": 0,
      "name": "Rock_Shale_Brick"
    },
    {
      "x": -42,
      "y": 24,
      "z": 0,
      "name": "Rock_Shale_Brick"
    },
    {
      "x": -42,
      "y": 25,
      "z": 0,
      "name": "Rock_Shale_Brick"
    },
    {
      "x": -42,
      "y": 26,
      "z": 0,
      "name": "Rock_Shale_Brick"
    },
    {
      "x": -42,
      "y": 27,
      "z": 0,
      "name": "Rock_Shale_Brick_Ornate"
    },
    {
      "x": -42,
      "y": 28,
      "z": 0,
      "name": "Rock_Shale_Brick_Ornate"
    },
    {
      "x": -42,
      "y": 29,
      "z": 0,
      "name": "Rock_Shale_Brick_Ornate"
    },
    {
      "x": -42,
      "y": 30,
      "z": 0,
      "name": "Rock_Shale_Brick_Ornate"
    },
    {
      "x": -42,
      "y": 31,
      "z": 0,
      "name": "Rock_Shale_Brick_Ornate"
    },
    {
      "x": -42,
      "y": 0,
      "z": 1,
      "name": "Rock_Shale_Brick_Ornate"
    },
    {
      "x": -42,
      "y": 1,
      "z": 1,
      "name": "Rock_Shale_Brick_Ornate"
    },
    {
      "x": -42,
      "y": 2,
      "z": 1,
      "name": "Rock_Shale_Brick_Ornate"
    },
    {
      "x": -42,
      "y": 3,
      "z": 1,
      "name": "Rock_Shale_Brick_Ornate"
    },
    {
      "x": -42,
      "y": 4,
      "z": 1,
      "name": "Rock_Shale_Brick_Ornate"
    },
    {
      "x": -42,
      "y": 5,
      "z": 1,
      "name": "Rock_Shale_Brick"
    },
    {
      "x": -42,
      "y": 6,
      "z": 1,
      "name": "Rock_Shale_Brick"
    },
    {
      "x": -42,
      "y": 7,
      "z": 1,
      "name": "Rock_Shale_Brick"
    },
    {
      "x": -42,
      "y": 8,
      "z": 1,
      "name": "Rock_Shale_Brick"
    },
    {
      "x": -42,
      "y": 9,
      "z": 1,
      "name": "Rock_Shale_Brick"
    },
    {
      "x": -42,
      "y": 10,
      "z": 1,
      "name": "Rock_Shale_Brick"
    },
    {
      "x": -42,
      "y": 11,
      "z": 1,
      "name": "Rock_Shale_Brick"
    },
    {
      "x": -42,
      "y": 12,
      "z": 1,
      "name": "Rock_Shale_Brick"
    },
    {
      "x": -42,
      "y": 13,
      "z": 1,
      "name": "Rock_Shale_Brick"
    },
    {
      "x": -42,
      "y": 14,
      "z": 1,
      "name": "Rock_Shale_Brick"
    },
    {
      "x": -42,
      "y": 15,
      "z": 1,
      "name": "Rock_Shale_Brick"
    },
    {
      "x": -42,
      "y": 16,
      "z": 1,
      "name": "Rock_Shale_Brick"
    },
    {
      "x": -42,
      "y": 17,
      "z": 1,
      "name": "Rock_Shale_Brick"
    },
    {
      "x": -42,
      "y": 18,
      "z": 1,
      "name": "Rock_Shale_Brick"
    },
    {
      "x": -42,
      "y": 19,
      "z": 1,
      "name": "Rock_Shale_Brick"
    },
    {
      "x": -42,
      "y": 20,
      "z": 1,
      "name": "Rock_Shale_Brick"
    },
    {
      "x": -42,
      "y": 21,
      "z": 1,
      "name": "Rock_Shale_Brick"
    },
    {
      "x": -42,
      "y": 22,
      "z": 1,
      "name": "Rock_Shale_Brick"
    },
    {
      "x": -42,
      "y": 23,
      "z": 1,
      "name": "Rock_Shale_Brick"
    },
    {
      "x": -42,
      "y": 24,
      "z": 1,
      "name": "Rock_Shale_Brick"
    },
    {
      "x": -42,
      "y": 25,
      "z": 1,
      "name": "Rock_Shale_Brick"
    },
    {
      "x": -42,
      "y": 26,
      "z": 1,
      "name": "Rock_Shale_Brick"
    },
    {
      "x": -42,
      "y": 27,
      "z": 1,
      "name": "Rock_Shale_Brick_Ornate"
    },
    {
      "x": -42,
      "y": 28,
      "z": 1,
      "name": "Rock_Shale_Brick_Ornate"
    },
    {
      "x": -42,
      "y": 29,
      "z": 1,
      "name": "Rock_Shale_Brick_Ornate"
    },
    {
      "x": -42,
      "y": 30,
      "z": 1,
      "name": "Rock_Shale_Brick_Ornate"
    },
    {
      "x": -42,
      "y": 31,
      "z": 1,
      "name": "Rock_Shale_Brick_Ornate"
    },
    {
      "x": -42,
      "y": 0,
      "z": 2,
      "name": "Rock_Shale_Brick_Ornate"
    },
    {
      "x": -42,
      "y": 1,
      "z": 2,
      "name": "Rock_Shale_Brick_Ornate"
    },
    {
      "x": -42,
      "y": 2,
      "z": 2,
      "name": "Rock_Shale_Brick_Ornate"
    },
    {
      "x": -42,
      "y": 3,
      "z": 2,
      "name": "Rock_Shale_Brick_Ornate"
    },
    {
      "x": -42,
      "y": 4,
      "z": 2,
      "name": "Rock_Shale_Brick_Ornate"
    },
    {
      "x": -42,
      "y": 5,
      "z": 2,
      "name": "Rock_Shale_Brick"
    },
    {
      "x": -42,
      "y": 6,
      "z": 2,
      "name": "Rock_Shale_Brick"
    },
    {
      "x": -42,
      "y": 7,
      "z": 2,
      "name": "Rock_Shale_Brick"
    },
    {
      "x": -42,
      "y": 8,
      "z": 2,
      "name": "Rock_Shale_Brick"
    },
    {
      "x": -42,
      "y": 9,
      "z": 2,
      "name": "Rock_Shale_Brick"
    },
    {
      "x": -42,
      "y": 10,
      "z": 2,
      "name": "Rock_Shale_Brick"
    },
    {
      "x": -42,
      "y": 11,
      "z": 2,
      "name": "Rock_Shale_Brick"
    },
    {
      "x": -42,
      "y": 12,
      "z": 2,
      "name": "Rock_Shale_Brick"
    },
    {
      "x": -42,
      "y": 13,
      "z": 2,
      "name": "Rock_Shale_Brick"
    },
    {
      "x": -42,
      "y": 14,
      "z": 2,
      "name": "Rock_Shale_Brick"
    },
    {
      "x": -42,
      "y": 15,
      "z": 2,
      "name": "Rock_Shale_Brick"
    },
    {
      "x": -42,
      "y": 16,
      "z": 2,
      "name": "Rock_Shale_Brick"
    },
    {
      "x": -42,
      "y": 17,
      "z": 2,
      "name": "Rock_Shale_Brick"
    },
    {
      "x": -42,
      "y": 18,
      "z": 2,
      "name": "Rock_Shale_Brick"
    },
    {
      "x": -42,
      "y": 20,
      "z": 2,
      "name": "Rock_Shale_Brick"
    },
    {
      "x": -42,
      "y": 21,
      "z": 2,
      "name": "Rock_Shale_Brick"
    },
    {
      "x": -42,
      "y": 22,
      "z": 2,
      "name": "Rock_Shale_Brick"
    },
    {
      "x": -42,
      "y": 23,
      "z": 2,
      "name": "Rock_Shale_Brick"
    },
    {
      "x": -42,
      "y": 24,
      "z": 2,
      "name": "Rock_Shale_Brick"
    },
    {
      "x": -42,
      "y": 25,
      "z": 2,
      "name": "Rock_Shale_Brick"
    },
    {
      "x": -42,
      "y": 26,
      "z": 2,
      "name": "Rock_Shale_Brick"
    },
    {
      "x": -42,
      "y": 27,
      "z": 2,
      "name": "Rock_Shale_Brick_Ornate"
    },
    {
      "x": -42,
      "y": 28,
      "z": 2,
      "name": "Rock_Shale_Brick_Ornate"
    },
    {
      "x": -42,
      "y": 29,
      "z": 2,
      "name": "Rock_Shale_Brick_Ornate"
    },
    {
      "x": -42,
      "y": 30,
      "z": 2,
      "name": "Rock_Shale_Brick_Ornate"
    },
    {
      "x": -42,
      "y": 31,
      "z": 2,
      "name": "Rock_Shale_Brick_Ornate"
    },
    {
      "x": -42,
      "y": 0,
      "z": 3,
      "name": "Rock_Shale_Brick_Ornate"
    },
    {
      "x": -42,
      "y": 1,
      "z": 3,
      "name": "Rock_Shale_Brick_Ornate"
    },
    {
      "x": -42,
      "y": 2,
      "z": 3,
      "name": "Rock_Shale_Brick_Ornate"
    },
    {
      "x": -42,
      "y": 3,
      "z": 3,
      "name": "Rock_Shale_Brick"
    },
    {
      "x": -42,
      "y": 4,
      "z": 3,
      "name": "Rock_Shale_Brick"
    },
    {
      "x": -42,
      "y": 5,
      "z": 3,
      "name": "Rock_Shale_Brick"
    },
    {
      "x": -42,
      "y": 6,
      "z": 3,
      "name": "Rock_Shale_Brick"
    },
    {
      "x": -42,
      "y": 7,
      "z": 3,
      "name": "Rock_Shale_Brick"
    },
    {
      "x": -42,
      "y": 8,
      "z": 3,
      "name": "Rock_Shale_Brick"
    },
    {
      "x": -42,
      "y": 9,
      "z": 3,
      "name": "Rock_Shale_Brick"
    },
    {
      "x": -42,
      "y": 10,
      "z": 3,
      "name": "Rock_Shale_Brick"
    },
    {
      "x": -42,
      "y": 11,
      "z": 3,
      "name": "Rock_Shale_Brick"
    },
    {
      "x": -42,
      "y": 12,
      "z": 3,
      "name": "Rock_Shale_Brick"
    },
    {
      "x": -42,
      "y": 13,
      "z": 3,
      "name": "Rock_Shale_Brick"
    },
    {
      "x": -42,
      "y": 20,
      "z": 3,
      "name": "Rock_Shale_Brick"
    },
    {
      "x": -42,
      "y": 21,
      "z": 3,
      "name": "Rock_Shale_Brick"
    },
    {
      "x": -42,
      "y": 22,
      "z": 3,
      "name": "Rock_Shale_Brick"
    },
    {
      "x": -42,
      "y": 23,
      "z": 3,
      "name": "Rock_Shale_Brick"
    },
    {
      "x": -42,
      "y": 24,
      "z": 3,
      "name": "Rock_Shale_Brick"
    },
    {
      "x": -42,
      "y": 25,
      "z": 3,
      "name": "Rock_Shale_Brick"
    },
    {
      "x": -42,
      "y": 26,
      "z": 3,
      "name": "Rock_Shale_Brick"
    },
    {
      "x": -42,
      "y": 27,
      "z": 3,
      "name": "Rock_Shale_Brick_Ornate"
    },
    {
      "x": -42,
      "y": 28,
      "z": 3,
      "name": "Rock_Shale_Brick_Ornate"
    },
    {
      "x": -42,
      "y": 29,
      "z": 3,
      "name": "Rock_Shale_Brick_Ornate"
    },
    {
      "x": -42,
      "y": 30,
      "z": 3,
      "name": "Rock_Shale_Brick_Ornate"
    },
    {
      "x": -42,
      "y": 31,
      "z": 3,
      "name": "Rock_Shale_Brick_Ornate"
    },
    {
      "x": -42,
      "y": 0,
      "z": 4,
      "name": "Rock_Shale_Brick_Ornate"
    },
    {
      "x": -42,
      "y": 1,
      "z": 4,
      "name": "Rock_Shale_Brick_Ornate"
    },
    {
      "x": -42,
      "y": 2,
      "z": 4,
      "name": "Rock_Shale_Brick"
    },
    {
      "x": -42,
      "y": 3,
      "z": 4,
      "name": "Rock_Shale_Brick"
    },
    {
      "x": -42,
      "y": 4,
      "z": 4,
      "name": "Rock_Shale_Brick"
    },
    {
      "x": -42,
      "y": 5,
      "z": 4,
      "name": "Rock_Shale_Brick"
    },
    {
      "x": -42,
      "y": 6,
      "z": 4,
      "name": "Rock_Shale_Brick"
    },
    {
      "x": -42,
      "y": 7,
      "z": 4,
      "name": "Rock_Shale_Brick"
    },
    {
      "x": -42,
      "y": 8,
      "z": 4,
      "name": "Rock_Shale_Brick"
    },
    {
      "x": -42,
      "y": 9,
      "z": 4,
      "name": "Rock_Shale_Brick"
    },
    {
      "x": -42,
      "y": 10,
      "z": 4,
      "name": "Rock_Shale_Brick"
    },
    {
      "x": -42,
      "y": 22,
      "z": 4,
      "name": "Rock_Shale_Brick"
    },
    {
      "x": -42,
      "y": 23,
      "z": 4,
      "name": "Rock_Shale_Brick"
    },
    {
      "x": -42,
      "y": 24,
      "z": 4,
      "name": "Rock_Shale_Brick"
    },
    {
      "x": -42,
      "y": 25,
      "z": 4,
      "name": "Rock_Shale_Brick"
    },
    {
      "x": -42,
      "y": 26,
      "z": 4,
      "name": "Rock_Shale_Brick"
    },
    {
      "x": -42,
      "y": 27,
      "z": 4,
      "name": "Rock_Shale_Brick_Ornate"
    },
    {
      "x": -42,
      "y": 28,
      "z": 4,
      "name": "Rock_Shale_Brick_Ornate"
    },
    {
      "x": -42,
      "y": 29,
      "z": 4,
      "name": "Rock_Shale_Brick_Ornate"
    },
    {
      "x": -42,
      "y": 30,
      "z": 4,
      "name": "Rock_Shale_Brick_Ornate"
    },
    {
      "x": -42,
      "y": 31,
      "z": 4,
      "name": "Rock_Shale_Brick_Ornate"
    },
    {
      "x": -42,
      "y": 0,
      "z": 5,
      "name": "Rock_Shale_Brick_Ornate"
    },
    {
      "x": -42,
      "y": 1,
      "z": 5,
      "name": "Rock_Shale_Brick_Ornate"
    },
    {
      "x": -42,
      "y": 2,
      "z": 5,
      "name": "Rock_Shale_Brick_Ornate"
    },
    {
      "x": -42,
      "y": 3,
      "z": 5,
      "name": "Rock_Shale_Brick_Ornate"
    },
    {
      "x": -42,
      "y": 27,
      "z": 5,
      "name": "Rock_Shale_Brick_Ornate"
    },
    {
      "x": -42,
      "y": 28,
      "z": 5,
      "name": "Rock_Shale_Brick_Ornate"
    },
    {
      "x": -42,
      "y": 29,
      "z": 5,
      "name": "Rock_Shale_Brick_Ornate"
    },
    {
      "x": -42,
      "y": 30,
      "z": 5,
      "name": "Rock_Shale_Brick_Ornate"
    },
    {
      "x": -42,
      "y": 31,
      "z": 5,
      "name": "Rock_Shale_Brick_Ornate"
    },
    {
      "x": -41,
      "y": 0,
      "z": -4,
      "name": "Rock_Shale_Brick_Ornate"
    },
    {
      "x": -41,
      "y": 1,
      "z": -4,
      "name": "Rock_Shale_Brick_Ornate"
    },
    {
      "x": -41,
      "y": 2,
      "z": -4,
      "name": "Rock_Shale_Brick_Ornate"
    },
    {
      "x": -41,
      "y": 3,
      "z": -4,
      "name": "Rock_Shale_Brick_Ornate"
    },
    {
      "x": -41,
      "y": 4,
      "z": -4,
      "name": "Rock_Shale_Brick_Ornate"
    },
    {
      "x": -41,
      "y": 27,
      "z": -4,
      "name": "Rock_Shale_Brick_Ornate"
    },
    {
      "x": -41,
      "y": 28,
      "z": -4,
      "name": "Rock_Shale_Brick_Ornate"
    },
    {
      "x": -41,
      "y": 29,
      "z": -4,
      "name": "Rock_Shale_Brick_Ornate"
    },
    {
      "x": -41,
      "y": 30,
      "z": -4,
      "name": "Rock_Shale_Brick_Ornate"
    },
    {
      "x": -41,
      "y": 0,
      "z": -3,
      "name": "Rock_Shale_Brick_Ornate"
    },
    {
      "x": -41,
      "y": 1,
      "z": -3,
      "name": "Rock_Shale_Brick_Ornate"
    },
    {
      "x": -41,
      "y": 2,
      "z": -3,
      "name": "Rock_Shale_Brick_Ornate"
    },
    {
      "x": -41,
      "y": 3,
      "z": -3,
      "name": "Rock_Shale_Brick_Ornate"
    },
    {
      "x": -41,
      "y": 4,
      "z": -3,
      "name": "Rock_Shale_Brick_Ornate"
    },
    {
      "x": -41,
      "y": 5,
      "z": -3,
      "name": "Rock_Shale_Brick"
    },
    {
      "x": -41,
      "y": 6,
      "z": -3,
      "name": "Rock_Shale_Brick"
    },
    {
      "x": -41,
      "y": 7,
      "z": -3,
      "name": "Rock_Shale_Brick"
    },
    {
      "x": -41,
      "y": 8,
      "z": -3,
      "name": "Rock_Shale_Brick"
    },
    {
      "x": -41,
      "y": 9,
      "z": -3,
      "name": "Rock_Shale_Brick"
    },
    {
      "x": -41,
      "y": 10,
      "z": -3,
      "name": "Rock_Shale_Brick"
    },
    {
      "x": -41,
      "y": 11,
      "z": -3,
      "name": "Rock_Shale_Brick"
    },
    {
      "x": -41,
      "y": 12,
      "z": -3,
      "name": "Rock_Shale_Brick"
    },
    {
      "x": -41,
      "y": 13,
      "z": -3,
      "name": "Rock_Shale_Brick"
    },
    {
      "x": -41,
      "y": 14,
      "z": -3,
      "name": "Rock_Shale_Brick"
    },
    {
      "x": -41,
      "y": 15,
      "z": -3,
      "name": "Rock_Shale_Brick"
    },
    {
      "x": -41,
      "y": 16,
      "z": -3,
      "name": "Rock_Shale_Brick"
    },
    {
      "x": -41,
      "y": 17,
      "z": -3,
      "name": "Rock_Shale_Brick"
    },
    {
      "x": -41,
      "y": 18,
      "z": -3,
      "name": "Rock_Shale_Brick"
    },
    {
      "x": -41,
      "y": 19,
      "z": -3,
      "name": "Rock_Shale_Brick"
    },
    {
      "x": -41,
      "y": 20,
      "z": -3,
      "name": "Rock_Shale_Brick"
    },
    {
      "x": -41,
      "y": 21,
      "z": -3,
      "name": "Rock_Shale_Brick"
    },
    {
      "x": -41,
      "y": 22,
      "z": -3,
      "name": "Rock_Shale_Brick"
    },
    {
      "x": -41,
      "y": 23,
      "z": -3,
      "name": "Rock_Shale_Brick"
    },
    {
      "x": -41,
      "y": 24,
      "z": -3,
      "name": "Rock_Shale_Brick"
    },
    {
      "x": -41,
      "y": 25,
      "z": -3,
      "name": "Rock_Shale_Brick"
    },
    {
      "x": -41,
      "y": 26,
      "z": -3,
      "name": "Rock_Shale_Brick"
    },
    {
      "x": -41,
      "y": 27,
      "z": -3,
      "name": "Rock_Shale_Brick_Ornate"
    },
    {
      "x": -41,
      "y": 28,
      "z": -3,
      "name": "Rock_Shale_Brick_Ornate"
    },
    {
      "x": -41,
      "y": 29,
      "z": -3,
      "name": "Rock_Shale_Brick_Ornate"
    },
    {
      "x": -41,
      "y": 30,
      "z": -3,
      "name": "Rock_Shale_Brick_Ornate"
    },
    {
      "x": -41,
      "y": 31,
      "z": -3,
      "name": "Rock_Shale_Brick_Ornate"
    },
    {
      "x": -41,
      "y": 0,
      "z": -2,
      "name": "Rock_Shale_Brick_Ornate"
    },
    {
      "x": -41,
      "y": 1,
      "z": -2,
      "name": "Rock_Shale_Brick_Ornate"
    },
    {
      "x": -41,
      "y": 2,
      "z": -2,
      "name": "Rock_Shale_Brick_Ornate"
    },
    {
      "x": -41,
      "y": 3,
      "z": -2,
      "name": "Rock_Shale_Brick_Ornate"
    },
    {
      "x": -41,
      "y": 4,
      "z": -2,
      "name": "Rock_Shale_Brick_Ornate"
    },
    {
      "x": -41,
      "y": 5,
      "z": -2,
      "name": "Rock_Shale_Brick"
    },
    {
      "x": -41,
      "y": 6,
      "z": -2,
      "name": "Rock_Shale_Brick"
    },
    {
      "x": -41,
      "y": 7,
      "z": -2,
      "name": "Rock_Shale_Brick"
    },
    {
      "x": -41,
      "y": 8,
      "z": -2,
      "name": "Rock_Shale_Brick"
    },
    {
      "x": -41,
      "y": 9,
      "z": -2,
      "name": "Rock_Shale_Brick"
    },
    {
      "x": -41,
      "y": 10,
      "z": -2,
      "name": "Rock_Shale_Brick"
    },
    {
      "x": -41,
      "y": 11,
      "z": -2,
      "name": "Rock_Shale_Brick"
    },
    {
      "x": -41,
      "y": 12,
      "z": -2,
      "name": "Rock_Shale_Brick"
    },
    {
      "x": -41,
      "y": 13,
      "z": -2,
      "name": "Rock_Shale_Brick"
    },
    {
      "x": -41,
      "y": 14,
      "z": -2,
      "name": "Rock_Shale_Brick"
    },
    {
      "x": -41,
      "y": 15,
      "z": -2,
      "name": "Rock_Shale_Brick"
    },
    {
      "x": -41,
      "y": 16,
      "z": -2,
      "name": "Rock_Shale_Brick"
    },
    {
      "x": -41,
      "y": 17,
      "z": -2,
      "name": "Rock_Shale_Brick"
    },
    {
      "x": -41,
      "y": 18,
      "z": -2,
      "name": "Rock_Shale_Brick"
    },
    {
      "x": -41,
      "y": 19,
      "z": -2,
      "name": "Rock_Shale_Brick"
    },
    {
      "x": -41,
      "y": 20,
      "z": -2,
      "name": "Rock_Shale_Brick"
    },
    {
      "x": -41,
      "y": 21,
      "z": -2,
      "name": "Rock_Shale_Brick"
    },
    {
      "x": -41,
      "y": 22,
      "z": -2,
      "name": "Rock_Shale_Brick"
    },
    {
      "x": -41,
      "y": 23,
      "z": -2,
      "name": "Rock_Shale_Brick"
    },
    {
      "x": -41,
      "y": 24,
      "z": -2,
      "name": "Rock_Shale_Brick"
    },
    {
      "x": -41,
      "y": 25,
      "z": -2,
      "name": "Rock_Shale_Brick"
    },
    {
      "x": -41,
      "y": 26,
      "z": -2,
      "name": "Rock_Shale_Brick"
    },
    {
      "x": -41,
      "y": 27,
      "z": -2,
      "name": "Rock_Shale_Brick_Ornate"
    },
    {
      "x": -41,
      "y": 28,
      "z": -2,
      "name": "Rock_Shale_Brick_Ornate"
    },
    {
      "x": -41,
      "y": 29,
      "z": -2,
      "name": "Rock_Shale_Brick_Ornate"
    },
    {
      "x": -41,
      "y": 30,
      "z": -2,
      "name": "Rock_Shale_Brick_Ornate"
    },
    {
      "x": -41,
      "y": 31,
      "z": -2,
      "name": "Rock_Shale_Brick_Ornate"
    },
    {
      "x": -41,
      "y": 0,
      "z": -1,
      "name": "Rock_Shale_Brick_Ornate"
    },
    {
      "x": -41,
      "y": 1,
      "z": -1,
      "name": "Rock_Shale_Brick_Ornate"
    },
    {
      "x": -41,
      "y": 2,
      "z": -1,
      "name": "Rock_Shale_Brick_Ornate"
    },
    {
      "x": -41,
      "y": 3,
      "z": -1,
      "name": "Rock_Shale_Brick_Ornate"
    },
    {
      "x": -41,
      "y": 4,
      "z": -1,
      "name": "Rock_Shale_Brick_Ornate"
    },
    {
      "x": -41,
      "y": 5,
      "z": -1,
      "name": "Rock_Shale_Brick"
    },
    {
      "x": -41,
      "y": 6,
      "z": -1,
      "name": "Rock_Shale_Brick"
    },
    {
      "x": -41,
      "y": 7,
      "z": -1,
      "name": "Rock_Shale_Brick"
    },
    {
      "x": -41,
      "y": 8,
      "z": -1,
      "name": "Rock_Shale_Brick"
    },
    {
      "x": -41,
      "y": 9,
      "z": -1,
      "name": "Rock_Shale_Brick"
    },
    {
      "x": -41,
      "y": 10,
      "z": -1,
      "name": "Rock_Shale_Brick"
    },
    {
      "x": -41,
      "y": 11,
      "z": -1,
      "name": "Rock_Shale_Brick"
    },
    {
      "x": -41,
      "y": 12,
      "z": -1,
      "name": "Rock_Shale_Brick"
    },
    {
      "x": -41,
      "y": 13,
      "z": -1,
      "name": "Rock_Shale_Brick"
    },
    {
      "x": -41,
      "y": 14,
      "z": -1,
      "name": "Rock_Shale_Brick"
    },
    {
      "x": -41,
      "y": 15,
      "z": -1,
      "name": "Rock_Shale_Brick"
    },
    {
      "x": -41,
      "y": 16,
      "z": -1,
      "name": "Rock_Shale_Brick"
    },
    {
      "x": -41,
      "y": 17,
      "z": -1,
      "name": "Rock_Shale_Brick"
    },
    {
      "x": -41,
      "y": 18,
      "z": -1,
      "name": "Rock_Shale_Brick"
    },
    {
      "x": -41,
      "y": 19,
      "z": -1,
      "name": "Rock_Shale_Brick"
    },
    {
      "x": -41,
      "y": 20,
      "z": -1,
      "name": "Rock_Shale_Brick"
    },
    {
      "x": -41,
      "y": 21,
      "z": -1,
      "name": "Rock_Shale_Brick"
    },
    {
      "x": -41,
      "y": 22,
      "z": -1,
      "name": "Rock_Shale_Brick"
    },
    {
      "x": -41,
      "y": 23,
      "z": -1,
      "name": "Rock_Shale_Brick"
    },
    {
      "x": -41,
      "y": 24,
      "z": -1,
      "name": "Rock_Shale_Brick"
    },
    {
      "x": -41,
      "y": 25,
      "z": -1,
      "name": "Rock_Shale_Brick"
    },
    {
      "x": -41,
      "y": 26,
      "z": -1,
      "name": "Rock_Shale_Brick"
    },
    {
      "x": -41,
      "y": 27,
      "z": -1,
      "name": "Rock_Shale_Brick_Ornate"
    },
    {
      "x": -41,
      "y": 28,
      "z": -1,
      "name": "Rock_Shale_Brick_Ornate"
    },
    {
      "x": -41,
      "y": 29,
      "z": -1,
      "name": "Rock_Shale_Brick_Ornate"
    },
    {
      "x": -41,
      "y": 30,
      "z": -1,
      "name": "Rock_Shale_Brick_Ornate"
    },
    {
      "x": -41,
      "y": 31,
      "z": -1,
      "name": "Rock_Shale_Brick_Ornate"
    },
    {
      "x": -41,
      "y": 0,
      "z": 0,
      "name": "Rock_Shale_Brick_Ornate"
    },
    {
      "x": -41,
      "y": 1,
      "z": 0,
      "name": "Rock_Shale_Brick_Ornate"
    },
    {
      "x": -41,
      "y": 2,
      "z": 0,
      "name": "Rock_Shale_Brick_Ornate"
    },
    {
      "x": -41,
      "y": 3,
      "z": 0,
      "name": "Rock_Shale_Brick_Ornate"
    },
    {
      "x": -41,
      "y": 4,
      "z": 0,
      "name": "Rock_Shale_Brick_Ornate"
    },
    {
      "x": -41,
      "y": 5,
      "z": 0,
      "name": "Rock_Shale_Brick"
    },
    {
      "x": -41,
      "y": 6,
      "z": 0,
      "name": "Rock_Shale_Brick"
    },
    {
      "x": -41,
      "y": 7,
      "z": 0,
      "name": "Rock_Shale_Brick"
    },
    {
      "x": -41,
      "y": 8,
      "z": 0,
      "name": "Rock_Shale_Brick"
    },
    {
      "x": -41,
      "y": 9,
      "z": 0,
      "name": "Rock_Shale_Brick"
    },
    {
      "x": -41,
      "y": 10,
      "z": 0,
      "name": "Rock_Shale_Brick"
    },
    {
      "x": -41,
      "y": 11,
      "z": 0,
      "name": "Rock_Shale_Brick"
    },
    {
      "x": -41,
      "y": 12,
      "z": 0,
      "name": "Rock_Shale_Brick"
    },
    {
      "x": -41,
      "y": 13,
      "z": 0,
      "name": "Rock_Shale_Brick"
    },
    {
      "x": -41,
      "y": 14,
      "z": 0,
      "name": "Rock_Shale_Brick"
    },
    {
      "x": -41,
      "y": 15,
      "z": 0,
      "name": "Rock_Shale_Brick"
    },
    {
      "x": -41,
      "y": 16,
      "z": 0,
      "name": "Rock_Shale_Brick"
    },
    {
      "x": -41,
      "y": 17,
      "z": 0,
      "name": "Rock_Shale_Brick"
    },
    {
      "x": -41,
      "y": 18,
      "z": 0,
      "name": "Rock_Shale_Brick"
    },
    {
      "x": -41,
      "y": 19,
      "z": 0,
      "name": "Rock_Shale_Brick"
    },
    {
      "x": -41,
      "y": 20,
      "z": 0,
      "name": "Rock_Shale_Brick"
    },
    {
      "x": -41,
      "y": 21,
      "z": 0,
      "name": "Rock_Shale_Brick"
    },
    {
      "x": -41,
      "y": 22,
      "z": 0,
      "name": "Rock_Shale_Brick"
    },
    {
      "x": -41,
      "y": 23,
      "z": 0,
      "name": "Rock_Shale_Brick"
    },
    {
      "x": -41,
      "y": 24,
      "z": 0,
      "name": "Rock_Shale_Brick"
    },
    {
      "x": -41,
      "y": 25,
      "z": 0,
      "name": "Rock_Shale_Brick"
    },
    {
      "x": -41,
      "y": 26,
      "z": 0,
      "name": "Rock_Shale_Brick"
    },
    {
      "x": -41,
      "y": 27,
      "z": 0,
      "name": "Rock_Shale_Brick_Ornate"
    },
    {
      "x": -41,
      "y": 28,
      "z": 0,
      "name": "Rock_Shale_Brick_Ornate"
    },
    {
      "x": -41,
      "y": 29,
      "z": 0,
      "name": "Rock_Shale_Brick_Ornate"
    },
    {
      "x": -41,
      "y": 30,
      "z": 0,
      "name": "Rock_Shale_Brick_Ornate"
    },
    {
      "x": -41,
      "y": 31,
      "z": 0,
      "name": "Rock_Shale_Brick_Ornate"
    },
    {
      "x": -41,
      "y": 0,
      "z": 1,
      "name": "Rock_Shale_Brick_Ornate"
    },
    {
      "x": -41,
      "y": 1,
      "z": 1,
      "name": "Rock_Shale_Brick_Ornate"
    },
    {
      "x": -41,
      "y": 2,
      "z": 1,
      "name": "Rock_Shale_Brick_Ornate"
    },
    {
      "x": -41,
      "y": 3,
      "z": 1,
      "name": "Rock_Shale_Brick_Ornate"
    },
    {
      "x": -41,
      "y": 4,
      "z": 1,
      "name": "Rock_Shale_Brick_Ornate"
    },
    {
      "x": -41,
      "y": 5,
      "z": 1,
      "name": "Rock_Shale_Brick"
    },
    {
      "x": -41,
      "y": 6,
      "z": 1,
      "name": "Rock_Shale_Brick"
    },
    {
      "x": -41,
      "y": 7,
      "z": 1,
      "name": "Rock_Shale_Brick"
    },
    {
      "x": -41,
      "y": 8,
      "z": 1,
      "name": "Rock_Shale_Brick"
    },
    {
      "x": -41,
      "y": 9,
      "z": 1,
      "name": "Rock_Shale_Brick"
    },
    {
      "x": -41,
      "y": 10,
      "z": 1,
      "name": "Rock_Shale_Brick"
    },
    {
      "x": -41,
      "y": 11,
      "z": 1,
      "name": "Rock_Shale_Brick"
    },
    {
      "x": -41,
      "y": 12,
      "z": 1,
      "name": "Rock_Shale_Brick"
    },
    {
      "x": -41,
      "y": 13,
      "z": 1,
      "name": "Rock_Shale_Brick"
    },
    {
      "x": -41,
      "y": 14,
      "z": 1,
      "name": "Rock_Shale_Brick"
    },
    {
      "x": -41,
      "y": 15,
      "z": 1,
      "name": "Rock_Shale_Brick"
    },
    {
      "x": -41,
      "y": 16,
      "z": 1,
      "name": "Rock_Shale_Brick"
    },
    {
      "x": -41,
      "y": 17,
      "z": 1,
      "name": "Rock_Shale_Brick"
    },
    {
      "x": -41,
      "y": 18,
      "z": 1,
      "name": "Rock_Shale_Brick"
    },
    {
      "x": -41,
      "y": 19,
      "z": 1,
      "name": "Rock_Shale_Brick"
    },
    {
      "x": -41,
      "y": 20,
      "z": 1,
      "name": "Rock_Shale_Brick"
    },
    {
      "x": -41,
      "y": 21,
      "z": 1,
      "name": "Rock_Shale_Brick"
    },
    {
      "x": -41,
      "y": 22,
      "z": 1,
      "name": "Rock_Shale_Brick"
    },
    {
      "x": -41,
      "y": 23,
      "z": 1,
      "name": "Rock_Shale_Brick"
    },
    {
      "x": -41,
      "y": 24,
      "z": 1,
      "name": "Rock_Shale_Brick"
    },
    {
      "x": -41,
      "y": 25,
      "z": 1,
      "name": "Rock_Shale_Brick"
    },
    {
      "x": -41,
      "y": 26,
      "z": 1,
      "name": "Rock_Shale_Brick"
    },
    {
      "x": -41,
      "y": 27,
      "z": 1,
      "name": "Rock_Shale_Brick_Ornate"
    },
    {
      "x": -41,
      "y": 28,
      "z": 1,
      "name": "Rock_Shale_Brick_Ornate"
    },
    {
      "x": -41,
      "y": 29,
      "z": 1,
      "name": "Rock_Shale_Brick_Ornate"
    },
    {
      "x": -41,
      "y": 30,
      "z": 1,
      "name": "Rock_Shale_Brick_Ornate"
    },
    {
      "x": -41,
      "y": 31,
      "z": 1,
      "name": "Rock_Shale_Brick_Ornate"
    },
    {
      "x": -41,
      "y": 0,
      "z": 2,
      "name": "Rock_Shale_Brick_Ornate"
    },
    {
      "x": -41,
      "y": 1,
      "z": 2,
      "name": "Rock_Shale_Brick_Ornate"
    },
    {
      "x": -41,
      "y": 2,
      "z": 2,
      "name": "Rock_Shale_Brick_Ornate"
    },
    {
      "x": -41,
      "y": 3,
      "z": 2,
      "name": "Rock_Shale_Brick_Ornate"
    },
    {
      "x": -41,
      "y": 4,
      "z": 2,
      "name": "Rock_Shale_Brick_Ornate"
    },
    {
      "x": -41,
      "y": 5,
      "z": 2,
      "name": "Rock_Shale_Brick"
    },
    {
      "x": -41,
      "y": 6,
      "z": 2,
      "name": "Rock_Shale_Brick"
    },
    {
      "x": -41,
      "y": 7,
      "z": 2,
      "name": "Rock_Shale_Brick"
    },
    {
      "x": -41,
      "y": 8,
      "z": 2,
      "name": "Rock_Shale_Brick"
    },
    {
      "x": -41,
      "y": 9,
      "z": 2,
      "name": "Rock_Shale_Brick"
    },
    {
      "x": -41,
      "y": 10,
      "z": 2,
      "name": "Rock_Shale_Brick"
    },
    {
      "x": -41,
      "y": 11,
      "z": 2,
      "name": "Rock_Shale_Brick"
    },
    {
      "x": -41,
      "y": 12,
      "z": 2,
      "name": "Rock_Shale_Brick"
    },
    {
      "x": -41,
      "y": 13,
      "z": 2,
      "name": "Rock_Shale_Brick"
    },
    {
      "x": -41,
      "y": 14,
      "z": 2,
      "name": "Rock_Shale_Brick"
    },
    {
      "x": -41,
      "y": 15,
      "z": 2,
      "name": "Rock_Shale_Brick"
    },
    {
      "x": -41,
      "y": 16,
      "z": 2,
      "name": "Rock_Shale_Brick"
    },
    {
      "x": -41,
      "y": 17,
      "z": 2,
      "name": "Rock_Shale_Brick"
    },
    {
      "x": -41,
      "y": 18,
      "z": 2,
      "name": "Rock_Shale_Brick"
    },
    {
      "x": -41,
      "y": 19,
      "z": 2,
      "name": "Rock_Shale_Brick"
    },
    {
      "x": -41,
      "y": 20,
      "z": 2,
      "name": "Rock_Shale_Brick"
    },
    {
      "x": -41,
      "y": 21,
      "z": 2,
      "name": "Rock_Shale_Brick"
    },
    {
      "x": -41,
      "y": 22,
      "z": 2,
      "name": "Rock_Shale_Brick"
    },
    {
      "x": -41,
      "y": 23,
      "z": 2,
      "name": "Rock_Shale_Brick"
    },
    {
      "x": -41,
      "y": 24,
      "z": 2,
      "name": "Rock_Shale_Brick"
    },
    {
      "x": -41,
      "y": 25,
      "z": 2,
      "name": "Rock_Shale_Brick"
    },
    {
      "x": -41,
      "y": 26,
      "z": 2,
      "name": "Rock_Shale_Brick"
    },
    {
      "x": -41,
      "y": 27,
      "z": 2,
      "name": "Rock_Shale_Brick_Ornate"
    },
    {
      "x": -41,
      "y": 28,
      "z": 2,
      "name": "Rock_Shale_Brick_Ornate"
    },
    {
      "x": -41,
      "y": 29,
      "z": 2,
      "name": "Rock_Shale_Brick_Ornate"
    },
    {
      "x": -41,
      "y": 30,
      "z": 2,
      "name": "Rock_Shale_Brick_Ornate"
    },
    {
      "x": -41,
      "y": 31,
      "z": 2,
      "name": "Rock_Shale_Brick_Ornate"
    },
    {
      "x": -41,
      "y": 0,
      "z": 3,
      "name": "Rock_Shale_Brick_Ornate"
    },
    {
      "x": -41,
      "y": 1,
      "z": 3,
      "name": "Rock_Shale_Brick_Ornate"
    },
    {
      "x": -41,
      "y": 2,
      "z": 3,
      "name": "Rock_Shale_Brick_Ornate"
    },
    {
      "x": -41,
      "y": 3,
      "z": 3,
      "name": "Rock_Shale_Brick_Ornate"
    },
    {
      "x": -41,
      "y": 4,
      "z": 3,
      "name": "Rock_Shale_Brick_Ornate"
    },
    {
      "x": -41,
      "y": 5,
      "z": 3,
      "name": "Rock_Shale_Brick"
    },
    {
      "x": -41,
      "y": 6,
      "z": 3,
      "name": "Rock_Shale_Brick"
    },
    {
      "x": -41,
      "y": 7,
      "z": 3,
      "name": "Rock_Shale_Brick"
    },
    {
      "x": -41,
      "y": 8,
      "z": 3,
      "name": "Rock_Shale_Brick"
    },
    {
      "x": -41,
      "y": 9,
      "z": 3,
      "name": "Rock_Shale_Brick"
    },
    {
      "x": -41,
      "y": 10,
      "z": 3,
      "name": "Rock_Shale_Brick"
    },
    {
      "x": -41,
      "y": 11,
      "z": 3,
      "name": "Rock_Shale_Brick"
    },
    {
      "x": -41,
      "y": 12,
      "z": 3,
      "name": "Rock_Shale_Brick"
    },
    {
      "x": -41,
      "y": 13,
      "z": 3,
      "name": "Rock_Shale_Brick"
    },
    {
      "x": -41,
      "y": 14,
      "z": 3,
      "name": "Rock_Shale_Brick"
    },
    {
      "x": -41,
      "y": 15,
      "z": 3,
      "name": "Rock_Shale_Brick"
    },
    {
      "x": -41,
      "y": 16,
      "z": 3,
      "name": "Rock_Shale_Brick"
    },
    {
      "x": -41,
      "y": 17,
      "z": 3,
      "name": "Rock_Shale_Brick"
    },
    {
      "x": -41,
      "y": 18,
      "z": 3,
      "name": "Rock_Shale_Brick"
    },
    {
      "x": -41,
      "y": 19,
      "z": 3,
      "name": "Rock_Shale_Brick"
    },
    {
      "x": -41,
      "y": 20,
      "z": 3,
      "name": "Rock_Shale_Brick"
    },
    {
      "x": -41,
      "y": 21,
      "z": 3,
      "name": "Rock_Shale_Brick"
    },
    {
      "x": -41,
      "y": 22,
      "z": 3,
      "name": "Rock_Shale_Brick"
    },
    {
      "x": -41,
      "y": 23,
      "z": 3,
      "name": "Rock_Shale_Brick"
    },
    {
      "x": -41,
      "y": 24,
      "z": 3,
      "name": "Rock_Shale_Brick"
    },
    {
      "x": -41,
      "y": 25,
      "z": 3,
      "name": "Rock_Shale_Brick"
    },
    {
      "x": -41,
      "y": 26,
      "z": 3,
      "name": "Rock_Shale_Brick"
    },
    {
      "x": -41,
      "y": 27,
      "z": 3,
      "name": "Rock_Shale_Brick_Ornate"
    },
    {
      "x": -41,
      "y": 28,
      "z": 3,
      "name": "Rock_Shale_Brick_Ornate"
    },
    {
      "x": -41,
      "y": 29,
      "z": 3,
      "name": "Rock_Shale_Brick_Ornate"
    },
    {
      "x": -41,
      "y": 30,
      "z": 3,
      "name": "Rock_Shale_Brick_Ornate"
    },
    {
      "x": -41,
      "y": 31,
      "z": 3,
      "name": "Rock_Shale_Brick_Ornate"
    },
    {
      "x": -41,
      "y": 0,
      "z": 4,
      "name": "Rock_Shale_Brick_Ornate"
    },
    {
      "x": -41,
      "y": 1,
      "z": 4,
      "name": "Rock_Shale_Brick_Ornate"
    },
    {
      "x": -41,
      "y": 2,
      "z": 4,
      "name": "Rock_Shale_Brick_Ornate"
    },
    {
      "x": -41,
      "y": 3,
      "z": 4,
      "name": "Rock_Shale_Brick_Ornate"
    },
    {
      "x": -41,
      "y": 4,
      "z": 4,
      "name": "Rock_Shale_Brick"
    },
    {
      "x": -41,
      "y": 5,
      "z": 4,
      "name": "Rock_Shale_Brick"
    },
    {
      "x": -41,
      "y": 6,
      "z": 4,
      "name": "Rock_Shale_Brick"
    },
    {
      "x": -41,
      "y": 7,
      "z": 4,
      "name": "Rock_Shale_Brick"
    },
    {
      "x": -41,
      "y": 8,
      "z": 4,
      "name": "Rock_Shale_Brick"
    },
    {
      "x": -41,
      "y": 9,
      "z": 4,
      "name": "Rock_Shale_Brick"
    },
    {
      "x": -41,
      "y": 10,
      "z": 4,
      "name": "Rock_Shale_Brick"
    },
    {
      "x": -41,
      "y": 11,
      "z": 4,
      "name": "Rock_Shale_Brick"
    },
    {
      "x": -41,
      "y": 12,
      "z": 4,
      "name": "Rock_Shale_Brick"
    },
    {
      "x": -41,
      "y": 13,
      "z": 4,
      "name": "Rock_Shale_Brick"
    },
    {
      "x": -41,
      "y": 14,
      "z": 4,
      "name": "Rock_Shale_Brick"
    },
    {
      "x": -41,
      "y": 15,
      "z": 4,
      "name": "Rock_Shale_Brick"
    },
    {
      "x": -41,
      "y": 16,
      "z": 4,
      "name": "Rock_Shale_Brick"
    },
    {
      "x": -41,
      "y": 21,
      "z": 4,
      "name": "Rock_Shale_Brick"
    },
    {
      "x": -41,
      "y": 22,
      "z": 4,
      "name": "Rock_Shale_Brick"
    },
    {
      "x": -41,
      "y": 23,
      "z": 4,
      "name": "Rock_Shale_Brick"
    },
    {
      "x": -41,
      "y": 24,
      "z": 4,
      "name": "Rock_Shale_Brick"
    },
    {
      "x": -41,
      "y": 25,
      "z": 4,
      "name": "Rock_Shale_Brick"
    },
    {
      "x": -41,
      "y": 26,
      "z": 4,
      "name": "Rock_Shale_Brick"
    },
    {
      "x": -41,
      "y": 27,
      "z": 4,
      "name": "Rock_Shale_Brick_Ornate"
    },
    {
      "x": -41,
      "y": 28,
      "z": 4,
      "name": "Rock_Shale_Brick_Ornate"
    },
    {
      "x": -41,
      "y": 29,
      "z": 4,
      "name": "Rock_Shale_Brick_Ornate"
    },
    {
      "x": -41,
      "y": 30,
      "z": 4,
      "name": "Rock_Shale_Brick_Ornate"
    },
    {
      "x": -41,
      "y": 31,
      "z": 4,
      "name": "Rock_Shale_Brick_Ornate"
    },
    {
      "x": -41,
      "y": 0,
      "z": 5,
      "name": "Rock_Shale_Brick_Ornate"
    },
    {
      "x": -41,
      "y": 1,
      "z": 5,
      "name": "Rock_Shale_Brick_Ornate"
    },
    {
      "x": -41,
      "y": 2,
      "z": 5,
      "name": "Rock_Shale_Brick_Ornate"
    },
    {
      "x": -41,
      "y": 3,
      "z": 5,
      "name": "Rock_Shale_Brick_Ornate"
    },
    {
      "x": -41,
      "y": 27,
      "z": 5,
      "name": "Rock_Shale_Brick_Ornate"
    },
    {
      "x": -41,
      "y": 28,
      "z": 5,
      "name": "Rock_Shale_Brick_Ornate"
    },
    {
      "x": -41,
      "y": 29,
      "z": 5,
      "name": "Rock_Shale_Brick_Ornate"
    },
    {
      "x": -41,
      "y": 30,
      "z": 5,
      "name": "Rock_Shale_Brick_Ornate"
    },
    {
      "x": -41,
      "y": 31,
      "z": 5,
      "name": "Rock_Shale_Brick_Ornate"
    },
    {
      "x": -40,
      "y": 0,
      "z": -4,
      "name": "Rock_Shale_Brick_Ornate"
    },
    {
      "x": -40,
      "y": 1,
      "z": -4,
      "name": "Rock_Shale_Brick_Ornate"
    },
    {
      "x": -40,
      "y": 2,
      "z": -4,
      "name": "Rock_Shale_Brick_Ornate"
    },
    {
      "x": -40,
      "y": 3,
      "z": -4,
      "name": "Rock_Shale_Brick_Ornate"
    },
    {
      "x": -40,
      "y": 4,
      "z": -4,
      "name": "Rock_Shale_Brick_Ornate"
    },
    {
      "x": -40,
      "y": 27,
      "z": -4,
      "name": "Rock_Shale_Brick_Ornate"
    },
    {
      "x": -40,
      "y": 28,
      "z": -4,
      "name": "Rock_Shale_Brick_Ornate"
    },
    {
      "x": -40,
      "y": 29,
      "z": -4,
      "name": "Rock_Shale_Brick_Ornate"
    },
    {
      "x": -40,
      "y": 30,
      "z": -4,
      "name": "Rock_Shale_Brick_Ornate"
    },
    {
      "x": -40,
      "y": 31,
      "z": -4,
      "name": "Rock_Shale_Brick_Ornate"
    },
    {
      "x": -40,
      "y": 0,
      "z": -3,
      "name": "Rock_Shale_Brick_Ornate"
    },
    {
      "x": -40,
      "y": 1,
      "z": -3,
      "name": "Rock_Shale_Brick_Ornate"
    },
    {
      "x": -40,
      "y": 2,
      "z": -3,
      "name": "Rock_Shale_Brick_Ornate"
    },
    {
      "x": -40,
      "y": 3,
      "z": -3,
      "name": "Rock_Shale_Brick_Ornate"
    },
    {
      "x": -40,
      "y": 4,
      "z": -3,
      "name": "Rock_Shale_Brick_Ornate"
    },
    {
      "x": -40,
      "y": 5,
      "z": -3,
      "name": "Rock_Shale_Brick"
    },
    {
      "x": -40,
      "y": 6,
      "z": -3,
      "name": "Rock_Shale_Brick"
    },
    {
      "x": -40,
      "y": 7,
      "z": -3,
      "name": "Rock_Shale_Brick"
    },
    {
      "x": -40,
      "y": 8,
      "z": -3,
      "name": "Rock_Shale_Brick"
    },
    {
      "x": -40,
      "y": 9,
      "z": -3,
      "name": "Rock_Shale_Brick"
    },
    {
      "x": -40,
      "y": 10,
      "z": -3,
      "name": "Rock_Shale_Brick"
    },
    {
      "x": -40,
      "y": 11,
      "z": -3,
      "name": "Rock_Shale_Brick"
    },
    {
      "x": -40,
      "y": 12,
      "z": -3,
      "name": "Rock_Shale_Brick"
    },
    {
      "x": -40,
      "y": 13,
      "z": -3,
      "name": "Rock_Shale_Brick"
    },
    {
      "x": -40,
      "y": 14,
      "z": -3,
      "name": "Rock_Shale_Brick"
    },
    {
      "x": -40,
      "y": 15,
      "z": -3,
      "name": "Rock_Shale_Brick"
    },
    {
      "x": -40,
      "y": 19,
      "z": -3,
      "name": "Rock_Shale_Brick"
    },
    {
      "x": -40,
      "y": 20,
      "z": -3,
      "name": "Rock_Shale_Brick"
    },
    {
      "x": -40,
      "y": 21,
      "z": -3,
      "name": "Rock_Shale_Brick"
    },
    {
      "x": -40,
      "y": 22,
      "z": -3,
      "name": "Rock_Shale_Brick"
    },
    {
      "x": -40,
      "y": 23,
      "z": -3,
      "name": "Rock_Shale_Brick"
    },
    {
      "x": -40,
      "y": 24,
      "z": -3,
      "name": "Rock_Shale_Brick"
    },
    {
      "x": -40,
      "y": 25,
      "z": -3,
      "name": "Rock_Shale_Brick"
    },
    {
      "x": -40,
      "y": 26,
      "z": -3,
      "name": "Rock_Shale_Brick"
    },
    {
      "x": -40,
      "y": 27,
      "z": -3,
      "name": "Rock_Shale_Brick_Ornate"
    },
    {
      "x": -40,
      "y": 28,
      "z": -3,
      "name": "Rock_Shale_Brick_Ornate"
    },
    {
      "x": -40,
      "y": 29,
      "z": -3,
      "name": "Rock_Shale_Brick_Ornate"
    },
    {
      "x": -40,
      "y": 30,
      "z": -3,
      "name": "Rock_Shale_Brick_Ornate"
    },
    {
      "x": -40,
      "y": 31,
      "z": -3,
      "name": "Rock_Shale_Brick_Ornate"
    },
    {
      "x": -40,
      "y": 0,
      "z": -2,
      "name": "Rock_Shale_Brick_Ornate"
    },
    {
      "x": -40,
      "y": 1,
      "z": -2,
      "name": "Rock_Shale_Brick_Ornate"
    },
    {
      "x": -40,
      "y": 2,
      "z": -2,
      "name": "Rock_Shale_Brick_Ornate"
    },
    {
      "x": -40,
      "y": 3,
      "z": -2,
      "name": "Rock_Shale_Brick_Ornate"
    },
    {
      "x": -40,
      "y": 4,
      "z": -2,
      "name": "Rock_Shale_Brick_Ornate"
    },
    {
      "x": -40,
      "y": 5,
      "z": -2,
      "name": "Rock_Shale_Brick"
    },
    {
      "x": -40,
      "y": 6,
      "z": -2,
      "name": "Rock_Shale_Brick"
    },
    {
      "x": -40,
      "y": 7,
      "z": -2,
      "name": "Rock_Shale_Brick"
    },
    {
      "x": -40,
      "y": 8,
      "z": -2,
      "name": "Rock_Shale_Brick"
    },
    {
      "x": -40,
      "y": 9,
      "z": -2,
      "name": "Rock_Shale_Brick"
    },
    {
      "x": -40,
      "y": 10,
      "z": -2,
      "name": "Rock_Shale_Brick"
    },
    {
      "x": -40,
      "y": 11,
      "z": -2,
      "name": "Rock_Shale_Brick"
    },
    {
      "x": -40,
      "y": 12,
      "z": -2,
      "name": "Rock_Shale_Brick"
    },
    {
      "x": -40,
      "y": 13,
      "z": -2,
      "name": "Rock_Shale_Brick"
    },
    {
      "x": -40,
      "y": 14,
      "z": -2,
      "name": "Rock_Shale_Brick"
    },
    {
      "x": -40,
      "y": 15,
      "z": -2,
      "name": "Rock_Shale_Brick"
    },
    {
      "x": -40,
      "y": 16,
      "z": -2,
      "name": "Rock_Shale_Brick"
    },
    {
      "x": -40,
      "y": 17,
      "z": -2,
      "name": "Rock_Shale_Brick"
    },
    {
      "x": -40,
      "y": 18,
      "z": -2,
      "name": "Rock_Shale_Brick"
    },
    {
      "x": -40,
      "y": 19,
      "z": -2,
      "name": "Rock_Shale_Brick"
    },
    {
      "x": -40,
      "y": 20,
      "z": -2,
      "name": "Rock_Shale_Brick"
    },
    {
      "x": -40,
      "y": 21,
      "z": -2,
      "name": "Rock_Shale_Brick"
    },
    {
      "x": -40,
      "y": 22,
      "z": -2,
      "name": "Rock_Shale_Brick"
    },
    {
      "x": -40,
      "y": 23,
      "z": -2,
      "name": "Rock_Shale_Brick"
    },
    {
      "x": -40,
      "y": 24,
      "z": -2,
      "name": "Rock_Shale_Brick"
    },
    {
      "x": -40,
      "y": 25,
      "z": -2,
      "name": "Rock_Shale_Brick"
    },
    {
      "x": -40,
      "y": 26,
      "z": -2,
      "name": "Rock_Shale_Brick"
    },
    {
      "x": -40,
      "y": 27,
      "z": -2,
      "name": "Rock_Shale_Brick_Ornate"
    },
    {
      "x": -40,
      "y": 28,
      "z": -2,
      "name": "Rock_Shale_Brick_Ornate"
    },
    {
      "x": -40,
      "y": 29,
      "z": -2,
      "name": "Rock_Shale_Brick_Ornate"
    },
    {
      "x": -40,
      "y": 30,
      "z": -2,
      "name": "Rock_Shale_Brick_Ornate"
    },
    {
      "x": -40,
      "y": 31,
      "z": -2,
      "name": "Rock_Shale_Brick_Ornate"
    },
    {
      "x": -40,
      "y": 0,
      "z": -1,
      "name": "Rock_Shale_Brick_Ornate"
    },
    {
      "x": -40,
      "y": 1,
      "z": -1,
      "name": "Rock_Shale_Brick_Ornate"
    },
    {
      "x": -40,
      "y": 2,
      "z": -1,
      "name": "Rock_Shale_Brick_Ornate"
    },
    {
      "x": -40,
      "y": 3,
      "z": -1,
      "name": "Rock_Shale_Brick_Ornate"
    },
    {
      "x": -40,
      "y": 4,
      "z": -1,
      "name": "Rock_Shale_Brick_Ornate"
    },
    {
      "x": -40,
      "y": 5,
      "z": -1,
      "name": "Rock_Shale_Brick"
    },
    {
      "x": -40,
      "y": 6,
      "z": -1,
      "name": "Rock_Shale_Brick"
    },
    {
      "x": -40,
      "y": 7,
      "z": -1,
      "name": "Rock_Shale_Brick"
    },
    {
      "x": -40,
      "y": 8,
      "z": -1,
      "name": "Rock_Shale_Brick"
    },
    {
      "x": -40,
      "y": 9,
      "z": -1,
      "name": "Rock_Shale_Brick"
    },
    {
      "x": -40,
      "y": 10,
      "z": -1,
      "name": "Rock_Shale_Brick"
    },
    {
      "x": -40,
      "y": 11,
      "z": -1,
      "name": "Rock_Shale_Brick"
    },
    {
      "x": -40,
      "y": 12,
      "z": -1,
      "name": "Rock_Shale_Brick"
    },
    {
      "x": -40,
      "y": 13,
      "z": -1,
      "name": "Rock_Shale_Brick"
    },
    {
      "x": -40,
      "y": 14,
      "z": -1,
      "name": "Rock_Shale_Brick"
    },
    {
      "x": -40,
      "y": 15,
      "z": -1,
      "name": "Rock_Shale_Brick"
    },
    {
      "x": -40,
      "y": 16,
      "z": -1,
      "name": "Rock_Shale_Brick"
    },
    {
      "x": -40,
      "y": 17,
      "z": -1,
      "name": "Rock_Shale_Brick"
    },
    {
      "x": -40,
      "y": 18,
      "z": -1,
      "name": "Rock_Shale_Brick"
    },
    {
      "x": -40,
      "y": 19,
      "z": -1,
      "name": "Rock_Shale_Brick"
    },
    {
      "x": -40,
      "y": 20,
      "z": -1,
      "name": "Rock_Shale_Brick"
    },
    {
      "x": -40,
      "y": 21,
      "z": -1,
      "name": "Rock_Shale_Brick"
    },
    {
      "x": -40,
      "y": 22,
      "z": -1,
      "name": "Rock_Shale_Brick"
    },
    {
      "x": -40,
      "y": 23,
      "z": -1,
      "name": "Rock_Shale_Brick"
    },
    {
      "x": -40,
      "y": 24,
      "z": -1,
      "name": "Rock_Shale_Brick"
    },
    {
      "x": -40,
      "y": 25,
      "z": -1,
      "name": "Rock_Shale_Brick"
    },
    {
      "x": -40,
      "y": 26,
      "z": -1,
      "name": "Rock_Shale_Brick"
    },
    {
      "x": -40,
      "y": 27,
      "z": -1,
      "name": "Rock_Shale_Brick_Ornate"
    },
    {
      "x": -40,
      "y": 28,
      "z": -1,
      "name": "Rock_Shale_Brick_Ornate"
    },
    {
      "x": -40,
      "y": 29,
      "z": -1,
      "name": "Rock_Shale_Brick_Ornate"
    },
    {
      "x": -40,
      "y": 30,
      "z": -1,
      "name": "Rock_Shale_Brick_Ornate"
    },
    {
      "x": -40,
      "y": 31,
      "z": -1,
      "name": "Rock_Shale_Brick_Ornate"
    },
    {
      "x": -40,
      "y": 0,
      "z": 0,
      "name": "Rock_Shale_Brick_Ornate"
    },
    {
      "x": -40,
      "y": 1,
      "z": 0,
      "name": "Rock_Shale_Brick_Ornate"
    },
    {
      "x": -40,
      "y": 2,
      "z": 0,
      "name": "Rock_Shale_Brick_Ornate"
    },
    {
      "x": -40,
      "y": 3,
      "z": 0,
      "name": "Rock_Shale_Brick_Ornate"
    },
    {
      "x": -40,
      "y": 4,
      "z": 0,
      "name": "Rock_Shale_Brick_Ornate"
    },
    {
      "x": -40,
      "y": 5,
      "z": 0,
      "name": "Rock_Shale_Brick"
    },
    {
      "x": -40,
      "y": 6,
      "z": 0,
      "name": "Rock_Shale_Brick"
    },
    {
      "x": -40,
      "y": 7,
      "z": 0,
      "name": "Rock_Shale_Brick"
    },
    {
      "x": -40,
      "y": 8,
      "z": 0,
      "name": "Rock_Shale_Brick"
    },
    {
      "x": -40,
      "y": 9,
      "z": 0,
      "name": "Rock_Shale_Brick"
    },
    {
      "x": -40,
      "y": 10,
      "z": 0,
      "name": "Rock_Shale_Brick"
    },
    {
      "x": -40,
      "y": 11,
      "z": 0,
      "name": "Rock_Shale_Brick"
    },
    {
      "x": -40,
      "y": 12,
      "z": 0,
      "name": "Rock_Shale_Brick"
    },
    {
      "x": -40,
      "y": 13,
      "z": 0,
      "name": "Rock_Shale_Brick"
    },
    {
      "x": -40,
      "y": 14,
      "z": 0,
      "name": "Rock_Shale_Brick"
    },
    {
      "x": -40,
      "y": 15,
      "z": 0,
      "name": "Rock_Shale_Brick"
    },
    {
      "x": -40,
      "y": 16,
      "z": 0,
      "name": "Rock_Shale_Brick"
    },
    {
      "x": -40,
      "y": 17,
      "z": 0,
      "name": "Rock_Shale_Brick"
    },
    {
      "x": -40,
      "y": 18,
      "z": 0,
      "name": "Rock_Shale_Brick"
    },
    {
      "x": -40,
      "y": 19,
      "z": 0,
      "name": "Rock_Shale_Brick"
    },
    {
      "x": -40,
      "y": 20,
      "z": 0,
      "name": "Rock_Shale_Brick"
    },
    {
      "x": -40,
      "y": 21,
      "z": 0,
      "name": "Rock_Shale_Brick"
    },
    {
      "x": -40,
      "y": 22,
      "z": 0,
      "name": "Rock_Shale_Brick"
    },
    {
      "x": -40,
      "y": 23,
      "z": 0,
      "name": "Rock_Shale_Brick"
    },
    {
      "x": -40,
      "y": 24,
      "z": 0,
      "name": "Rock_Shale_Brick"
    },
    {
      "x": -40,
      "y": 25,
      "z": 0,
      "name": "Rock_Shale_Brick"
    },
    {
      "x": -40,
      "y": 26,
      "z": 0,
      "name": "Rock_Shale_Brick"
    },
    {
      "x": -40,
      "y": 27,
      "z": 0,
      "name": "Rock_Shale_Brick_Ornate"
    },
    {
      "x": -40,
      "y": 28,
      "z": 0,
      "name": "Rock_Shale_Brick_Ornate"
    },
    {
      "x": -40,
      "y": 29,
      "z": 0,
      "name": "Rock_Shale_Brick_Ornate"
    },
    {
      "x": -40,
      "y": 30,
      "z": 0,
      "name": "Rock_Shale_Brick_Ornate"
    },
    {
      "x": -40,
      "y": 31,
      "z": 0,
      "name": "Rock_Shale_Brick_Ornate"
    },
    {
      "x": -40,
      "y": 0,
      "z": 1,
      "name": "Rock_Shale_Brick_Ornate",
      "rotation": 2
    },
    {
      "x": -40,
      "y": 1,
      "z": 1,
      "name": "Rock_Shale_Brick_Ornate",
      "rotation": 2
    },
    {
      "x": -40,
      "y": 2,
      "z": 1,
      "name": "Rock_Shale_Brick_Ornate",
      "rotation": 2
    },
    {
      "x": -40,
      "y": 3,
      "z": 1,
      "name": "Rock_Shale_Brick_Ornate",
      "rotation": 2
    },
    {
      "x": -40,
      "y": 4,
      "z": 1,
      "name": "Rock_Shale_Brick_Ornate",
      "rotation": 2
    },
    {
      "x": -40,
      "y": 5,
      "z": 1,
      "name": "Rock_Shale_Brick",
      "rotation": 2
    },
    {
      "x": -40,
      "y": 6,
      "z": 1,
      "name": "Rock_Shale_Brick",
      "rotation": 2
    },
    {
      "x": -40,
      "y": 7,
      "z": 1,
      "name": "Rock_Shale_Brick",
      "rotation": 2
    },
    {
      "x": -40,
      "y": 8,
      "z": 1,
      "name": "Rock_Shale_Brick",
      "rotation": 2
    },
    {
      "x": -40,
      "y": 9,
      "z": 1,
      "name": "Rock_Shale_Brick",
      "rotation": 2
    },
    {
      "x": -40,
      "y": 10,
      "z": 1,
      "name": "Rock_Shale_Brick",
      "rotation": 2
    },
    {
      "x": -40,
      "y": 11,
      "z": 1,
      "name": "Rock_Shale_Brick",
      "rotation": 2
    },
    {
      "x": -40,
      "y": 12,
      "z": 1,
      "name": "Rock_Shale_Brick",
      "rotation": 2
    },
    {
      "x": -40,
      "y": 13,
      "z": 1,
      "name": "Rock_Shale_Brick",
      "rotation": 2
    },
    {
      "x": -40,
      "y": 14,
      "z": 1,
      "name": "Rock_Shale_Brick",
      "rotation": 2
    },
    {
      "x": -40,
      "y": 15,
      "z": 1,
      "name": "Rock_Shale_Brick",
      "rotation": 2
    },
    {
      "x": -40,
      "y": 16,
      "z": 1,
      "name": "Rock_Shale_Brick",
      "rotation": 2
    },
    {
      "x": -40,
      "y": 17,
      "z": 1,
      "name": "Rock_Shale_Brick",
      "rotation": 2
    },
    {
      "x": -40,
      "y": 18,
      "z": 1,
      "name": "Rock_Shale_Brick",
      "rotation": 2
    },
    {
      "x": -40,
      "y": 19,
      "z": 1,
      "name": "Rock_Shale_Brick",
      "rotation": 2
    },
    {
      "x": -40,
      "y": 20,
      "z": 1,
      "name": "Rock_Shale_Brick",
      "rotation": 2
    },
    {
      "x": -40,
      "y": 21,
      "z": 1,
      "name": "Rock_Shale_Brick",
      "rotation": 2
    },
    {
      "x": -40,
      "y": 22,
      "z": 1,
      "name": "Rock_Shale_Brick",
      "rotation": 2
    },
    {
      "x": -40,
      "y": 23,
      "z": 1,
      "name": "Rock_Shale_Brick",
      "rotation": 2
    },
    {
      "x": -40,
      "y": 24,
      "z": 1,
      "name": "Rock_Shale_Brick",
      "rotation": 2
    },
    {
      "x": -40,
      "y": 25,
      "z": 1,
      "name": "Rock_Shale_Brick",
      "rotation": 2
    },
    {
      "x": -40,
      "y": 26,
      "z": 1,
      "name": "Rock_Shale_Brick",
      "rotation": 2
    },
    {
      "x": -40,
      "y": 27,
      "z": 1,
      "name": "Rock_Shale_Brick_Ornate"
    },
    {
      "x": -40,
      "y": 28,
      "z": 1,
      "name": "Rock_Shale_Brick_Ornate"
    },
    {
      "x": -40,
      "y": 29,
      "z": 1,
      "name": "Rock_Shale_Brick_Ornate"
    },
    {
      "x": -40,
      "y": 30,
      "z": 1,
      "name": "Rock_Shale_Brick_Ornate"
    },
    {
      "x": -40,
      "y": 31,
      "z": 1,
      "name": "Rock_Shale_Brick_Ornate"
    },
    {
      "x": -40,
      "y": 0,
      "z": 2,
      "name": "Rock_Shale_Brick_Ornate",
      "rotation": 2
    },
    {
      "x": -40,
      "y": 1,
      "z": 2,
      "name": "Rock_Shale_Brick_Ornate",
      "rotation": 2
    },
    {
      "x": -40,
      "y": 2,
      "z": 2,
      "name": "Rock_Shale_Brick_Ornate",
      "rotation": 2
    },
    {
      "x": -40,
      "y": 3,
      "z": 2,
      "name": "Rock_Shale_Brick_Ornate",
      "rotation": 2
    },
    {
      "x": -40,
      "y": 4,
      "z": 2,
      "name": "Rock_Shale_Brick_Ornate",
      "rotation": 2
    },
    {
      "x": -40,
      "y": 5,
      "z": 2,
      "name": "Rock_Shale_Brick",
      "rotation": 2
    },
    {
      "x": -40,
      "y": 6,
      "z": 2,
      "name": "Rock_Shale_Brick",
      "rotation": 2
    },
    {
      "x": -40,
      "y": 7,
      "z": 2,
      "name": "Rock_Shale_Brick",
      "rotation": 2
    },
    {
      "x": -40,
      "y": 8,
      "z": 2,
      "name": "Rock_Shale_Brick",
      "rotation": 2
    },
    {
      "x": -40,
      "y": 9,
      "z": 2,
      "name": "Rock_Shale_Brick",
      "rotation": 2
    },
    {
      "x": -40,
      "y": 10,
      "z": 2,
      "name": "Rock_Shale_Brick",
      "rotation": 2
    },
    {
      "x": -40,
      "y": 11,
      "z": 2,
      "name": "Rock_Shale_Brick",
      "rotation": 2
    },
    {
      "x": -40,
      "y": 12,
      "z": 2,
      "name": "Rock_Shale_Brick",
      "rotation": 2
    },
    {
      "x": -40,
      "y": 13,
      "z": 2,
      "name": "Rock_Shale_Brick",
      "rotation": 2
    },
    {
      "x": -40,
      "y": 14,
      "z": 2,
      "name": "Rock_Shale_Brick",
      "rotation": 2
    },
    {
      "x": -40,
      "y": 15,
      "z": 2,
      "name": "Rock_Shale_Brick",
      "rotation": 2
    },
    {
      "x": -40,
      "y": 16,
      "z": 2,
      "name": "Rock_Shale_Brick",
      "rotation": 2
    },
    {
      "x": -40,
      "y": 17,
      "z": 2,
      "name": "Rock_Shale_Brick",
      "rotation": 2
    },
    {
      "x": -40,
      "y": 18,
      "z": 2,
      "name": "Rock_Shale_Brick",
      "rotation": 2
    },
    {
      "x": -40,
      "y": 19,
      "z": 2,
      "name": "Rock_Shale_Brick",
      "rotation": 2
    },
    {
      "x": -40,
      "y": 20,
      "z": 2,
      "name": "Rock_Shale_Brick",
      "rotation": 2
    },
    {
      "x": -40,
      "y": 21,
      "z": 2,
      "name": "Rock_Shale_Brick",
      "rotation": 2
    },
    {
      "x": -40,
      "y": 22,
      "z": 2,
      "name": "Rock_Shale_Brick",
      "rotation": 2
    },
    {
      "x": -40,
      "y": 23,
      "z": 2,
      "name": "Rock_Shale_Brick",
      "rotation": 2
    },
    {
      "x": -40,
      "y": 24,
      "z": 2,
      "name": "Rock_Shale_Brick",
      "rotation": 2
    },
    {
      "x": -40,
      "y": 25,
      "z": 2,
      "name": "Rock_Shale_Brick",
      "rotation": 2
    },
    {
      "x": -40,
      "y": 26,
      "z": 2,
      "name": "Rock_Shale_Brick",
      "rotation": 2
    },
    {
      "x": -40,
      "y": 27,
      "z": 2,
      "name": "Rock_Shale_Brick_Ornate"
    },
    {
      "x": -40,
      "y": 28,
      "z": 2,
      "name": "Rock_Shale_Brick_Ornate"
    },
    {
      "x": -40,
      "y": 29,
      "z": 2,
      "name": "Rock_Shale_Brick_Ornate"
    },
    {
      "x": -40,
      "y": 30,
      "z": 2,
      "name": "Rock_Shale_Brick_Ornate"
    },
    {
      "x": -40,
      "y": 31,
      "z": 2,
      "name": "Rock_Shale_Brick_Ornate"
    },
    {
      "x": -40,
      "y": 0,
      "z": 3,
      "name": "Rock_Shale_Brick_Ornate",
      "rotation": 2
    },
    {
      "x": -40,
      "y": 1,
      "z": 3,
      "name": "Rock_Shale_Brick_Ornate",
      "rotation": 2
    },
    {
      "x": -40,
      "y": 2,
      "z": 3,
      "name": "Rock_Shale_Brick_Ornate",
      "rotation": 2
    },
    {
      "x": -40,
      "y": 3,
      "z": 3,
      "name": "Rock_Shale_Brick_Ornate",
      "rotation": 2
    },
    {
      "x": -40,
      "y": 4,
      "z": 3,
      "name": "Rock_Shale_Brick_Ornate",
      "rotation": 2
    },
    {
      "x": -40,
      "y": 5,
      "z": 3,
      "name": "Rock_Shale_Brick",
      "rotation": 2
    },
    {
      "x": -40,
      "y": 6,
      "z": 3,
      "name": "Rock_Shale_Brick",
      "rotation": 2
    },
    {
      "x": -40,
      "y": 7,
      "z": 3,
      "name": "Rock_Shale_Brick",
      "rotation": 2
    },
    {
      "x": -40,
      "y": 8,
      "z": 3,
      "name": "Rock_Shale_Brick",
      "rotation": 2
    },
    {
      "x": -40,
      "y": 9,
      "z": 3,
      "name": "Rock_Shale_Brick",
      "rotation": 2
    },
    {
      "x": -40,
      "y": 10,
      "z": 3,
      "name": "Rock_Shale_Brick",
      "rotation": 2
    },
    {
      "x": -40,
      "y": 11,
      "z": 3,
      "name": "Rock_Shale_Brick",
      "rotation": 2
    },
    {
      "x": -40,
      "y": 12,
      "z": 3,
      "name": "Rock_Shale_Brick",
      "rotation": 2
    },
    {
      "x": -40,
      "y": 13,
      "z": 3,
      "name": "Rock_Shale_Brick",
      "rotation": 2
    },
    {
      "x": -40,
      "y": 14,
      "z": 3,
      "name": "Rock_Shale_Brick",
      "rotation": 2
    },
    {
      "x": -40,
      "y": 15,
      "z": 3,
      "name": "Rock_Shale_Brick",
      "rotation": 2
    },
    {
      "x": -40,
      "y": 16,
      "z": 3,
      "name": "Rock_Shale_Brick",
      "rotation": 2
    },
    {
      "x": -40,
      "y": 17,
      "z": 3,
      "name": "Rock_Shale_Brick",
      "rotation": 2
    },
    {
      "x": -40,
      "y": 18,
      "z": 3,
      "name": "Rock_Shale_Brick",
      "rotation": 2
    },
    {
      "x": -40,
      "y": 19,
      "z": 3,
      "name": "Rock_Shale_Brick",
      "rotation": 2
    },
    {
      "x": -40,
      "y": 20,
      "z": 3,
      "name": "Rock_Shale_Brick",
      "rotation": 2
    },
    {
      "x": -40,
      "y": 21,
      "z": 3,
      "name": "Rock_Shale_Brick",
      "rotation": 2
    },
    {
      "x": -40,
      "y": 22,
      "z": 3,
      "name": "Rock_Shale_Brick",
      "rotation": 2
    },
    {
      "x": -40,
      "y": 23,
      "z": 3,
      "name": "Rock_Shale_Brick",
      "rotation": 2
    },
    {
      "x": -40,
      "y": 24,
      "z": 3,
      "name": "Rock_Shale_Brick",
      "rotation": 2
    },
    {
      "x": -40,
      "y": 25,
      "z": 3,
      "name": "Rock_Shale_Brick",
      "rotation": 2
    },
    {
      "x": -40,
      "y": 26,
      "z": 3,
      "name": "Rock_Shale_Brick",
      "rotation": 2
    },
    {
      "x": -40,
      "y": 27,
      "z": 3,
      "name": "Rock_Shale_Brick_Ornate"
    },
    {
      "x": -40,
      "y": 28,
      "z": 3,
      "name": "Rock_Shale_Brick_Ornate"
    },
    {
      "x": -40,
      "y": 29,
      "z": 3,
      "name": "Rock_Shale_Brick_Ornate"
    },
    {
      "x": -40,
      "y": 30,
      "z": 3,
      "name": "Rock_Shale_Brick_Ornate"
    },
    {
      "x": -40,
      "y": 31,
      "z": 3,
      "name": "Rock_Shale_Brick_Ornate"
    },
    {
      "x": -40,
      "y": 0,
      "z": 4,
      "name": "Rock_Shale_Brick_Ornate",
      "rotation": 2
    },
    {
      "x": -40,
      "y": 1,
      "z": 4,
      "name": "Rock_Shale_Brick_Ornate",
      "rotation": 2
    },
    {
      "x": -40,
      "y": 2,
      "z": 4,
      "name": "Rock_Shale_Brick_Ornate",
      "rotation": 2
    },
    {
      "x": -40,
      "y": 3,
      "z": 4,
      "name": "Rock_Shale_Brick_Ornate",
      "rotation": 2
    },
    {
      "x": -40,
      "y": 4,
      "z": 4,
      "name": "Rock_Shale_Brick_Ornate",
      "rotation": 2
    },
    {
      "x": -40,
      "y": 5,
      "z": 4,
      "name": "Rock_Shale_Brick",
      "rotation": 2
    },
    {
      "x": -40,
      "y": 6,
      "z": 4,
      "name": "Rock_Shale_Brick",
      "rotation": 2
    },
    {
      "x": -40,
      "y": 7,
      "z": 4,
      "name": "Rock_Shale_Brick",
      "rotation": 2
    },
    {
      "x": -40,
      "y": 8,
      "z": 4,
      "name": "Rock_Shale_Brick",
      "rotation": 2
    },
    {
      "x": -40,
      "y": 9,
      "z": 4,
      "name": "Rock_Shale_Brick",
      "rotation": 2
    },
    {
      "x": -40,
      "y": 10,
      "z": 4,
      "name": "Rock_Shale_Brick",
      "rotation": 2
    },
    {
      "x": -40,
      "y": 11,
      "z": 4,
      "name": "Rock_Shale_Brick",
      "rotation": 2
    },
    {
      "x": -40,
      "y": 12,
      "z": 4,
      "name": "Rock_Shale_Brick",
      "rotation": 2
    },
    {
      "x": -40,
      "y": 13,
      "z": 4,
      "name": "Rock_Shale_Brick",
      "rotation": 2
    },
    {
      "x": -40,
      "y": 14,
      "z": 4,
      "name": "Rock_Shale_Brick",
      "rotation": 2
    },
    {
      "x": -40,
      "y": 15,
      "z": 4,
      "name": "Rock_Shale_Brick",
      "rotation": 2
    },
    {
      "x": -40,
      "y": 16,
      "z": 4,
      "name": "Rock_Shale_Brick",
      "rotation": 2
    },
    {
      "x": -40,
      "y": 17,
      "z": 4,
      "name": "Rock_Shale_Brick",
      "rotation": 2
    },
    {
      "x": -40,
      "y": 18,
      "z": 4,
      "name": "Rock_Shale_Brick",
      "rotation": 2
    },
    {
      "x": -40,
      "y": 19,
      "z": 4,
      "name": "Rock_Shale_Brick",
      "rotation": 2
    },
    {
      "x": -40,
      "y": 20,
      "z": 4,
      "name": "Rock_Shale_Brick",
      "rotation": 2
    },
    {
      "x": -40,
      "y": 21,
      "z": 4,
      "name": "Rock_Shale_Brick",
      "rotation": 2
    },
    {
      "x": -40,
      "y": 22,
      "z": 4,
      "name": "Rock_Shale_Brick",
      "rotation": 2
    },
    {
      "x": -40,
      "y": 23,
      "z": 4,
      "name": "Rock_Shale_Brick",
      "rotation": 2
    },
    {
      "x": -40,
      "y": 24,
      "z": 4,
      "name": "Rock_Shale_Brick",
      "rotation": 2
    },
    {
      "x": -40,
      "y": 25,
      "z": 4,
      "name": "Rock_Shale_Brick",
      "rotation": 2
    },
    {
      "x": -40,
      "y": 26,
      "z": 4,
      "name": "Rock_Shale_Brick",
      "rotation": 2
    },
    {
      "x": -40,
      "y": 27,
      "z": 4,
      "name": "Rock_Shale_Brick_Ornate"
    },
    {
      "x": -40,
      "y": 28,
      "z": 4,
      "name": "Rock_Shale_Brick_Ornate"
    },
    {
      "x": -40,
      "y": 29,
      "z": 4,
      "name": "Rock_Shale_Brick_Ornate"
    },
    {
      "x": -40,
      "y": 30,
      "z": 4,
      "name": "Rock_Shale_Brick_Ornate"
    },
    {
      "x": -40,
      "y": 31,
      "z": 4,
      "name": "Rock_Shale_Brick_Ornate"
    },
    {
      "x": -40,
      "y": 0,
      "z": 5,
      "name": "Rock_Shale_Brick_Ornate",
      "rotation": 2
    },
    {
      "x": -40,
      "y": 1,
      "z": 5,
      "name": "Rock_Shale_Brick_Ornate",
      "rotation": 2
    },
    {
      "x": -40,
      "y": 2,
      "z": 5,
      "name": "Rock_Shale_Brick_Ornate",
      "rotation": 2
    },
    {
      "x": -40,
      "y": 3,
      "z": 5,
      "name": "Rock_Shale_Brick_Ornate",
      "rotation": 2
    },
    {
      "x": -40,
      "y": 4,
      "z": 5,
      "name": "Rock_Shale_Brick_Ornate",
      "rotation": 2
    },
    {
      "x": -40,
      "y": 27,
      "z": 5,
      "name": "Rock_Shale_Brick_Ornate"
    },
    {
      "x": -40,
      "y": 28,
      "z": 5,
      "name": "Rock_Shale_Brick_Ornate"
    },
    {
      "x": -40,
      "y": 29,
      "z": 5,
      "name": "Rock_Shale_Brick_Ornate"
    },
    {
      "x": -40,
      "y": 30,
      "z": 5,
      "name": "Rock_Shale_Brick_Ornate"
    },
    {
      "x": -40,
      "y": 31,
      "z": 5,
      "name": "Rock_Shale_Brick_Ornate"
    },
    {
      "x": -39,
      "y": 0,
      "z": -4,
      "name": "Rock_Shale_Brick_Ornate"
    },
    {
      "x": -39,
      "y": 1,
      "z": -4,
      "name": "Rock_Shale_Brick_Ornate"
    },
    {
      "x": -39,
      "y": 2,
      "z": -4,
      "name": "Rock_Shale_Brick_Ornate"
    },
    {
      "x": -39,
      "y": 3,
      "z": -4,
      "name": "Rock_Shale_Brick_Ornate"
    },
    {
      "x": -39,
      "y": 4,
      "z": -4,
      "name": "Rock_Shale_Brick_Ornate"
    },
    {
      "x": -39,
      "y": 27,
      "z": -4,
      "name": "Rock_Shale_Brick_Ornate"
    },
    {
      "x": -39,
      "y": 28,
      "z": -4,
      "name": "Rock_Shale_Brick_Ornate"
    },
    {
      "x": -39,
      "y": 29,
      "z": -4,
      "name": "Rock_Shale_Brick_Ornate"
    },
    {
      "x": -39,
      "y": 30,
      "z": -4,
      "name": "Rock_Shale_Brick_Ornate"
    },
    {
      "x": -39,
      "y": 31,
      "z": -4,
      "name": "Rock_Shale_Brick_Ornate"
    },
    {
      "x": -39,
      "y": 0,
      "z": -3,
      "name": "Rock_Shale_Brick_Ornate"
    },
    {
      "x": -39,
      "y": 1,
      "z": -3,
      "name": "Rock_Shale_Brick_Ornate"
    },
    {
      "x": -39,
      "y": 2,
      "z": -3,
      "name": "Rock_Shale_Brick_Ornate"
    },
    {
      "x": -39,
      "y": 3,
      "z": -3,
      "name": "Rock_Shale_Brick_Ornate"
    },
    {
      "x": -39,
      "y": 4,
      "z": -3,
      "name": "Rock_Shale_Brick_Ornate"
    },
    {
      "x": -39,
      "y": 5,
      "z": -3,
      "name": "Rock_Shale_Brick"
    },
    {
      "x": -39,
      "y": 6,
      "z": -3,
      "name": "Rock_Shale_Brick"
    },
    {
      "x": -39,
      "y": 7,
      "z": -3,
      "name": "Rock_Shale_Brick"
    },
    {
      "x": -39,
      "y": 8,
      "z": -3,
      "name": "Rock_Shale_Brick"
    },
    {
      "x": -39,
      "y": 9,
      "z": -3,
      "name": "Rock_Shale_Brick"
    },
    {
      "x": -39,
      "y": 10,
      "z": -3,
      "name": "Rock_Shale_Brick"
    },
    {
      "x": -39,
      "y": 11,
      "z": -3,
      "name": "Rock_Shale_Brick"
    },
    {
      "x": -39,
      "y": 12,
      "z": -3,
      "name": "Rock_Shale_Brick"
    },
    {
      "x": -39,
      "y": 13,
      "z": -3,
      "name": "Rock_Shale_Brick"
    },
    {
      "x": -39,
      "y": 22,
      "z": -3,
      "name": "Rock_Shale_Brick"
    },
    {
      "x": -39,
      "y": 23,
      "z": -3,
      "name": "Rock_Shale_Brick"
    },
    {
      "x": -39,
      "y": 24,
      "z": -3,
      "name": "Rock_Shale_Brick"
    },
    {
      "x": -39,
      "y": 25,
      "z": -3,
      "name": "Rock_Shale_Brick"
    },
    {
      "x": -39,
      "y": 26,
      "z": -3,
      "name": "Rock_Shale_Brick"
    },
    {
      "x": -39,
      "y": 27,
      "z": -3,
      "name": "Rock_Shale_Brick_Ornate"
    },
    {
      "x": -39,
      "y": 28,
      "z": -3,
      "name": "Rock_Shale_Brick_Ornate"
    },
    {
      "x": -39,
      "y": 29,
      "z": -3,
      "name": "Rock_Shale_Brick_Ornate"
    },
    {
      "x": -39,
      "y": 30,
      "z": -3,
      "name": "Rock_Shale_Brick_Ornate"
    },
    {
      "x": -39,
      "y": 31,
      "z": -3,
      "name": "Rock_Shale_Brick_Ornate"
    },
    {
      "x": -39,
      "y": 0,
      "z": -2,
      "name": "Rock_Shale_Brick_Ornate"
    },
    {
      "x": -39,
      "y": 1,
      "z": -2,
      "name": "Rock_Shale_Brick_Ornate"
    },
    {
      "x": -39,
      "y": 2,
      "z": -2,
      "name": "Rock_Shale_Brick_Ornate"
    },
    {
      "x": -39,
      "y": 3,
      "z": -2,
      "name": "Rock_Shale_Brick_Ornate"
    },
    {
      "x": -39,
      "y": 4,
      "z": -2,
      "name": "Rock_Shale_Brick_Ornate"
    },
    {
      "x": -39,
      "y": 5,
      "z": -2,
      "name": "Rock_Shale_Brick"
    },
    {
      "x": -39,
      "y": 6,
      "z": -2,
      "name": "Rock_Shale_Brick"
    },
    {
      "x": -39,
      "y": 7,
      "z": -2,
      "name": "Rock_Shale_Brick"
    },
    {
      "x": -39,
      "y": 8,
      "z": -2,
      "name": "Rock_Shale_Brick"
    },
    {
      "x": -39,
      "y": 9,
      "z": -2,
      "name": "Rock_Shale_Brick"
    },
    {
      "x": -39,
      "y": 10,
      "z": -2,
      "name": "Rock_Shale_Brick"
    },
    {
      "x": -39,
      "y": 11,
      "z": -2,
      "name": "Rock_Shale_Brick"
    },
    {
      "x": -39,
      "y": 12,
      "z": -2,
      "name": "Rock_Shale_Brick"
    },
    {
      "x": -39,
      "y": 13,
      "z": -2,
      "name": "Rock_Shale_Brick"
    },
    {
      "x": -39,
      "y": 14,
      "z": -2,
      "name": "Rock_Shale_Brick"
    },
    {
      "x": -39,
      "y": 15,
      "z": -2,
      "name": "Rock_Shale_Brick"
    },
    {
      "x": -39,
      "y": 19,
      "z": -2,
      "name": "Rock_Shale_Brick"
    },
    {
      "x": -39,
      "y": 20,
      "z": -2,
      "name": "Rock_Shale_Brick"
    },
    {
      "x": -39,
      "y": 21,
      "z": -2,
      "name": "Rock_Shale_Brick"
    },
    {
      "x": -39,
      "y": 22,
      "z": -2,
      "name": "Rock_Shale_Brick"
    },
    {
      "x": -39,
      "y": 23,
      "z": -2,
      "name": "Rock_Shale_Brick"
    },
    {
      "x": -39,
      "y": 24,
      "z": -2,
      "name": "Rock_Shale_Brick"
    },
    {
      "x": -39,
      "y": 25,
      "z": -2,
      "name": "Rock_Shale_Brick"
    },
    {
      "x": -39,
      "y": 26,
      "z": -2,
      "name": "Rock_Shale_Brick"
    },
    {
      "x": -39,
      "y": 27,
      "z": -2,
      "name": "Rock_Shale_Brick_Ornate"
    },
    {
      "x": -39,
      "y": 28,
      "z": -2,
      "name": "Rock_Shale_Brick_Ornate"
    },
    {
      "x": -39,
      "y": 29,
      "z": -2,
      "name": "Rock_Shale_Brick_Ornate"
    },
    {
      "x": -39,
      "y": 30,
      "z": -2,
      "name": "Rock_Shale_Brick_Ornate"
    },
    {
      "x": -39,
      "y": 31,
      "z": -2,
      "name": "Rock_Shale_Brick_Ornate"
    },
    {
      "x": -39,
      "y": 0,
      "z": -1,
      "name": "Rock_Shale_Brick_Ornate"
    },
    {
      "x": -39,
      "y": 1,
      "z": -1,
      "name": "Rock_Shale_Brick_Ornate"
    },
    {
      "x": -39,
      "y": 2,
      "z": -1,
      "name": "Rock_Shale_Brick_Ornate"
    },
    {
      "x": -39,
      "y": 3,
      "z": -1,
      "name": "Rock_Shale_Brick_Ornate"
    },
    {
      "x": -39,
      "y": 4,
      "z": -1,
      "name": "Rock_Shale_Brick_Ornate"
    },
    {
      "x": -39,
      "y": 5,
      "z": -1,
      "name": "Rock_Shale_Brick"
    },
    {
      "x": -39,
      "y": 6,
      "z": -1,
      "name": "Rock_Shale_Brick"
    },
    {
      "x": -39,
      "y": 7,
      "z": -1,
      "name": "Rock_Shale_Brick"
    },
    {
      "x": -39,
      "y": 8,
      "z": -1,
      "name": "Rock_Shale_Brick"
    },
    {
      "x": -39,
      "y": 9,
      "z": -1,
      "name": "Rock_Shale_Brick"
    },
    {
      "x": -39,
      "y": 10,
      "z": -1,
      "name": "Rock_Shale_Brick"
    },
    {
      "x": -39,
      "y": 11,
      "z": -1,
      "name": "Rock_Shale_Brick"
    },
    {
      "x": -39,
      "y": 12,
      "z": -1,
      "name": "Rock_Shale_Brick"
    },
    {
      "x": -39,
      "y": 13,
      "z": -1,
      "name": "Rock_Shale_Brick"
    },
    {
      "x": -39,
      "y": 14,
      "z": -1,
      "name": "Rock_Shale_Brick"
    },
    {
      "x": -39,
      "y": 15,
      "z": -1,
      "name": "Rock_Shale_Brick"
    },
    {
      "x": -39,
      "y": 16,
      "z": -1,
      "name": "Rock_Shale_Brick"
    },
    {
      "x": -39,
      "y": 17,
      "z": -1,
      "name": "Rock_Shale_Brick"
    },
    {
      "x": -39,
      "y": 18,
      "z": -1,
      "name": "Rock_Shale_Brick"
    },
    {
      "x": -39,
      "y": 19,
      "z": -1,
      "name": "Rock_Shale_Brick"
    },
    {
      "x": -39,
      "y": 20,
      "z": -1,
      "name": "Rock_Shale_Brick"
    },
    {
      "x": -39,
      "y": 21,
      "z": -1,
      "name": "Rock_Shale_Brick"
    },
    {
      "x": -39,
      "y": 22,
      "z": -1,
      "name": "Rock_Shale_Brick"
    },
    {
      "x": -39,
      "y": 23,
      "z": -1,
      "name": "Rock_Shale_Brick"
    },
    {
      "x": -39,
      "y": 24,
      "z": -1,
      "name": "Rock_Shale_Brick"
    },
    {
      "x": -39,
      "y": 25,
      "z": -1,
      "name": "Rock_Shale_Brick"
    },
    {
      "x": -39,
      "y": 26,
      "z": -1,
      "name": "Rock_Shale_Brick"
    },
    {
      "x": -39,
      "y": 27,
      "z": -1,
      "name": "Rock_Shale_Brick_Ornate"
    },
    {
      "x": -39,
      "y": 28,
      "z": -1,
      "name": "Rock_Shale_Brick_Ornate"
    },
    {
      "x": -39,
      "y": 29,
      "z": -1,
      "name": "Rock_Shale_Brick_Ornate"
    },
    {
      "x": -39,
      "y": 30,
      "z": -1,
      "name": "Rock_Shale_Brick_Ornate"
    },
    {
      "x": -39,
      "y": 31,
      "z": -1,
      "name": "Rock_Shale_Brick_Ornate"
    },
    {
      "x": -39,
      "y": 0,
      "z": 0,
      "name": "Rock_Shale_Brick_Ornate"
    },
    {
      "x": -39,
      "y": 1,
      "z": 0,
      "name": "Rock_Shale_Brick_Ornate"
    },
    {
      "x": -39,
      "y": 2,
      "z": 0,
      "name": "Rock_Shale_Brick_Ornate"
    },
    {
      "x": -39,
      "y": 3,
      "z": 0,
      "name": "Rock_Shale_Brick_Ornate"
    },
    {
      "x": -39,
      "y": 4,
      "z": 0,
      "name": "Rock_Shale_Brick_Ornate"
    },
    {
      "x": -39,
      "y": 5,
      "z": 0,
      "name": "Rock_Shale_Brick"
    },
    {
      "x": -39,
      "y": 6,
      "z": 0,
      "name": "Rock_Shale_Brick"
    },
    {
      "x": -39,
      "y": 7,
      "z": 0,
      "name": "Rock_Shale_Brick"
    },
    {
      "x": -39,
      "y": 8,
      "z": 0,
      "name": "Rock_Shale_Brick"
    },
    {
      "x": -39,
      "y": 9,
      "z": 0,
      "name": "Rock_Shale_Brick"
    },
    {
      "x": -39,
      "y": 10,
      "z": 0,
      "name": "Rock_Shale_Brick"
    },
    {
      "x": -39,
      "y": 11,
      "z": 0,
      "name": "Rock_Shale_Brick"
    },
    {
      "x": -39,
      "y": 12,
      "z": 0,
      "name": "Rock_Shale_Brick"
    },
    {
      "x": -39,
      "y": 13,
      "z": 0,
      "name": "Rock_Shale_Brick"
    },
    {
      "x": -39,
      "y": 14,
      "z": 0,
      "name": "Rock_Shale_Brick"
    },
    {
      "x": -39,
      "y": 15,
      "z": 0,
      "name": "Rock_Shale_Brick"
    },
    {
      "x": -39,
      "y": 16,
      "z": 0,
      "name": "Rock_Shale_Brick"
    },
    {
      "x": -39,
      "y": 17,
      "z": 0,
      "name": "Rock_Shale_Brick"
    },
    {
      "x": -39,
      "y": 18,
      "z": 0,
      "name": "Rock_Shale_Brick"
    },
    {
      "x": -39,
      "y": 19,
      "z": 0,
      "name": "Rock_Shale_Brick"
    },
    {
      "x": -39,
      "y": 20,
      "z": 0,
      "name": "Rock_Shale_Brick"
    },
    {
      "x": -39,
      "y": 21,
      "z": 0,
      "name": "Rock_Shale_Brick"
    },
    {
      "x": -39,
      "y": 22,
      "z": 0,
      "name": "Rock_Shale_Brick"
    },
    {
      "x": -39,
      "y": 23,
      "z": 0,
      "name": "Rock_Shale_Brick"
    },
    {
      "x": -39,
      "y": 24,
      "z": 0,
      "name": "Rock_Shale_Brick"
    },
    {
      "x": -39,
      "y": 25,
      "z": 0,
      "name": "Rock_Shale_Brick"
    },
    {
      "x": -39,
      "y": 26,
      "z": 0,
      "name": "Rock_Shale_Brick"
    },
    {
      "x": -39,
      "y": 27,
      "z": 0,
      "name": "Rock_Shale_Brick_Ornate"
    },
    {
      "x": -39,
      "y": 28,
      "z": 0,
      "name": "Rock_Shale_Brick_Ornate"
    },
    {
      "x": -39,
      "y": 29,
      "z": 0,
      "name": "Rock_Shale_Brick_Ornate"
    },
    {
      "x": -39,
      "y": 30,
      "z": 0,
      "name": "Rock_Shale_Brick_Ornate"
    },
    {
      "x": -39,
      "y": 31,
      "z": 0,
      "name": "Rock_Shale_Brick_Ornate"
    },
    {
      "x": -39,
      "y": 0,
      "z": 1,
      "name": "Rock_Shale_Brick_Ornate",
      "rotation": 2
    },
    {
      "x": -39,
      "y": 1,
      "z": 1,
      "name": "Rock_Shale_Brick_Ornate",
      "rotation": 2
    },
    {
      "x": -39,
      "y": 2,
      "z": 1,
      "name": "Rock_Shale_Brick_Ornate",
      "rotation": 2
    },
    {
      "x": -39,
      "y": 3,
      "z": 1,
      "name": "Rock_Shale_Brick_Ornate",
      "rotation": 2
    },
    {
      "x": -39,
      "y": 4,
      "z": 1,
      "name": "Rock_Shale_Brick_Ornate",
      "rotation": 2
    },
    {
      "x": -39,
      "y": 5,
      "z": 1,
      "name": "Rock_Shale_Brick",
      "rotation": 2
    },
    {
      "x": -39,
      "y": 6,
      "z": 1,
      "name": "Rock_Shale_Brick",
      "rotation": 2
    },
    {
      "x": -39,
      "y": 7,
      "z": 1,
      "name": "Rock_Shale_Brick",
      "rotation": 2
    },
    {
      "x": -39,
      "y": 8,
      "z": 1,
      "name": "Rock_Shale_Brick",
      "rotation": 2
    },
    {
      "x": -39,
      "y": 9,
      "z": 1,
      "name": "Rock_Shale_Brick",
      "rotation": 2
    },
    {
      "x": -39,
      "y": 10,
      "z": 1,
      "name": "Rock_Shale_Brick",
      "rotation": 2
    },
    {
      "x": -39,
      "y": 11,
      "z": 1,
      "name": "Rock_Shale_Brick",
      "rotation": 2
    },
    {
      "x": -39,
      "y": 12,
      "z": 1,
      "name": "Rock_Shale_Brick",
      "rotation": 2
    },
    {
      "x": -39,
      "y": 13,
      "z": 1,
      "name": "Rock_Shale_Brick",
      "rotation": 2
    },
    {
      "x": -39,
      "y": 14,
      "z": 1,
      "name": "Rock_Shale_Brick",
      "rotation": 2
    },
    {
      "x": -39,
      "y": 15,
      "z": 1,
      "name": "Rock_Shale_Brick",
      "rotation": 2
    },
    {
      "x": -39,
      "y": 16,
      "z": 1,
      "name": "Rock_Shale_Brick",
      "rotation": 2
    },
    {
      "x": -39,
      "y": 17,
      "z": 1,
      "name": "Rock_Shale_Brick",
      "rotation": 2
    },
    {
      "x": -39,
      "y": 18,
      "z": 1,
      "name": "Rock_Shale_Brick",
      "rotation": 2
    },
    {
      "x": -39,
      "y": 19,
      "z": 1,
      "name": "Rock_Shale_Brick",
      "rotation": 2
    },
    {
      "x": -39,
      "y": 20,
      "z": 1,
      "name": "Rock_Shale_Brick",
      "rotation": 2
    },
    {
      "x": -39,
      "y": 21,
      "z": 1,
      "name": "Rock_Shale_Brick",
      "rotation": 2
    },
    {
      "x": -39,
      "y": 22,
      "z": 1,
      "name": "Rock_Shale_Brick",
      "rotation": 2
    },
    {
      "x": -39,
      "y": 23,
      "z": 1,
      "name": "Rock_Shale_Brick",
      "rotation": 2
    },
    {
      "x": -39,
      "y": 24,
      "z": 1,
      "name": "Rock_Shale_Brick",
      "rotation": 2
    },
    {
      "x": -39,
      "y": 25,
      "z": 1,
      "name": "Rock_Shale_Brick",
      "rotation": 2
    },
    {
      "x": -39,
      "y": 26,
      "z": 1,
      "name": "Rock_Shale_Brick",
      "rotation": 2
    },
    {
