{
  "version": 8,
  "blockIdVersion": 11,
  "anchorX": 11,
  "anchorY": 36,
  "anchorZ": -2,
  "blocks": [
    {
      "x": -45,
      "y": 33,
      "z": -5,
      "name": "Rock_Volcanic_Brick"
    },
    {
      "x": -45,
      "y": 34,
      "z": -5,
      "name": "Rock_Volcanic_Brick"
    },
    {
      "x": -45,
      "y": 35,
      "z": -5,
      "name": "Rock_Volcanic_Brick"
    },
    {
      "x": -45,
      "y": 33,
      "z": -4,
      "name": "Rock_Volcanic_Brick"
    },
    {
      "x": -45,
      "y": 34,
      "z": -4,
      "name": "Rock_Volcanic_Brick"
    },
    {
      "x": -45,
      "y": 35,
      "z": -4,
      "name": "Rock_Volcanic_Brick"
    },
    {
      "x": -45,
      "y": 36,
      "z": -4,
      "name": "Rock_Volcanic_Brick"
    },
    {
      "x": -45,
      "y": 32,
      "z": -3,
      "name": "Rock_Volcanic_Brick"
    },
    {
      "x": -45,
      "y": 33,
      "z": -3,
      "name": "Rock_Volcanic_Brick"
    },
    {
      "x": -45,
      "y": 34,
      "z": -3,
      "name": "Rock_Volcanic_Brick"
    },
    {
      "x": -45,
      "y": 35,
      "z": -3,
      "name": "Rock_Volcanic_Brick"
    },
    {
      "x": -45,
      "y": 33,
      "z": -2,
      "name": "Rock_Volcanic_Brick"
    },
    {
      "x": -45,
      "y": 34,
      "z": -2,
      "name": "Rock_Volcanic_Brick"
    },
    {
      "x": -45,
      "y": 35,
      "z": -2,
      "name": "Rock_Volcanic_Brick"
    },
    {
      "x": -45,
      "y": 40,
      "z": -2,
      "name": "Rock_Volcanic_Brick"
    },
    {
      "x": -45,
      "y": 41,
      "z": -2,
      "name": "Rock_Volcanic_Brick"
    },
    {
      "x": -45,
      "y": 34,
      "z": -1,
      "name": "Rock_Volcanic_Brick"
    },
    {
      "x": -45,
      "y": 39,
      "z": -1,
      "name": "Rock_Volcanic_Brick"
    },
    {
      "x": -45,
      "y": 40,
      "z": -1,
      "name": "Rock_Volcanic_Brick"
    },
    {
      "x": -45,
      "y": 41,
      "z": -1,
      "name": "Rock_Volcanic_Brick"
    },
    {
      "x": -45,
      "y": 42,
      "z": -1,
      "name": "Rock_Volcanic_Brick"
    },
    {
      "x": -45,
      "y": 39,
      "z": 0,
      "name": "Rock_Volcanic_Brick"
    },
    {
      "x": -45,
      "y": 40,
      "z": 0,
      "name": "Rock_Volcanic_Brick"
    },
    {
      "x": -45,
      "y": 41,
      "z": 0,
      "name": "Rock_Volcanic_Brick"
    },
    {
      "x": -45,
      "y": 42,
      "z": 0,
      "name": "Rock_Volcanic_Brick"
    },
    {
      "x": -45,
      "y": 38,
      "z": 1,
      "name": "Rock_Volcanic_Brick"
    },
    {
      "x": -45,
      "y": 39,
      "z": 1,
      "name": "Rock_Volcanic_Brick"
    },
    {
      "x": -45,
      "y": 40,
      "z": 1,
      "name": "Rock_Volcanic_Brick"
    },
    {
      "x": -45,
      "y": 41,
      "z": 1,
      "name": "Rock_Volcanic_Brick"
    },
    {
      "x": -45,
      "y": 42,
      "z": 1,
      "name": "Rock_Volcanic_Brick"
    },
    {
      "x": -45,
      "y": 39,
      "z": 2,
      "name": "Rock_Volcanic_Brick"
    },
    {
      "x": -45,
      "y": 40,
      "z": 2,
      "name": "Rock_Volcanic_Brick"
    },
    {
      "x": -45,
      "y": 41,
      "z": 2,
      "name": "Rock_Volcanic_Brick"
    },
    {
      "x": -45,
      "y": 42,
      "z": 2,
      "name": "Rock_Volcanic_Brick"
    },
    {
      "x": -45,
      "y": 47,
      "z": 2,
      "name": "Rock_Volcanic_Brick"
    },
    {
      "x": -45,
      "y": 41,
      "z": 3,
      "name": "Rock_Volcanic_Brick"
    },
    {
      "x": -45,
      "y": 46,
      "z": 3,
      "name": "Rock_Volcanic_Brick"
    },
    {
      "x": -45,
      "y": 47,
      "z": 3,
      "name": "Rock_Volcanic_Brick"
    },
    {
      "x": -45,
      "y": 48,
      "z": 3,
      "name": "Rock_Volcanic_Brick"
    },
    {
      "x": -45,
      "y": 49,
      "z": 3,
      "name": "Rock_Volcanic_Brick"
    },
    {
      "x": -45,
      "y": 46,
      "z": 4,
      "name": "Rock_Volcanic_Brick"
    },
    {
      "x": -45,
      "y": 47,
      "z": 4,
      "name": "Rock_Volcanic_Brick"
    },
    {
      "x": -45,
      "y": 48,
      "z": 4,
      "name": "Rock_Volcanic_Brick"
    },
    {
      "x": -45,
      "y": 49,
      "z": 4,
      "name": "Rock_Volcanic_Brick"
    },
    {
      "x": -45,
      "y": 46,
      "z": 5,
      "name": "Rock_Volcanic_Brick"
    },
    {
      "x": -45,
      "y": 47,
      "z": 5,
      "name": "Rock_Volcanic_Brick"
    },
    {
      "x": -45,
      "y": 48,
      "z": 5,
      "name": "Rock_Volcanic_Brick"
    },
    {
      "x": -45,
      "y": 49,
      "z": 5,
      "name": "Rock_Volcanic_Brick"
    },
    {
      "x": -45,
      "y": 46,
      "z": 6,
      "name": "Rock_Volcanic_Brick"
    },
    {
      "x": -45,
      "y": 47,
      "z": 6,
      "name": "Rock_Volcanic_Brick"
    },
    {
      "x": -45,
      "y": 48,
      "z": 6,
      "name": "Rock_Volcanic_Brick"
    },
    {
      "x": -44,
      "y": 33,
      "z": -6,
      "name": "Rock_Volcanic_Brick"
    },
    {
      "x": -44,
      "y": 33,
      "z": -5,
      "name": "Rock_Volcanic_Brick"
    },
    {
      "x": -44,
      "y": 34,
      "z": -5,
      "name": "Rock_Volcanic_Brick"
    },
    {
      "x": -44,
      "y": 35,
      "z": -5,
      "name": "Rock_Volcanic_Brick"
    },
    {
      "x": -44,
      "y": 32,
      "z": -4,
      "name": "Rock_Volcanic_Brick"
    },
    {
      "x": -44,
      "y": 33,
      "z": -4,
      "name": "Rock_Volcanic_Brick"
    },
    {
      "x": -44,
      "y": 34,
      "z": -4,
      "name": "Rock_Volcanic_Brick"
    },
    {
      "x": -44,
      "y": 35,
      "z": -4,
      "name": "Rock_Volcanic_Brick"
    },
    {
      "x": -44,
      "y": 36,
      "z": -4,
      "name": "Rock_Volcanic_Brick"
    },
    {
      "x": -44,
      "y": 32,
      "z": -3,
      "name": "Rock_Volcanic_Brick"
    },
    {
      "x": -44,
      "y": 33,
      "z": -3,
      "name": "Rock_Volcanic_Brick"
    },
    {
      "x": -44,
      "y": 34,
      "z": -3,
      "name": "Rock_Volcanic_Brick"
    },
    {
      "x": -44,
      "y": 35,
      "z": -3,
      "name": "Rock_Volcanic_Brick"
    },
    {
      "x": -44,
      "y": 36,
      "z": -3,
      "name": "Rock_Volcanic_Brick"
    },
    {
      "x": -44,
      "y": 32,
      "z": -2,
      "name": "Rock_Volcanic_Brick"
    },
    {
      "x": -44,
      "y": 33,
      "z": -2,
      "name": "Rock_Volcanic_Brick"
    },
    {
      "x": -44,
      "y": 34,
      "z": -2,
      "name": "Rock_Volcanic_Brick"
    },
    {
      "x": -44,
      "y": 35,
      "z": -2,
      "name": "Rock_Volcanic_Brick"
    },
    {
      "x": -44,
      "y": 36,
      "z": -2,
      "name": "Rock_Volcanic_Brick"
    },
    {
      "x": -44,
      "y": 39,
      "z": -2,
      "name": "Rock_Volcanic_Brick"
    },
    {
      "x": -44,
      "y": 40,
      "z": -2,
      "name": "Rock_Volcanic_Brick"
    },
    {
      "x": -44,
      "y": 41,
      "z": -2,
      "name": "Rock_Volcanic_Brick"
    },
    {
      "x": -44,
      "y": 34,
      "z": -1,
      "name": "Rock_Volcanic_Brick"
    },
    {
      "x": -44,
      "y": 35,
      "z": -1,
      "name": "Rock_Volcanic_Brick"
    },
    {
      "x": -44,
      "y": 39,
      "z": -1,
      "name": "Rock_Volcanic_Brick"
    },
    {
      "x": -44,
      "y": 40,
      "z": -1,
      "name": "Rock_Volcanic_Brick"
    },
    {
      "x": -44,
      "y": 41,
      "z": -1,
      "name": "Rock_Volcanic_Brick"
    },
    {
      "x": -44,
      "y": 42,
      "z": -1,
      "name": "Rock_Volcanic_Brick"
    },
    {
      "x": -44,
      "y": 38,
      "z": 0,
      "name": "Rock_Volcanic_Brick"
    },
    {
      "x": -44,
      "y": 39,
      "z": 0,
      "name": "Rock_Volcanic_Brick"
    },
    {
      "x": -44,
      "y": 40,
      "z": 0,
      "name": "Rock_Volcanic_Brick"
    },
    {
      "x": -44,
      "y": 41,
      "z": 0,
      "name": "Rock_Volcanic_Brick"
    },
    {
      "x": -44,
      "y": 42,
      "z": 0,
      "name": "Rock_Volcanic_Brick"
    },
    {
      "x": -44,
      "y": 43,
      "z": 0,
      "name": "Rock_Volcanic_Brick"
    },
    {
      "x": -44,
      "y": 38,
      "z": 1,
      "name": "Rock_Volcanic_Brick"
    },
    {
      "x": -44,
      "y": 39,
      "z": 1,
      "name": "Rock_Volcanic_Brick"
    },
    {
      "x": -44,
      "y": 40,
      "z": 1,
      "name": "Rock_Volcanic_Brick"
    },
    {
      "x": -44,
      "y": 41,
      "z": 1,
      "name": "Rock_Volcanic_Brick"
    },
    {
      "x": -44,
      "y": 42,
      "z": 1,
      "name": "Rock_Volcanic_Brick"
    },
    {
      "x": -44,
      "y": 43,
      "z": 1,
      "name": "Rock_Volcanic_Brick"
    },
    {
      "x": -44,
      "y": 39,
      "z": 2,
      "name": "Rock_Volcanic_Brick"
    },
    {
      "x": -44,
      "y": 40,
      "z": 2,
      "name": "Rock_Volcanic_Brick"
    },
    {
      "x": -44,
      "y": 41,
      "z": 2,
      "name": "Rock_Volcanic_Brick"
    },
    {
      "x": -44,
      "y": 42,
      "z": 2,
      "name": "Rock_Volcanic_Brick"
    },
    {
      "x": -44,
      "y": 46,
      "z": 2,
      "name": "Rock_Volcanic_Brick"
    },
    {
      "x": -44,
      "y": 47,
      "z": 2,
      "name": "Rock_Volcanic_Brick"
    },
    {
      "x": -44,
      "y": 48,
      "z": 2,
      "name": "Rock_Volcanic_Brick"
    },
    {
      "x": -44,
      "y": 41,
      "z": 3,
      "name": "Rock_Volcanic_Brick"
    },
    {
      "x": -44,
      "y": 46,
      "z": 3,
      "name": "Rock_Volcanic_Brick"
    },
    {
      "x": -44,
      "y": 47,
      "z": 3,
      "name": "Rock_Volcanic_Brick"
    },
    {
      "x": -44,
      "y": 48,
      "z": 3,
      "name": "Rock_Volcanic_Brick"
    },
    {
      "x": -44,
      "y": 49,
      "z": 3,
      "name": "Rock_Volcanic_Brick"
    },
    {
      "x": -44,
      "y": 45,
      "z": 4,
      "name": "Rock_Volcanic_Brick"
    },
    {
      "x": -44,
      "y": 46,
      "z": 4,
      "name": "Rock_Volcanic_Brick"
    },
    {
      "x": -44,
      "y": 47,
      "z": 4,
      "name": "Rock_Volcanic_Brick"
    },
    {
      "x": -44,
      "y": 48,
      "z": 4,
      "name": "Rock_Volcanic_Brick"
    },
    {
      "x": -44,
      "y": 49,
      "z": 4,
      "name": "Rock_Volcanic_Brick"
    },
    {
      "x": -44,
      "y": 45,
      "z": 5,
      "name": "Rock_Volcanic_Brick"
    },
    {
      "x": -44,
      "y": 46,
      "z": 5,
      "name": "Rock_Volcanic_Brick"
    },
    {
      "x": -44,
      "y": 47,
      "z": 5,
      "name": "Rock_Volcanic_Brick"
    },
    {
      "x": -44,
      "y": 48,
      "z": 5,
      "name": "Rock_Volcanic_Brick"
    },
    {
      "x": -44,
      "y": 49,
      "z": 5,
      "name": "Rock_Volcanic_Brick"
    },
    {
      "x": -44,
      "y": 46,
      "z": 6,
      "name": "Rock_Volcanic_Brick"
    },
    {
      "x": -44,
      "y": 47,
      "z": 6,
      "name": "Rock_Volcanic_Brick"
    },
    {
      "x": -44,
      "y": 48,
      "z": 6,
      "name": "Rock_Volcanic_Brick"
    },
    {
      "x": -43,
      "y": 27,
      "z": -9,
      "name": "Rock_Volcanic_Brick"
    },
    {
      "x": -43,
      "y": 28,
      "z": -9,
      "name": "Rock_Volcanic_Brick"
    },
    {
      "x": -43,
      "y": 26,
      "z": -8,
      "name": "Rock_Volcanic_Brick"
    },
    {
      "x": -43,
      "y": 27,
      "z": -8,
      "name": "Rock_Volcanic_Brick"
    },
    {
      "x": -43,
      "y": 28,
      "z": -8,
      "name": "Rock_Volcanic_Brick"
    },
    {
      "x": -43,
      "y": 29,
      "z": -8,
      "name": "Rock_Volcanic_Brick"
    },
    {
      "x": -43,
      "y": 26,
      "z": -7,
      "name": "Rock_Volcanic_Brick"
    },
    {
      "x": -43,
      "y": 27,
      "z": -7,
      "name": "Rock_Volcanic_Brick"
    },
    {
      "x": -43,
      "y": 28,
      "z": -7,
      "name": "Rock_Volcanic_Brick"
    },
    {
      "x": -43,
      "y": 29,
      "z": -7,
      "name": "Rock_Volcanic_Brick"
    },
    {
      "x": -43,
      "y": 26,
      "z": -6,
      "name": "Rock_Volcanic_Brick"
    },
    {
      "x": -43,
      "y": 27,
      "z": -6,
      "name": "Rock_Volcanic_Brick"
    },
    {
      "x": -43,
      "y": 28,
      "z": -6,
      "name": "Rock_Volcanic_Brick"
    },
    {
      "x": -43,
      "y": 29,
      "z": -6,
      "name": "Rock_Volcanic_Brick"
    },
    {
      "x": -43,
      "y": 33,
      "z": -6,
      "name": "Rock_Volcanic_Brick"
    },
    {
      "x": -43,
      "y": 34,
      "z": -6,
      "name": "Rock_Volcanic_Brick"
    },
    {
      "x": -43,
      "y": 27,
      "z": -5,
      "name": "Rock_Volcanic_Brick"
    },
    {
      "x": -43,
      "y": 28,
      "z": -5,
      "name": "Rock_Volcanic_Brick"
    },
    {
      "x": -43,
      "y": 32,
      "z": -5,
      "name": "Rock_Volcanic_Brick"
    },
    {
      "x": -43,
      "y": 33,
      "z": -5,
      "name": "Rock_Volcanic_Brick"
    },
    {
      "x": -43,
      "y": 34,
      "z": -5,
      "name": "Rock_Volcanic_Brick"
    },
    {
      "x": -43,
      "y": 35,
      "z": -5,
      "name": "Rock_Volcanic_Brick"
    },
    {
      "x": -43,
      "y": 32,
      "z": -4,
      "name": "Rock_Volcanic_Brick"
    },
    {
      "x": -43,
      "y": 33,
      "z": -4,
      "name": "Rock_Volcanic_Brick"
    },
    {
      "x": -43,
      "y": 34,
      "z": -4,
      "name": "Rock_Volcanic_Brick"
    },
    {
      "x": -43,
      "y": 35,
      "z": -4,
      "name": "Rock_Volcanic_Brick"
    },
    {
      "x": -43,
      "y": 36,
      "z": -4,
      "name": "Rock_Volcanic_Brick"
    },
    {
      "x": -43,
      "y": 31,
      "z": -3,
      "name": "Rock_Volcanic_Brick"
    },
    {
      "x": -43,
      "y": 32,
      "z": -3,
      "name": "Rock_Volcanic_Brick"
    },
    {
      "x": -43,
      "y": 33,
      "z": -3,
      "name": "Rock_Volcanic_Brick"
    },
    {
      "x": -43,
      "y": 34,
      "z": -3,
      "name": "Rock_Volcanic_Brick"
    },
    {
      "x": -43,
      "y": 35,
      "z": -3,
      "name": "Rock_Volcanic_Brick"
    },
    {
      "x": -43,
      "y": 36,
      "z": -3,
      "name": "Rock_Volcanic_Brick"
    },
    {
      "x": -43,
      "y": 37,
      "z": -3,
      "name": "Rock_Volcanic_Brick"
    },
    {
      "x": -43,
      "y": 32,
      "z": -2,
      "name": "Rock_Volcanic_Brick"
    },
    {
      "x": -43,
      "y": 33,
      "z": -2,
      "name": "Rock_Volcanic_Brick"
    },
    {
      "x": -43,
      "y": 34,
      "z": -2,
      "name": "Rock_Volcanic_Brick"
    },
    {
      "x": -43,
      "y": 35,
      "z": -2,
      "name": "Rock_Volcanic_Brick"
    },
    {
      "x": -43,
      "y": 36,
      "z": -2,
      "name": "Rock_Volcanic_Brick"
    },
    {
      "x": -43,
      "y": 39,
      "z": -2,
      "name": "Rock_Volcanic_Brick"
    },
    {
      "x": -43,
      "y": 40,
      "z": -2,
      "name": "Rock_Volcanic_Brick"
    },
    {
      "x": -43,
      "y": 41,
      "z": -2,
      "name": "Rock_Volcanic_Brick"
    },
    {
      "x": -43,
      "y": 34,
      "z": -1,
      "name": "Rock_Volcanic_Brick"
    },
    {
      "x": -43,
      "y": 35,
      "z": -1,
      "name": "Rock_Volcanic_Brick"
    },
    {
      "x": -43,
      "y": 36,
      "z": -1,
      "name": "Rock_Volcanic_Brick"
    },
    {
      "x": -43,
      "y": 38,
      "z": -1,
      "name": "Rock_Volcanic_Brick"
    },
    {
      "x": -43,
      "y": 39,
      "z": -1,
      "name": "Rock_Volcanic_Brick"
    },
    {
      "x": -43,
      "y": 40,
      "z": -1,
      "name": "Rock_Volcanic_Brick"
    },
    {
      "x": -43,
      "y": 41,
      "z": -1,
      "name": "Rock_Volcanic_Brick"
    },
    {
      "x": -43,
      "y": 42,
      "z": -1,
      "name": "Rock_Volcanic_Brick"
    },
    {
      "x": -43,
      "y": 38,
      "z": 0,
      "name": "Rock_Volcanic_Brick"
    },
    {
      "x": -43,
      "y": 39,
      "z": 0,
      "name": "Rock_Volcanic_Brick"
    },
    {
      "x": -43,
      "y": 40,
      "z": 0,
      "name": "Rock_Volcanic_Brick"
    },
    {
      "x": -43,
      "y": 41,
      "z": 0,
      "name": "Rock_Volcanic_Brick"
    },
    {
      "x": -43,
      "y": 42,
      "z": 0,
      "name": "Rock_Volcanic_Brick"
    },
    {
      "x": -43,
      "y": 43,
      "z": 0,
      "name": "Rock_Volcanic_Brick"
    },
    {
      "x": -43,
      "y": 38,
      "z": 1,
      "name": "Rock_Volcanic_Brick"
    },
    {
      "x": -43,
      "y": 39,
      "z": 1,
      "name": "Rock_Volcanic_Brick"
    },
    {
      "x": -43,
      "y": 40,
      "z": 1,
      "name": "Rock_Volcanic_Brick"
    },
    {
      "x": -43,
      "y": 41,
      "z": 1,
      "name": "Rock_Volcanic_Brick"
    },
    {
      "x": -43,
      "y": 42,
      "z": 1,
      "name": "Rock_Volcanic_Brick"
    },
    {
      "x": -43,
      "y": 43,
      "z": 1,
      "name": "Rock_Volcanic_Brick"
    },
    {
      "x": -43,
      "y": 39,
      "z": 2,
      "name": "Rock_Volcanic_Brick"
    },
    {
      "x": -43,
      "y": 40,
      "z": 2,
      "name": "Rock_Volcanic_Brick"
    },
    {
      "x": -43,
      "y": 41,
      "z": 2,
      "name": "Rock_Volcanic_Brick"
    },
    {
      "x": -43,
      "y": 42,
      "z": 2,
      "name": "Rock_Volcanic_Brick"
    },
    {
      "x": -43,
      "y": 43,
      "z": 2,
      "name": "Rock_Volcanic_Brick"
    },
    {
      "x": -43,
      "y": 45,
      "z": 2,
      "name": "Rock_Volcanic_Brick"
    },
    {
      "x": -43,
      "y": 46,
      "z": 2,
      "name": "Rock_Volcanic_Brick"
    },
    {
      "x": -43,
      "y": 47,
      "z": 2,
      "name": "Rock_Volcanic_Brick"
    },
    {
      "x": -43,
      "y": 48,
      "z": 2,
      "name": "Rock_Volcanic_Brick"
    },
    {
      "x": -43,
      "y": 41,
      "z": 3,
      "name": "Rock_Volcanic_Brick"
    },
    {
      "x": -43,
      "y": 42,
      "z": 3,
      "name": "Rock_Volcanic_Brick"
    },
    {
      "x": -43,
      "y": 45,
      "z": 3,
      "name": "Rock_Volcanic_Brick"
    },
    {
      "x": -43,
      "y": 46,
      "z": 3,
      "name": "Rock_Volcanic_Brick"
    },
    {
      "x": -43,
      "y": 47,
      "z": 3,
      "name": "Rock_Volcanic_Brick"
    },
    {
      "x": -43,
      "y": 48,
      "z": 3,
      "name": "Rock_Volcanic_Brick"
    },
    {
      "x": -43,
      "y": 49,
      "z": 3,
      "name": "Rock_Volcanic_Brick"
    },
    {
      "x": -43,
      "y": 44,
      "z": 4,
      "name": "Rock_Volcanic_Brick"
    },
    {
      "x": -43,
      "y": 45,
      "z": 4,
      "name": "Rock_Volcanic_Brick"
    },
    {
      "x": -43,
      "y": 46,
      "z": 4,
      "name": "Rock_Volcanic_Brick"
    },
    {
      "x": -43,
      "y": 47,
      "z": 4,
      "name": "Rock_Volcanic_Brick"
    },
    {
      "x": -43,
      "y": 48,
      "z": 4,
      "name": "Rock_Volcanic_Brick"
    },
    {
      "x": -43,
      "y": 49,
      "z": 4,
      "name": "Rock_Volcanic_Brick"
    },
    {
      "x": -43,
      "y": 45,
      "z": 5,
      "name": "Rock_Volcanic_Brick"
    },
    {
      "x": -43,
      "y": 46,
      "z": 5,
      "name": "Rock_Volcanic_Brick"
    },
    {
      "x": -43,
      "y": 47,
      "z": 5,
      "name": "Rock_Volcanic_Brick"
    },
    {
      "x": -43,
      "y": 48,
      "z": 5,
      "name": "Rock_Volcanic_Brick"
    },
    {
      "x": -43,
      "y": 49,
      "z": 5,
      "name": "Rock_Volcanic_Brick"
    },
    {
      "x": -43,
      "y": 46,
      "z": 6,
      "name": "Rock_Volcanic_Brick"
    },
    {
      "x": -43,
      "y": 47,
      "z": 6,
      "name": "Rock_Volcanic_Brick"
    },
    {
      "x": -43,
      "y": 48,
      "z": 6,
      "name": "Rock_Volcanic_Brick"
    },
    {
      "x": -43,
      "y": 49,
      "z": 6,
      "name": "Rock_Volcanic_Brick"
    },
    {
      "x": -43,
      "y": 53,
      "z": 6,
      "name": "Rock_Volcanic_Brick"
    },
    {
      "x": -43,
      "y": 54,
      "z": 6,
      "name": "Rock_Volcanic_Brick"
    },
    {
      "x": -43,
      "y": 48,
      "z": 7,
      "name": "Rock_Volcanic_Brick"
    },
    {
      "x": -43,
      "y": 53,
      "z": 7,
      "name": "Rock_Volcanic_Brick"
    },
    {
      "x": -43,
      "y": 54,
      "z": 7,
      "name": "Rock_Volcanic_Brick"
    },
    {
      "x": -43,
      "y": 55,
      "z": 7,
      "name": "Rock_Volcanic_Brick"
    },
    {
      "x": -43,
      "y": 52,
      "z": 8,
      "name": "Rock_Volcanic_Brick"
    },
    {
      "x": -43,
      "y": 53,
      "z": 8,
      "name": "Rock_Volcanic_Brick"
    },
    {
      "x": -43,
      "y": 54,
      "z": 8,
      "name": "Rock_Volcanic_Brick"
    },
    {
      "x": -43,
      "y": 55,
      "z": 8,
      "name": "Rock_Volcanic_Brick"
    },
    {
      "x": -43,
      "y": 52,
      "z": 9,
      "name": "Rock_Volcanic_Brick"
    },
    {
      "x": -43,
      "y": 53,
      "z": 9,
      "name": "Rock_Volcanic_Brick"
    },
    {
      "x": -43,
      "y": 54,
      "z": 9,
      "name": "Rock_Volcanic_Brick"
    },
    {
      "x": -43,
      "y": 55,
      "z": 9,
      "name": "Rock_Volcanic_Brick"
    },
    {
      "x": -43,
      "y": 53,
      "z": 10,
      "name": "Rock_Volcanic_Brick"
    },
    {
      "x": -43,
      "y": 54,
      "z": 10,
      "name": "Rock_Volcanic_Brick"
    },
    {
      "x": -42,
      "y": 26,
      "z": -9,
      "name": "Rock_Volcanic_Brick"
    },
    {
      "x": -42,
      "y": 27,
      "z": -9,
      "name": "Rock_Volcanic_Brick"
    },
    {
      "x": -42,
      "y": 28,
      "z": -9,
      "name": "Rock_Volcanic_Brick"
    },
    {
      "x": -42,
      "y": 26,
      "z": -8,
      "name": "Rock_Volcanic_Brick"
    },
    {
      "x": -42,
      "y": 27,
      "z": -8,
      "name": "Rock_Volcanic_Brick"
    },
    {
      "x": -42,
      "y": 28,
      "z": -8,
      "name": "Rock_Volcanic_Brick"
    },
    {
      "x": -42,
      "y": 29,
      "z": -8,
      "name": "Rock_Volcanic_Brick"
    },
    {
      "x": -42,
      "y": 30,
      "z": -8,
      "name": "Rock_Volcanic_Brick"
    },
    {
      "x": -42,
      "y": 25,
      "z": -7,
      "name": "Rock_Volcanic_Brick"
    },
    {
      "x": -42,
      "y": 26,
      "z": -7,
      "name": "Rock_Volcanic_Brick"
    },
    {
      "x": -42,
      "y": 27,
      "z": -7,
      "name": "Rock_Volcanic_Brick"
    },
    {
      "x": -42,
      "y": 28,
      "z": -7,
      "name": "Rock_Volcanic_Brick"
    },
    {
      "x": -42,
      "y": 29,
      "z": -7,
      "name": "Rock_Volcanic_Brick"
    },
    {
      "x": -42,
      "y": 30,
      "z": -7,
      "name": "Rock_Volcanic_Brick"
    },
    {
      "x": -42,
      "y": 26,
      "z": -6,
      "name": "Rock_Volcanic_Brick"
    },
    {
      "x": -42,
      "y": 27,
      "z": -6,
      "name": "Rock_Volcanic_Brick"
    },
    {
      "x": -42,
      "y": 28,
      "z": -6,
      "name": "Rock_Volcanic_Brick"
    },
    {
      "x": -42,
      "y": 29,
      "z": -6,
      "name": "Rock_Volcanic_Brick"
    },
    {
      "x": -42,
      "y": 30,
      "z": -6,
      "name": "Rock_Volcanic_Brick"
    },
    {
      "x": -42,
      "y": 33,
      "z": -6,
      "name": "Rock_Volcanic_Brick"
    },
    {
      "x": -42,
      "y": 34,
      "z": -6,
      "name": "Rock_Volcanic_Brick"
    },
    {
      "x": -42,
      "y": 27,
      "z": -5,
      "name": "Rock_Volcanic_Brick"
    },
    {
      "x": -42,
      "y": 28,
      "z": -5,
      "name": "Rock_Volcanic_Brick"
    },
    {
      "x": -42,
      "y": 29,
      "z": -5,
      "name": "Rock_Volcanic_Brick"
    },
    {
      "x": -42,
      "y": 32,
      "z": -5,
      "name": "Rock_Volcanic_Brick"
    },
    {
      "x": -42,
      "y": 33,
      "z": -5,
      "name": "Rock_Volcanic_Brick"
    },
    {
      "x": -42,
      "y": 34,
      "z": -5,
      "name": "Rock_Volcanic_Brick"
    },
    {
      "x": -42,
      "y": 35,
      "z": -5,
      "name": "Rock_Volcanic_Brick"
    },
    {
      "x": -42,
      "y": 32,
      "z": -4,
      "name": "Rock_Volcanic_Brick"
    },
    {
      "x": -42,
      "y": 33,
      "z": -4,
      "name": "Rock_Volcanic_Brick"
    },
    {
      "x": -42,
      "y": 34,
      "z": -4,
      "name": "Rock_Volcanic_Brick"
    },
    {
      "x": -42,
      "y": 35,
      "z": -4,
      "name": "Rock_Volcanic_Brick"
    },
    {
      "x": -42,
      "y": 36,
      "z": -4,
      "name": "Rock_Volcanic_Brick"
    },
    {
      "x": -42,
      "y": 37,
      "z": -4,
      "name": "Rock_Volcanic_Brick"
    },
    {
      "x": -42,
      "y": 31,
      "z": -3,
      "name": "Rock_Volcanic_Brick"
    },
    {
      "x": -42,
      "y": 32,
      "z": -3,
      "name": "Rock_Volcanic_Brick"
    },
    {
      "x": -42,
      "y": 33,
      "z": -3,
      "name": "Rock_Volcanic_Brick"
    },
    {
      "x": -42,
      "y": 34,
      "z": -3,
      "name": "Rock_Volcanic_Brick"
    },
    {
      "x": -42,
      "y": 35,
      "z": -3,
      "name": "Rock_Volcanic_Brick"
    },
    {
      "x": -42,
      "y": 36,
      "z": -3,
      "name": "Rock_Volcanic_Brick"
    },
    {
      "x": -42,
      "y": 37,
      "z": -3,
      "name": "Rock_Volcanic_Brick"
    },
    {
      "x": -42,
      "y": 32,
      "z": -2,
      "name": "Rock_Volcanic_Brick"
    },
    {
      "x": -42,
      "y": 33,
      "z": -2,
      "name": "Rock_Volcanic_Brick"
    },
    {
      "x": -42,
      "y": 34,
      "z": -2,
      "name": "Rock_Volcanic_Brick"
    },
    {
      "x": -42,
      "y": 35,
      "z": -2,
      "name": "Rock_Volcanic_Brick"
    },
    {
      "x": -42,
      "y": 36,
      "z": -2,
      "name": "Rock_Volcanic_Brick"
    },
    {
      "x": -42,
      "y": 37,
      "z": -2,
      "name": "Rock_Volcanic_Brick"
    },
    {
      "x": -42,
      "y": 39,
      "z": -2,
      "name": "Rock_Volcanic_Brick"
    },
    {
      "x": -42,
      "y": 40,
      "z": -2,
      "name": "Rock_Volcanic_Brick"
    },
    {
      "x": -42,
      "y": 41,
      "z": -2,
      "name": "Rock_Volcanic_Brick"
    },
    {
      "x": -42,
      "y": 34,
      "z": -1,
      "name": "Rock_Volcanic_Brick"
    },
    {
      "x": -42,
      "y": 35,
      "z": -1,
      "name": "Rock_Volcanic_Brick"
    },
    {
      "x": -42,
      "y": 36,
      "z": -1,
      "name": "Rock_Volcanic_Brick"
    },
    {
      "x": -42,
      "y": 38,
      "z": -1,
      "name": "Rock_Volcanic_Brick"
    },
    {
      "x": -42,
      "y": 39,
      "z": -1,
      "name": "Rock_Volcanic_Brick"
    },
    {
      "x": -42,
      "y": 40,
      "z": -1,
      "name": "Rock_Volcanic_Brick"
    },
    {
      "x": -42,
      "y": 41,
      "z": -1,
      "name": "Rock_Volcanic_Brick"
    },
    {
      "x": -42,
      "y": 42,
      "z": -1,
      "name": "Rock_Volcanic_Brick"
    },
    {
      "x": -42,
      "y": 38,
      "z": 0,
      "name": "Rock_Volcanic_Brick"
    },
    {
      "x": -42,
      "y": 39,
      "z": 0,
      "name": "Rock_Volcanic_Brick"
    },
    {
      "x": -42,
      "y": 40,
      "z": 0,
      "name": "Rock_Volcanic_Brick"
    },
    {
      "x": -42,
      "y": 41,
      "z": 0,
      "name": "Rock_Volcanic_Brick"
    },
    {
      "x": -42,
      "y": 42,
      "z": 0,
      "name": "Rock_Volcanic_Brick"
    },
    {
      "x": -42,
      "y": 43,
      "z": 0,
      "name": "Rock_Volcanic_Brick"
    },
    {
      "x": -42,
      "y": 44,
      "z": 0,
      "name": "Rock_Volcanic_Brick"
    },
    {
      "x": -42,
      "y": 38,
      "z": 1,
      "name": "Rock_Volcanic_Brick"
    },
    {
      "x": -42,
      "y": 39,
      "z": 1,
      "name": "Rock_Volcanic_Brick"
    },
    {
      "x": -42,
      "y": 40,
      "z": 1,
      "name": "Rock_Volcanic_Brick"
    },
    {
      "x": -42,
      "y": 41,
      "z": 1,
      "name": "Rock_Volcanic_Brick"
    },
    {
      "x": -42,
      "y": 42,
      "z": 1,
      "name": "Rock_Volcanic_Brick"
    },
    {
      "x": -42,
      "y": 43,
      "z": 1,
      "name": "Rock_Volcanic_Brick"
    },
    {
      "x": -42,
      "y": 44,
      "z": 1,
      "name": "Rock_Volcanic_Brick"
    },
    {
      "x": -42,
      "y": 46,
      "z": 1,
      "name": "Rock_Volcanic_Brick"
    },
    {
      "x": -42,
      "y": 39,
      "z": 2,
      "name": "Rock_Volcanic_Brick"
    },
    {
      "x": -42,
      "y": 40,
      "z": 2,
      "name": "Rock_Volcanic_Brick"
    },
    {
      "x": -42,
      "y": 41,
      "z": 2,
      "name": "Rock_Volcanic_Brick"
    },
    {
      "x": -42,
      "y": 42,
      "z": 2,
      "name": "Rock_Volcanic_Brick"
    },
    {
      "x": -42,
      "y": 43,
      "z": 2,
      "name": "Rock_Volcanic_Brick"
    },
    {
      "x": -42,
      "y": 45,
      "z": 2,
      "name": "Rock_Volcanic_Brick"
    },
    {
      "x": -42,
      "y": 46,
      "z": 2,
      "name": "Rock_Volcanic_Brick"
    },
    {
      "x": -42,
      "y": 47,
      "z": 2,
      "name": "Rock_Volcanic_Brick"
    },
    {
      "x": -42,
      "y": 48,
      "z": 2,
      "name": "Rock_Volcanic_Brick"
    },
    {
      "x": -42,
      "y": 41,
      "z": 3,
      "name": "Rock_Volcanic_Brick"
    },
    {
      "x": -42,
      "y": 42,
      "z": 3,
      "name": "Rock_Volcanic_Brick"
    },
    {
      "x": -42,
      "y": 44,
      "z": 3,
      "name": "Rock_Volcanic_Brick"
    },
    {
      "x": -42,
      "y": 45,
      "z": 3,
      "name": "Rock_Volcanic_Brick"
    },
    {
      "x": -42,
      "y": 46,
      "z": 3,
      "name": "Rock_Volcanic_Brick"
    },
    {
      "x": -42,
      "y": 47,
      "z": 3,
      "name": "Rock_Volcanic_Brick"
    },
    {
      "x": -42,
      "y": 48,
      "z": 3,
      "name": "Rock_Volcanic_Brick"
    },
    {
      "x": -42,
      "y": 49,
      "z": 3,
      "name": "Rock_Volcanic_Brick"
    },
    {
      "x": -42,
      "y": 44,
      "z": 4,
      "name": "Rock_Volcanic_Brick"
    },
    {
      "x": -42,
      "y": 45,
      "z": 4,
      "name": "Rock_Volcanic_Brick"
    },
    {
      "x": -42,
      "y": 46,
      "z": 4,
      "name": "Rock_Volcanic_Brick"
    },
    {
      "x": -42,
      "y": 47,
      "z": 4,
      "name": "Rock_Volcanic_Brick"
    },
    {
      "x": -42,
      "y": 48,
      "z": 4,
      "name": "Rock_Volcanic_Brick"
    },
    {
      "x": -42,
      "y": 49,
      "z": 4,
      "name": "Rock_Volcanic_Brick"
    },
    {
      "x": -42,
      "y": 50,
      "z": 4,
      "name": "Rock_Volcanic_Brick"
    },
    {
      "x": -42,
      "y": 44,
      "z": 5,
      "name": "Rock_Volcanic_Brick"
    },
    {
      "x": -42,
      "y": 45,
      "z": 5,
      "name": "Rock_Volcanic_Brick"
    },
    {
      "x": -42,
      "y": 46,
      "z": 5,
      "name": "Rock_Volcanic_Brick"
    },
    {
      "x": -42,
      "y": 47,
      "z": 5,
      "name": "Rock_Volcanic_Brick"
    },
    {
      "x": -42,
      "y": 48,
      "z": 5,
      "name": "Rock_Volcanic_Brick"
    },
    {
      "x": -42,
      "y": 49,
      "z": 5,
      "name": "Rock_Volcanic_Brick"
    },
    {
      "x": -42,
      "y": 50,
      "z": 5,
      "name": "Rock_Volcanic_Brick"
    },
    {
      "x": -42,
      "y": 46,
      "z": 6,
      "name": "Rock_Volcanic_Brick"
    },
    {
      "x": -42,
      "y": 47,
      "z": 6,
      "name": "Rock_Volcanic_Brick"
    },
    {
      "x": -42,
      "y": 48,
      "z": 6,
      "name": "Rock_Volcanic_Brick"
    },
    {
      "x": -42,
      "y": 49,
      "z": 6,
      "name": "Rock_Volcanic_Brick"
    },
    {
      "x": -42,
      "y": 52,
      "z": 6,
      "name": "Rock_Volcanic_Brick"
    },
    {
      "x": -42,
      "y": 53,
      "z": 6,
      "name": "Rock_Volcanic_Brick"
    },
    {
      "x": -42,
      "y": 54,
      "z": 6,
      "name": "Rock_Volcanic_Brick"
    },
    {
      "x": -42,
      "y": 48,
      "z": 7,
      "name": "Rock_Volcanic_Brick"
    },
    {
      "x": -42,
      "y": 52,
      "z": 7,
      "name": "Rock_Volcanic_Brick"
    },
    {
      "x": -42,
      "y": 53,
      "z": 7,
      "name": "Rock_Volcanic_Brick"
    },
    {
      "x": -42,
      "y": 54,
      "z": 7,
      "name": "Rock_Volcanic_Brick"
    },
    {
      "x": -42,
      "y": 55,
      "z": 7,
      "name": "Rock_Volcanic_Brick"
    },
    {
      "x": -42,
      "y": 56,
      "z": 7,
      "name": "Rock_Volcanic_Brick"
    },
    {
      "x": -42,
      "y": 51,
      "z": 8,
      "name": "Rock_Volcanic_Brick"
    },
    {
      "x": -42,
      "y": 52,
      "z": 8,
      "name": "Rock_Volcanic_Brick"
    },
    {
      "x": -42,
      "y": 53,
      "z": 8,
      "name": "Rock_Volcanic_Brick"
    },
    {
      "x": -42,
      "y": 54,
      "z": 8,
      "name": "Rock_Volcanic_Brick"
    },
    {
      "x": -42,
      "y": 55,
      "z": 8,
      "name": "Rock_Volcanic_Brick"
    },
    {
      "x": -42,
      "y": 56,
      "z": 8,
      "name": "Rock_Volcanic_Brick"
    },
    {
      "x": -42,
      "y": 52,
      "z": 9,
      "name": "Rock_Volcanic_Brick"
    },
    {
      "x": -42,
      "y": 53,
      "z": 9,
      "name": "Rock_Volcanic_Brick"
    },
    {
      "x": -42,
      "y": 54,
      "z": 9,
      "name": "Rock_Volcanic_Brick"
    },
    {
      "x": -42,
      "y": 55,
      "z": 9,
      "name": "Rock_Volcanic_Brick"
    },
    {
      "x": -42,
      "y": 53,
      "z": 10,
      "name": "Rock_Volcanic_Brick"
    },
    {
      "x": -42,
      "y": 54,
      "z": 10,
      "name": "Rock_Volcanic_Brick"
    },
    {
      "x": -42,
      "y": 55,
      "z": 10,
      "name": "Rock_Volcanic_Brick"
    },
    {
      "x": -41,
      "y": 26,
      "z": -9,
      "name": "Rock_Volcanic_Brick"
    },
    {
      "x": -41,
      "y": 27,
      "z": -9,
      "name": "Rock_Volcanic_Brick"
    },
    {
      "x": -41,
      "y": 28,
      "z": -9,
      "name": "Rock_Volcanic_Brick"
    },
    {
      "x": -41,
      "y": 26,
      "z": -8,
      "name": "Rock_Volcanic_Brick"
    },
    {
      "x": -41,
      "y": 27,
      "z": -8,
      "name": "Rock_Volcanic_Brick"
    },
    {
      "x": -41,
      "y": 28,
      "z": -8,
      "name": "Rock_Volcanic_Brick"
    },
    {
      "x": -41,
      "y": 29,
      "z": -8,
      "name": "Rock_Volcanic_Brick"
    },
    {
      "x": -41,
      "y": 30,
      "z": -8,
      "name": "Rock_Volcanic_Brick"
    },
    {
      "x": -41,
      "y": 25,
      "z": -7,
      "name": "Rock_Volcanic_Brick"
    },
    {
      "x": -41,
      "y": 26,
      "z": -7,
      "name": "Rock_Volcanic_Brick"
    },
    {
      "x": -41,
      "y": 27,
      "z": -7,
      "name": "Rock_Volcanic_Brick"
    },
    {
      "x": -41,
      "y": 28,
      "z": -7,
      "name": "Rock_Volcanic_Brick"
    },
    {
      "x": -41,
      "y": 29,
      "z": -7,
      "name": "Rock_Volcanic_Brick"
    },
    {
      "x": -41,
      "y": 30,
      "z": -7,
      "name": "Rock_Volcanic_Brick"
    },
    {
      "x": -41,
      "y": 31,
      "z": -7,
      "name": "Rock_Volcanic_Brick"
    },
    {
      "x": -41,
      "y": 26,
      "z": -6,
      "name": "Rock_Volcanic_Brick"
    },
    {
      "x": -41,
      "y": 27,
      "z": -6,
      "name": "Rock_Volcanic_Brick"
    },
    {
      "x": -41,
      "y": 28,
      "z": -6,
      "name": "Rock_Volcanic_Brick"
    },
    {
      "x": -41,
      "y": 29,
      "z": -6,
      "name": "Rock_Volcanic_Brick"
    },
    {
      "x": -41,
      "y": 30,
      "z": -6,
      "name": "Rock_Volcanic_Brick"
    },
    {
      "x": -41,
      "y": 31,
      "z": -6,
      "name": "Rock_Volcanic_Brick"
    },
    {
      "x": -41,
      "y": 33,
      "z": -6,
      "name": "Rock_Volcanic_Brick"
    },
    {
      "x": -41,
      "y": 34,
      "z": -6,
      "name": "Rock_Volcanic_Brick"
    },
    {
      "x": -41,
      "y": 27,
      "z": -5,
      "name": "Rock_Volcanic_Brick"
    },
    {
      "x": -41,
      "y": 28,
      "z": -5,
      "name": "Rock_Volcanic_Brick"
    },
    {
      "x": -41,
      "y": 29,
      "z": -5,
      "name": "Rock_Volcanic_Brick"
    },
    {
      "x": -41,
      "y": 30,
      "z": -5,
      "name": "Rock_Volcanic_Brick"
    },
    {
      "x": -41,
      "y": 32,
      "z": -5,
      "name": "Rock_Volcanic_Brick"
    },
    {
      "x": -41,
      "y": 33,
      "z": -5,
      "name": "Rock_Volcanic_Brick"
    },
    {
      "x": -41,
      "y": 34,
      "z": -5,
      "name": "Rock_Volcanic_Brick"
    },
    {
      "x": -41,
      "y": 35,
      "z": -5,
      "name": "Rock_Volcanic_Brick"
    },
    {
      "x": -41,
      "y": 29,
      "z": -4,
      "name": "Rock_Volcanic_Brick"
    },
    {
      "x": -41,
      "y": 32,
      "z": -4,
      "name": "Rock_Volcanic_Brick"
    },
    {
      "x": -41,
      "y": 33,
      "z": -4,
      "name": "Rock_Volcanic_Brick"
    },
    {
      "x": -41,
      "y": 34,
      "z": -4,
      "name": "Rock_Volcanic_Brick"
    },
    {
      "x": -41,
      "y": 35,
      "z": -4,
      "name": "Rock_Volcanic_Brick"
    },
    {
      "x": -41,
      "y": 36,
      "z": -4,
      "name": "Rock_Volcanic_Brick"
    },
    {
      "x": -41,
      "y": 37,
      "z": -4,
      "name": "Rock_Volcanic_Brick"
    },
    {
      "x": -41,
      "y": 31,
      "z": -3,
      "name": "Rock_Volcanic_Brick"
    },
    {
      "x": -41,
      "y": 32,
      "z": -3,
      "name": "Rock_Volcanic_Brick"
    },
    {
      "x": -41,
      "y": 33,
      "z": -3,
      "name": "Rock_Volcanic_Brick"
    },
    {
      "x": -41,
      "y": 34,
      "z": -3,
      "name": "Rock_Volcanic_Brick"
    },
    {
      "x": -41,
      "y": 35,
      "z": -3,
      "name": "Rock_Volcanic_Brick"
    },
    {
      "x": -41,
      "y": 36,
      "z": -3,
      "name": "Rock_Volcanic_Brick"
    },
    {
      "x": -41,
      "y": 37,
      "z": -3,
      "name": "Rock_Volcanic_Brick"
    },
    {
      "x": -41,
      "y": 38,
      "z": -3,
      "name": "Rock_Volcanic_Brick"
    },
    {
      "x": -41,
      "y": 39,
      "z": -3,
      "name": "Rock_Volcanic_Brick"
    },
    {
      "x": -41,
      "y": 32,
      "z": -2,
      "name": "Rock_Volcanic_Brick"
    },
    {
      "x": -41,
      "y": 33,
      "z": -2,
      "name": "Rock_Volcanic_Brick"
    },
    {
      "x": -41,
      "y": 34,
      "z": -2,
      "name": "Rock_Volcanic_Brick"
    },
    {
      "x": -41,
      "y": 35,
      "z": -2,
      "name": "Rock_Volcanic_Brick"
    },
    {
      "x": -41,
      "y": 36,
      "z": -2,
      "name": "Rock_Volcanic_Brick"
    },
    {
      "x": -41,
      "y": 37,
      "z": -2,
      "name": "Rock_Volcanic_Brick"
    },
    {
      "x": -41,
      "y": 38,
      "z": -2,
      "name": "Rock_Volcanic_Brick"
    },
    {
      "x": -41,
      "y": 39,
      "z": -2,
      "name": "Rock_Volcanic_Brick"
    },
    {
      "x": -41,
      "y": 40,
      "z": -2,
      "name": "Rock_Volcanic_Brick"
    },
    {
      "x": -41,
      "y": 41,
      "z": -2,
      "name": "Rock_Volcanic_Brick"
    },
    {
      "x": -41,
      "y": 34,
      "z": -1,
      "name": "Rock_Volcanic_Brick"
    },
    {
      "x": -41,
      "y": 35,
      "z": -1,
      "name": "Rock_Volcanic_Brick"
    },
    {
      "x": -41,
      "y": 36,
      "z": -1,
      "name": "Rock_Volcanic_Brick"
    },
    {
      "x": -41,
      "y": 37,
      "z": -1,
      "name": "Rock_Volcanic_Brick"
    },
    {
      "x": -41,
      "y": 38,
      "z": -1,
      "name": "Rock_Volcanic_Brick"
    },
    {
      "x": -41,
      "y": 39,
      "z": -1,
      "name": "Rock_Volcanic_Brick"
    },
    {
      "x": -41,
      "y": 40,
      "z": -1,
      "name": "Rock_Volcanic_Brick"
    },
    {
      "x": -41,
      "y": 41,
      "z": -1,
      "name": "Rock_Volcanic_Brick"
    },
    {
      "x": -41,
      "y": 42,
      "z": -1,
      "name": "Rock_Volcanic_Brick"
    },
    {
      "x": -41,
      "y": 36,
      "z": 0,
      "name": "Rock_Volcanic_Brick"
    },
    {
      "x": -41,
      "y": 37,
      "z": 0,
      "name": "Rock_Volcanic_Brick"
    },
    {
      "x": -41,
      "y": 38,
      "z": 0,
      "name": "Rock_Volcanic_Brick"
    },
    {
      "x": -41,
      "y": 39,
      "z": 0,
      "name": "Rock_Volcanic_Brick"
    },
    {
      "x": -41,
      "y": 40,
      "z": 0,
      "name": "Rock_Volcanic_Brick"
    },
    {
      "x": -41,
      "y": 41,
      "z": 0,
      "name": "Rock_Volcanic_Brick"
    },
    {
      "x": -41,
      "y": 42,
      "z": 0,
      "name": "Rock_Volcanic_Brick"
    },
    {
      "x": -41,
      "y": 43,
      "z": 0,
      "name": "Rock_Volcanic_Brick"
    },
    {
      "x": -41,
      "y": 44,
      "z": 0,
      "name": "Rock_Volcanic_Brick"
    },
    {
      "x": -41,
      "y": 37,
      "z": 1,
      "name": "Rock_Volcanic_Brick"
    },
    {
      "x": -41,
      "y": 38,
      "z": 1,
      "name": "Rock_Volcanic_Brick"
    },
    {
      "x": -41,
      "y": 39,
      "z": 1,
      "name": "Rock_Volcanic_Brick"
    },
    {
      "x": -41,
      "y": 40,
      "z": 1,
      "name": "Rock_Volcanic_Brick"
    },
    {
      "x": -41,
      "y": 41,
      "z": 1,
      "name": "Rock_Volcanic_Brick"
    },
    {
      "x": -41,
      "y": 42,
      "z": 1,
      "name": "Rock_Volcanic_Brick"
    },
    {
      "x": -41,
      "y": 43,
      "z": 1,
      "name": "Rock_Volcanic_Brick"
    },
    {
      "x": -41,
      "y": 44,
      "z": 1,
      "name": "Rock_Volcanic_Brick"
    },
    {
      "x": -41,
      "y": 45,
      "z": 1,
      "name": "Rock_Volcanic_Brick"
    },
    {
      "x": -41,
      "y": 46,
      "z": 1,
      "name": "Rock_Volcanic_Brick"
    },
    {
      "x": -41,
      "y": 39,
      "z": 2,
      "name": "Rock_Volcanic_Brick"
    },
    {
      "x": -41,
      "y": 40,
      "z": 2,
      "name": "Rock_Volcanic_Brick"
    },
    {
      "x": -41,
      "y": 41,
      "z": 2,
      "name": "Rock_Volcanic_Brick"
    },
    {
      "x": -41,
      "y": 42,
      "z": 2,
      "name": "Rock_Volcanic_Brick"
    },
    {
      "x": -41,
      "y": 43,
      "z": 2,
      "name": "Rock_Volcanic_Brick"
    },
    {
      "x": -41,
      "y": 44,
      "z": 2,
      "name": "Rock_Volcanic_Brick"
    },
    {
      "x": -41,
      "y": 45,
      "z": 2,
      "name": "Rock_Volcanic_Brick"
    },
    {
      "x": -41,
      "y": 46,
      "z": 2,
      "name": "Rock_Volcanic_Brick"
    },
    {
      "x": -41,
      "y": 47,
      "z": 2,
      "name": "Rock_Volcanic_Brick"
    },
    {
      "x": -41,
      "y": 48,
      "z": 2,
      "name": "Rock_Volcanic_Brick"
    },
    {
      "x": -41,
      "y": 41,
      "z": 3,
      "name": "Rock_Volcanic_Brick"
    },
    {
      "x": -41,
      "y": 42,
      "z": 3,
      "name": "Rock_Volcanic_Brick"
    },
    {
      "x": -41,
      "y": 43,
      "z": 3,
      "name": "Rock_Volcanic_Brick"
    },
    {
      "x": -41,
      "y": 44,
      "z": 3,
      "name": "Rock_Volcanic_Brick"
    },
    {
      "x": -41,
      "y": 45,
      "z": 3,
      "name": "Rock_Volcanic_Brick"
    },
    {
      "x": -41,
      "y": 46,
      "z": 3,
      "name": "Rock_Volcanic_Brick"
    },
    {
      "x": -41,
      "y": 47,
      "z": 3,
      "name": "Rock_Volcanic_Brick"
    },
    {
      "x": -41,
      "y": 48,
      "z": 3,
      "name": "Rock_Volcanic_Brick"
    },
    {
      "x": -41,
      "y": 49,
      "z": 3,
      "name": "Rock_Volcanic_Brick"
    },
    {
      "x": -41,
      "y": 42,
      "z": 4,
      "name": "Rock_Volcanic_Brick"
    },
    {
      "x": -41,
      "y": 43,
      "z": 4,
      "name": "Rock_Volcanic_Brick"
    },
    {
      "x": -41,
      "y": 44,
      "z": 4,
      "name": "Rock_Volcanic_Brick"
    },
    {
      "x": -41,
      "y": 45,
      "z": 4,
      "name": "Rock_Volcanic_Brick"
    },
    {
      "x": -41,
      "y": 46,
      "z": 4,
      "name": "Rock_Volcanic_Brick"
    },
    {
      "x": -41,
      "y": 47,
      "z": 4,
      "name": "Rock_Volcanic_Brick"
    },
    {
      "x": -41,
      "y": 48,
      "z": 4,
      "name": "Rock_Volcanic_Brick"
    },
    {
      "x": -41,
      "y": 49,
      "z": 4,
      "name": "Rock_Volcanic_Brick"
    },
    {
      "x": -41,
      "y": 50,
      "z": 4,
      "name": "Rock_Volcanic_Brick"
    },
    {
      "x": -41,
      "y": 44,
      "z": 5,
      "name": "Rock_Volcanic_Brick"
    },
    {
      "x": -41,
      "y": 45,
      "z": 5,
      "name": "Rock_Volcanic_Brick"
    },
    {
      "x": -41,
      "y": 46,
      "z": 5,
      "name": "Rock_Volcanic_Brick"
    },
    {
      "x": -41,
      "y": 47,
      "z": 5,
      "name": "Rock_Volcanic_Brick"
    },
    {
      "x": -41,
      "y": 48,
      "z": 5,
      "name": "Rock_Volcanic_Brick"
    },
    {
      "x": -41,
      "y": 49,
      "z": 5,
      "name": "Rock_Volcanic_Brick"
    },
    {
      "x": -41,
      "y": 50,
      "z": 5,
      "name": "Rock_Volcanic_Brick"
    },
    {
      "x": -41,
      "y": 52,
      "z": 5,
      "name": "Rock_Volcanic_Brick"
    },
    {
      "x": -41,
      "y": 53,
      "z": 5,
      "name": "Rock_Volcanic_Brick"
    },
    {
      "x": -41,
      "y": 46,
      "z": 6,
      "name": "Rock_Volcanic_Brick"
    },
    {
      "x": -41,
      "y": 47,
      "z": 6,
      "name": "Rock_Volcanic_Brick"
    },
    {
      "x": -41,
      "y": 48,
      "z": 6,
      "name": "Rock_Volcanic_Brick"
    },
    {
      "x": -41,
      "y": 49,
      "z": 6,
      "name": "Rock_Volcanic_Brick"
    },
    {
      "x": -41,
      "y": 51,
      "z": 6,
      "name": "Rock_Volcanic_Brick"
    },
    {
      "x": -41,
      "y": 52,
      "z": 6,
      "name": "Rock_Volcanic_Brick"
    },
    {
      "x": -41,
      "y": 53,
      "z": 6,
      "name": "Rock_Volcanic_Brick"
    },
    {
      "x": -41,
      "y": 54,
      "z": 6,
      "name": "Rock_Volcanic_Brick"
    },
    {
      "x": -41,
      "y": 48,
      "z": 7,
      "name": "Rock_Volcanic_Brick"
    },
    {
      "x": -41,
      "y": 51,
      "z": 7,
      "name": "Rock_Volcanic_Brick"
    },
    {
      "x": -41,
      "y": 52,
      "z": 7,
      "name": "Rock_Volcanic_Brick"
    },
    {
      "x": -41,
      "y": 53,
      "z": 7,
      "name": "Rock_Volcanic_Brick"
    },
    {
      "x": -41,
      "y": 54,
      "z": 7,
      "name": "Rock_Volcanic_Brick"
    },
    {
      "x": -41,
      "y": 55,
      "z": 7,
      "name": "Rock_Volcanic_Brick"
    },
    {
      "x": -41,
      "y": 56,
      "z": 7,
      "name": "Rock_Volcanic_Brick"
    },
    {
      "x": -41,
      "y": 50,
      "z": 8,
      "name": "Rock_Volcanic_Brick"
    },
    {
      "x": -41,
      "y": 51,
      "z": 8,
      "name": "Rock_Volcanic_Brick"
    },
    {
      "x": -41,
      "y": 52,
      "z": 8,
      "name": "Rock_Volcanic_Brick"
    },
    {
      "x": -41,
      "y": 53,
      "z": 8,
      "name": "Rock_Volcanic_Brick"
    },
    {
      "x": -41,
      "y": 54,
      "z": 8,
      "name": "Rock_Volcanic_Brick"
    },
    {
      "x": -41,
      "y": 55,
      "z": 8,
      "name": "Rock_Volcanic_Brick"
    },
    {
      "x": -41,
      "y": 56,
      "z": 8,
      "name": "Rock_Volcanic_Brick"
    },
    {
      "x": -41,
      "y": 51,
      "z": 9,
      "name": "Rock_Volcanic_Brick"
    },
    {
      "x": -41,
      "y": 52,
      "z": 9,
      "name": "Rock_Volcanic_Brick"
    },
    {
      "x": -41,
      "y": 53,
      "z": 9,
      "name": "Rock_Volcanic_Brick"
    },
    {
      "x": -41,
      "y": 54,
      "z": 9,
      "name": "Rock_Volcanic_Brick"
    },
    {
      "x": -41,
      "y": 55,
      "z": 9,
      "name": "Rock_Volcanic_Brick"
    },
    {
      "x": -41,
      "y": 53,
      "z": 10,
      "name": "Rock_Volcanic_Brick"
    },
    {
      "x": -41,
      "y": 54,
      "z": 10,
      "name": "Rock_Volcanic_Brick"
    },
    {
      "x": -41,
      "y": 55,
      "z": 10,
      "name": "Rock_Volcanic_Brick"
    },
    {
      "x": -40,
      "y": 21,
      "z": -12,
      "name": "Rock_Volcanic_Brick"
    },
    {
      "x": -40,
      "y": 22,
      "z": -12,
      "name": "Rock_Volcanic_Brick"
    },
    {
      "x": -40,
      "y": 23,
      "z": -12,
      "name": "Rock_Volcanic_Brick"
    },
    {
      "x": -40,
      "y": 21,
      "z": -11,
      "name": "Rock_Volcanic_Brick"
    },
    {
      "x": -40,
      "y": 22,
      "z": -11,
      "name": "Rock_Volcanic_Brick"
    },
    {
      "x": -40,
      "y": 23,
      "z": -11,
      "name": "Rock_Volcanic_Brick"
    },
    {
      "x": -40,
      "y": 20,
      "z": -10,
      "name": "Rock_Volcanic_Brick"
    },
    {
      "x": -40,
      "y": 21,
      "z": -10,
      "name": "Rock_Volcanic_Brick"
    },
    {
      "x": -40,
      "y": 22,
      "z": -10,
      "name": "Rock_Volcanic_Brick"
    },
    {
      "x": -40,
      "y": 23,
      "z": -10,
      "name": "Rock_Volcanic_Brick"
    },
    {
      "x": -40,
      "y": 21,
      "z": -9,
      "name": "Rock_Volcanic_Brick"
    },
    {
      "x": -40,
      "y": 22,
      "z": -9,
      "name": "Rock_Volcanic_Brick"
    },
    {
      "x": -40,
      "y": 26,
      "z": -9,
      "name": "Rock_Volcanic_Brick"
    },
    {
      "x": -40,
      "y": 27,
      "z": -9,
      "name": "Rock_Volcanic_Brick"
    },
    {
      "x": -40,
      "y": 28,
      "z": -9,
      "name": "Rock_Volcanic_Brick"
    },
    {
      "x": -40,
      "y": 26,
      "z": -8,
      "name": "Rock_Volcanic_Brick"
    },
    {
      "x": -40,
      "y": 27,
      "z": -8,
      "name": "Rock_Volcanic_Brick"
    },
    {
      "x": -40,
      "y": 28,
      "z": -8,
      "name": "Rock_Volcanic_Brick"
    },
    {
      "x": -40,
      "y": 29,
      "z": -8,
      "name": "Rock_Volcanic_Brick"
    },
    {
      "x": -40,
      "y": 30,
      "z": -8,
      "name": "Rock_Volcanic_Brick"
    },
    {
      "x": -40,
      "y": 25,
      "z": -7,
      "name": "Rock_Volcanic_Brick"
    },
    {
      "x": -40,
      "y": 26,
      "z": -7,
      "name": "Rock_Volcanic_Brick"
    },
    {
      "x": -40,
      "y": 27,
      "z": -7,
      "name": "Rock_Volcanic_Brick"
    },
    {
      "x": -40,
      "y": 28,
      "z": -7,
      "name": "Rock_Volcanic_Brick"
    },
    {
      "x": -40,
      "y": 29,
      "z": -7,
      "name": "Rock_Volcanic_Brick"
    },
    {
      "x": -40,
      "y": 30,
      "z": -7,
      "name": "Rock_Volcanic_Brick"
    },
    {
      "x": -40,
      "y": 31,
      "z": -7,
      "name": "Rock_Volcanic_Brick"
    },
    {
      "x": -40,
      "y": 32,
      "z": -7,
      "name": "Rock_Volcanic_Brick"
    },
    {
      "x": -40,
      "y": 26,
      "z": -6,
      "name": "Rock_Volcanic_Brick"
    },
    {
      "x": -40,
      "y": 27,
      "z": -6,
      "name": "Rock_Volcanic_Brick"
    },
    {
      "x": -40,
      "y": 28,
      "z": -6,
      "name": "Rock_Volcanic_Brick"
    },
    {
      "x": -40,
      "y": 29,
      "z": -6,
      "name": "Rock_Volcanic_Brick"
    },
    {
      "x": -40,
      "y": 30,
      "z": -6,
      "name": "Rock_Volcanic_Brick"
    },
    {
      "x": -40,
      "y": 31,
      "z": -6,
      "name": "Rock_Volcanic_Brick"
    },
    {
      "x": -40,
      "y": 32,
      "z": -6,
      "name": "Rock_Volcanic_Brick"
    },
    {
      "x": -40,
      "y": 33,
      "z": -6,
      "name": "Rock_Volcanic_Brick"
    },
    {
      "x": -40,
      "y": 34,
      "z": -6,
      "name": "Rock_Volcanic_Brick"
    },
    {
      "x": -40,
      "y": 27,
      "z": -5,
      "name": "Rock_Volcanic_Brick"
    },
    {
      "x": -40,
      "y": 28,
      "z": -5,
      "name": "Rock_Volcanic_Brick"
    },
    {
      "x": -40,
      "y": 29,
      "z": -5,
      "name": "Rock_Volcanic_Brick"
    },
    {
      "x": -40,
      "y": 30,
      "z": -5,
      "name": "Rock_Volcanic_Brick"
    },
    {
      "x": -40,
      "y": 31,
      "z": -5,
      "name": "Rock_Volcanic_Brick"
    },
    {
      "x": -40,
      "y": 32,
      "z": -5,
      "name": "Rock_Volcanic_Brick"
    },
    {
      "x": -40,
      "y": 33,
      "z": -5,
      "name": "Rock_Volcanic_Brick"
    },
    {
      "x": -40,
      "y": 34,
      "z": -5,
      "name": "Rock_Volcanic_Brick"
    },
    {
      "x": -40,
      "y": 35,
      "z": -5,
      "name": "Rock_Volcanic_Brick"
    },
    {
      "x": -40,
      "y": 29,
      "z": -4,
      "name": "Rock_Volcanic_Brick"
    },
    {
      "x": -40,
      "y": 30,
      "z": -4,
      "name": "Rock_Volcanic_Brick"
    },
    {
      "x": -40,
      "y": 31,
      "z": -4,
      "name": "Rock_Volcanic_Brick"
    },
    {
      "x": -40,
      "y": 32,
      "z": -4,
      "name": "Rock_Volcanic_Brick"
    },
    {
      "x": -40,
      "y": 33,
      "z": -4,
      "name": "Rock_Volcanic_Brick"
    },
    {
      "x": -40,
      "y": 34,
      "z": -4,
      "name": "Rock_Volcanic_Brick"
    },
    {
      "x": -40,
      "y": 35,
      "z": -4,
      "name": "Rock_Volcanic_Brick"
    },
    {
      "x": -40,
      "y": 36,
      "z": -4,
      "name": "Rock_Volcanic_Brick"
    },
    {
      "x": -40,
      "y": 37,
      "z": -4,
      "name": "Rock_Volcanic_Brick"
    },
    {
      "x": -40,
      "y": 31,
      "z": -3,
      "name": "Rock_Volcanic_Brick"
    },
    {
      "x": -40,
      "y": 32,
      "z": -3,
      "name": "Rock_Volcanic_Brick"
    },
    {
      "x": -40,
      "y": 33,
      "z": -3,
      "name": "Rock_Volcanic_Brick"
    },
    {
      "x": -40,
      "y": 34,
      "z": -3,
      "name": "Rock_Volcanic_Brick"
    },
    {
      "x": -40,
      "y": 35,
      "z": -3,
      "name": "Rock_Volcanic_Brick"
    },
    {
      "x": -40,
      "y": 36,
      "z": -3,
      "name": "Rock_Volcanic_Brick"
    },
    {
      "x": -40,
      "y": 37,
      "z": -3,
      "name": "Rock_Volcanic_Brick"
    },
    {
      "x": -40,
      "y": 38,
      "z": -3,
      "name": "Rock_Volcanic_Brick"
    },
    {
      "x": -40,
      "y": 39,
      "z": -3,
      "name": "Rock_Volcanic_Brick"
    },
    {
      "x": -40,
      "y": 32,
      "z": -2,
      "name": "Rock_Volcanic_Brick"
    },
    {
      "x": -40,
      "y": 33,
      "z": -2,
      "name": "Rock_Volcanic_Brick"
    },
    {
      "x": -40,
      "y": 34,
      "z": -2,
      "name": "Rock_Volcanic_Brick"
    },
    {
      "x": -40,
      "y": 35,
      "z": -2,
      "name": "Rock_Volcanic_Brick"
    },
    {
      "x": -40,
      "y": 36,
      "z": -2,
      "name": "Rock_Volcanic_Brick"
    },
    {
      "x": -40,
      "y": 37,
      "z": -2,
      "name": "Rock_Volcanic_Brick"
    },
    {
      "x": -40,
      "y": 38,
      "z": -2,
      "name": "Rock_Volcanic_Brick"
    },
    {
      "x": -40,
      "y": 39,
      "z": -2,
      "name": "Rock_Volcanic_Brick"
    },
    {
      "x": -40,
      "y": 40,
      "z": -2,
      "name": "Rock_Volcanic_Brick"
    },
    {
      "x": -40,
      "y": 41,
      "z": -2,
      "name": "Rock_Volcanic_Brick"
    },
    {
      "x": -40,
      "y": 34,
      "z": -1,
      "name": "Rock_Volcanic_Brick"
    },
    {
      "x": -40,
      "y": 35,
      "z": -1,
      "name": "Rock_Volcanic_Brick"
    },
    {
      "x": -40,
      "y": 36,
      "z": -1,
      "name": "Rock_Volcanic_Brick"
    },
    {
      "x": -40,
      "y": 37,
      "z": -1,
      "name": "Rock_Volcanic_Brick"
    },
    {
      "x": -40,
      "y": 38,
      "z": -1,
      "name": "Rock_Volcanic_Brick"
    },
    {
      "x": -40,
      "y": 39,
      "z": -1,
      "name": "Rock_Volcanic_Brick"
    },
    {
      "x": -40,
      "y": 40,
      "z": -1,
      "name": "Rock_Volcanic_Brick"
    },
    {
      "x": -40,
      "y": 41,
      "z": -1,
      "name": "Rock_Volcanic_Brick"
    },
    {
      "x": -40,
      "y": 42,
      "z": -1,
      "name": "Rock_Volcanic_Brick"
    },
    {
      "x": -40,
      "y": 36,
      "z": 0,
      "name": "Rock_Volcanic_Brick"
    },
    {
      "x": -40,
      "y": 37,
      "z": 0,
      "name": "Rock_Volcanic_Brick"
    },
    {
      "x": -40,
      "y": 38,
      "z": 0,
      "name": "Rock_Volcanic_Brick"
    },
    {
      "x": -40,
      "y": 39,
      "z": 0,
      "name": "Rock_Volcanic_Brick"
    },
    {
      "x": -40,
      "y": 40,
      "z": 0,
      "name": "Rock_Volcanic_Brick"
    },
    {
      "x": -40,
      "y": 41,
      "z": 0,
      "name": "Rock_Volcanic_Brick"
    },
    {
      "x": -40,
      "y": 42,
      "z": 0,
      "name": "Rock_Volcanic_Brick"
    },
    {
      "x": -40,
      "y": 43,
      "z": 0,
      "name": "Rock_Volcanic_Brick"
    },
    {
      "x": -40,
      "y": 44,
      "z": 0,
      "name": "Rock_Volcanic_Brick"
    },
    {
      "x": -40,
      "y": 37,
      "z": 1,
      "name": "Rock_Volcanic_Brick"
    },
    {
      "x": -40,
      "y": 38,
      "z": 1,
      "name": "Rock_Volcanic_Brick"
    },
    {
      "x": -40,
      "y": 39,
      "z": 1,
      "name": "Rock_Volcanic_Brick"
    },
    {
      "x": -40,
      "y": 40,
      "z": 1,
      "name": "Rock_Volcanic_Brick"
    },
    {
      "x": -40,
      "y": 41,
      "z": 1,
      "name": "Rock_Volcanic_Brick"
    },
    {
      "x": -40,
      "y": 42,
      "z": 1,
      "name": "Rock_Volcanic_Brick"
    },
    {
      "x": -40,
      "y": 43,
      "z": 1,
      "name": "Rock_Volcanic_Brick"
    },
    {
      "x": -40,
      "y": 44,
      "z": 1,
      "name": "Rock_Volcanic_Brick"
    },
    {
      "x": -40,
      "y": 45,
      "z": 1,
      "name": "Rock_Volcanic_Brick"
    },
    {
      "x": -40,
      "y": 46,
      "z": 1,
      "name": "Rock_Volcanic_Brick"
    },
    {
      "x": -40,
      "y": 39,
      "z": 2,
      "name": "Rock_Volcanic_Brick"
    },
    {
      "x": -40,
      "y": 40,
      "z": 2,
      "name": "Rock_Volcanic_Brick"
    },
    {
      "x": -40,
      "y": 41,
      "z": 2,
      "name": "Rock_Volcanic_Brick"
    },
    {
      "x": -40,
      "y": 42,
      "z": 2,
      "name": "Rock_Volcanic_Brick"
    },
    {
      "x": -40,
      "y": 43,
      "z": 2,
      "name": "Rock_Volcanic_Brick"
    },
    {
      "x": -40,
      "y": 44,
      "z": 2,
      "name": "Rock_Volcanic_Brick"
    },
    {
      "x": -40,
      "y": 45,
      "z": 2,
      "name": "Rock_Volcanic_Brick"
    },
    {
      "x": -40,
      "y": 46,
      "z": 2,
      "name": "Rock_Volcanic_Brick"
    },
    {
      "x": -40,
      "y": 47,
      "z": 2,
      "name": "Rock_Volcanic_Brick"
    },
    {
      "x": -40,
      "y": 48,
      "z": 2,
      "name": "Rock_Volcanic_Brick"
    },
    {
      "x": -40,
      "y": 41,
      "z": 3,
      "name": "Rock_Volcanic_Brick"
    },
    {
      "x": -40,
      "y": 42,
      "z": 3,
      "name": "Rock_Volcanic_Brick"
    },
    {
      "x": -40,
      "y": 43,
      "z": 3,
      "name": "Rock_Volcanic_Brick"
    },
    {
      "x": -40,
      "y": 44,
      "z": 3,
      "name": "Rock_Volcanic_Brick"
    },
    {
      "x": -40,
      "y": 45,
      "z": 3,
      "name": "Rock_Volcanic_Brick"
    },
    {
      "x": -40,
      "y": 46,
      "z": 3,
      "name": "Rock_Volcanic_Brick"
    },
    {
      "x": -40,
      "y": 47,
      "z": 3,
      "name": "Rock_Volcanic_Brick"
    },
    {
      "x": -40,
      "y": 48,
      "z": 3,
      "name": "Rock_Volcanic_Brick"
    },
    {
      "x": -40,
      "y": 49,
      "z": 3,
      "name": "Rock_Volcanic_Brick"
    },
    {
      "x": -40,
      "y": 42,
      "z": 4,
      "name": "Rock_Volcanic_Brick"
    },
    {
      "x": -40,
      "y": 43,
      "z": 4,
      "name": "Rock_Volcanic_Brick"
    },
    {
      "x": -40,
      "y": 44,
      "z": 4,
      "name": "Rock_Volcanic_Brick"
    },
    {
      "x": -40,
      "y": 45,
      "z": 4,
      "name": "Rock_Volcanic_Brick"
    },
    {
      "x": -40,
      "y": 46,
      "z": 4,
      "name": "Rock_Volcanic_Brick"
    },
    {
      "x": -40,
      "y": 47,
      "z": 4,
      "name": "Rock_Volcanic_Brick"
    },
    {
      "x": -40,
      "y": 48,
      "z": 4,
      "name": "Rock_Volcanic_Brick"
    },
    {
      "x": -40,
      "y": 49,
      "z": 4,
      "name": "Rock_Volcanic_Brick"
    },
    {
      "x": -40,
      "y": 50,
      "z": 4,
      "name": "Rock_Volcanic_Brick"
    },
    {
      "x": -40,
      "y": 44,
      "z": 5,
      "name": "Rock_Volcanic_Brick"
    },
    {
      "x": -40,
      "y": 45,
      "z": 5,
      "name": "Rock_Volcanic_Brick"
    },
    {
      "x": -40,
      "y": 46,
      "z": 5,
      "name": "Rock_Volcanic_Brick"
    },
    {
      "x": -40,
      "y": 47,
      "z": 5,
      "name": "Rock_Volcanic_Brick"
    },
    {
      "x": -40,
      "y": 48,
      "z": 5,
      "name": "Rock_Volcanic_Brick"
    },
    {
      "x": -40,
      "y": 49,
      "z": 5,
      "name": "Rock_Volcanic_Brick"
    },
    {
      "x": -40,
      "y": 50,
      "z": 5,
      "name": "Rock_Volcanic_Brick"
    },
    {
      "x": -40,
      "y": 51,
      "z": 5,
      "name": "Rock_Volcanic_Brick"
    },
    {
      "x": -40,
      "y": 52,
      "z": 5,
      "name": "Rock_Volcanic_Brick"
    },
    {
      "x": -40,
      "y": 53,
      "z": 5,
      "name": "Rock_Volcanic_Brick"
    },
    {
      "x": -40,
      "y": 46,
      "z": 6,
      "name": "Rock_Volcanic_Brick"
    },
    {
      "x": -40,
      "y": 47,
      "z": 6,
      "name": "Rock_Volcanic_Brick"
    },
    {
      "x": -40,
      "y": 48,
      "z": 6,
      "name": "Rock_Volcanic_Brick"
    },
    {
      "x": -40,
      "y": 49,
      "z": 6,
      "name": "Rock_Volcanic_Brick"
    },
    {
      "x": -40,
      "y": 50,
      "z": 6,
      "name": "Rock_Volcanic_Brick"
    },
    {
      "x": -40,
      "y": 51,
      "z": 6,
      "name": "Rock_Volcanic_Brick"
    },
    {
      "x": -40,
      "y": 52,
      "z": 6,
      "name": "Rock_Volcanic_Brick"
    },
    {
      "x": -40,
      "y": 53,
      "z": 6,
      "name": "Rock_Volcanic_Brick"
    },
    {
      "x": -40,
      "y": 54,
      "z": 6,
      "name": "Rock_Volcanic_Brick"
    },
    {
      "x": -40,
      "y": 48,
      "z": 7,
      "name": "Rock_Volcanic_Brick"
    },
    {
      "x": -40,
      "y": 50,
      "z": 7,
      "name": "Rock_Volcanic_Brick"
    },
    {
      "x": -40,
      "y": 51,
      "z": 7,
      "name": "Rock_Volcanic_Brick"
    },
    {
      "x": -40,
      "y": 52,
      "z": 7,
      "name": "Rock_Volcanic_Brick"
    },
    {
      "x": -40,
      "y": 53,
      "z": 7,
      "name": "Rock_Volcanic_Brick"
    },
    {
      "x": -40,
      "y": 54,
      "z": 7,
      "name": "Rock_Volcanic_Brick"
    },
    {
      "x": -40,
      "y": 55,
      "z": 7,
      "name": "Rock_Volcanic_Brick"
    },
    {
      "x": -40,
      "y": 56,
      "z": 7,
      "name": "Rock_Volcanic_Brick"
    },
    {
      "x": -40,
      "y": 50,
      "z": 8,
      "name": "Rock_Volcanic_Brick"
    },
    {
      "x": -40,
      "y": 51,
      "z": 8,
      "name": "Rock_Volcanic_Brick"
    },
    {
      "x": -40,
      "y": 52,
      "z": 8,
      "name": "Rock_Volcanic_Brick"
    },
    {
      "x": -40,
      "y": 53,
      "z": 8,
      "name": "Rock_Volcanic_Brick"
    },
    {
      "x": -40,
      "y": 54,
      "z": 8,
      "name": "Rock_Volcanic_Brick"
    },
    {
      "x": -40,
      "y": 55,
      "z": 8,
      "name": "Rock_Volcanic_Brick"
    },
    {
      "x": -40,
      "y": 56,
      "z": 8,
      "name": "Rock_Volcanic_Brick"
    },
    {
      "x": -40,
      "y": 51,
      "z": 9,
      "name": "Rock_Volcanic_Brick"
    },
    {
      "x": -40,
      "y": 52,
      "z": 9,
      "name": "Rock_Volcanic_Brick"
    },
    {
      "x": -40,
      "y": 53,
      "z": 9,
      "name": "Rock_Volcanic_Brick"
    },
    {
      "x": -40,
      "y": 54,
      "z": 9,
      "name": "Rock_Volcanic_Brick"
    },
    {
      "x": -40,
      "y": 55,
      "z": 9,
      "name": "Rock_Volcanic_Brick"
    },
    {
      "x": -40,
      "y": 53,
      "z": 10,
      "name": "Rock_Volcanic_Brick"
    },
    {
      "x": -40,
      "y": 54,
      "z": 10,
      "name": "Rock_Volcanic_Brick"
    },
    {
      "x": -40,
      "y": 55,
      "z": 10,
      "name": "Rock_Volcanic_Brick"
    },
    {
      "x": -40,
      "y": 59,
      "z": 10,
      "name": "Rock_Volcanic_Brick"
    },
    {
      "x": -40,
      "y": 60,
      "z": 10,
      "name": "Rock_Volcanic_Brick"
    },
    {
      "x": -40,
      "y": 61,
      "z": 10,
      "name": "Rock_Volcanic_Brick"
    },
    {
      "x": -40,
      "y": 59,
      "z": 11,
      "name": "Rock_Volcanic_Brick"
    },
    {
      "x": -40,
      "y": 60,
      "z": 11,
      "name": "Rock_Volcanic_Brick"
    },
    {
      "x": -40,
      "y": 61,
      "z": 11,
      "name": "Rock_Volcanic_Brick"
    },
    {
      "x": -40,
      "y": 58,
      "z": 12,
      "name": "Rock_Volcanic_Brick"
    },
    {
      "x": -40,
      "y": 59,
      "z": 12,
      "name": "Rock_Volcanic_Brick"
    },
    {
      "x": -40,
      "y": 60,
      "z": 12,
      "name": "Rock_Volcanic_Brick"
    },
    {
      "x": -40,
      "y": 59,
      "z": 13,
      "name": "Rock_Volcanic_Brick"
    },
    {
      "x": -40,
      "y": 60,
      "z": 13,
      "name": "Rock_Volcanic_Brick"
    },
    {
      "x": -39,
      "y": 21,
      "z": -13,
      "name": "Rock_Volcanic_Brick"
    },
    {
      "x": -39,
      "y": 22,
      "z": -13,
      "name": "Rock_Volcanic_Brick"
    },
    {
      "x": -39,
      "y": 20,
      "z": -12,
      "name": "Rock_Volcanic_Brick"
    },
    {
      "x": -39,
      "y": 21,
      "z": -12,
      "name": "Rock_Volcanic_Brick"
    },
    {
      "x": -39,
      "y": 22,
      "z": -12,
      "name": "Rock_Volcanic_Brick"
    },
    {
      "x": -39,
      "y": 23,
      "z": -12,
      "name": "Rock_Volcanic_Brick"
    },
    {
      "x": -39,
      "y": 20,
      "z": -11,
      "name": "Rock_Volcanic_Brick"
    },
    {
      "x": -39,
      "y": 21,
      "z": -11,
      "name": "Rock_Volcanic_Brick"
    },
    {
      "x": -39,
      "y": 22,
      "z": -11,
      "name": "Rock_Volcanic_Brick"
    },
    {
      "x": -39,
      "y": 23,
      "z": -11,
      "name": "Rock_Volcanic_Brick"
    },
    {
      "x": -39,
      "y": 24,
      "z": -11,
      "name": "Rock_Volcanic_Brick"
    },
    {
      "x": -39,
      "y": 19,
      "z": -10,
      "name": "Rock_Volcanic_Brick"
    },
    {
      "x": -39,
      "y": 20,
      "z": -10,
      "name": "Rock_Volcanic_Brick"
    },
    {
      "x": -39,
      "y": 21,
      "z": -10,
      "name": "Rock_Volcanic_Brick"
    },
    {
      "x": -39,
      "y": 22,
      "z": -10,
      "name": "Rock_Volcanic_Brick"
    },
    {
      "x": -39,
      "y": 23,
      "z": -10,
      "name": "Rock_Volcanic_Brick"
    },
    {
      "x": -39,
      "y": 24,
      "z": -10,
      "name": "Rock_Volcanic_Brick"
    },
    {
      "x": -39,
      "y": 20,
      "z": -9,
      "name": "Rock_Volcanic_Brick"
    },
    {
      "x": -39,
      "y": 21,
      "z": -9,
      "name": "Rock_Volcanic_Brick"
    },
    {
      "x": -39,
      "y": 22,
      "z": -9,
      "name": "Rock_Volcanic_Brick"
    },
    {
      "x": -39,
      "y": 23,
      "z": -9,
      "name": "Rock_Volcanic_Brick"
    },
    {
      "x": -39,
      "y": 24,
      "z": -9,
      "name": "Rock_Volcanic_Brick"
    },
    {
      "x": -39,
      "y": 26,
      "z": -9,
      "name": "Rock_Volcanic_Brick"
    },
    {
      "x": -39,
      "y": 27,
      "z": -9,
      "name": "Rock_Volcanic_Brick"
    },
    {
      "x": -39,
      "y": 28,
      "z": -9,
      "name": "Rock_Volcanic_Brick"
    },
    {
      "x": -39,
      "y": 22,
      "z": -8,
      "name": "Rock_Volcanic_Brick"
    },
    {
      "x": -39,
      "y": 23,
      "z": -8,
      "name": "Rock_Volcanic_Brick"
    },
    {
      "x": -39,
      "y": 26,
      "z": -8,
      "name": "Rock_Volcanic_Brick"
    },
    {
      "x": -39,
      "y": 27,
      "z": -8,
      "name": "Rock_Volcanic_Brick"
    },
    {
      "x": -39,
      "y": 28,
      "z": -8,
      "name": "Rock_Volcanic_Brick"
    },
    {
      "x": -39,
      "y": 29,
      "z": -8,
      "name": "Rock_Volcanic_Brick"
    },
    {
      "x": -39,
      "y": 30,
      "z": -8,
      "name": "Rock_Volcanic_Brick"
    },
    {
      "x": -39,
      "y": 25,
      "z": -7,
      "name": "Rock_Volcanic_Brick"
    },
    {
      "x": -39,
      "y": 26,
      "z": -7,
      "name": "Rock_Volcanic_Brick"
    },
    {
      "x": -39,
      "y": 27,
      "z": -7,
      "name": "Rock_Volcanic_Brick"
    },
    {
      "x": -39,
      "y": 28,
      "z": -7,
      "name": "Rock_Volcanic_Brick"
    },
    {
      "x": -39,
      "y": 29,
      "z": -7,
      "name": "Rock_Volcanic_Brick"
    },
    {
      "x": -39,
      "y": 30,
      "z": -7,
      "name": "Rock_Volcanic_Brick"
    },
    {
      "x": -39,
      "y": 31,
      "z": -7,
      "name": "Rock_Volcanic_Brick"
    },
    {
      "x": -39,
      "y": 32,
      "z": -7,
      "name": "Rock_Volcanic_Brick"
    },
    {
      "x": -39,
      "y": 26,
      "z": -6,
      "name": "Rock_Volcanic_Brick"
    },
    {
      "x": -39,
      "y": 27,
      "z": -6,
      "name": "Rock_Volcanic_Brick"
    },
    {
      "x": -39,
      "y": 28,
      "z": -6,
      "name": "Rock_Volcanic_Brick"
    },
    {
      "x": -39,
      "y": 29,
      "z": -6,
      "name": "Rock_Volcanic_Brick"
    },
    {
      "x": -39,
      "y": 30,
      "z": -6,
      "name": "Rock_Volcanic_Brick"
    },
    {
      "x": -39,
      "y": 31,
      "z": -6,
      "name": "Rock_Volcanic_Brick"
    },
    {
      "x": -39,
      "y": 32,
      "z": -6,
      "name": "Rock_Volcanic_Brick"
    },
    {
      "x": -39,
      "y": 33,
      "z": -6,
      "name": "Rock_Volcanic_Brick"
    },
    {
      "x": -39,
      "y": 34,
      "z": -6,
      "name": "Rock_Volcanic_Brick"
    },
    {
      "x": -39,
      "y": 27,
      "z": -5,
      "name": "Rock_Volcanic_Brick"
    },
    {
      "x": -39,
      "y": 28,
      "z": -5,
      "name": "Rock_Volcanic_Brick"
    },
    {
      "x": -39,
      "y": 29,
      "z": -5,
      "name": "Rock_Volcanic_Brick"
    },
    {
      "x": -39,
      "y": 30,
      "z": -5,
      "name": "Rock_Volcanic_Brick"
    },
    {
      "x": -39,
      "y": 31,
      "z": -5,
      "name": "Rock_Volcanic_Brick"
    },
    {
      "x": -39,
      "y": 32,
      "z": -5,
      "name": "Rock_Volcanic_Brick"
    },
    {
      "x": -39,
      "y": 33,
      "z": -5,
      "name": "Rock_Volcanic_Brick"
    },
    {
      "x": -39,
      "y": 34,
      "z": -5,
      "name": "Rock_Volcanic_Brick"
    },
    {
      "x": -39,
      "y": 35,
      "z": -5,
      "name": "Rock_Volcanic_Brick"
    },
    {
      "x": -39,
      "y": 29,
      "z": -4,
      "name": "Rock_Volcanic_Brick"
    },
    {
      "x": -39,
      "y": 30,
      "z": -4,
      "name": "Rock_Volcanic_Brick"
    },
    {
      "x": -39,
      "y": 31,
      "z": -4,
      "name": "Rock_Volcanic_Brick"
    },
    {
      "x": -39,
      "y": 32,
      "z": -4,
      "name": "Rock_Volcanic_Brick"
    },
    {
      "x": -39,
      "y": 33,
      "z": -4,
      "name": "Rock_Volcanic_Brick"
    },
    {
      "x": -39,
      "y": 34,
      "z": -4,
      "name": "Rock_Volcanic_Brick"
    },
    {
      "x": -39,
      "y": 35,
      "z": -4,
      "name": "Rock_Volcanic_Brick"
    },
    {
      "x": -39,
      "y": 36,
      "z": -4,
      "name": "Rock_Volcanic_Brick"
    },
    {
      "x": -39,
      "y": 37,
      "z": -4,
      "name": "Rock_Volcanic_Brick"
    },
    {
      "x": -39,
      "y": 30,
      "z": -3,
      "name": "Rock_Volcanic_Brick"
    },
    {
      "x": -39,
      "y": 31,
      "z": -3,
      "name": "Rock_Volcanic_Brick"
    },
    {
      "x": -39,
      "y": 32,
      "z": -3,
      "name": "Rock_Volcanic_Brick"
    },
    {
      "x": -39,
      "y": 33,
      "z": -3,
      "name": "Rock_Volcanic_Brick"
    },
    {
      "x": -39,
      "y": 34,
      "z": -3,
      "name": "Rock_Volcanic_Brick"
    },
    {
      "x": -39,
      "y": 35,
      "z": -3,
      "name": "Rock_Volcanic_Brick"
    },
    {
      "x": -39,
      "y": 36,
      "z": -3,
      "name": "Rock_Volcanic_Brick"
    },
    {
      "x": -39,
      "y": 37,
      "z": -3,
      "name": "Rock_Volcanic_Brick"
    },
    {
      "x": -39,
      "y": 38,
      "z": -3,
      "name": "Rock_Volcanic_Brick"
    },
    {
      "x": -39,
      "y": 39,
      "z": -3,
      "name": "Rock_Volcanic_Brick"
    },
    {
      "x": -39,
      "y": 32,
      "z": -2,
      "name": "Rock_Volcanic_Brick"
    },
    {
      "x": -39,
      "y": 33,
      "z": -2,
      "name": "Rock_Volcanic_Brick"
    },
    {
      "x": -39,
      "y": 34,
      "z": -2,
      "name": "Rock_Volcanic_Brick"
    },
    {
      "x": -39,
      "y": 35,
      "z": -2,
      "name": "Rock_Volcanic_Brick"
    },
    {
      "x": -39,
      "y": 36,
      "z": -2,
      "name": "Rock_Volcanic_Brick"
    },
    {
      "x": -39,
      "y": 37,
      "z": -2,
      "name": "Rock_Volcanic_Brick"
    },
    {
      "x": -39,
      "y": 38,
      "z": -2,
      "name": "Rock_Volcanic_Brick"
    },
    {
      "x": -39,
      "y": 39,
      "z": -2,
      "name": "Rock_Volcanic_Brick"
    },
    {
      "x": -39,
      "y": 40,
      "z": -2,
      "name": "Rock_Volcanic_Brick"
    },
    {
      "x": -39,
      "y": 41,
      "z": -2,
      "name": "Rock_Volcanic_Brick"
    },
    {
      "x": -39,
      "y": 34,
      "z": -1,
      "name": "Rock_Volcanic_Brick"
    },
    {
      "x": -39,
      "y": 35,
      "z": -1,
      "name": "Rock_Volcanic_Brick"
    },
    {
      "x": -39,
      "y": 36,
      "z": -1,
      "name": "Rock_Volcanic_Brick"
    },
    {
      "x": -39,
      "y": 37,
      "z": -1,
      "name": "Rock_Volcanic_Brick"
    },
    {
      "x": -39,
      "y": 38,
      "z": -1,
      "name": "Rock_Volcanic_Brick"
    },
    {
      "x": -39,
      "y": 39,
      "z": -1,
      "name": "Rock_Volcanic_Brick"
    },
    {
      "x": -39,
      "y": 40,
      "z": -1,
      "name": "Rock_Volcanic_Brick"
    },
    {
      "x": -39,
      "y": 41,
      "z": -1,
      "name": "Rock_Volcanic_Brick"
    },
    {
      "x": -39,
      "y": 42,
      "z": -1,
      "name": "Rock_Volcanic_Brick"
    },
    {
      "x": -39,
      "y": 36,
      "z": 0,
      "name": "Rock_Volcanic_Brick"
    },
    {
      "x": -39,
      "y": 37,
      "z": 0,
      "name": "Rock_Volcanic_Brick"
    },
    {
      "x": -39,
      "y": 38,
      "z": 0,
      "name": "Rock_Volcanic_Brick"
    },
    {
      "x": -39,
      "y": 39,
      "z": 0,
      "name": "Rock_Volcanic_Brick"
    },
    {
      "x": -39,
      "y": 40,
      "z": 0,
      "name": "Rock_Volcanic_Brick"
    },
    {
      "x": -39,
      "y": 41,
      "z": 0,
      "name": "Rock_Volcanic_Brick"
    },
    {
      "x": -39,
      "y": 42,
      "z": 0,
      "name": "Rock_Volcanic_Brick"
    },
    {
      "x": -39,
      "y": 43,
      "z": 0,
      "name": "Rock_Volcanic_Brick"
    },
    {
      "x": -39,
      "y": 44,
      "z": 0,
      "name": "Rock_Volcanic_Brick"
    },
    {
      "x": -39,
      "y": 37,
      "z": 1,
      "name": "Rock_Volcanic_Brick"
    },
    {
      "x": -39,
      "y": 38,
      "z": 1,
      "name": "Rock_Volcanic_Brick"
    },
    {
      "x": -39,
      "y": 39,
      "z": 1,
      "name": "Rock_Volcanic_Brick"
    },
    {
      "x": -39,
      "y": 40,
      "z": 1,
      "name": "Rock_Volcanic_Brick"
    },
    {
      "x": -39,
      "y": 41,
      "z": 1,
      "name": "Rock_Volcanic_Brick"
    },
    {
      "x": -39,
      "y": 42,
      "z": 1,
      "name": "Rock_Volcanic_Brick"
    },
    {
      "x": -39,
      "y": 43,
      "z": 1,
      "name": "Rock_Volcanic_Brick"
    },
    {
      "x": -39,
      "y": 44,
      "z": 1,
      "name": "Rock_Volcanic_Brick"
    },
    {
      "x": -39,
      "y": 45,
      "z": 1,
      "name": "Rock_Volcanic_Brick"
    },
    {
      "x": -39,
      "y": 46,
      "z": 1,
      "name": "Rock_Volcanic_Brick"
    },
    {
      "x": -39,
      "y": 39,
      "z": 2,
      "name": "Rock_Volcanic_Brick"
    },
    {
      "x": -39,
      "y": 40,
      "z": 2,
      "name": "Rock_Volcanic_Brick"
    },
    {
      "x": -39,
      "y": 41,
      "z": 2,
      "name": "Rock_Volcanic_Brick"
    },
    {
      "x": -39,
      "y": 42,
      "z": 2,
      "name": "Rock_Volcanic_Brick"
    },
    {
      "x": -39,
      "y": 43,
      "z": 2,
      "name": "Rock_Volcanic_Brick"
    },
    {
      "x": -39,
      "y": 44,
      "z": 2,
      "name": "Rock_Volcanic_Brick"
    },
    {
      "x": -39,
      "y": 45,
      "z": 2,
      "name": "Rock_Volcanic_Brick"
    },
    {
      "x": -39,
      "y": 46,
      "z": 2,
      "name": "Rock_Volcanic_Brick"
    },
    {
      "x": -39,
      "y": 47,
      "z": 2,
      "name": "Rock_Volcanic_Brick"
    },
    {
      "x": -39,
      "y": 48,
      "z": 2,
      "name": "Rock_Volcanic_Brick"
    },
    {
      "x": -39,
      "y": 41,
      "z": 3,
      "name": "Rock_Volcanic_Brick"
    },
    {
      "x": -39,
      "y": 42,
      "z": 3,
      "name": "Rock_Volcanic_Brick"
    },
    {
      "x": -39,
      "y": 43,
      "z": 3,
      "name": "Rock_Volcanic_Brick"
    },
    {
      "x": -39,
      "y": 44,
      "z": 3,
      "name": "Rock_Volcanic_Brick"
    },
    {
      "x": -39,
      "y": 45,
      "z": 3,
      "name": "Rock_Volcanic_Brick"
    },
    {
      "x": -39,
      "y": 46,
      "z": 3,
      "name": "Rock_Volcanic_Brick"
    },
    {
      "x": -39,
      "y": 47,
      "z": 3,
      "name": "Rock_Volcanic_Brick"
    },
    {
      "x": -39,
      "y": 48,
      "z": 3,
      "name": "Rock_Volcanic_Brick"
    },
    {
      "x": -39,
      "y": 49,
      "z": 3,
      "name": "Rock_Volcanic_Brick"
    },
    {
      "x": -39,
      "y": 42,
      "z": 4,
      "name": "Rock_Volcanic_Brick"
    },
    {
      "x": -39,
      "y": 43,
      "z": 4,
      "name": "Rock_Volcanic_Brick"
    },
    {
      "x": -39,
      "y": 44,
      "z": 4,
      "name": "Rock_Volcanic_Brick"
    },
    {
      "x": -39,
      "y": 45,
      "z": 4,
      "name": "Rock_Volcanic_Brick"
    },
    {
      "x": -39,
      "y": 46,
      "z": 4,
      "name": "Rock_Volcanic_Brick"
    },
    {
      "x": -39,
      "y": 47,
      "z": 4,
      "name": "Rock_Volcanic_Brick"
    },
    {
      "x": -39,
      "y": 48,
      "z": 4,
      "name": "Rock_Volcanic_Brick"
    },
    {
      "x": -39,
      "y": 49,
      "z": 4,
      "name": "Rock_Volcanic_Brick"
    },
    {
      "x": -39,
      "y": 50,
      "z": 4,
      "name": "Rock_Volcanic_Brick"
    },
    {
      "x": -39,
      "y": 51,
      "z": 4,
      "name": "Rock_Volcanic_Brick"
    },
    {
      "x": -39,
      "y": 44,
      "z": 5,
      "name": "Rock_Volcanic_Brick"
    },
    {
      "x": -39,
      "y": 45,
      "z": 5,
      "name": "Rock_Volcanic_Brick"
    },
    {
      "x": -39,
      "y": 46,
      "z": 5,
      "name": "Rock_Volcanic_Brick"
    },
    {
      "x": -39,
      "y": 47,
      "z": 5,
      "name": "Rock_Volcanic_Brick"
    },
    {
      "x": -39,
      "y": 48,
      "z": 5,
      "name": "Rock_Volcanic_Brick"
    },
    {
      "x": -39,
      "y": 49,
      "z": 5,
      "name": "Rock_Volcanic_Brick"
    },
    {
      "x": -39,
      "y": 50,
      "z": 5,
      "name": "Rock_Volcanic_Brick"
    },
    {
      "x": -39,
      "y": 51,
      "z": 5,
      "name": "Rock_Volcanic_Brick"
    },
    {
      "x": -39,
      "y": 52,
      "z": 5,
      "name": "Rock_Volcanic_Brick"
    },
    {
      "x": -39,
      "y": 53,
      "z": 5,
      "name": "Rock_Volcanic_Brick"
    },
    {
      "x": -39,
      "y": 46,
      "z": 6,
      "name": "Rock_Volcanic_Brick"
    },
    {
      "x": -39,
      "y": 47,
      "z": 6,
      "name": "Rock_Volcanic_Brick"
    },
    {
      "x": -39,
      "y": 48,
      "z": 6,
      "name": "Rock_Volcanic_Brick"
    },
    {
      "x": -39,
      "y": 49,
      "z": 6,
      "name": "Rock_Volcanic_Brick"
    },
    {
      "x": -39,
      "y": 50,
      "z": 6,
      "name": "Rock_Volcanic_Brick"
    },
    {
      "x": -39,
      "y": 51,
      "z": 6,
      "name": "Rock_Volcanic_Brick"
    },
    {
      "x": -39,
      "y": 52,
      "z": 6,
      "name": "Rock_Volcanic_Brick"
    },
    {
      "x": -39,
      "y": 53,
      "z": 6,
      "name": "Rock_Volcanic_Brick"
    },
    {
      "x": -39,
      "y": 54,
      "z": 6,
      "name": "Rock_Volcanic_Brick"
    },
    {
      "x": -39,
      "y": 48,
      "z": 7,
      "name": "Rock_Volcanic_Brick"
    },
    {
      "x": -39,
      "y": 49,
      "z": 7,
      "name": "Rock_Volcanic_Brick"
    },
    {
      "x": -39,
      "y": 50,
      "z": 7,
      "name": "Rock_Volcanic_Brick"
    },
    {
      "x": -39,
      "y": 51,
      "z": 7,
      "name": "Rock_Volcanic_Brick"
    },
    {
      "x": -39,
      "y": 52,
      "z": 7,
      "name": "Rock_Volcanic_Brick"
    },
    {
      "x": -39,
      "y": 53,
      "z": 7,
      "name": "Rock_Volcanic_Brick"
    },
    {
      "x": -39,
      "y": 54,
      "z": 7,
      "name": "Rock_Volcanic_Brick"
    },
    {
      "x": -39,
      "y": 55,
      "z": 7,
      "name": "Rock_Volcanic_Brick"
    },
    {
      "x": -39,
      "y": 56,
      "z": 7,
      "name": "Rock_Volcanic_Brick"
    },
    {
      "x": -39,
      "y": 49,
      "z": 8,
      "name": "Rock_Volcanic_Brick"
    },
    {
      "x": -39,
      "y": 50,
      "z": 8,
      "name": "Rock_Volcanic_Brick"
    },
    {
      "x": -39,
      "y": 51,
      "z": 8,
      "name": "Rock_Volcanic_Brick"
    },
    {
      "x": -39,
      "y": 52,
      "z": 8,
      "name": "Rock_Volcanic_Brick"
    },
    {
      "x": -39,
      "y": 53,
      "z": 8,
      "name": "Rock_Volcanic_Brick"
    },
    {
      "x": -39,
      "y": 54,
      "z": 8,
      "name": "Rock_Volcanic_Brick"
    },
    {
      "x": -39,
      "y": 55,
      "z": 8,
      "name": "Rock_Volcanic_Brick"
    },
    {
      "x": -39,
      "y": 56,
      "z": 8,
      "name": "Rock_Volcanic_Brick"
    },
    {
      "x": -39,
      "y": 51,
      "z": 9,
      "name": "Rock_Volcanic_Brick"
    },
    {
      "x": -39,
      "y": 52,
      "z": 9,
      "name": "Rock_Volcanic_Brick"
    },
    {
      "x": -39,
      "y": 53,
      "z": 9,
      "name": "Rock_Volcanic_Brick"
    },
    {
      "x": -39,
      "y": 54,
      "z": 9,
      "name": "Rock_Volcanic_Brick"
    },
    {
      "x": -39,
      "y": 55,
      "z": 9,
      "name": "Rock_Volcanic_Brick"
    },
    {
      "x": -39,
      "y": 58,
      "z": 9,
      "name": "Rock_Volcanic_Brick"
    },
    {
      "x": -39,
      "y": 59,
      "z": 9,
      "name": "Rock_Volcanic_Brick"
    },
    {
      "x": -39,
      "y": 60,
      "z": 9,
      "name": "Rock_Volcanic_Brick"
    },
    {
      "x": -39,
      "y": 53,
      "z": 10,
      "name": "Rock_Volcanic_Brick"
    },
    {
      "x": -39,
      "y": 54,
      "z": 10,
      "name": "Rock_Volcanic_Brick"
    },
    {
      "x": -39,
      "y": 55,
      "z": 10,
      "name": "Rock_Volcanic_Brick"
    },
    {
      "x": -39,
      "y": 58,
      "z": 10,
      "name": "Rock_Volcanic_Brick"
    },
    {
      "x": -39,
      "y": 59,
      "z": 10,
      "name": "Rock_Volcanic_Brick"
    },
    {
      "x": -39,
      "y": 60,
      "z": 10,
      "name": "Rock_Volcanic_Brick"
    },
    {
      "x": -39,
      "y": 61,
      "z": 10,
      "name": "Rock_Volcanic_Brick"
    },
    {
      "x": -39,
      "y": 57,
      "z": 11,
      "name": "Rock_Volcanic_Brick"
    },
    {
      "x": -39,
      "y": 58,
      "z": 11,
      "name": "Rock_Volcanic_Brick"
    },
    {
      "x": -39,
      "y": 59,
      "z": 11,
      "name": "Rock_Volcanic_Brick"
    },
    {
      "x": -39,
      "y": 60,
      "z": 11,
      "name": "Rock_Volcanic_Brick"
    },
    {
      "x": -39,
      "y": 61,
      "z": 11,
      "name": "Rock_Volcanic_Brick"
    },
    {
      "x": -39,
      "y": 62,
      "z": 11,
      "name": "Rock_Volcanic_Brick"
    },
    {
      "x": -39,
      "y": 57,
      "z": 12,
      "name": "Rock_Volcanic_Brick"
    },
    {
      "x": -39,
      "y": 58,
      "z": 12,
      "name": "Rock_Volcanic_Brick"
    },
    {
      "x": -39,
      "y": 59,
      "z": 12,
      "name": "Rock_Volcanic_Brick"
    },
    {
      "x": -39,
      "y": 60,
      "z": 12,
      "name": "Rock_Volcanic_Brick"
    },
    {
      "x": -39,
      "y": 61,
      "z": 12,
      "name": "Rock_Volcanic_Brick"
    },
    {
      "x": -39,
      "y": 62,
      "z": 12,
      "name": "Rock_Volcanic_Brick"
    },
    {
      "x": -39,
      "y": 58,
      "z": 13,
      "name": "Rock_Volcanic_Brick"
    },
    {
      "x": -39,
      "y": 59,
      "z": 13,
      "name": "Rock_Volcanic_Brick"
    },
    {
      "x": -39,
      "y": 60,
      "z": 13,
      "name": "Rock_Volcanic_Brick"
    },
    {
      "x": -39,
      "y": 61,
      "z": 13,
      "name": "Rock_Volcanic_Brick"
    },
    {
      "x": -38,
      "y": 21,
      "z": -13,
      "name": "Rock_Volcanic_Brick"
    },
    {
      "x": -38,
      "y": 22,
      "z": -13,
      "name": "Rock_Volcanic_Brick"
    },
    {
      "x": -38,
      "y": 20,
      "z": -12,
      "name": "Rock_Volcanic_Brick"
    },
    {
      "x": -38,
      "y": 21,
      "z": -12,
      "name": "Rock_Volcanic_Brick"
    },
    {
      "x": -38,
      "y": 22,
      "z": -12,
      "name": "Rock_Volcanic_Brick"
    },
    {
      "x": -38,
      "y": 23,
      "z": -12,
      "name": "Rock_Volcanic_Brick"
    },
    {
      "x": -38,
      "y": 19,
      "z": -11,
      "name": "Rock_Volcanic_Brick"
    },
    {
      "x": -38,
      "y": 20,
      "z": -11,
      "name": "Rock_Volcanic_Brick"
    },
    {
      "x": -38,
      "y": 21,
      "z": -11,
      "name": "Rock_Volcanic_Brick"
    },
    {
      "x": -38,
      "y": 22,
      "z": -11,
      "name": "Rock_Volcanic_Brick"
    },
    {
      "x": -38,
      "y": 23,
      "z": -11,
      "name": "Rock_Volcanic_Brick"
    },
    {
      "x": -38,
      "y": 24,
      "z": -11,
      "name": "Rock_Volcanic_Brick"
    },
    {
      "x": -38,
      "y": 25,
      "z": -11,
      "name": "Rock_Volcanic_Brick"
    },
    {
      "x": -38,
      "y": 19,
      "z": -10,
      "name": "Rock_Volcanic_Brick"
    },
    {
      "x": -38,
      "y": 20,
      "z": -10,
      "name": "Rock_Volcanic_Brick"
    },
    {
      "x": -38,
      "y": 21,
      "z": -10,
      "name": "Rock_Volcanic_Brick"
    },
    {
      "x": -38,
      "y": 22,
      "z": -10,
      "name": "Rock_Volcanic_Brick"
    },
    {
      "x": -38,
      "y": 23,
      "z": -10,
      "name": "Rock_Volcanic_Brick"
    },
    {
      "x": -38,
      "y": 24,
      "z": -10,
      "name": "Rock_Volcanic_Brick"
    },
    {
      "x": -38,
      "y": 25,
      "z": -10,
      "name": "Rock_Volcanic_Brick"
    },
    {
      "x": -38,
      "y": 20,
      "z": -9,
      "name": "Rock_Volcanic_Brick"
    },
    {
      "x": -38,
      "y": 21,
      "z": -9,
      "name": "Rock_Volcanic_Brick"
    },
    {
      "x": -38,
      "y": 22,
      "z": -9,
      "name": "Rock_Volcanic_Brick"
    },
    {
      "x": -38,
      "y": 23,
      "z": -9,
      "name": "Rock_Volcanic_Brick"
    },
    {
      "x": -38,
      "y": 24,
      "z": -9,
      "name": "Rock_Volcanic_Brick"
    },
    {
      "x": -38,
      "y": 25,
      "z": -9,
      "name": "Rock_Volcanic_Brick"
    },
    {
      "x": -38,
      "y": 26,
      "z": -9,
      "name": "Rock_Volcanic_Brick"
    },
    {
      "x": -38,
      "y": 27,
      "z": -9,
      "name": "Rock_Volcanic_Brick"
    },
    {
      "x": -38,
      "y": 28,
      "z": -9,
      "name": "Rock_Volcanic_Brick"
    },
    {
      "x": -38,
      "y": 22,
      "z": -8,
      "name": "Rock_Volcanic_Brick"
    },
    {
      "x": -38,
      "y": 23,
      "z": -8,
      "name": "Rock_Volcanic_Brick"
    },
    {
      "x": -38,
      "y": 24,
      "z": -8,
      "name": "Rock_Volcanic_Brick"
    },
    {
      "x": -38,
      "y": 26,
      "z": -8,
      "name": "Rock_Volcanic_Brick"
    },
    {
      "x": -38,
      "y": 27,
      "z": -8,
      "name": "Rock_Volcanic_Brick"
    },
    {
      "x": -38,
      "y": 28,
      "z": -8,
      "name": "Rock_Volcanic_Brick"
    },
    {
      "x": -38,
      "y": 29,
      "z": -8,
      "name": "Rock_Volcanic_Brick"
    },
    {
      "x": -38,
      "y": 30,
      "z": -8,
      "name": "Rock_Volcanic_Brick"
    },
    {
      "x": -38,
      "y": 25,
      "z": -7,
      "name": "Rock_Volcanic_Brick"
    },
    {
      "x": -38,
      "y": 26,
      "z": -7,
      "name": "Rock_Volcanic_Brick"
    },
    {
      "x": -38,
      "y": 27,
      "z": -7,
      "name": "Rock_Volcanic_Brick"
    },
    {
      "x": -38,
      "y": 28,
      "z": -7,
      "name": "Rock_Volcanic_Brick"
    },
    {
      "x": -38,
      "y": 29,
      "z": -7,
      "name": "Rock_Volcanic_Brick"
    },
    {
      "x": -38,
      "y": 30,
      "z": -7,
      "name": "Rock_Volcanic_Brick"
    },
    {
      "x": -38,
      "y": 31,
      "z": -7,
      "name": "Rock_Volcanic_Brick"
    },
    {
      "x": -38,
      "y": 32,
      "z": -7,
      "name": "Rock_Volcanic_Brick"
    },
    {
      "x": -38,
      "y": 26,
      "z": -6,
      "name": "Rock_Volcanic_Brick"
    },
    {
      "x": -38,
      "y": 27,
      "z": -6,
      "name": "Rock_Volcanic_Brick"
    },
    {
      "x": -38,
      "y": 28,
      "z": -6,
      "name": "Rock_Volcanic_Brick"
    },
    {
      "x": -38,
      "y": 29,
      "z": -6,
      "name": "Rock_Volcanic_Brick"
    },
    {
      "x": -38,
      "y": 30,
      "z": -6,
      "name": "Rock_Volcanic_Brick"
    },
    {
      "x": -38,
      "y": 31,
      "z": -6,
      "name": "Rock_Volcanic_Brick"
    },
    {
      "x": -38,
      "y": 32,
      "z": -6,
      "name": "Rock_Volcanic_Brick"
    },
    {
      "x": -38,
      "y": 33,
      "z": -6,
      "name": "Rock_Volcanic_Brick"
    },
    {
      "x": -38,
      "y": 34,
      "z": -6,
      "name": "Rock_Volcanic_Brick"
    },
    {
      "x": -38,
      "y": 27,
      "z": -5,
      "name": "Rock_Volcanic_Brick"
    },
    {
      "x": -38,
      "y": 28,
      "z": -5,
      "name": "Rock_Volcanic_Brick"
    },
    {
      "x": -38,
      "y": 29,
      "z": -5,
      "name": "Rock_Volcanic_Brick"
    },
    {
      "x": -38,
      "y": 30,
      "z": -5,
      "name": "Rock_Volcanic_Brick"
    },
    {
      "x": -38,
      "y": 31,
      "z": -5,
      "name": "Rock_Volcanic_Brick"
    },
    {
      "x": -38,
      "y": 32,
      "z": -5,
      "name": "Rock_Volcanic_Brick"
    },
    {
      "x": -38,
      "y": 33,
      "z": -5,
      "name": "Rock_Volcanic_Brick"
    },
    {
      "x": -38,
      "y": 34,
      "z": -5,
      "name": "Rock_Volcanic_Brick"
    },
    {
      "x": -38,
      "y": 35,
      "z": -5,
      "name": "Rock_Volcanic_Brick"
    },
    {
      "x": -38,
      "y": 29,
      "z": -4,
      "name": "Rock_Volcanic_Brick"
    },
    {
      "x": -38,
      "y": 30,
      "z": -4,
      "name": "Rock_Volcanic_Brick"
    },
    {
      "x": -38,
      "y": 31,
      "z": -4,
      "name": "Rock_Volcanic_Brick"
    },
    {
      "x": -38,
      "y": 32,
      "z": -4,
      "name": "Rock_Volcanic_Brick"
    },
    {
      "x": -38,
      "y": 33,
      "z": -4,
      "name": "Rock_Volcanic_Brick"
    },
    {
      "x": -38,
      "y": 34,
      "z": -4,
      "name": "Rock_Volcanic_Brick"
    },
    {
      "x": -38,
      "y": 35,
      "z": -4,
      "name": "Rock_Volcanic_Brick"
    },
    {
      "x": -38,
      "y": 36,
      "z": -4,
      "name": "Rock_Volcanic_Brick"
    },
    {
      "x": -38,
      "y": 37,
      "z": -4,
      "name": "Rock_Volcanic_Brick"
    },
    {
      "x": -38,
      "y": 30,
      "z": -3,
      "name": "Rock_Volcanic_Brick"
    },
    {
      "x": -38,
      "y": 31,
      "z": -3,
      "name": "Rock_Volcanic_Brick"
    },
    {
      "x": -38,
      "y": 32,
      "z": -3,
      "name": "Rock_Volcanic_Brick"
    },
    {
      "x": -38,
      "y": 33,
      "z": -3,
      "name": "Rock_Volcanic_Brick"
    },
    {
      "x": -38,
      "y": 34,
      "z": -3,
      "name": "Rock_Volcanic_Brick"
    },
    {
      "x": -38,
      "y": 35,
      "z": -3,
      "name": "Rock_Volcanic_Brick"
    },
    {
      "x": -38,
      "y": 36,
      "z": -3,
      "name": "Rock_Volcanic_Brick"
    },
    {
      "x": -38,
      "y": 37,
      "z": -3,
      "name": "Rock_Volcanic_Brick"
    },
    {
      "x": -38,
      "y": 38,
      "z": -3,
      "name": "Rock_Volcanic_Brick"
    },
    {
      "x": -38,
      "y": 39,
      "z": -3,
      "name": "Rock_Volcanic_Brick"
    },
    {
      "x": -38,
      "y": 32,
      "z": -2,
      "name": "Rock_Volcanic_Brick"
    },
    {
      "x": -38,
      "y": 33,
      "z": -2,
      "name": "Rock_Volcanic_Brick"
    },
    {
      "x": -38,
      "y": 34,
      "z": -2,
      "name": "Rock_Volcanic_Brick"
    },
    {
      "x": -38,
      "y": 35,
      "z": -2,
      "name": "Rock_Volcanic_Brick"
    },
    {
      "x": -38,
      "y": 36,
      "z": -2,
      "name": "Rock_Volcanic_Brick"
    },
    {
      "x": -38,
      "y": 37,
      "z": -2,
      "name": "Rock_Volcanic_Brick"
    },
    {
      "x": -38,
      "y": 38,
      "z": -2,
      "name": "Rock_Volcanic_Brick"
    },
    {
      "x": -38,
      "y": 39,
      "z": -2,
      "name": "Rock_Volcanic_Brick"
    },
    {
      "x": -38,
      "y": 40,
      "z": -2,
      "name": "Rock_Volcanic_Brick"
    },
    {
      "x": -38,
      "y": 41,
      "z": -2,
      "name": "Rock_Volcanic_Brick"
    },
    {
      "x": -38,
      "y": 34,
      "z": -1,
      "name": "Rock_Volcanic_Brick"
    },
    {
      "x": -38,
      "y": 35,
      "z": -1,
      "name": "Rock_Volcanic_Brick"
    },
    {
      "x": -38,
      "y": 36,
      "z": -1,
      "name": "Rock_Volcanic_Brick"
    },
    {
      "x": -38,
      "y": 37,
      "z": -1,
      "name": "Rock_Volcanic_Brick"
    },
    {
      "x": -38,
      "y": 38,
      "z": -1,
      "name": "Rock_Volcanic_Brick"
    },
    {
      "x": -38,
      "y": 39,
      "z": -1,
      "name": "Rock_Volcanic_Brick"
    },
    {
      "x": -38,
      "y": 40,
      "z": -1,
      "name": "Rock_Volcanic_Brick"
    },
    {
      "x": -38,
      "y": 41,
      "z": -1,
      "name": "Rock_Volcanic_Brick"
    },
    {
      "x": -38,
      "y": 42,
      "z": -1,
      "name": "Rock_Volcanic_Brick"
    },
    {
      "x": -38,
      "y": 36,
      "z": 0,
      "name": "Rock_Volcanic_Brick"
    },
    {
      "x": -38,
      "y": 37,
      "z": 0,
      "name": "Rock_Volcanic_Brick"
    },
    {
      "x": -38,
      "y": 38,
      "z": 0,
      "name": "Rock_Volcanic_Brick"
    },
    {
      "x": -38,
      "y": 39,
      "z": 0,
      "name": "Rock_Volcanic_Brick"
    },
    {
      "x": -38,
      "y": 40,
      "z": 0,
      "name": "Rock_Volcanic_Brick"
    },
    {
      "x": -38,
      "y": 41,
      "z": 0,
      "name": "Rock_Volcanic_Brick"
    },
    {
      "x": -38,
      "y": 42,
      "z": 0,
      "name": "Rock_Volcanic_Brick"
    },
    {
      "x": -38,
      "y": 43,
      "z": 0,
      "name": "Rock_Volcanic_Brick"
    },
    {
      "x": -38,
      "y": 44,
      "z": 0,
      "name": "Rock_Volcanic_Brick"
    },
    {
      "x": -38,
      "y": 37,
      "z": 1,
      "name": "Rock_Volcanic_Brick"
    },
    {
      "x": -38,
      "y": 38,
      "z": 1,
      "name": "Rock_Volcanic_Brick"
    },
    {
      "x": -38,
      "y": 39,
      "z": 1,
      "name": "Rock_Volcanic_Brick"
    },
    {
      "x": -38,
      "y": 40,
      "z": 1,
      "name": "Rock_Volcanic_Brick"
    },
    {
      "x": -38,
      "y": 41,
      "z": 1,
      "name": "Rock_Volcanic_Brick"
    },
    {
      "x": -38,
      "y": 42,
      "z": 1,
      "name": "Rock_Volcanic_Brick"
    },
    {
      "x": -38,
      "y": 43,
      "z": 1,
      "name": "Rock_Volcanic_Brick"
    },
    {
      "x": -38,
      "y": 44,
      "z": 1,
      "name": "Rock_Volcanic_Brick"
    },
    {
      "x": -38,
      "y": 45,
      "z": 1,
      "name": "Rock_Volcanic_Brick"
    },
    {
      "x": -38,
      "y": 46,
      "z": 1,
      "name": "Rock_Volcanic_Brick"
    },
    {
      "x": -38,
      "y": 39,
      "z": 2,
      "name": "Rock_Volcanic_Brick"
    },
    {
      "x": -38,
      "y": 40,
      "z": 2,
      "name": "Rock_Volcanic_Brick"
    },
    {
      "x": -38,
      "y": 41,
      "z": 2,
      "name": "Rock_Volcanic_Brick"
    },
    {
      "x": -38,
      "y": 42,
      "z": 2,
      "name": "Rock_Volcanic_Brick"
    },
    {
      "x": -38,
      "y": 43,
      "z": 2,
      "name": "Rock_Volcanic_Brick"
    },
    {
      "x": -38,
      "y": 44,
      "z": 2,
      "name": "Rock_Volcanic_Brick"
    },
    {
      "x": -38,
      "y": 45,
      "z": 2,
      "name": "Rock_Volcanic_Brick"
    },
    {
      "x": -38,
      "y": 46,
      "z": 2,
      "name": "Rock_Volcanic_Brick"
    },
    {
      "x": -38,
      "y": 47,
      "z": 2,
      "name": "Rock_Volcanic_Brick"
    },
    {
      "x": -38,
      "y": 48,
      "z": 2,
      "name": "Rock_Volcanic_Brick"
    },
    {
      "x": -38,
      "y": 41,
      "z": 3,
      "name": "Rock_Volcanic_Brick"
    },
    {
      "x": -38,
      "y": 42,
      "z": 3,
      "name": "Rock_Volcanic_Brick"
    },
    {
      "x": -38,
      "y": 43,
      "z": 3,
      "name": "Rock_Volcanic_Brick"
    },
    {
      "x": -38,
      "y": 44,
      "z": 3,
      "name": "Rock_Volcanic_Brick"
    },
    {
      "x": -38,
      "y": 45,
      "z": 3,
      "name": "Rock_Volcanic_Brick"
    },
    {
      "x": -38,
      "y": 46,
      "z": 3,
      "name": "Rock_Volcanic_Brick"
    },
    {
      "x": -38,
      "y": 47,
      "z": 3,
      "name": "Rock_Volcanic_Brick"
    },
    {
      "x": -38,
      "y": 48,
      "z": 3,
      "name": "Rock_Volcanic_Brick"
    },
    {
      "x": -38,
      "y": 49,
      "z": 3,
      "name": "Rock_Volcanic_Brick"
    },
    {
      "x": -38,
      "y": 42,
      "z": 4,
      "name": "Rock_Volcanic_Brick"
    },
    {
      "x": -38,
      "y": 43,
      "z": 4,
      "name": "Rock_Volcanic_Brick"
    },
    {
      "x": -38,
      "y": 44,
      "z": 4,
      "name": "Rock_Volcanic_Brick"
    },
    {
      "x": -38,
      "y": 45,
      "z": 4,
      "name": "Rock_Volcanic_Brick"
    },
    {
      "x": -38,
      "y": 46,
      "z": 4,
      "name": "Rock_Volcanic_Brick"
    },
    {
      "x": -38,
      "y": 47,
      "z": 4,
      "name": "Rock_Volcanic_Brick"
    },
    {
      "x": -38,
      "y": 48,
      "z": 4,
      "name": "Rock_Volcanic_Brick"
    },
    {
      "x": -38,
      "y": 49,
      "z": 4,
      "name": "Rock_Volcanic_Brick"
    },
    {
      "x": -38,
      "y": 50,
      "z": 4,
      "name": "Rock_Volcanic_Brick"
    },
    {
      "x": -38,
      "y": 51,
      "z": 4,
      "name": "Rock_Volcanic_Brick"
    },
    {
      "x": -38,
      "y": 44,
      "z": 5,
      "name": "Rock_Volcanic_Brick"
    },
    {
      "x": -38,
      "y": 45,
      "z": 5,
      "name": "Rock_Volcanic_Brick"
    },
    {
      "x": -38,
      "y": 46,
      "z": 5,
      "name": "Rock_Volcanic_Brick"
    },
    {
      "x": -38,
      "y": 47,
      "z": 5,
      "name": "Rock_Volcanic_Brick"
    },
    {
      "x": -38,
      "y": 48,
      "z": 5,
      "name": "Rock_Volcanic_Brick"
    },
    {
      "x": -38,
      "y": 49,
      "z": 5,
      "name": "Rock_Volcanic_Brick"
    },
    {
      "x": -38,
