{
  "version": 8,
  "blockIdVersion": 11,
  "anchorX": -1,
  "anchorY": 20,
  "anchorZ": 1,
  "blocks": [
    {
      "x": -18,
      "y": 16,
      "z": -11,
      "name": "Rock_Volcanic_Brick"
    },
    {
      "x": -18,
      "y": 14,
      "z": -10,
      "name": "Rock_Volcanic_Brick"
    },
    {
      "x": -17,
      "y": 20,
      "z": -13,
      "name": "Rock_Volcanic_Brick"
    },
    {
      "x": -17,
      "y": 15,
      "z": -12,
      "name": "Rock_Volcanic_Brick"
    },
    {
      "x": -17,
      "y": 16,
      "z": -12,
      "name": "Rock_Volcanic_Brick"
    },
    {
      "x": -17,
      "y": 19,
      "z": -12,
      "name": "Rock_Volcanic_Brick"
    },
    {
      "x": -17,
      "y": 20,
      "z": -12,
      "name": "Rock_Volcanic_Brick"
    },
    {
      "x": -17,
      "y": 21,
      "z": -12,
      "name": "Rock_Volcanic_Brick"
    },
    {
      "x": -17,
      "y": 22,
      "z": -12,
      "name": "Rock_Volcanic_Brick"
    },
    {
      "x": -17,
      "y": 13,
      "z": -11,
      "name": "Rock_Volcanic_Brick"
    },
    {
      "x": -17,
      "y": 14,
      "z": -11,
      "name": "Rock_Volcanic_Brick"
    },
    {
      "x": -17,
      "y": 15,
      "z": -11,
      "name": "Rock_Volcanic_Brick"
    },
    {
      "x": -17,
      "y": 16,
      "z": -11,
      "name": "Rock_Volcanic_Brick"
    },
    {
      "x": -17,
      "y": 17,
      "z": -11,
      "name": "Rock_Volcanic_Brick"
    },
    {
      "x": -17,
      "y": 20,
      "z": -11,
      "name": "Rock_Volcanic_Brick"
    },
    {
      "x": -17,
      "y": 13,
      "z": -10,
      "name": "Rock_Volcanic_Brick"
    },
    {
      "x": -17,
      "y": 14,
      "z": -10,
      "name": "Rock_Volcanic_Brick"
    },
    {
      "x": -17,
      "y": 15,
      "z": -10,
      "name": "Rock_Volcanic_Brick"
    },
    {
      "x": -17,
      "y": 16,
      "z": -10,
      "name": "Rock_Volcanic_Brick"
    },
    {
      "x": -17,
      "y": 17,
      "z": -10,
      "name": "Rock_Volcanic_Brick"
    },
    {
      "x": -17,
      "y": 13,
      "z": -9,
      "name": "Rock_Volcanic_Brick"
    },
    {
      "x": -17,
      "y": 14,
      "z": -9,
      "name": "Rock_Volcanic_Brick"
    },
    {
      "x": -17,
      "y": 15,
      "z": -9,
      "name": "Rock_Volcanic_Brick"
    },
    {
      "x": -17,
      "y": 16,
      "z": -9,
      "name": "Rock_Volcanic_Brick"
    },
    {
      "x": -17,
      "y": 10,
      "z": -8,
      "name": "Rock_Volcanic_Brick"
    },
    {
      "x": -17,
      "y": 14,
      "z": -8,
      "name": "Rock_Volcanic_Brick"
    },
    {
      "x": -17,
      "y": 9,
      "z": -7,
      "name": "Rock_Volcanic_Brick"
    },
    {
      "x": -17,
      "y": 10,
      "z": -7,
      "name": "Rock_Volcanic_Brick"
    },
    {
      "x": -17,
      "y": 9,
      "z": -6,
      "name": "Rock_Volcanic_Brick"
    },
    {
      "x": -16,
      "y": 20,
      "z": -14,
      "name": "Rock_Volcanic_Brick"
    },
    {
      "x": -16,
      "y": 21,
      "z": -14,
      "name": "Rock_Volcanic_Brick"
    },
    {
      "x": -16,
      "y": 22,
      "z": -14,
      "name": "Rock_Volcanic_Brick"
    },
    {
      "x": -16,
      "y": 19,
      "z": -13,
      "name": "Rock_Volcanic_Brick"
    },
    {
      "x": -16,
      "y": 20,
      "z": -13,
      "name": "Rock_Volcanic_Brick"
    },
    {
      "x": -16,
      "y": 21,
      "z": -13,
      "name": "Rock_Volcanic_Brick"
    },
    {
      "x": -16,
      "y": 22,
      "z": -13,
      "name": "Rock_Volcanic_Brick"
    },
    {
      "x": -16,
      "y": 23,
      "z": -13,
      "name": "Rock_Volcanic_Brick"
    },
    {
      "x": -16,
      "y": 14,
      "z": -12,
      "name": "Rock_Volcanic_Brick"
    },
    {
      "x": -16,
      "y": 15,
      "z": -12,
      "name": "Rock_Volcanic_Brick"
    },
    {
      "x": -16,
      "y": 16,
      "z": -12,
      "name": "Rock_Volcanic_Brick"
    },
    {
      "x": -16,
      "y": 19,
      "z": -12,
      "name": "Rock_Volcanic_Brick"
    },
    {
      "x": -16,
      "y": 20,
      "z": -12,
      "name": "Rock_Volcanic_Brick"
    },
    {
      "x": -16,
      "y": 21,
      "z": -12,
      "name": "Rock_Volcanic_Brick"
    },
    {
      "x": -16,
      "y": 22,
      "z": -12,
      "name": "Rock_Volcanic_Brick"
    },
    {
      "x": -16,
      "y": 23,
      "z": -12,
      "name": "Rock_Volcanic_Brick"
    },
    {
      "x": -16,
      "y": 13,
      "z": -11,
      "name": "Rock_Volcanic_Brick"
    },
    {
      "x": -16,
      "y": 14,
      "z": -11,
      "name": "Rock_Volcanic_Brick"
    },
    {
      "x": -16,
      "y": 15,
      "z": -11,
      "name": "Rock_Volcanic_Brick"
    },
    {
      "x": -16,
      "y": 16,
      "z": -11,
      "name": "Rock_Volcanic_Brick"
    },
    {
      "x": -16,
      "y": 17,
      "z": -11,
      "name": "Rock_Volcanic_Brick"
    },
    {
      "x": -16,
      "y": 19,
      "z": -11,
      "name": "Rock_Volcanic_Brick"
    },
    {
      "x": -16,
      "y": 20,
      "z": -11,
      "name": "Rock_Volcanic_Brick"
    },
    {
      "x": -16,
      "y": 21,
      "z": -11,
      "name": "Rock_Volcanic_Brick"
    },
    {
      "x": -16,
      "y": 22,
      "z": -11,
      "name": "Rock_Volcanic_Brick"
    },
    {
      "x": -16,
      "y": 12,
      "z": -10,
      "name": "Rock_Volcanic_Brick"
    },
    {
      "x": -16,
      "y": 13,
      "z": -10,
      "name": "Rock_Volcanic_Brick"
    },
    {
      "x": -16,
      "y": 14,
      "z": -10,
      "name": "Rock_Volcanic_Brick"
    },
    {
      "x": -16,
      "y": 15,
      "z": -10,
      "name": "Rock_Volcanic_Brick"
    },
    {
      "x": -16,
      "y": 16,
      "z": -10,
      "name": "Rock_Volcanic_Brick"
    },
    {
      "x": -16,
      "y": 17,
      "z": -10,
      "name": "Rock_Volcanic_Brick"
    },
    {
      "x": -16,
      "y": 9,
      "z": -9,
      "name": "Rock_Volcanic_Brick"
    },
    {
      "x": -16,
      "y": 10,
      "z": -9,
      "name": "Rock_Volcanic_Brick"
    },
    {
      "x": -16,
      "y": 13,
      "z": -9,
      "name": "Rock_Volcanic_Brick"
    },
    {
      "x": -16,
      "y": 14,
      "z": -9,
      "name": "Rock_Volcanic_Brick"
    },
    {
      "x": -16,
      "y": 15,
      "z": -9,
      "name": "Rock_Volcanic_Brick"
    },
    {
      "x": -16,
      "y": 16,
      "z": -9,
      "name": "Rock_Volcanic_Brick"
    },
    {
      "x": -16,
      "y": 17,
      "z": -9,
      "name": "Rock_Volcanic_Brick"
    },
    {
      "x": -16,
      "y": 8,
      "z": -8,
      "name": "Rock_Volcanic_Brick"
    },
    {
      "x": -16,
      "y": 9,
      "z": -8,
      "name": "Rock_Volcanic_Brick"
    },
    {
      "x": -16,
      "y": 10,
      "z": -8,
      "name": "Rock_Volcanic_Brick"
    },
    {
      "x": -16,
      "y": 13,
      "z": -8,
      "name": "Rock_Volcanic_Brick"
    },
    {
      "x": -16,
      "y": 14,
      "z": -8,
      "name": "Rock_Volcanic_Brick"
    },
    {
      "x": -16,
      "y": 15,
      "z": -8,
      "name": "Rock_Volcanic_Brick"
    },
    {
      "x": -16,
      "y": 16,
      "z": -8,
      "name": "Rock_Volcanic_Brick"
    },
    {
      "x": -16,
      "y": 7,
      "z": -7,
      "name": "Rock_Volcanic_Brick"
    },
    {
      "x": -16,
      "y": 8,
      "z": -7,
      "name": "Rock_Volcanic_Brick"
    },
    {
      "x": -16,
      "y": 9,
      "z": -7,
      "name": "Rock_Volcanic_Brick"
    },
    {
      "x": -16,
      "y": 10,
      "z": -7,
      "name": "Rock_Volcanic_Brick"
    },
    {
      "x": -16,
      "y": 11,
      "z": -7,
      "name": "Rock_Volcanic_Brick"
    },
    {
      "x": -16,
      "y": 7,
      "z": -6,
      "name": "Rock_Volcanic_Brick"
    },
    {
      "x": -16,
      "y": 8,
      "z": -6,
      "name": "Rock_Volcanic_Brick"
    },
    {
      "x": -16,
      "y": 9,
      "z": -6,
      "name": "Rock_Volcanic_Brick"
    },
    {
      "x": -16,
      "y": 10,
      "z": -6,
      "name": "Rock_Volcanic_Brick"
    },
    {
      "x": -16,
      "y": 11,
      "z": -6,
      "name": "Rock_Volcanic_Brick"
    },
    {
      "x": -16,
      "y": 7,
      "z": -5,
      "name": "Rock_Volcanic_Brick"
    },
    {
      "x": -16,
      "y": 8,
      "z": -5,
      "name": "Rock_Volcanic_Brick"
    },
    {
      "x": -16,
      "y": 9,
      "z": -5,
      "name": "Rock_Volcanic_Brick"
    },
    {
      "x": -15,
      "y": 20,
      "z": -14,
      "name": "Rock_Volcanic_Brick"
    },
    {
      "x": -15,
      "y": 21,
      "z": -14,
      "name": "Rock_Volcanic_Brick"
    },
    {
      "x": -15,
      "y": 22,
      "z": -14,
      "name": "Rock_Volcanic_Brick"
    },
    {
      "x": -15,
      "y": 23,
      "z": -14,
      "name": "Rock_Volcanic_Brick"
    },
    {
      "x": -15,
      "y": 19,
      "z": -13,
      "name": "Rock_Volcanic_Brick"
    },
    {
      "x": -15,
      "y": 20,
      "z": -13,
      "name": "Rock_Volcanic_Brick"
    },
    {
      "x": -15,
      "y": 21,
      "z": -13,
      "name": "Rock_Volcanic_Brick"
    },
    {
      "x": -15,
      "y": 22,
      "z": -13,
      "name": "Rock_Volcanic_Brick"
    },
    {
      "x": -15,
      "y": 23,
      "z": -13,
      "name": "Rock_Volcanic_Brick"
    },
    {
      "x": -15,
      "y": 19,
      "z": -12,
      "name": "Rock_Volcanic_Brick"
    },
    {
      "x": -15,
      "y": 20,
      "z": -12,
      "name": "Rock_Volcanic_Brick"
    },
    {
      "x": -15,
      "y": 21,
      "z": -12,
      "name": "Rock_Volcanic_Brick"
    },
    {
      "x": -15,
      "y": 22,
      "z": -12,
      "name": "Rock_Volcanic_Brick"
    },
    {
      "x": -15,
      "y": 23,
      "z": -12,
      "name": "Rock_Volcanic_Brick"
    },
    {
      "x": -15,
      "y": 13,
      "z": -11,
      "name": "Rock_Volcanic_Brick"
    },
    {
      "x": -15,
      "y": 14,
      "z": -11,
      "name": "Rock_Volcanic_Brick"
    },
    {
      "x": -15,
      "y": 15,
      "z": -11,
      "name": "Rock_Volcanic_Brick"
    },
    {
      "x": -15,
      "y": 16,
      "z": -11,
      "name": "Rock_Volcanic_Brick"
    },
    {
      "x": -15,
      "y": 17,
      "z": -11,
      "name": "Rock_Volcanic_Brick"
    },
    {
      "x": -15,
      "y": 18,
      "z": -11,
      "name": "Rock_Volcanic_Brick"
    },
    {
      "x": -15,
      "y": 19,
      "z": -11,
      "name": "Rock_Volcanic_Brick"
    },
    {
      "x": -15,
      "y": 20,
      "z": -11,
      "name": "Rock_Volcanic_Brick"
    },
    {
      "x": -15,
      "y": 21,
      "z": -11,
      "name": "Rock_Volcanic_Brick"
    },
    {
      "x": -15,
      "y": 22,
      "z": -11,
      "name": "Rock_Volcanic_Brick"
    },
    {
      "x": -15,
      "y": 23,
      "z": -11,
      "name": "Rock_Volcanic_Brick"
    },
    {
      "x": -15,
      "y": 13,
      "z": -10,
      "name": "Rock_Volcanic_Brick"
    },
    {
      "x": -15,
      "y": 14,
      "z": -10,
      "name": "Rock_Volcanic_Brick"
    },
    {
      "x": -15,
      "y": 15,
      "z": -10,
      "name": "Rock_Volcanic_Brick"
    },
    {
      "x": -15,
      "y": 16,
      "z": -10,
      "name": "Rock_Volcanic_Brick"
    },
    {
      "x": -15,
      "y": 17,
      "z": -10,
      "name": "Rock_Volcanic_Brick"
    },
    {
      "x": -15,
      "y": 18,
      "z": -10,
      "name": "Rock_Volcanic_Brick"
    },
    {
      "x": -15,
      "y": 19,
      "z": -10,
      "name": "Rock_Volcanic_Brick"
    },
    {
      "x": -15,
      "y": 20,
      "z": -10,
      "name": "Rock_Volcanic_Brick"
    },
    {
      "x": -15,
      "y": 21,
      "z": -10,
      "name": "Rock_Volcanic_Brick"
    },
    {
      "x": -15,
      "y": 22,
      "z": -10,
      "name": "Rock_Volcanic_Brick"
    },
    {
      "x": -15,
      "y": 9,
      "z": -9,
      "name": "Rock_Volcanic_Brick"
    },
    {
      "x": -15,
      "y": 13,
      "z": -9,
      "name": "Rock_Volcanic_Brick"
    },
    {
      "x": -15,
      "y": 14,
      "z": -9,
      "name": "Rock_Volcanic_Brick"
    },
    {
      "x": -15,
      "y": 15,
      "z": -9,
      "name": "Rock_Volcanic_Brick"
    },
    {
      "x": -15,
      "y": 16,
      "z": -9,
      "name": "Rock_Volcanic_Brick"
    },
    {
      "x": -15,
      "y": 17,
      "z": -9,
      "name": "Rock_Volcanic_Brick"
    },
    {
      "x": -15,
      "y": 18,
      "z": -9,
      "name": "Rock_Volcanic_Brick"
    },
    {
      "x": -15,
      "y": 19,
      "z": -9,
      "name": "Rock_Volcanic_Brick"
    },
    {
      "x": -15,
      "y": 8,
      "z": -8,
      "name": "Rock_Volcanic_Brick"
    },
    {
      "x": -15,
      "y": 9,
      "z": -8,
      "name": "Rock_Volcanic_Brick"
    },
    {
      "x": -15,
      "y": 10,
      "z": -8,
      "name": "Rock_Volcanic_Brick"
    },
    {
      "x": -15,
      "y": 11,
      "z": -8,
      "name": "Rock_Volcanic_Brick"
    },
    {
      "x": -15,
      "y": 12,
      "z": -8,
      "name": "Rock_Volcanic_Brick"
    },
    {
      "x": -15,
      "y": 13,
      "z": -8,
      "name": "Rock_Volcanic_Brick"
    },
    {
      "x": -15,
      "y": 14,
      "z": -8,
      "name": "Rock_Volcanic_Brick"
    },
    {
      "x": -15,
      "y": 15,
      "z": -8,
      "name": "Rock_Volcanic_Brick"
    },
    {
      "x": -15,
      "y": 16,
      "z": -8,
      "name": "Rock_Volcanic_Brick"
    },
    {
      "x": -15,
      "y": 17,
      "z": -8,
      "name": "Rock_Volcanic_Brick"
    },
    {
      "x": -15,
      "y": 7,
      "z": -7,
      "name": "Rock_Volcanic_Brick"
    },
    {
      "x": -15,
      "y": 8,
      "z": -7,
      "name": "Rock_Volcanic_Brick"
    },
    {
      "x": -15,
      "y": 9,
      "z": -7,
      "name": "Rock_Volcanic_Brick"
    },
    {
      "x": -15,
      "y": 10,
      "z": -7,
      "name": "Rock_Volcanic_Brick"
    },
    {
      "x": -15,
      "y": 11,
      "z": -7,
      "name": "Rock_Volcanic_Brick"
    },
    {
      "x": -15,
      "y": 12,
      "z": -7,
      "name": "Rock_Volcanic_Brick"
    },
    {
      "x": -15,
      "y": 13,
      "z": -7,
      "name": "Rock_Volcanic_Brick"
    },
    {
      "x": -15,
      "y": 14,
      "z": -7,
      "name": "Rock_Volcanic_Brick"
    },
    {
      "x": -15,
      "y": 15,
      "z": -7,
      "name": "Rock_Volcanic_Brick"
    },
    {
      "x": -15,
      "y": 7,
      "z": -6,
      "name": "Rock_Volcanic_Brick"
    },
    {
      "x": -15,
      "y": 8,
      "z": -6,
      "name": "Rock_Volcanic_Brick"
    },
    {
      "x": -15,
      "y": 9,
      "z": -6,
      "name": "Rock_Volcanic_Brick"
    },
    {
      "x": -15,
      "y": 10,
      "z": -6,
      "name": "Rock_Volcanic_Brick"
    },
    {
      "x": -15,
      "y": 11,
      "z": -6,
      "name": "Rock_Volcanic_Brick"
    },
    {
      "x": -15,
      "y": 12,
      "z": -6,
      "name": "Rock_Volcanic_Brick"
    },
    {
      "x": -15,
      "y": 13,
      "z": -6,
      "name": "Rock_Volcanic_Brick"
    },
    {
      "x": -15,
      "y": 7,
      "z": -5,
      "name": "Rock_Volcanic_Brick"
    },
    {
      "x": -15,
      "y": 8,
      "z": -5,
      "name": "Rock_Volcanic_Brick"
    },
    {
      "x": -15,
      "y": 9,
      "z": -5,
      "name": "Rock_Volcanic_Brick"
    },
    {
      "x": -15,
      "y": 10,
      "z": -5,
      "name": "Rock_Volcanic_Brick"
    },
    {
      "x": -15,
      "y": 11,
      "z": -5,
      "name": "Rock_Volcanic_Brick"
    },
    {
      "x": -14,
      "y": 22,
      "z": -14,
      "name": "Rock_Volcanic_Brick"
    },
    {
      "x": -14,
      "y": 23,
      "z": -14,
      "name": "Rock_Volcanic_Brick"
    },
    {
      "x": -14,
      "y": 26,
      "z": -14,
      "name": "Rock_Volcanic_Brick"
    },
    {
      "x": -14,
      "y": 27,
      "z": -14,
      "name": "Rock_Volcanic_Brick"
    },
    {
      "x": -14,
      "y": 19,
      "z": -13,
      "name": "Rock_Volcanic_Brick"
    },
    {
      "x": -14,
      "y": 20,
      "z": -13,
      "name": "Rock_Volcanic_Brick"
    },
    {
      "x": -14,
      "y": 21,
      "z": -13,
      "name": "Rock_Volcanic_Brick"
    },
    {
      "x": -14,
      "y": 22,
      "z": -13,
      "name": "Rock_Volcanic_Brick"
    },
    {
      "x": -14,
      "y": 23,
      "z": -13,
      "name": "Rock_Volcanic_Brick"
    },
    {
      "x": -14,
      "y": 26,
      "z": -13,
      "name": "Rock_Volcanic_Brick"
    },
    {
      "x": -14,
      "y": 27,
      "z": -13,
      "name": "Rock_Volcanic_Brick"
    },
    {
      "x": -14,
      "y": 28,
      "z": -13,
      "name": "Rock_Volcanic_Brick"
    },
    {
      "x": -14,
      "y": 18,
      "z": -12,
      "name": "Rock_Volcanic_Brick"
    },
    {
      "x": -14,
      "y": 19,
      "z": -12,
      "name": "Rock_Volcanic_Brick"
    },
    {
      "x": -14,
      "y": 20,
      "z": -12,
      "name": "Rock_Volcanic_Brick"
    },
    {
      "x": -14,
      "y": 21,
      "z": -12,
      "name": "Rock_Volcanic_Brick"
    },
    {
      "x": -14,
      "y": 22,
      "z": -12,
      "name": "Rock_Volcanic_Brick"
    },
    {
      "x": -14,
      "y": 23,
      "z": -12,
      "name": "Rock_Volcanic_Brick"
    },
    {
      "x": -14,
      "y": 26,
      "z": -12,
      "name": "Rock_Volcanic_Brick"
    },
    {
      "x": -14,
      "y": 27,
      "z": -12,
      "name": "Rock_Volcanic_Brick"
    },
    {
      "x": -14,
      "y": 28,
      "z": -12,
      "name": "Rock_Volcanic_Brick"
    },
    {
      "x": -14,
      "y": 15,
      "z": -11,
      "name": "Rock_Volcanic_Brick"
    },
    {
      "x": -14,
      "y": 16,
      "z": -11,
      "name": "Rock_Volcanic_Brick"
    },
    {
      "x": -14,
      "y": 17,
      "z": -11,
      "name": "Rock_Volcanic_Brick"
    },
    {
      "x": -14,
      "y": 18,
      "z": -11,
      "name": "Rock_Volcanic_Brick"
    },
    {
      "x": -14,
      "y": 19,
      "z": -11,
      "name": "Rock_Volcanic_Brick"
    },
    {
      "x": -14,
      "y": 20,
      "z": -11,
      "name": "Rock_Volcanic_Brick"
    },
    {
      "x": -14,
      "y": 21,
      "z": -11,
      "name": "Rock_Volcanic_Brick"
    },
    {
      "x": -14,
      "y": 22,
      "z": -11,
      "name": "Rock_Volcanic_Brick"
    },
    {
      "x": -14,
      "y": 23,
      "z": -11,
      "name": "Rock_Volcanic_Brick"
    },
    {
      "x": -14,
      "y": 24,
      "z": -11,
      "name": "Rock_Volcanic_Brick"
    },
    {
      "x": -14,
      "y": 13,
      "z": -10,
      "name": "Rock_Volcanic_Brick"
    },
    {
      "x": -14,
      "y": 14,
      "z": -10,
      "name": "Rock_Volcanic_Brick"
    },
    {
      "x": -14,
      "y": 15,
      "z": -10,
      "name": "Rock_Volcanic_Brick"
    },
    {
      "x": -14,
      "y": 16,
      "z": -10,
      "name": "Rock_Volcanic_Brick"
    },
    {
      "x": -14,
      "y": 17,
      "z": -10,
      "name": "Rock_Volcanic_Brick"
    },
    {
      "x": -14,
      "y": 18,
      "z": -10,
      "name": "Rock_Volcanic_Brick"
    },
    {
      "x": -14,
      "y": 19,
      "z": -10,
      "name": "Rock_Volcanic_Brick"
    },
    {
      "x": -14,
      "y": 20,
      "z": -10,
      "name": "Rock_Volcanic_Brick"
    },
    {
      "x": -14,
      "y": 21,
      "z": -10,
      "name": "Rock_Volcanic_Brick"
    },
    {
      "x": -14,
      "y": 22,
      "z": -10,
      "name": "Rock_Volcanic_Brick"
    },
    {
      "x": -14,
      "y": 23,
      "z": -10,
      "name": "Rock_Volcanic_Brick"
    },
    {
      "x": -14,
      "y": 12,
      "z": -9,
      "name": "Rock_Volcanic_Brick"
    },
    {
      "x": -14,
      "y": 13,
      "z": -9,
      "name": "Rock_Volcanic_Brick"
    },
    {
      "x": -14,
      "y": 14,
      "z": -9,
      "name": "Rock_Volcanic_Brick"
    },
    {
      "x": -14,
      "y": 15,
      "z": -9,
      "name": "Rock_Volcanic_Brick"
    },
    {
      "x": -14,
      "y": 16,
      "z": -9,
      "name": "Rock_Volcanic_Brick"
    },
    {
      "x": -14,
      "y": 17,
      "z": -9,
      "name": "Rock_Volcanic_Brick"
    },
    {
      "x": -14,
      "y": 18,
      "z": -9,
      "name": "Rock_Volcanic_Brick"
    },
    {
      "x": -14,
      "y": 19,
      "z": -9,
      "name": "Rock_Volcanic_Brick"
    },
    {
      "x": -14,
      "y": 20,
      "z": -9,
      "name": "Rock_Volcanic_Brick"
    },
    {
      "x": -14,
      "y": 21,
      "z": -9,
      "name": "Rock_Volcanic_Brick"
    },
    {
      "x": -14,
      "y": 8,
      "z": -8,
      "name": "Rock_Volcanic_Brick"
    },
    {
      "x": -14,
      "y": 9,
      "z": -8,
      "name": "Rock_Volcanic_Brick"
    },
    {
      "x": -14,
      "y": 10,
      "z": -8,
      "name": "Rock_Volcanic_Brick"
    },
    {
      "x": -14,
      "y": 11,
      "z": -8,
      "name": "Rock_Volcanic_Brick"
    },
    {
      "x": -14,
      "y": 12,
      "z": -8,
      "name": "Rock_Volcanic_Brick"
    },
    {
      "x": -14,
      "y": 13,
      "z": -8,
      "name": "Rock_Volcanic_Brick"
    },
    {
      "x": -14,
      "y": 14,
      "z": -8,
      "name": "Rock_Volcanic_Brick"
    },
    {
      "x": -14,
      "y": 15,
      "z": -8,
      "name": "Rock_Volcanic_Brick"
    },
    {
      "x": -14,
      "y": 16,
      "z": -8,
      "name": "Rock_Volcanic_Brick"
    },
    {
      "x": -14,
      "y": 17,
      "z": -8,
      "name": "Rock_Volcanic_Brick"
    },
    {
      "x": -14,
      "y": 18,
      "z": -8,
      "name": "Rock_Volcanic_Brick"
    },
    {
      "x": -14,
      "y": 19,
      "z": -8,
      "name": "Rock_Volcanic_Brick"
    },
    {
      "x": -14,
      "y": 7,
      "z": -7,
      "name": "Rock_Volcanic_Brick"
    },
    {
      "x": -14,
      "y": 8,
      "z": -7,
      "name": "Rock_Volcanic_Brick"
    },
    {
      "x": -14,
      "y": 9,
      "z": -7,
      "name": "Rock_Volcanic_Brick"
    },
    {
      "x": -14,
      "y": 10,
      "z": -7,
      "name": "Rock_Volcanic_Brick"
    },
    {
      "x": -14,
      "y": 11,
      "z": -7,
      "name": "Rock_Volcanic_Brick"
    },
    {
      "x": -14,
      "y": 12,
      "z": -7,
      "name": "Rock_Volcanic_Brick"
    },
    {
      "x": -14,
      "y": 13,
      "z": -7,
      "name": "Rock_Volcanic_Brick"
    },
    {
      "x": -14,
      "y": 14,
      "z": -7,
      "name": "Rock_Volcanic_Brick"
    },
    {
      "x": -14,
      "y": 15,
      "z": -7,
      "name": "Rock_Volcanic_Brick"
    },
    {
      "x": -14,
      "y": 16,
      "z": -7,
      "name": "Rock_Volcanic_Brick"
    },
    {
      "x": -14,
      "y": 17,
      "z": -7,
      "name": "Rock_Volcanic_Brick"
    },
    {
      "x": -14,
      "y": 7,
      "z": -6,
      "name": "Rock_Volcanic_Brick"
    },
    {
      "x": -14,
      "y": 8,
      "z": -6,
      "name": "Rock_Volcanic_Brick"
    },
    {
      "x": -14,
      "y": 9,
      "z": -6,
      "name": "Rock_Volcanic_Brick"
    },
    {
      "x": -14,
      "y": 10,
      "z": -6,
      "name": "Rock_Volcanic_Brick"
    },
    {
      "x": -14,
      "y": 11,
      "z": -6,
      "name": "Rock_Volcanic_Brick"
    },
    {
      "x": -14,
      "y": 12,
      "z": -6,
      "name": "Rock_Volcanic_Brick"
    },
    {
      "x": -14,
      "y": 13,
      "z": -6,
      "name": "Rock_Volcanic_Brick"
    },
    {
      "x": -14,
      "y": 14,
      "z": -6,
      "name": "Rock_Volcanic_Brick"
    },
    {
      "x": -14,
      "y": 7,
      "z": -5,
      "name": "Rock_Volcanic_Brick"
    },
    {
      "x": -14,
      "y": 8,
      "z": -5,
      "name": "Rock_Volcanic_Brick"
    },
    {
      "x": -14,
      "y": 9,
      "z": -5,
      "name": "Rock_Volcanic_Brick"
    },
    {
      "x": -14,
      "y": 10,
      "z": -5,
      "name": "Rock_Volcanic_Brick"
    },
    {
      "x": -14,
      "y": 11,
      "z": -5,
      "name": "Rock_Volcanic_Brick"
    },
    {
      "x": -14,
      "y": 12,
      "z": -5,
      "name": "Rock_Volcanic_Brick"
    },
    {
      "x": -14,
      "y": 4,
      "z": -4,
      "name": "Rock_Volcanic_Brick"
    },
    {
      "x": -14,
      "y": 5,
      "z": -4,
      "name": "Rock_Volcanic_Brick"
    },
    {
      "x": -14,
      "y": 8,
      "z": -4,
      "name": "Rock_Volcanic_Brick"
    },
    {
      "x": -14,
      "y": 9,
      "z": -4,
      "name": "Rock_Volcanic_Brick"
    },
    {
      "x": -14,
      "y": 10,
      "z": -4,
      "name": "Rock_Volcanic_Brick"
    },
    {
      "x": -14,
      "y": 4,
      "z": -3,
      "name": "Rock_Volcanic_Brick"
    },
    {
      "x": -14,
      "y": 5,
      "z": -3,
      "name": "Rock_Volcanic_Brick"
    },
    {
      "x": -14,
      "y": 6,
      "z": -3,
      "name": "Rock_Volcanic_Brick"
    },
    {
      "x": -14,
      "y": 4,
      "z": -2,
      "name": "Rock_Volcanic_Brick"
    },
    {
      "x": -14,
      "y": 5,
      "z": -2,
      "name": "Rock_Volcanic_Brick"
    },
    {
      "x": -13,
      "y": 27,
      "z": -15,
      "name": "Rock_Volcanic_Brick"
    },
    {
      "x": -13,
      "y": 26,
      "z": -14,
      "name": "Rock_Volcanic_Brick"
    },
    {
      "x": -13,
      "y": 27,
      "z": -14,
      "name": "Rock_Volcanic_Brick"
    },
    {
      "x": -13,
      "y": 28,
      "z": -14,
      "name": "Rock_Volcanic_Brick"
    },
    {
      "x": -13,
      "y": 29,
      "z": -14,
      "name": "Rock_Volcanic_Brick"
    },
    {
      "x": -13,
      "y": 21,
      "z": -13,
      "name": "Rock_Volcanic_Brick"
    },
    {
      "x": -13,
      "y": 22,
      "z": -13,
      "name": "Rock_Volcanic_Brick"
    },
    {
      "x": -13,
      "y": 23,
      "z": -13,
      "name": "Rock_Volcanic_Brick"
    },
    {
      "x": -13,
      "y": 25,
      "z": -13,
      "name": "Rock_Volcanic_Brick"
    },
    {
      "x": -13,
      "y": 26,
      "z": -13,
      "name": "Rock_Volcanic_Brick"
    },
    {
      "x": -13,
      "y": 27,
      "z": -13,
      "name": "Rock_Volcanic_Brick"
    },
    {
      "x": -13,
      "y": 28,
      "z": -13,
      "name": "Rock_Volcanic_Brick"
    },
    {
      "x": -13,
      "y": 29,
      "z": -13,
      "name": "Rock_Volcanic_Brick"
    },
    {
      "x": -13,
      "y": 30,
      "z": -13,
      "name": "Rock_Volcanic_Brick"
    },
    {
      "x": -13,
      "y": 19,
      "z": -12,
      "name": "Rock_Volcanic_Brick"
    },
    {
      "x": -13,
      "y": 20,
      "z": -12,
      "name": "Rock_Volcanic_Brick"
    },
    {
      "x": -13,
      "y": 21,
      "z": -12,
      "name": "Rock_Volcanic_Brick"
    },
    {
      "x": -13,
      "y": 22,
      "z": -12,
      "name": "Rock_Volcanic_Brick"
    },
    {
      "x": -13,
      "y": 23,
      "z": -12,
      "name": "Rock_Volcanic_Brick"
    },
    {
      "x": -13,
      "y": 24,
      "z": -12,
      "name": "Rock_Volcanic_Brick"
    },
    {
      "x": -13,
      "y": 25,
      "z": -12,
      "name": "Rock_Volcanic_Brick"
    },
    {
      "x": -13,
      "y": 26,
      "z": -12,
      "name": "Rock_Volcanic_Brick"
    },
    {
      "x": -13,
      "y": 27,
      "z": -12,
      "name": "Rock_Volcanic_Brick"
    },
    {
      "x": -13,
      "y": 28,
      "z": -12,
      "name": "Rock_Volcanic_Brick"
    },
    {
      "x": -13,
      "y": 29,
      "z": -12,
      "name": "Rock_Volcanic_Brick"
    },
    {
      "x": -13,
      "y": 17,
      "z": -11,
      "name": "Rock_Volcanic_Brick"
    },
    {
      "x": -13,
      "y": 18,
      "z": -11,
      "name": "Rock_Volcanic_Brick"
    },
    {
      "x": -13,
      "y": 19,
      "z": -11,
      "name": "Rock_Volcanic_Brick"
    },
    {
      "x": -13,
      "y": 20,
      "z": -11,
      "name": "Rock_Volcanic_Brick"
    },
    {
      "x": -13,
      "y": 21,
      "z": -11,
      "name": "Rock_Volcanic_Brick"
    },
    {
      "x": -13,
      "y": 22,
      "z": -11,
      "name": "Rock_Volcanic_Brick"
    },
    {
      "x": -13,
      "y": 23,
      "z": -11,
      "name": "Rock_Volcanic_Brick"
    },
    {
      "x": -13,
      "y": 24,
      "z": -11,
      "name": "Rock_Volcanic_Brick"
    },
    {
      "x": -13,
      "y": 25,
      "z": -11,
      "name": "Rock_Volcanic_Brick"
    },
    {
      "x": -13,
      "y": 26,
      "z": -11,
      "name": "Rock_Volcanic_Brick"
    },
    {
      "x": -13,
      "y": 27,
      "z": -11,
      "name": "Rock_Volcanic_Brick"
    },
    {
      "x": -13,
      "y": 14,
      "z": -10,
      "name": "Rock_Volcanic_Brick"
    },
    {
      "x": -13,
      "y": 15,
      "z": -10,
      "name": "Rock_Volcanic_Brick"
    },
    {
      "x": -13,
      "y": 16,
      "z": -10,
      "name": "Rock_Volcanic_Brick"
    },
    {
      "x": -13,
      "y": 17,
      "z": -10,
      "name": "Rock_Volcanic_Brick"
    },
    {
      "x": -13,
      "y": 18,
      "z": -10,
      "name": "Rock_Volcanic_Brick"
    },
    {
      "x": -13,
      "y": 19,
      "z": -10,
      "name": "Rock_Volcanic_Brick"
    },
    {
      "x": -13,
      "y": 20,
      "z": -10,
      "name": "Rock_Volcanic_Brick"
    },
    {
      "x": -13,
      "y": 21,
      "z": -10,
      "name": "Rock_Volcanic_Brick"
    },
    {
      "x": -13,
      "y": 22,
      "z": -10,
      "name": "Rock_Volcanic_Brick"
    },
    {
      "x": -13,
      "y": 23,
      "z": -10,
      "name": "Rock_Volcanic_Brick"
    },
    {
      "x": -13,
      "y": 24,
      "z": -10,
      "name": "Rock_Volcanic_Brick"
    },
    {
      "x": -13,
      "y": 25,
      "z": -10,
      "name": "Rock_Volcanic_Brick"
    },
    {
      "x": -13,
      "y": 12,
      "z": -9,
      "name": "Rock_Volcanic_Brick"
    },
    {
      "x": -13,
      "y": 13,
      "z": -9,
      "name": "Rock_Volcanic_Brick"
    },
    {
      "x": -13,
      "y": 14,
      "z": -9,
      "name": "Rock_Volcanic_Brick"
    },
    {
      "x": -13,
      "y": 15,
      "z": -9,
      "name": "Rock_Volcanic_Brick"
    },
    {
      "x": -13,
      "y": 16,
      "z": -9,
      "name": "Rock_Volcanic_Brick"
    },
    {
      "x": -13,
      "y": 17,
      "z": -9,
      "name": "Rock_Volcanic_Brick"
    },
    {
      "x": -13,
      "y": 18,
      "z": -9,
      "name": "Rock_Volcanic_Brick"
    },
    {
      "x": -13,
      "y": 19,
      "z": -9,
      "name": "Rock_Volcanic_Brick"
    },
    {
      "x": -13,
      "y": 20,
      "z": -9,
      "name": "Rock_Volcanic_Brick"
    },
    {
      "x": -13,
      "y": 21,
      "z": -9,
      "name": "Rock_Volcanic_Brick"
    },
    {
      "x": -13,
      "y": 22,
      "z": -9,
      "name": "Rock_Volcanic_Brick"
    },
    {
      "x": -13,
      "y": 23,
      "z": -9,
      "name": "Rock_Volcanic_Brick"
    },
    {
      "x": -13,
      "y": 10,
      "z": -8,
      "name": "Rock_Volcanic_Brick"
    },
    {
      "x": -13,
      "y": 11,
      "z": -8,
      "name": "Rock_Volcanic_Brick"
    },
    {
      "x": -13,
      "y": 12,
      "z": -8,
      "name": "Rock_Volcanic_Brick"
    },
    {
      "x": -13,
      "y": 13,
      "z": -8,
      "name": "Rock_Volcanic_Brick"
    },
    {
      "x": -13,
      "y": 14,
      "z": -8,
      "name": "Rock_Volcanic_Brick"
    },
    {
      "x": -13,
      "y": 15,
      "z": -8,
      "name": "Rock_Volcanic_Brick"
    },
    {
      "x": -13,
      "y": 16,
      "z": -8,
      "name": "Rock_Volcanic_Brick"
    },
    {
      "x": -13,
      "y": 17,
      "z": -8,
      "name": "Rock_Volcanic_Brick"
    },
    {
      "x": -13,
      "y": 18,
      "z": -8,
      "name": "Rock_Volcanic_Brick"
    },
    {
      "x": -13,
      "y": 19,
      "z": -8,
      "name": "Rock_Volcanic_Brick"
    },
    {
      "x": -13,
      "y": 20,
      "z": -8,
      "name": "Rock_Volcanic_Brick"
    },
    {
      "x": -13,
      "y": 8,
      "z": -7,
      "name": "Rock_Volcanic_Brick"
    },
    {
      "x": -13,
      "y": 9,
      "z": -7,
      "name": "Rock_Volcanic_Brick"
    },
    {
      "x": -13,
      "y": 10,
      "z": -7,
      "name": "Rock_Volcanic_Brick"
    },
    {
      "x": -13,
      "y": 11,
      "z": -7,
      "name": "Rock_Volcanic_Brick"
    },
    {
      "x": -13,
      "y": 12,
      "z": -7,
      "name": "Rock_Volcanic_Brick"
    },
    {
      "x": -13,
      "y": 13,
      "z": -7,
      "name": "Rock_Volcanic_Brick"
    },
    {
      "x": -13,
      "y": 14,
      "z": -7,
      "name": "Rock_Volcanic_Brick"
    },
    {
      "x": -13,
      "y": 15,
      "z": -7,
      "name": "Rock_Volcanic_Brick"
    },
    {
      "x": -13,
      "y": 16,
      "z": -7,
      "name": "Rock_Volcanic_Brick"
    },
    {
      "x": -13,
      "y": 17,
      "z": -7,
      "name": "Rock_Volcanic_Brick"
    },
    {
      "x": -13,
      "y": 18,
      "z": -7,
      "name": "Rock_Volcanic_Brick"
    },
    {
      "x": -13,
      "y": 7,
      "z": -6,
      "name": "Rock_Volcanic_Brick"
    },
    {
      "x": -13,
      "y": 8,
      "z": -6,
      "name": "Rock_Volcanic_Brick"
    },
    {
      "x": -13,
      "y": 9,
      "z": -6,
      "name": "Rock_Volcanic_Brick"
    },
    {
      "x": -13,
      "y": 10,
      "z": -6,
      "name": "Rock_Volcanic_Brick"
    },
    {
      "x": -13,
      "y": 11,
      "z": -6,
      "name": "Rock_Volcanic_Brick"
    },
    {
      "x": -13,
      "y": 12,
      "z": -6,
      "name": "Rock_Volcanic_Brick"
    },
    {
      "x": -13,
      "y": 13,
      "z": -6,
      "name": "Rock_Volcanic_Brick"
    },
    {
      "x": -13,
      "y": 14,
      "z": -6,
      "name": "Rock_Volcanic_Brick"
    },
    {
      "x": -13,
      "y": 15,
      "z": -6,
      "name": "Rock_Volcanic_Brick"
    },
    {
      "x": -13,
      "y": 16,
      "z": -6,
      "name": "Rock_Volcanic_Brick"
    },
    {
      "x": -13,
      "y": 7,
      "z": -5,
      "name": "Rock_Volcanic_Brick"
    },
    {
      "x": -13,
      "y": 8,
      "z": -5,
      "name": "Rock_Volcanic_Brick"
    },
    {
      "x": -13,
      "y": 9,
      "z": -5,
      "name": "Rock_Volcanic_Brick"
    },
    {
      "x": -13,
      "y": 10,
      "z": -5,
      "name": "Rock_Volcanic_Brick"
    },
    {
      "x": -13,
      "y": 11,
      "z": -5,
      "name": "Rock_Volcanic_Brick"
    },
    {
      "x": -13,
      "y": 12,
      "z": -5,
      "name": "Rock_Volcanic_Brick"
    },
    {
      "x": -13,
      "y": 13,
      "z": -5,
      "name": "Rock_Volcanic_Brick"
    },
    {
      "x": -13,
      "y": 3,
      "z": -4,
      "name": "Rock_Volcanic_Brick"
    },
    {
      "x": -13,
      "y": 4,
      "z": -4,
      "name": "Rock_Volcanic_Brick"
    },
    {
      "x": -13,
      "y": 5,
      "z": -4,
      "name": "Rock_Volcanic_Brick"
    },
    {
      "x": -13,
      "y": 6,
      "z": -4,
      "name": "Rock_Volcanic_Brick"
    },
    {
      "x": -13,
      "y": 7,
      "z": -4,
      "name": "Rock_Volcanic_Brick"
    },
    {
      "x": -13,
      "y": 8,
      "z": -4,
      "name": "Rock_Volcanic_Brick"
    },
    {
      "x": -13,
      "y": 9,
      "z": -4,
      "name": "Rock_Volcanic_Brick"
    },
    {
      "x": -13,
      "y": 10,
      "z": -4,
      "name": "Rock_Volcanic_Brick"
    },
    {
      "x": -13,
      "y": 11,
      "z": -4,
      "name": "Rock_Volcanic_Brick"
    },
    {
      "x": -13,
      "y": 12,
      "z": -4,
      "name": "Rock_Volcanic_Brick"
    },
    {
      "x": -13,
      "y": 3,
      "z": -3,
      "name": "Rock_Volcanic_Brick"
    },
    {
      "x": -13,
      "y": 4,
      "z": -3,
      "name": "Rock_Volcanic_Brick"
    },
    {
      "x": -13,
      "y": 5,
      "z": -3,
      "name": "Rock_Volcanic_Brick"
    },
    {
      "x": -13,
      "y": 6,
      "z": -3,
      "name": "Rock_Volcanic_Brick"
    },
    {
      "x": -13,
      "y": 7,
      "z": -3,
      "name": "Rock_Volcanic_Brick"
    },
    {
      "x": -13,
      "y": 8,
      "z": -3,
      "name": "Rock_Volcanic_Brick"
    },
    {
      "x": -13,
      "y": 9,
      "z": -3,
      "name": "Rock_Volcanic_Brick"
    },
    {
      "x": -13,
      "y": 10,
      "z": -3,
      "name": "Rock_Volcanic_Brick"
    },
    {
      "x": -13,
      "y": 3,
      "z": -2,
      "name": "Rock_Volcanic_Brick"
    },
    {
      "x": -13,
      "y": 4,
      "z": -2,
      "name": "Rock_Volcanic_Brick"
    },
    {
      "x": -13,
      "y": 5,
      "z": -2,
      "name": "Rock_Volcanic_Brick"
    },
    {
      "x": -13,
      "y": 6,
      "z": -2,
      "name": "Rock_Volcanic_Brick"
    },
    {
      "x": -13,
      "y": 7,
      "z": -2,
      "name": "Rock_Volcanic_Brick"
    },
    {
      "x": -13,
      "y": 3,
      "z": -1,
      "name": "Rock_Volcanic_Brick"
    },
    {
      "x": -13,
      "y": 4,
      "z": -1,
      "name": "Rock_Volcanic_Brick"
    },
    {
      "x": -13,
      "y": 5,
      "z": -1,
      "name": "Rock_Volcanic_Brick"
    },
    {
      "x": -12,
      "y": 27,
      "z": -15,
      "name": "Rock_Volcanic_Brick"
    },
    {
      "x": -12,
      "y": 25,
      "z": -14,
      "name": "Rock_Volcanic_Brick"
    },
    {
      "x": -12,
      "y": 26,
      "z": -14,
      "name": "Rock_Volcanic_Brick"
    },
    {
      "x": -12,
      "y": 27,
      "z": -14,
      "name": "Rock_Volcanic_Brick"
    },
    {
      "x": -12,
      "y": 28,
      "z": -14,
      "name": "Rock_Volcanic_Brick"
    },
    {
      "x": -12,
      "y": 29,
      "z": -14,
      "name": "Rock_Volcanic_Brick"
    },
    {
      "x": -12,
      "y": 23,
      "z": -13,
      "name": "Rock_Volcanic_Brick"
    },
    {
      "x": -12,
      "y": 24,
      "z": -13,
      "name": "Rock_Volcanic_Brick"
    },
    {
      "x": -12,
      "y": 25,
      "z": -13,
      "name": "Rock_Volcanic_Brick"
    },
    {
      "x": -12,
      "y": 26,
      "z": -13,
      "name": "Rock_Volcanic_Brick"
    },
    {
      "x": -12,
      "y": 27,
      "z": -13,
      "name": "Rock_Volcanic_Brick"
    },
    {
      "x": -12,
      "y": 28,
      "z": -13,
      "name": "Rock_Volcanic_Brick"
    },
    {
      "x": -12,
      "y": 29,
      "z": -13,
      "name": "Rock_Volcanic_Brick"
    },
    {
      "x": -12,
      "y": 30,
      "z": -13,
      "name": "Rock_Volcanic_Brick"
    },
    {
      "x": -12,
      "y": 21,
      "z": -12,
      "name": "Rock_Volcanic_Brick"
    },
    {
      "x": -12,
      "y": 22,
      "z": -12,
      "name": "Rock_Volcanic_Brick"
    },
    {
      "x": -12,
      "y": 23,
      "z": -12,
      "name": "Rock_Volcanic_Brick"
    },
    {
      "x": -12,
      "y": 24,
      "z": -12,
      "name": "Rock_Volcanic_Brick"
    },
    {
      "x": -12,
      "y": 25,
      "z": -12,
      "name": "Rock_Volcanic_Brick"
    },
    {
      "x": -12,
      "y": 26,
      "z": -12,
      "name": "Rock_Volcanic_Brick"
    },
    {
      "x": -12,
      "y": 27,
      "z": -12,
      "name": "Rock_Volcanic_Brick"
    },
    {
      "x": -12,
      "y": 28,
      "z": -12,
      "name": "Rock_Volcanic_Brick"
    },
    {
      "x": -12,
      "y": 29,
      "z": -12,
      "name": "Rock_Volcanic_Brick"
    },
    {
      "x": -12,
      "y": 19,
      "z": -11,
      "name": "Rock_Volcanic_Brick"
    },
    {
      "x": -12,
      "y": 20,
      "z": -11,
      "name": "Rock_Volcanic_Brick"
    },
    {
      "x": -12,
      "y": 21,
      "z": -11,
      "name": "Rock_Volcanic_Brick"
    },
    {
      "x": -12,
      "y": 22,
      "z": -11,
      "name": "Rock_Volcanic_Brick"
    },
    {
      "x": -12,
      "y": 23,
      "z": -11,
      "name": "Rock_Volcanic_Brick"
    },
    {
      "x": -12,
      "y": 24,
      "z": -11,
      "name": "Rock_Volcanic_Brick"
    },
    {
      "x": -12,
      "y": 25,
      "z": -11,
      "name": "Rock_Volcanic_Brick"
    },
    {
      "x": -12,
      "y": 26,
      "z": -11,
      "name": "Rock_Volcanic_Brick"
    },
    {
      "x": -12,
      "y": 27,
      "z": -11,
      "name": "Rock_Volcanic_Brick"
    },
    {
      "x": -12,
      "y": 28,
      "z": -11,
      "name": "Rock_Volcanic_Brick"
    },
    {
      "x": -12,
      "y": 29,
      "z": -11,
      "name": "Rock_Volcanic_Brick"
    },
    {
      "x": -12,
      "y": 17,
      "z": -10,
      "name": "Rock_Volcanic_Brick"
    },
    {
      "x": -12,
      "y": 18,
      "z": -10,
      "name": "Rock_Volcanic_Brick"
    },
    {
      "x": -12,
      "y": 19,
      "z": -10,
      "name": "Rock_Volcanic_Brick"
    },
    {
      "x": -12,
      "y": 20,
      "z": -10,
      "name": "Rock_Volcanic_Brick"
    },
    {
      "x": -12,
      "y": 21,
      "z": -10,
      "name": "Rock_Volcanic_Brick"
    },
    {
      "x": -12,
      "y": 22,
      "z": -10,
      "name": "Rock_Volcanic_Brick"
    },
    {
      "x": -12,
      "y": 23,
      "z": -10,
      "name": "Rock_Volcanic_Brick"
    },
    {
      "x": -12,
      "y": 24,
      "z": -10,
      "name": "Rock_Volcanic_Brick"
    },
    {
      "x": -12,
      "y": 25,
      "z": -10,
      "name": "Rock_Volcanic_Brick"
    },
    {
      "x": -12,
      "y": 26,
      "z": -10,
      "name": "Rock_Volcanic_Brick"
    },
    {
      "x": -12,
      "y": 27,
      "z": -10,
      "name": "Rock_Volcanic_Brick"
    },
    {
      "x": -12,
      "y": 15,
      "z": -9,
      "name": "Rock_Volcanic_Brick"
    },
    {
      "x": -12,
      "y": 16,
      "z": -9,
      "name": "Rock_Volcanic_Brick"
    },
    {
      "x": -12,
      "y": 17,
      "z": -9,
      "name": "Rock_Volcanic_Brick"
    },
    {
      "x": -12,
      "y": 18,
      "z": -9,
      "name": "Rock_Volcanic_Brick"
    },
    {
      "x": -12,
      "y": 19,
      "z": -9,
      "name": "Rock_Volcanic_Brick"
    },
    {
      "x": -12,
      "y": 20,
      "z": -9,
      "name": "Rock_Volcanic_Brick"
    },
    {
      "x": -12,
      "y": 21,
      "z": -9,
      "name": "Rock_Volcanic_Brick"
    },
    {
      "x": -12,
      "y": 22,
      "z": -9,
      "name": "Rock_Volcanic_Brick"
    },
    {
      "x": -12,
      "y": 23,
      "z": -9,
      "name": "Rock_Volcanic_Brick"
    },
    {
      "x": -12,
      "y": 24,
      "z": -9,
      "name": "Rock_Volcanic_Brick"
    },
    {
      "x": -12,
      "y": 12,
      "z": -8,
      "name": "Rock_Volcanic_Brick"
    },
    {
      "x": -12,
      "y": 13,
      "z": -8,
      "name": "Rock_Volcanic_Brick"
    },
    {
      "x": -12,
      "y": 14,
      "z": -8,
      "name": "Rock_Volcanic_Brick"
    },
    {
      "x": -12,
      "y": 15,
      "z": -8,
      "name": "Rock_Volcanic_Brick"
    },
    {
      "x": -12,
      "y": 16,
      "z": -8,
      "name": "Rock_Volcanic_Brick"
    },
    {
      "x": -12,
      "y": 17,
      "z": -8,
      "name": "Rock_Volcanic_Brick"
    },
    {
      "x": -12,
      "y": 18,
      "z": -8,
      "name": "Rock_Volcanic_Brick"
    },
    {
      "x": -12,
      "y": 19,
      "z": -8,
      "name": "Rock_Volcanic_Brick"
    },
    {
      "x": -12,
      "y": 20,
      "z": -8,
      "name": "Rock_Volcanic_Brick"
    },
    {
      "x": -12,
      "y": 21,
      "z": -8,
      "name": "Rock_Volcanic_Brick"
    },
    {
      "x": -12,
      "y": 9,
      "z": -7,
      "name": "Rock_Volcanic_Brick"
    },
    {
      "x": -12,
      "y": 10,
      "z": -7,
      "name": "Rock_Volcanic_Brick"
    },
    {
      "x": -12,
      "y": 11,
      "z": -7,
      "name": "Rock_Volcanic_Brick"
    },
    {
      "x": -12,
      "y": 12,
      "z": -7,
      "name": "Rock_Volcanic_Brick"
    },
    {
      "x": -12,
      "y": 13,
      "z": -7,
      "name": "Rock_Volcanic_Brick"
    },
    {
      "x": -12,
      "y": 14,
      "z": -7,
      "name": "Rock_Volcanic_Brick"
    },
    {
      "x": -12,
      "y": 15,
      "z": -7,
      "name": "Rock_Volcanic_Brick"
    },
    {
      "x": -12,
      "y": 16,
      "z": -7,
      "name": "Rock_Volcanic_Brick"
    },
    {
      "x": -12,
      "y": 17,
      "z": -7,
      "name": "Rock_Volcanic_Brick"
    },
    {
      "x": -12,
      "y": 18,
      "z": -7,
      "name": "Rock_Volcanic_Brick"
    },
    {
      "x": -12,
      "y": 19,
      "z": -7,
      "name": "Rock_Volcanic_Brick"
    },
    {
      "x": -12,
      "y": 20,
      "z": -7,
      "name": "Rock_Volcanic_Brick"
    },
    {
      "x": -12,
      "y": 8,
      "z": -6,
      "name": "Rock_Volcanic_Brick"
    },
    {
      "x": -12,
      "y": 9,
      "z": -6,
      "name": "Rock_Volcanic_Brick"
    },
    {
      "x": -12,
      "y": 10,
      "z": -6,
      "name": "Rock_Volcanic_Brick"
    },
    {
      "x": -12,
      "y": 11,
      "z": -6,
      "name": "Rock_Volcanic_Brick"
    },
    {
      "x": -12,
      "y": 12,
      "z": -6,
      "name": "Rock_Volcanic_Brick"
    },
    {
      "x": -12,
      "y": 13,
      "z": -6,
      "name": "Rock_Volcanic_Brick"
    },
    {
      "x": -12,
      "y": 14,
      "z": -6,
      "name": "Rock_Volcanic_Brick"
    },
    {
      "x": -12,
      "y": 15,
      "z": -6,
      "name": "Rock_Volcanic_Brick"
    },
    {
      "x": -12,
      "y": 16,
      "z": -6,
      "name": "Rock_Volcanic_Brick"
    },
    {
      "x": -12,
      "y": 17,
      "z": -6,
      "name": "Rock_Volcanic_Brick"
    },
    {
      "x": -12,
      "y": 18,
      "z": -6,
      "name": "Rock_Volcanic_Brick"
    },
    {
      "x": -12,
      "y": 7,
      "z": -5,
      "name": "Rock_Volcanic_Brick"
    },
    {
      "x": -12,
      "y": 8,
      "z": -5,
      "name": "Rock_Volcanic_Brick"
    },
    {
      "x": -12,
      "y": 9,
      "z": -5,
      "name": "Rock_Volcanic_Brick"
    },
    {
      "x": -12,
      "y": 10,
      "z": -5,
      "name": "Rock_Volcanic_Brick"
    },
    {
      "x": -12,
      "y": 11,
      "z": -5,
      "name": "Rock_Volcanic_Brick"
    },
    {
      "x": -12,
      "y": 12,
      "z": -5,
      "name": "Rock_Volcanic_Brick"
    },
    {
      "x": -12,
      "y": 13,
      "z": -5,
      "name": "Rock_Volcanic_Brick"
    },
    {
      "x": -12,
      "y": 16,
      "z": -5,
      "name": "Rock_Volcanic_Brick"
    },
    {
      "x": -12,
      "y": 3,
      "z": -4,
      "name": "Rock_Volcanic_Brick"
    },
    {
      "x": -12,
      "y": 4,
      "z": -4,
      "name": "Rock_Volcanic_Brick"
    },
    {
      "x": -12,
      "y": 5,
      "z": -4,
      "name": "Rock_Volcanic_Brick"
    },
    {
      "x": -12,
      "y": 6,
      "z": -4,
      "name": "Rock_Volcanic_Brick"
    },
    {
      "x": -12,
      "y": 7,
      "z": -4,
      "name": "Rock_Volcanic_Brick"
    },
    {
      "x": -12,
      "y": 8,
      "z": -4,
      "name": "Rock_Volcanic_Brick"
    },
    {
      "x": -12,
      "y": 9,
      "z": -4,
      "name": "Rock_Volcanic_Brick"
    },
    {
      "x": -12,
      "y": 10,
      "z": -4,
      "name": "Rock_Volcanic_Brick"
    },
    {
      "x": -12,
      "y": 11,
      "z": -4,
      "name": "Rock_Volcanic_Brick"
    },
    {
      "x": -12,
      "y": 12,
      "z": -4,
      "name": "Rock_Volcanic_Brick"
    },
    {
      "x": -12,
      "y": 2,
      "z": -3,
      "name": "Rock_Volcanic_Brick"
    },
    {
      "x": -12,
      "y": 3,
      "z": -3,
      "name": "Rock_Volcanic_Brick"
    },
    {
      "x": -12,
      "y": 4,
      "z": -3,
      "name": "Rock_Volcanic_Brick"
    },
    {
      "x": -12,
      "y": 5,
      "z": -3,
      "name": "Rock_Volcanic_Brick"
    },
    {
      "x": -12,
      "y": 6,
      "z": -3,
      "name": "Rock_Volcanic_Brick"
    },
    {
      "x": -12,
      "y": 7,
      "z": -3,
      "name": "Rock_Volcanic_Brick"
    },
    {
      "x": -12,
      "y": 8,
      "z": -3,
      "name": "Rock_Volcanic_Brick"
    },
    {
      "x": -12,
      "y": 9,
      "z": -3,
      "name": "Rock_Volcanic_Brick"
    },
    {
      "x": -12,
      "y": 10,
      "z": -3,
      "name": "Rock_Volcanic_Brick"
    },
    {
      "x": -12,
      "y": 2,
      "z": -2,
      "name": "Rock_Volcanic_Brick"
    },
    {
      "x": -12,
      "y": 3,
      "z": -2,
      "name": "Rock_Volcanic_Brick"
    },
    {
      "x": -12,
      "y": 4,
      "z": -2,
      "name": "Rock_Volcanic_Brick"
    },
    {
      "x": -12,
      "y": 5,
      "z": -2,
      "name": "Rock_Volcanic_Brick"
    },
    {
      "x": -12,
      "y": 6,
      "z": -2,
      "name": "Rock_Volcanic_Brick"
    },
    {
      "x": -12,
      "y": 7,
      "z": -2,
      "name": "Rock_Volcanic_Brick"
    },
    {
      "x": -12,
      "y": 8,
      "z": -2,
      "name": "Rock_Volcanic_Brick"
    },
    {
      "x": -12,
      "y": 9,
      "z": -2,
      "name": "Rock_Volcanic_Brick"
    },
    {
      "x": -12,
      "y": 2,
      "z": -1,
      "name": "Rock_Volcanic_Brick"
    },
    {
      "x": -12,
      "y": 3,
      "z": -1,
      "name": "Rock_Volcanic_Brick"
    },
    {
      "x": -12,
      "y": 4,
      "z": -1,
      "name": "Rock_Volcanic_Brick"
    },
    {
      "x": -12,
      "y": 5,
      "z": -1,
      "name": "Rock_Volcanic_Brick"
    },
    {
      "x": -12,
      "y": 6,
      "z": -1,
      "name": "Rock_Volcanic_Brick"
    },
    {
      "x": -12,
      "y": 7,
      "z": -1,
      "name": "Rock_Volcanic_Brick"
    },
    {
      "x": -12,
      "y": 4,
      "z": 0,
      "name": "Rock_Volcanic_Brick"
    },
    {
      "x": -12,
      "y": 5,
      "z": 0,
      "name": "Rock_Volcanic_Brick"
    },
    {
      "x": -11,
      "y": 26,
      "z": -14,
      "name": "Rock_Volcanic_Brick"
    },
    {
      "x": -11,
      "y": 27,
      "z": -14,
      "name": "Rock_Volcanic_Brick"
    },
    {
      "x": -11,
      "y": 28,
      "z": -14,
      "name": "Rock_Volcanic_Brick"
    },
    {
      "x": -11,
      "y": 29,
      "z": -14,
      "name": "Rock_Volcanic_Brick"
    },
    {
      "x": -11,
      "y": 24,
      "z": -13,
      "name": "Rock_Volcanic_Brick"
    },
    {
      "x": -11,
      "y": 25,
      "z": -13,
      "name": "Rock_Volcanic_Brick"
    },
    {
      "x": -11,
      "y": 26,
      "z": -13,
      "name": "Rock_Volcanic_Brick"
    },
    {
      "x": -11,
      "y": 27,
      "z": -13,
      "name": "Rock_Volcanic_Brick"
    },
    {
      "x": -11,
      "y": 28,
      "z": -13,
      "name": "Rock_Volcanic_Brick"
    },
    {
      "x": -11,
      "y": 29,
      "z": -13,
      "name": "Rock_Volcanic_Brick"
    },
    {
      "x": -11,
      "y": 23,
      "z": -12,
      "name": "Rock_Volcanic_Brick"
    },
    {
      "x": -11,
      "y": 24,
      "z": -12,
      "name": "Rock_Volcanic_Brick"
    },
    {
      "x": -11,
      "y": 25,
      "z": -12,
      "name": "Rock_Volcanic_Brick"
    },
    {
      "x": -11,
      "y": 26,
      "z": -12,
      "name": "Rock_Volcanic_Brick"
    },
    {
      "x": -11,
      "y": 27,
      "z": -12,
      "name": "Rock_Volcanic_Brick"
    },
    {
      "x": -11,
      "y": 28,
      "z": -12,
      "name": "Rock_Volcanic_Brick"
    },
    {
      "x": -11,
      "y": 29,
      "z": -12,
      "name": "Rock_Volcanic_Brick"
    },
    {
      "x": -11,
      "y": 21,
      "z": -11,
      "name": "Rock_Volcanic_Brick"
    },
    {
      "x": -11,
      "y": 22,
      "z": -11,
      "name": "Rock_Volcanic_Brick"
    },
    {
      "x": -11,
      "y": 23,
      "z": -11,
      "name": "Rock_Volcanic_Brick"
    },
    {
      "x": -11,
      "y": 24,
      "z": -11,
      "name": "Rock_Volcanic_Brick"
    },
    {
      "x": -11,
      "y": 25,
      "z": -11,
      "name": "Rock_Volcanic_Brick"
    },
    {
      "x": -11,
      "y": 26,
      "z": -11,
      "name": "Rock_Volcanic_Brick"
    },
    {
      "x": -11,
      "y": 27,
      "z": -11,
      "name": "Rock_Volcanic_Brick"
    },
    {
      "x": -11,
      "y": 28,
      "z": -11,
      "name": "Rock_Volcanic_Brick"
    },
    {
      "x": -11,
      "y": 29,
      "z": -11,
      "name": "Rock_Volcanic_Brick"
    },
    {
      "x": -11,
      "y": 18,
      "z": -10,
      "name": "Rock_Volcanic_Brick"
    },
    {
      "x": -11,
      "y": 19,
      "z": -10,
      "name": "Rock_Volcanic_Brick"
    },
    {
      "x": -11,
      "y": 20,
      "z": -10,
      "name": "Rock_Volcanic_Brick"
    },
    {
      "x": -11,
      "y": 21,
      "z": -10,
      "name": "Rock_Volcanic_Brick"
    },
    {
      "x": -11,
      "y": 22,
      "z": -10,
      "name": "Rock_Volcanic_Brick"
    },
    {
      "x": -11,
      "y": 23,
      "z": -10,
      "name": "Rock_Volcanic_Brick"
    },
    {
      "x": -11,
      "y": 24,
      "z": -10,
      "name": "Rock_Volcanic_Brick"
    },
    {
      "x": -11,
      "y": 25,
      "z": -10,
      "name": "Rock_Volcanic_Brick"
    },
    {
      "x": -11,
      "y": 26,
      "z": -10,
      "name": "Rock_Volcanic_Brick"
    },
    {
      "x": -11,
      "y": 27,
      "z": -10,
      "name": "Rock_Volcanic_Brick"
    },
    {
      "x": -11,
      "y": 28,
      "z": -10,
      "name": "Rock_Volcanic_Brick"
    },
    {
      "x": -11,
      "y": 16,
      "z": -9,
      "name": "Rock_Volcanic_Brick"
    },
    {
      "x": -11,
      "y": 17,
      "z": -9,
      "name": "Rock_Volcanic_Brick"
    },
    {
      "x": -11,
      "y": 18,
      "z": -9,
      "name": "Rock_Volcanic_Brick"
    },
    {
      "x": -11,
      "y": 19,
      "z": -9,
      "name": "Rock_Volcanic_Brick"
    },
    {
      "x": -11,
      "y": 20,
      "z": -9,
      "name": "Rock_Volcanic_Brick"
    },
    {
      "x": -11,
      "y": 21,
      "z": -9,
      "name": "Rock_Volcanic_Brick"
    },
    {
      "x": -11,
      "y": 22,
      "z": -9,
      "name": "Rock_Volcanic_Brick"
    },
    {
      "x": -11,
      "y": 23,
      "z": -9,
      "name": "Rock_Volcanic_Brick"
    },
    {
      "x": -11,
      "y": 24,
      "z": -9,
      "name": "Rock_Volcanic_Brick"
    },
    {
      "x": -11,
      "y": 25,
      "z": -9,
      "name": "Rock_Volcanic_Brick"
    },
    {
      "x": -11,
      "y": 26,
      "z": -9,
      "name": "Rock_Volcanic_Brick"
    },
    {
      "x": -11,
      "y": 13,
      "z": -8,
      "name": "Rock_Volcanic_Brick"
    },
    {
      "x": -11,
      "y": 14,
      "z": -8,
      "name": "Rock_Volcanic_Brick"
    },
    {
      "x": -11,
      "y": 15,
      "z": -8,
      "name": "Rock_Volcanic_Brick"
    },
    {
      "x": -11,
      "y": 16,
      "z": -8,
      "name": "Rock_Volcanic_Brick"
    },
    {
      "x": -11,
      "y": 17,
      "z": -8,
      "name": "Rock_Volcanic_Brick"
    },
    {
      "x": -11,
      "y": 18,
      "z": -8,
      "name": "Rock_Volcanic_Brick"
    },
    {
      "x": -11,
      "y": 19,
      "z": -8,
      "name": "Rock_Volcanic_Brick"
    },
    {
      "x": -11,
      "y": 20,
      "z": -8,
      "name": "Rock_Volcanic_Brick"
    },
    {
      "x": -11,
      "y": 12,
      "z": -7,
      "name": "Rock_Volcanic_Brick"
    },
    {
      "x": -11,
      "y": 13,
      "z": -7,
      "name": "Rock_Volcanic_Brick"
    },
    {
      "x": -11,
      "y": 14,
      "z": -7,
      "name": "Rock_Volcanic_Brick"
    },
    {
      "x": -11,
      "y": 15,
      "z": -7,
      "name": "Rock_Volcanic_Brick"
    },
    {
      "x": -11,
      "y": 16,
      "z": -7,
      "name": "Rock_Volcanic_Brick"
    },
    {
      "x": -11,
      "y": 17,
      "z": -7,
      "name": "Rock_Volcanic_Brick"
    },
    {
      "x": -11,
      "y": 18,
      "z": -7,
      "name": "Rock_Volcanic_Brick"
    },
    {
      "x": -11,
      "y": 19,
      "z": -7,
      "name": "Rock_Volcanic_Brick"
    },
    {
      "x": -11,
      "y": 20,
      "z": -7,
      "name": "Rock_Volcanic_Brick"
    },
    {
      "x": -11,
      "y": 10,
      "z": -6,
      "name": "Rock_Volcanic_Brick"
    },
    {
      "x": -11,
      "y": 11,
      "z": -6,
      "name": "Rock_Volcanic_Brick"
    },
    {
      "x": -11,
      "y": 12,
      "z": -6,
      "name": "Rock_Volcanic_Brick"
    },
    {
      "x": -11,
      "y": 15,
      "z": -6,
      "name": "Rock_Volcanic_Brick"
    },
    {
      "x": -11,
      "y": 16,
      "z": -6,
      "name": "Rock_Volcanic_Brick"
    },
    {
      "x": -11,
      "y": 17,
      "z": -6,
      "name": "Rock_Volcanic_Brick"
    },
    {
      "x": -11,
      "y": 18,
      "z": -6,
      "name": "Rock_Volcanic_Brick"
    },
    {
      "x": -11,
      "y": 19,
      "z": -6,
      "name": "Rock_Volcanic_Brick"
    },
    {
      "x": -11,
      "y": 7,
      "z": -5,
      "name": "Rock_Volcanic_Brick"
    },
    {
      "x": -11,
      "y": 8,
      "z": -5,
      "name": "Rock_Volcanic_Brick"
    },
    {
      "x": -11,
      "y": 9,
      "z": -5,
      "name": "Rock_Volcanic_Brick"
    },
    {
      "x": -11,
      "y": 10,
      "z": -5,
      "name": "Rock_Volcanic_Brick"
    },
    {
      "x": -11,
      "y": 11,
      "z": -5,
      "name": "Rock_Volcanic_Brick"
    },
    {
      "x": -11,
      "y": 12,
      "z": -5,
      "name": "Rock_Volcanic_Brick"
    },
    {
      "x": -11,
      "y": 15,
      "z": -5,
      "name": "Rock_Volcanic_Brick"
    },
    {
      "x": -11,
      "y": 16,
      "z": -5,
      "name": "Rock_Volcanic_Brick"
    },
    {
      "x": -11,
      "y": 17,
      "z": -5,
      "name": "Rock_Volcanic_Brick"
    },
    {
      "x": -11,
      "y": 5,
      "z": -4,
      "name": "Rock_Volcanic_Brick"
    },
    {
      "x": -11,
      "y": 6,
      "z": -4,
      "name": "Rock_Volcanic_Brick"
    },
    {
      "x": -11,
      "y": 7,
      "z": -4,
      "name": "Rock_Volcanic_Brick"
    },
    {
      "x": -11,
      "y": 8,
      "z": -4,
      "name": "Rock_Volcanic_Brick"
    },
    {
      "x": -11,
      "y": 9,
      "z": -4,
      "name": "Rock_Volcanic_Brick"
    },
    {
      "x": -11,
      "y": 10,
      "z": -4,
      "name": "Rock_Volcanic_Brick"
    },
    {
      "x": -11,
      "y": 11,
      "z": -4,
      "name": "Rock_Volcanic_Brick"
    },
    {
      "x": -11,
      "y": 3,
      "z": -3,
      "name": "Rock_Volcanic_Brick"
    },
    {
      "x": -11,
      "y": 4,
      "z": -3,
      "name": "Rock_Volcanic_Brick"
    },
    {
      "x": -11,
      "y": 5,
      "z": -3,
      "name": "Rock_Volcanic_Brick"
    },
    {
      "x": -11,
      "y": 6,
      "z": -3,
      "name": "Rock_Volcanic_Brick"
    },
    {
      "x": -11,
      "y": 7,
      "z": -3,
      "name": "Rock_Volcanic_Brick"
    },
    {
      "x": -11,
      "y": 8,
      "z": -3,
      "name": "Rock_Volcanic_Brick"
    },
    {
      "x": -11,
      "y": 9,
      "z": -3,
      "name": "Rock_Volcanic_Brick"
    },
    {
      "x": -11,
      "y": 10,
      "z": -3,
      "name": "Rock_Volcanic_Brick"
    },
    {
      "x": -11,
      "y": 2,
      "z": -2,
      "name": "Rock_Volcanic_Brick"
    },
    {
      "x": -11,
      "y": 3,
      "z": -2,
      "name": "Rock_Volcanic_Brick"
    },
    {
      "x": -11,
      "y": 4,
      "z": -2,
      "name": "Rock_Volcanic_Brick"
    },
    {
      "x": -11,
      "y": 5,
      "z": -2,
      "name": "Rock_Volcanic_Brick"
    },
    {
      "x": -11,
      "y": 6,
      "z": -2,
      "name": "Rock_Volcanic_Brick"
    },
    {
      "x": -11,
      "y": 7,
      "z": -2,
      "name": "Rock_Volcanic_Brick"
    },
    {
      "x": -11,
      "y": 8,
      "z": -2,
      "name": "Rock_Volcanic_Brick"
    },
    {
      "x": -11,
      "y": 9,
      "z": -2,
      "name": "Rock_Volcanic_Brick"
    },
    {
      "x": -11,
      "y": 3,
      "z": -1,
      "name": "Rock_Volcanic_Brick"
    },
    {
      "x": -11,
      "y": 4,
      "z": -1,
      "name": "Rock_Volcanic_Brick"
    },
    {
      "x": -11,
      "y": 5,
      "z": -1,
      "name": "Rock_Volcanic_Brick"
    },
    {
      "x": -11,
      "y": 6,
      "z": -1,
      "name": "Rock_Volcanic_Brick"
    },
    {
      "x": -11,
      "y": 7,
      "z": -1,
      "name": "Rock_Volcanic_Brick"
    },
    {
      "x": -11,
      "y": 8,
      "z": -1,
      "name": "Rock_Volcanic_Brick"
    },
    {
      "x": -11,
      "y": 4,
      "z": 0,
      "name": "Rock_Volcanic_Brick"
    },
    {
      "x": -11,
      "y": 5,
      "z": 0,
      "name": "Rock_Volcanic_Brick"
    },
    {
      "x": -11,
      "y": 6,
      "z": 0,
      "name": "Rock_Volcanic_Brick"
    },
    {
      "x": -10,
      "y": 26,
      "z": -13,
      "name": "Rock_Volcanic_Brick"
    },
    {
      "x": -10,
      "y": 27,
      "z": -13,
      "name": "Rock_Volcanic_Brick"
    },
    {
      "x": -10,
      "y": 28,
      "z": -13,
      "name": "Rock_Volcanic_Brick"
    },
    {
      "x": -10,
      "y": 29,
      "z": -13,
      "name": "Rock_Volcanic_Brick"
    },
    {
      "x": -10,
      "y": 32,
      "z": -13,
      "name": "Rock_Volcanic_Brick"
    },
    {
      "x": -10,
      "y": 33,
      "z": -13,
      "name": "Rock_Volcanic_Brick"
    },
    {
      "x": -10,
      "y": 24,
      "z": -12,
      "name": "Rock_Volcanic_Brick"
    },
    {
      "x": -10,
      "y": 25,
      "z": -12,
      "name": "Rock_Volcanic_Brick"
    },
    {
      "x": -10,
      "y": 26,
      "z": -12,
      "name": "Rock_Volcanic_Brick"
    },
    {
      "x": -10,
      "y": 27,
      "z": -12,
      "name": "Rock_Volcanic_Brick"
    },
    {
      "x": -10,
      "y": 28,
      "z": -12,
      "name": "Rock_Volcanic_Brick"
    },
    {
      "x": -10,
      "y": 29,
      "z": -12,
      "name": "Rock_Volcanic_Brick"
    },
    {
      "x": -10,
      "y": 30,
      "z": -12,
      "name": "Rock_Volcanic_Brick"
    },
    {
      "x": -10,
      "y": 31,
      "z": -12,
      "name": "Rock_Volcanic_Brick"
    },
    {
      "x": -10,
      "y": 32,
      "z": -12,
      "name": "Rock_Volcanic_Brick"
    },
    {
      "x": -10,
      "y": 33,
      "z": -12,
      "name": "Rock_Volcanic_Brick"
    },
    {
      "x": -10,
      "y": 22,
      "z": -11,
      "name": "Rock_Volcanic_Brick"
    },
    {
      "x": -10,
      "y": 23,
      "z": -11,
      "name": "Rock_Volcanic_Brick"
    },
    {
      "x": -10,
      "y": 24,
      "z": -11,
      "name": "Rock_Volcanic_Brick"
    },
    {
      "x": -10,
      "y": 25,
      "z": -11,
      "name": "Rock_Volcanic_Brick"
    },
    {
      "x": -10,
      "y": 26,
      "z": -11,
      "name": "Rock_Volcanic_Brick"
    },
    {
      "x": -10,
      "y": 27,
      "z": -11,
      "name": "Rock_Volcanic_Brick"
    },
    {
      "x": -10,
      "y": 28,
      "z": -11,
      "name": "Rock_Volcanic_Brick"
    },
    {
      "x": -10,
      "y": 29,
      "z": -11,
      "name": "Rock_Volcanic_Brick"
    },
    {
      "x": -10,
      "y": 30,
      "z": -11,
      "name": "Rock_Volcanic_Brick"
    },
    {
      "x": -10,
      "y": 31,
      "z": -11,
      "name": "Rock_Volcanic_Brick"
    },
    {
      "x": -10,
      "y": 32,
      "z": -11,
      "name": "Rock_Volcanic_Brick"
    },
    {
      "x": -10,
      "y": 19,
      "z": -10,
      "name": "Rock_Volcanic_Brick"
    },
    {
      "x": -10,
      "y": 22,
      "z": -10,
      "name": "Rock_Volcanic_Brick"
    },
    {
      "x": -10,
      "y": 23,
      "z": -10,
      "name": "Rock_Volcanic_Brick"
    },
    {
      "x": -10,
      "y": 24,
      "z": -10,
      "name": "Rock_Volcanic_Brick"
    },
    {
      "x": -10,
      "y": 25,
      "z": -10,
      "name": "Rock_Volcanic_Brick"
    },
    {
      "x": -10,
      "y": 26,
      "z": -10,
      "name": "Rock_Volcanic_Brick"
    },
    {
      "x": -10,
      "y": 27,
      "z": -10,
      "name": "Rock_Volcanic_Brick"
    },
    {
      "x": -10,
      "y": 28,
      "z": -10,
      "name": "Rock_Volcanic_Brick"
    },
    {
      "x": -10,
      "y": 29,
      "z": -10,
      "name": "Rock_Volcanic_Brick"
    },
    {
      "x": -10,
      "y": 30,
      "z": -10,
      "name": "Rock_Volcanic_Brick"
    },
    {
      "x": -10,
      "y": 17,
      "z": -9,
      "name": "Rock_Volcanic_Brick"
    },
    {
      "x": -10,
      "y": 18,
      "z": -9,
      "name": "Rock_Volcanic_Brick"
    },
    {
      "x": -10,
      "y": 19,
      "z": -9,
      "name": "Rock_Volcanic_Brick"
    },
    {
      "x": -10,
      "y": 20,
      "z": -9,
      "name": "Rock_Volcanic_Brick"
    },
    {
      "x": -10,
      "y": 24,
      "z": -9,
      "name": "Rock_Volcanic_Brick"
    },
    {
      "x": -10,
      "y": 25,
      "z": -9,
      "name": "Rock_Volcanic_Brick"
    },
    {
      "x": -10,
      "y": 26,
      "z": -9,
      "name": "Rock_Volcanic_Brick"
    },
    {
      "x": -10,
      "y": 27,
      "z": -9,
      "name": "Rock_Volcanic_Brick"
    },
    {
      "x": -10,
      "y": 28,
      "z": -9,
      "name": "Rock_Volcanic_Brick"
    },
    {
      "x": -10,
      "y": 15,
      "z": -8,
      "name": "Rock_Volcanic_Brick"
    },
    {
      "x": -10,
      "y": 16,
      "z": -8,
      "name": "Rock_Volcanic_Brick"
    },
    {
      "x": -10,
      "y": 17,
      "z": -8,
      "name": "Rock_Volcanic_Brick"
    },
    {
      "x": -10,
      "y": 18,
      "z": -8,
      "name": "Rock_Volcanic_Brick"
    },
    {
      "x": -10,
      "y": 19,
      "z": -8,
      "name": "Rock_Volcanic_Brick"
    },
    {
      "x": -10,
      "y": 20,
      "z": -8,
      "name": "Rock_Volcanic_Brick"
    },
    {
      "x": -10,
      "y": 15,
      "z": -7,
      "name": "Rock_Volcanic_Brick"
    },
    {
      "x": -10,
      "y": 16,
      "z": -7,
      "name": "Rock_Volcanic_Brick"
    },
    {
      "x": -10,
      "y": 17,
      "z": -7,
      "name": "Rock_Volcanic_Brick"
    },
    {
      "x": -10,
      "y": 18,
      "z": -7,
      "name": "Rock_Volcanic_Brick"
    },
    {
      "x": -10,
      "y": 19,
      "z": -7,
      "name": "Rock_Volcanic_Brick"
    },
    {
      "x": -10,
      "y": 20,
      "z": -7,
      "name": "Rock_Volcanic_Brick"
    },
    {
      "x": -10,
      "y": 15,
      "z": -6,
      "name": "Rock_Volcanic_Brick"
    },
    {
      "x": -10,
      "y": 16,
      "z": -6,
      "name": "Rock_Volcanic_Brick"
    },
    {
      "x": -10,
      "y": 17,
      "z": -6,
      "name": "Rock_Volcanic_Brick"
    },
    {
      "x": -10,
      "y": 18,
      "z": -6,
      "name": "Rock_Volcanic_Brick"
    },
    {
      "x": -10,
      "y": 19,
      "z": -6,
      "name": "Rock_Volcanic_Brick"
    },
    {
      "x": -10,
      "y": 20,
      "z": -6,
      "name": "Rock_Volcanic_Brick"
    },
    {
      "x": -10,
      "y": 9,
      "z": -5,
      "name": "Rock_Volcanic_Brick"
    },
    {
      "x": -10,
      "y": 10,
      "z": -5,
      "name": "Rock_Volcanic_Brick"
    },
    {
      "x": -10,
      "y": 15,
      "z": -5,
      "name": "Rock_Volcanic_Brick"
    },
    {
      "x": -10,
      "y": 16,
      "z": -5,
      "name": "Rock_Volcanic_Brick"
    },
    {
      "x": -10,
      "y": 17,
      "z": -5,
      "name": "Rock_Volcanic_Brick"
    },
    {
      "x": -10,
      "y": 18,
      "z": -5,
      "name": "Rock_Volcanic_Brick"
    },
    {
      "x": -10,
      "y": 19,
      "z": -5,
      "name": "Rock_Volcanic_Brick"
    },
    {
      "x": -10,
      "y": 6,
      "z": -4,
      "name": "Rock_Volcanic_Brick"
    },
    {
      "x": -10,
      "y": 7,
      "z": -4,
      "name": "Rock_Volcanic_Brick"
    },
    {
      "x": -10,
      "y": 8,
      "z": -4,
      "name": "Rock_Volcanic_Brick"
    },
    {
      "x": -10,
      "y": 9,
      "z": -4,
      "name": "Rock_Volcanic_Brick"
    },
    {
      "x": -10,
      "y": 10,
      "z": -4,
      "name": "Rock_Volcanic_Brick"
    },
    {
      "x": -10,
      "y": 15,
      "z": -4,
      "name": "Rock_Volcanic_Brick"
    },
    {
      "x": -10,
      "y": 16,
      "z": -4,
      "name": "Rock_Volcanic_Brick"
    },
    {
      "x": -10,
      "y": 17,
      "z": -4,
      "name": "Rock_Volcanic_Brick"
    },
    {
      "x": -10,
      "y": 4,
      "z": -3,
      "name": "Rock_Volcanic_Brick"
    },
    {
      "x": -10,
      "y": 5,
      "z": -3,
      "name": "Rock_Volcanic_Brick"
    },
    {
      "x": -10,
      "y": 6,
      "z": -3,
      "name": "Rock_Volcanic_Brick"
    },
    {
      "x": -10,
      "y": 7,
      "z": -3,
      "name": "Rock_Volcanic_Brick"
    },
    {
      "x": -10,
      "y": 8,
      "z": -3,
      "name": "Rock_Volcanic_Brick"
    },
    {
      "x": -10,
      "y": 9,
      "z": -3,
      "name": "Rock_Volcanic_Brick"
    },
    {
      "x": -10,
      "y": 3,
      "z": -2,
      "name": "Rock_Volcanic_Brick"
    },
    {
      "x": -10,
      "y": 4,
      "z": -2,
      "name": "Rock_Volcanic_Brick"
    },
    {
      "x": -10,
      "y": 5,
      "z": -2,
      "name": "Rock_Volcanic_Brick"
    },
    {
      "x": -10,
      "y": 6,
      "z": -2,
      "name": "Rock_Volcanic_Brick"
    },
    {
      "x": -10,
      "y": 7,
      "z": -2,
      "name": "Rock_Volcanic_Brick"
    },
    {
      "x": -10,
      "y": 8,
      "z": -2,
      "name": "Rock_Volcanic_Brick"
    },
    {
      "x": -10,
      "y": 9,
      "z": -2,
      "name": "Rock_Volcanic_Brick"
    },
    {
      "x": -10,
      "y": 3,
      "z": -1,
      "name": "Rock_Volcanic_Brick"
    },
    {
      "x": -10,
      "y": 4,
      "z": -1,
      "name": "Rock_Volcanic_Brick"
    },
    {
      "x": -10,
      "y": 5,
      "z": -1,
      "name": "Rock_Volcanic_Brick"
    },
    {
      "x": -10,
      "y": 6,
      "z": -1,
      "name": "Rock_Volcanic_Brick"
    },
    {
      "x": -10,
      "y": 7,
      "z": -1,
      "name": "Rock_Volcanic_Brick"
    },
    {
      "x": -10,
      "y": 8,
      "z": -1,
      "name": "Rock_Volcanic_Brick"
    },
    {
      "x": -10,
      "y": 4,
      "z": 0,
      "name": "Rock_Volcanic_Brick"
    },
    {
      "x": -10,
      "y": 5,
      "z": 0,
      "name": "Rock_Volcanic_Brick"
    },
    {
      "x": -10,
      "y": 6,
      "z": 0,
      "name": "Rock_Volcanic_Brick"
    },
    {
      "x": -10,
      "y": 7,
      "z": 0,
      "name": "Rock_Volcanic_Brick"
    },
    {
      "x": -10,
      "y": 8,
      "z": 0,
      "name": "Rock_Volcanic_Brick"
    },
    {
      "x": -10,
      "y": 1,
      "z": 1,
      "name": "Rock_Volcanic_Brick"
    },
    {
      "x": -10,
      "y": 2,
      "z": 1,
      "name": "Rock_Volcanic_Brick"
    },
    {
      "x": -10,
      "y": 4,
      "z": 1,
      "name": "Rock_Volcanic_Brick"
    },
    {
      "x": -10,
      "y": 5,
      "z": 1,
      "name": "Rock_Volcanic_Brick"
    },
    {
      "x": -10,
      "y": 6,
      "z": 1,
      "name": "Rock_Volcanic_Brick"
    },
    {
      "x": -10,
      "y": 1,
      "z": 2,
      "name": "Rock_Volcanic_Brick"
    },
    {
      "x": -10,
      "y": 2,
      "z": 2,
      "name": "Rock_Volcanic_Brick"
    },
    {
      "x": -9,
      "y": 31,
      "z": -14,
      "name": "Rock_Volcanic_Brick"
    },
    {
      "x": -9,
      "y": 32,
      "z": -14,
      "name": "Rock_Volcanic_Brick"
    },
    {
      "x": -9,
      "y": 33,
      "z": -14,
      "name": "Rock_Volcanic_Brick"
    },
    {
      "x": -9,
      "y": 28,
      "z": -13,
      "name": "Rock_Volcanic_Brick"
    },
    {
      "x": -9,
      "y": 29,
      "z": -13,
      "name": "Rock_Volcanic_Brick"
    },
    {
      "x": -9,
      "y": 30,
      "z": -13,
      "name": "Rock_Volcanic_Brick"
    },
    {
      "x": -9,
      "y": 31,
      "z": -13,
      "name": "Rock_Volcanic_Brick"
    },
    {
      "x": -9,
      "y": 32,
      "z": -13,
      "name": "Rock_Volcanic_Brick"
    },
    {
      "x": -9,
      "y": 33,
      "z": -13,
      "name": "Rock_Volcanic_Brick"
    },
    {
      "x": -9,
      "y": 34,
      "z": -13,
      "name": "Rock_Volcanic_Brick"
    },
    {
      "x": -9,
      "y": 26,
      "z": -12,
      "name": "Rock_Volcanic_Brick"
    },
    {
      "x": -9,
      "y": 27,
      "z": -12,
      "name": "Rock_Volcanic_Brick"
    },
    {
      "x": -9,
      "y": 28,
      "z": -12,
      "name": "Rock_Volcanic_Brick"
    },
    {
      "x": -9,
      "y": 29,
      "z": -12,
      "name": "Rock_Volcanic_Brick"
    },
    {
      "x": -9,
      "y": 30,
      "z": -12,
      "name": "Rock_Volcanic_Brick"
    },
    {
      "x": -9,
      "y": 31,
      "z": -12,
      "name": "Rock_Volcanic_Brick"
    },
    {
      "x": -9,
      "y": 32,
      "z": -12,
      "name": "Rock_Volcanic_Brick"
    },
    {
      "x": -9,
      "y": 33,
      "z": -12,
      "name": "Rock_Volcanic_Brick"
    },
    {
      "x": -9,
      "y": 34,
      "z": -12,
      "name": "Rock_Volcanic_Brick"
    },
    {
      "x": -9,
      "y": 24,
      "z": -11,
      "name": "Rock_Volcanic_Brick"
    },
    {
      "x": -9,
      "y": 25,
      "z": -11,
      "name": "Rock_Volcanic_Brick"
    },
    {
      "x": -9,
      "y": 26,
      "z": -11,
      "name": "Rock_Volcanic_Brick"
    },
    {
      "x": -9,
      "y": 27,
      "z": -11,
      "name": "Rock_Volcanic_Brick"
    },
    {
      "x": -9,
      "y": 28,
      "z": -11,
      "name": "Rock_Volcanic_Brick"
    },
    {
      "x": -9,
      "y": 29,
      "z": -11,
      "name": "Rock_Volcanic_Brick"
    },
    {
      "x": -9,
      "y": 30,
      "z": -11,
      "name": "Rock_Volcanic_Brick"
    },
    {
      "x": -9,
      "y": 31,
      "z": -11,
      "name": "Rock_Volcanic_Brick"
    },
    {
      "x": -9,
      "y": 32,
      "z": -11,
      "name": "Rock_Volcanic_Brick"
    },
    {
      "x": -9,
      "y": 33,
      "z": -11,
      "name": "Rock_Volcanic_Brick"
    },
    {
      "x": -9,
      "y": 34,
      "z": -11,
      "name": "Rock_Volcanic_Brick"
    },
    {
      "x": -9,
      "y": 24,
      "z": -10,
      "name": "Rock_Volcanic_Brick"
    },
    {
      "x": -9,
      "y": 25,
      "z": -10,
      "name": "Rock_Volcanic_Brick"
    },
    {
      "x": -9,
      "y": 26,
      "z": -10,
      "name": "Rock_Volcanic_Brick"
    },
    {
      "x": -9,
      "y": 27,
      "z": -10,
      "name": "Rock_Volcanic_Brick"
    },
    {
      "x": -9,
      "y": 28,
      "z": -10,
      "name": "Rock_Volcanic_Brick"
    },
    {
      "x": -9,
      "y": 29,
      "z": -10,
      "name": "Rock_Volcanic_Brick"
    },
    {
      "x": -9,
      "y": 30,
      "z": -10,
      "name": "Rock_Volcanic_Brick"
    },
    {
      "x": -9,
      "y": 31,
      "z": -10,
      "name": "Rock_Volcanic_Brick"
    },
    {
      "x": -9,
      "y": 32,
      "z": -10,
      "name": "Rock_Volcanic_Brick"
    },
    {
      "x": -9,
      "y": 26,
      "z": -9,
      "name": "Rock_Volcanic_Brick"
    },
    {
      "x": -9,
      "y": 27,
      "z": -9,
      "name": "Rock_Volcanic_Brick"
    },
    {
      "x": -9,
      "y": 28,
      "z": -9,
      "name": "Rock_Volcanic_Brick"
    },
    {
      "x": -9,
      "y": 29,
      "z": -9,
      "name": "Rock_Volcanic_Brick"
    },
    {
      "x": -9,
      "y": 17,
      "z": -8,
      "name": "Rock_Volcanic_Brick"
    },
    {
      "x": -9,
      "y": 18,
      "z": -8,
      "name": "Rock_Volcanic_Brick"
    },
    {
      "x": -9,
      "y": 19,
      "z": -8,
      "name": "Rock_Volcanic_Brick"
    },
    {
      "x": -9,
      "y": 20,
      "z": -8,
      "name": "Rock_Volcanic_Brick"
    },
    {
      "x": -9,
      "y": 15,
      "z": -7,
      "name": "Rock_Volcanic_Brick"
    },
    {
      "x": -9,
      "y": 16,
      "z": -7,
      "name": "Rock_Volcanic_Brick"
    },
    {
      "x": -9,
      "y": 17,
      "z": -7,
      "name": "Rock_Volcanic_Brick"
    },
    {
      "x": -9,
      "y": 18,
      "z": -7,
      "name": "Rock_Volcanic_Brick"
    },
    {
      "x": -9,
      "y": 19,
      "z": -7,
      "name": "Rock_Volcanic_Brick"
    },
    {
      "x": -9,
      "y": 20,
      "z": -7,
      "name": "Rock_Volcanic_Brick"
    },
    {
      "x": -9,
      "y": 21,
      "z": -7,
      "name": "Rock_Volcanic_Brick"
    },
    {
      "x": -9,
      "y": 22,
      "z": -7,
      "name": "Rock_Volcanic_Brick"
    },
    {
      "x": -9,
      "y": 15,
      "z": -6,
      "name": "Rock_Volcanic_Brick"
    },
    {
      "x": -9,
      "y": 16,
      "z": -6,
      "name": "Rock_Volcanic_Brick"
    },
    {
      "x": -9,
      "y": 17,
      "z": -6,
      "name": "Rock_Volcanic_Brick"
    },
    {
      "x": -9,
      "y": 18,
      "z": -6,
      "name": "Rock_Volcanic_Brick"
    },
    {
      "x": -9,
      "y": 19,
      "z": -6,
      "name": "Rock_Volcanic_Brick"
    },
    {
      "x": -9,
      "y": 20,
      "z": -6,
      "name": "Rock_Volcanic_Brick"
    },
    {
      "x": -9,
      "y": 21,
      "z": -6,
      "name": "Rock_Volcanic_Brick"
    },
    {
      "x": -9,
      "y": 22,
      "z": -6,
      "name": "Rock_Volcanic_Brick"
    },
    {
      "x": -9,
      "y": 14,
      "z": -5,
      "name": "Rock_Volcanic_Brick"
    },
    {
      "x": -9,
      "y": 15,
      "z": -5,
      "name": "Rock_Volcanic_Brick"
    },
    {
      "x": -9,
      "y": 16,
      "z": -5,
      "name": "Rock_Volcanic_Brick"
    },
    {
      "x": -9,
      "y": 17,
      "z": -5,
      "name": "Rock_Volcanic_Brick"
    },
    {
      "x": -9,
      "y": 18,
      "z": -5,
      "name": "Rock_Volcanic_Brick"
    },
    {
      "x": -9,
      "y": 19,
      "z": -5,
      "name": "Rock_Volcanic_Brick"
    },
    {
      "x": -9,
      "y": 20,
      "z": -5,
      "name": "Rock_Volcanic_Brick"
    },
    {
      "x": -9,
      "y": 21,
      "z": -5,
      "name": "Rock_Volcanic_Brick"
    },
    {
      "x": -9,
      "y": 8,
      "z": -4,
      "name": "Rock_Volcanic_Brick"
    },
    {
      "x": -9,
      "y": 9,
      "z": -4,
      "name": "Rock_Volcanic_Brick"
    },
    {
      "x": -9,
      "y": 13,
      "z": -4,
      "name": "Rock_Volcanic_Brick"
    },
    {
      "x": -9,
      "y": 14,
      "z": -4,
      "name": "Rock_Volcanic_Brick"
    },
    {
      "x": -9,
      "y": 15,
      "z": -4,
      "name": "Rock_Volcanic_Brick"
    },
    {
      "x": -9,
      "y": 16,
      "z": -4,
      "name": "Rock_Volcanic_Brick"
    },
    {
      "x": -9,
      "y": 17,
      "z": -4,
      "name": "Rock_Volcanic_Brick"
    },
    {
      "x": -9,
      "y": 18,
      "z": -4,
      "name": "Rock_Volcanic_Brick"
    },
    {
      "x": -9,
      "y": 6,
      "z": -3,
      "name": "Rock_Volcanic_Brick"
    },
    {
      "x": -9,
      "y": 7,
      "z": -3,
      "name": "Rock_Volcanic_Brick"
    },
    {
      "x": -9,
      "y": 8,
      "z": -3,
      "name": "Rock_Volcanic_Brick"
    },
    {
      "x": -9,
      "y": 13,
      "z": -3,
      "name": "Rock_Volcanic_Brick"
    },
    {
      "x": -9,
      "y": 14,
      "z": -3,
      "name": "Rock_Volcanic_Brick"
    },
    {
      "x": -9,
      "y": 15,
      "z": -3,
      "name": "Rock_Volcanic_Brick"
    },
    {
      "x": -9,
      "y": 16,
      "z": -3,
      "name": "Rock_Volcanic_Brick"
    },
    {
      "x": -9,
      "y": 4,
      "z": -2,
      "name": "Rock_Volcanic_Brick"
    },
    {
      "x": -9,
      "y": 5,
      "z": -2,
      "name": "Rock_Volcanic_Brick"
    },
    {
      "x": -9,
      "y": 6,
      "z": -2,
      "name": "Rock_Volcanic_Brick"
    },
    {
      "x": -9,
      "y": 7,
      "z": -2,
      "name": "Rock_Volcanic_Brick"
    },
    {
      "x": -9,
      "y": 8,
      "z": -2,
      "name": "Rock_Volcanic_Brick"
    },
    {
      "x": -9,
      "y": 13,
      "z": -2,
      "name": "Rock_Volcanic_Brick"
    },
    {
      "x": -9,
      "y": 14,
      "z": -2,
      "name": "Rock_Volcanic_Brick"
    },
    {
      "x": -9,
      "y": 4,
      "z": -1,
      "name": "Rock_Volcanic_Brick"
    },
    {
      "x": -9,
      "y": 5,
      "z": -1,
      "name": "Rock_Volcanic_Brick"
    },
    {
      "x": -9,
      "y": 6,
      "z": -1,
      "name": "Rock_Volcanic_Brick"
    },
    {
      "x": -9,
      "y": 7,
      "z": -1,
      "name": "Rock_Volcanic_Brick"
    },
    {
      "x": -9,
      "y": 8,
      "z": -1,
      "name": "Rock_Volcanic_Brick"
    },
    {
      "x": -9,
      "y": 1,
      "z": 0,
      "name": "Rock_Volcanic_Brick"
    },
    {
      "x": -9,
      "y": 2,
      "z": 0,
      "name": "Rock_Volcanic_Brick"
    },
    {
      "x": -9,
      "y": 3,
      "z": 0,
      "name": "Rock_Volcanic_Brick"
    },
    {
      "x": -9,
      "y": 4,
      "z": 0,
      "name": "Rock_Volcanic_Brick"
    },
    {
      "x": -9,
      "y": 5,
      "z": 0,
      "name": "Rock_Volcanic_Brick"
    },
    {
      "x": -9,
      "y": 6,
      "z": 0,
      "name": "Rock_Volcanic_Brick"
    },
    {
      "x": -9,
      "y": 7,
      "z": 0,
      "name": "Rock_Volcanic_Brick"
    },
    {
      "x": -9,
      "y": 8,
      "z": 0,
      "name": "Rock_Volcanic_Brick"
    },
    {
      "x": -9,
      "y": 0,
      "z": 1,
      "name": "Rock_Volcanic_Brick"
    },
    {
      "x": -9,
      "y": 1,
      "z": 1,
      "name": "Rock_Volcanic_Brick"
    },
    {
      "x": -9,
      "y": 2,
      "z": 1,
      "name": "Rock_Volcanic_Brick"
    },
    {
      "x": -9,
      "y": 3,
      "z": 1,
      "name": "Rock_Volcanic_Brick"
    },
    {
      "x": -9,
      "y": 4,
      "z": 1,
      "name": "Rock_Volcanic_Brick"
    },
    {
      "x": -9,
      "y": 5,
      "z": 1,
      "name": "Rock_Volcanic_Brick"
    },
    {
      "x": -9,
      "y": 6,
      "z": 1,
      "name": "Rock_Volcanic_Brick"
    },
    {
      "x": -9,
      "y": 7,
      "z": 1,
      "name": "Rock_Volcanic_Brick"
    },
    {
      "x": -9,
      "y": 0,
      "z": 2,
      "name": "Rock_Volcanic_Brick"
    },
    {
      "x": -9,
      "y": 1,
      "z": 2,
      "name": "Rock_Volcanic_Brick"
    },
    {
      "x": -9,
      "y": 2,
      "z": 2,
      "name": "Rock_Volcanic_Brick"
    },
    {
      "x": -9,
      "y": 3,
      "z": 2,
      "name": "Rock_Volcanic_Brick"
    },
    {
      "x": -9,
      "y": 4,
      "z": 2,
      "name": "Rock_Volcanic_Brick"
    },
    {
      "x": -9,
      "y": 5,
      "z": 2,
      "name": "Rock_Volcanic_Brick"
    },
    {
      "x": -9,
      "y": 1,
      "z": 3,
      "name": "Rock_Volcanic_Brick"
    },
    {
      "x": -9,
      "y": 2,
      "z": 3,
      "name": "Rock_Volcanic_Brick"
    },
    {
      "x": -9,
      "y": 3,
      "z": 3,
      "name": "Rock_Volcanic_Brick"
    },
    {
      "x": -9,
      "y": 1,
      "z": 4,
      "name": "Rock_Volcanic_Brick"
    },
    {
      "x": -8,
      "y": 32,
      "z": -14,
      "name": "Rock_Volcanic_Brick"
    },
    {
      "x": -8,
      "y": 33,
      "z": -14,
      "name": "Rock_Volcanic_Brick"
    },
    {
      "x": -8,
      "y": 29,
      "z": -13,
      "name": "Rock_Volcanic_Brick"
    },
    {
      "x": -8,
      "y": 30,
      "z": -13,
      "name": "Rock_Volcanic_Brick"
    },
    {
      "x": -8,
      "y": 31,
      "z": -13,
      "name": "Rock_Volcanic_Brick"
    },
    {
      "x": -8,
      "y": 32,
      "z": -13,
      "name": "Rock_Volcanic_Brick"
    },
    {
      "x": -8,
      "y": 33,
      "z": -13,
      "name": "Rock_Volcanic_Brick"
    },
    {
      "x": -8,
      "y": 34,
      "z": -13,
      "name": "Rock_Volcanic_Brick"
    },
    {
      "x": -8,
      "y": 28,
      "z": -12,
      "name": "Rock_Volcanic_Brick"
    },
    {
      "x": -8,
      "y": 29,
      "z": -12,
      "name": "Rock_Volcanic_Brick"
    },
    {
      "x": -8,
      "y": 30,
      "z": -12,
      "name": "Rock_Volcanic_Brick"
    },
    {
      "x": -8,
      "y": 31,
      "z": -12,
      "name": "Rock_Volcanic_Brick"
    },
    {
      "x": -8,
      "y": 32,
      "z": -12,
      "name": "Rock_Volcanic_Brick"
    },
    {
      "x": -8,
      "y": 33,
      "z": -12,
      "name": "Rock_Volcanic_Brick"
    },
    {
      "x": -8,
      "y": 34,
      "z": -12,
      "name": "Rock_Volcanic_Brick"
    },
    {
      "x": -8,
      "y": 35,
      "z": -12,
      "name": "Rock_Volcanic_Brick"
    },
    {
      "x": -8,
      "y": 26,
      "z": -11,
      "name": "Rock_Volcanic_Brick"
    },
    {
      "x": -8,
      "y": 27,
      "z": -11,
      "name": "Rock_Volcanic_Brick"
    },
    {
      "x": -8,
      "y": 28,
      "z": -11,
      "name": "Rock_Volcanic_Brick"
    },
    {
      "x": -8,
      "y": 29,
      "z": -11,
      "name": "Rock_Volcanic_Brick"
    },
    {
      "x": -8,
      "y": 30,
      "z": -11,
      "name": "Rock_Volcanic_Brick"
    },
    {
      "x": -8,
      "y": 31,
      "z": -11,
      "name": "Rock_Volcanic_Brick"
    },
    {
      "x": -8,
      "y": 32,
      "z": -11,
      "name": "Rock_Volcanic_Brick"
    },
    {
      "x": -8,
      "y": 33,
      "z": -11,
      "name": "Rock_Volcanic_Brick"
    },
    {
      "x": -8,
      "y": 34,
      "z": -11,
      "name": "Rock_Volcanic_Brick"
    },
    {
      "x": -8,
      "y": 35,
      "z": -11,
      "name": "Rock_Volcanic_Brick"
    },
    {
      "x": -8,
      "y": 26,
      "z": -10,
      "name": "Rock_Volcanic_Brick"
    },
    {
      "x": -8,
      "y": 27,
      "z": -10,
      "name": "Rock_Volcanic_Brick"
    },
    {
      "x": -8,
      "y": 28,
      "z": -10,
      "name": "Rock_Volcanic_Brick"
    },
    {
      "x": -8,
      "y": 29,
      "z": -10,
      "name": "Rock_Volcanic_Brick"
    },
    {
      "x": -8,
      "y": 30,
      "z": -10,
      "name": "Rock_Volcanic_Brick"
    },
    {
      "x": -8,
      "y": 31,
      "z": -10,
      "name": "Rock_Volcanic_Brick"
    },
    {
      "x": -8,
      "y": 32,
      "z": -10,
      "name": "Rock_Volcanic_Brick"
    },
    {
      "x": -8,
      "y": 33,
      "z": -10,
      "name": "Rock_Volcanic_Brick"
    },
    {
      "x": -8,
      "y": 28,
      "z": -9,
      "name": "Rock_Volcanic_Brick"
    },
    {
      "x": -8,
      "y": 29,
      "z": -9,
      "name": "Rock_Volcanic_Brick"
    },
    {
      "x": -8,
      "y": 30,
      "z": -9,
      "name": "Rock_Volcanic_Brick"
    },
    {
      "x": -8,
      "y": 31,
      "z": -9,
      "name": "Rock_Volcanic_Brick"
    },
    {
      "x": -8,
      "y": 18,
      "z": -8,
      "name": "Rock_Volcanic_Brick"
    },
    {
      "x": -8,
      "y": 19,
      "z": -8,
      "name": "Rock_Volcanic_Brick"
    },
    {
      "x": -8,
      "y": 20,
      "z": -8,
      "name": "Rock_Volcanic_Brick"
    },
    {
      "x": -8,
      "y": 21,
      "z": -8,
      "name": "Rock_Volcanic_Brick"
    },
    {
      "x": -8,
      "y": 22,
      "z": -8,
      "name": "Rock_Volcanic_Brick"
    },
    {
      "x": -8,
      "y": 23,
      "z": -8,
      "name": "Rock_Volcanic_Brick"
    },
    {
      "x": -8,
      "y": 29,
      "z": -8,
      "name": "Rock_Volcanic_Brick"
    },
    {
      "x": -8,
      "y": 16,
      "z": -7,
      "name": "Rock_Volcanic_Brick"
    },
    {
      "x": -8,
      "y": 17,
      "z": -7,
      "name": "Rock_Volcanic_Brick"
    },
    {
      "x": -8,
      "y": 18,
      "z": -7,
      "name": "Rock_Volcanic_Brick"
    },
    {
      "x": -8,
      "y": 19,
      "z": -7,
      "name": "Rock_Volcanic_Brick"
    },
    {
      "x": -8,
      "y": 20,
      "z": -7,
      "name": "Rock_Volcanic_Brick"
    },
    {
      "x": -8,
      "y": 21,
      "z": -7,
      "name": "Rock_Volcanic_Brick"
    },
    {
      "x": -8,
      "y": 22,
      "z": -7,
      "name": "Rock_Volcanic_Brick"
    },
    {
      "x": -8,
      "y": 23,
      "z": -7,
      "name": "Rock_Volcanic_Brick"
    },
    {
      "x": -8,
      "y": 24,
      "z": -7,
      "name": "Rock_Volcanic_Brick"
    },
    {
      "x": -8,
      "y": 15,
      "z": -6,
      "name": "Rock_Volcanic_Brick"
    },
    {
      "x": -8,
      "y": 16,
      "z": -6,
      "name": "Rock_Volcanic_Brick"
    },
    {
      "x": -8,
      "y": 17,
      "z": -6,
      "name": "Rock_Volcanic_Brick"
    },
    {
      "x": -8,
      "y": 18,
      "z": -6,
      "name": "Rock_Volcanic_Brick"
    },
    {
      "x": -8,
      "y": 19,
      "z": -6,
      "name": "Rock_Volcanic_Brick"
    },
    {
      "x": -8,
      "y": 20,
      "z": -6,
      "name": "Rock_Volcanic_Brick"
    },
    {
      "x": -8,
      "y": 21,
      "z": -6,
      "name": "Rock_Volcanic_Brick"
    },
    {
      "x": -8,
      "y": 22,
      "z": -6,
      "name": "Rock_Volcanic_Brick"
    },
    {
      "x": -8,
      "y": 23,
      "z": -6,
      "name": "Rock_Volcanic_Brick"
    },
    {
      "x": -8,
      "y": 24,
      "z": -6,
      "name": "Rock_Volcanic_Brick"
    },
    {
      "x": -8,
      "y": 13,
      "z": -5,
      "name": "Rock_Volcanic_Brick"
    },
    {
      "x": -8,
      "y": 14,
      "z": -5,
      "name": "Rock_Volcanic_Brick"
    },
    {
      "x": -8,
      "y": 15,
      "z": -5,
      "name": "Rock_Volcanic_Brick"
    },
    {
      "x": -8,
      "y": 16,
      "z": -5,
      "name": "Rock_Volcanic_Brick"
    },
    {
      "x": -8,
      "y": 17,
      "z": -5,
      "name": "Rock_Volcanic_Brick"
    },
    {
      "x": -8,
      "y": 18,
      "z": -5,
      "name": "Rock_Volcanic_Brick"
    },
    {
      "x": -8,
      "y": 19,
      "z": -5,
      "name": "Rock_Volcanic_Brick"
    },
    {
      "x": -8,
      "y": 20,
      "z": -5,
      "name": "Rock_Volcanic_Brick"
    },
    {
      "x": -8,
      "y": 21,
      "z": -5,
      "name": "Rock_Volcanic_Brick"
    },
    {
      "x": -8,
      "y": 22,
      "z": -5,
      "name": "Rock_Volcanic_Brick"
    },
    {
      "x": -8,
      "y": 12,
      "z": -4,
      "name": "Rock_Volcanic_Brick"
    },
    {
      "x": -8,
      "y": 13,
      "z": -4,
      "name": "Rock_Volcanic_Brick"
    },
    {
      "x": -8,
      "y": 14,
      "z": -4,
      "name": "Rock_Volcanic_Brick"
    },
    {
      "x": -8,
      "y": 15,
      "z": -4,
      "name": "Rock_Volcanic_Brick"
    },
    {
      "x": -8,
      "y": 16,
      "z": -4,
      "name": "Rock_Volcanic_Brick"
    },
    {
      "x": -8,
      "y": 17,
      "z": -4,
      "name": "Rock_Volcanic_Brick"
    },
    {
      "x": -8,
      "y": 18,
      "z": -4,
      "name": "Rock_Volcanic_Brick"
    },
    {
      "x": -8,
      "y": 19,
      "z": -4,
      "name": "Rock_Volcanic_Brick"
    },
    {
      "x": -8,
      "y": 20,
      "z": -4,
      "name": "Rock_Volcanic_Brick"
    },
    {
      "x": -8,
      "y": 12,
      "z": -3,
      "name": "Rock_Volcanic_Brick"
    },
    {
      "x": -8,
      "y": 13,
      "z": -3,
      "name": "Rock_Volcanic_Brick"
    },
    {
      "x": -8,
      "y": 14,
      "z": -3,
      "name": "Rock_Volcanic_Brick"
    },
    {
      "x": -8,
      "y": 15,
      "z": -3,
      "name": "Rock_Volcanic_Brick"
    },
    {
      "x": -8,
      "y": 16,
      "z": -3,
      "name": "Rock_Volcanic_Brick"
    },
    {
      "x": -8,
      "y": 17,
      "z": -3,
      "name": "Rock_Volcanic_Brick"
    },
    {
      "x": -8,
      "y": 18,
      "z": -3,
      "name": "Rock_Volcanic_Brick"
    },
    {
      "x": -8,
      "y": 6,
      "z": -2,
      "name": "Rock_Volcanic_Brick"
    },
    {
      "x": -8,
      "y": 7,
      "z": -2,
      "name": "Rock_Volcanic_Brick"
    },
    {
      "x": -8,
      "y": 8,
      "z": -2,
      "name": "Rock_Volcanic_Brick"
    },
    {
      "x": -8,
      "y": 11,
      "z": -2,
      "name": "Rock_Volcanic_Brick"
    },
    {
      "x": -8,
      "y": 12,
      "z": -2,
      "name": "Rock_Volcanic_Brick"
    },
    {
      "x": -8,
      "y": 13,
      "z": -2,
      "name": "Rock_Volcanic_Brick"
    },
    {
      "x": -8,
      "y": 14,
      "z": -2,
      "name": "Rock_Volcanic_Brick"
    },
    {
      "x": -8,
      "y": 15,
      "z": -2,
      "name": "Rock_Volcanic_Brick"
    },
    {
      "x": -8,
      "y": 16,
      "z": -2,
      "name": "Rock_Volcanic_Brick"
    },
    {
      "x": -8,
      "y": 3,
      "z": -1,
      "name": "Rock_Volcanic_Brick"
    },
    {
      "x": -8,
      "y": 4,
      "z": -1,
      "name": "Rock_Volcanic_Brick"
    },
    {
      "x": -8,
      "y": 5,
      "z": -1,
      "name": "Rock_Volcanic_Brick"
    },
    {
      "x": -8,
      "y": 6,
      "z": -1,
      "name": "Rock_Volcanic_Brick"
    },
    {
      "x": -8,
      "y": 7,
      "z": -1,
      "name": "Rock_Volcanic_Brick"
    },
    {
      "x": -8,
      "y": 8,
      "z": -1,
      "name": "Rock_Volcanic_Brick"
    },
    {
      "x": -8,
      "y": 9,
      "z": -1,
      "name": "Rock_Volcanic_Brick"
    },
    {
      "x": -8,
      "y": 11,
      "z": -1,
      "name": "Rock_Volcanic_Brick"
    },
    {
      "x": -8,
      "y": 12,
      "z": -1,
      "name": "Rock_Volcanic_Brick"
    },
    {
      "x": -8,
      "y": 13,
      "z": -1,
      "name": "Rock_Volcanic_Brick"
    },
    {
      "x": -8,
      "y": 1,
      "z": 0,
      "name": "Rock_Volcanic_Brick"
    },
    {
      "x": -8,
      "y": 2,
      "z": 0,
      "name": "Rock_Volcanic_Brick"
    },
    {
      "x": -8,
      "y": 3,
      "z": 0,
      "name": "Rock_Volcanic_Brick"
    },
    {
      "x": -8,
      "y": 4,
      "z": 0,
      "name": "Rock_Volcanic_Brick"
    },
    {
      "x": -8,
      "y": 5,
      "z": 0,
      "name": "Rock_Volcanic_Brick"
    },
    {
      "x": -8,
      "y": 6,
      "z": 0,
      "name": "Rock_Volcanic_Brick"
    },
    {
      "x": -8,
      "y": 7,
      "z": 0,
      "name": "Rock_Volcanic_Brick"
    },
    {
      "x": -8,
      "y": 8,
      "z": 0,
      "name": "Rock_Volcanic_Brick"
    },
    {
      "x": -8,
      "y": 9,
      "z": 0,
      "name": "Rock_Volcanic_Brick"
    },
    {
      "x": -8,
      "y": 10,
      "z": 0,
      "name": "Rock_Volcanic_Brick"
    },
    {
      "x": -8,
      "y": 0,
      "z": 1,
      "name": "Rock_Volcanic_Brick"
    },
    {
      "x": -8,
      "y": 1,
      "z": 1,
      "name": "Rock_Volcanic_Brick"
    },
    {
      "x": -8,
      "y": 2,
      "z": 1,
      "name": "Rock_Volcanic_Brick"
    },
    {
      "x": -8,
      "y": 3,
      "z": 1,
      "name": "Rock_Volcanic_Brick"
    },
    {
      "x": -8,
      "y": 4,
      "z": 1,
      "name": "Rock_Volcanic_Brick"
    },
    {
      "x": -8,
      "y": 5,
      "z": 1,
      "name": "Rock_Volcanic_Brick"
    },
    {
      "x": -8,
      "y": 6,
      "z": 1,
      "name": "Rock_Volcanic_Brick"
    },
    {
      "x": -8,
      "y": 7,
      "z": 1,
      "name": "Rock_Volcanic_Brick"
    },
    {
      "x": -8,
      "y": 8,
      "z": 1,
      "name": "Rock_Volcanic_Brick"
    },
    {
      "x": -8,
      "y": 9,
      "z": 1,
      "name": "Rock_Volcanic_Brick"
    },
    {
      "x": -8,
      "y": 0,
      "z": 2,
      "name": "Rock_Volcanic_Brick"
    },
    {
      "x": -8,
      "y": 1,
      "z": 2,
      "name": "Rock_Volcanic_Brick"
    },
    {
      "x": -8,
      "y": 2,
      "z": 2,
      "name": "Rock_Volcanic_Brick"
    },
    {
      "x": -8,
      "y": 3,
      "z": 2,
      "name": "Rock_Volcanic_Brick"
    },
    {
      "x": -8,
      "y": 4,
      "z": 2,
      "name": "Rock_Volcanic_Brick"
    },
    {
      "x": -8,
      "y": 5,
      "z": 2,
      "name": "Rock_Volcanic_Brick"
    },
    {
      "x": -8,
      "y": 6,
      "z": 2,
      "name": "Rock_Volcanic_Brick"
    },
    {
      "x": -8,
      "y": 7,
      "z": 2,
      "name": "Rock_Volcanic_Brick"
    },
    {
      "x": -8,
      "y": 0,
      "z": 3,
      "name": "Rock_Volcanic_Brick"
    },
    {
      "x": -8,
      "y": 1,
      "z": 3,
      "name": "Rock_Volcanic_Brick"
    },
    {
      "x": -8,
      "y": 2,
      "z": 3,
      "name": "Rock_Volcanic_Brick"
    },
    {
      "x": -8,
      "y": 3,
      "z": 3,
      "name": "Rock_Volcanic_Brick"
    },
    {
      "x": -8,
      "y": 4,
      "z": 3,
      "name": "Rock_Volcanic_Brick"
    },
    {
      "x": -8,
      "y": 5,
      "z": 3,
      "name": "Rock_Volcanic_Brick"
    },
    {
      "x": -8,
      "y": 0,
      "z": 4,
      "name": "Rock_Volcanic_Brick"
    },
    {
      "x": -8,
      "y": 1,
      "z": 4,
      "name": "Rock_Volcanic_Brick"
    },
    {
      "x": -8,
      "y": 2,
      "z": 4,
      "name": "Rock_Volcanic_Brick"
    },
    {
      "x": -7,
      "y": 33,
      "z": -14,
      "name": "Rock_Volcanic_Brick"
    },
    {
      "x": -7,
      "y": 31,
      "z": -13,
      "name": "Rock_Volcanic_Brick"
    },
    {
      "x": -7,
      "y": 32,
      "z": -13,
      "name": "Rock_Volcanic_Brick"
    },
    {
      "x": -7,
      "y": 33,
      "z": -13,
      "name": "Rock_Volcanic_Brick"
    },
    {
      "x": -7,
      "y": 34,
      "z": -13,
      "name": "Rock_Volcanic_Brick"
    },
    {
      "x": -7,
      "y": 29,
      "z": -12,
      "name": "Rock_Volcanic_Brick"
    },
    {
      "x": -7,
      "y": 30,
      "z": -12,
      "name": "Rock_Volcanic_Brick"
    },
    {
      "x": -7,
      "y": 31,
      "z": -12,
      "name": "Rock_Volcanic_Brick"
    },
    {
      "x": -7,
      "y": 32,
      "z": -12,
      "name": "Rock_Volcanic_Brick"
    },
    {
      "x": -7,
      "y": 33,
      "z": -12,
      "name": "Rock_Volcanic_Brick"
    },
    {
      "x": -7,
      "y": 34,
      "z": -12,
      "name": "Rock_Volcanic_Brick"
    },
    {
      "x": -7,
      "y": 35,
      "z": -12,
      "name": "Rock_Volcanic_Brick"
    },
    {
      "x": -7,
      "y": 27,
      "z": -11,
      "name": "Rock_Volcanic_Brick"
    },
    {
      "x": -7,
      "y": 28,
      "z": -11,
      "name": "Rock_Volcanic_Brick"
    },
    {
      "x": -7,
      "y": 29,
      "z": -11,
      "name": "Rock_Volcanic_Brick"
    },
    {
      "x": -7,
      "y": 30,
      "z": -11,
      "name": "Rock_Volcanic_Brick"
    },
    {
      "x": -7,
      "y": 31,
      "z": -11,
      "name": "Rock_Volcanic_Brick"
    },
    {
      "x": -7,
      "y": 32,
      "z": -11,
      "name": "Rock_Volcanic_Brick"
    },
    {
      "x": -7,
      "y": 33,
      "z": -11,
      "name": "Rock_Volcanic_Brick"
    },
    {
      "x": -7,
      "y": 34,
      "z": -11,
      "name": "Rock_Volcanic_Brick"
    },
    {
      "x": -7,
      "y": 35,
      "z": -11,
      "name": "Rock_Volcanic_Brick"
    },
    {
      "x": -7,
      "y": 27,
      "z": -10,
      "name": "Rock_Volcanic_Brick"
    },
    {
      "x": -7,
      "y": 28,
      "z": -10,
      "name": "Rock_Volcanic_Brick"
    },
    {
      "x": -7,
      "y": 29,
      "z": -10,
      "name": "Rock_Volcanic_Brick"
    },
    {
      "x": -7,
      "y": 30,
      "z": -10,
      "name": "Rock_Volcanic_Brick"
    },
    {
      "x": -7,
      "y": 31,
      "z": -10,
      "name": "Rock_Volcanic_Brick"
    },
    {
      "x": -7,
      "y": 32,
      "z": -10,
      "name": "Rock_Volcanic_Brick"
    },
    {
      "x": -7,
      "y": 33,
      "z": -10,
      "name": "Rock_Volcanic_Brick"
    },
    {
      "x": -7,
      "y": 34,
      "z": -10,
      "name": "Rock_Volcanic_Brick"
    },
    {
      "x": -7,
      "y": 28,
      "z": -9,
      "name": "Rock_Volcanic_Brick"
    },
    {
      "x": -7,
      "y": 29,
      "z": -9,
      "name": "Rock_Volcanic_Brick"
    },
    {
      "x": -7,
      "y": 30,
      "z": -9,
      "name": "Rock_Volcanic_Brick"
    },
    {
      "x": -7,
      "y": 31,
      "z": -9,
      "name": "Rock_Volcanic_Brick"
    },
    {
      "x": -7,
      "y": 32,
      "z": -9,
      "name": "Rock_Volcanic_Brick"
    },
    {
      "x": -7,
      "y": 33,
      "z": -9,
      "name": "Rock_Volcanic_Brick"
    },
    {
      "x": -7,
      "y": 20,
      "z": -8,
      "name": "Rock_Volcanic_Brick"
    },
    {
      "x": -7,
      "y": 21,
      "z": -8,
      "name": "Rock_Volcanic_Brick"
    },
    {
      "x": -7,
      "y": 22,
      "z": -8,
      "name": "Rock_Volcanic_Brick"
    },
    {
      "x": -7,
      "y": 23,
      "z": -8,
      "name": "Rock_Volcanic_Brick"
    },
    {
      "x": -7,
      "y": 24,
      "z": -8,
      "name": "Rock_Volcanic_Brick"
    },
    {
      "x": -7,
      "y": 27,
      "z": -8,
      "name": "Rock_Volcanic_Brick"
    },
    {
      "x": -7,
      "y": 28,
      "z": -8,
      "name": "Rock_Volcanic_Brick"
    },
    {
      "x": -7,
      "y": 29,
      "z": -8,
      "name": "Rock_Volcanic_Brick"
    },
    {
      "x": -7,
      "y": 30,
      "z": -8,
      "name": "Rock_Volcanic_Brick"
    },
    {
      "x": -7,
