{
  "version": 8,
  "blockIdVersion": 11,
  "anchorX": -11,
  "anchorY": 14,
  "anchorZ": 3,
  "blocks": [
    {
      "x": -16,
      "y": 13,
      "z": 3,
      "name": "Rock_Slate"
    },
    {
      "x": -15,
      "y": 13,
      "z": 2,
      "name": "Rock_Slate"
    },
    {
      "x": -15,
      "y": 12,
      "z": 3,
      "name": "Rock_Slate"
    },
    {
      "x": -15,
      "y": 13,
      "z": 3,
      "name": "Rock_Slate"
    },
    {
      "x": -14,
      "y": 13,
      "z": 1,
      "name": "Rock_Slate"
    },
    {
      "x": -14,
      "y": 13,
      "z": 2,
      "name": "Rock_Slate"
    },
    {
      "x": -14,
      "y": 12,
      "z": 3,
      "name": "Rock_Slate"
    },
    {
      "x": -14,
      "y": 13,
      "z": 3,
      "name": "Rock_Slate"
    },
    {
      "x": -14,
      "y": 13,
      "z": 4,
      "name": "Rock_Slate"
    },
    {
      "x": -13,
      "y": 12,
      "z": 1,
      "name": "Rock_Slate"
    },
    {
      "x": -13,
      "y": 13,
      "z": 1,
      "name": "Rock_Slate"
    },
    {
      "x": -13,
      "y": 11,
      "z": 2,
      "name": "Rock_Slate"
    },
    {
      "x": -13,
      "y": 12,
      "z": 2,
      "name": "Rock_Slate"
    },
    {
      "x": -13,
      "y": 13,
      "z": 2,
      "name": "Rock_Slate_Cobble"
    },
    {
      "x": -13,
      "y": 11,
      "z": 3,
      "name": "Rock_Slate"
    },
    {
      "x": -13,
      "y": 12,
      "z": 3,
      "name": "Rock_Slate"
    },
    {
      "x": -13,
      "y": 13,
      "z": 3,
      "name": "Rock_Slate"
    },
    {
      "x": -13,
      "y": 12,
      "z": 4,
      "name": "Rock_Slate"
    },
    {
      "x": -13,
      "y": 13,
      "z": 4,
      "name": "Rock_Slate"
    },
    {
      "x": -12,
      "y": 13,
      "z": 0,
      "name": "Rock_Slate"
    },
    {
      "x": -12,
      "y": 12,
      "z": 1,
      "name": "Rock_Slate"
    },
    {
      "x": -12,
      "y": 13,
      "z": 1,
      "name": "Rock_Slate"
    },
    {
      "x": -12,
      "y": 10,
      "z": 2,
      "name": "Rock_Slate"
    },
    {
      "x": -12,
      "y": 11,
      "z": 2,
      "name": "Rock_Slate"
    },
    {
      "x": -12,
      "y": 12,
      "z": 2,
      "name": "Rock_Slate"
    },
    {
      "x": -12,
      "y": 13,
      "z": 2,
      "name": "Rock_Slate"
    },
    {
      "x": -12,
      "y": 14,
      "z": 2,
      "name": "Rock_Slate"
    },
    {
      "x": -12,
      "y": 10,
      "z": 3,
      "name": "Rock_Slate_Cobble"
    },
    {
      "x": -12,
      "y": 11,
      "z": 3,
      "name": "Rock_Slate"
    },
    {
      "x": -12,
      "y": 12,
      "z": 3,
      "name": "Rock_Slate"
    },
    {
      "x": -12,
      "y": 13,
      "z": 3,
      "name": "Rock_Slate_Cobble"
    },
    {
      "x": -12,
      "y": 10,
      "z": 4,
      "name": "Rock_Slate_Cobble"
    },
    {
      "x": -12,
      "y": 11,
      "z": 4,
      "name": "Rock_Slate_Cobble"
    },
    {
      "x": -12,
      "y": 12,
      "z": 4,
      "name": "Rock_Slate"
    },
    {
      "x": -12,
      "y": 13,
      "z": 4,
      "name": "Rock_Slate"
    },
    {
      "x": -12,
      "y": 13,
      "z": 5,
      "name": "Rock_Slate"
    },
    {
      "x": -12,
      "y": 13,
      "z": 6,
      "name": "Rock_Slate"
    },
    {
      "x": -11,
      "y": 12,
      "z": -2,
      "name": "Rock_Slate_Cobble"
    },
    {
      "x": -11,
      "y": 13,
      "z": -2,
      "name": "Rock_Slate"
    },
    {
      "x": -11,
      "y": 13,
      "z": -1,
      "name": "Rock_Slate"
    },
    {
      "x": -11,
      "y": 12,
      "z": 0,
      "name": "Rock_Slate_Cobble"
    },
    {
      "x": -11,
      "y": 13,
      "z": 0,
      "name": "Rock_Slate"
    },
    {
      "x": -11,
      "y": 10,
      "z": 1,
      "name": "Rock_Slate"
    },
    {
      "x": -11,
      "y": 11,
      "z": 1,
      "name": "Rock_Slate_Cobble"
    },
    {
      "x": -11,
      "y": 12,
      "z": 1,
      "name": "Rock_Shale_Brick"
    },
    {
      "x": -11,
      "y": 13,
      "z": 1,
      "name": "Rock_Shale_Brick"
    },
    {
      "x": -11,
      "y": 14,
      "z": 1,
      "name": "Rock_Shale_Brick"
    },
    {
      "x": -11,
      "y": 15,
      "z": 1,
      "name": "Rock_Shale_Brick_Smooth"
    },
    {
      "x": -11,
      "y": 10,
      "z": 2,
      "name": "Rock_Slate"
    },
    {
      "x": -11,
      "y": 11,
      "z": 2,
      "name": "Rock_Slate"
    },
    {
      "x": -11,
      "y": 12,
      "z": 2,
      "name": "Rock_Shale_Brick"
    },
    {
      "x": -11,
      "y": 13,
      "z": 2,
      "name": "Rock_Shale_Brick"
    },
    {
      "x": -11,
      "y": 14,
      "z": 2,
      "name": "Rock_Shale_Brick"
    },
    {
      "x": -11,
      "y": 15,
      "z": 2,
      "name": "Rock_Shale_Brick"
    },
    {
      "x": -11,
      "y": 10,
      "z": 3,
      "name": "Rock_Slate_Cobble"
    },
    {
      "x": -11,
      "y": 11,
      "z": 3,
      "name": "Rock_Slate"
    },
    {
      "x": -11,
      "y": 12,
      "z": 3,
      "name": "Rock_Shale_Brick"
    },
    {
      "x": -11,
      "y": 13,
      "z": 3,
      "name": "Rock_Shale_Brick"
    },
    {
      "x": -11,
      "y": 14,
      "z": 3,
      "name": "Rock_Shale_Brick"
    },
    {
      "x": -11,
      "y": 15,
      "z": 3,
      "name": "Rock_Shale_Brick"
    },
    {
      "x": -11,
      "y": 10,
      "z": 4,
      "name": "Rock_Slate"
    },
    {
      "x": -11,
      "y": 11,
      "z": 4,
      "name": "Rock_Slate"
    },
    {
      "x": -11,
      "y": 12,
      "z": 4,
      "name": "Rock_Shale_Brick"
    },
    {
      "x": -11,
      "y": 13,
      "z": 4,
      "name": "Rock_Shale_Brick"
    },
    {
      "x": -11,
      "y": 14,
      "z": 4,
      "name": "Rock_Shale_Brick"
    },
    {
      "x": -11,
      "y": 15,
      "z": 4,
      "name": "Rock_Shale_Brick_Smooth"
    },
    {
      "x": -11,
      "y": 10,
      "z": 5,
      "name": "Rock_Slate"
    },
    {
      "x": -11,
      "y": 11,
      "z": 5,
      "name": "Rock_Slate"
    },
    {
      "x": -11,
      "y": 12,
      "z": 5,
      "name": "Rock_Slate"
    },
    {
      "x": -11,
      "y": 13,
      "z": 5,
      "name": "Rock_Slate"
    },
    {
      "x": -11,
      "y": 12,
      "z": 6,
      "name": "Rock_Slate_Cobble"
    },
    {
      "x": -11,
      "y": 13,
      "z": 6,
      "name": "Rock_Slate"
    },
    {
      "x": -10,
      "y": 12,
      "z": -3,
      "name": "Rock_Slate"
    },
    {
      "x": -10,
      "y": 13,
      "z": -3,
      "name": "Rock_Slate"
    },
    {
      "x": -10,
      "y": 9,
      "z": -2,
      "name": "Rock_Slate"
    },
    {
      "x": -10,
      "y": 12,
      "z": -2,
      "name": "Rock_Slate"
    },
    {
      "x": -10,
      "y": 13,
      "z": -2,
      "name": "Rock_Slate_Cobble"
    },
    {
      "x": -10,
      "y": 10,
      "z": -1,
      "name": "Rock_Slate"
    },
    {
      "x": -10,
      "y": 11,
      "z": -1,
      "name": "Rock_Slate"
    },
    {
      "x": -10,
      "y": 12,
      "z": -1,
      "name": "Rock_Slate"
    },
    {
      "x": -10,
      "y": 13,
      "z": -1,
      "name": "Rock_Slate_Cobble"
    },
    {
      "x": -10,
      "y": 11,
      "z": 0,
      "name": "Rock_Slate_Cobble"
    },
    {
      "x": -10,
      "y": 12,
      "z": 0,
      "name": "Rock_Shale_Brick"
    },
    {
      "x": -10,
      "y": 13,
      "z": 0,
      "name": "Rock_Shale_Brick"
    },
    {
      "x": -10,
      "y": 14,
      "z": 0,
      "name": "Rock_Shale_Brick"
    },
    {
      "x": -10,
      "y": 15,
      "z": 0,
      "name": "Rock_Shale_Brick_Smooth"
    },
    {
      "x": -10,
      "y": 16,
      "z": 0,
      "name": "Furniture_Human_Ruins_Brazier"
    },
    {
      "x": -10,
      "y": 10,
      "z": 1,
      "name": "Rock_Slate_Cobble"
    },
    {
      "x": -10,
      "y": 11,
      "z": 1,
      "name": "Rock_Slate_Cobble"
    },
    {
      "x": -10,
      "y": 12,
      "z": 1,
      "name": "Rock_Shale_Brick"
    },
    {
      "x": -10,
      "y": 13,
      "z": 1,
      "name": "Rock_Shale_Brick"
    },
    {
      "x": -10,
      "y": 14,
      "z": 1,
      "name": "Rock_Shale_Brick"
    },
    {
      "x": -10,
      "y": 15,
      "z": 1,
      "name": "Rock_Shale_Brick"
    },
    {
      "x": -10,
      "y": 8,
      "z": 2,
      "name": "Rock_Slate"
    },
    {
      "x": -10,
      "y": 10,
      "z": 2,
      "name": "Rock_Slate"
    },
    {
      "x": -10,
      "y": 11,
      "z": 2,
      "name": "Rock_Slate"
    },
    {
      "x": -10,
      "y": 12,
      "z": 2,
      "name": "Rock_Shale_Brick"
    },
    {
      "x": -10,
      "y": 13,
      "z": 2,
      "name": "Rock_Shale_Brick"
    },
    {
      "x": -10,
      "y": 14,
      "z": 2,
      "name": "Rock_Shale_Brick"
    },
    {
      "x": -10,
      "y": 15,
      "z": 2,
      "name": "Rock_Shale_Brick_Stairs",
      "rotation": 1
    },
    {
      "x": -10,
      "y": 9,
      "z": 3,
      "name": "Rock_Slate"
    },
    {
      "x": -10,
      "y": 10,
      "z": 3,
      "name": "Rock_Slate"
    },
    {
      "x": -10,
      "y": 11,
      "z": 3,
      "name": "Rock_Slate"
    },
    {
      "x": -10,
      "y": 12,
      "z": 3,
      "name": "Rock_Shale_Brick"
    },
    {
      "x": -10,
      "y": 13,
      "z": 3,
      "name": "Rock_Shale_Brick"
    },
    {
      "x": -10,
      "y": 14,
      "z": 3,
      "name": "Rock_Shale_Brick"
    },
    {
      "x": -10,
      "y": 15,
      "z": 3,
      "name": "Rock_Shale_Brick_Stairs",
      "rotation": 1
    },
    {
      "x": -10,
      "y": 9,
      "z": 4,
      "name": "Rock_Slate_Cobble"
    },
    {
      "x": -10,
      "y": 10,
      "z": 4,
      "name": "Rock_Slate"
    },
    {
      "x": -10,
      "y": 11,
      "z": 4,
      "name": "Rock_Slate"
    },
    {
      "x": -10,
      "y": 12,
      "z": 4,
      "name": "Rock_Shale_Brick"
    },
    {
      "x": -10,
      "y": 13,
      "z": 4,
      "name": "Rock_Shale_Brick"
    },
    {
      "x": -10,
      "y": 14,
      "z": 4,
      "name": "Rock_Shale_Brick"
    },
    {
      "x": -10,
      "y": 15,
      "z": 4,
      "name": "Rock_Shale_Brick"
    },
    {
      "x": -10,
      "y": 10,
      "z": 5,
      "name": "Rock_Slate"
    },
    {
      "x": -10,
      "y": 11,
      "z": 5,
      "name": "Rock_Slate"
    },
    {
      "x": -10,
      "y": 12,
      "z": 5,
      "name": "Rock_Shale_Brick"
    },
    {
      "x": -10,
      "y": 13,
      "z": 5,
      "name": "Rock_Shale_Brick"
    },
    {
      "x": -10,
      "y": 14,
      "z": 5,
      "name": "Rock_Shale_Brick"
    },
    {
      "x": -10,
      "y": 15,
      "z": 5,
      "name": "Rock_Shale_Brick_Smooth"
    },
    {
      "x": -10,
      "y": 16,
      "z": 5,
      "name": "Furniture_Human_Ruins_Brazier"
    },
    {
      "x": -10,
      "y": 11,
      "z": 6,
      "name": "Rock_Slate"
    },
    {
      "x": -10,
      "y": 12,
      "z": 6,
      "name": "Rock_Slate"
    },
    {
      "x": -10,
      "y": 13,
      "z": 6,
      "name": "Rock_Slate"
    },
    {
      "x": -9,
      "y": 12,
      "z": -9,
      "name": "Rock_Slate"
    },
    {
      "x": -9,
      "y": 13,
      "z": -6,
      "name": "Rock_Slate"
    },
    {
      "x": -9,
      "y": 13,
      "z": -5,
      "name": "Rock_Slate"
    },
    {
      "x": -9,
      "y": 9,
      "z": -3,
      "name": "Rock_Slate"
    },
    {
      "x": -9,
      "y": 10,
      "z": -3,
      "name": "Rock_Slate"
    },
    {
      "x": -9,
      "y": 11,
      "z": -3,
      "name": "Rock_Slate"
    },
    {
      "x": -9,
      "y": 12,
      "z": -3,
      "name": "Rock_Slate"
    },
    {
      "x": -9,
      "y": 13,
      "z": -3,
      "name": "Rock_Slate"
    },
    {
      "x": -9,
      "y": 9,
      "z": -2,
      "name": "Rock_Slate"
    },
    {
      "x": -9,
      "y": 10,
      "z": -2,
      "name": "Rock_Slate"
    },
    {
      "x": -9,
      "y": 11,
      "z": -2,
      "name": "Rock_Slate"
    },
    {
      "x": -9,
      "y": 12,
      "z": -2,
      "name": "Rock_Slate_Cobble"
    },
    {
      "x": -9,
      "y": 13,
      "z": -2,
      "name": "Rock_Slate"
    },
    {
      "x": -9,
      "y": 9,
      "z": -1,
      "name": "Rock_Slate"
    },
    {
      "x": -9,
      "y": 10,
      "z": -1,
      "name": "Rock_Slate"
    },
    {
      "x": -9,
      "y": 11,
      "z": -1,
      "name": "Rock_Slate"
    },
    {
      "x": -9,
      "y": 12,
      "z": -1,
      "name": "Rock_Slate_Cobble"
    },
    {
      "x": -9,
      "y": 13,
      "z": -1,
      "name": "Rock_Slate_Cobble"
    },
    {
      "x": -9,
      "y": 8,
      "z": 0,
      "name": "Rock_Slate"
    },
    {
      "x": -9,
      "y": 10,
      "z": 0,
      "name": "Rock_Slate"
    },
    {
      "x": -9,
      "y": 11,
      "z": 0,
      "name": "Rock_Slate"
    },
    {
      "x": -9,
      "y": 12,
      "z": 0,
      "name": "Rock_Shale_Brick"
    },
    {
      "x": -9,
      "y": 13,
      "z": 0,
      "name": "Rock_Shale_Brick"
    },
    {
      "x": -9,
      "y": 14,
      "z": 0,
      "name": "Rock_Shale_Brick"
    },
    {
      "x": -9,
      "y": 15,
      "z": 0,
      "name": "Rock_Shale_Brick"
    },
    {
      "x": -9,
      "y": 8,
      "z": 1,
      "name": "Rock_Slate"
    },
    {
      "x": -9,
      "y": 10,
      "z": 1,
      "name": "Rock_Slate"
    },
    {
      "x": -9,
      "y": 11,
      "z": 1,
      "name": "Rock_Slate"
    },
    {
      "x": -9,
      "y": 12,
      "z": 1,
      "name": "Rock_Shale_Brick"
    },
    {
      "x": -9,
      "y": 13,
      "z": 1,
      "name": "Rock_Shale_Brick"
    },
    {
      "x": -9,
      "y": 14,
      "z": 1,
      "name": "Rock_Shale_Brick"
    },
    {
      "x": -9,
      "y": 7,
      "z": 2,
      "name": "Rock_Slate"
    },
    {
      "x": -9,
      "y": 8,
      "z": 2,
      "name": "Rock_Slate"
    },
    {
      "x": -9,
      "y": 9,
      "z": 2,
      "name": "Rock_Slate_Cobble"
    },
    {
      "x": -9,
      "y": 10,
      "z": 2,
      "name": "Rock_Slate"
    },
    {
      "x": -9,
      "y": 11,
      "z": 2,
      "name": "Rock_Slate"
    },
    {
      "x": -9,
      "y": 12,
      "z": 2,
      "name": "Rock_Shale_Brick"
    },
    {
      "x": -9,
      "y": 13,
      "z": 2,
      "name": "Rock_Shale_Brick"
    },
    {
      "x": -9,
      "y": 14,
      "z": 2,
      "name": "Rock_Shale_Brick"
    },
    {
      "x": -9,
      "y": 7,
      "z": 3,
      "name": "Rock_Slate_Cobble"
    },
    {
      "x": -9,
      "y": 8,
      "z": 3,
      "name": "Rock_Slate_Cobble"
    },
    {
      "x": -9,
      "y": 9,
      "z": 3,
      "name": "Rock_Slate"
    },
    {
      "x": -9,
      "y": 10,
      "z": 3,
      "name": "Rock_Slate"
    },
    {
      "x": -9,
      "y": 11,
      "z": 3,
      "name": "Rock_Slate_Cobble"
    },
    {
      "x": -9,
      "y": 12,
      "z": 3,
      "name": "Rock_Shale_Brick"
    },
    {
      "x": -9,
      "y": 13,
      "z": 3,
      "name": "Rock_Shale_Brick"
    },
    {
      "x": -9,
      "y": 14,
      "z": 3,
      "name": "Rock_Shale_Brick"
    },
    {
      "x": -9,
      "y": 8,
      "z": 4,
      "name": "Rock_Slate"
    },
    {
      "x": -9,
      "y": 9,
      "z": 4,
      "name": "Rock_Slate"
    },
    {
      "x": -9,
      "y": 10,
      "z": 4,
      "name": "Rock_Slate"
    },
    {
      "x": -9,
      "y": 11,
      "z": 4,
      "name": "Rock_Slate"
    },
    {
      "x": -9,
      "y": 12,
      "z": 4,
      "name": "Rock_Shale_Brick"
    },
    {
      "x": -9,
      "y": 13,
      "z": 4,
      "name": "Rock_Shale_Brick"
    },
    {
      "x": -9,
      "y": 14,
      "z": 4,
      "name": "Rock_Shale_Brick"
    },
    {
      "x": -9,
      "y": 9,
      "z": 5,
      "name": "Rock_Slate_Cobble"
    },
    {
      "x": -9,
      "y": 10,
      "z": 5,
      "name": "Rock_Slate_Cobble"
    },
    {
      "x": -9,
      "y": 11,
      "z": 5,
      "name": "Rock_Slate"
    },
    {
      "x": -9,
      "y": 12,
      "z": 5,
      "name": "Rock_Shale_Brick"
    },
    {
      "x": -9,
      "y": 13,
      "z": 5,
      "name": "Rock_Shale_Brick"
    },
    {
      "x": -9,
      "y": 14,
      "z": 5,
      "name": "Rock_Shale_Brick"
    },
    {
      "x": -9,
      "y": 15,
      "z": 5,
      "name": "Rock_Shale_Brick"
    },
    {
      "x": -9,
      "y": 10,
      "z": 6,
      "name": "Rock_Slate"
    },
    {
      "x": -9,
      "y": 11,
      "z": 6,
      "name": "Rock_Slate"
    },
    {
      "x": -9,
      "y": 12,
      "z": 6,
      "name": "Rock_Slate_Cobble"
    },
    {
      "x": -9,
      "y": 13,
      "z": 6,
      "name": "Rock_Slate_Cobble"
    },
    {
      "x": -9,
      "y": 14,
      "z": 6,
      "name": "Rock_Slate"
    },
    {
      "x": -9,
      "y": 11,
      "z": 7,
      "name": "Rock_Slate"
    },
    {
      "x": -9,
      "y": 12,
      "z": 7,
      "name": "Rock_Slate"
    },
    {
      "x": -9,
      "y": 13,
      "z": 7,
      "name": "Rock_Slate"
    },
    {
      "x": -9,
      "y": 12,
      "z": 14,
      "name": "Rock_Slate"
    },
    {
      "x": -8,
      "y": 12,
      "z": -9,
      "name": "Rock_Slate"
    },
    {
      "x": -8,
      "y": 11,
      "z": -8,
      "name": "Rock_Slate"
    },
    {
      "x": -8,
      "y": 12,
      "z": -8,
      "name": "Rock_Slate"
    },
    {
      "x": -8,
      "y": 11,
      "z": -7,
      "name": "Rock_Slate"
    },
    {
      "x": -8,
      "y": 12,
      "z": -7,
      "name": "Rock_Slate"
    },
    {
      "x": -8,
      "y": 13,
      "z": -7,
      "name": "Rock_Slate"
    },
    {
      "x": -8,
      "y": 12,
      "z": -6,
      "name": "Rock_Slate"
    },
    {
      "x": -8,
      "y": 13,
      "z": -6,
      "name": "Rock_Slate"
    },
    {
      "x": -8,
      "y": 12,
      "z": -5,
      "name": "Rock_Slate"
    },
    {
      "x": -8,
      "y": 13,
      "z": -5,
      "name": "Rock_Slate"
    },
    {
      "x": -8,
      "y": 11,
      "z": -4,
      "name": "Rock_Slate"
    },
    {
      "x": -8,
      "y": 13,
      "z": -4,
      "name": "Rock_Slate"
    },
    {
      "x": -8,
      "y": 10,
      "z": -3,
      "name": "Rock_Slate_Cobble"
    },
    {
      "x": -8,
      "y": 11,
      "z": -3,
      "name": "Rock_Slate"
    },
    {
      "x": -8,
      "y": 12,
      "z": -3,
      "name": "Rock_Slate_Cobble"
    },
    {
      "x": -8,
      "y": 13,
      "z": -3,
      "name": "Rock_Slate_Cobble"
    },
    {
      "x": -8,
      "y": 9,
      "z": -2,
      "name": "Rock_Slate"
    },
    {
      "x": -8,
      "y": 10,
      "z": -2,
      "name": "Rock_Slate"
    },
    {
      "x": -8,
      "y": 11,
      "z": -2,
      "name": "Rock_Slate_Cobble"
    },
    {
      "x": -8,
      "y": 12,
      "z": -2,
      "name": "Rock_Slate"
    },
    {
      "x": -8,
      "y": 13,
      "z": -2,
      "name": "Rock_Slate"
    },
    {
      "x": -8,
      "y": 8,
      "z": -1,
      "name": "Rock_Slate"
    },
    {
      "x": -8,
      "y": 9,
      "z": -1,
      "name": "Rock_Slate"
    },
    {
      "x": -8,
      "y": 10,
      "z": -1,
      "name": "Rock_Slate"
    },
    {
      "x": -8,
      "y": 11,
      "z": -1,
      "name": "Rock_Slate"
    },
    {
      "x": -8,
      "y": 12,
      "z": -1,
      "name": "Rock_Slate"
    },
    {
      "x": -8,
      "y": 13,
      "z": -1,
      "name": "Rock_Slate_Cobble"
    },
    {
      "x": -8,
      "y": 14,
      "z": -1,
      "name": "Rock_Slate"
    },
    {
      "x": -8,
      "y": 8,
      "z": 0,
      "name": "Rock_Slate_Cobble"
    },
    {
      "x": -8,
      "y": 9,
      "z": 0,
      "name": "Rock_Slate_Cobble"
    },
    {
      "x": -8,
      "y": 10,
      "z": 0,
      "name": "Rock_Slate"
    },
    {
      "x": -8,
      "y": 11,
      "z": 0,
      "name": "Rock_Slate"
    },
    {
      "x": -8,
      "y": 12,
      "z": 0,
      "name": "Rock_Shale_Brick"
    },
    {
      "x": -8,
      "y": 13,
      "z": 0,
      "name": "Rock_Shale_Brick"
    },
    {
      "x": -8,
      "y": 14,
      "z": 0,
      "name": "Rock_Shale_Brick"
    },
    {
      "x": -8,
      "y": 15,
      "z": 0,
      "name": "Rock_Shale_Brick"
    },
    {
      "x": -8,
      "y": 7,
      "z": 1,
      "name": "Rock_Slate"
    },
    {
      "x": -8,
      "y": 8,
      "z": 1,
      "name": "Rock_Slate"
    },
    {
      "x": -8,
      "y": 9,
      "z": 1,
      "name": "Rock_Slate"
    },
    {
      "x": -8,
      "y": 10,
      "z": 1,
      "name": "Rock_Slate_Cobble"
    },
    {
      "x": -8,
      "y": 11,
      "z": 1,
      "name": "Rock_Slate_Cobble"
    },
    {
      "x": -8,
      "y": 12,
      "z": 1,
      "name": "Rock_Shale_Brick"
    },
    {
      "x": -8,
      "y": 13,
      "z": 1,
      "name": "Rock_Shale_Brick"
    },
    {
      "x": -8,
      "y": 14,
      "z": 1,
      "name": "Rock_Shale_Brick"
    },
    {
      "x": -8,
      "y": 7,
      "z": 2,
      "name": "Rock_Slate_Cobble"
    },
    {
      "x": -8,
      "y": 8,
      "z": 2,
      "name": "Rock_Slate"
    },
    {
      "x": -8,
      "y": 9,
      "z": 2,
      "name": "Rock_Slate"
    },
    {
      "x": -8,
      "y": 10,
      "z": 2,
      "name": "Rock_Slate"
    },
    {
      "x": -8,
      "y": 11,
      "z": 2,
      "name": "Rock_Slate"
    },
    {
      "x": -8,
      "y": 12,
      "z": 2,
      "name": "Rock_Shale_Brick"
    },
    {
      "x": -8,
      "y": 13,
      "z": 2,
      "name": "Rock_Shale_Brick"
    },
    {
      "x": -8,
      "y": 14,
      "z": 2,
      "name": "Rock_Shale_Brick"
    },
    {
      "x": -8,
      "y": 6,
      "z": 3,
      "name": "Rock_Slate_Cobble"
    },
    {
      "x": -8,
      "y": 7,
      "z": 3,
      "name": "Rock_Slate"
    },
    {
      "x": -8,
      "y": 8,
      "z": 3,
      "name": "Rock_Slate"
    },
    {
      "x": -8,
      "y": 9,
      "z": 3,
      "name": "Rock_Slate"
    },
    {
      "x": -8,
      "y": 10,
      "z": 3,
      "name": "Rock_Slate_Cobble"
    },
    {
      "x": -8,
      "y": 11,
      "z": 3,
      "name": "Rock_Slate"
    },
    {
      "x": -8,
      "y": 12,
      "z": 3,
      "name": "Rock_Shale_Brick"
    },
    {
      "x": -8,
      "y": 13,
      "z": 3,
      "name": "Rock_Shale_Brick"
    },
    {
      "x": -8,
      "y": 14,
      "z": 3,
      "name": "Rock_Shale_Brick"
    },
    {
      "x": -8,
      "y": 7,
      "z": 4,
      "name": "Rock_Slate"
    },
    {
      "x": -8,
      "y": 8,
      "z": 4,
      "name": "Rock_Slate"
    },
    {
      "x": -8,
      "y": 9,
      "z": 4,
      "name": "Rock_Slate"
    },
    {
      "x": -8,
      "y": 10,
      "z": 4,
      "name": "Rock_Slate"
    },
    {
      "x": -8,
      "y": 11,
      "z": 4,
      "name": "Rock_Slate_Cobble"
    },
    {
      "x": -8,
      "y": 12,
      "z": 4,
      "name": "Rock_Shale_Brick"
    },
    {
      "x": -8,
      "y": 13,
      "z": 4,
      "name": "Rock_Shale_Brick"
    },
    {
      "x": -8,
      "y": 14,
      "z": 4,
      "name": "Rock_Shale_Brick"
    },
    {
      "x": -8,
      "y": 7,
      "z": 5,
      "name": "Rock_Slate"
    },
    {
      "x": -8,
      "y": 8,
      "z": 5,
      "name": "Rock_Slate"
    },
    {
      "x": -8,
      "y": 9,
      "z": 5,
      "name": "Rock_Slate"
    },
    {
      "x": -8,
      "y": 10,
      "z": 5,
      "name": "Rock_Slate"
    },
    {
      "x": -8,
      "y": 11,
      "z": 5,
      "name": "Rock_Slate"
    },
    {
      "x": -8,
      "y": 12,
      "z": 5,
      "name": "Rock_Shale_Brick"
    },
    {
      "x": -8,
      "y": 13,
      "z": 5,
      "name": "Rock_Shale_Brick"
    },
    {
      "x": -8,
      "y": 14,
      "z": 5,
      "name": "Rock_Shale_Brick"
    },
    {
      "x": -8,
      "y": 15,
      "z": 5,
      "name": "Rock_Shale_Brick"
    },
    {
      "x": -8,
      "y": 10,
      "z": 6,
      "name": "Rock_Slate"
    },
    {
      "x": -8,
      "y": 11,
      "z": 6,
      "name": "Rock_Slate"
    },
    {
      "x": -8,
      "y": 12,
      "z": 6,
      "name": "Rock_Slate"
    },
    {
      "x": -8,
      "y": 13,
      "z": 6,
      "name": "Rock_Slate"
    },
    {
      "x": -8,
      "y": 14,
      "z": 6,
      "name": "Rock_Slate"
    },
    {
      "x": -8,
      "y": 10,
      "z": 7,
      "name": "Rock_Slate"
    },
    {
      "x": -8,
      "y": 11,
      "z": 7,
      "name": "Rock_Slate"
    },
    {
      "x": -8,
      "y": 12,
      "z": 7,
      "name": "Rock_Slate"
    },
    {
      "x": -8,
      "y": 13,
      "z": 7,
      "name": "Rock_Slate"
    },
    {
      "x": -8,
      "y": 10,
      "z": 8,
      "name": "Rock_Slate"
    },
    {
      "x": -8,
      "y": 11,
      "z": 8,
      "name": "Rock_Slate"
    },
    {
      "x": -8,
      "y": 12,
      "z": 8,
      "name": "Rock_Slate"
    },
    {
      "x": -8,
      "y": 13,
      "z": 8,
      "name": "Rock_Slate"
    },
    {
      "x": -8,
      "y": 11,
      "z": 11,
      "name": "Rock_Slate"
    },
    {
      "x": -8,
      "y": 12,
      "z": 11,
      "name": "Rock_Slate"
    },
    {
      "x": -8,
      "y": 11,
      "z": 12,
      "name": "Rock_Slate"
    },
    {
      "x": -8,
      "y": 12,
      "z": 12,
      "name": "Rock_Slate"
    },
    {
      "x": -8,
      "y": 11,
      "z": 13,
      "name": "Rock_Slate"
    },
    {
      "x": -8,
      "y": 12,
      "z": 13,
      "name": "Rock_Slate"
    },
    {
      "x": -8,
      "y": 12,
      "z": 14,
      "name": "Rock_Slate"
    },
    {
      "x": -7,
      "y": 12,
      "z": -10,
      "name": "Rock_Slate"
    },
    {
      "x": -7,
      "y": 12,
      "z": -9,
      "name": "Rock_Slate"
    },
    {
      "x": -7,
      "y": 13,
      "z": -9,
      "name": "Rock_Slate"
    },
    {
      "x": -7,
      "y": 11,
      "z": -8,
      "name": "Rock_Slate"
    },
    {
      "x": -7,
      "y": 12,
      "z": -8,
      "name": "Rock_Shale_Brick"
    },
    {
      "x": -7,
      "y": 13,
      "z": -8,
      "name": "Rock_Shale_Brick"
    },
    {
      "x": -7,
      "y": 14,
      "z": -8,
      "name": "Rock_Shale_Brick"
    },
    {
      "x": -7,
      "y": 15,
      "z": -8,
      "name": "Rock_Shale_Brick"
    },
    {
      "x": -7,
      "y": 16,
      "z": -8,
      "name": "Rock_Shale_Brick_Decorative"
    },
    {
      "x": -7,
      "y": 17,
      "z": -8,
      "name": "Rock_Shale_Brick_Beam",
      "rotation": 2
    },
    {
      "x": -7,
      "y": 18,
      "z": -8,
      "name": "Rock_Shale_Brick_Beam",
      "rotation": 2
    },
    {
      "x": -7,
      "y": 19,
      "z": -8,
      "name": "Rock_Shale_Brick_Beam",
      "rotation": 2
    },
    {
      "x": -7,
      "y": 20,
      "z": -8,
      "name": "Rock_Shale_Brick_Beam",
      "rotation": 2
    },
    {
      "x": -7,
      "y": 21,
      "z": -8,
      "name": "Rock_Shale_Brick_Half",
      "rotation": 2
    },
    {
      "x": -7,
      "y": 10,
      "z": -7,
      "name": "Rock_Slate"
    },
    {
      "x": -7,
      "y": 11,
      "z": -7,
      "name": "Rock_Slate"
    },
    {
      "x": -7,
      "y": 12,
      "z": -7,
      "name": "Rock_Shale_Brick"
    },
    {
      "x": -7,
      "y": 13,
      "z": -7,
      "name": "Rock_Shale_Brick"
    },
    {
      "x": -7,
      "y": 14,
      "z": -7,
      "name": "Rock_Shale_Brick"
    },
    {
      "x": -7,
      "y": 15,
      "z": -7,
      "name": "Rock_Shale_Brick"
    },
    {
      "x": -7,
      "y": 16,
      "z": -7,
      "name": "Rock_Shale_Brick_Ornate"
    },
    {
      "x": -7,
      "y": 17,
      "z": -7,
      "name": "Rock_Shale_Brick_Pillar_Base"
    },
    {
      "x": -7,
      "y": 18,
      "z": -7,
      "name": "Rock_Shale_Brick_Pillar_Middle"
    },
    {
      "x": -7,
      "y": 19,
      "z": -7,
      "name": "Rock_Shale_Brick_Pillar_Middle",
      "rotation": 2
    },
    {
      "x": -7,
      "y": 20,
      "z": -7,
      "name": "Rock_Shale_Brick_Pillar_Base",
      "rotation": 10
    },
    {
      "x": -7,
      "y": 21,
      "z": -7,
      "name": "Rock_Shale_Brick_Roof_Steep",
      "rotation": 3
    },
    {
      "x": -7,
      "y": 22,
      "z": -7,
      "name": "Rock_Shale_Brick_Roof_Steep",
      "filler": 1024,
      "rotation": 3
    },
    {
      "x": -7,
      "y": 11,
      "z": -6,
      "name": "Rock_Slate"
    },
    {
      "x": -7,
      "y": 12,
      "z": -6,
      "name": "Rock_Slate"
    },
    {
      "x": -7,
      "y": 13,
      "z": -6,
      "name": "Rock_Slate"
    },
    {
      "x": -7,
      "y": 10,
      "z": -5,
      "name": "Rock_Slate"
    },
    {
      "x": -7,
      "y": 12,
      "z": -5,
      "name": "Rock_Slate"
    },
    {
      "x": -7,
      "y": 13,
      "z": -5,
      "name": "Rock_Slate_Cobble"
    },
    {
      "x": -7,
      "y": 14,
      "z": -5,
      "name": "Rock_Slate_Cobble"
    },
    {
      "x": -7,
      "y": 9,
      "z": -4,
      "name": "Rock_Slate"
    },
    {
      "x": -7,
      "y": 10,
      "z": -4,
      "name": "Rock_Slate"
    },
    {
      "x": -7,
      "y": 11,
      "z": -4,
      "name": "Rock_Slate_Cobble"
    },
    {
      "x": -7,
      "y": 12,
      "z": -4,
      "name": "Rock_Slate"
    },
    {
      "x": -7,
      "y": 13,
      "z": -4,
      "name": "Rock_Slate"
    },
    {
      "x": -7,
      "y": 14,
      "z": -4,
      "name": "Rock_Slate"
    },
    {
      "x": -7,
      "y": 10,
      "z": -3,
      "name": "Rock_Slate"
    },
    {
      "x": -7,
      "y": 11,
      "z": -3,
      "name": "Rock_Slate"
    },
    {
      "x": -7,
      "y": 12,
      "z": -3,
      "name": "Rock_Slate"
    },
    {
      "x": -7,
      "y": 13,
      "z": -3,
      "name": "Rock_Slate"
    },
    {
      "x": -7,
      "y": 14,
      "z": -3,
      "name": "Rock_Slate_Cobble"
    },
    {
      "x": -7,
      "y": 8,
      "z": -2,
      "name": "Rock_Slate"
    },
    {
      "x": -7,
      "y": 9,
      "z": -2,
      "name": "Rock_Slate"
    },
    {
      "x": -7,
      "y": 10,
      "z": -2,
      "name": "Rock_Slate"
    },
    {
      "x": -7,
      "y": 11,
      "z": -2,
      "name": "Rock_Slate_Cobble"
    },
    {
      "x": -7,
      "y": 12,
      "z": -2,
      "name": "Rock_Slate"
    },
    {
      "x": -7,
      "y": 13,
      "z": -2,
      "name": "Rock_Slate"
    },
    {
      "x": -7,
      "y": 8,
      "z": -1,
      "name": "Rock_Slate"
    },
    {
      "x": -7,
      "y": 9,
      "z": -1,
      "name": "Rock_Slate"
    },
    {
      "x": -7,
      "y": 10,
      "z": -1,
      "name": "Rock_Slate"
    },
    {
      "x": -7,
      "y": 11,
      "z": -1,
      "name": "Rock_Slate_Cobble"
    },
    {
      "x": -7,
      "y": 12,
      "z": -1,
      "name": "Rock_Slate"
    },
    {
      "x": -7,
      "y": 13,
      "z": -1,
      "name": "Rock_Slate"
    },
    {
      "x": -7,
      "y": 8,
      "z": 0,
      "name": "Rock_Slate"
    },
    {
      "x": -7,
      "y": 9,
      "z": 0,
      "name": "Rock_Slate"
    },
    {
      "x": -7,
      "y": 10,
      "z": 0,
      "name": "Rock_Slate"
    },
    {
      "x": -7,
      "y": 11,
      "z": 0,
      "name": "Rock_Slate_Cobble"
    },
    {
      "x": -7,
      "y": 12,
      "z": 0,
      "name": "Rock_Shale_Brick"
    },
    {
      "x": -7,
      "y": 13,
      "z": 0,
      "name": "Rock_Shale_Brick"
    },
    {
      "x": -7,
      "y": 14,
      "z": 0,
      "name": "Rock_Shale_Brick"
    },
    {
      "x": -7,
      "y": 15,
      "z": 0,
      "name": "Rock_Shale_Brick"
    },
    {
      "x": -7,
      "y": 16,
      "z": 0,
      "name": "Furniture_Human_Ruins_Brazier"
    },
    {
      "x": -7,
      "y": 7,
      "z": 1,
      "name": "Rock_Slate"
    },
    {
      "x": -7,
      "y": 8,
      "z": 1,
      "name": "Rock_Slate"
    },
    {
      "x": -7,
      "y": 9,
      "z": 1,
      "name": "Rock_Slate"
    },
    {
      "x": -7,
      "y": 10,
      "z": 1,
      "name": "Rock_Slate"
    },
    {
      "x": -7,
      "y": 11,
      "z": 1,
      "name": "Rock_Slate"
    },
    {
      "x": -7,
      "y": 12,
      "z": 1,
      "name": "Rock_Shale_Brick"
    },
    {
      "x": -7,
      "y": 13,
      "z": 1,
      "name": "Rock_Shale_Brick"
    },
    {
      "x": -7,
      "y": 14,
      "z": 1,
      "name": "Rock_Shale_Brick"
    },
    {
      "x": -7,
      "y": 7,
      "z": 2,
      "name": "Rock_Slate"
    },
    {
      "x": -7,
      "y": 8,
      "z": 2,
      "name": "Rock_Slate_Cobble"
    },
    {
      "x": -7,
      "y": 9,
      "z": 2,
      "name": "Rock_Slate_Cobble"
    },
    {
      "x": -7,
      "y": 10,
      "z": 2,
      "name": "Rock_Slate_Cobble"
    },
    {
      "x": -7,
      "y": 11,
      "z": 2,
      "name": "Rock_Slate"
    },
    {
      "x": -7,
      "y": 12,
      "z": 2,
      "name": "Rock_Shale_Brick"
    },
    {
      "x": -7,
      "y": 13,
      "z": 2,
      "name": "Rock_Shale_Brick"
    },
    {
      "x": -7,
      "y": 14,
      "z": 2,
      "name": "Rock_Shale_Brick"
    },
    {
      "x": -7,
      "y": 20,
      "z": 2,
      "name": "Rock_Shale_Cobble_Stairs",
      "rotation": 9
    },
    {
      "x": -7,
      "y": 21,
      "z": 2,
      "name": "Rock_Shale_Brick_Roof_Steep",
      "rotation": 3
    },
    {
      "x": -7,
      "y": 22,
      "z": 2,
      "name": "Rock_Shale_Brick_Roof_Steep",
      "filler": 1024,
      "rotation": 3
    },
    {
      "x": -7,
      "y": 6,
      "z": 3,
      "name": "Rock_Slate"
    },
    {
      "x": -7,
      "y": 7,
      "z": 3,
      "name": "Rock_Slate"
    },
    {
      "x": -7,
      "y": 8,
      "z": 3,
      "name": "Rock_Slate"
    },
    {
      "x": -7,
      "y": 9,
      "z": 3,
      "name": "Rock_Slate"
    },
    {
      "x": -7,
      "y": 10,
      "z": 3,
      "name": "Rock_Slate"
    },
    {
      "x": -7,
      "y": 11,
      "z": 3,
      "name": "Rock_Slate"
    },
    {
      "x": -7,
      "y": 12,
      "z": 3,
      "name": "Rock_Shale_Brick"
    },
    {
      "x": -7,
      "y": 13,
      "z": 3,
      "name": "Rock_Shale_Brick"
    },
    {
      "x": -7,
      "y": 14,
      "z": 3,
      "name": "Rock_Shale_Brick"
    },
    {
      "x": -7,
      "y": 20,
      "z": 3,
      "name": "Rock_Shale_Cobble_Stairs",
      "rotation": 9
    },
    {
      "x": -7,
      "y": 21,
      "z": 3,
      "name": "Rock_Shale_Brick_Roof_Steep",
      "rotation": 3
    },
    {
      "x": -7,
      "y": 22,
      "z": 3,
      "name": "Rock_Shale_Brick_Roof_Steep",
      "filler": 1024,
      "rotation": 3
    },
    {
      "x": -7,
      "y": 7,
      "z": 4,
      "name": "Rock_Slate"
    },
    {
      "x": -7,
      "y": 8,
      "z": 4,
      "name": "Rock_Slate"
    },
    {
      "x": -7,
      "y": 9,
      "z": 4,
      "name": "Rock_Slate"
    },
    {
      "x": -7,
      "y": 10,
      "z": 4,
      "name": "Rock_Slate"
    },
    {
      "x": -7,
      "y": 11,
      "z": 4,
      "name": "Rock_Slate"
    },
    {
      "x": -7,
      "y": 12,
      "z": 4,
      "name": "Rock_Shale_Brick"
    },
    {
      "x": -7,
      "y": 13,
      "z": 4,
      "name": "Rock_Shale_Brick"
    },
    {
      "x": -7,
      "y": 14,
      "z": 4,
      "name": "Rock_Shale_Brick"
    },
    {
      "x": -7,
      "y": 8,
      "z": 5,
      "name": "Rock_Slate"
    },
    {
      "x": -7,
      "y": 9,
      "z": 5,
      "name": "Rock_Slate_Cobble"
    },
    {
      "x": -7,
      "y": 10,
      "z": 5,
      "name": "Rock_Slate"
    },
    {
      "x": -7,
      "y": 11,
      "z": 5,
      "name": "Rock_Slate"
    },
    {
      "x": -7,
      "y": 12,
      "z": 5,
      "name": "Rock_Shale_Brick"
    },
    {
      "x": -7,
      "y": 13,
      "z": 5,
      "name": "Rock_Shale_Brick"
    },
    {
      "x": -7,
      "y": 14,
      "z": 5,
      "name": "Rock_Shale_Brick"
    },
    {
      "x": -7,
      "y": 15,
      "z": 5,
      "name": "Rock_Shale_Brick"
    },
    {
      "x": -7,
      "y": 16,
      "z": 5,
      "name": "Furniture_Human_Ruins_Brazier"
    },
    {
      "x": -7,
      "y": 9,
      "z": 6,
      "name": "Rock_Slate"
    },
    {
      "x": -7,
      "y": 10,
      "z": 6,
      "name": "Rock_Slate"
    },
    {
      "x": -7,
      "y": 11,
      "z": 6,
      "name": "Rock_Slate_Cobble"
    },
    {
      "x": -7,
      "y": 12,
      "z": 6,
      "name": "Rock_Slate_Cobble"
    },
    {
      "x": -7,
      "y": 13,
      "z": 6,
      "name": "Rock_Slate"
    },
    {
      "x": -7,
      "y": 14,
      "z": 6,
      "name": "Rock_Slate"
    },
    {
      "x": -7,
      "y": 10,
      "z": 7,
      "name": "Rock_Slate"
    },
    {
      "x": -7,
      "y": 11,
      "z": 7,
      "name": "Rock_Slate"
    },
    {
      "x": -7,
      "y": 12,
      "z": 7,
      "name": "Rock_Slate"
    },
    {
      "x": -7,
      "y": 13,
      "z": 7,
      "name": "Rock_Slate"
    },
    {
      "x": -7,
      "y": 9,
      "z": 8,
      "name": "Rock_Slate"
    },
    {
      "x": -7,
      "y": 10,
      "z": 8,
      "name": "Rock_Slate"
    },
    {
      "x": -7,
      "y": 11,
      "z": 8,
      "name": "Rock_Slate"
    },
    {
      "x": -7,
      "y": 12,
      "z": 8,
      "name": "Rock_Slate"
    },
    {
      "x": -7,
      "y": 13,
      "z": 8,
      "name": "Rock_Slate"
    },
    {
      "x": -7,
      "y": 12,
      "z": 9,
      "name": "Rock_Slate"
    },
    {
      "x": -7,
      "y": 13,
      "z": 9,
      "name": "Rock_Slate"
    },
    {
      "x": -7,
      "y": 11,
      "z": 10,
      "name": "Rock_Slate"
    },
    {
      "x": -7,
      "y": 12,
      "z": 10,
      "name": "Rock_Slate_Cobble"
    },
    {
      "x": -7,
      "y": 13,
      "z": 10,
      "name": "Rock_Slate"
    },
    {
      "x": -7,
      "y": 10,
      "z": 11,
      "name": "Rock_Slate_Cobble"
    },
    {
      "x": -7,
      "y": 11,
      "z": 11,
      "name": "Rock_Slate_Cobble"
    },
    {
      "x": -7,
      "y": 12,
      "z": 11,
      "name": "Rock_Slate"
    },
    {
      "x": -7,
      "y": 13,
      "z": 11,
      "name": "Rock_Slate_Cobble"
    },
    {
      "x": -7,
      "y": 9,
      "z": 12,
      "name": "Rock_Slate"
    },
    {
      "x": -7,
      "y": 10,
      "z": 12,
      "name": "Rock_Slate_Cobble"
    },
    {
      "x": -7,
      "y": 11,
      "z": 12,
      "name": "Rock_Slate"
    },
    {
      "x": -7,
      "y": 12,
      "z": 12,
      "name": "Rock_Shale_Brick"
    },
    {
      "x": -7,
      "y": 13,
      "z": 12,
      "name": "Rock_Shale_Brick"
    },
    {
      "x": -7,
      "y": 14,
      "z": 12,
      "name": "Rock_Shale_Brick"
    },
    {
      "x": -7,
      "y": 15,
      "z": 12,
      "name": "Rock_Shale_Brick"
    },
    {
      "x": -7,
      "y": 16,
      "z": 12,
      "name": "Rock_Shale_Brick_Ornate"
    },
    {
      "x": -7,
      "y": 17,
      "z": 12,
      "name": "Rock_Shale_Brick_Pillar_Base"
    },
    {
      "x": -7,
      "y": 18,
      "z": 12,
      "name": "Rock_Shale_Brick_Pillar_Middle"
    },
    {
      "x": -7,
      "y": 19,
      "z": 12,
      "name": "Rock_Shale_Brick_Pillar_Middle",
      "rotation": 3
    },
    {
      "x": -7,
      "y": 20,
      "z": 12,
      "name": "Rock_Shale_Brick_Pillar_Base",
      "rotation": 11
    },
    {
      "x": -7,
      "y": 21,
      "z": 12,
      "name": "Rock_Shale_Brick_Roof_Steep",
      "rotation": 3
    },
    {
      "x": -7,
      "y": 22,
      "z": 12,
      "name": "Rock_Shale_Brick_Roof_Steep",
      "filler": 1024,
      "rotation": 3
    },
    {
      "x": -7,
      "y": 10,
      "z": 13,
      "name": "Rock_Slate_Cobble"
    },
    {
      "x": -7,
      "y": 11,
      "z": 13,
      "name": "Rock_Slate_Cobble"
    },
    {
      "x": -7,
      "y": 12,
      "z": 13,
      "name": "Rock_Shale_Brick"
    },
    {
      "x": -7,
      "y": 13,
      "z": 13,
      "name": "Rock_Shale_Brick"
    },
    {
      "x": -7,
      "y": 14,
      "z": 13,
      "name": "Rock_Shale_Brick"
    },
    {
      "x": -7,
      "y": 15,
      "z": 13,
      "name": "Rock_Shale_Brick"
    },
    {
      "x": -7,
      "y": 16,
      "z": 13,
      "name": "Rock_Shale_Brick_Decorative"
    },
    {
      "x": -7,
      "y": 17,
      "z": 13,
      "name": "Rock_Shale_Brick_Beam",
      "rotation": 3
    },
    {
      "x": -7,
      "y": 18,
      "z": 13,
      "name": "Rock_Shale_Brick_Beam",
      "rotation": 3
    },
    {
      "x": -7,
      "y": 19,
      "z": 13,
      "name": "Rock_Shale_Brick_Beam",
      "rotation": 3
    },
    {
      "x": -7,
      "y": 20,
      "z": 13,
      "name": "Rock_Shale_Brick_Beam",
      "rotation": 3
    },
    {
      "x": -7,
      "y": 21,
      "z": 13,
      "name": "Rock_Shale_Brick_Half",
      "rotation": 3
    },
    {
      "x": -7,
      "y": 11,
      "z": 14,
      "name": "Rock_Slate_Cobble"
    },
    {
      "x": -7,
      "y": 12,
      "z": 14,
      "name": "Rock_Slate"
    },
    {
      "x": -7,
      "y": 12,
      "z": 15,
      "name": "Rock_Slate"
    },
    {
      "x": -6,
      "y": 12,
      "z": -10,
      "name": "Rock_Slate"
    },
    {
      "x": -6,
      "y": 11,
      "z": -9,
      "name": "Rock_Slate"
    },
    {
      "x": -6,
      "y": 12,
      "z": -9,
      "name": "Rock_Slate_Cobble"
    },
    {
      "x": -6,
      "y": 13,
      "z": -9,
      "name": "Rock_Slate"
    },
    {
      "x": -6,
      "y": 10,
      "z": -8,
      "name": "Rock_Slate"
    },
    {
      "x": -6,
      "y": 11,
      "z": -8,
      "name": "Rock_Slate"
    },
    {
      "x": -6,
      "y": 12,
      "z": -8,
      "name": "Rock_Shale_Brick"
    },
    {
      "x": -6,
      "y": 13,
      "z": -8,
      "name": "Rock_Shale_Brick"
    },
    {
      "x": -6,
      "y": 14,
      "z": -8,
      "name": "Rock_Shale_Brick"
    },
    {
      "x": -6,
      "y": 15,
      "z": -8,
      "name": "Rock_Shale_Brick"
    },
    {
      "x": -6,
      "y": 16,
      "z": -8,
      "name": "Rock_Shale_Brick_Ornate"
    },
    {
      "x": -6,
      "y": 17,
      "z": -8,
      "name": "Rock_Shale_Brick_Pillar_Base"
    },
    {
      "x": -6,
      "y": 18,
      "z": -8,
      "name": "Rock_Shale_Brick_Pillar_Middle"
    },
    {
      "x": -6,
      "y": 19,
      "z": -8,
      "name": "Rock_Shale_Brick_Pillar_Middle",
      "rotation": 2
    },
    {
      "x": -6,
      "y": 20,
      "z": -8,
      "name": "Rock_Shale_Brick_Pillar_Base",
      "rotation": 10
    },
    {
      "x": -6,
      "y": 21,
      "z": -8,
      "name": "Rock_Shale_Brick_Roof_Steep",
      "rotation": 2
    },
    {
      "x": -6,
      "y": 22,
      "z": -8,
      "name": "Rock_Shale_Brick_Roof_Steep",
      "filler": 1024,
      "rotation": 2
    },
    {
      "x": -6,
      "y": 10,
      "z": -7,
      "name": "Rock_Slate"
    },
    {
      "x": -6,
      "y": 11,
      "z": -7,
      "name": "Rock_Slate"
    },
    {
      "x": -6,
      "y": 12,
      "z": -7,
      "name": "Rock_Shale_Brick"
    },
    {
      "x": -6,
      "y": 13,
      "z": -7,
      "name": "Rock_Shale_Brick"
    },
    {
      "x": -6,
      "y": 14,
      "z": -7,
      "name": "Rock_Shale_Brick"
    },
    {
      "x": -6,
      "y": 15,
      "z": -7,
      "name": "Rock_Shale_Brick"
    },
    {
      "x": -6,
      "y": 16,
      "z": -7,
      "name": "Rock_Shale_Brick"
    },
    {
      "x": -6,
      "y": 17,
      "z": -7,
      "name": "Rock_Shale_Brick",
      "rotation": 2
    },
    {
      "x": -6,
      "y": 18,
      "z": -7,
      "name": "Rock_Shale_Brick",
      "rotation": 2
    },
    {
      "x": -6,
      "y": 19,
      "z": -7,
      "name": "Rock_Shale_Brick",
      "rotation": 2
    },
    {
      "x": -6,
      "y": 20,
      "z": -7,
      "name": "Rock_Shale_Brick",
      "rotation": 2
    },
    {
      "x": -6,
      "y": 21,
      "z": -7,
      "name": "Rock_Shale_Brick"
    },
    {
      "x": -6,
      "y": 22,
      "z": -7,
      "name": "Rock_Shale_Brick"
    },
    {
      "x": -6,
      "y": 23,
      "z": -7,
      "name": "Rock_Shale_Brick"
    },
    {
      "x": -6,
      "y": 24,
      "z": -7,
      "name": "Furniture_Human_Ruins_Brazier"
    },
    {
      "x": -6,
      "y": 10,
      "z": -6,
      "name": "Rock_Slate"
    },
    {
      "x": -6,
      "y": 11,
      "z": -6,
      "name": "Rock_Slate"
    },
    {
      "x": -6,
      "y": 12,
      "z": -6,
      "name": "Rock_Shale_Brick"
    },
    {
      "x": -6,
      "y": 13,
      "z": -6,
      "name": "Rock_Shale_Brick"
    },
    {
      "x": -6,
      "y": 14,
      "z": -6,
      "name": "Rock_Shale_Brick"
    },
    {
      "x": -6,
      "y": 15,
      "z": -6,
      "name": "Rock_Shale_Brick"
    },
    {
      "x": -6,
      "y": 16,
      "z": -6,
      "name": "Rock_Shale_Brick"
    },
    {
      "x": -6,
      "y": 17,
      "z": -6,
      "name": "Rock_Shale_Brick_Roof",
      "rotation": 3
    },
    {
      "x": -6,
      "y": 18,
      "z": -6,
      "name": "Empty"
    },
    {
      "x": -6,
      "y": 19,
      "z": -6,
      "name": "Rock_Shale_Cobble_Stairs",
      "rotation": 10
    },
    {
      "x": -6,
      "y": 20,
      "z": -6,
      "name": "Rock_Shale_Brick"
    },
    {
      "x": -6,
      "y": 21,
      "z": -6,
      "name": "Rock_Shale_Brick_Roof_Flat",
      "rotation": 3
    },
    {
      "x": -6,
      "y": 9,
      "z": -5,
      "name": "Rock_Slate"
    },
    {
      "x": -6,
      "y": 10,
      "z": -5,
      "name": "Rock_Slate"
    },
    {
      "x": -6,
      "y": 11,
      "z": -5,
      "name": "Rock_Slate"
    },
    {
      "x": -6,
      "y": 12,
      "z": -5,
      "name": "Rock_Shale_Brick"
    },
    {
      "x": -6,
      "y": 13,
      "z": -5,
      "name": "Rock_Shale_Brick"
    },
    {
      "x": -6,
      "y": 14,
      "z": -5,
      "name": "Rock_Shale_Brick"
    },
    {
      "x": -6,
      "y": 15,
      "z": -5,
      "name": "Rock_Shale_Brick"
    },
    {
      "x": -6,
      "y": 16,
      "z": -5,
      "name": "Rock_Shale_Brick_Wall",
      "rotation": 1
    },
    {
      "x": -6,
      "y": 17,
      "z": -5,
      "name": "Empty"
    },
    {
      "x": -6,
      "y": 18,
      "z": -5,
      "name": "Empty"
    },
    {
      "x": -6,
      "y": 19,
      "z": -5,
      "name": "Empty"
    },
    {
      "x": -6,
      "y": 20,
      "z": -5,
      "name": "Rock_Shale_Brick"
    },
    {
      "x": -6,
      "y": 21,
      "z": -5,
      "name": "Rock_Shale_Brick_Roof_Flat",
      "rotation": 3
    },
    {
      "x": -6,
      "y": 8,
      "z": -4,
      "name": "Rock_Slate"
    },
    {
      "x": -6,
      "y": 9,
      "z": -4,
      "name": "Rock_Slate"
    },
    {
      "x": -6,
      "y": 10,
      "z": -4,
      "name": "Rock_Slate"
    },
    {
      "x": -6,
      "y": 11,
      "z": -4,
      "name": "Rock_Slate"
    },
    {
      "x": -6,
      "y": 12,
      "z": -4,
      "name": "Rock_Shale_Brick"
    },
    {
      "x": -6,
      "y": 13,
      "z": -4,
      "name": "Rock_Shale_Brick"
    },
    {
      "x": -6,
      "y": 14,
      "z": -4,
      "name": "Rock_Shale_Brick"
    },
    {
      "x": -6,
      "y": 15,
      "z": -4,
      "name": "Rock_Shale_Brick"
    },
    {
      "x": -6,
      "y": 16,
      "z": -4,
      "name": "Rock_Shale_Brick_Decorative"
    },
    {
      "x": -6,
      "y": 17,
      "z": -4,
      "name": "Rock_Shale_Brick_Beam"
    },
    {
      "x": -6,
      "y": 18,
      "z": -4,
      "name": "Rock_Shale_Brick_Beam"
    },
    {
      "x": -6,
      "y": 19,
      "z": -4,
      "name": "Rock_Shale_Brick_Decorative"
    },
    {
      "x": -6,
      "y": 20,
      "z": -4,
      "name": "Rock_Shale_Brick"
    },
    {
      "x": -6,
      "y": 21,
      "z": -4,
      "name": "Rock_Shale_Brick_Roof_Flat",
      "rotation": 3
    },
    {
      "x": -6,
      "y": 9,
      "z": -3,
      "name": "Rock_Slate"
    },
    {
      "x": -6,
      "y": 10,
      "z": -3,
      "name": "Rock_Slate"
    },
    {
      "x": -6,
      "y": 11,
      "z": -3,
      "name": "Rock_Slate"
    },
    {
      "x": -6,
      "y": 12,
      "z": -3,
      "name": "Rock_Shale_Brick"
    },
    {
      "x": -6,
      "y": 13,
      "z": -3,
      "name": "Rock_Shale_Brick"
    },
    {
      "x": -6,
      "y": 14,
      "z": -3,
      "name": "Rock_Shale_Brick"
    },
    {
      "x": -6,
      "y": 15,
      "z": -3,
      "name": "Rock_Shale_Brick"
    },
    {
      "x": -6,
      "y": 16,
      "z": -3,
      "name": "Empty"
    },
    {
      "x": -6,
      "y": 17,
      "z": -3,
      "name": "Empty"
    },
    {
      "x": -6,
      "y": 18,
      "z": -3,
      "name": "Empty"
    },
    {
      "x": -6,
      "y": 19,
      "z": -3,
      "name": "Empty"
    },
    {
      "x": -6,
      "y": 20,
      "z": -3,
      "name": "Rock_Shale_Brick_Stairs",
      "rotation": 9
    },
    {
      "x": -6,
      "y": 21,
      "z": -3,
      "name": "Rock_Shale_Brick_Roof_Flat",
      "rotation": 3
    },
    {
      "x": -6,
      "y": 9,
      "z": -2,
      "name": "Rock_Slate"
    },
    {
      "x": -6,
      "y": 10,
      "z": -2,
      "name": "Rock_Slate"
    },
    {
      "x": -6,
      "y": 11,
      "z": -2,
      "name": "Rock_Slate"
    },
    {
      "x": -6,
      "y": 12,
      "z": -2,
      "name": "Rock_Shale_Brick"
    },
    {
      "x": -6,
      "y": 13,
      "z": -2,
      "name": "Rock_Shale_Brick"
    },
    {
      "x": -6,
      "y": 14,
      "z": -2,
      "name": "Rock_Shale_Brick"
    },
    {
      "x": -6,
      "y": 15,
      "z": -2,
      "name": "Rock_Shale_Brick"
    },
    {
      "x": -6,
      "y": 16,
      "z": -2,
      "name": "Rock_Shale_Brick_Decorative"
    },
    {
      "x": -6,
      "y": 17,
      "z": -2,
      "name": "Rock_Shale_Brick_Beam"
    },
    {
      "x": -6,
      "y": 18,
      "z": -2,
      "name": "Rock_Shale_Brick_Beam"
    },
    {
      "x": -6,
      "y": 19,
      "z": -2,
      "name": "Rock_Shale_Brick_Decorative"
    },
    {
      "x": -6,
      "y": 20,
      "z": -2,
      "name": "Rock_Shale_Brick"
    },
    {
      "x": -6,
      "y": 21,
      "z": -2,
      "name": "Rock_Shale_Brick_Roof_Flat",
      "rotation": 3
    },
    {
      "x": -6,
      "y": 8,
      "z": -1,
      "name": "Rock_Slate"
    },
    {
      "x": -6,
      "y": 9,
      "z": -1,
      "name": "Rock_Slate_Cobble"
    },
    {
      "x": -6,
      "y": 10,
      "z": -1,
      "name": "Rock_Slate_Cobble"
    },
    {
      "x": -6,
      "y": 11,
      "z": -1,
      "name": "Rock_Slate_Cobble"
    },
    {
      "x": -6,
      "y": 12,
      "z": -1,
      "name": "Rock_Shale_Brick"
    },
    {
      "x": -6,
      "y": 13,
      "z": -1,
      "name": "Rock_Shale_Brick"
    },
    {
      "x": -6,
      "y": 14,
      "z": -1,
      "name": "Rock_Shale_Brick"
    },
    {
      "x": -6,
      "y": 15,
      "z": -1,
      "name": "Rock_Shale_Brick"
    },
    {
      "x": -6,
      "y": 16,
      "z": -1,
      "name": "Rock_Shale_Brick_Wall",
      "rotation": 1
    },
    {
      "x": -6,
      "y": 17,
      "z": -1,
      "name": "Empty"
    },
    {
      "x": -6,
      "y": 18,
      "z": -1,
      "name": "Empty"
    },
    {
      "x": -6,
      "y": 19,
      "z": -1,
      "name": "Empty"
    },
    {
      "x": -6,
      "y": 20,
      "z": -1,
      "name": "Rock_Shale_Brick"
    },
    {
      "x": -6,
      "y": 21,
      "z": -1,
      "name": "Rock_Shale_Brick_Roof_Flat",
      "rotation": 3
    },
    {
      "x": -6,
      "y": 7,
      "z": 0,
      "name": "Rock_Slate"
    },
    {
      "x": -6,
      "y": 8,
      "z": 0,
      "name": "Rock_Slate"
    },
    {
      "x": -6,
      "y": 9,
      "z": 0,
      "name": "Rock_Slate"
    },
    {
      "x": -6,
      "y": 10,
      "z": 0,
      "name": "Rock_Slate"
    },
    {
      "x": -6,
      "y": 11,
      "z": 0,
      "name": "Rock_Slate"
    },
    {
      "x": -6,
      "y": 12,
      "z": 0,
      "name": "Rock_Shale_Brick"
    },
    {
      "x": -6,
      "y": 13,
      "z": 0,
      "name": "Rock_Shale_Brick"
    },
    {
      "x": -6,
      "y": 14,
      "z": 0,
      "name": "Rock_Shale_Brick"
    },
    {
      "x": -6,
      "y": 15,
      "z": 0,
      "name": "Rock_Shale_Brick"
    },
    {
      "x": -6,
      "y": 16,
      "z": 0,
      "name": "Rock_Shale_Brick"
    },
    {
      "x": -6,
      "y": 17,
      "z": 0,
      "name": "Rock_Shale_Brick_Roof",
      "rotation": 3
    },
    {
      "x": -6,
      "y": 18,
      "z": 0,
      "name": "Empty"
    },
    {
      "x": -6,
      "y": 19,
      "z": 0,
      "name": "Rock_Shale_Cobble_Stairs",
      "rotation": 8
    },
    {
      "x": -6,
      "y": 20,
      "z": 0,
      "name": "Rock_Shale_Brick"
    },
    {
      "x": -6,
      "y": 21,
      "z": 0,
      "name": "Rock_Shale_Brick_Roof_Flat",
      "rotation": 3
    },
    {
      "x": -6,
      "y": 8,
      "z": 1,
      "name": "Rock_Slate"
    },
    {
      "x": -6,
      "y": 9,
      "z": 1,
      "name": "Rock_Slate"
    },
    {
      "x": -6,
      "y": 10,
      "z": 1,
      "name": "Rock_Slate"
    },
    {
      "x": -6,
      "y": 11,
      "z": 1,
      "name": "Rock_Slate"
    },
    {
      "x": -6,
      "y": 12,
      "z": 1,
      "name": "Rock_Shale_Brick"
    },
    {
      "x": -6,
      "y": 13,
      "z": 1,
      "name": "Rock_Shale_Brick"
    },
    {
      "x": -6,
      "y": 14,
      "z": 1,
      "name": "Rock_Shale_Brick"
    },
    {
      "x": -6,
      "y": 15,
      "z": 1,
      "name": "Rock_Shale_Brick"
    },
    {
      "x": -6,
      "y": 16,
      "z": 1,
      "name": "Rock_Shale_Brick_Pillar_Base"
    },
    {
      "x": -6,
      "y": 17,
      "z": 1,
      "name": "Rock_Shale_Brick_Pillar_Middle"
    },
    {
      "x": -6,
      "y": 18,
      "z": 1,
      "name": "Rock_Shale_Brick_Pillar_Base",
      "rotation": 8
    },
    {
      "x": -6,
      "y": 19,
      "z": 1,
      "name": "Rock_Shale_Brick"
    },
    {
      "x": -6,
      "y": 20,
      "z": 1,
      "name": "Rock_Shale_Brick"
    },
    {
      "x": -6,
      "y": 21,
      "z": 1,
      "name": "Rock_Shale_Brick_Roof",
      "rotation": 2
    },
    {
      "x": -6,
      "y": 7,
      "z": 2,
      "name": "Rock_Slate_Cobble"
    },
    {
      "x": -6,
      "y": 8,
      "z": 2,
      "name": "Rock_Slate"
    },
    {
      "x": -6,
      "y": 9,
      "z": 2,
      "name": "Rock_Slate_Cobble"
    },
    {
      "x": -6,
      "y": 10,
      "z": 2,
      "name": "Rock_Slate_Cobble"
    },
    {
      "x": -6,
      "y": 11,
      "z": 2,
      "name": "Rock_Slate_Cobble"
    },
    {
      "x": -6,
      "y": 12,
      "z": 2,
      "name": "Rock_Shale_Brick"
    },
    {
      "x": -6,
      "y": 13,
      "z": 2,
      "name": "Rock_Shale_Brick"
    },
    {
      "x": -6,
      "y": 14,
      "z": 2,
      "name": "Rock_Shale_Brick_Stairs",
      "rotation": 1
    },
    {
      "x": -6,
      "y": 15,
      "z": 2,
      "name": "*Furniture_Temple_Dark_Door_State_Definitions_OpenDoorOut",
      "rotation": 3
    },
    {
      "x": -6,
      "y": 16,
      "z": 2,
      "name": "*Furniture_Temple_Dark_Door_State_Definitions_OpenDoorOut",
      "filler": 1024,
      "rotation": 3
    },
    {
      "x": -6,
      "y": 17,
      "z": 2,
      "name": "*Furniture_Temple_Dark_Trapdoor_State_Definitions_OpenDoorOut",
      "rotation": 1
    },
    {
      "x": -6,
      "y": 18,
      "z": 2,
      "name": "Rock_Shale_Brick"
    },
    {
      "x": -6,
      "y": 19,
      "z": 2,
      "name": "Rock_Shale_Brick_Beam",
      "rotation": 4
    },
    {
      "x": -6,
      "y": 20,
      "z": 2,
      "name": "Rock_Shale_Brick"
    },
    {
      "x": -6,
      "y": 21,
      "z": 2,
      "name": "Rock_Shale_Brick"
    },
    {
      "x": -6,
      "y": 22,
      "z": 2,
      "name": "Rock_Shale_Brick"
    },
    {
      "x": -6,
      "y": 7,
      "z": 3,
      "name": "Rock_Slate_Cobble"
    },
    {
      "x": -6,
      "y": 8,
      "z": 3,
      "name": "Rock_Slate"
    },
    {
      "x": -6,
      "y": 9,
      "z": 3,
      "name": "Rock_Slate"
    },
    {
      "x": -6,
      "y": 10,
      "z": 3,
      "name": "Rock_Slate"
    },
    {
      "x": -6,
      "y": 11,
      "z": 3,
      "name": "Rock_Slate_Cobble"
    },
    {
      "x": -6,
      "y": 12,
      "z": 3,
      "name": "Rock_Shale_Brick"
    },
    {
      "x": -6,
      "y": 13,
      "z": 3,
      "name": "Rock_Shale_Brick"
    },
    {
      "x": -6,
      "y": 14,
      "z": 3,
      "name": "Rock_Shale_Brick_Stairs",
      "rotation": 1
    },
    {
      "x": -6,
      "y": 15,
      "z": 3,
      "name": "*Furniture_Temple_Dark_Door_State_Definitions_OpenDoorIn",
      "rotation": 1
    },
    {
      "x": -6,
      "y": 16,
      "z": 3,
      "name": "*Furniture_Temple_Dark_Door_State_Definitions_OpenDoorIn",
      "filler": 1024,
      "rotation": 1
    },
    {
      "x": -6,
      "y": 17,
      "z": 3,
      "name": "*Furniture_Temple_Dark_Trapdoor_State_Definitions_OpenDoorOut",
      "rotation": 1
    },
    {
      "x": -6,
      "y": 18,
      "z": 3,
      "name": "Rock_Shale_Brick"
    },
    {
      "x": -6,
      "y": 19,
      "z": 3,
      "name": "Rock_Shale_Brick_Beam",
      "rotation": 4
    },
    {
      "x": -6,
      "y": 20,
      "z": 3,
      "name": "Rock_Shale_Brick"
    },
    {
      "x": -6,
      "y": 21,
      "z": 3,
      "name": "Rock_Shale_Brick"
    },
    {
      "x": -6,
      "y": 22,
      "z": 3,
      "name": "Rock_Shale_Brick"
    },
    {
      "x": -6,
      "y": 7,
      "z": 4,
      "name": "Rock_Slate"
    },
    {
      "x": -6,
      "y": 8,
      "z": 4,
      "name": "Rock_Slate"
    },
    {
      "x": -6,
      "y": 9,
      "z": 4,
      "name": "Rock_Slate"
    },
    {
      "x": -6,
      "y": 10,
      "z": 4,
      "name": "Rock_Slate"
    },
    {
      "x": -6,
      "y": 11,
      "z": 4,
      "name": "Rock_Slate"
    },
    {
      "x": -6,
      "y": 12,
      "z": 4,
      "name": "Rock_Shale_Brick"
    },
    {
      "x": -6,
      "y": 13,
      "z": 4,
      "name": "Rock_Shale_Brick"
    },
    {
      "x": -6,
      "y": 14,
      "z": 4,
      "name": "Rock_Shale_Brick"
    },
    {
      "x": -6,
      "y": 15,
      "z": 4,
      "name": "Rock_Shale_Brick"
    },
    {
      "x": -6,
      "y": 16,
      "z": 4,
      "name": "Rock_Shale_Brick_Pillar_Base"
    },
    {
      "x": -6,
      "y": 17,
      "z": 4,
      "name": "Rock_Shale_Brick_Pillar_Middle"
    },
    {
      "x": -6,
      "y": 18,
      "z": 4,
      "name": "Rock_Shale_Brick_Pillar_Base",
      "rotation": 8
    },
    {
      "x": -6,
      "y": 19,
      "z": 4,
      "name": "Rock_Shale_Brick"
    },
    {
      "x": -6,
      "y": 20,
      "z": 4,
      "name": "Rock_Shale_Brick"
    },
    {
      "x": -6,
      "y": 21,
      "z": 4,
      "name": "Rock_Shale_Brick_Roof"
    },
    {
      "x": -6,
      "y": 7,
      "z": 5,
      "name": "Rock_Slate"
    },
    {
      "x": -6,
      "y": 8,
      "z": 5,
      "name": "Rock_Slate_Cobble"
    },
    {
      "x": -6,
      "y": 9,
      "z": 5,
      "name": "Rock_Slate"
    },
    {
      "x": -6,
      "y": 10,
      "z": 5,
      "name": "Rock_Slate"
    },
    {
      "x": -6,
      "y": 11,
      "z": 5,
      "name": "Rock_Slate_Cobble"
    },
    {
      "x": -6,
      "y": 12,
      "z": 5,
      "name": "Rock_Shale_Brick"
    },
    {
      "x": -6,
      "y": 13,
      "z": 5,
      "name": "Rock_Shale_Brick"
    },
    {
      "x": -6,
      "y": 14,
      "z": 5,
      "name": "Rock_Shale_Brick"
    },
    {
      "x": -6,
      "y": 15,
      "z": 5,
      "name": "Rock_Shale_Brick"
    },
    {
      "x": -6,
      "y": 16,
      "z": 5,
      "name": "Rock_Shale_Brick"
    },
    {
      "x": -6,
      "y": 17,
      "z": 5,
      "name": "Rock_Shale_Brick_Roof",
      "rotation": 3
    },
    {
      "x": -6,
      "y": 18,
      "z": 5,
      "name": "Empty"
    },
    {
      "x": -6,
      "y": 19,
      "z": 5,
      "name": "Rock_Shale_Cobble_Stairs",
      "rotation": 10
    },
    {
      "x": -6,
      "y": 20,
      "z": 5,
      "name": "Rock_Shale_Brick"
    },
    {
      "x": -6,
      "y": 21,
      "z": 5,
      "name": "Rock_Shale_Brick_Roof_Flat",
      "rotation": 1
    },
    {
      "x": -6,
      "y": 8,
      "z": 6,
      "name": "Rock_Slate"
    },
    {
      "x": -6,
      "y": 9,
      "z": 6,
      "name": "Rock_Slate"
    },
    {
      "x": -6,
      "y": 10,
      "z": 6,
      "name": "Rock_Slate"
    },
    {
      "x": -6,
      "y": 11,
      "z": 6,
      "name": "Rock_Slate"
    },
    {
      "x": -6,
      "y": 12,
      "z": 6,
      "name": "Rock_Shale_Brick"
    },
    {
      "x": -6,
      "y": 13,
      "z": 6,
      "name": "Rock_Shale_Brick"
    },
    {
      "x": -6,
      "y": 14,
      "z": 6,
      "name": "Rock_Shale_Brick"
    },
    {
      "x": -6,
      "y": 15,
      "z": 6,
      "name": "Rock_Shale_Brick"
    },
    {
      "x": -6,
      "y": 16,
      "z": 6,
      "name": "Rock_Shale_Brick_Wall",
      "rotation": 1
    },
    {
      "x": -6,
      "y": 17,
      "z": 6,
      "name": "Empty"
    },
    {
      "x": -6,
      "y": 18,
      "z": 6,
      "name": "Empty"
    },
    {
      "x": -6,
      "y": 19,
      "z": 6,
      "name": "Empty"
    },
    {
      "x": -6,
      "y": 20,
      "z": 6,
      "name": "Rock_Shale_Brick"
    },
    {
      "x": -6,
      "y": 21,
      "z": 6,
      "name": "Rock_Shale_Brick_Roof_Flat",
      "rotation": 1
    },
    {
      "x": -6,
      "y": 9,
      "z": 7,
      "name": "Rock_Slate_Cobble"
    },
    {
      "x": -6,
      "y": 10,
      "z": 7,
      "name": "Rock_Slate"
    },
    {
      "x": -6,
      "y": 11,
      "z": 7,
      "name": "Rock_Slate"
    },
    {
      "x": -6,
      "y": 12,
      "z": 7,
      "name": "Rock_Shale_Brick"
    },
    {
      "x": -6,
      "y": 13,
      "z": 7,
      "name": "Rock_Shale_Brick"
    },
    {
      "x": -6,
      "y": 14,
      "z": 7,
      "name": "Rock_Shale_Brick"
    },
    {
      "x": -6,
      "y": 15,
      "z": 7,
      "name": "Rock_Shale_Brick"
    },
    {
      "x": -6,
      "y": 16,
      "z": 7,
      "name": "Rock_Shale_Brick_Decorative"
    },
    {
      "x": -6,
      "y": 17,
      "z": 7,
      "name": "Rock_Shale_Brick_Beam"
    },
    {
      "x": -6,
      "y": 18,
      "z": 7,
      "name": "Rock_Shale_Brick_Beam"
    },
    {
      "x": -6,
      "y": 19,
      "z": 7,
      "name": "Rock_Shale_Brick_Decorative"
    },
    {
      "x": -6,
      "y": 20,
      "z": 7,
      "name": "Rock_Shale_Brick"
    },
    {
      "x": -6,
      "y": 21,
      "z": 7,
      "name": "Rock_Shale_Brick_Roof_Flat",
      "rotation": 1
    },
    {
      "x": -6,
      "y": 9,
      "z": 8,
      "name": "Rock_Slate"
    },
    {
      "x": -6,
      "y": 10,
      "z": 8,
      "name": "Rock_Slate"
    },
    {
      "x": -6,
      "y": 11,
      "z": 8,
      "name": "Rock_Slate"
    },
    {
      "x": -6,
      "y": 12,
      "z": 8,
      "name": "Rock_Shale_Brick"
    },
    {
      "x": -6,
      "y": 13,
      "z": 8,
      "name": "Rock_Shale_Brick"
    },
    {
      "x": -6,
      "y": 14,
      "z": 8,
      "name": "Rock_Shale_Brick"
    },
    {
      "x": -6,
      "y": 15,
      "z": 8,
      "name": "Rock_Shale_Brick"
    },
    {
      "x": -6,
      "y": 16,
      "z": 8,
      "name": "Empty"
    },
    {
      "x": -6,
      "y": 17,
      "z": 8,
      "name": "Empty"
    },
    {
      "x": -6,
      "y": 18,
      "z": 8,
      "name": "Empty"
    },
    {
      "x": -6,
      "y": 19,
      "z": 8,
      "name": "Empty"
    },
    {
      "x": -6,
      "y": 20,
      "z": 8,
      "name": "Rock_Shale_Brick_Stairs",
      "rotation": 9
    },
    {
      "x": -6,
      "y": 21,
      "z": 8,
      "name": "Rock_Shale_Brick_Roof_Flat",
      "rotation": 1
    },
    {
      "x": -6,
      "y": 9,
      "z": 9,
      "name": "Rock_Slate_Cobble"
    },
    {
      "x": -6,
      "y": 10,
      "z": 9,
      "name": "Rock_Slate"
    },
    {
      "x": -6,
      "y": 11,
      "z": 9,
      "name": "Rock_Slate"
    },
    {
      "x": -6,
      "y": 12,
      "z": 9,
      "name": "Rock_Shale_Brick"
    },
    {
      "x": -6,
      "y": 13,
      "z": 9,
      "name": "Rock_Shale_Brick"
    },
    {
      "x": -6,
      "y": 14,
      "z": 9,
      "name": "Rock_Shale_Brick"
    },
    {
      "x": -6,
      "y": 15,
      "z": 9,
      "name": "Rock_Shale_Brick"
    },
    {
      "x": -6,
      "y": 16,
      "z": 9,
      "name": "Rock_Shale_Brick_Decorative"
    },
    {
      "x": -6,
      "y": 17,
      "z": 9,
      "name": "Rock_Shale_Brick_Beam"
    },
    {
      "x": -6,
      "y": 18,
      "z": 9,
      "name": "Rock_Shale_Brick_Beam"
    },
    {
      "x": -6,
      "y": 19,
      "z": 9,
      "name": "Rock_Shale_Brick_Decorative"
    },
    {
      "x": -6,
      "y": 20,
      "z": 9,
      "name": "Rock_Shale_Brick"
    },
    {
      "x": -6,
      "y": 21,
      "z": 9,
      "name": "Rock_Shale_Brick_Roof_Flat",
      "rotation": 1
    },
    {
      "x": -6,
      "y": 10,
      "z": 10,
      "name": "Rock_Slate"
    },
    {
      "x": -6,
      "y": 11,
      "z": 10,
      "name": "Rock_Slate"
    },
    {
      "x": -6,
      "y": 12,
      "z": 10,
      "name": "Rock_Shale_Brick"
    },
    {
      "x": -6,
      "y": 13,
      "z": 10,
      "name": "Rock_Shale_Brick"
    },
    {
      "x": -6,
      "y": 14,
      "z": 10,
      "name": "Rock_Shale_Brick"
    },
    {
      "x": -6,
      "y": 15,
      "z": 10,
      "name": "Rock_Shale_Brick"
    },
    {
      "x": -6,
      "y": 16,
      "z": 10,
      "name": "Rock_Shale_Brick_Wall",
      "rotation": 1
    },
    {
      "x": -6,
      "y": 17,
      "z": 10,
      "name": "Empty"
    },
    {
      "x": -6,
      "y": 18,
      "z": 10,
      "name": "Empty"
    },
    {
      "x": -6,
      "y": 19,
      "z": 10,
      "name": "Empty"
    },
    {
      "x": -6,
      "y": 20,
      "z": 10,
      "name": "Rock_Shale_Brick"
    },
    {
      "x": -6,
      "y": 21,
      "z": 10,
      "name": "Rock_Shale_Brick_Roof_Flat",
      "rotation": 1
    },
    {
      "x": -6,
      "y": 9,
      "z": 11,
      "name": "Rock_Slate"
    },
    {
      "x": -6,
      "y": 10,
      "z": 11,
      "name": "Rock_Slate"
    },
    {
      "x": -6,
      "y": 11,
      "z": 11,
      "name": "Rock_Slate"
    },
    {
      "x": -6,
      "y": 12,
      "z": 11,
      "name": "Rock_Shale_Brick"
    },
    {
      "x": -6,
      "y": 13,
      "z": 11,
      "name": "Rock_Shale_Brick"
    },
    {
      "x": -6,
      "y": 14,
      "z": 11,
      "name": "Rock_Shale_Brick"
    },
    {
      "x": -6,
      "y": 15,
      "z": 11,
      "name": "Rock_Shale_Brick"
    },
    {
      "x": -6,
      "y": 16,
      "z": 11,
      "name": "Rock_Shale_Brick"
    },
    {
      "x": -6,
      "y": 17,
      "z": 11,
      "name": "Rock_Shale_Brick_Roof",
      "rotation": 3
    },
    {
      "x": -6,
      "y": 18,
      "z": 11,
      "name": "Empty"
    },
    {
      "x": -6,
      "y": 19,
      "z": 11,
      "name": "Rock_Shale_Cobble_Stairs",
      "rotation": 8
    },
    {
      "x": -6,
      "y": 20,
      "z": 11,
      "name": "Rock_Shale_Brick"
    },
    {
      "x": -6,
      "y": 21,
      "z": 11,
      "name": "Rock_Shale_Brick_Roof_Flat",
      "rotation": 1
    },
    {
      "x": -6,
      "y": 9,
      "z": 12,
      "name": "Rock_Slate"
    },
    {
      "x": -6,
      "y": 10,
      "z": 12,
      "name": "Rock_Slate_Cobble"
    },
    {
      "x": -6,
      "y": 11,
      "z": 12,
      "name": "Rock_Slate"
    },
    {
      "x": -6,
      "y": 12,
      "z": 12,
      "name": "Rock_Shale_Brick"
    },
    {
      "x": -6,
      "y": 13,
      "z": 12,
      "name": "Rock_Shale_Brick"
    },
    {
      "x": -6,
      "y": 14,
      "z": 12,
      "name": "Rock_Shale_Brick"
    },
    {
      "x": -6,
      "y": 15,
      "z": 12,
      "name": "Rock_Shale_Brick"
    },
    {
      "x": -6,
      "y": 16,
      "z": 12,
      "name": "Rock_Shale_Brick"
    },
    {
      "x": -6,
      "y": 17,
      "z": 12,
      "name": "Rock_Shale_Brick",
      "rotation": 3
    },
    {
      "x": -6,
      "y": 18,
      "z": 12,
      "name": "Rock_Shale_Brick",
      "rotation": 3
    },
    {
      "x": -6,
      "y": 19,
      "z": 12,
      "name": "Rock_Shale_Brick",
      "rotation": 3
    },
    {
      "x": -6,
      "y": 20,
      "z": 12,
      "name": "Rock_Shale_Brick_Ornate",
      "rotation": 3
    },
    {
      "x": -6,
      "y": 21,
      "z": 12,
      "name": "Rock_Shale_Brick"
    },
    {
      "x": -6,
      "y": 22,
      "z": 12,
      "name": "Rock_Shale_Brick"
    },
    {
      "x": -6,
      "y": 23,
      "z": 12,
      "name": "Rock_Shale_Brick"
    },
    {
      "x": -6,
      "y": 24,
      "z": 12,
      "name": "Furniture_Human_Ruins_Brazier"
    },
    {
      "x": -6,
      "y": 10,
      "z": 13,
      "name": "Rock_Slate"
    },
    {
      "x": -6,
      "y": 11,
      "z": 13,
      "name": "Rock_Slate"
    },
    {
      "x": -6,
      "y": 12,
      "z": 13,
      "name": "Rock_Shale_Brick"
    },
    {
      "x": -6,
      "y": 13,
      "z": 13,
      "name": "Rock_Shale_Brick"
    },
    {
      "x": -6,
      "y": 14,
      "z": 13,
      "name": "Rock_Shale_Brick"
    },
    {
      "x": -6,
      "y": 15,
      "z": 13,
      "name": "Rock_Shale_Brick"
    },
    {
      "x": -6,
      "y": 16,
      "z": 13,
      "name": "Rock_Shale_Brick"
    },
    {
      "x": -6,
      "y": 17,
      "z": 13,
      "name": "Rock_Shale_Brick_Ornate",
      "rotation": 3
    },
    {
      "x": -6,
      "y": 18,
      "z": 13,
      "name": "Rock_Shale_Brick_Pillar_Base",
      "rotation": 3
    },
    {
      "x": -6,
      "y": 19,
      "z": 13,
      "name": "Rock_Shale_Brick_Pillar_Middle",
      "rotation": 3
    },
    {
      "x": -6,
      "y": 20,
      "z": 13,
      "name": "Rock_Shale_Brick_Pillar_Base",
      "rotation": 11
    },
    {
      "x": -6,
      "y": 21,
      "z": 13,
      "name": "Rock_Shale_Brick_Roof_Steep"
    },
    {
      "x": -6,
      "y": 22,
      "z": 13,
      "name": "Rock_Shale_Brick_Roof_Steep",
      "filler": 1024
    },
    {
      "x": -6,
      "y": 10,
      "z": 14,
      "name": "Rock_Slate"
    },
    {
      "x": -6,
      "y": 11,
      "z": 14,
      "name": "Rock_Slate_Cobble"
    },
    {
      "x": -6,
      "y": 12,
      "z": 14,
      "name": "Rock_Slate"
    },
    {
      "x": -5,
      "y": 12,
      "z": -9,
      "name": "Rock_Slate_Cobble"
    },
    {
      "x": -5,
      "y": 11,
      "z": -8,
      "name": "Rock_Slate"
    },
    {
      "x": -5,
      "y": 12,
      "z": -8,
      "name": "Rock_Slate_Cobble"
    },
    {
      "x": -5,
      "y": 13,
      "z": -8,
      "name": "Rock_Slate_Cobble"
    },
    {
      "x": -5,
      "y": 10,
      "z": -7,
      "name": "Rock_Slate"
    },
    {
      "x": -5,
      "y": 11,
      "z": -7,
      "name": "Rock_Slate_Cobble"
    },
    {
      "x": -5,
      "y": 12,
      "z": -7,
      "name": "Rock_Shale_Brick"
    },
    {
      "x": -5,
      "y": 13,
      "z": -7,
      "name": "Rock_Shale_Brick"
    },
    {
      "x": -5,
      "y": 14,
      "z": -7,
      "name": "Rock_Shale_Brick"
    },
    {
      "x": -5,
      "y": 15,
      "z": -7,
      "name": "Rock_Shale_Brick"
    },
    {
      "x": -5,
      "y": 16,
      "z": -7,
      "name": "Rock_Shale_Brick",
      "rotation": 3
    },
    {
      "x": -5,
      "y": 17,
      "z": -7,
      "name": "Rock_Shale_Brick_Roof",
      "rotation": 2
    },
    {
      "x": -5,
      "y": 18,
      "z": -7,
      "name": "Empty"
    },
    {
      "x": -5,
      "y": 19,
      "z": -7,
      "name": "Rock_Shale_Cobble_Stairs",
      "rotation": 11
    },
    {
      "x": -5,
      "y": 20,
      "z": -7,
      "name": "Rock_Shale_Brick"
    },
    {
      "x": -5,
      "y": 21,
      "z": -7,
      "name": "Rock_Shale_Brick_Roof_Flat"
    },
    {
      "x": -5,
      "y": 9,
      "z": -6,
      "name": "Rock_Slate"
    },
    {
      "x": -5,
      "y": 10,
      "z": -6,
      "name": "Rock_Slate_Cobble"
    },
    {
      "x": -5,
      "y": 11,
      "z": -6,
      "name": "Rock_Slate"
    },
    {
      "x": -5,
      "y": 12,
      "z": -6,
      "name": "Rock_Slate_Cobble"
    },
    {
      "x": -5,
      "y": 13,
      "z": -6,
      "name": "Rock_Slate_Cobble"
    },
    {
      "x": -5,
      "y": 14,
      "z": -6,
      "name": "Rock_Slate_Cobble"
    },
    {
      "x": -5,
      "y": 15,
      "z": -6,
      "name": "Rock_Slate_Cobble"
    },
    {
      "x": -5,
      "y": 16,
      "z": -6,
      "name": "Rock_Slate_Cobble"
    },
    {
      "x": -5,
      "y": 17,
      "z": -6,
      "name": "Rock_Slate_Cobble"
    },
    {
      "x": -5,
      "y": 18,
      "z": -6,
      "name": "Rock_Slate_Cobble"
    },
    {
      "x": -5,
      "y": 19,
      "z": -6,
      "name": "Rock_Slate_Cobble"
    },
    {
      "x": -5,
      "y": 20,
      "z": -6,
      "name": "Rock_Shale_Brick"
    },
    {
      "x": -5,
      "y": 21,
      "z": -6,
      "name": "Empty"
    },
    {
      "x": -5,
      "y": 9,
      "z": -5,
      "name": "Rock_Slate_Cobble"
    },
    {
      "x": -5,
      "y": 10,
      "z": -5,
      "name": "Rock_Slate"
    },
    {
      "x": -5,
      "y": 11,
      "z": -5,
      "name": "Rock_Slate_Cobble"
    },
    {
      "x": -5,
      "y": 12,
      "z": -5,
      "name": "Rock_Slate_Cobble"
    },
    {
      "x": -5,
      "y": 13,
      "z": -5,
      "name": "Rock_Slate_Cobble"
    },
    {
      "x": -5,
      "y": 14,
      "z": -5,
      "name": "Rock_Slate_Cobble"
    },
    {
      "x": -5,
      "y": 15,
      "z": -5,
      "name": "Rock_Slate_Cobble"
    },
    {
      "x": -5,
      "y": 16,
      "z": -5,
      "name": "Rock_Slate_Cobble"
    },
    {
      "x": -5,
      "y": 17,
      "z": -5,
      "name": "Rock_Slate_Cobble"
    },
    {
      "x": -5,
      "y": 18,
      "z": -5,
      "name": "Rock_Slate_Cobble"
    },
    {
      "x": -5,
      "y": 19,
      "z": -5,
      "name": "Rock_Slate_Cobble"
    },
    {
      "x": -5,
      "y": 20,
      "z": -5,
      "name": "Rock_Shale_Brick"
    },
    {
      "x": -5,
      "y": 21,
      "z": -5,
      "name": "Empty"
    },
    {
      "x": -5,
      "y": 8,
      "z": -4,
      "name": "Rock_Slate_Cobble"
    },
    {
      "x": -5,
      "y": 9,
      "z": -4,
      "name": "Rock_Slate_Cobble"
    },
    {
      "x": -5,
      "y": 10,
      "z": -4,
      "name": "Rock_Slate_Cobble"
    },
    {
      "x": -5,
      "y": 11,
      "z": -4,
      "name": "Rock_Slate"
    },
    {
      "x": -5,
      "y": 12,
      "z": -4,
      "name": "Rock_Slate_Cobble"
    },
    {
      "x": -5,
      "y": 13,
      "z": -4,
      "name": "Rock_Slate_Cobble"
    },
    {
      "x": -5,
      "y": 14,
      "z": -4,
      "name": "Rock_Slate_Cobble"
    },
    {
      "x": -5,
      "y": 15,
      "z": -4,
      "name": "Rock_Slate_Cobble"
    },
    {
      "x": -5,
      "y": 16,
      "z": -4,
      "name": "Rock_Slate_Cobble"
    },
    {
      "x": -5,
      "y": 17,
      "z": -4,
      "name": "Rock_Slate_Cobble"
    },
    {
      "x": -5,
      "y": 18,
      "z": -4,
      "name": "Rock_Slate_Cobble"
    },
    {
      "x": -5,
      "y": 19,
      "z": -4,
      "name": "Rock_Slate_Cobble"
    },
    {
      "x": -5,
      "y": 20,
      "z": -4,
      "name": "Rock_Shale_Brick"
    },
    {
      "x": -5,
      "y": 21,
      "z": -4,
      "name": "Empty"
    },
    {
      "x": -5,
      "y": 8,
      "z": -3,
      "name": "Rock_Slate"
    },
    {
      "x": -5,
      "y": 9,
      "z": -3,
      "name": "Rock_Slate"
    },
    {
      "x": -5,
      "y": 10,
      "z": -3,
      "name": "Rock_Slate"
    },
    {
      "x": -5,
      "y": 11,
      "z": -3,
      "name": "Rock_Slate"
    },
    {
      "x": -5,
      "y": 12,
      "z": -3,
      "name": "Rock_Slate_Cobble"
    },
    {
      "x": -5,
      "y": 13,
      "z": -3,
      "name": "Rock_Slate_Cobble"
    },
    {
      "x": -5,
      "y": 14,
      "z": -3,
      "name": "Rock_Crystal_Yellow_Block",
      "rotation": 4
    },
    {
      "x": -5,
      "y": 15,
      "z": -3,
      "name": "Rock_Slate_Cobble"
    },
    {
      "x": -5,
      "y": 16,
      "z": -3,
      "name": "Rock_Slate_Cobble"
    },
    {
      "x": -5,
      "y": 17,
      "z": -3,
      "name": "Rock_Slate_Cobble"
    },
    {
      "x": -5,
      "y": 18,
      "z": -3,
      "name": "Rock_Slate_Cobble"
    },
    {
      "x": -5,
      "y": 19,
      "z": -3,
      "name": "Rock_Slate_Cobble"
    },
    {
      "x": -5,
      "y": 20,
      "z": -3,
      "name": "Rock_Shale_Brick"
    },
    {
      "x": -5,
      "y": 21,
      "z": -3,
      "name": "Empty"
    },
    {
      "x": -5,
      "y": 9,
      "z": -2,
      "name": "Rock_Slate"
    },
    {
      "x": -5,
      "y": 10,
      "z": -2,
      "name": "Rock_Slate"
    },
    {
      "x": -5,
      "y": 11,
      "z": -2,
      "name": "Rock_Slate_Cobble"
    },
    {
      "x": -5,
      "y": 12,
      "z": -2,
      "name": "Rock_Slate_Cobble"
    },
    {
      "x": -5,
      "y": 13,
      "z": -2,
      "name": "Rock_Slate_Cobble"
    },
    {
      "x": -5,
      "y": 14,
      "z": -2,
      "name": "Rock_Slate_Cobble"
    },
    {
      "x": -5,
      "y": 15,
      "z": -2,
      "name": "Rock_Crystal_Yellow_Block",
      "rotation": 5
    },
    {
      "x": -5,
      "y": 16,
      "z": -2,
      "name": "Rock_Slate_Cobble"
    },
    {
      "x": -5,
      "y": 17,
      "z": -2,
      "name": "Rock_Slate_Cobble"
    },
    {
      "x": -5,
      "y": 18,
      "z": -2,
      "name": "Rock_Slate_Cobble"
    },
    {
      "x": -5,
      "y": 19,
      "z": -2,
      "name": "Rock_Slate_Cobble"
    },
    {
      "x": -5,
      "y": 20,
      "z": -2,
      "name": "Rock_Shale_Brick"
    },
    {
      "x": -5,
      "y": 21,
      "z": -2,
      "name": "Empty"
    },
    {
      "x": -5,
      "y": 9,
      "z": -1,
      "name": "Rock_Slate_Cobble"
    },
    {
      "x": -5,
      "y": 10,
      "z": -1,
      "name": "Rock_Slate_Cobble"
    },
    {
      "x": -5,
      "y": 11,
      "z": -1,
      "name": "Rock_Slate"
    },
    {
      "x": -5,
      "y": 12,
      "z": -1,
      "name": "Rock_Slate_Cobble"
    },
    {
      "x": -5,
      "y": 13,
      "z": -1,
      "name": "Rock_Slate_Cobble"
    },
    {
      "x": -5,
      "y": 14,
      "z": -1,
      "name": "Rock_Slate_Cobble"
    },
    {
      "x": -5,
      "y": 15,
      "z": -1,
      "name": "Rock_Slate_Cobble"
    },
    {
      "x": -5,
      "y": 16,
      "z": -1,
      "name": "Rock_Slate_Cobble"
    },
    {
      "x": -5,
      "y": 17,
      "z": -1,
      "name": "Rock_Slate_Cobble"
    },
    {
      "x": -5,
      "y": 18,
      "z": -1,
      "name": "Rock_Slate_Cobble"
    },
    {
      "x": -5,
      "y": 19,
      "z": -1,
      "name": "Rock_Slate_Cobble"
    },
    {
      "x": -5,
      "y": 20,
      "z": -1,
      "name": "Rock_Shale_Brick"
    },
    {
      "x": -5,
      "y": 21,
      "z": -1,
      "name": "Empty"
    },
    {
      "x": -5,
      "y": 7,
      "z": 0,
      "name": "Rock_Slate_Cobble"
    },
    {
      "x": -5,
      "y": 8,
      "z": 0,
      "name": "Rock_Slate"
    },
    {
      "x": -5,
      "y": 9,
      "z": 0,
      "name": "Rock_Slate_Cobble"
    },
    {
      "x": -5,
      "y": 10,
      "z": 0,
      "name": "Rock_Slate"
    },
    {
      "x": -5,
      "y": 11,
      "z": 0,
      "name": "Rock_Slate_Cobble"
    },
    {
      "x": -5,
      "y": 12,
      "z": 0,
      "name": "Rock_Slate_Cobble"
    },
    {
      "x": -5,
      "y": 13,
      "z": 0,
      "name": "Rock_Slate_Cobble"
    },
    {
      "x": -5,
      "y": 14,
      "z": 0,
      "name": "Rock_Slate_Cobble"
    },
    {
      "x": -5,
      "y": 15,
      "z": 0,
      "name": "Rock_Slate_Cobble"
    },
    {
      "x": -5,
      "y": 16,
      "z": 0,
      "name": "Rock_Slate_Cobble"
    },
    {
      "x": -5,
      "y": 17,
      "z": 0,
      "name": "Rock_Slate_Cobble"
    },
    {
      "x": -5,
      "y": 18,
      "z": 0,
      "name": "Rock_Slate_Cobble"
    },
    {
      "x": -5,
      "y": 19,
      "z": 0,
      "name": "Rock_Slate_Cobble"
    },
    {
      "x": -5,
      "y": 20,
      "z": 0,
      "name": "Rock_Shale_Brick"
    },
    {
      "x": -5,
      "y": 21,
      "z": 0,
      "name": "Empty"
    },
    {
      "x": -5,
      "y": 7,
      "z": 1,
      "name": "Rock_Slate"
    },
    {
      "x": -5,
      "y": 8,
      "z": 1,
      "name": "Rock_Slate"
    },
    {
      "x": -5,
      "y": 9,
      "z": 1,
      "name": "Rock_Slate"
    },
    {
      "x": -5,
      "y": 10,
      "z": 1,
      "name": "Rock_Slate"
    },
    {
      "x": -5,
      "y": 11,
      "z": 1,
      "name": "Rock_Slate"
    },
    {
      "x": -5,
      "y": 12,
      "z": 1,
      "name": "Rock_Slate_Cobble"
    },
    {
      "x": -5,
      "y": 13,
      "z": 1,
      "name": "Rock_Slate_Cobble"
    },
    {
      "x": -5,
      "y": 14,
      "z": 1,
      "name": "Rock_Slate_Cobble"
    },
    {
      "x": -5,
      "y": 15,
      "z": 1,
      "name": "Rock_Slate_Cobble"
    },
    {
      "x": -5,
      "y": 16,
      "z": 1,
      "name": "Rock_Slate_Cobble"
    },
    {
      "x": -5,
      "y": 17,
      "z": 1,
      "name": "Rock_Slate_Cobble"
    },
    {
      "x": -5,
      "y": 18,
      "z": 1,
      "name": "Rock_Slate_Cobble"
    },
    {
      "x": -5,
      "y": 19,
      "z": 1,
      "name": "Rock_Slate_Cobble"
    },
    {
      "x": -5,
      "y": 20,
      "z": 1,
      "name": "Rock_Shale_Brick"
    },
    {
      "x": -5,
      "y": 21,
      "z": 1,
      "name": "Empty"
    },
    {
      "x": -5,
      "y": 6,
      "z": 2,
      "name": "Rock_Slate"
    },
    {
      "x": -5,
      "y": 7,
      "z": 2,
      "name": "Rock_Slate"
    },
    {
      "x": -5,
      "y": 8,
      "z": 2,
      "name": "Rock_Slate"
    },
    {
      "x": -5,
      "y": 9,
      "z": 2,
      "name": "Rock_Slate_Cobble"
    },
    {
      "x": -5,
      "y": 10,
      "z": 2,
      "name": "Rock_Slate_Cobble"
    },
    {
      "x": -5,
      "y": 11,
      "z": 2,
      "name": "Rock_Slate"
    },
    {
      "x": -5,
      "y": 12,
      "z": 2,
      "name": "Rock_Slate_Cobble"
    },
    {
      "x": -5,
      "y": 13,
      "z": 2,
      "name": "Rock_Shale_Brick_Stairs",
      "rotation": 1
    },
    {
      "x": -5,
      "y": 14,
      "z": 2,
      "name": "Empty"
    },
    {
      "x": -5,
      "y": 15,
      "z": 2,
      "name": "*Furniture_Temple_Dark_Door_State_Definitions_OpenDoorOut",
      "filler": 1,
      "rotation": 3
    },
    {
      "x": -5,
      "y": 16,
      "z": 2,
      "name": "*Furniture_Temple_Dark_Door_State_Definitions_OpenDoorOut",
      "filler": 1025,
      "rotation": 3
    },
    {
      "x": -5,
      "y": 17,
      "z": 2,
      "name": "Furniture_Temple_Dark_Sign",
      "rotation": 3
    },
    {
      "x": -5,
      "y": 18,
      "z": 2,
      "name": "Rock_Slate_Cobble"
    },
    {
      "x": -5,
      "y": 19,
      "z": 2,
      "name": "Rock_Slate_Cobble"
    },
    {
      "x": -5,
      "y": 20,
      "z": 2,
      "name": "Rock_Shale_Brick"
    },
    {
      "x": -5,
      "y": 21,
      "z": 2,
      "name": "Rock_Shale_Brick"
    },
    {
      "x": -5,
      "y": 22,
      "z": 2,
      "name": "Rock_Shale_Brick"
    },
    {
      "x": -5,
      "y": 7,
      "z": 3,
      "name": "Rock_Slate"
    },
    {
      "x": -5,
      "y": 8,
      "z": 3,
      "name": "Rock_Slate"
    },
    {
      "x": -5,
      "y": 9,
      "z": 3,
      "name": "Rock_Slate"
    },
    {
      "x": -5,
      "y": 10,
      "z": 3,
      "name": "Rock_Slate"
    },
    {
      "x": -5,
      "y": 11,
      "z": 3,
      "name": "Rock_Slate"
    },
    {
      "x": -5,
      "y": 12,
      "z": 3,
      "name": "Rock_Slate_Cobble"
    },
    {
      "x": -5,
      "y": 13,
      "z": 3,
      "name": "Rock_Shale_Brick_Stairs",
      "rotation": 1
    },
    {
      "x": -5,
      "y": 14,
      "z": 3,
      "name": "Empty"
    },
    {
      "x": -5,
      "y": 15,
      "z": 3,
      "name": "*Furniture_Temple_Dark_Door_State_Definitions_OpenDoorIn",
      "filler": 1,
      "rotation": 1
    },
    {
      "x": -5,
      "y": 16,
      "z": 3,
      "name": "*Furniture_Temple_Dark_Door_State_Definitions_OpenDoorIn",
      "filler": 1025,
      "rotation": 1
    },
    {
      "x": -5,
      "y": 17,
      "z": 3,
      "name": "Furniture_Temple_Dark_Sign",
      "rotation": 3
    },
    {
      "x": -5,
      "y": 18,
      "z": 3,
      "name": "Rock_Slate_Cobble"
    },
    {
      "x": -5,
      "y": 19,
      "z": 3,
      "name": "Rock_Slate_Cobble"
    },
    {
      "x": -5,
      "y": 20,
      "z": 3,
      "name": "Rock_Shale_Brick"
    },
    {
      "x": -5,
      "y": 21,
      "z": 3,
      "name": "Rock_Shale_Brick"
    },
    {
      "x": -5,
      "y": 22,
      "z": 3,
      "name": "Rock_Shale_Brick"
    },
    {
      "x": -5,
      "y": 7,
      "z": 4,
      "name": "Rock_Slate"
    },
    {
      "x": -5,
      "y": 8,
      "z": 4,
      "name": "Rock_Slate"
    },
    {
      "x": -5,
      "y": 9,
      "z": 4,
      "name": "Rock_Slate"
    },
    {
      "x": -5,
      "y": 10,
      "z": 4,
      "name": "Rock_Slate"
    },
    {
      "x": -5,
      "y": 11,
      "z": 4,
      "name": "Rock_Slate"
    },
    {
      "x": -5,
      "y": 12,
      "z": 4,
      "name": "Rock_Slate_Cobble"
    },
    {
      "x": -5,
      "y": 13,
      "z": 4,
      "name": "Rock_Slate_Cobble"
    },
    {
      "x": -5,
      "y": 14,
      "z": 4,
      "name": "Rock_Slate_Cobble"
    },
    {
      "x": -5,
      "y": 15,
      "z": 4,
      "name": "Rock_Slate_Cobble"
    },
    {
      "x": -5,
      "y": 16,
      "z": 4,
      "name": "Rock_Slate_Cobble"
    },
    {
      "x": -5,
      "y": 17,
      "z": 4,
      "name": "Rock_Slate_Cobble"
    },
    {
      "x": -5,
      "y": 18,
      "z": 4,
      "name": "Rock_Slate_Cobble"
    },
    {
      "x": -5,
      "y": 19,
      "z": 4,
      "name": "Rock_Slate_Cobble"
    },
    {
      "x": -5,
      "y": 20,
      "z": 4,
      "name": "Rock_Shale_Brick"
    },
    {
      "x": -5,
      "y": 21,
      "z": 4,
      "name": "Rock_Shale_Brick_Roof_Flat"
    },
    {
      "x": -5,
      "y": 7,
      "z": 5,
      "name": "Rock_Slate_Cobble"
    },
    {
      "x": -5,
      "y": 8,
      "z": 5,
      "name": "Rock_Slate"
    },
    {
      "x": -5,
      "y": 9,
      "z": 5,
      "name": "Rock_Slate_Cobble"
    },
    {
      "x": -5,
      "y": 10,
      "z": 5,
      "name": "Rock_Slate"
    },
    {
      "x": -5,
      "y": 11,
      "z": 5,
      "name": "Rock_Slate"
    },
    {
      "x": -5,
      "y": 12,
      "z": 5,
      "name": "Rock_Slate_Cobble"
    },
    {
      "x": -5,
      "y": 13,
      "z": 5,
      "name": "Rock_Slate_Cobble"
    },
    {
      "x": -5,
      "y": 14,
      "z": 5,
      "name": "Rock_Slate_Cobble"
    },
    {
      "x": -5,
      "y": 15,
      "z": 5,
      "name": "Rock_Slate_Cobble"
    },
    {
      "x": -5,
      "y": 16,
      "z": 5,
      "name": "Rock_Slate_Cobble"
    },
    {
      "x": -5,
      "y": 17,
      "z": 5,
      "name": "Rock_Slate_Cobble"
    },
    {
      "x": -5,
      "y": 18,
      "z": 5,
      "name": "Rock_Slate_Cobble"
    },
    {
      "x": -5,
      "y": 19,
      "z": 5,
      "name": "Rock_Slate_Cobble"
    },
    {
      "x": -5,
      "y": 20,
      "z": 5,
      "name": "Rock_Shale_Brick"
    },
    {
      "x": -5,
      "y": 21,
      "z": 5,
      "name": "Empty"
    },
    {
      "x": -5,
      "y": 8,
      "z": 6,
      "name": "Rock_Slate_Cobble"
    },
    {
      "x": -5,
      "y": 9,
      "z": 6,
      "name": "Rock_Slate"
    },
    {
      "x": -5,
      "y": 10,
      "z": 6,
      "name": "Rock_Slate_Cobble"
    },
    {
      "x": -5,
      "y": 11,
      "z": 6,
      "name": "Rock_Slate"
    },
    {
      "x": -5,
      "y": 12,
      "z": 6,
      "name": "Rock_Slate_Cobble"
    },
    {
      "x": -5,
      "y": 13,
      "z": 6,
      "name": "Rock_Slate_Cobble"
    },
    {
      "x": -5,
      "y": 14,
      "z": 6,
      "name": "Rock_Slate_Cobble"
    },
    {
      "x": -5,
      "y": 15,
      "z": 6,
      "name": "Rock_Slate_Cobble"
    },
    {
      "x": -5,
      "y": 16,
      "z": 6,
      "name": "Rock_Slate_Cobble"
    },
    {
      "x": -5,
      "y": 17,
      "z": 6,
      "name": "Rock_Slate_Cobble"
    },
    {
      "x": -5,
      "y": 18,
      "z": 6,
      "name": "Rock_Slate_Cobble"
    },
    {
      "x": -5,
      "y": 19,
      "z": 6,
      "name": "Rock_Slate_Cobble"
    },
    {
      "x": -5,
      "y": 20,
      "z": 6,
      "name": "Rock_Shale_Brick"
    },
    {
      "x": -5,
      "y": 21,
      "z": 6,
      "name": "Empty"
    },
    {
      "x": -5,
      "y": 9,
      "z": 7,
      "name": "Rock_Slate_Cobble"
    },
    {
      "x": -5,
      "y": 10,
      "z": 7,
      "name": "Rock_Slate"
    },
    {
      "x": -5,
      "y": 11,
      "z": 7,
      "name": "Rock_Slate"
    },
    {
      "x": -5,
      "y": 12,
      "z": 7,
      "name": "Rock_Slate_Cobble"
    },
    {
      "x": -5,
      "y": 13,
      "z": 7,
      "name": "Rock_Slate_Cobble"
    },
    {
      "x": -5,
      "y": 14,
      "z": 7,
      "name": "Rock_Slate_Cobble"
    },
    {
      "x": -5,
      "y": 15,
      "z": 7,
      "name": "Rock_Slate_Cobble"
    },
    {
      "x": -5,
      "y": 16,
      "z": 7,
      "name": "Rock_Slate_Cobble"
    },
    {
      "x": -5,
      "y": 17,
      "z": 7,
      "name": "Rock_Slate_Cobble"
    },
    {
      "x": -5,
      "y": 18,
      "z": 7,
      "name": "Rock_Slate_Cobble"
    },
    {
      "x": -5,
      "y": 19,
      "z": 7,
      "name": "Rock_Slate_Cobble"
    },
    {
      "x": -5,
      "y": 20,
      "z": 7,
      "name": "Rock_Shale_Brick"
    },
    {
      "x": -5,
      "y": 21,
      "z": 7,
      "name": "Empty"
    },
    {
      "x": -5,
      "y": 9,
      "z": 8,
      "name": "Rock_Slate"
    },
    {
      "x": -5,
      "y": 10,
      "z": 8,
      "name": "Rock_Slate"
    },
    {
      "x": -5,
      "y": 11,
      "z": 8,
      "name": "Rock_Slate"
    },
    {
      "x": -5,
      "y": 12,
      "z": 8,
      "name": "Rock_Slate_Cobble"
    },
    {
      "x": -5,
      "y": 13,
      "z": 8,
      "name": "Rock_Slate_Cobble"
    },
    {
      "x": -5,
      "y": 14,
      "z": 8,
      "name": "Rock_Slate_Cobble"
    },
    {
      "x": -5,
      "y": 15,
      "z": 8,
      "name": "Rock_Slate_Cobble"
    },
    {
      "x": -5,
      "y": 16,
      "z": 8,
      "name": "Rock_Slate_Cobble"
    },
    {
      "x": -5,
      "y": 17,
      "z": 8,
      "name": "Rock_Slate_Cobble"
    },
    {
      "x": -5,
      "y": 18,
      "z": 8,
      "name": "Rock_Slate_Cobble"
    },
    {
      "x": -5,
      "y": 19,
      "z": 8,
      "name": "Rock_Slate_Cobble"
    },
    {
      "x": -5,
      "y": 20,
      "z": 8,
      "name": "Rock_Shale_Brick"
    },
    {
      "x": -5,
      "y": 21,
      "z": 8,
      "name": "Empty"
    },
    {
      "x": -5,
      "y": 10,
      "z": 9,
      "name": "Rock_Slate"
    },
    {
      "x": -5,
      "y": 11,
      "z": 9,
      "name": "Rock_Slate"
    },
    {
      "x": -5,
      "y": 12,
      "z": 9,
      "name": "Rock_Slate_Cobble"
    },
    {
      "x": -5,
      "y": 13,
      "z": 9,
      "name": "Rock_Slate_Cobble"
    },
    {
      "x": -5,
      "y": 14,
      "z": 9,
      "name": "Rock_Slate_Cobble"
    },
    {
      "x": -5,
      "y": 15,
      "z": 9,
      "name": "Rock_Slate_Cobble"
    },
    {
      "x": -5,
      "y": 16,
      "z": 9,
      "name": "Rock_Slate_Cobble"
    },
    {
      "x": -5,
      "y": 17,
      "z": 9,
      "name": "Rock_Slate_Cobble"
    },
    {
      "x": -5,
      "y": 18,
      "z": 9,
      "name": "Rock_Slate_Cobble"
    },
    {
      "x": -5,
      "y": 19,
      "z": 9,
      "name": "Rock_Slate_Cobble"
    },
    {
      "x": -5,
      "y": 20,
      "z": 9,
      "name": "Rock_Shale_Brick"
    },
    {
      "x": -5,
      "y": 21,
      "z": 9,
      "name": "Empty"
    },
    {
      "x": -5,
      "y": 10,
      "z": 10,
      "name": "Rock_Slate"
    },
    {
      "x": -5,
      "y": 11,
      "z": 10,
      "name": "Rock_Slate"
    },
    {
      "x": -5,
      "y": 12,
      "z": 10,
      "name": "Rock_Slate_Cobble"
    },
    {
      "x": -5,
      "y": 13,
      "z": 10,
      "name": "Rock_Slate_Cobble"
    },
    {
      "x": -5,
      "y": 14,
      "z": 10,
      "name": "Rock_Slate_Cobble"
    },
    {
      "x": -5,
      "y": 15,
      "z": 10,
      "name": "Rock_Slate_Cobble"
    },
    {
      "x": -5,
      "y": 16,
      "z": 10,
      "name": "Rock_Slate_Cobble"
    },
    {
      "x": -5,
      "y": 17,
      "z": 10,
      "name": "Rock_Slate_Cobble"
    },
    {
      "x": -5,
      "y": 18,
      "z": 10,
      "name": "Rock_Slate_Cobble"
    },
    {
      "x": -5,
      "y": 19,
      "z": 10,
      "name": "Rock_Slate_Cobble"
    },
    {
      "x": -5,
      "y": 20,
      "z": 10,
      "name": "Rock_Shale_Brick"
    },
    {
      "x": -5,
      "y": 21,
      "z": 10,
      "name": "Empty"
    },
    {
      "x": -5,
      "y": 10,
      "z": 11,
      "name": "Rock_Slate"
    },
    {
      "x": -5,
      "y": 11,
      "z": 11,
      "name": "Rock_Slate_Cobble"
    },
    {
      "x": -5,
      "y": 12,
      "z": 11,
      "name": "Rock_Slate_Cobble"
    },
    {
      "x": -5,
      "y": 13,
      "z": 11,
      "name": "Rock_Slate_Cobble"
    },
    {
      "x": -5,
      "y": 14,
      "z": 11,
      "name": "Rock_Slate_Cobble"
    },
    {
      "x": -5,
      "y": 15,
      "z": 11,
      "name": "Rock_Slate_Cobble"
    },
    {
      "x": -5,
      "y": 16,
      "z": 11,
      "name": "Rock_Slate_Cobble",
      "rotation": 1
    },
    {
      "x": -5,
      "y": 17,
      "z": 11,
      "name": "Rock_Slate_Cobble",
      "rotation": 1
    },
    {
      "x": -5,
      "y": 18,
      "z": 11,
      "name": "Rock_Slate_Cobble",
      "rotation": 1
    },
    {
      "x": -5,
      "y": 19,
      "z": 11,
      "name": "Rock_Slate_Cobble",
      "rotation": 1
    },
    {
      "x": -5,
      "y": 20,
      "z": 11,
      "name": "Rock_Shale_Brick",
      "rotation": 2
    },
    {
      "x": -5,
      "y": 21,
      "z": 11,
      "name": "Empty"
    },
    {
      "x": -5,
      "y": 9,
      "z": 12,
      "name": "Rock_Slate_Cobble"
    },
    {
      "x": -5,
      "y": 10,
      "z": 12,
      "name": "Rock_Slate"
    },
    {
      "x": -5,
      "y": 11,
      "z": 12,
      "name": "Rock_Slate"
    },
    {
      "x": -5,
      "y": 12,
      "z": 12,
      "name": "Rock_Shale_Brick"
    },
    {
      "x": -5,
      "y": 13,
      "z": 12,
      "name": "Rock_Shale_Brick"
    },
    {
      "x": -5,
      "y": 14,
      "z": 12,
      "name": "Rock_Shale_Brick"
    },
    {
      "x": -5,
      "y": 15,
      "z": 12,
      "name": "Rock_Shale_Brick"
    },
    {
      "x": -5,
      "y": 16,
      "z": 12,
      "name": "Rock_Shale_Brick",
      "rotation": 1
    },
    {
      "x": -5,
      "y": 17,
      "z": 12,
      "name": "Rock_Shale_Brick_Roof"
    },
    {
      "x": -5,
      "y": 18,
      "z": 12,
      "name": "Empty"
    },
    {
      "x": -5,
      "y": 19,
      "z": 12,
      "name": "Rock_Shale_Cobble_Stairs",
      "rotation": 11
    },
    {
      "x": -5,
      "y": 20,
      "z": 12,
      "name": "Rock_Shale_Brick",
      "rotation": 2
    },
    {
      "x": -5,
      "y": 21,
      "z": 12,
      "name": "Rock_Shale_Brick_Roof_Flat"
    },
    {
      "x": -5,
      "y": 10,
      "z": 13,
      "name": "Rock_Slate"
    },
    {
      "x": -5,
      "y": 11,
      "z": 13,
      "name": "Rock_Slate"
    },
    {
      "x": -5,
      "y": 12,
      "z": 13,
      "name": "Rock_Slate"
    },
    {
      "x": -5,
      "y": 13,
      "z": 13,
      "name": "Rock_Slate"
    },
    {
      "x": -5,
      "y": 11,
      "z": 14,
      "name": "Rock_Slate"
    },
    {
      "x": -5,
      "y": 12,
      "z": 14,
      "name": "Rock_Slate"
    },
    {
      "x": -4,
      "y": 20,
      "z": -13,
      "name": "Rock_Volcanic_Brick_Half",
      "rotation": 6
    },
    {
      "x": -4,
      "y": 19,
      "z": -12,
      "name": "Rock_Volcanic_Brick_Stairs",
      "rotation": 2
    },
    {
      "x": -4,
      "y": 20,
      "z": -12,
      "name": "Rock_Volcanic_Brick"
    },
    {
      "x": -4,
      "y": 21,
      "z": -12,
      "name": "Rock_Volcanic_Brick_Stairs",
      "rotation": 8
    },
    {
      "x": -4,
      "y": 17,
      "z": -11,
      "name": "Rock_Volcanic_Brick_Stairs",
      "rotation": 2
    },
    {
      "x": -4,
      "y": 18,
      "z": -11,
      "name": "Rock_Volcanic_Brick"
    },
    {
      "x": -4,
      "y": 19,
      "z": -11,
      "name": "Rock_Volcanic_Brick"
    },
    {
      "x": -4,
      "y": 21,
      "z": -11,
      "name": "Rock_Volcanic_Brick"
    },
    {
      "x": -4,
      "y": 22,
      "z": -11,
      "name": "Rock_Volcanic_Brick"
    },
    {
      "x": -4,
      "y": 23,
      "z": -11,
      "name": "Rock_Volcanic_Brick_Stairs",
      "rotation": 8
    },
    {
      "x": -4,
      "y": 16,
      "z": -10,
      "name": "Rock_Volcanic_Brick_Stairs",
      "rotation": 10
    },
    {
      "x": -4,
      "y": 17,
      "z": -10,
      "name": "Rock_Volcanic_Brick_Stairs"
    },
    {
      "x": -4,
      "y": 19,
      "z": -10,
      "name": "Rock_Volcanic_Brick_Stairs",
      "rotation": 10
    },
    {
      "x": -4,
      "y": 20,
      "z": -10,
      "name": "Rock_Volcanic_Brick"
    },
    {
      "x": -4,
      "y": 21,
      "z": -10,
      "name": "Rock_Volcanic_Brick_Stairs"
    },
    {
      "x": -4,
      "y": 23,
      "z": -10,
      "name": "Rock_Volcanic_Brick_Stairs",
      "rotation": 10
    },
    {
      "x": -4,
      "y": 24,
      "z": -10,
      "name": "Rock_Volcanic_Brick_Stairs"
    },
    {
      "x": -4,
      "y": 16,
      "z": -9,
      "name": "Rock_Volcanic_Brick"
    },
    {
      "x": -4,
      "y": 20,
      "z": -9,
      "name": "Rock_Volcanic_Brick"
    },
    {
      "x": -4,
      "y": 24,
      "z": -9,
      "name": "Rock_Volcanic_Brick"
    },
    {
      "x": -4,
      "y": 12,
      "z": -8,
      "name": "Rock_Slate"
    },
    {
      "x": -4,
      "y": 15,
      "z": -8,
      "name": "Rock_Volcanic_Brick_Stairs",
      "rotation": 10
    },
    {
      "x": -4,
      "y": 16,
      "z": -8,
      "name": "Rock_Volcanic_Brick"
    },
    {
      "x": -4,
      "y": 17,
      "z": -8,
      "name": "Rock_Volcanic_Brick_Stairs",
      "rotation": 2
    },
    {
      "x": -4,
      "y": 19,
      "z": -8,
      "name": "Rock_Volcanic_Brick_Stairs",
      "rotation": 8
    },
    {
      "x": -4,
      "y": 20,
      "z": -8,
      "name": "Rock_Volcanic_Brick"
    },
    {
      "x": -4,
      "y": 21,
      "z": -8,
      "name": "Rock_Volcanic_Brick_Stairs",
      "rotation": 2
    },
    {
      "x": -4,
