{
  "version": 8,
  "blockIdVersion": 11,
  "anchorX": 1,
  "anchorY": 5,
  "anchorZ": 1,
  "blocks": [
    {
      "x": -14,
      "y": 4,
      "z": 0,
      "name": "Rock_Slate"
    },
    {
      "x": -13,
      "y": 4,
      "z": 0,
      "name": "Rock_Slate"
    },
    {
      "x": -13,
      "y": 4,
      "z": 2,
      "name": "Rock_Slate"
    },
    {
      "x": -13,
      "y": 4,
      "z": 7,
      "name": "Rock_Slate"
    },
    {
      "x": -12,
      "y": 4,
      "z": -2,
      "name": "Rock_Slate"
    },
    {
      "x": -12,
      "y": 4,
      "z": -1,
      "name": "Rock_Slate"
    },
    {
      "x": -12,
      "y": 3,
      "z": 0,
      "name": "Rock_Slate"
    },
    {
      "x": -12,
      "y": 4,
      "z": 0,
      "name": "Rock_Slate"
    },
    {
      "x": -12,
      "y": 4,
      "z": 1,
      "name": "Rock_Slate"
    },
    {
      "x": -12,
      "y": 3,
      "z": 2,
      "name": "Rock_Slate"
    },
    {
      "x": -12,
      "y": 4,
      "z": 2,
      "name": "Rock_Slate"
    },
    {
      "x": -12,
      "y": 4,
      "z": 5,
      "name": "Rock_Slate"
    },
    {
      "x": -12,
      "y": 4,
      "z": 7,
      "name": "Rock_Slate"
    },
    {
      "x": -11,
      "y": 4,
      "z": -4,
      "name": "Rock_Slate"
    },
    {
      "x": -11,
      "y": 3,
      "z": -3,
      "name": "Rock_Slate"
    },
    {
      "x": -11,
      "y": 4,
      "z": -3,
      "name": "Rock_Slate"
    },
    {
      "x": -11,
      "y": 4,
      "z": -2,
      "name": "Rock_Slate"
    },
    {
      "x": -11,
      "y": 3,
      "z": -1,
      "name": "Rock_Slate"
    },
    {
      "x": -11,
      "y": 4,
      "z": -1,
      "name": "Rock_Slate"
    },
    {
      "x": -11,
      "y": 3,
      "z": 0,
      "name": "Rock_Slate"
    },
    {
      "x": -11,
      "y": 4,
      "z": 0,
      "name": "Rock_Slate"
    },
    {
      "x": -11,
      "y": 4,
      "z": 1,
      "name": "Rock_Slate"
    },
    {
      "x": -11,
      "y": 3,
      "z": 2,
      "name": "Rock_Slate"
    },
    {
      "x": -11,
      "y": 4,
      "z": 5,
      "name": "Rock_Slate"
    },
    {
      "x": -11,
      "y": 4,
      "z": 6,
      "name": "Rock_Slate"
    },
    {
      "x": -11,
      "y": 4,
      "z": 7,
      "name": "Rock_Slate"
    },
    {
      "x": -10,
      "y": 4,
      "z": -12,
      "name": "Rock_Slate"
    },
    {
      "x": -10,
      "y": 2,
      "z": -11,
      "name": "Rock_Slate"
    },
    {
      "x": -10,
      "y": 3,
      "z": -11,
      "name": "Rock_Slate"
    },
    {
      "x": -10,
      "y": 4,
      "z": -10,
      "name": "Rock_Slate"
    },
    {
      "x": -10,
      "y": 3,
      "z": -9,
      "name": "Rock_Slate"
    },
    {
      "x": -10,
      "y": 2,
      "z": -6,
      "name": "Rock_Slate"
    },
    {
      "x": -10,
      "y": 2,
      "z": -5,
      "name": "Rock_Slate"
    },
    {
      "x": -10,
      "y": 4,
      "z": -5,
      "name": "Rock_Slate"
    },
    {
      "x": -10,
      "y": 4,
      "z": -4,
      "name": "Rock_Slate"
    },
    {
      "x": -10,
      "y": 2,
      "z": -3,
      "name": "Rock_Slate"
    },
    {
      "x": -10,
      "y": 3,
      "z": -3,
      "name": "Rock_Slate"
    },
    {
      "x": -10,
      "y": 4,
      "z": -3,
      "name": "Rock_Slate"
    },
    {
      "x": -10,
      "y": 5,
      "z": -3,
      "name": "Rock_Slate"
    },
    {
      "x": -10,
      "y": 3,
      "z": -2,
      "name": "Rock_Slate"
    },
    {
      "x": -10,
      "y": 4,
      "z": -2,
      "name": "Rock_Slate"
    },
    {
      "x": -10,
      "y": 5,
      "z": -2,
      "name": "Rock_Slate"
    },
    {
      "x": -10,
      "y": 3,
      "z": -1,
      "name": "Rock_Slate"
    },
    {
      "x": -10,
      "y": 4,
      "z": -1,
      "name": "Rock_Slate"
    },
    {
      "x": -10,
      "y": 5,
      "z": -1,
      "name": "Rock_Slate"
    },
    {
      "x": -10,
      "y": 2,
      "z": 0,
      "name": "Rock_Slate"
    },
    {
      "x": -10,
      "y": 3,
      "z": 0,
      "name": "Rock_Slate"
    },
    {
      "x": -10,
      "y": 4,
      "z": 0,
      "name": "Rock_Slate"
    },
    {
      "x": -10,
      "y": 2,
      "z": 1,
      "name": "Rock_Slate"
    },
    {
      "x": -10,
      "y": 3,
      "z": 1,
      "name": "Rock_Slate"
    },
    {
      "x": -10,
      "y": 3,
      "z": 2,
      "name": "Rock_Slate"
    },
    {
      "x": -10,
      "y": 2,
      "z": 3,
      "name": "Rock_Slate"
    },
    {
      "x": -10,
      "y": 3,
      "z": 3,
      "name": "Rock_Slate"
    },
    {
      "x": -10,
      "y": 4,
      "z": 3,
      "name": "Rock_Slate"
    },
    {
      "x": -10,
      "y": 3,
      "z": 4,
      "name": "Rock_Slate"
    },
    {
      "x": -10,
      "y": 4,
      "z": 4,
      "name": "Rock_Slate"
    },
    {
      "x": -10,
      "y": 3,
      "z": 5,
      "name": "Rock_Slate"
    },
    {
      "x": -10,
      "y": 4,
      "z": 5,
      "name": "Rock_Slate"
    },
    {
      "x": -10,
      "y": 2,
      "z": 6,
      "name": "Rock_Slate"
    },
    {
      "x": -10,
      "y": 3,
      "z": 6,
      "name": "Rock_Slate"
    },
    {
      "x": -10,
      "y": 4,
      "z": 6,
      "name": "Rock_Slate"
    },
    {
      "x": -10,
      "y": 2,
      "z": 7,
      "name": "Rock_Slate"
    },
    {
      "x": -10,
      "y": 3,
      "z": 7,
      "name": "Rock_Slate"
    },
    {
      "x": -10,
      "y": 4,
      "z": 7,
      "name": "Rock_Slate"
    },
    {
      "x": -10,
      "y": 2,
      "z": 8,
      "name": "Rock_Slate"
    },
    {
      "x": -10,
      "y": 3,
      "z": 8,
      "name": "Rock_Slate"
    },
    {
      "x": -10,
      "y": 4,
      "z": 8,
      "name": "Rock_Slate"
    },
    {
      "x": -10,
      "y": 3,
      "z": 9,
      "name": "Rock_Slate"
    },
    {
      "x": -10,
      "y": 4,
      "z": 9,
      "name": "Rock_Slate"
    },
    {
      "x": -10,
      "y": 3,
      "z": 10,
      "name": "Rock_Slate"
    },
    {
      "x": -9,
      "y": 2,
      "z": -12,
      "name": "Rock_Slate"
    },
    {
      "x": -9,
      "y": 4,
      "z": -12,
      "name": "Rock_Slate"
    },
    {
      "x": -9,
      "y": 2,
      "z": -11,
      "name": "Rock_Slate"
    },
    {
      "x": -9,
      "y": 3,
      "z": -11,
      "name": "Rock_Slate"
    },
    {
      "x": -9,
      "y": 4,
      "z": -11,
      "name": "Rock_Slate"
    },
    {
      "x": -9,
      "y": 2,
      "z": -10,
      "name": "Rock_Slate"
    },
    {
      "x": -9,
      "y": 3,
      "z": -10,
      "name": "Rock_Slate"
    },
    {
      "x": -9,
      "y": 4,
      "z": -10,
      "name": "Rock_Slate"
    },
    {
      "x": -9,
      "y": 2,
      "z": -9,
      "name": "Rock_Slate"
    },
    {
      "x": -9,
      "y": 3,
      "z": -9,
      "name": "Rock_Slate"
    },
    {
      "x": -9,
      "y": 4,
      "z": -9,
      "name": "Rock_Slate"
    },
    {
      "x": -9,
      "y": 2,
      "z": -8,
      "name": "Rock_Slate"
    },
    {
      "x": -9,
      "y": 3,
      "z": -8,
      "name": "Rock_Slate"
    },
    {
      "x": -9,
      "y": 4,
      "z": -8,
      "name": "Rock_Slate"
    },
    {
      "x": -9,
      "y": 4,
      "z": -7,
      "name": "Rock_Slate"
    },
    {
      "x": -9,
      "y": 2,
      "z": -6,
      "name": "Rock_Slate"
    },
    {
      "x": -9,
      "y": 3,
      "z": -6,
      "name": "Rock_Slate"
    },
    {
      "x": -9,
      "y": 4,
      "z": -6,
      "name": "Rock_Slate"
    },
    {
      "x": -9,
      "y": 1,
      "z": -5,
      "name": "Rock_Slate"
    },
    {
      "x": -9,
      "y": 2,
      "z": -5,
      "name": "Rock_Slate"
    },
    {
      "x": -9,
      "y": 3,
      "z": -5,
      "name": "Rock_Slate"
    },
    {
      "x": -9,
      "y": 4,
      "z": -5,
      "name": "Rock_Slate"
    },
    {
      "x": -9,
      "y": 2,
      "z": -4,
      "name": "Rock_Slate"
    },
    {
      "x": -9,
      "y": 3,
      "z": -4,
      "name": "Rock_Slate"
    },
    {
      "x": -9,
      "y": 4,
      "z": -4,
      "name": "Rock_Slate"
    },
    {
      "x": -9,
      "y": 5,
      "z": -4,
      "name": "Rock_Slate"
    },
    {
      "x": -9,
      "y": 2,
      "z": -3,
      "name": "Rock_Slate"
    },
    {
      "x": -9,
      "y": 3,
      "z": -3,
      "name": "Rock_Slate"
    },
    {
      "x": -9,
      "y": 4,
      "z": -3,
      "name": "Rock_Slate"
    },
    {
      "x": -9,
      "y": 5,
      "z": -3,
      "name": "Rock_Slate"
    },
    {
      "x": -9,
      "y": 6,
      "z": -3,
      "name": "Rock_Slate"
    },
    {
      "x": -9,
      "y": 7,
      "z": -3,
      "name": "Rock_Slate"
    },
    {
      "x": -9,
      "y": 2,
      "z": -2,
      "name": "Rock_Slate"
    },
    {
      "x": -9,
      "y": 3,
      "z": -2,
      "name": "Rock_Slate"
    },
    {
      "x": -9,
      "y": 4,
      "z": -2,
      "name": "Rock_Slate"
    },
    {
      "x": -9,
      "y": 2,
      "z": -1,
      "name": "Rock_Slate"
    },
    {
      "x": -9,
      "y": 3,
      "z": -1,
      "name": "Rock_Slate"
    },
    {
      "x": -9,
      "y": 4,
      "z": -1,
      "name": "Rock_Slate"
    },
    {
      "x": -9,
      "y": 2,
      "z": 0,
      "name": "Rock_Slate"
    },
    {
      "x": -9,
      "y": 3,
      "z": 0,
      "name": "Rock_Slate"
    },
    {
      "x": -9,
      "y": 4,
      "z": 0,
      "name": "Rock_Slate"
    },
    {
      "x": -9,
      "y": 2,
      "z": 1,
      "name": "Rock_Slate"
    },
    {
      "x": -9,
      "y": 3,
      "z": 1,
      "name": "Rock_Slate"
    },
    {
      "x": -9,
      "y": 3,
      "z": 2,
      "name": "Rock_Slate"
    },
    {
      "x": -9,
      "y": 4,
      "z": 2,
      "name": "Rock_Slate"
    },
    {
      "x": -9,
      "y": 2,
      "z": 3,
      "name": "Rock_Slate"
    },
    {
      "x": -9,
      "y": 3,
      "z": 3,
      "name": "Rock_Slate"
    },
    {
      "x": -9,
      "y": 4,
      "z": 3,
      "name": "Rock_Slate"
    },
    {
      "x": -9,
      "y": 5,
      "z": 3,
      "name": "Rock_Slate"
    },
    {
      "x": -9,
      "y": 2,
      "z": 4,
      "name": "Rock_Slate"
    },
    {
      "x": -9,
      "y": 3,
      "z": 4,
      "name": "Rock_Slate"
    },
    {
      "x": -9,
      "y": 4,
      "z": 4,
      "name": "Rock_Slate"
    },
    {
      "x": -9,
      "y": 3,
      "z": 5,
      "name": "Rock_Slate"
    },
    {
      "x": -9,
      "y": 4,
      "z": 5,
      "name": "Rock_Slate"
    },
    {
      "x": -9,
      "y": 3,
      "z": 6,
      "name": "Rock_Slate"
    },
    {
      "x": -9,
      "y": 4,
      "z": 6,
      "name": "Rock_Slate"
    },
    {
      "x": -9,
      "y": 2,
      "z": 7,
      "name": "Rock_Slate"
    },
    {
      "x": -9,
      "y": 3,
      "z": 7,
      "name": "Rock_Slate"
    },
    {
      "x": -9,
      "y": 4,
      "z": 7,
      "name": "Rock_Slate"
    },
    {
      "x": -9,
      "y": 2,
      "z": 8,
      "name": "Rock_Slate"
    },
    {
      "x": -9,
      "y": 3,
      "z": 8,
      "name": "Rock_Slate"
    },
    {
      "x": -9,
      "y": 4,
      "z": 8,
      "name": "Rock_Slate"
    },
    {
      "x": -9,
      "y": 2,
      "z": 9,
      "name": "Rock_Slate"
    },
    {
      "x": -9,
      "y": 3,
      "z": 9,
      "name": "Rock_Slate"
    },
    {
      "x": -9,
      "y": 4,
      "z": 9,
      "name": "Rock_Slate"
    },
    {
      "x": -9,
      "y": 2,
      "z": 10,
      "name": "Rock_Slate"
    },
    {
      "x": -9,
      "y": 3,
      "z": 10,
      "name": "Rock_Slate"
    },
    {
      "x": -9,
      "y": 4,
      "z": 10,
      "name": "Rock_Slate"
    },
    {
      "x": -9,
      "y": 2,
      "z": 11,
      "name": "Rock_Slate"
    },
    {
      "x": -9,
      "y": 4,
      "z": 12,
      "name": "Rock_Slate"
    },
    {
      "x": -8,
      "y": 3,
      "z": -13,
      "name": "Rock_Slate"
    },
    {
      "x": -8,
      "y": 4,
      "z": -13,
      "name": "Rock_Slate"
    },
    {
      "x": -8,
      "y": 3,
      "z": -12,
      "name": "Rock_Slate"
    },
    {
      "x": -8,
      "y": 4,
      "z": -12,
      "name": "Rock_Slate"
    },
    {
      "x": -8,
      "y": 2,
      "z": -11,
      "name": "Rock_Slate"
    },
    {
      "x": -8,
      "y": 3,
      "z": -11,
      "name": "Rock_Slate"
    },
    {
      "x": -8,
      "y": 4,
      "z": -11,
      "name": "Rock_Slate"
    },
    {
      "x": -8,
      "y": 5,
      "z": -11,
      "name": "Rock_Shale_Brick_Decorative",
      "rotation": 1
    },
    {
      "x": -8,
      "y": 6,
      "z": -11,
      "name": "Rock_Shale_Brick_Beam",
      "rotation": 2
    },
    {
      "x": -8,
      "y": 7,
      "z": -11,
      "name": "Rock_Shale_Brick_Beam",
      "rotation": 2
    },
    {
      "x": -8,
      "y": 8,
      "z": -11,
      "name": "Rock_Shale_Brick_Beam",
      "rotation": 2
    },
    {
      "x": -8,
      "y": 9,
      "z": -11,
      "name": "Rock_Shale_Brick_Beam",
      "rotation": 2
    },
    {
      "x": -8,
      "y": 10,
      "z": -11,
      "name": "Rock_Shale_Brick_Half",
      "rotation": 2
    },
    {
      "x": -8,
      "y": 2,
      "z": -10,
      "name": "Rock_Slate"
    },
    {
      "x": -8,
      "y": 3,
      "z": -10,
      "name": "Rock_Slate"
    },
    {
      "x": -8,
      "y": 4,
      "z": -10,
      "name": "Rock_Slate"
    },
    {
      "x": -8,
      "y": 5,
      "z": -10,
      "name": "Rock_Shale_Brick",
      "rotation": 1
    },
    {
      "x": -8,
      "y": 6,
      "z": -10,
      "name": "Rock_Shale_Brick_Ornate",
      "rotation": 2
    },
    {
      "x": -8,
      "y": 7,
      "z": -10,
      "name": "Rock_Shale_Brick_Pillar_Base",
      "rotation": 2
    },
    {
      "x": -8,
      "y": 8,
      "z": -10,
      "name": "Rock_Shale_Brick_Pillar_Middle",
      "rotation": 2
    },
    {
      "x": -8,
      "y": 9,
      "z": -10,
      "name": "Rock_Shale_Brick_Pillar_Base",
      "rotation": 10
    },
    {
      "x": -8,
      "y": 2,
      "z": -9,
      "name": "Rock_Slate"
    },
    {
      "x": -8,
      "y": 3,
      "z": -9,
      "name": "Rock_Slate"
    },
    {
      "x": -8,
      "y": 4,
      "z": -9,
      "name": "Rock_Slate"
    },
    {
      "x": -8,
      "y": 2,
      "z": -8,
      "name": "Rock_Slate"
    },
    {
      "x": -8,
      "y": 3,
      "z": -8,
      "name": "Rock_Slate"
    },
    {
      "x": -8,
      "y": 4,
      "z": -8,
      "name": "Rock_Slate"
    },
    {
      "x": -8,
      "y": 3,
      "z": -7,
      "name": "Rock_Slate"
    },
    {
      "x": -8,
      "y": 4,
      "z": -7,
      "name": "Rock_Slate"
    },
    {
      "x": -8,
      "y": 2,
      "z": -6,
      "name": "Rock_Slate"
    },
    {
      "x": -8,
      "y": 3,
      "z": -6,
      "name": "Rock_Slate"
    },
    {
      "x": -8,
      "y": 4,
      "z": -6,
      "name": "Rock_Slate"
    },
    {
      "x": -8,
      "y": 1,
      "z": -5,
      "name": "Rock_Slate"
    },
    {
      "x": -8,
      "y": 2,
      "z": -5,
      "name": "Rock_Slate"
    },
    {
      "x": -8,
      "y": 3,
      "z": -5,
      "name": "Rock_Slate"
    },
    {
      "x": -8,
      "y": 4,
      "z": -5,
      "name": "Rock_Slate"
    },
    {
      "x": -8,
      "y": 2,
      "z": -4,
      "name": "Rock_Slate"
    },
    {
      "x": -8,
      "y": 3,
      "z": -4,
      "name": "Rock_Slate"
    },
    {
      "x": -8,
      "y": 4,
      "z": -4,
      "name": "Rock_Slate"
    },
    {
      "x": -8,
      "y": 0,
      "z": -3,
      "name": "Rock_Slate"
    },
    {
      "x": -8,
      "y": 1,
      "z": -3,
      "name": "Rock_Slate"
    },
    {
      "x": -8,
      "y": 2,
      "z": -3,
      "name": "Rock_Slate"
    },
    {
      "x": -8,
      "y": 3,
      "z": -3,
      "name": "Rock_Slate"
    },
    {
      "x": -8,
      "y": 4,
      "z": -3,
      "name": "Rock_Slate"
    },
    {
      "x": -8,
      "y": 1,
      "z": -2,
      "name": "Rock_Slate"
    },
    {
      "x": -8,
      "y": 2,
      "z": -2,
      "name": "Rock_Slate"
    },
    {
      "x": -8,
      "y": 3,
      "z": -2,
      "name": "Rock_Slate"
    },
    {
      "x": -8,
      "y": 4,
      "z": -2,
      "name": "Rock_Slate"
    },
    {
      "x": -8,
      "y": 2,
      "z": -1,
      "name": "Rock_Slate"
    },
    {
      "x": -8,
      "y": 3,
      "z": -1,
      "name": "Rock_Slate"
    },
    {
      "x": -8,
      "y": 4,
      "z": -1,
      "name": "Rock_Slate"
    },
    {
      "x": -8,
      "y": 9,
      "z": -1,
      "name": "Rock_Shale_Cobble_Stairs",
      "rotation": 9
    },
    {
      "x": -8,
      "y": 10,
      "z": -1,
      "name": "Rock_Shale_Brick_Roof_Steep",
      "rotation": 3
    },
    {
      "x": -8,
      "y": 11,
      "z": -1,
      "name": "Rock_Shale_Brick_Roof_Steep",
      "filler": 1024,
      "rotation": 3
    },
    {
      "x": -8,
      "y": 2,
      "z": 0,
      "name": "Rock_Slate"
    },
    {
      "x": -8,
      "y": 3,
      "z": 0,
      "name": "Rock_Slate"
    },
    {
      "x": -8,
      "y": 4,
      "z": 0,
      "name": "Rock_Slate"
    },
    {
      "x": -8,
      "y": 9,
      "z": 0,
      "name": "Rock_Shale_Cobble_Stairs",
      "rotation": 9
    },
    {
      "x": -8,
      "y": 10,
      "z": 0,
      "name": "Rock_Shale_Brick_Roof_Steep",
      "rotation": 3
    },
    {
      "x": -8,
      "y": 11,
      "z": 0,
      "name": "Rock_Shale_Brick_Roof_Steep",
      "filler": 1024,
      "rotation": 3
    },
    {
      "x": -8,
      "y": 3,
      "z": 1,
      "name": "Rock_Slate"
    },
    {
      "x": -8,
      "y": 4,
      "z": 1,
      "name": "Rock_Slate"
    },
    {
      "x": -8,
      "y": 3,
      "z": 2,
      "name": "Rock_Slate"
    },
    {
      "x": -8,
      "y": 4,
      "z": 2,
      "name": "Rock_Slate"
    },
    {
      "x": -8,
      "y": 3,
      "z": 3,
      "name": "Rock_Slate"
    },
    {
      "x": -8,
      "y": 4,
      "z": 3,
      "name": "Rock_Slate"
    },
    {
      "x": -8,
      "y": 5,
      "z": 3,
      "name": "Rock_Slate"
    },
    {
      "x": -8,
      "y": 6,
      "z": 3,
      "name": "Rock_Slate"
    },
    {
      "x": -8,
      "y": 2,
      "z": 4,
      "name": "Rock_Slate"
    },
    {
      "x": -8,
      "y": 3,
      "z": 4,
      "name": "Rock_Slate"
    },
    {
      "x": -8,
      "y": 4,
      "z": 4,
      "name": "Rock_Slate"
    },
    {
      "x": -8,
      "y": 2,
      "z": 5,
      "name": "Rock_Slate"
    },
    {
      "x": -8,
      "y": 3,
      "z": 5,
      "name": "Rock_Slate"
    },
    {
      "x": -8,
      "y": 4,
      "z": 5,
      "name": "Rock_Slate"
    },
    {
      "x": -8,
      "y": 5,
      "z": 5,
      "name": "Rock_Slate"
    },
    {
      "x": -8,
      "y": 3,
      "z": 6,
      "name": "Rock_Slate"
    },
    {
      "x": -8,
      "y": 4,
      "z": 6,
      "name": "Rock_Slate"
    },
    {
      "x": -8,
      "y": 5,
      "z": 6,
      "name": "Rock_Slate"
    },
    {
      "x": -8,
      "y": 2,
      "z": 7,
      "name": "Rock_Slate"
    },
    {
      "x": -8,
      "y": 3,
      "z": 7,
      "name": "Rock_Slate"
    },
    {
      "x": -8,
      "y": 4,
      "z": 7,
      "name": "Rock_Slate"
    },
    {
      "x": -8,
      "y": 2,
      "z": 8,
      "name": "Rock_Slate"
    },
    {
      "x": -8,
      "y": 3,
      "z": 8,
      "name": "Rock_Slate"
    },
    {
      "x": -8,
      "y": 4,
      "z": 8,
      "name": "Rock_Slate"
    },
    {
      "x": -8,
      "y": 2,
      "z": 9,
      "name": "Rock_Slate"
    },
    {
      "x": -8,
      "y": 3,
      "z": 9,
      "name": "Rock_Slate"
    },
    {
      "x": -8,
      "y": 4,
      "z": 9,
      "name": "Rock_Slate"
    },
    {
      "x": -8,
      "y": 5,
      "z": 9,
      "name": "Rock_Shale_Brick",
      "rotation": 2
    },
    {
      "x": -8,
      "y": 6,
      "z": 9,
      "name": "Rock_Shale_Brick_Ornate",
      "rotation": 3
    },
    {
      "x": -8,
      "y": 7,
      "z": 9,
      "name": "Rock_Shale_Brick_Pillar_Base",
      "rotation": 3
    },
    {
      "x": -8,
      "y": 2,
      "z": 10,
      "name": "Rock_Slate"
    },
    {
      "x": -8,
      "y": 3,
      "z": 10,
      "name": "Rock_Slate"
    },
    {
      "x": -8,
      "y": 4,
      "z": 10,
      "name": "Rock_Slate"
    },
    {
      "x": -8,
      "y": 5,
      "z": 10,
      "name": "Rock_Shale_Brick_Decorative",
      "rotation": 2
    },
    {
      "x": -8,
      "y": 6,
      "z": 10,
      "name": "Rock_Shale_Brick_Beam",
      "rotation": 3
    },
    {
      "x": -8,
      "y": 7,
      "z": 10,
      "name": "Rock_Shale_Brick_Beam",
      "rotation": 3
    },
    {
      "x": -8,
      "y": 2,
      "z": 11,
      "name": "Rock_Slate"
    },
    {
      "x": -8,
      "y": 3,
      "z": 11,
      "name": "Rock_Slate"
    },
    {
      "x": -8,
      "y": 4,
      "z": 11,
      "name": "Rock_Slate"
    },
    {
      "x": -8,
      "y": 2,
      "z": 12,
      "name": "Rock_Slate"
    },
    {
      "x": -8,
      "y": 4,
      "z": 12,
      "name": "Rock_Slate"
    },
    {
      "x": -7,
      "y": 3,
      "z": -13,
      "name": "Rock_Slate"
    },
    {
      "x": -7,
      "y": 4,
      "z": -13,
      "name": "Rock_Slate"
    },
    {
      "x": -7,
      "y": 2,
      "z": -12,
      "name": "Rock_Slate"
    },
    {
      "x": -7,
      "y": 3,
      "z": -12,
      "name": "Rock_Slate"
    },
    {
      "x": -7,
      "y": 4,
      "z": -12,
      "name": "Rock_Slate"
    },
    {
      "x": -7,
      "y": 2,
      "z": -11,
      "name": "Rock_Slate"
    },
    {
      "x": -7,
      "y": 3,
      "z": -11,
      "name": "Rock_Slate"
    },
    {
      "x": -7,
      "y": 4,
      "z": -11,
      "name": "Rock_Slate"
    },
    {
      "x": -7,
      "y": 5,
      "z": -11,
      "name": "Rock_Shale_Brick",
      "rotation": 1
    },
    {
      "x": -7,
      "y": 6,
      "z": -11,
      "name": "Rock_Shale_Brick_Ornate",
      "rotation": 2
    },
    {
      "x": -7,
      "y": 7,
      "z": -11,
      "name": "Rock_Shale_Brick_Pillar_Base",
      "rotation": 2
    },
    {
      "x": -7,
      "y": 8,
      "z": -11,
      "name": "Rock_Shale_Brick_Pillar_Middle",
      "rotation": 2
    },
    {
      "x": -7,
      "y": 9,
      "z": -11,
      "name": "Rock_Shale_Brick_Pillar_Base",
      "rotation": 10
    },
    {
      "x": -7,
      "y": 10,
      "z": -11,
      "name": "Rock_Shale_Brick_Roof_Steep",
      "rotation": 2
    },
    {
      "x": -7,
      "y": 11,
      "z": -11,
      "name": "Rock_Shale_Brick_Roof_Steep",
      "filler": 1024,
      "rotation": 2
    },
    {
      "x": -7,
      "y": 2,
      "z": -10,
      "name": "Rock_Slate"
    },
    {
      "x": -7,
      "y": 3,
      "z": -10,
      "name": "Rock_Slate"
    },
    {
      "x": -7,
      "y": 4,
      "z": -10,
      "name": "Rock_Slate"
    },
    {
      "x": -7,
      "y": 5,
      "z": -10,
      "name": "Rock_Shale_Brick",
      "rotation": 2
    },
    {
      "x": -7,
      "y": 6,
      "z": -10,
      "name": "Rock_Shale_Brick",
      "rotation": 2
    },
    {
      "x": -7,
      "y": 7,
      "z": -10,
      "name": "Rock_Shale_Brick",
      "rotation": 2
    },
    {
      "x": -7,
      "y": 8,
      "z": -10,
      "name": "Rock_Shale_Brick",
      "rotation": 2
    },
    {
      "x": -7,
      "y": 9,
      "z": -10,
      "name": "Rock_Shale_Brick_Ornate",
      "rotation": 2
    },
    {
      "x": -7,
      "y": 10,
      "z": -10,
      "name": "Rock_Shale_Brick_Ornate",
      "rotation": 2
    },
    {
      "x": -7,
      "y": 11,
      "z": -10,
      "name": "Rock_Shale_Brick_Ornate",
      "rotation": 2
    },
    {
      "x": -7,
      "y": 2,
      "z": -9,
      "name": "Rock_Slate"
    },
    {
      "x": -7,
      "y": 3,
      "z": -9,
      "name": "Rock_Slate"
    },
    {
      "x": -7,
      "y": 4,
      "z": -9,
      "name": "Rock_Slate"
    },
    {
      "x": -7,
      "y": 5,
      "z": -9,
      "name": "Rock_Shale_Brick"
    },
    {
      "x": -7,
      "y": 6,
      "z": -9,
      "name": "Rock_Shale_Brick_Roof",
      "rotation": 3
    },
    {
      "x": -7,
      "y": 8,
      "z": -9,
      "name": "Rock_Shale_Cobble_Stairs",
      "rotation": 10
    },
    {
      "x": -7,
      "y": 9,
      "z": -9,
      "name": "Rock_Shale_Brick",
      "rotation": 2
    },
    {
      "x": -7,
      "y": 10,
      "z": -9,
      "name": "Rock_Shale_Brick_Roof_Flat",
      "rotation": 3
    },
    {
      "x": -7,
      "y": 2,
      "z": -8,
      "name": "Rock_Slate"
    },
    {
      "x": -7,
      "y": 3,
      "z": -8,
      "name": "Rock_Slate"
    },
    {
      "x": -7,
      "y": 4,
      "z": -8,
      "name": "Rock_Slate"
    },
    {
      "x": -7,
      "y": 5,
      "z": -8,
      "name": "Rock_Shale_Brick_Wall",
      "rotation": 1
    },
    {
      "x": -7,
      "y": 9,
      "z": -8,
      "name": "Rock_Shale_Brick",
      "rotation": 2
    },
    {
      "x": -7,
      "y": 10,
      "z": -8,
      "name": "Rock_Shale_Brick_Roof_Flat",
      "rotation": 3
    },
    {
      "x": -7,
      "y": 2,
      "z": -7,
      "name": "Rock_Slate"
    },
    {
      "x": -7,
      "y": 3,
      "z": -7,
      "name": "Rock_Slate"
    },
    {
      "x": -7,
      "y": 4,
      "z": -7,
      "name": "Rock_Slate"
    },
    {
      "x": -7,
      "y": 5,
      "z": -7,
      "name": "Rock_Shale_Brick_Decorative"
    },
    {
      "x": -7,
      "y": 6,
      "z": -7,
      "name": "Rock_Shale_Brick_Beam"
    },
    {
      "x": -7,
      "y": 7,
      "z": -7,
      "name": "Rock_Shale_Brick_Beam"
    },
    {
      "x": -7,
      "y": 8,
      "z": -7,
      "name": "Rock_Shale_Brick_Decorative"
    },
    {
      "x": -7,
      "y": 9,
      "z": -7,
      "name": "Rock_Shale_Brick",
      "rotation": 2
    },
    {
      "x": -7,
      "y": 10,
      "z": -7,
      "name": "Rock_Shale_Brick_Roof_Flat",
      "rotation": 3
    },
    {
      "x": -7,
      "y": 3,
      "z": -6,
      "name": "Rock_Slate"
    },
    {
      "x": -7,
      "y": 4,
      "z": -6,
      "name": "Rock_Shale_Brick"
    },
    {
      "x": -7,
      "y": 9,
      "z": -6,
      "name": "Rock_Shale_Brick_Stairs",
      "rotation": 9
    },
    {
      "x": -7,
      "y": 2,
      "z": -5,
      "name": "Rock_Slate"
    },
    {
      "x": -7,
      "y": 3,
      "z": -5,
      "name": "Rock_Slate"
    },
    {
      "x": -7,
      "y": 4,
      "z": -5,
      "name": "Rock_Slate"
    },
    {
      "x": -7,
      "y": 5,
      "z": -5,
      "name": "Rock_Shale_Brick_Decorative"
    },
    {
      "x": -7,
      "y": 6,
      "z": -5,
      "name": "Rock_Shale_Brick_Beam"
    },
    {
      "x": -7,
      "y": 7,
      "z": -5,
      "name": "Rock_Shale_Brick_Beam"
    },
    {
      "x": -7,
      "y": 8,
      "z": -5,
      "name": "Rock_Shale_Brick_Decorative"
    },
    {
      "x": -7,
      "y": 9,
      "z": -5,
      "name": "Rock_Shale_Brick",
      "rotation": 2
    },
    {
      "x": -7,
      "y": 10,
      "z": -5,
      "name": "Rock_Shale_Brick_Roof_Flat",
      "rotation": 3
    },
    {
      "x": -7,
      "y": 2,
      "z": -4,
      "name": "Rock_Slate"
    },
    {
      "x": -7,
      "y": 3,
      "z": -4,
      "name": "Rock_Slate"
    },
    {
      "x": -7,
      "y": 4,
      "z": -4,
      "name": "Rock_Slate"
    },
    {
      "x": -7,
      "y": 5,
      "z": -4,
      "name": "Rock_Shale_Brick_Wall",
      "rotation": 1
    },
    {
      "x": -7,
      "y": 9,
      "z": -4,
      "name": "Rock_Shale_Brick",
      "rotation": 2
    },
    {
      "x": -7,
      "y": 10,
      "z": -4,
      "name": "Rock_Shale_Brick_Roof_Flat",
      "rotation": 3
    },
    {
      "x": -7,
      "y": 2,
      "z": -3,
      "name": "Rock_Slate"
    },
    {
      "x": -7,
      "y": 3,
      "z": -3,
      "name": "Rock_Slate"
    },
    {
      "x": -7,
      "y": 4,
      "z": -3,
      "name": "Rock_Slate"
    },
    {
      "x": -7,
      "y": 5,
      "z": -3,
      "name": "Rock_Shale_Brick"
    },
    {
      "x": -7,
      "y": 6,
      "z": -3,
      "name": "Rock_Shale_Brick_Roof",
      "rotation": 3
    },
    {
      "x": -7,
      "y": 8,
      "z": -3,
      "name": "Rock_Shale_Cobble_Stairs",
      "rotation": 8
    },
    {
      "x": -7,
      "y": 9,
      "z": -3,
      "name": "Rock_Shale_Brick",
      "rotation": 2
    },
    {
      "x": -7,
      "y": 10,
      "z": -3,
      "name": "Rock_Shale_Brick_Roof_Flat",
      "rotation": 3
    },
    {
      "x": -7,
      "y": 1,
      "z": -2,
      "name": "Rock_Slate"
    },
    {
      "x": -7,
      "y": 2,
      "z": -2,
      "name": "Rock_Slate"
    },
    {
      "x": -7,
      "y": 3,
      "z": -2,
      "name": "Rock_Slate"
    },
    {
      "x": -7,
      "y": 4,
      "z": -2,
      "name": "Rock_Slate"
    },
    {
      "x": -7,
      "y": 5,
      "z": -2,
      "name": "Rock_Shale_Brick"
    },
    {
      "x": -7,
      "y": 6,
      "z": -2,
      "name": "Rock_Shale_Brick_Pillar_Base",
      "rotation": 2
    },
    {
      "x": -7,
      "y": 7,
      "z": -2,
      "name": "Rock_Shale_Brick_Pillar_Base",
      "rotation": 10
    },
    {
      "x": -7,
      "y": 8,
      "z": -2,
      "name": "Rock_Shale_Brick"
    },
    {
      "x": -7,
      "y": 9,
      "z": -2,
      "name": "Rock_Shale_Brick",
      "rotation": 2
    },
    {
      "x": -7,
      "y": 10,
      "z": -2,
      "name": "Rock_Shale_Brick_Roof",
      "rotation": 2
    },
    {
      "x": -7,
      "y": 1,
      "z": -1,
      "name": "Rock_Slate"
    },
    {
      "x": -7,
      "y": 2,
      "z": -1,
      "name": "Rock_Slate"
    },
    {
      "x": -7,
      "y": 3,
      "z": -1,
      "name": "Rock_Slate"
    },
    {
      "x": -7,
      "y": 4,
      "z": -1,
      "name": "Rock_Slate"
    },
    {
      "x": -7,
      "y": 5,
      "z": -1,
      "name": "Rock_Shale_Cobble_Stairs"
    },
    {
      "x": -7,
      "y": 8,
      "z": -1,
      "name": "Rock_Shale_Brick_Beam",
      "rotation": 6
    },
    {
      "x": -7,
      "y": 9,
      "z": -1,
      "name": "Rock_Shale_Brick",
      "rotation": 2
    },
    {
      "x": -7,
      "y": 10,
      "z": -1,
      "name": "Rock_Shale_Brick",
      "rotation": 2
    },
    {
      "x": -7,
      "y": 11,
      "z": -1,
      "name": "Rock_Shale_Brick",
      "rotation": 2
    },
    {
      "x": -7,
      "y": 2,
      "z": 0,
      "name": "Rock_Slate"
    },
    {
      "x": -7,
      "y": 3,
      "z": 0,
      "name": "Rock_Slate"
    },
    {
      "x": -7,
      "y": 4,
      "z": 0,
      "name": "Rock_Slate"
    },
    {
      "x": -7,
      "y": 5,
      "z": 0,
      "name": "Rock_Shale_Cobble_Stairs",
      "rotation": 2
    },
    {
      "x": -7,
      "y": 8,
      "z": 0,
      "name": "Rock_Shale_Brick_Beam",
      "rotation": 6
    },
    {
      "x": -7,
      "y": 9,
      "z": 0,
      "name": "Rock_Shale_Brick",
      "rotation": 2
    },
    {
      "x": -7,
      "y": 10,
      "z": 0,
      "name": "Rock_Shale_Brick",
      "rotation": 2
    },
    {
      "x": -7,
      "y": 11,
      "z": 0,
      "name": "Rock_Shale_Brick",
      "rotation": 2
    },
    {
      "x": -7,
      "y": 2,
      "z": 1,
      "name": "Rock_Slate"
    },
    {
      "x": -7,
      "y": 3,
      "z": 1,
      "name": "Rock_Slate"
    },
    {
      "x": -7,
      "y": 4,
      "z": 1,
      "name": "Rock_Slate"
    },
    {
      "x": -7,
      "y": 5,
      "z": 1,
      "name": "Rock_Shale_Brick"
    },
    {
      "x": -7,
      "y": 6,
      "z": 1,
      "name": "Rock_Shale_Brick_Pillar_Base",
      "rotation": 2
    },
    {
      "x": -7,
      "y": 7,
      "z": 1,
      "name": "Rock_Shale_Brick_Pillar_Base",
      "rotation": 10
    },
    {
      "x": -7,
      "y": 8,
      "z": 1,
      "name": "Rock_Shale_Brick"
    },
    {
      "x": -7,
      "y": 9,
      "z": 1,
      "name": "Rock_Shale_Brick",
      "rotation": 2
    },
    {
      "x": -7,
      "y": 10,
      "z": 1,
      "name": "Rock_Shale_Brick_Roof"
    },
    {
      "x": -7,
      "y": 2,
      "z": 2,
      "name": "Rock_Slate"
    },
    {
      "x": -7,
      "y": 3,
      "z": 2,
      "name": "Rock_Slate"
    },
    {
      "x": -7,
      "y": 4,
      "z": 2,
      "name": "Rock_Slate"
    },
    {
      "x": -7,
      "y": 5,
      "z": 2,
      "name": "Rock_Shale_Brick"
    },
    {
      "x": -7,
      "y": 6,
      "z": 2,
      "name": "Rock_Shale_Brick_Roof",
      "rotation": 3
    },
    {
      "x": -7,
      "y": 8,
      "z": 2,
      "name": "Rock_Shale_Cobble_Stairs",
      "rotation": 10
    },
    {
      "x": -7,
      "y": 9,
      "z": 2,
      "name": "Rock_Shale_Brick",
      "rotation": 2
    },
    {
      "x": -7,
      "y": 10,
      "z": 2,
      "name": "Rock_Shale_Brick_Roof_Flat",
      "rotation": 1
    },
    {
      "x": -7,
      "y": 3,
      "z": 3,
      "name": "Rock_Slate"
    },
    {
      "x": -7,
      "y": 4,
      "z": 3,
      "name": "Rock_Slate"
    },
    {
      "x": -7,
      "y": 5,
      "z": 3,
      "name": "Rock_Shale_Brick_Wall",
      "rotation": 1
    },
    {
      "x": -7,
      "y": 9,
      "z": 3,
      "name": "Rock_Shale_Brick",
      "rotation": 2
    },
    {
      "x": -7,
      "y": 10,
      "z": 3,
      "name": "Rock_Shale_Brick_Roof_Flat",
      "rotation": 1
    },
    {
      "x": -7,
      "y": 2,
      "z": 4,
      "name": "Rock_Slate"
    },
    {
      "x": -7,
      "y": 3,
      "z": 4,
      "name": "Rock_Slate"
    },
    {
      "x": -7,
      "y": 4,
      "z": 4,
      "name": "Rock_Slate"
    },
    {
      "x": -7,
      "y": 5,
      "z": 4,
      "name": "Rock_Shale_Brick_Decorative"
    },
    {
      "x": -7,
      "y": 6,
      "z": 4,
      "name": "Rock_Shale_Brick_Beam"
    },
    {
      "x": -7,
      "y": 7,
      "z": 4,
      "name": "Rock_Shale_Brick_Beam"
    },
    {
      "x": -7,
      "y": 8,
      "z": 4,
      "name": "Rock_Shale_Brick_Decorative"
    },
    {
      "x": -7,
      "y": 9,
      "z": 4,
      "name": "Rock_Shale_Brick",
      "rotation": 2
    },
    {
      "x": -7,
      "y": 10,
      "z": 4,
      "name": "Rock_Shale_Brick_Roof_Flat",
      "rotation": 1
    },
    {
      "x": -7,
      "y": 3,
      "z": 5,
      "name": "Rock_Slate"
    },
    {
      "x": -7,
      "y": 4,
      "z": 5,
      "name": "Rock_Shale_Brick"
    },
    {
      "x": -7,
      "y": 9,
      "z": 5,
      "name": "Rock_Shale_Brick_Stairs",
      "rotation": 9
    },
    {
      "x": -7,
      "y": 10,
      "z": 5,
      "name": "Rock_Shale_Brick_Roof_Flat",
      "rotation": 1
    },
    {
      "x": -7,
      "y": 3,
      "z": 6,
      "name": "Rock_Slate"
    },
    {
      "x": -7,
      "y": 4,
      "z": 6,
      "name": "Rock_Slate"
    },
    {
      "x": -7,
      "y": 5,
      "z": 6,
      "name": "Rock_Shale_Brick_Decorative"
    },
    {
      "x": -7,
      "y": 6,
      "z": 6,
      "name": "Rock_Shale_Brick_Beam"
    },
    {
      "x": -7,
      "y": 7,
      "z": 6,
      "name": "Rock_Shale_Brick_Beam"
    },
    {
      "x": -7,
      "y": 8,
      "z": 6,
      "name": "Rock_Shale_Brick_Decorative"
    },
    {
      "x": -7,
      "y": 9,
      "z": 6,
      "name": "Rock_Shale_Brick",
      "rotation": 2
    },
    {
      "x": -7,
      "y": 10,
      "z": 6,
      "name": "Rock_Shale_Brick_Roof_Flat",
      "rotation": 1
    },
    {
      "x": -7,
      "y": 2,
      "z": 7,
      "name": "Rock_Slate"
    },
    {
      "x": -7,
      "y": 3,
      "z": 7,
      "name": "Rock_Slate"
    },
    {
      "x": -7,
      "y": 4,
      "z": 7,
      "name": "Rock_Slate"
    },
    {
      "x": -7,
      "y": 5,
      "z": 7,
      "name": "Rock_Shale_Brick_Wall",
      "rotation": 1
    },
    {
      "x": -7,
      "y": 9,
      "z": 7,
      "name": "Rock_Shale_Brick",
      "rotation": 2
    },
    {
      "x": -7,
      "y": 2,
      "z": 8,
      "name": "Rock_Slate"
    },
    {
      "x": -7,
      "y": 3,
      "z": 8,
      "name": "Rock_Slate"
    },
    {
      "x": -7,
      "y": 4,
      "z": 8,
      "name": "Rock_Slate"
    },
    {
      "x": -7,
      "y": 5,
      "z": 8,
      "name": "Rock_Shale_Brick"
    },
    {
      "x": -7,
      "y": 6,
      "z": 8,
      "name": "Rock_Shale_Brick_Roof",
      "rotation": 3
    },
    {
      "x": -7,
      "y": 8,
      "z": 8,
      "name": "Rock_Shale_Cobble_Stairs",
      "rotation": 8
    },
    {
      "x": -7,
      "y": 2,
      "z": 9,
      "name": "Rock_Slate"
    },
    {
      "x": -7,
      "y": 3,
      "z": 9,
      "name": "Rock_Slate"
    },
    {
      "x": -7,
      "y": 4,
      "z": 9,
      "name": "Rock_Slate"
    },
    {
      "x": -7,
      "y": 5,
      "z": 9,
      "name": "Rock_Shale_Brick",
      "rotation": 2
    },
    {
      "x": -7,
      "y": 6,
      "z": 9,
      "name": "Rock_Shale_Brick",
      "rotation": 3
    },
    {
      "x": -7,
      "y": 7,
      "z": 9,
      "name": "Rock_Shale_Brick",
      "rotation": 3
    },
    {
      "x": -7,
      "y": 8,
      "z": 9,
      "name": "Rock_Shale_Brick",
      "rotation": 3
    },
    {
      "x": -7,
      "y": 2,
      "z": 10,
      "name": "Rock_Slate"
    },
    {
      "x": -7,
      "y": 3,
      "z": 10,
      "name": "Rock_Slate"
    },
    {
      "x": -7,
      "y": 4,
      "z": 10,
      "name": "Rock_Slate"
    },
    {
      "x": -7,
      "y": 5,
      "z": 10,
      "name": "Rock_Shale_Brick",
      "rotation": 2
    },
    {
      "x": -7,
      "y": 6,
      "z": 10,
      "name": "Rock_Shale_Brick_Ornate",
      "rotation": 3
    },
    {
      "x": -7,
      "y": 7,
      "z": 10,
      "name": "Rock_Shale_Brick_Pillar_Base",
      "rotation": 3
    },
    {
      "x": -7,
      "y": 8,
      "z": 10,
      "name": "Rock_Shale_Brick_Pillar_Middle",
      "rotation": 3
    },
    {
      "x": -7,
      "y": 2,
      "z": 11,
      "name": "Rock_Slate"
    },
    {
      "x": -7,
      "y": 3,
      "z": 11,
      "name": "Rock_Slate"
    },
    {
      "x": -7,
      "y": 4,
      "z": 11,
      "name": "Rock_Slate"
    },
    {
      "x": -7,
      "y": 2,
      "z": 12,
      "name": "Rock_Slate"
    },
    {
      "x": -7,
      "y": 3,
      "z": 12,
      "name": "Rock_Slate"
    },
    {
      "x": -7,
      "y": 4,
      "z": 12,
      "name": "Rock_Slate"
    },
    {
      "x": -6,
      "y": 2,
      "z": -13,
      "name": "Rock_Slate"
    },
    {
      "x": -6,
      "y": 3,
      "z": -13,
      "name": "Rock_Slate"
    },
    {
      "x": -6,
      "y": 4,
      "z": -13,
      "name": "Rock_Slate"
    },
    {
      "x": -6,
      "y": 2,
      "z": -12,
      "name": "Rock_Slate"
    },
    {
      "x": -6,
      "y": 3,
      "z": -12,
      "name": "Rock_Slate"
    },
    {
      "x": -6,
      "y": 4,
      "z": -12,
      "name": "Rock_Slate"
    },
    {
      "x": -6,
      "y": 2,
      "z": -11,
      "name": "Rock_Slate"
    },
    {
      "x": -6,
      "y": 3,
      "z": -11,
      "name": "Rock_Slate"
    },
    {
      "x": -6,
      "y": 4,
      "z": -11,
      "name": "Rock_Slate"
    },
    {
      "x": -6,
      "y": 1,
      "z": -10,
      "name": "Rock_Slate_Cobble"
    },
    {
      "x": -6,
      "y": 2,
      "z": -10,
      "name": "Rock_Slate"
    },
    {
      "x": -6,
      "y": 3,
      "z": -10,
      "name": "Rock_Slate"
    },
    {
      "x": -6,
      "y": 4,
      "z": -10,
      "name": "Rock_Slate"
    },
    {
      "x": -6,
      "y": 5,
      "z": -10,
      "name": "Rock_Shale_Brick"
    },
    {
      "x": -6,
      "y": 6,
      "z": -10,
      "name": "Rock_Shale_Brick_Roof",
      "rotation": 2
    },
    {
      "x": -6,
      "y": 9,
      "z": -10,
      "name": "Rock_Shale_Brick"
    },
    {
      "x": -6,
      "y": 10,
      "z": -10,
      "name": "Rock_Shale_Brick_Roof_Flat",
      "rotation": 2
    },
    {
      "x": -6,
      "y": 2,
      "z": -9,
      "name": "Rock_Slate"
    },
    {
      "x": -6,
      "y": 3,
      "z": -9,
      "name": "Rock_Slate"
    },
    {
      "x": -6,
      "y": 4,
      "z": -9,
      "name": "Rock_Slate"
    },
    {
      "x": -6,
      "y": 9,
      "z": -9,
      "name": "Rock_Shale_Brick"
    },
    {
      "x": -6,
      "y": 2,
      "z": -8,
      "name": "Rock_Slate"
    },
    {
      "x": -6,
      "y": 3,
      "z": -8,
      "name": "Rock_Slate"
    },
    {
      "x": -6,
      "y": 4,
      "z": -8,
      "name": "Rock_Slate"
    },
    {
      "x": -6,
      "y": 5,
      "z": -8,
      "name": "Rock_Slate_Cobble"
    },
    {
      "x": -6,
      "y": 8,
      "z": -8,
      "name": "Rock_Slate_Cobble"
    },
    {
      "x": -6,
      "y": 9,
      "z": -8,
      "name": "Rock_Shale_Brick"
    },
    {
      "x": -6,
      "y": 2,
      "z": -7,
      "name": "Rock_Slate"
    },
    {
      "x": -6,
      "y": 3,
      "z": -7,
      "name": "Rock_Slate"
    },
    {
      "x": -6,
      "y": 4,
      "z": -7,
      "name": "Rock_Slate"
    },
    {
      "x": -6,
      "y": 5,
      "z": -7,
      "name": "Rock_Slate_Cobble"
    },
    {
      "x": -6,
      "y": 6,
      "z": -7,
      "name": "Rock_Slate_Cobble"
    },
    {
      "x": -6,
      "y": 7,
      "z": -7,
      "name": "Rock_Slate_Cobble"
    },
    {
      "x": -6,
      "y": 8,
      "z": -7,
      "name": "Rock_Slate_Cobble"
    },
    {
      "x": -6,
      "y": 9,
      "z": -7,
      "name": "Rock_Shale_Brick"
    },
    {
      "x": -6,
      "y": 2,
      "z": -6,
      "name": "Rock_Slate"
    },
    {
      "x": -6,
      "y": 3,
      "z": -6,
      "name": "Rock_Slate"
    },
    {
      "x": -6,
      "y": 4,
      "z": -6,
      "name": "Rock_Slate"
    },
    {
      "x": -6,
      "y": 5,
      "z": -6,
      "name": "Rock_Slate_Cobble"
    },
    {
      "x": -6,
      "y": 7,
      "z": -6,
      "name": "Rock_Slate_Cobble"
    },
    {
      "x": -6,
      "y": 8,
      "z": -6,
      "name": "Rock_Slate_Cobble"
    },
    {
      "x": -6,
      "y": 9,
      "z": -6,
      "name": "Rock_Shale_Brick"
    },
    {
      "x": -6,
      "y": 3,
      "z": -5,
      "name": "Rock_Slate"
    },
    {
      "x": -6,
      "y": 4,
      "z": -5,
      "name": "Rock_Slate"
    },
    {
      "x": -6,
      "y": 5,
      "z": -5,
      "name": "Rock_Slate_Cobble"
    },
    {
      "x": -6,
      "y": 8,
      "z": -5,
      "name": "Rock_Slate_Cobble"
    },
    {
      "x": -6,
      "y": 9,
      "z": -5,
      "name": "Rock_Shale_Brick"
    },
    {
      "x": -6,
      "y": 2,
      "z": -4,
      "name": "Rock_Slate"
    },
    {
      "x": -6,
      "y": 3,
      "z": -4,
      "name": "Rock_Slate"
    },
    {
      "x": -6,
      "y": 4,
      "z": -4,
      "name": "Rock_Slate"
    },
    {
      "x": -6,
      "y": 5,
      "z": -4,
      "name": "Rock_Slate_Cobble"
    },
    {
      "x": -6,
      "y": 8,
      "z": -4,
      "name": "Rock_Slate_Cobble"
    },
    {
      "x": -6,
      "y": 9,
      "z": -4,
      "name": "Rock_Shale_Brick"
    },
    {
      "x": -6,
      "y": 2,
      "z": -3,
      "name": "Rock_Slate"
    },
    {
      "x": -6,
      "y": 3,
      "z": -3,
      "name": "Rock_Slate"
    },
    {
      "x": -6,
      "y": 4,
      "z": -3,
      "name": "Rock_Slate"
    },
    {
      "x": -6,
      "y": 5,
      "z": -3,
      "name": "Rock_Slate_Cobble"
    },
    {
      "x": -6,
      "y": 6,
      "z": -3,
      "name": "Rock_Slate_Cobble"
    },
    {
      "x": -6,
      "y": 9,
      "z": -3,
      "name": "Rock_Shale_Brick"
    },
    {
      "x": -6,
      "y": 2,
      "z": -2,
      "name": "Rock_Slate"
    },
    {
      "x": -6,
      "y": 3,
      "z": -2,
      "name": "Rock_Slate"
    },
    {
      "x": -6,
      "y": 4,
      "z": -2,
      "name": "Rock_Slate"
    },
    {
      "x": -6,
      "y": 5,
      "z": -2,
      "name": "Rock_Slate_Cobble"
    },
    {
      "x": -6,
      "y": 6,
      "z": -2,
      "name": "Rock_Slate_Cobble"
    },
    {
      "x": -6,
      "y": 9,
      "z": -2,
      "name": "Rock_Shale_Brick"
    },
    {
      "x": -6,
      "y": 2,
      "z": -1,
      "name": "Rock_Slate"
    },
    {
      "x": -6,
      "y": 3,
      "z": -1,
      "name": "Rock_Slate"
    },
    {
      "x": -6,
      "y": 4,
      "z": -1,
      "name": "Rock_Slate"
    },
    {
      "x": -6,
      "y": 5,
      "z": -1,
      "name": "Rock_Slate_Cobble"
    },
    {
      "x": -6,
      "y": 6,
      "z": -1,
      "name": "Rock_Slate_Cobble"
    },
    {
      "x": -6,
      "y": 7,
      "z": -1,
      "name": "Rock_Slate_Cobble"
    },
    {
      "x": -6,
      "y": 8,
      "z": -1,
      "name": "Rock_Slate_Cobble"
    },
    {
      "x": -6,
      "y": 9,
      "z": -1,
      "name": "Rock_Shale_Brick"
    },
    {
      "x": -6,
      "y": 10,
      "z": -1,
      "name": "Rock_Shale_Brick"
    },
    {
      "x": -6,
      "y": 11,
      "z": -1,
      "name": "Rock_Shale_Brick"
    },
    {
      "x": -6,
      "y": 2,
      "z": 0,
      "name": "Rock_Slate"
    },
    {
      "x": -6,
      "y": 3,
      "z": 0,
      "name": "Rock_Slate"
    },
    {
      "x": -6,
      "y": 4,
      "z": 0,
      "name": "Rock_Slate"
    },
    {
      "x": -6,
      "y": 5,
      "z": 0,
      "name": "Rock_Slate_Cobble"
    },
    {
      "x": -6,
      "y": 6,
      "z": 0,
      "name": "Rock_Slate_Cobble"
    },
    {
      "x": -6,
      "y": 7,
      "z": 0,
      "name": "Rock_Slate_Cobble"
    },
    {
      "x": -6,
      "y": 8,
      "z": 0,
      "name": "Rock_Slate_Cobble"
    },
    {
      "x": -6,
      "y": 9,
      "z": 0,
      "name": "Rock_Shale_Brick"
    },
    {
      "x": -6,
      "y": 10,
      "z": 0,
      "name": "Rock_Shale_Brick"
    },
    {
      "x": -6,
      "y": 11,
      "z": 0,
      "name": "Rock_Shale_Brick"
    },
    {
      "x": -6,
      "y": 2,
      "z": 1,
      "name": "Rock_Slate"
    },
    {
      "x": -6,
      "y": 3,
      "z": 1,
      "name": "Rock_Slate"
    },
    {
      "x": -6,
      "y": 4,
      "z": 1,
      "name": "Rock_Slate"
    },
    {
      "x": -6,
      "y": 5,
      "z": 1,
      "name": "Rock_Slate_Cobble"
    },
    {
      "x": -6,
      "y": 6,
      "z": 1,
      "name": "Rock_Slate_Cobble"
    },
    {
      "x": -6,
      "y": 7,
      "z": 1,
      "name": "Rock_Slate_Cobble"
    },
    {
      "x": -6,
      "y": 8,
      "z": 1,
      "name": "Rock_Slate_Cobble"
    },
    {
      "x": -6,
      "y": 9,
      "z": 1,
      "name": "Rock_Shale_Brick"
    },
    {
      "x": -6,
      "y": 3,
      "z": 2,
      "name": "Rock_Slate"
    },
    {
      "x": -6,
      "y": 4,
      "z": 2,
      "name": "Rock_Slate"
    },
    {
      "x": -6,
      "y": 5,
      "z": 2,
      "name": "Rock_Slate_Cobble"
    },
    {
      "x": -6,
      "y": 6,
      "z": 2,
      "name": "Rock_Slate_Cobble"
    },
    {
      "x": -6,
      "y": 7,
      "z": 2,
      "name": "Rock_Slate_Cobble"
    },
    {
      "x": -6,
      "y": 8,
      "z": 2,
      "name": "Rock_Slate_Cobble"
    },
    {
      "x": -6,
      "y": 9,
      "z": 2,
      "name": "Rock_Shale_Brick"
    },
    {
      "x": -6,
      "y": 4,
      "z": 3,
      "name": "Rock_Slate"
    },
    {
      "x": -6,
      "y": 5,
      "z": 3,
      "name": "Rock_Slate_Cobble"
    },
    {
      "x": -6,
      "y": 6,
      "z": 3,
      "name": "Rock_Slate_Cobble"
    },
    {
      "x": -6,
      "y": 9,
      "z": 3,
      "name": "Rock_Shale_Brick"
    },
    {
      "x": -6,
      "y": 2,
      "z": 4,
      "name": "Rock_Slate"
    },
    {
      "x": -6,
      "y": 3,
      "z": 4,
      "name": "Rock_Slate"
    },
    {
      "x": -6,
      "y": 4,
      "z": 4,
      "name": "Rock_Slate"
    },
    {
      "x": -6,
      "y": 5,
      "z": 4,
      "name": "Rock_Slate_Cobble"
    },
    {
      "x": -6,
      "y": 6,
      "z": 4,
      "name": "Rock_Slate_Cobble"
    },
    {
      "x": -6,
      "y": 9,
      "z": 4,
      "name": "Rock_Shale_Brick"
    },
    {
      "x": -6,
      "y": 2,
      "z": 5,
      "name": "Rock_Slate"
    },
    {
      "x": -6,
      "y": 3,
      "z": 5,
      "name": "Rock_Slate"
    },
    {
      "x": -6,
      "y": 4,
      "z": 5,
      "name": "Rock_Slate"
    },
    {
      "x": -6,
      "y": 5,
      "z": 5,
      "name": "Rock_Slate_Cobble"
    },
    {
      "x": -6,
      "y": 9,
      "z": 5,
      "name": "Rock_Shale_Brick"
    },
    {
      "x": -6,
      "y": 3,
      "z": 6,
      "name": "Rock_Slate"
    },
    {
      "x": -6,
      "y": 4,
      "z": 6,
      "name": "Rock_Slate"
    },
    {
      "x": -6,
      "y": 9,
      "z": 6,
      "name": "Rock_Shale_Brick"
    },
    {
      "x": -6,
      "y": 3,
      "z": 7,
      "name": "Rock_Slate"
    },
    {
      "x": -6,
      "y": 4,
      "z": 7,
      "name": "Rock_Slate"
    },
    {
      "x": -6,
      "y": 5,
      "z": 7,
      "name": "Rock_Slate_Cobble"
    },
    {
      "x": -6,
      "y": 6,
      "z": 7,
      "name": "Rock_Slate_Stalactite_Small"
    },
    {
      "x": -6,
      "y": 4,
      "z": 8,
      "name": "Rock_Slate"
    },
    {
      "x": -6,
      "y": 5,
      "z": 8,
      "name": "Rock_Slate_Cobble"
    },
    {
      "x": -6,
      "y": 6,
      "z": 8,
      "name": "Rock_Slate_Cobble"
    },
    {
      "x": -6,
      "y": 7,
      "z": 8,
      "name": "Rock_Slate_Cobble"
    },
    {
      "x": -6,
      "y": 2,
      "z": 9,
      "name": "Rock_Slate"
    },
    {
      "x": -6,
      "y": 3,
      "z": 9,
      "name": "Rock_Slate"
    },
    {
      "x": -6,
      "y": 4,
      "z": 9,
      "name": "Rock_Slate"
    },
    {
      "x": -6,
      "y": 5,
      "z": 9,
      "name": "Rock_Shale_Brick"
    },
    {
      "x": -6,
      "y": 6,
      "z": 9,
      "name": "Rock_Shale_Brick_Roof"
    },
    {
      "x": -6,
      "y": 2,
      "z": 10,
      "name": "Rock_Slate"
    },
    {
      "x": -6,
      "y": 3,
      "z": 10,
      "name": "Rock_Slate"
    },
    {
      "x": -6,
      "y": 4,
      "z": 10,
      "name": "Rock_Slate"
    },
    {
      "x": -6,
      "y": 2,
      "z": 11,
      "name": "Rock_Slate"
    },
    {
      "x": -6,
      "y": 3,
      "z": 11,
      "name": "Rock_Slate"
    },
    {
      "x": -6,
      "y": 4,
      "z": 11,
      "name": "Rock_Slate"
    },
    {
      "x": -6,
      "y": 3,
      "z": 12,
      "name": "Rock_Slate"
    },
    {
      "x": -6,
      "y": 4,
      "z": 12,
      "name": "Rock_Slate"
    },
    {
      "x": -5,
      "y": 3,
      "z": -13,
      "name": "Rock_Slate"
    },
    {
      "x": -5,
      "y": 1,
      "z": -12,
      "name": "Rock_Slate_Cobble"
    },
    {
      "x": -5,
      "y": 2,
      "z": -12,
      "name": "Rock_Slate"
    },
    {
      "x": -5,
      "y": 3,
      "z": -12,
      "name": "Rock_Slate"
    },
    {
      "x": -5,
      "y": 4,
      "z": -12,
      "name": "Rock_Slate"
    },
    {
      "x": -5,
      "y": 1,
      "z": -11,
      "name": "Rock_Slate"
    },
    {
      "x": -5,
      "y": 2,
      "z": -11,
      "name": "Rock_Slate"
    },
    {
      "x": -5,
      "y": 3,
      "z": -11,
      "name": "Rock_Slate"
    },
    {
      "x": -5,
      "y": 4,
      "z": -11,
      "name": "Rock_Slate"
    },
    {
      "x": -5,
      "y": 1,
      "z": -10,
      "name": "Rock_Slate"
    },
    {
      "x": -5,
      "y": 2,
      "z": -10,
      "name": "Rock_Slate"
    },
    {
      "x": -5,
      "y": 3,
      "z": -10,
      "name": "Rock_Slate"
    },
    {
      "x": -5,
      "y": 4,
      "z": -10,
      "name": "Rock_Slate"
    },
    {
      "x": -5,
      "y": 5,
      "z": -10,
      "name": "Rock_Shale_Brick_Wall"
    },
    {
      "x": -5,
      "y": 9,
      "z": -10,
      "name": "Rock_Shale_Brick"
    },
    {
      "x": -5,
      "y": 10,
      "z": -10,
      "name": "Rock_Shale_Brick_Roof_Flat",
      "rotation": 2
    },
    {
      "x": -5,
      "y": 2,
      "z": -9,
      "name": "Rock_Slate"
    },
    {
      "x": -5,
      "y": 3,
      "z": -9,
      "name": "Rock_Slate"
    },
    {
      "x": -5,
      "y": 4,
      "z": -9,
      "name": "Rock_Slate"
    },
    {
      "x": -5,
      "y": 5,
      "z": -9,
      "name": "Rock_Slate_Cobble"
    },
    {
      "x": -5,
      "y": 9,
      "z": -9,
      "name": "Rock_Shale_Brick"
    },
    {
      "x": -5,
      "y": 2,
      "z": -8,
      "name": "Rock_Slate"
    },
    {
      "x": -5,
      "y": 3,
      "z": -8,
      "name": "Rock_Slate"
    },
    {
      "x": -5,
      "y": 4,
      "z": -8,
      "name": "Rock_Slate"
    },
    {
      "x": -5,
      "y": 9,
      "z": -8,
      "name": "Rock_Shale_Brick"
    },
    {
      "x": -5,
      "y": 10,
      "z": -8,
      "name": "*Rock_Slate_Cobble_Roof_Shallow_State_Definitions_Corner_Left",
      "rotation": 2
    },
    {
      "x": -5,
      "y": 2,
      "z": -7,
      "name": "Rock_Slate"
    },
    {
      "x": -5,
      "y": 3,
      "z": -7,
      "name": "Rock_Slate"
    },
    {
      "x": -5,
      "y": 4,
      "z": -7,
      "name": "Rock_Slate"
    },
    {
      "x": -5,
      "y": 5,
      "z": -7,
      "name": "Rubble_Slate"
    },
    {
      "x": -5,
      "y": 9,
      "z": -7,
      "name": "Rock_Shale_Brick"
    },
    {
      "x": -5,
      "y": 10,
      "z": -7,
      "name": "*Rock_Slate_Cobble_Roof_Shallow_State_Definitions_Corner_Left",
      "filler": 32,
      "rotation": 2
    },
    {
      "x": -5,
      "y": 2,
      "z": -6,
      "name": "Rock_Slate"
    },
    {
      "x": -5,
      "y": 3,
      "z": -6,
      "name": "Rock_Slate"
    },
    {
      "x": -5,
      "y": 4,
      "z": -6,
      "name": "Rock_Slate"
    },
    {
      "x": -5,
      "y": 5,
      "z": -6,
      "name": "Rubble_Slate_Medium"
    },
    {
      "x": -5,
      "y": 9,
      "z": -6,
      "name": "Rock_Shale_Brick"
    },
    {
      "x": -5,
      "y": 10,
      "z": -6,
      "name": "Rock_Slate_Cobble_Roof_Shallow",
      "rotation": 3
    },
    {
      "x": -5,
      "y": 2,
      "z": -5,
      "name": "Rock_Slate"
    },
    {
      "x": -5,
      "y": 3,
      "z": -5,
      "name": "Rock_Slate"
    },
    {
      "x": -5,
      "y": 4,
      "z": -5,
      "name": "Rock_Slate"
    },
    {
      "x": -5,
      "y": 9,
      "z": -5,
      "name": "Rock_Shale_Brick"
    },
    {
      "x": -5,
      "y": 10,
      "z": -5,
      "name": "Rock_Slate_Cobble_Roof_Shallow",
      "rotation": 3
    },
    {
      "x": -5,
      "y": 4,
      "z": -4,
      "name": "Rock_Slate"
    },
    {
      "x": -5,
      "y": 9,
      "z": -4,
      "name": "Rock_Shale_Brick"
    },
    {
      "x": -5,
      "y": 10,
      "z": -4,
      "name": "Rock_Slate_Cobble_Roof_Shallow",
      "rotation": 3
    },
    {
      "x": -5,
      "y": 2,
      "z": -3,
      "name": "Rock_Slate"
    },
    {
      "x": -5,
      "y": 3,
      "z": -3,
      "name": "Rock_Slate"
    },
    {
      "x": -5,
      "y": 4,
      "z": -3,
      "name": "Rock_Slate"
    },
    {
      "x": -5,
      "y": 9,
      "z": -3,
      "name": "Rock_Shale_Brick"
    },
    {
      "x": -5,
      "y": 10,
      "z": -3,
      "name": "Rock_Slate_Cobble_Roof_Shallow",
      "rotation": 3
    },
    {
      "x": -5,
      "y": 2,
      "z": -2,
      "name": "Rock_Slate"
    },
    {
      "x": -5,
      "y": 3,
      "z": -2,
      "name": "Rock_Slate"
    },
    {
      "x": -5,
      "y": 4,
      "z": -2,
      "name": "Rock_Slate"
    },
    {
      "x": -5,
      "y": 9,
      "z": -2,
      "name": "Rock_Shale_Brick"
    },
    {
      "x": -5,
      "y": 10,
      "z": -2,
      "name": "Rock_Slate_Cobble_Roof_Shallow",
      "rotation": 3
    },
    {
      "x": -5,
      "y": 2,
      "z": -1,
      "name": "Rock_Slate"
    },
    {
      "x": -5,
      "y": 3,
      "z": -1,
      "name": "Rock_Slate"
    },
    {
      "x": -5,
      "y": 4,
      "z": -1,
      "name": "Rock_Shale_Brick_Smooth"
    },
    {
      "x": -5,
      "y": 5,
      "z": -1,
      "name": "Rubble_Slate_Medium"
    },
    {
      "x": -5,
      "y": 9,
      "z": -1,
      "name": "Rock_Shale_Brick"
    },
    {
      "x": -5,
      "y": 10,
      "z": -1,
      "name": "Rock_Shale_Brick"
    },
    {
      "x": -5,
      "y": 11,
      "z": -1,
      "name": "Rock_Shale_Brick"
    },
    {
      "x": -5,
      "y": 2,
      "z": 0,
      "name": "Rock_Slate"
    },
    {
      "x": -5,
      "y": 3,
      "z": 0,
      "name": "Rock_Slate"
    },
    {
      "x": -5,
      "y": 4,
      "z": 0,
      "name": "Rock_Slate"
    },
    {
      "x": -5,
      "y": 5,
      "z": 0,
      "name": "Rock_Slate_Cobble"
    },
    {
      "x": -5,
      "y": 9,
      "z": 0,
      "name": "Rock_Shale_Brick"
    },
    {
      "x": -5,
      "y": 10,
      "z": 0,
      "name": "Rock_Shale_Brick"
    },
    {
      "x": -5,
      "y": 11,
      "z": 0,
      "name": "Rock_Shale_Brick"
    },
    {
      "x": -5,
      "y": 2,
      "z": 1,
      "name": "Rock_Slate"
    },
    {
      "x": -5,
      "y": 3,
      "z": 1,
      "name": "Rock_Slate"
    },
    {
      "x": -5,
      "y": 4,
      "z": 1,
      "name": "Rock_Slate"
    },
    {
      "x": -5,
      "y": 5,
      "z": 1,
      "name": "Rock_Slate_Cobble"
    },
    {
      "x": -5,
      "y": 6,
      "z": 1,
      "name": "Rock_Slate_Cobble"
    },
    {
      "x": -5,
      "y": 9,
      "z": 1,
      "name": "Rock_Shale_Brick"
    },
    {
      "x": -5,
      "y": 10,
      "z": 1,
      "name": "Rock_Slate_Cobble_Roof_Shallow",
      "rotation": 3
    },
    {
      "x": -5,
      "y": 2,
      "z": 2,
      "name": "Rock_Slate"
    },
    {
      "x": -5,
      "y": 3,
      "z": 2,
      "name": "Rock_Slate"
    },
    {
      "x": -5,
      "y": 4,
      "z": 2,
      "name": "Rock_Slate"
    },
    {
      "x": -5,
      "y": 5,
      "z": 2,
      "name": "Rock_Slate_Stalactite_Large"
    },
    {
      "x": -5,
      "y": 6,
      "z": 2,
      "name": "Rock_Slate_Stalactite_Large",
      "filler": 1024
    },
    {
      "x": -5,
      "y": 9,
      "z": 2,
      "name": "Rock_Shale_Brick"
    },
    {
      "x": -5,
      "y": 10,
      "z": 2,
      "name": "Rock_Slate_Cobble_Roof_Shallow",
      "rotation": 3
    },
    {
      "x": -5,
      "y": 3,
      "z": 3,
      "name": "Rock_Slate"
    },
    {
      "x": -5,
      "y": 4,
      "z": 3,
      "name": "Rock_Slate"
    },
    {
      "x": -5,
      "y": 9,
      "z": 3,
      "name": "Rock_Shale_Brick"
    },
    {
      "x": -5,
      "y": 10,
      "z": 3,
      "name": "Rock_Slate_Cobble_Roof_Shallow",
      "rotation": 3
    },
    {
      "x": -5,
      "y": 2,
      "z": 4,
      "name": "Rock_Slate"
    },
    {
      "x": -5,
      "y": 3,
      "z": 4,
      "name": "Rock_Slate"
    },
    {
      "x": -5,
      "y": 4,
      "z": 4,
      "name": "Rock_Slate"
    },
    {
      "x": -5,
      "y": 9,
      "z": 4,
      "name": "Rock_Shale_Brick"
    },
    {
      "x": -5,
      "y": 10,
      "z": 4,
      "name": "Rock_Slate_Cobble_Roof_Shallow",
      "rotation": 3
    },
    {
      "x": -5,
      "y": 2,
      "z": 5,
      "name": "Rock_Slate"
    },
    {
      "x": -5,
      "y": 3,
      "z": 5,
      "name": "Rock_Slate"
    },
    {
      "x": -5,
      "y": 4,
      "z": 5,
      "name": "Rock_Slate"
    },
    {
      "x": -5,
      "y": 9,
      "z": 5,
      "name": "Rock_Shale_Brick_Smooth_Half"
    },
    {
      "x": -5,
      "y": 2,
      "z": 6,
      "name": "Rock_Slate"
    },
    {
      "x": -5,
      "y": 3,
      "z": 6,
      "name": "Rock_Slate"
    },
    {
      "x": -5,
      "y": 4,
      "z": 6,
      "name": "Rock_Slate"
    },
    {
      "x": -5,
      "y": 2,
      "z": 7,
      "name": "Rock_Slate"
    },
    {
      "x": -5,
      "y": 3,
      "z": 7,
      "name": "Rock_Slate"
    },
    {
      "x": -5,
      "y": 4,
      "z": 7,
      "name": "Rock_Slate"
    },
    {
      "x": -5,
      "y": 2,
      "z": 8,
      "name": "Rock_Slate"
    },
    {
      "x": -5,
      "y": 3,
      "z": 8,
      "name": "Rock_Slate"
    },
    {
      "x": -5,
      "y": 4,
      "z": 8,
      "name": "Rock_Slate"
    },
    {
      "x": -5,
      "y": 5,
      "z": 8,
      "name": "Rock_Slate_Cobble"
    },
    {
      "x": -5,
      "y": 6,
      "z": 8,
      "name": "Rock_Slate_Cobble"
    },
    {
      "x": -5,
      "y": 3,
      "z": 9,
      "name": "Rock_Slate"
    },
    {
      "x": -5,
      "y": 4,
      "z": 9,
      "name": "Rock_Slate"
    },
    {
      "x": -5,
      "y": 5,
      "z": 9,
      "name": "Rock_Shale_Brick_Wall"
    },
    {
      "x": -5,
      "y": 9,
      "z": 9,
      "name": "Rock_Shale_Brick"
    },
    {
      "x": -5,
      "y": 3,
      "z": 10,
      "name": "Rock_Slate"
    },
    {
      "x": -5,
      "y": 4,
      "z": 10,
      "name": "Rock_Slate"
    },
    {
      "x": -5,
      "y": 2,
      "z": 11,
      "name": "Rock_Slate"
    },
    {
      "x": -5,
      "y": 3,
      "z": 11,
      "name": "Rock_Slate"
    },
    {
      "x": -5,
      "y": 4,
      "z": 11,
      "name": "Rock_Slate"
    },
    {
      "x": -5,
      "y": 3,
      "z": 12,
      "name": "Rock_Slate"
    },
    {
      "x": -5,
      "y": 4,
      "z": 12,
      "name": "Rock_Slate"
    },
    {
      "x": -4,
      "y": 2,
      "z": -13,
      "name": "Rock_Slate_Cobble"
    },
    {
      "x": -4,
      "y": 3,
      "z": -13,
      "name": "Rock_Slate"
    },
    {
      "x": -4,
      "y": 2,
      "z": -12,
      "name": "Rock_Slate"
    },
    {
      "x": -4,
      "y": 3,
      "z": -12,
      "name": "Rock_Slate"
    },
    {
      "x": -4,
      "y": 4,
      "z": -12,
      "name": "Rock_Slate"
    },
    {
      "x": -4,
      "y": 1,
      "z": -11,
      "name": "Rock_Slate"
    },
    {
      "x": -4,
      "y": 2,
      "z": -11,
      "name": "Rock_Slate"
    },
    {
      "x": -4,
      "y": 3,
      "z": -11,
      "name": "Rock_Slate"
    },
    {
      "x": -4,
      "y": 4,
      "z": -11,
      "name": "Rock_Slate"
    },
    {
      "x": -4,
      "y": 1,
      "z": -10,
      "name": "Rock_Slate"
    },
    {
      "x": -4,
      "y": 2,
      "z": -10,
      "name": "Rock_Slate"
    },
    {
      "x": -4,
      "y": 3,
      "z": -10,
      "name": "Rock_Slate"
    },
    {
      "x": -4,
      "y": 4,
      "z": -10,
      "name": "Rock_Slate"
    },
    {
      "x": -4,
      "y": 5,
      "z": -10,
      "name": "Rock_Shale_Brick_Decorative"
    },
    {
      "x": -4,
      "y": 6,
      "z": -10,
      "name": "Rock_Shale_Brick_Beam"
    },
    {
      "x": -4,
      "y": 7,
      "z": -10,
      "name": "Rock_Shale_Brick_Beam"
    },
    {
      "x": -4,
      "y": 8,
      "z": -10,
      "name": "Rock_Shale_Brick_Decorative"
    },
    {
      "x": -4,
      "y": 9,
      "z": -10,
      "name": "Rock_Shale_Brick"
    },
    {
      "x": -4,
      "y": 1,
      "z": -9,
      "name": "Rock_Slate"
    },
    {
      "x": -4,
      "y": 2,
      "z": -9,
      "name": "Rock_Slate"
    },
    {
      "x": -4,
      "y": 3,
      "z": -9,
      "name": "Rock_Slate"
    },
    {
      "x": -4,
      "y": 4,
      "z": -9,
      "name": "Rock_Slate"
    },
    {
      "x": -4,
      "y": 5,
      "z": -9,
      "name": "Rock_Slate_Cobble"
    },
    {
      "x": -4,
      "y": 6,
      "z": -9,
      "name": "Rock_Slate_Cobble"
    },
    {
      "x": -4,
      "y": 7,
      "z": -9,
      "name": "Rock_Slate_Cobble"
    },
    {
      "x": -4,
      "y": 9,
      "z": -9,
      "name": "Rock_Shale_Brick"
    },
    {
      "x": -4,
      "y": 1,
      "z": -8,
      "name": "Rock_Slate_Cobble"
    },
    {
      "x": -4,
      "y": 2,
      "z": -8,
      "name": "Rock_Slate"
    },
    {
      "x": -4,
      "y": 3,
      "z": -8,
      "name": "Rock_Slate"
    },
    {
      "x": -4,
      "y": 4,
      "z": -8,
      "name": "Rock_Slate"
    },
    {
      "x": -4,
      "y": 9,
      "z": -8,
      "name": "Rock_Shale_Brick"
    },
    {
      "x": -4,
      "y": 10,
      "z": -8,
      "name": "*Rock_Slate_Cobble_Roof_Shallow_State_Definitions_Corner_Left",
      "filler": 1,
      "rotation": 2
    },
    {
      "x": -4,
      "y": 1,
      "z": -7,
      "name": "Rock_Slate_Cobble"
    },
    {
      "x": -4,
      "y": 2,
      "z": -7,
      "name": "Rock_Slate"
    },
    {
      "x": -4,
      "y": 3,
      "z": -7,
      "name": "Rock_Slate"
    },
    {
      "x": -4,
      "y": 4,
      "z": -7,
      "name": "Rock_Slate"
    },
    {
      "x": -4,
      "y": 9,
      "z": -7,
      "name": "Rock_Shale_Brick"
    },
    {
      "x": -4,
      "y": 10,
      "z": -7,
      "name": "*Rock_Slate_Cobble_Roof_Shallow_State_Definitions_Corner_Left",
      "filler": 33,
      "rotation": 2
    },
    {
      "x": -4,
      "y": 2,
      "z": -6,
      "name": "Rock_Slate"
    },
    {
      "x": -4,
      "y": 3,
      "z": -6,
      "name": "Rock_Slate"
    },
    {
      "x": -4,
      "y": 4,
      "z": -6,
      "name": "Rock_Slate"
    },
    {
      "x": -4,
      "y": 9,
      "z": -6,
      "name": "Rock_Shale_Brick"
    },
    {
      "x": -4,
      "y": 10,
      "z": -6,
      "name": "Rock_Slate_Cobble_Roof_Shallow",
      "filler": 1,
      "rotation": 3
    },
    {
      "x": -4,
      "y": 2,
      "z": -5,
      "name": "Rock_Slate"
    },
    {
      "x": -4,
      "y": 3,
      "z": -5,
      "name": "Rock_Slate"
    },
    {
      "x": -4,
      "y": 4,
      "z": -5,
      "name": "Rock_Slate"
    },
    {
      "x": -4,
      "y": 9,
      "z": -5,
      "name": "Rock_Shale_Brick"
    },
    {
      "x": -4,
      "y": 10,
      "z": -5,
      "name": "Rock_Slate_Cobble_Roof_Shallow",
      "filler": 1,
      "rotation": 3
    },
    {
      "x": -4,
      "y": 2,
      "z": -4,
      "name": "Rock_Slate"
    },
    {
      "x": -4,
      "y": 3,
      "z": -4,
      "name": "Rock_Slate"
    },
    {
      "x": -4,
      "y": 4,
      "z": -4,
      "name": "Rock_Slate"
    },
    {
      "x": -4,
      "y": 9,
      "z": -4,
      "name": "Rock_Shale_Brick"
    },
    {
      "x": -4,
      "y": 10,
      "z": -4,
      "name": "Rock_Slate_Cobble_Roof_Shallow",
      "filler": 1,
      "rotation": 3
    },
    {
      "x": -4,
      "y": 3,
      "z": -3,
      "name": "Rock_Slate"
    },
    {
      "x": -4,
      "y": 4,
      "z": -3,
      "name": "Rock_Slate"
    },
    {
      "x": -4,
      "y": 9,
      "z": -3,
      "name": "Rock_Shale_Brick"
    },
    {
      "x": -4,
      "y": 10,
      "z": -3,
      "name": "Rock_Slate_Cobble_Roof_Shallow",
      "filler": 1,
      "rotation": 3
    },
    {
      "x": -4,
      "y": 2,
      "z": -2,
      "name": "Rock_Slate"
    },
    {
      "x": -4,
      "y": 3,
      "z": -2,
      "name": "Rock_Slate"
    },
    {
      "x": -4,
      "y": 4,
      "z": -2,
      "name": "Rock_Slate"
    },
    {
      "x": -4,
      "y": 9,
      "z": -2,
      "name": "Rock_Shale_Brick"
    },
    {
      "x": -4,
      "y": 10,
      "z": -2,
      "name": "Rock_Slate_Cobble_Roof_Shallow",
      "filler": 1,
      "rotation": 3
    },
    {
      "x": -4,
      "y": 2,
      "z": -1,
      "name": "Rock_Slate"
    },
    {
      "x": -4,
      "y": 3,
      "z": -1,
      "name": "Rock_Slate"
    },
    {
      "x": -4,
      "y": 4,
      "z": -1,
      "name": "Rock_Shale_Brick_Smooth"
    },
    {
      "x": -4,
      "y": 9,
      "z": -1,
      "name": "Rock_Shale_Brick"
    },
    {
      "x": -4,
      "y": 10,
      "z": -1,
      "name": "Rock_Shale_Brick"
    },
    {
      "x": -4,
      "y": 11,
      "z": -1,
      "name": "Rock_Shale_Brick"
    },
    {
      "x": -4,
      "y": 12,
      "z": -1,
      "name": "Rock_Shale_Brick_Roof",
      "rotation": 1
    },
    {
      "x": -4,
      "y": 2,
      "z": 0,
      "name": "Rock_Slate"
    },
    {
      "x": -4,
      "y": 3,
      "z": 0,
      "name": "Rock_Slate"
    },
    {
      "x": -4,
      "y": 4,
      "z": 0,
      "name": "Rock_Slate"
    },
    {
      "x": -4,
      "y": 5,
      "z": 0,
      "name": "Rubble_Slate"
    },
    {
      "x": -4,
      "y": 9,
      "z": 0,
      "name": "Rock_Shale_Brick"
    },
    {
      "x": -4,
      "y": 10,
      "z": 0,
      "name": "Rock_Shale_Brick"
    },
    {
      "x": -4,
      "y": 2,
      "z": 1,
      "name": "Rock_Slate"
    },
    {
      "x": -4,
      "y": 3,
      "z": 1,
      "name": "Rock_Slate"
    },
    {
      "x": -4,
      "y": 4,
      "z": 1,
      "name": "Rock_Slate"
    },
    {
      "x": -4,
      "y": 5,
      "z": 1,
      "name": "Rock_Slate_Cobble"
    },
    {
      "x": -4,
      "y": 9,
      "z": 1,
      "name": "Rock_Shale_Brick"
    },
    {
      "x": -4,
      "y": 10,
      "z": 1,
      "name": "Rock_Slate_Cobble_Roof_Shallow",
      "filler": 1,
      "rotation": 3
    },
    {
      "x": -4,
      "y": 2,
      "z": 2,
      "name": "Rock_Slate"
    },
    {
      "x": -4,
      "y": 3,
      "z": 2,
      "name": "Rock_Slate"
    },
    {
      "x": -4,
      "y": 4,
      "z": 2,
      "name": "Rock_Slate"
    },
    {
      "x": -4,
      "y": 5,
      "z": 2,
      "name": "Rock_Slate_Cobble"
    },
    {
      "x": -4,
      "y": 9,
      "z": 2,
      "name": "Rock_Shale_Brick"
    },
    {
      "x": -4,
      "y": 10,
      "z": 2,
      "name": "Rock_Slate_Cobble_Roof_Shallow",
      "filler": 1,
      "rotation": 3
    },
    {
      "x": -4,
      "y": 3,
      "z": 3,
      "name": "Rock_Slate"
    },
    {
      "x": -4,
      "y": 4,
      "z": 3,
      "name": "Rock_Slate"
    },
    {
      "x": -4,
      "y": 9,
      "z": 3,
      "name": "Rock_Shale_Brick"
    },
    {
      "x": -4,
      "y": 10,
      "z": 3,
      "name": "Rock_Slate_Cobble_Roof_Shallow",
      "filler": 1,
      "rotation": 3
    },
    {
      "x": -4,
      "y": 2,
      "z": 4,
      "name": "Rock_Slate"
    },
    {
      "x": -4,
      "y": 3,
      "z": 4,
      "name": "Rock_Slate"
    },
    {
      "x": -4,
      "y": 4,
      "z": 4,
      "name": "Rock_Slate"
    },
    {
      "x": -4,
      "y": 9,
      "z": 4,
      "name": "Rock_Shale_Brick"
    },
    {
      "x": -4,
      "y": 10,
      "z": 4,
      "name": "Rock_Slate_Cobble_Roof_Shallow",
      "filler": 1,
      "rotation": 3
    },
    {
      "x": -4,
      "y": 2,
      "z": 5,
      "name": "Rock_Slate"
    },
    {
      "x": -4,
      "y": 3,
      "z": 5,
      "name": "Rock_Slate"
    },
    {
      "x": -4,
      "y": 4,
      "z": 5,
      "name": "Rock_Slate"
    },
    {
      "x": -4,
      "y": 2,
      "z": 6,
      "name": "Rock_Slate"
    },
    {
      "x": -4,
      "y": 3,
      "z": 6,
      "name": "Rock_Slate"
    },
    {
      "x": -4,
      "y": 4,
      "z": 6,
      "name": "Rock_Slate"
    },
    {
      "x": -4,
      "y": 2,
      "z": 7,
      "name": "Rock_Slate"
    },
    {
      "x": -4,
      "y": 3,
      "z": 7,
      "name": "Rock_Slate"
    },
    {
      "x": -4,
      "y": 4,
      "z": 7,
      "name": "Rock_Slate"
    },
    {
      "x": -4,
      "y": 2,
      "z": 8,
      "name": "Rock_Slate"
    },
    {
      "x": -4,
      "y": 3,
      "z": 8,
      "name": "Rock_Slate"
    },
    {
      "x": -4,
      "y": 4,
      "z": 8,
      "name": "Rock_Slate"
    },
    {
      "x": -4,
      "y": 9,
      "z": 8,
      "name": "Rock_Shale_Brick"
    },
    {
      "x": -4,
      "y": 2,
      "z": 9,
      "name": "Rock_Slate"
    },
    {
      "x": -4,
      "y": 3,
      "z": 9,
      "name": "Rock_Slate"
    },
    {
      "x": -4,
      "y": 4,
      "z": 9,
      "name": "Rock_Slate"
    },
    {
      "x": -4,
      "y": 5,
      "z": 9,
      "name": "Rock_Shale_Brick_Decorative"
    },
    {
      "x": -4,
      "y": 6,
      "z": 9,
      "name": "Rock_Shale_Brick_Beam"
    },
    {
      "x": -4,
      "y": 7,
      "z": 9,
      "name": "Rock_Shale_Brick_Beam"
    },
    {
      "x": -4,
      "y": 8,
      "z": 9,
      "name": "Rock_Shale_Brick_Decorative"
    },
    {
      "x": -4,
      "y": 9,
      "z": 9,
      "name": "Rock_Shale_Brick"
    },
    {
      "x": -4,
      "y": 2,
      "z": 10,
      "name": "Rock_Slate"
    },
    {
      "x": -4,
      "y": 3,
      "z": 10,
      "name": "Rock_Slate"
    },
    {
      "x": -4,
      "y": 4,
      "z": 10,
      "name": "Rock_Slate"
    },
    {
      "x": -4,
      "y": 2,
      "z": 11,
      "name": "Rock_Slate"
    },
    {
      "x": -4,
      "y": 3,
      "z": 11,
      "name": "Rock_Slate"
    },
    {
      "x": -4,
      "y": 4,
      "z": 11,
      "name": "Rock_Slate"
    },
    {
      "x": -4,
      "y": 2,
      "z": 12,
      "name": "Rock_Slate"
    },
    {
      "x": -3,
      "y": 2,
      "z": -13,
      "name": "Rock_Slate"
    },
    {
      "x": -3,
      "y": 3,
      "z": -13,
      "name": "Rock_Slate_Cobble"
    },
    {
      "x": -3,
      "y": 2,
      "z": -12,
      "name": "Rock_Slate"
    },
    {
      "x": -3,
      "y": 3,
      "z": -12,
      "name": "Rock_Slate"
    },
    {
      "x": -3,
      "y": 4,
      "z": -12,
      "name": "Rock_Slate"
    },
    {
      "x": -3,
      "y": 1,
      "z": -11,
      "name": "Rock_Slate"
    },
    {
      "x": -3,
      "y": 2,
      "z": -11,
      "name": "Rock_Slate"
    },
    {
      "x": -3,
      "y": 3,
      "z": -11,
      "name": "Rock_Slate"
    },
    {
      "x": -3,
      "y": 4,
      "z": -11,
      "name": "Rock_Slate"
    },
    {
      "x": -3,
      "y": 1,
      "z": -10,
      "name": "Rock_Slate"
    },
    {
      "x": -3,
      "y": 2,
      "z": -10,
      "name": "Rock_Slate"
    },
    {
      "x": -3,
      "y": 3,
      "z": -10,
      "name": "Rock_Slate"
    },
    {
      "x": -3,
      "y": 4,
      "z": -10,
      "name": "Rock_Slate"
    },
    {
      "x": -3,
      "y": 9,
      "z": -10,
      "name": "Rock_Shale_Brick"
    },
    {
      "x": -3,
      "y": 1,
      "z": -9,
      "name": "Rock_Slate_Cobble"
    },
    {
      "x": -3,
      "y": 2,
      "z": -9,
      "name": "Rock_Slate"
    },
    {
      "x": -3,
      "y": 3,
      "z": -9,
      "name": "Rock_Slate"
    },
    {
      "x": -3,
      "y": 4,
      "z": -9,
      "name": "Rock_Slate"
    },
    {
      "x": -3,
      "y": 5,
      "z": -9,
      "name": "Rock_Slate_Cobble"
    },
    {
      "x": -3,
      "y": 6,
      "z": -9,
      "name": "Rock_Slate_Cobble"
    },
    {
      "x": -3,
      "y": 7,
      "z": -9,
      "name": "Rock_Slate_Cobble"
    },
    {
      "x": -3,
      "y": 8,
      "z": -9,
      "name": "Rock_Slate_Cobble"
    },
    {
      "x": -3,
      "y": 9,
      "z": -9,
      "name": "Rock_Shale_Brick"
    },
    {
      "x": -3,
      "y": 1,
      "z": -8,
      "name": "Rock_Slate_Cobble"
    },
    {
      "x": -3,
      "y": 2,
      "z": -8,
      "name": "Rock_Slate"
    },
    {
      "x": -3,
      "y": 3,
      "z": -8,
      "name": "Rock_Slate"
    },
    {
      "x": -3,
      "y": 4,
      "z": -8,
      "name": "Rock_Shale_Brick_Smooth"
    },
    {
      "x": -3,
      "y": 5,
      "z": -8,
      "name": "Rock_Shale_Brick_Beam"
    },
    {
      "x": -3,
      "y": 6,
      "z": -8,
      "name": "Rock_Shale_Brick_Beam"
    },
    {
      "x": -3,
      "y": 7,
      "z": -8,
      "name": "Rock_Shale_Brick_Smooth"
    },
    {
      "x": -3,
      "y": 9,
      "z": -8,
      "name": "Rock_Shale_Brick"
    },
    {
      "x": -3,
      "y": 10,
      "z": -8,
      "name": "Rock_Slate_Cobble_Roof_Shallow",
      "rotation": 2
    },
    {
      "x": -3,
      "y": 1,
      "z": -7,
      "name": "Rock_Slate"
    },
    {
      "x": -3,
      "y": 2,
      "z": -7,
      "name": "Rock_Slate"
    },
    {
      "x": -3,
      "y": 3,
      "z": -7,
      "name": "Rock_Slate"
    },
    {
      "x": -3,
      "y": 4,
      "z": -7,
      "name": "Rock_Slate"
    },
    {
      "x": -3,
      "y": 7,
      "z": -7,
      "name": "Rock_Shale_Brick_Beam",
      "rotation": 4
    },
    {
      "x": -3,
      "y": 9,
      "z": -7,
      "name": "Rock_Shale_Brick"
    },
    {
      "x": -3,
      "y": 10,
      "z": -7,
      "name": "Rock_Slate_Cobble_Roof_Shallow",
      "filler": 32,
      "rotation": 2
    },
    {
      "x": -3,
      "y": 1,
      "z": -6,
      "name": "Rock_Slate_Cobble"
    },
    {
      "x": -3,
      "y": 2,
      "z": -6,
      "name": "Rock_Slate"
    },
    {
      "x": -3,
      "y": 3,
      "z": -6,
      "name": "Rock_Slate"
    },
    {
      "x": -3,
      "y": 4,
      "z": -6,
      "name": "Rock_Slate"
    },
    {
      "x": -3,
      "y": 7,
      "z": -6,
      "name": "Rock_Shale_Brick_Beam",
      "rotation": 4
    },
    {
      "x": -3,
      "y": 9,
      "z": -6,
      "name": "Rock_Shale_Brick"
    },
    {
      "x": -3,
      "y": 10,
      "z": -6,
      "name": "Rock_Shale_Brick"
    },
    {
      "x": -3,
      "y": 2,
      "z": -5,
      "name": "Rock_Slate"
    },
    {
      "x": -3,
      "y": 3,
      "z": -5,
      "name": "Rock_Slate"
    },
    {
      "x": -3,
      "y": 4,
      "z": -5,
      "name": "Rock_Slate"
    },
    {
      "x": -3,
      "y": 9,
      "z": -5,
      "name": "Rock_Shale_Brick"
    },
    {
      "x": -3,
      "y": 10,
      "z": -5,
      "name": "Rock_Shale_Brick"
    },
    {
      "x": -3,
      "y": 2,
      "z": -4,
      "name": "Rock_Slate"
    },
    {
      "x": -3,
      "y": 3,
      "z": -4,
      "name": "Rock_Slate"
    },
    {
      "x": -3,
      "y": 4,
      "z": -4,
      "name": "Rock_Slate"
    },
    {
      "x": -3,
      "y": 8,
      "z": -4,
      "name": "Rock_Shale_Brick_Beam"
    },
    {
      "x": -3,
      "y": 9,
      "z": -4,
      "name": "Rock_Shale_Brick"
    },
    {
      "x": -3,
      "y": 10,
      "z": -4,
      "name": "Rock_Shale_Brick"
    },
    {
      "x": -3,
      "y": 2,
      "z": -3,
      "name": "Rock_Slate"
    },
    {
      "x": -3,
      "y": 3,
      "z": -3,
      "name": "Rock_Slate"
    },
    {
      "x": -3,
      "y": 4,
      "z": -3,
      "name": "Rock_Slate"
    },
    {
      "x": -3,
      "y": 9,
      "z": -3,
      "name": "Rock_Shale_Brick"
    },
    {
      "x": -3,
      "y": 10,
      "z": -3,
      "name": "Rock_Shale_Brick"
    },
    {
      "x": -3,
      "y": 3,
      "z": -2,
      "name": "Rock_Slate"
    },
    {
      "x": -3,
      "y": 4,
      "z": -2,
      "name": "Rock_Slate"
    },
    {
      "x": -3,
      "y": 9,
      "z": -2,
      "name": "Rock_Shale_Brick"
    },
    {
      "x": -3,
      "y": 10,
      "z": -2,
      "name": "Rock_Shale_Brick"
    },
    {
      "x": -3,
      "y": 2,
      "z": -1,
      "name": "Rock_Slate"
    },
    {
      "x": -3,
      "y": 3,
      "z": -1,
      "name": "Rock_Slate"
    },
    {
      "x": -3,
      "y": 4,
      "z": -1,
      "name": "Rock_Shale_Brick_Smooth"
    },
    {
      "x": -3,
      "y": 9,
      "z": -1,
      "name": "Rock_Shale_Brick"
    },
    {
      "x": -3,
      "y": 10,
      "z": -1,
      "name": "Rock_Shale_Brick_Ornate"
    },
    {
      "x": -3,
      "y": 11,
      "z": -1,
      "name": "Rock_Shale_Brick_Stairs",
      "rotation": 1
    },
    {
      "x": -3,
      "y": 2,
      "z": 0,
      "name": "Rock_Slate"
    },
    {
      "x": -3,
      "y": 3,
      "z": 0,
      "name": "Rock_Slate"
    },
    {
      "x": -3,
      "y": 4,
      "z": 0,
      "name": "Rock_Slate"
    },
    {
      "x": -3,
      "y": 9,
      "z": 0,
      "name": "Rock_Shale_Brick"
    },
    {
      "x": -3,
      "y": 10,
      "z": 0,
      "name": "Rock_Shale_Brick_Ornate"
    },
    {
      "x": -3,
      "y": 2,
      "z": 1,
      "name": "Rock_Slate"
    },
    {
      "x": -3,
      "y": 3,
      "z": 1,
      "name": "Rock_Slate"
    },
    {
      "x": -3,
      "y": 4,
      "z": 1,
      "name": "Rock_Slate"
    },
    {
      "x": -3,
      "y": 9,
      "z": 1,
      "name": "Rock_Shale_Brick"
    },
    {
      "x": -3,
      "y": 10,
      "z": 1,
      "name": "Rock_Shale_Brick"
    },
    {
      "x": -3,
      "y": 3,
      "z": 2,
      "name": "Rock_Slate"
    },
    {
      "x": -3,
      "y": 4,
      "z": 2,
      "name": "Rock_Slate"
    },
    {
      "x": -3,
      "y": 9,
      "z": 2,
      "name": "Rock_Shale_Brick"
    },
    {
      "x": -3,
      "y": 10,
      "z": 2,
      "name": "Rock_Shale_Brick"
    },
    {
      "x": -3,
      "y": 3,
      "z": 3,
      "name": "Rock_Slate"
    },
    {
      "x": -3,
      "y": 4,
      "z": 3,
      "name": "Rock_Slate"
    },
    {
      "x": -3,
      "y": 9,
      "z": 3,
      "name": "Rock_Shale_Brick"
    },
    {
      "x": -3,
      "y": 10,
      "z": 3,
      "name": "Rock_Shale_Brick"
    },
    {
      "x": -3,
      "y": 2,
      "z": 4,
      "name": "Rock_Slate"
    },
    {
      "x": -3,
      "y": 3,
      "z": 4,
      "name": "Rock_Slate"
    },
    {
      "x": -3,
      "y": 4,
      "z": 4,
      "name": "Rock_Slate"
    },
    {
      "x": -3,
      "y": 2,
      "z": 5,
      "name": "Rock_Slate"
    },
    {
      "x": -3,
      "y": 3,
      "z": 5,
      "name": "Rock_Slate"
    },
    {
      "x": -3,
      "y": 4,
      "z": 5,
      "name": "Rock_Slate"
    },
    {
      "x": -3,
      "y": 2,
      "z": 6,
      "name": "Rock_Slate"
    },
    {
      "x": -3,
      "y": 3,
      "z": 6,
      "name": "Rock_Slate"
    },
    {
      "x": -3,
      "y": 4,
      "z": 6,
      "name": "Rock_Slate"
    },
    {
      "x": -3,
      "y": 2,
      "z": 7,
      "name": "Rock_Slate"
    },
    {
      "x": -3,
      "y": 3,
      "z": 7,
      "name": "Rock_Slate"
    },
    {
      "x": -3,
      "y": 4,
      "z": 7,
      "name": "Rock_Slate"
    },
    {
      "x": -3,
      "y": 2,
      "z": 8,
      "name": "Rock_Slate"
    },
    {
      "x": -3,
      "y": 3,
      "z": 8,
      "name": "Rock_Slate"
    },
    {
      "x": -3,
      "y": 4,
      "z": 8,
      "name": "Rock_Slate"
    },
    {
      "x": -3,
      "y": 9,
      "z": 8,
      "name": "Rock_Shale_Brick"
    },
    {
      "x": -3,
      "y": 2,
      "z": 9,
      "name": "Rock_Slate"
    },
    {
      "x": -3,
      "y": 3,
      "z": 9,
      "name": "Rock_Slate"
    },
    {
      "x": -3,
      "y": 4,
      "z": 9,
      "name": "Rock_Slate"
    },
    {
      "x": -3,
      "y": 9,
      "z": 9,
      "name": "Rock_Shale_Brick"
    },
    {
      "x": -3,
      "y": 10,
      "z": 9,
      "name": "Rock_Shale_Brick_Roof_Flat",
      "rotation": 2
    },
    {
      "x": -3,
      "y": 2,
      "z": 10,
      "name": "Rock_Slate"
    },
    {
      "x": -3,
      "y": 3,
      "z": 10,
      "name": "Rock_Slate"
    },
    {
      "x": -3,
      "y": 4,
      "z": 10,
      "name": "Rock_Slate"
    },
    {
      "x": -3,
      "y": 2,
      "z": 11,
      "name": "Rock_Slate"
    },
    {
      "x": -3,
      "y": 3,
      "z": 11,
      "name": "Rock_Slate"
    },
    {
      "x": -3,
      "y": 4,
      "z": 11,
      "name": "Rock_Slate"
    },
    {
      "x": -3,
      "y": 2,
      "z": 12,
      "name": "Rock_Slate"
    },
    {
      "x": -3,
      "y": 3,
      "z": 12,
      "name": "Rock_Slate"
    },
    {
      "x": -2,
      "y": 2,
      "z": -13,
      "name": "Rock_Slate_Cobble"
    },
    {
      "x": -2,
      "y": 3,
      "z": -13,
      "name": "Rock_Slate_Cobble"
    },
    {
      "x": -2,
      "y": 2,
      "z": -12,
      "name": "Rock_Slate"
    },
    {
      "x": -2,
      "y": 3,
      "z": -12,
      "name": "Rock_Slate"
    },
    {
      "x": -2,
      "y": 4,
      "z": -12,
      "name": "Rock_Slate"
    },
    {
      "x": -2,
      "y": 3,
      "z": -11,
      "name": "Rock_Slate"
    },
    {
      "x": -2,
      "y": 4,
      "z": -11,
      "name": "Rock_Slate"
    },
    {
      "x": -2,
      "y": 2,
      "z": -10,
      "name": "Rock_Slate"
    },
    {
      "x": -2,
      "y": 3,
      "z": -10,
      "name": "Rock_Slate"
    },
    {
      "x": -2,
      "y": 4,
      "z": -10,
      "name": "Rock_Slate"
    },
    {
      "x": -2,
      "y": 5,
      "z": -10,
      "name": "Rock_Shale_Brick_Decorative"
    },
    {
      "x": -2,
      "y": 6,
      "z": -10,
      "name": "Rock_Shale_Brick_Beam"
    },
    {
      "x": -2,
      "y": 7,
      "z": -10,
      "name": "Rock_Shale_Brick_Beam"
    },
    {
      "x": -2,
      "y": 8,
      "z": -10,
      "name": "Rock_Shale_Brick_Decorative"
    },
    {
      "x": -2,
      "y": 9,
      "z": -10,
      "name": "Rock_Shale_Brick"
    },
    {
      "x": -2,
      "y": 10,
      "z": -10,
      "name": "Rock_Shale_Brick_Roof_Flat",
      "rotation": 2
    },
    {
      "x": -2,
      "y": 2,
      "z": -9,
      "name": "Rock_Slate"
    },
    {
      "x": -2,
      "y": 3,
      "z": -9,
      "name": "Rock_Slate"
    },
    {
      "x": -2,
      "y": 4,
      "z": -9,
      "name": "Rock_Slate"
    },
    {
      "x": -2,
      "y": 5,
      "z": -9,
      "name": "Rock_Slate_Cobble"
    },
    {
      "x": -2,
      "y": 6,
      "z": -9,
      "name": "Rock_Slate_Cobble"
    },
    {
      "x": -2,
      "y": 7,
      "z": -9,
      "name": "Rock_Slate_Cobble"
    },
    {
      "x": -2,
      "y": 8,
      "z": -9,
      "name": "Rock_Slate_Cobble"
    },
    {
      "x": -2,
      "y": 9,
      "z": -9,
      "name": "Rock_Shale_Brick"
    },
    {
      "x": -2,
      "y": 3,
      "z": -8,
      "name": "Rock_Slate"
    },
    {
      "x": -2,
      "y": 4,
      "z": -8,
      "name": "Rock_Slate"
    },
    {
      "x": -2,
      "y": 5,
      "z": -8,
      "name": "Rock_Slate_Cobble"
    },
    {
      "x": -2,
      "y": 9,
      "z": -8,
      "name": "Rock_Shale_Brick"
    },
    {
      "x": -2,
      "y": 10,
      "z": -8,
      "name": "Rock_Slate_Cobble_Roof_Shallow",
      "rotation": 2
    },
    {
      "x": -2,
      "y": 1,
      "z": -7,
      "name": "Rock_Slate"
    },
    {
      "x": -2,
      "y": 3,
      "z": -7,
      "name": "Rock_Slate"
    },
    {
      "x": -2,
      "y": 4,
      "z": -7,
      "name": "Rock_Slate"
    },
    {
      "x": -2,
      "y": 5,
      "z": -7,
      "name": "Rock_Slate_Cobble"
    },
    {
      "x": -2,
      "y": 9,
      "z": -7,
      "name": "Rock_Shale_Brick"
    },
    {
      "x": -2,
      "y": 10,
      "z": -7,
      "name": "Rock_Slate_Cobble_Roof_Shallow",
      "filler": 32,
      "rotation": 2
    },
    {
      "x": -2,
      "y": 2,
      "z": -6,
      "name": "Rock_Slate"
    },
    {
      "x": -2,
      "y": 3,
      "z": -6,
      "name": "Rock_Slate"
    },
    {
      "x": -2,
      "y": 4,
      "z": -6,
      "name": "Rock_Slate"
    },
    {
      "x": -2,
      "y": 9,
      "z": -6,
      "name": "Rock_Shale_Brick"
    },
    {
      "x": -2,
      "y": 10,
      "z": -6,
      "name": "Rock_Shale_Brick"
    },
    {
      "x": -2,
      "y": 1,
      "z": -5,
      "name": "Rock_Slate"
    },
    {
      "x": -2,
      "y": 2,
      "z": -5,
      "name": "Rock_Slate"
    },
    {
      "x": -2,
      "y": 3,
      "z": -5,
      "name": "Rock_Slate"
    },
    {
      "x": -2,
      "y": 4,
      "z": -5,
      "name": "Rock_Slate"
    },
    {
      "x": -2,
      "y": 9,
      "z": -5,
      "name": "Rock_Shale_Brick"
    },
    {
      "x": -2,
      "y": 10,
      "z": -5,
      "name": "Rock_Shale_Brick"
    },
    {
      "x": -2,
      "y": 2,
      "z": -4,
      "name": "Rock_Slate"
    },
    {
      "x": -2,
      "y": 3,
      "z": -4,
      "name": "Rock_Slate"
    },
    {
      "x": -2,
      "y": 4,
      "z": -4,
      "name": "Rock_Slate"
    },
    {
      "x": -2,
      "y": 9,
      "z": -4,
      "name": "Rock_Shale_Brick"
    },
    {
      "x": -2,
      "y": 10,
      "z": -4,
      "name": "Rock_Shale_Brick"
    },
    {
      "x": -2,
      "y": 11,
      "z": -4,
      "name": "Rock_Shale_Brick"
    },
    {
      "x": -2,
      "y": 12,
      "z": -4,
      "name": "Rock_Shale_Brick"
    },
    {
      "x": -2,
      "y": 13,
      "z": -4,
      "name": "Rock_Shale_Brick_Decorative"
    },
    {
      "x": -2,
      "y": 2,
      "z": -3,
      "name": "Rock_Slate"
    },
    {
      "x": -2,
      "y": 3,
      "z": -3,
      "name": "Rock_Slate"
    },
    {
      "x": -2,
      "y": 4,
      "z": -3,
      "name": "Rock_Slate"
    },
    {
      "x": -2,
      "y": 9,
      "z": -3,
      "name": "Rock_Shale_Brick"
    },
    {
      "x": -2,
      "y": 10,
      "z": -3,
      "name": "Rock_Shale_Brick"
    },
    {
      "x": -2,
      "y": 3,
      "z": -2,
      "name": "Rock_Slate"
    },
    {
      "x": -2,
      "y": 4,
      "z": -2,
      "name": "Rock_Slate"
    },
    {
      "x": -2,
      "y": 9,
      "z": -2,
      "name": "Rock_Shale_Brick"
    },
    {
      "x": -2,
      "y": 10,
      "z": -2,
      "name": "Rock_Shale_Brick"
    },
    {
      "x": -2,
      "y": 4,
      "z": -1,
      "name": "Rock_Shale_Brick_Smooth"
    },
    {
      "x": -2,
      "y": 9,
      "z": -1,
      "name": "Rock_Shale_Brick"
    },
    {
      "x": -2,
      "y": 10,
      "z": -1,
      "name": "Rock_Shale_Brick_Ornate"
    },
    {
      "x": -2,
      "y": 3,
      "z": 0,
      "name": "Rock_Slate"
    },
    {
      "x": -2,
      "y": 4,
      "z": 0,
      "name": "Rock_Slate"
    },
    {
      "x": -2,
      "y": 9,
      "z": 0,
      "name": "Rock_Shale_Brick"
    },
    {
      "x": -2,
      "y": 10,
      "z": 0,
      "name": "Rock_Shale_Brick_Ornate"
    },
    {
      "x": -2,
      "y": 3,
      "z": 1,
      "name": "Rock_Slate"
    },
    {
      "x": -2,
      "y": 4,
      "z": 1,
      "name": "Rock_Slate"
    },
    {
      "x": -2,
      "y": 9,
      "z": 1,
      "name": "Rock_Shale_Brick"
    },
    {
      "x": -2,
      "y": 10,
      "z": 1,
      "name": "Rock_Shale_Brick"
    },
    {
      "x": -2,
      "y": 14,
      "z": 1,
      "name": "Rock_Shale_Brick_Half",
      "rotation": 8
    },
    {
      "x": -2,
      "y": 15,
      "z": 1,
      "name": "Rock_Shale_Brick_Half",
      "rotation": 2
    },
    {
      "x": -2,
      "y": 2,
      "z": 2,
      "name": "Rock_Slate"
    },
    {
      "x": -2,
      "y": 3,
      "z": 2,
      "name": "Rock_Slate"
    },
    {
      "x": -2,
      "y": 4,
      "z": 2,
      "name": "Rock_Slate"
    },
    {
      "x": -2,
      "y": 9,
      "z": 2,
      "name": "Rock_Shale_Brick"
    },
    {
      "x": -2,
      "y": 10,
      "z": 2,
      "name": "Rock_Shale_Brick"
    },
    {
      "x": -2,
      "y": 13,
      "z": 2,
      "name": "Rock_Shale_Brick_Half",
      "rotation": 6
    },
    {
      "x": -2,
      "y": 14,
      "z": 2,
      "name": "Rock_Shale_Brick_Stairs"
    },
    {
      "x": -2,
      "y": 3,
      "z": 3,
      "name": "Rock_Slate"
    },
    {
      "x": -2,
      "y": 4,
      "z": 3,
      "name": "Rock_Slate"
    },
    {
      "x": -2,
      "y": 9,
      "z": 3,
      "name": "Rock_Shale_Brick"
    },
    {
      "x": -2,
      "y": 10,
      "z": 3,
      "name": "Rock_Shale_Brick"
    },
    {
      "x": -2,
      "y": 11,
      "z": 3,
      "name": "Rock_Shale_Brick"
    },
    {
      "x": -2,
      "y": 12,
      "z": 3,
      "name": "Rock_Shale_Brick"
    },
    {
      "x": -2,
      "y": 13,
      "z": 3,
      "name": "Rock_Shale_Brick_Decorative"
    },
    {
      "x": -2,
      "y": 2,
      "z": 4,
      "name": "Rock_Slate"
    },
    {
      "x": -2,
      "y": 3,
      "z": 4,
      "name": "Rock_Slate"
    },
    {
      "x": -2,
      "y": 4,
      "z": 4,
      "name": "Rock_Slate"
    },
    {
      "x": -2,
      "y": 10,
      "z": 4,
      "name": "Rock_Shale_Brick"
    },
    {
      "x": -2,
      "y": 2,
      "z": 5,
      "name": "Rock_Slate"
    },
    {
      "x": -2,
      "y": 3,
      "z": 5,
      "name": "Rock_Slate"
    },
    {
      "x": -2,
      "y": 4,
      "z": 5,
      "name": "Rock_Slate"
    },
    {
      "x": -2,
      "y": 2,
      "z": 6,
      "name": "Rock_Slate"
    },
    {
      "x": -2,
      "y": 3,
      "z": 6,
      "name": "Rock_Slate"
    },
    {
      "x": -2,
      "y": 4,
      "z": 6,
      "name": "Rock_Slate"
    },
    {
      "x": -2,
      "y": 9,
      "z": 6,
      "name": "Rock_Shale_Brick_Smooth_Half"
    },
    {
      "x": -2,
      "y": 3,
      "z": 7,
      "name": "Rock_Slate"
    },
    {
      "x": -2,
      "y": 4,
      "z": 7,
      "name": "Rock_Slate"
    },
    {
      "x": -2,
      "y": 9,
      "z": 7,
      "name": "Rock_Shale_Brick"
    },
    {
      "x": -2,
      "y": 2,
      "z": 8,
      "name": "Rock_Slate"
    },
    {
      "x": -2,
      "y": 3,
      "z": 8,
      "name": "Rock_Slate"
    },
    {
      "x": -2,
      "y": 4,
      "z": 8,
      "name": "Rock_Slate"
    },
    {
      "x": -2,
      "y": 5,
      "z": 8,
      "name": "Rock_Slate_Cobble"
    },
    {
      "x": -2,
      "y": 9,
      "z": 8,
      "name": "Rock_Shale_Brick"
    },
    {
      "x": -2,
      "y": 2,
      "z": 9,
      "name": "Rock_Slate"
    },
    {
      "x": -2,
      "y": 3,
      "z": 9,
      "name": "Rock_Slate"
    },
    {
      "x": -2,
      "y": 4,
      "z": 9,
      "name": "Rock_Slate"
    },
    {
      "x": -2,
      "y": 5,
      "z": 9,
      "name": "Rock_Shale_Brick_Decorative"
    },
    {
      "x": -2,
      "y": 6,
      "z": 9,
      "name": "Rock_Shale_Brick_Beam"
    },
    {
      "x": -2,
      "y": 7,
      "z": 9,
      "name": "Rock_Shale_Brick_Beam"
    },
    {
      "x": -2,
      "y": 8,
      "z": 9,
      "name": "Rock_Shale_Brick_Decorative"
    },
    {
      "x": -2,
      "y": 9,
      "z": 9,
      "name": "Rock_Shale_Brick"
    },
    {
      "x": -2,
      "y": 10,
      "z": 9,
      "name": "Rock_Shale_Brick_Roof_Flat",
      "rotation": 2
    },
    {
      "x": -2,
      "y": 2,
      "z": 10,
      "name": "Rock_Slate"
    },
    {
      "x": -2,
      "y": 3,
      "z": 10,
      "name": "Rock_Slate"
    },
    {
      "x": -2,
      "y": 4,
      "z": 10,
      "name": "Rock_Slate"
    },
    {
      "x": -2,
      "y": 2,
      "z": 11,
      "name": "Rock_Slate"
    },
    {
      "x": -2,
      "y": 3,
      "z": 11,
      "name": "Rock_Slate"
    },
    {
      "x": -2,
      "y": 4,
      "z": 11,
      "name": "Rock_Slate"
    },
    {
      "x": -2,
      "y": 2,
      "z": 12,
      "name": "Rock_Slate"
    },
    {
      "x": -2,
      "y": 3,
      "z": 12,
      "name": "Rock_Slate"
    },
    {
      "x": -2,
      "y": 4,
      "z": 12,
      "name": "Rock_Slate"
    },
    {
      "x": -2,
      "y": 3,
      "z": 13,
      "name": "Rock_Slate"
    },
    {
      "x": -2,
      "y": 4,
      "z": 13,
      "name": "Rock_Slate"
    },
    {
      "x": -1,
      "y": 2,
      "z": -13,
      "name": "Rock_Slate"
    },
    {
      "x": -1,
      "y": 4,
      "z": -13,
      "name": "Rock_Slate"
    },
    {
      "x": -1,
      "y": 2,
      "z": -12,
      "name": "Rock_Slate"
    },
    {
      "x": -1,
      "y": 3,
      "z": -12,
      "name": "Rock_Slate"
    },
    {
      "x": -1,
      "y": 4,
      "z": -12,
      "name": "Rock_Slate"
    },
    {
      "x": -1,
      "y": 2,
      "z": -11,
      "name": "Rock_Slate"
    },
    {
      "x": -1,
      "y": 3,
      "z": -11,
      "name": "Rock_Slate"
    },
    {
      "x": -1,
      "y": 4,
      "z": -11,
      "name": "Rock_Slate"
    },
    {
      "x": -1,
      "y": 2,
      "z": -10,
      "name": "Rock_Slate"
    },
    {
      "x": -1,
      "y": 3,
      "z": -10,
      "name": "Rock_Slate"
    },
    {
      "x": -1,
      "y": 4,
      "z": -10,
      "name": "Rock_Slate"
    },
    {
      "x": -1,
      "y": 5,
      "z": -10,
      "name": "Rock_Shale_Brick_Wall"
    },
    {
      "x": -1,
      "y": 9,
      "z": -10,
      "name": "Rock_Shale_Brick"
    },
    {
      "x": -1,
      "y": 10,
      "z": -10,
      "name": "Rock_Shale_Brick_Roof_Flat",
      "rotation": 2
    },
    {
      "x": -1,
      "y": 2,
      "z": -9,
      "name": "Rock_Slate"
    },
    {
      "x": -1,
      "y": 3,
      "z": -9,
      "name": "Rock_Slate"
    },
    {
      "x": -1,
      "y": 4,
      "z": -9,
      "name": "Rock_Slate"
    },
    {
      "x": -1,
      "y": 5,
      "z": -9,
      "name": "Rock_Slate_Cobble"
    },
    {
      "x": -1,
      "y": 6,
      "z": -9,
      "name": "Rock_Slate_Cobble"
    },
    {
      "x": -1,
      "y": 7,
      "z": -9,
      "name": "Rock_Slate_Cobble"
    },
    {
      "x": -1,
      "y": 8,
      "z": -9,
      "name": "Rock_Slate_Cobble"
    },
    {
      "x": -1,
      "y": 9,
      "z": -9,
      "name": "Rock_Shale_Brick"
    },
    {
      "x": -1,
      "y": 1,
      "z": -8,
      "name": "Rock_Slate_Cobble"
    },
    {
      "x": -1,
      "y": 2,
      "z": -8,
      "name": "Rock_Slate"
    },
    {
      "x": -1,
      "y": 3,
      "z": -8,
      "name": "Rock_Slate"
    },
    {
      "x": -1,
      "y": 4,
      "z": -8,
      "name": "Rock_Slate"
    },
    {
      "x": -1,
      "y": 5,
      "z": -8,
      "name": "Rock_Slate_Cobble"
    },
    {
      "x": -1,
      "y": 6,
      "z": -8,
      "name": "Rock_Slate_Cobble"
    },
    {
      "x": -1,
      "y": 7,
      "z": -8,
      "name": "Rock_Slate_Cobble"
    },
    {
      "x": -1,
      "y": 9,
      "z": -8,
      "name": "Rock_Shale_Brick"
    },
    {
      "x": -1,
      "y": 10,
      "z": -8,
      "name": "Rock_Slate_Cobble_Roof_Shallow",
      "rotation": 2
    },
    {
      "x": -1,
      "y": 2,
      "z": -7,
      "name": "Rock_Slate"
    },
    {
      "x": -1,
      "y": 3,
      "z": -7,
      "name": "Rock_Slate"
    },
    {
      "x": -1,
      "y": 4,
      "z": -7,
      "name": "Rock_Slate"
    },
    {
      "x": -1,
      "y": 5,
      "z": -7,
      "name": "Rock_Slate_Cobble"
    },
    {
      "x": -1,
      "y": 6,
      "z": -7,
      "name": "Rock_Slate_Cobble"
    },
    {
      "x": -1,
      "y": 9,
      "z": -7,
      "name": "Rock_Shale_Brick"
    },
    {
      "x": -1,
      "y": 10,
      "z": -7,
      "name": "Rock_Slate_Cobble_Roof_Shallow",
      "filler": 32,
      "rotation": 2
    },
    {
      "x": -1,
      "y": 2,
      "z": -6,
      "name": "Rock_Slate"
    },
    {
      "x": -1,
      "y": 3,
      "z": -6,
      "name": "Rock_Slate"
    },
    {
      "x": -1,
      "y": 4,
      "z": -6,
      "name": "Rock_Slate"
    },
    {
      "x": -1,
      "y": 5,
      "z": -6,
      "name": "Rock_Slate_Cobble"
    },
    {
      "x": -1,
      "y": 9,
      "z": -6,
      "name": "Rock_Shale_Brick"
    },
    {
      "x": -1,
      "y": 10,
      "z": -6,
      "name": "Rock_Shale_Brick"
    },
    {
      "x": -1,
      "y": 2,
      "z": -5,
      "name": "Rock_Slate"
    },
    {
      "x": -1,
      "y": 3,
      "z": -5,
      "name": "Rock_Slate"
    },
    {
      "x": -1,
      "y": 4,
      "z": -5,
      "name": "Rock_Slate"
    },
    {
      "x": -1,
      "y": 5,
      "z": -5,
      "name": "Rock_Slate_Cobble"
    },
    {
      "x": -1,
      "y": 9,
      "z": -5,
      "name": "Rock_Shale_Brick"
    },
    {
      "x": -1,
      "y": 10,
      "z": -5,
      "name": "Rock_Shale_Brick"
    },
    {
      "x": -1,
      "y": 2,
      "z": -4,
      "name": "Rock_Slate"
    },
    {
      "x": -1,
      "y": 3,
      "z": -4,
      "name": "Rock_Slate"
    },
    {
      "x": -1,
      "y": 4,
      "z": -4,
      "name": "Rock_Slate"
    },
    {
      "x": -1,
      "y": 9,
      "z": -4,
      "name": "Rock_Shale_Brick"
    },
