{
  "version": 8,
  "blockIdVersion": 11,
  "anchorX": 0,
  "anchorY": 6,
  "anchorZ": -3,
  "blocks": [
    {
      "x": -3,
      "y": 5,
      "z": -9,
      "name": "Rock_Slate"
    },
    {
      "x": -3,
      "y": 5,
      "z": -8,
      "name": "Rock_Slate"
    },
    {
      "x": -3,
      "y": 5,
      "z": 8,
      "name": "Rock_Slate"
    },
    {
      "x": -3,
      "y": 5,
      "z": 9,
      "name": "Rock_Slate"
    },
    {
      "x": -3,
      "y": 5,
      "z": 10,
      "name": "Rock_Slate_Cobble"
    },
    {
      "x": -2,
      "y": 5,
      "z": -9,
      "name": "Rock_Slate"
    },
    {
      "x": -2,
      "y": 6,
      "z": -9,
      "name": "Rock_Shale_Brick_Decorative",
      "rotation": 3
    },
    {
      "x": -2,
      "y": 7,
      "z": -9,
      "name": "Rock_Shale_Brick_Beam",
      "rotation": 2
    },
    {
      "x": -2,
      "y": 8,
      "z": -9,
      "name": "Rock_Shale_Brick_Beam",
      "rotation": 2
    },
    {
      "x": -2,
      "y": 9,
      "z": -9,
      "name": "Rock_Shale_Brick_Beam",
      "rotation": 2
    },
    {
      "x": -2,
      "y": 10,
      "z": -9,
      "name": "Rock_Shale_Brick_Beam",
      "rotation": 2
    },
    {
      "x": -2,
      "y": 11,
      "z": -9,
      "name": "Rock_Shale_Brick_Half",
      "rotation": 2
    },
    {
      "x": -2,
      "y": 5,
      "z": -8,
      "name": "Rock_Slate"
    },
    {
      "x": -2,
      "y": 6,
      "z": -8,
      "name": "Rock_Shale_Brick",
      "rotation": 3
    },
    {
      "x": -2,
      "y": 7,
      "z": -8,
      "name": "Rock_Shale_Brick_Ornate",
      "rotation": 2
    },
    {
      "x": -2,
      "y": 8,
      "z": -8,
      "name": "Rock_Shale_Brick_Pillar_Base",
      "rotation": 2
    },
    {
      "x": -2,
      "y": 9,
      "z": -8,
      "name": "Rock_Shale_Brick_Pillar_Middle",
      "rotation": 2
    },
    {
      "x": -2,
      "y": 10,
      "z": -8,
      "name": "Rock_Shale_Brick_Pillar_Base",
      "rotation": 10
    },
    {
      "x": -2,
      "y": 11,
      "z": -8,
      "name": "Rock_Shale_Brick_Roof_Steep",
      "rotation": 3
    },
    {
      "x": -2,
      "y": 12,
      "z": -8,
      "name": "Rock_Shale_Brick_Roof_Steep",
      "filler": 1024,
      "rotation": 3
    },
    {
      "x": -2,
      "y": 5,
      "z": -7,
      "name": "Rock_Slate"
    },
    {
      "x": -2,
      "y": 5,
      "z": -6,
      "name": "Rock_Slate"
    },
    {
      "x": -2,
      "y": 6,
      "z": 0,
      "name": "Rock_Shale_Brick",
      "rotation": 1
    },
    {
      "x": -2,
      "y": 7,
      "z": 0,
      "name": "Rock_Shale_Brick_Ornate",
      "rotation": 1
    },
    {
      "x": -2,
      "y": 8,
      "z": 0,
      "name": "Rock_Shale_Brick_Pillar_Base",
      "rotation": 1
    },
    {
      "x": -2,
      "y": 9,
      "z": 0,
      "name": "Rock_Shale_Brick_Pillar_Middle",
      "rotation": 1
    },
    {
      "x": -2,
      "y": 10,
      "z": 0,
      "name": "Rock_Shale_Brick_Pillar_Base",
      "rotation": 9
    },
    {
      "x": -2,
      "y": 11,
      "z": 0,
      "name": "Rock_Shale_Brick_Roof_Steep",
      "rotation": 3
    },
    {
      "x": -2,
      "y": 12,
      "z": 0,
      "name": "Rock_Shale_Brick_Roof_Steep",
      "filler": 1024,
      "rotation": 3
    },
    {
      "x": -2,
      "y": 5,
      "z": 7,
      "name": "Rock_Slate_Cobble"
    },
    {
      "x": -2,
      "y": 5,
      "z": 8,
      "name": "Rock_Slate"
    },
    {
      "x": -2,
      "y": 6,
      "z": 8,
      "name": "Rock_Shale_Brick",
      "rotation": 3
    },
    {
      "x": -2,
      "y": 7,
      "z": 8,
      "name": "Rock_Shale_Brick_Ornate",
      "rotation": 3
    },
    {
      "x": -2,
      "y": 8,
      "z": 8,
      "name": "Rock_Shale_Brick_Pillar_Base"
    },
    {
      "x": -2,
      "y": 4,
      "z": 9,
      "name": "Rock_Slate"
    },
    {
      "x": -2,
      "y": 5,
      "z": 9,
      "name": "Rock_Slate"
    },
    {
      "x": -2,
      "y": 6,
      "z": 9,
      "name": "Rock_Shale_Brick_Decorative",
      "rotation": 3
    },
    {
      "x": -2,
      "y": 7,
      "z": 9,
      "name": "Rock_Shale_Brick_Beam",
      "rotation": 3
    },
    {
      "x": -2,
      "y": 5,
      "z": 10,
      "name": "Rock_Slate"
    },
    {
      "x": -1,
      "y": 5,
      "z": -9,
      "name": "Rock_Slate"
    },
    {
      "x": -1,
      "y": 6,
      "z": -9,
      "name": "Rock_Shale_Brick_Ornate",
      "rotation": 3
    },
    {
      "x": -1,
      "y": 7,
      "z": -9,
      "name": "Rock_Shale_Brick_Pillar_Base"
    },
    {
      "x": -1,
      "y": 8,
      "z": -9,
      "name": "Rock_Shale_Brick_Pillar_Middle",
      "rotation": 3
    },
    {
      "x": -1,
      "y": 9,
      "z": -9,
      "name": "Rock_Shale_Brick_Pillar_Middle",
      "rotation": 2
    },
    {
      "x": -1,
      "y": 10,
      "z": -9,
      "name": "Rock_Shale_Brick_Pillar_Base",
      "rotation": 10
    },
    {
      "x": -1,
      "y": 11,
      "z": -9,
      "name": "Rock_Shale_Brick_Roof_Steep",
      "rotation": 2
    },
    {
      "x": -1,
      "y": 12,
      "z": -9,
      "name": "Rock_Shale_Brick_Roof_Steep",
      "filler": 1024,
      "rotation": 2
    },
    {
      "x": -1,
      "y": 5,
      "z": -8,
      "name": "Rock_Slate"
    },
    {
      "x": -1,
      "y": 6,
      "z": -8,
      "name": "Rock_Shale_Brick",
      "rotation": 3
    },
    {
      "x": -1,
      "y": 7,
      "z": -8,
      "name": "Rock_Shale_Brick",
      "rotation": 2
    },
    {
      "x": -1,
      "y": 8,
      "z": -8,
      "name": "Rock_Shale_Brick",
      "rotation": 2
    },
    {
      "x": -1,
      "y": 9,
      "z": -8,
      "name": "Rock_Shale_Brick",
      "rotation": 2
    },
    {
      "x": -1,
      "y": 10,
      "z": -8,
      "name": "Rock_Shale_Brick_Ornate",
      "rotation": 2
    },
    {
      "x": -1,
      "y": 11,
      "z": -8,
      "name": "Rock_Shale_Brick",
      "rotation": 3
    },
    {
      "x": -1,
      "y": 12,
      "z": -8,
      "name": "Rock_Shale_Brick",
      "rotation": 3
    },
    {
      "x": -1,
      "y": 13,
      "z": -8,
      "name": "Rock_Shale_Brick",
      "rotation": 3
    },
    {
      "x": -1,
      "y": 14,
      "z": -8,
      "name": "Furniture_Human_Ruins_Brazier",
      "rotation": 3
    },
    {
      "x": -1,
      "y": 5,
      "z": -7,
      "name": "Rock_Slate"
    },
    {
      "x": -1,
      "y": 6,
      "z": -7,
      "name": "Rock_Shale_Brick"
    },
    {
      "x": -1,
      "y": 7,
      "z": -7,
      "name": "Rock_Shale_Brick_Roof",
      "rotation": 3
    },
    {
      "x": -1,
      "y": 9,
      "z": -7,
      "name": "Rock_Shale_Cobble_Stairs",
      "rotation": 10
    },
    {
      "x": -1,
      "y": 10,
      "z": -7,
      "name": "Rock_Shale_Brick",
      "rotation": 1
    },
    {
      "x": -1,
      "y": 11,
      "z": -7,
      "name": "Rock_Shale_Brick_Roof_Flat",
      "rotation": 3
    },
    {
      "x": -1,
      "y": 6,
      "z": -6,
      "name": "Rock_Shale_Brick_Wall",
      "rotation": 1
    },
    {
      "x": -1,
      "y": 10,
      "z": -6,
      "name": "Rock_Shale_Brick",
      "rotation": 1
    },
    {
      "x": -1,
      "y": 11,
      "z": -6,
      "name": "Rock_Shale_Brick_Roof_Flat",
      "rotation": 3
    },
    {
      "x": -1,
      "y": 6,
      "z": -5,
      "name": "Rock_Shale_Brick_Decorative"
    },
    {
      "x": -1,
      "y": 7,
      "z": -5,
      "name": "Rock_Shale_Brick_Beam"
    },
    {
      "x": -1,
      "y": 8,
      "z": -5,
      "name": "Rock_Shale_Brick_Beam"
    },
    {
      "x": -1,
      "y": 9,
      "z": -5,
      "name": "Rock_Shale_Brick_Decorative"
    },
    {
      "x": -1,
      "y": 10,
      "z": -5,
      "name": "Rock_Shale_Brick",
      "rotation": 1
    },
    {
      "x": -1,
      "y": 11,
      "z": -5,
      "name": "Rock_Shale_Brick_Roof_Flat",
      "rotation": 3
    },
    {
      "x": -1,
      "y": 6,
      "z": -4,
      "name": "Rock_Slate"
    },
    {
      "x": -1,
      "y": 10,
      "z": -4,
      "name": "Rock_Shale_Brick_Stairs",
      "rotation": 9
    },
    {
      "x": -1,
      "y": 11,
      "z": -4,
      "name": "Rock_Shale_Brick_Roof_Flat",
      "rotation": 3
    },
    {
      "x": -1,
      "y": 5,
      "z": -3,
      "name": "Rock_Slate"
    },
    {
      "x": -1,
      "y": 6,
      "z": -3,
      "name": "Rock_Shale_Brick_Decorative"
    },
    {
      "x": -1,
      "y": 7,
      "z": -3,
      "name": "Rock_Shale_Brick_Beam"
    },
    {
      "x": -1,
      "y": 8,
      "z": -3,
      "name": "Rock_Shale_Brick_Beam"
    },
    {
      "x": -1,
      "y": 9,
      "z": -3,
      "name": "Rock_Shale_Brick_Decorative"
    },
    {
      "x": -1,
      "y": 10,
      "z": -3,
      "name": "Rock_Shale_Brick",
      "rotation": 1
    },
    {
      "x": -1,
      "y": 11,
      "z": -3,
      "name": "Rock_Shale_Brick_Roof_Flat",
      "rotation": 3
    },
    {
      "x": -1,
      "y": 6,
      "z": -2,
      "name": "Rock_Shale_Brick_Wall",
      "rotation": 1
    },
    {
      "x": -1,
      "y": 10,
      "z": -2,
      "name": "Rock_Shale_Brick",
      "rotation": 1
    },
    {
      "x": -1,
      "y": 11,
      "z": -2,
      "name": "Rock_Shale_Brick_Roof_Flat",
      "rotation": 3
    },
    {
      "x": -1,
      "y": 5,
      "z": -1,
      "name": "Rock_Slate"
    },
    {
      "x": -1,
      "y": 6,
      "z": -1,
      "name": "Rock_Shale_Brick"
    },
    {
      "x": -1,
      "y": 7,
      "z": -1,
      "name": "Rock_Shale_Brick_Roof",
      "rotation": 3
    },
    {
      "x": -1,
      "y": 9,
      "z": -1,
      "name": "Rock_Shale_Cobble_Stairs",
      "rotation": 8
    },
    {
      "x": -1,
      "y": 10,
      "z": -1,
      "name": "Rock_Shale_Brick",
      "rotation": 1
    },
    {
      "x": -1,
      "y": 11,
      "z": -1,
      "name": "Rock_Shale_Brick_Roof",
      "rotation": 2
    },
    {
      "x": -1,
      "y": 6,
      "z": 0,
      "name": "Rock_Shale_Brick",
      "rotation": 1
    },
    {
      "x": -1,
      "y": 7,
      "z": 0,
      "name": "Rock_Shale_Brick",
      "rotation": 1
    },
    {
      "x": -1,
      "y": 8,
      "z": 0,
      "name": "Rock_Shale_Brick",
      "rotation": 1
    },
    {
      "x": -1,
      "y": 9,
      "z": 0,
      "name": "Rock_Shale_Brick",
      "rotation": 1
    },
    {
      "x": -1,
      "y": 10,
      "z": 0,
      "name": "Rock_Shale_Brick",
      "rotation": 1
    },
    {
      "x": -1,
      "y": 11,
      "z": 0,
      "name": "Rock_Shale_Brick_Ornate",
      "rotation": 1
    },
    {
      "x": -1,
      "y": 12,
      "z": 0,
      "name": "Rock_Shale_Brick",
      "rotation": 3
    },
    {
      "x": -1,
      "y": 5,
      "z": 1,
      "name": "Rock_Slate"
    },
    {
      "x": -1,
      "y": 6,
      "z": 1,
      "name": "Rock_Shale_Brick"
    },
    {
      "x": -1,
      "y": 7,
      "z": 1,
      "name": "Rock_Shale_Brick_Roof",
      "rotation": 3
    },
    {
      "x": -1,
      "y": 9,
      "z": 1,
      "name": "Rock_Shale_Cobble_Stairs",
      "rotation": 10
    },
    {
      "x": -1,
      "y": 10,
      "z": 1,
      "name": "Rock_Shale_Brick",
      "rotation": 1
    },
    {
      "x": -1,
      "y": 11,
      "z": 1,
      "name": "Rock_Shale_Brick_Roof"
    },
    {
      "x": -1,
      "y": 4,
      "z": 2,
      "name": "Rock_Slate"
    },
    {
      "x": -1,
      "y": 5,
      "z": 2,
      "name": "Rock_Slate"
    },
    {
      "x": -1,
      "y": 6,
      "z": 2,
      "name": "Rock_Shale_Brick_Wall",
      "rotation": 1
    },
    {
      "x": -1,
      "y": 10,
      "z": 2,
      "name": "Rock_Shale_Brick",
      "rotation": 1
    },
    {
      "x": -1,
      "y": 11,
      "z": 2,
      "name": "Rock_Shale_Brick_Roof_Flat",
      "rotation": 1
    },
    {
      "x": -1,
      "y": 5,
      "z": 3,
      "name": "Rock_Slate_Cobble"
    },
    {
      "x": -1,
      "y": 6,
      "z": 3,
      "name": "Rock_Shale_Brick_Decorative"
    },
    {
      "x": -1,
      "y": 7,
      "z": 3,
      "name": "Rock_Shale_Brick_Beam"
    },
    {
      "x": -1,
      "y": 8,
      "z": 3,
      "name": "Rock_Shale_Brick_Beam"
    },
    {
      "x": -1,
      "y": 9,
      "z": 3,
      "name": "Rock_Shale_Brick_Decorative"
    },
    {
      "x": -1,
      "y": 10,
      "z": 3,
      "name": "Rock_Shale_Brick",
      "rotation": 1
    },
    {
      "x": -1,
      "y": 11,
      "z": 3,
      "name": "Rock_Shale_Brick_Roof_Flat",
      "rotation": 1
    },
    {
      "x": -1,
      "y": 10,
      "z": 4,
      "name": "Rock_Shale_Brick_Stairs",
      "rotation": 9
    },
    {
      "x": -1,
      "y": 11,
      "z": 4,
      "name": "Rock_Shale_Brick_Roof_Flat",
      "rotation": 1
    },
    {
      "x": -1,
      "y": 6,
      "z": 5,
      "name": "Rock_Shale_Brick_Decorative"
    },
    {
      "x": -1,
      "y": 7,
      "z": 5,
      "name": "Rock_Shale_Brick_Beam"
    },
    {
      "x": -1,
      "y": 10,
      "z": 5,
      "name": "Rock_Shale_Brick",
      "rotation": 1
    },
    {
      "x": -1,
      "y": 11,
      "z": 5,
      "name": "Rock_Shale_Brick_Roof_Flat",
      "rotation": 1
    },
    {
      "x": -1,
      "y": 5,
      "z": 6,
      "name": "Rock_Slate"
    },
    {
      "x": -1,
      "y": 6,
      "z": 6,
      "name": "Rock_Shale_Brick_Wall",
      "rotation": 1
    },
    {
      "x": -1,
      "y": 10,
      "z": 6,
      "name": "Rock_Shale_Brick"
    },
    {
      "x": -1,
      "y": 5,
      "z": 7,
      "name": "Rock_Slate"
    },
    {
      "x": -1,
      "y": 6,
      "z": 7,
      "name": "Rock_Shale_Brick"
    },
    {
      "x": -1,
      "y": 7,
      "z": 7,
      "name": "Rock_Shale_Brick_Roof",
      "rotation": 3
    },
    {
      "x": -1,
      "y": 9,
      "z": 7,
      "name": "Rock_Shale_Cobble_Stairs",
      "rotation": 8
    },
    {
      "x": -1,
      "y": 10,
      "z": 7,
      "name": "Rock_Shale_Brick"
    },
    {
      "x": -1,
      "y": 3,
      "z": 8,
      "name": "Rock_Slate"
    },
    {
      "x": -1,
      "y": 4,
      "z": 8,
      "name": "Rock_Slate"
    },
    {
      "x": -1,
      "y": 5,
      "z": 8,
      "name": "Rock_Slate"
    },
    {
      "x": -1,
      "y": 6,
      "z": 8,
      "name": "Rock_Shale_Brick",
      "rotation": 3
    },
    {
      "x": -1,
      "y": 7,
      "z": 8,
      "name": "Rock_Shale_Brick",
      "rotation": 3
    },
    {
      "x": -1,
      "y": 8,
      "z": 8,
      "name": "Rock_Shale_Brick",
      "rotation": 3
    },
    {
      "x": -1,
      "y": 9,
      "z": 8,
      "name": "Rock_Shale_Brick",
      "rotation": 3
    },
    {
      "x": -1,
      "y": 10,
      "z": 8,
      "name": "Rock_Shale_Brick"
    },
    {
      "x": -1,
      "y": 4,
      "z": 9,
      "name": "Rock_Slate_Cobble"
    },
    {
      "x": -1,
      "y": 5,
      "z": 9,
      "name": "Rock_Slate"
    },
    {
      "x": -1,
      "y": 10,
      "z": 9,
      "name": "Rock_Shale_Brick"
    },
    {
      "x": -1,
      "y": 5,
      "z": 11,
      "name": "Rock_Slate_Cobble"
    },
    {
      "x": 0,
      "y": 5,
      "z": -10,
      "name": "Rock_Slate"
    },
    {
      "x": 0,
      "y": 4,
      "z": -9,
      "name": "Rock_Slate"
    },
    {
      "x": 0,
      "y": 5,
      "z": -9,
      "name": "Rock_Slate"
    },
    {
      "x": 0,
      "y": 6,
      "z": -9,
      "name": "Rock_Shale_Brick"
    },
    {
      "x": 0,
      "y": 7,
      "z": -9,
      "name": "Rock_Shale_Brick"
    },
    {
      "x": 0,
      "y": 8,
      "z": -9,
      "name": "Rock_Shale_Brick"
    },
    {
      "x": 0,
      "y": 9,
      "z": -9,
      "name": "Rock_Shale_Brick"
    },
    {
      "x": 0,
      "y": 10,
      "z": -9,
      "name": "Rock_Shale_Brick"
    },
    {
      "x": 0,
      "y": 4,
      "z": -8,
      "name": "Rock_Slate"
    },
    {
      "x": 0,
      "y": 5,
      "z": -8,
      "name": "Rock_Slate"
    },
    {
      "x": 0,
      "y": 6,
      "z": -8,
      "name": "Rock_Slate_Cobble"
    },
    {
      "x": 0,
      "y": 7,
      "z": -8,
      "name": "Rock_Slate_Cobble"
    },
    {
      "x": 0,
      "y": 8,
      "z": -8,
      "name": "Rock_Slate_Cobble"
    },
    {
      "x": 0,
      "y": 9,
      "z": -8,
      "name": "Rock_Slate_Cobble"
    },
    {
      "x": 0,
      "y": 10,
      "z": -8,
      "name": "Rock_Shale_Brick"
    },
    {
      "x": 0,
      "y": 3,
      "z": -7,
      "name": "Rock_Slate"
    },
    {
      "x": 0,
      "y": 4,
      "z": -7,
      "name": "Rock_Slate"
    },
    {
      "x": 0,
      "y": 5,
      "z": -7,
      "name": "Rock_Slate"
    },
    {
      "x": 0,
      "y": 6,
      "z": -7,
      "name": "Rock_Slate_Cobble"
    },
    {
      "x": 0,
      "y": 7,
      "z": -7,
      "name": "Rock_Slate_Cobble"
    },
    {
      "x": 0,
      "y": 8,
      "z": -7,
      "name": "Rock_Slate_Cobble"
    },
    {
      "x": 0,
      "y": 9,
      "z": -7,
      "name": "Rock_Slate_Cobble"
    },
    {
      "x": 0,
      "y": 10,
      "z": -7,
      "name": "Rock_Shale_Brick"
    },
    {
      "x": 0,
      "y": 5,
      "z": -6,
      "name": "Rock_Slate"
    },
    {
      "x": 0,
      "y": 6,
      "z": -6,
      "name": "Rock_Slate_Cobble"
    },
    {
      "x": 0,
      "y": 7,
      "z": -6,
      "name": "Rock_Slate_Cobble"
    },
    {
      "x": 0,
      "y": 8,
      "z": -6,
      "name": "Rock_Slate_Cobble"
    },
    {
      "x": 0,
      "y": 9,
      "z": -6,
      "name": "Rock_Slate_Cobble"
    },
    {
      "x": 0,
      "y": 10,
      "z": -6,
      "name": "Rock_Shale_Brick"
    },
    {
      "x": 0,
      "y": 6,
      "z": -5,
      "name": "Rock_Slate_Cobble"
    },
    {
      "x": 0,
      "y": 8,
      "z": -5,
      "name": "Rock_Slate_Cobble"
    },
    {
      "x": 0,
      "y": 9,
      "z": -5,
      "name": "Rock_Slate_Cobble"
    },
    {
      "x": 0,
      "y": 10,
      "z": -5,
      "name": "Rock_Shale_Brick"
    },
    {
      "x": 0,
      "y": 9,
      "z": -4,
      "name": "Rock_Slate_Cobble"
    },
    {
      "x": 0,
      "y": 10,
      "z": -4,
      "name": "Rock_Shale_Brick"
    },
    {
      "x": 0,
      "y": 5,
      "z": -3,
      "name": "Rock_Slate"
    },
    {
      "x": 0,
      "y": 6,
      "z": -3,
      "name": "Rock_Slate_Cobble"
    },
    {
      "x": 0,
      "y": 9,
      "z": -3,
      "name": "Rock_Slate_Cobble"
    },
    {
      "x": 0,
      "y": 10,
      "z": -3,
      "name": "Rock_Shale_Brick"
    },
    {
      "x": 0,
      "y": 5,
      "z": -2,
      "name": "Rock_Slate"
    },
    {
      "x": 0,
      "y": 6,
      "z": -2,
      "name": "Rock_Slate_Cobble"
    },
    {
      "x": 0,
      "y": 7,
      "z": -2,
      "name": "Rock_Slate_Cobble"
    },
    {
      "x": 0,
      "y": 9,
      "z": -2,
      "name": "Rock_Slate_Cobble"
    },
    {
      "x": 0,
      "y": 10,
      "z": -2,
      "name": "Rock_Shale_Brick"
    },
    {
      "x": 0,
      "y": 5,
      "z": -1,
      "name": "Rock_Slate"
    },
    {
      "x": 0,
      "y": 6,
      "z": -1,
      "name": "Rock_Slate_Cobble"
    },
    {
      "x": 0,
      "y": 7,
      "z": -1,
      "name": "Rock_Slate_Cobble"
    },
    {
      "x": 0,
      "y": 8,
      "z": -1,
      "name": "Rock_Slate_Cobble"
    },
    {
      "x": 0,
      "y": 9,
      "z": -1,
      "name": "Rock_Slate_Cobble"
    },
    {
      "x": 0,
      "y": 10,
      "z": -1,
      "name": "Rock_Shale_Brick"
    },
    {
      "x": 0,
      "y": 4,
      "z": 0,
      "name": "Rock_Slate"
    },
    {
      "x": 0,
      "y": 5,
      "z": 0,
      "name": "Rock_Slate"
    },
    {
      "x": 0,
      "y": 6,
      "z": 0,
      "name": "Rock_Slate_Cobble"
    },
    {
      "x": 0,
      "y": 7,
      "z": 0,
      "name": "Rock_Slate_Cobble"
    },
    {
      "x": 0,
      "y": 8,
      "z": 0,
      "name": "Rock_Slate_Cobble"
    },
    {
      "x": 0,
      "y": 9,
      "z": 0,
      "name": "Rock_Slate_Cobble"
    },
    {
      "x": 0,
      "y": 10,
      "z": 0,
      "name": "Rock_Shale_Brick"
    },
    {
      "x": 0,
      "y": 3,
      "z": 1,
      "name": "Rock_Slate"
    },
    {
      "x": 0,
      "y": 4,
      "z": 1,
      "name": "Rock_Slate"
    },
    {
      "x": 0,
      "y": 5,
      "z": 1,
      "name": "Rock_Slate"
    },
    {
      "x": 0,
      "y": 6,
      "z": 1,
      "name": "Rock_Slate_Cobble"
    },
    {
      "x": 0,
      "y": 7,
      "z": 1,
      "name": "Rock_Slate_Cobble"
    },
    {
      "x": 0,
      "y": 9,
      "z": 1,
      "name": "Rock_Slate_Cobble"
    },
    {
      "x": 0,
      "y": 10,
      "z": 1,
      "name": "Rock_Shale_Brick"
    },
    {
      "x": 0,
      "y": 0,
      "z": 2,
      "name": "Rock_Slate_Cobble"
    },
    {
      "x": 0,
      "y": 2,
      "z": 2,
      "name": "Rock_Slate"
    },
    {
      "x": 0,
      "y": 3,
      "z": 2,
      "name": "Rock_Slate"
    },
    {
      "x": 0,
      "y": 4,
      "z": 2,
      "name": "Rock_Slate"
    },
    {
      "x": 0,
      "y": 5,
      "z": 2,
      "name": "Rock_Slate"
    },
    {
      "x": 0,
      "y": 6,
      "z": 2,
      "name": "Rock_Slate_Cobble"
    },
    {
      "x": 0,
      "y": 9,
      "z": 2,
      "name": "Rock_Slate_Cobble"
    },
    {
      "x": 0,
      "y": 10,
      "z": 2,
      "name": "Rock_Shale_Brick"
    },
    {
      "x": 0,
      "y": 5,
      "z": 3,
      "name": "Rock_Slate"
    },
    {
      "x": 0,
      "y": 6,
      "z": 3,
      "name": "Rock_Slate_Cobble"
    },
    {
      "x": 0,
      "y": 7,
      "z": 3,
      "name": "Rock_Slate_Cobble"
    },
    {
      "x": 0,
      "y": 9,
      "z": 3,
      "name": "Rock_Slate_Cobble"
    },
    {
      "x": 0,
      "y": 10,
      "z": 3,
      "name": "Rock_Shale_Brick"
    },
    {
      "x": 0,
      "y": 4,
      "z": 4,
      "name": "Rock_Slate"
    },
    {
      "x": 0,
      "y": 5,
      "z": 4,
      "name": "Rock_Slate"
    },
    {
      "x": 0,
      "y": 6,
      "z": 4,
      "name": "Rock_Slate_Cobble"
    },
    {
      "x": 0,
      "y": 7,
      "z": 4,
      "name": "Rock_Slate_Cobble"
    },
    {
      "x": 0,
      "y": 8,
      "z": 4,
      "name": "Rock_Slate_Cobble"
    },
    {
      "x": 0,
      "y": 9,
      "z": 4,
      "name": "Rock_Slate_Cobble"
    },
    {
      "x": 0,
      "y": 10,
      "z": 4,
      "name": "Rock_Shale_Brick"
    },
    {
      "x": 0,
      "y": 4,
      "z": 5,
      "name": "Rock_Slate_Cobble"
    },
    {
      "x": 0,
      "y": 5,
      "z": 5,
      "name": "Rock_Slate_Cobble"
    },
    {
      "x": 0,
      "y": 6,
      "z": 5,
      "name": "Rock_Slate_Cobble"
    },
    {
      "x": 0,
      "y": 8,
      "z": 5,
      "name": "Rock_Slate_Cobble"
    },
    {
      "x": 0,
      "y": 9,
      "z": 5,
      "name": "Rock_Slate_Cobble"
    },
    {
      "x": 0,
      "y": 10,
      "z": 5,
      "name": "Rock_Shale_Brick"
    },
    {
      "x": 0,
      "y": 5,
      "z": 6,
      "name": "Rock_Slate_Cobble"
    },
    {
      "x": 0,
      "y": 6,
      "z": 6,
      "name": "Rock_Slate_Cobble"
    },
    {
      "x": 0,
      "y": 9,
      "z": 6,
      "name": "Rock_Slate_Cobble"
    },
    {
      "x": 0,
      "y": 10,
      "z": 6,
      "name": "Rock_Shale_Brick"
    },
    {
      "x": 0,
      "y": 3,
      "z": 7,
      "name": "Rock_Slate"
    },
    {
      "x": 0,
      "y": 4,
      "z": 7,
      "name": "Rock_Slate"
    },
    {
      "x": 0,
      "y": 5,
      "z": 7,
      "name": "Rock_Slate"
    },
    {
      "x": 0,
      "y": 6,
      "z": 7,
      "name": "Rock_Slate_Cobble"
    },
    {
      "x": 0,
      "y": 7,
      "z": 7,
      "name": "Rock_Slate_Cobble"
    },
    {
      "x": 0,
      "y": 9,
      "z": 7,
      "name": "Rock_Slate_Cobble"
    },
    {
      "x": 0,
      "y": 10,
      "z": 7,
      "name": "Rock_Shale_Brick"
    },
    {
      "x": 0,
      "y": 2,
      "z": 8,
      "name": "Rock_Slate"
    },
    {
      "x": 0,
      "y": 3,
      "z": 8,
      "name": "Rock_Slate"
    },
    {
      "x": 0,
      "y": 4,
      "z": 8,
      "name": "Rock_Slate"
    },
    {
      "x": 0,
      "y": 5,
      "z": 8,
      "name": "Rock_Slate"
    },
    {
      "x": 0,
      "y": 6,
      "z": 8,
      "name": "Rock_Shale_Brick"
    },
    {
      "x": 0,
      "y": 9,
      "z": 8,
      "name": "Rock_Shale_Brick"
    },
    {
      "x": 0,
      "y": 10,
      "z": 8,
      "name": "Rock_Shale_Brick"
    },
    {
      "x": 0,
      "y": 5,
      "z": 9,
      "name": "Rock_Slate"
    },
    {
      "x": 0,
      "y": 9,
      "z": 9,
      "name": "Rock_Shale_Brick"
    },
    {
      "x": 0,
      "y": 10,
      "z": 9,
      "name": "Rock_Shale_Brick"
    },
    {
      "x": 0,
      "y": 9,
      "z": 10,
      "name": "Rock_Shale_Cobble_Stairs",
      "rotation": 10
    },
    {
      "x": 0,
      "y": 10,
      "z": 10,
      "name": "Rock_Shale_Brick"
    },
    {
      "x": 0,
      "y": 10,
      "z": 11,
      "name": "Rock_Shale_Brick"
    },
    {
      "x": 1,
      "y": 5,
      "z": -11,
      "name": "Rock_Slate"
    },
    {
      "x": 1,
      "y": 5,
      "z": -10,
      "name": "Rock_Slate"
    },
    {
      "x": 1,
      "y": 4,
      "z": -9,
      "name": "Rock_Slate"
    },
    {
      "x": 1,
      "y": 5,
      "z": -9,
      "name": "Rock_Slate"
    },
    {
      "x": 1,
      "y": 6,
      "z": -9,
      "name": "Rock_Shale_Brick_Ornate"
    },
    {
      "x": 1,
      "y": 7,
      "z": -9,
      "name": "Rock_Shale_Brick_Pillar_Base"
    },
    {
      "x": 1,
      "y": 8,
      "z": -9,
      "name": "Rock_Shale_Brick_Pillar_Middle"
    },
    {
      "x": 1,
      "y": 9,
      "z": -9,
      "name": "Rock_Shale_Brick_Pillar_Middle",
      "rotation": 1
    },
    {
      "x": 1,
      "y": 10,
      "z": -9,
      "name": "Rock_Shale_Brick_Pillar_Base",
      "rotation": 9
    },
    {
      "x": 1,
      "y": 11,
      "z": -9,
      "name": "Rock_Shale_Brick_Roof_Steep",
      "rotation": 2
    },
    {
      "x": 1,
      "y": 12,
      "z": -9,
      "name": "Rock_Shale_Brick_Roof_Steep",
      "filler": 1024,
      "rotation": 2
    },
    {
      "x": 1,
      "y": 2,
      "z": -8,
      "name": "Rock_Slate"
    },
    {
      "x": 1,
      "y": 3,
      "z": -8,
      "name": "Rock_Slate"
    },
    {
      "x": 1,
      "y": 4,
      "z": -8,
      "name": "Rock_Slate"
    },
    {
      "x": 1,
      "y": 5,
      "z": -8,
      "name": "Rock_Slate"
    },
    {
      "x": 1,
      "y": 6,
      "z": -8,
      "name": "Rock_Shale_Brick",
      "rotation": 1
    },
    {
      "x": 1,
      "y": 7,
      "z": -8,
      "name": "Rock_Shale_Brick",
      "rotation": 1
    },
    {
      "x": 1,
      "y": 8,
      "z": -8,
      "name": "Rock_Shale_Brick",
      "rotation": 1
    },
    {
      "x": 1,
      "y": 9,
      "z": -8,
      "name": "Rock_Shale_Brick",
      "rotation": 1
    },
    {
      "x": 1,
      "y": 10,
      "z": -8,
      "name": "Rock_Shale_Brick_Ornate",
      "rotation": 1
    },
    {
      "x": 1,
      "y": 11,
      "z": -8,
      "name": "Rock_Shale_Brick_Ornate",
      "rotation": 1
    },
    {
      "x": 1,
      "y": 12,
      "z": -8,
      "name": "Rock_Shale_Brick_Ornate",
      "rotation": 1
    },
    {
      "x": 1,
      "y": 13,
      "z": -8,
      "name": "Rock_Shale_Brick",
      "rotation": 1
    },
    {
      "x": 1,
      "y": 5,
      "z": -7,
      "name": "Rock_Slate"
    },
    {
      "x": 1,
      "y": 6,
      "z": -7,
      "name": "Rock_Shale_Brick",
      "rotation": 2
    },
    {
      "x": 1,
      "y": 7,
      "z": -7,
      "name": "Rock_Shale_Brick_Roof",
      "rotation": 1
    },
    {
      "x": 1,
      "y": 9,
      "z": -7,
      "name": "Rock_Shale_Cobble_Stairs",
      "rotation": 10
    },
    {
      "x": 1,
      "y": 10,
      "z": -7,
      "name": "Rock_Shale_Brick",
      "rotation": 3
    },
    {
      "x": 1,
      "y": 11,
      "z": -7,
      "name": "Rock_Shale_Brick_Roof_Flat",
      "rotation": 3
    },
    {
      "x": 1,
      "y": 5,
      "z": -6,
      "name": "Rock_Slate"
    },
    {
      "x": 1,
      "y": 6,
      "z": -6,
      "name": "Rock_Shale_Brick_Wall",
      "rotation": 3
    },
    {
      "x": 1,
      "y": 10,
      "z": -6,
      "name": "Rock_Shale_Brick",
      "rotation": 3
    },
    {
      "x": 1,
      "y": 11,
      "z": -6,
      "name": "Rock_Shale_Brick_Roof_Flat",
      "rotation": 3
    },
    {
      "x": 1,
      "y": 4,
      "z": -5,
      "name": "Rock_Slate"
    },
    {
      "x": 1,
      "y": 5,
      "z": -5,
      "name": "Rock_Slate"
    },
    {
      "x": 1,
      "y": 6,
      "z": -5,
      "name": "Rock_Shale_Brick_Decorative",
      "rotation": 2
    },
    {
      "x": 1,
      "y": 7,
      "z": -5,
      "name": "Rock_Shale_Brick_Beam",
      "rotation": 2
    },
    {
      "x": 1,
      "y": 8,
      "z": -5,
      "name": "Rock_Shale_Brick_Beam",
      "rotation": 2
    },
    {
      "x": 1,
      "y": 9,
      "z": -5,
      "name": "Rock_Shale_Brick_Decorative",
      "rotation": 2
    },
    {
      "x": 1,
      "y": 10,
      "z": -5,
      "name": "Rock_Shale_Brick",
      "rotation": 3
    },
    {
      "x": 1,
      "y": 11,
      "z": -5,
      "name": "Rock_Shale_Brick_Roof_Flat",
      "rotation": 3
    },
    {
      "x": 1,
      "y": 3,
      "z": -4,
      "name": "Rock_Slate"
    },
    {
      "x": 1,
      "y": 4,
      "z": -4,
      "name": "Rock_Slate"
    },
    {
      "x": 1,
      "y": 5,
      "z": -4,
      "name": "Rock_Slate"
    },
    {
      "x": 1,
      "y": 10,
      "z": -4,
      "name": "Rock_Shale_Brick_Stairs",
      "rotation": 11
    },
    {
      "x": 1,
      "y": 11,
      "z": -4,
      "name": "Rock_Shale_Brick_Roof_Flat",
      "rotation": 3
    },
    {
      "x": 1,
      "y": 2,
      "z": -3,
      "name": "Rock_Slate"
    },
    {
      "x": 1,
      "y": 3,
      "z": -3,
      "name": "Rock_Slate"
    },
    {
      "x": 1,
      "y": 4,
      "z": -3,
      "name": "Rock_Slate"
    },
    {
      "x": 1,
      "y": 5,
      "z": -3,
      "name": "Rock_Slate"
    },
    {
      "x": 1,
      "y": 6,
      "z": -3,
      "name": "Rock_Shale_Brick_Decorative",
      "rotation": 2
    },
    {
      "x": 1,
      "y": 7,
      "z": -3,
      "name": "Rock_Shale_Brick_Beam",
      "rotation": 2
    },
    {
      "x": 1,
      "y": 8,
      "z": -3,
      "name": "Rock_Shale_Brick_Beam",
      "rotation": 2
    },
    {
      "x": 1,
      "y": 9,
      "z": -3,
      "name": "Rock_Shale_Brick_Decorative",
      "rotation": 2
    },
    {
      "x": 1,
      "y": 10,
      "z": -3,
      "name": "Rock_Shale_Brick",
      "rotation": 3
    },
    {
      "x": 1,
      "y": 11,
      "z": -3,
      "name": "Rock_Shale_Brick_Roof_Flat",
      "rotation": 3
    },
    {
      "x": 1,
      "y": 4,
      "z": -2,
      "name": "Rock_Slate"
    },
    {
      "x": 1,
      "y": 5,
      "z": -2,
      "name": "Rock_Slate"
    },
    {
      "x": 1,
      "y": 6,
      "z": -2,
      "name": "Rock_Shale_Brick_Wall",
      "rotation": 3
    },
    {
      "x": 1,
      "y": 10,
      "z": -2,
      "name": "Rock_Shale_Brick",
      "rotation": 3
    },
    {
      "x": 1,
      "y": 11,
      "z": -2,
      "name": "Rock_Shale_Brick_Roof_Flat",
      "rotation": 3
    },
    {
      "x": 1,
      "y": 4,
      "z": -1,
      "name": "Rock_Slate"
    },
    {
      "x": 1,
      "y": 5,
      "z": -1,
      "name": "Rock_Slate"
    },
    {
      "x": 1,
      "y": 6,
      "z": -1,
      "name": "Rock_Shale_Brick",
      "rotation": 2
    },
    {
      "x": 1,
      "y": 7,
      "z": -1,
      "name": "Rock_Shale_Brick_Roof",
      "rotation": 1
    },
    {
      "x": 1,
      "y": 9,
      "z": -1,
      "name": "Rock_Shale_Cobble_Stairs",
      "rotation": 8
    },
    {
      "x": 1,
      "y": 10,
      "z": -1,
      "name": "Rock_Shale_Brick",
      "rotation": 3
    },
    {
      "x": 1,
      "y": 11,
      "z": -1,
      "name": "Rock_Shale_Brick_Roof",
      "rotation": 2
    },
    {
      "x": 1,
      "y": 4,
      "z": 0,
      "name": "Rock_Slate"
    },
    {
      "x": 1,
      "y": 5,
      "z": 0,
      "name": "Rock_Slate"
    },
    {
      "x": 1,
      "y": 6,
      "z": 0,
      "name": "Rock_Shale_Brick",
      "rotation": 3
    },
    {
      "x": 1,
      "y": 7,
      "z": 0,
      "name": "Rock_Shale_Brick",
      "rotation": 3
    },
    {
      "x": 1,
      "y": 8,
      "z": 0,
      "name": "Rock_Shale_Brick",
      "rotation": 3
    },
    {
      "x": 1,
      "y": 9,
      "z": 0,
      "name": "Rock_Shale_Brick",
      "rotation": 3
    },
    {
      "x": 1,
      "y": 10,
      "z": 0,
      "name": "Rock_Shale_Brick",
      "rotation": 3
    },
    {
      "x": 1,
      "y": 11,
      "z": 0,
      "name": "Rock_Shale_Brick_Ornate",
      "rotation": 3
    },
    {
      "x": 1,
      "y": 12,
      "z": 0,
      "name": "Rock_Shale_Brick",
      "rotation": 1
    },
    {
      "x": 1,
      "y": 5,
      "z": 1,
      "name": "Rock_Slate"
    },
    {
      "x": 1,
      "y": 6,
      "z": 1,
      "name": "Rock_Shale_Brick",
      "rotation": 2
    },
    {
      "x": 1,
      "y": 7,
      "z": 1,
      "name": "Rock_Shale_Brick_Roof",
      "rotation": 1
    },
    {
      "x": 1,
      "y": 9,
      "z": 1,
      "name": "Rock_Shale_Cobble_Stairs",
      "rotation": 10
    },
    {
      "x": 1,
      "y": 10,
      "z": 1,
      "name": "Rock_Shale_Brick",
      "rotation": 3
    },
    {
      "x": 1,
      "y": 11,
      "z": 1,
      "name": "Rock_Shale_Brick_Roof"
    },
    {
      "x": 1,
      "y": 4,
      "z": 2,
      "name": "Rock_Slate"
    },
    {
      "x": 1,
      "y": 5,
      "z": 2,
      "name": "Rock_Slate"
    },
    {
      "x": 1,
      "y": 6,
      "z": 2,
      "name": "Rock_Shale_Brick_Wall",
      "rotation": 3
    },
    {
      "x": 1,
      "y": 10,
      "z": 2,
      "name": "Rock_Shale_Brick",
      "rotation": 3
    },
    {
      "x": 1,
      "y": 11,
      "z": 2,
      "name": "Rock_Shale_Brick_Roof_Flat",
      "rotation": 1
    },
    {
      "x": 1,
      "y": 4,
      "z": 3,
      "name": "Rock_Slate"
    },
    {
      "x": 1,
      "y": 5,
      "z": 3,
      "name": "Rock_Slate"
    },
    {
      "x": 1,
      "y": 6,
      "z": 3,
      "name": "Rock_Shale_Brick_Decorative",
      "rotation": 2
    },
    {
      "x": 1,
      "y": 7,
      "z": 3,
      "name": "Rock_Shale_Brick_Beam",
      "rotation": 2
    },
    {
      "x": 1,
      "y": 8,
      "z": 3,
      "name": "Rock_Shale_Brick_Beam",
      "rotation": 2
    },
    {
      "x": 1,
      "y": 9,
      "z": 3,
      "name": "Rock_Shale_Brick_Decorative",
      "rotation": 2
    },
    {
      "x": 1,
      "y": 10,
      "z": 3,
      "name": "Rock_Shale_Brick",
      "rotation": 3
    },
    {
      "x": 1,
      "y": 10,
      "z": 4,
      "name": "Rock_Shale_Brick_Stairs",
      "rotation": 11
    },
    {
      "x": 1,
      "y": 11,
      "z": 4,
      "name": "Rock_Shale_Brick_Roof_Flat",
      "rotation": 1
    },
    {
      "x": 1,
      "y": 5,
      "z": 5,
      "name": "Rock_Slate_Cobble"
    },
    {
      "x": 1,
      "y": 6,
      "z": 5,
      "name": "Rock_Shale_Brick_Decorative",
      "rotation": 2
    },
    {
      "x": 1,
      "y": 7,
      "z": 5,
      "name": "Rock_Shale_Brick_Beam",
      "rotation": 2
    },
    {
      "x": 1,
      "y": 8,
      "z": 5,
      "name": "Rock_Shale_Brick_Beam",
      "rotation": 2
    },
    {
      "x": 1,
      "y": 9,
      "z": 5,
      "name": "Rock_Shale_Brick_Decorative",
      "rotation": 2
    },
    {
      "x": 1,
      "y": 10,
      "z": 5,
      "name": "Rock_Shale_Brick",
      "rotation": 3
    },
    {
      "x": 1,
      "y": 11,
      "z": 5,
      "name": "Rock_Shale_Brick_Roof_Flat",
      "rotation": 1
    },
    {
      "x": 1,
      "y": 5,
      "z": 6,
      "name": "Rock_Slate"
    },
    {
      "x": 1,
      "y": 6,
      "z": 6,
      "name": "Rock_Shale_Brick_Wall",
      "rotation": 3
    },
    {
      "x": 1,
      "y": 10,
      "z": 6,
      "name": "Rock_Shale_Brick",
      "rotation": 3
    },
    {
      "x": 1,
      "y": 11,
      "z": 6,
      "name": "Rock_Shale_Brick_Roof_Flat",
      "rotation": 1
    },
    {
      "x": 1,
      "y": 4,
      "z": 7,
      "name": "Rock_Slate_Cobble"
    },
    {
      "x": 1,
      "y": 5,
      "z": 7,
      "name": "Rock_Slate"
    },
    {
      "x": 1,
      "y": 9,
      "z": 7,
      "name": "Rock_Shale_Cobble_Stairs",
      "rotation": 8
    },
    {
      "x": 1,
      "y": 10,
      "z": 7,
      "name": "Rock_Shale_Brick",
      "rotation": 3
    },
    {
      "x": 1,
      "y": 11,
      "z": 7,
      "name": "Rock_Shale_Brick_Roof_Flat",
      "rotation": 1
    },
    {
      "x": 1,
      "y": 4,
      "z": 8,
      "name": "Rock_Slate"
    },
    {
      "x": 1,
      "y": 5,
      "z": 8,
      "name": "Rock_Slate"
    },
    {
      "x": 1,
      "y": 8,
      "z": 8,
      "name": "Rock_Shale_Brick"
    },
    {
      "x": 1,
      "y": 9,
      "z": 8,
      "name": "Rock_Shale_Brick"
    },
    {
      "x": 1,
      "y": 10,
      "z": 8,
      "name": "Rock_Shale_Brick_Ornate"
    },
    {
      "x": 1,
      "y": 10,
      "z": 9,
      "name": "Rock_Shale_Brick"
    },
    {
      "x": 1,
      "y": 10,
      "z": 10,
      "name": "Rock_Shale_Brick"
    },
    {
      "x": 2,
      "y": 5,
      "z": -9,
      "name": "Rock_Slate"
    },
    {
      "x": 2,
      "y": 6,
      "z": -9,
      "name": "Rock_Shale_Brick_Decorative",
      "rotation": 1
    },
    {
      "x": 2,
      "y": 7,
      "z": -9,
      "name": "Rock_Shale_Brick_Beam",
      "rotation": 1
    },
    {
      "x": 2,
      "y": 8,
      "z": -9,
      "name": "Rock_Shale_Brick_Beam",
      "rotation": 1
    },
    {
      "x": 2,
      "y": 9,
      "z": -9,
      "name": "Rock_Shale_Brick_Beam",
      "rotation": 1
    },
    {
      "x": 2,
      "y": 10,
      "z": -9,
      "name": "Rock_Shale_Brick_Beam",
      "rotation": 1
    },
    {
      "x": 2,
      "y": 11,
      "z": -9,
      "name": "Rock_Shale_Brick_Half",
      "rotation": 1
    },
    {
      "x": 2,
      "y": 5,
      "z": -8,
      "name": "Rock_Slate"
    },
    {
      "x": 2,
      "y": 6,
      "z": -8,
      "name": "Rock_Shale_Brick",
      "rotation": 1
    },
    {
      "x": 2,
      "y": 7,
      "z": -8,
      "name": "Rock_Shale_Brick_Ornate",
      "rotation": 1
    },
    {
      "x": 2,
      "y": 8,
      "z": -8,
      "name": "Rock_Shale_Brick_Pillar_Base",
      "rotation": 1
    },
    {
      "x": 2,
      "y": 9,
      "z": -8,
      "name": "Rock_Shale_Brick_Pillar_Middle",
      "rotation": 1
    },
    {
      "x": 2,
      "y": 10,
      "z": -8,
      "name": "Rock_Shale_Brick_Pillar_Base",
      "rotation": 9
    },
    {
      "x": 2,
      "y": 11,
      "z": -8,
      "name": "Rock_Shale_Brick_Roof_Steep",
      "rotation": 1
    },
    {
      "x": 2,
      "y": 12,
      "z": -8,
      "name": "Rock_Shale_Brick_Roof_Steep",
      "filler": 1024,
      "rotation": 1
    },
    {
      "x": 2,
      "y": 5,
      "z": -3,
      "name": "Rock_Slate"
    },
    {
      "x": 2,
      "y": 5,
      "z": -2,
      "name": "Rock_Slate"
    },
    {
      "x": 2,
      "y": 5,
      "z": -1,
      "name": "Rock_Slate"
    },
    {
      "x": 2,
      "y": 5,
      "z": 0,
      "name": "Rock_Slate"
    },
    {
      "x": 2,
      "y": 6,
      "z": 0,
      "name": "Rock_Shale_Brick",
      "rotation": 3
    },
    {
      "x": 2,
      "y": 7,
      "z": 0,
      "name": "Rock_Shale_Brick_Ornate",
      "rotation": 3
    },
    {
      "x": 2,
      "y": 8,
      "z": 0,
      "name": "Rock_Shale_Brick_Pillar_Base",
      "rotation": 3
    },
    {
      "x": 2,
      "y": 9,
      "z": 0,
      "name": "Rock_Shale_Brick_Pillar_Middle",
      "rotation": 3
    },
    {
      "x": 2,
      "y": 10,
      "z": 0,
      "name": "Rock_Shale_Brick_Pillar_Base",
      "rotation": 11
    },
    {
      "x": 2,
      "y": 11,
      "z": 0,
      "name": "Rock_Shale_Brick_Roof_Steep",
      "rotation": 1
    },
    {
      "x": 2,
      "y": 12,
      "z": 0,
      "name": "Rock_Shale_Brick_Roof_Steep",
      "filler": 1024,
      "rotation": 1
    },
    {
      "x": 2,
      "y": 5,
      "z": 1,
      "name": "Rock_Slate"
    },
    {
      "x": 2,
      "y": 7,
      "z": 1,
      "name": "Rock_Slate"
    },
    {
      "x": 2,
      "y": 5,
      "z": 7,
      "name": "Rock_Slate"
    },
    {
      "x": 2,
      "y": 5,
      "z": 8,
      "name": "Rock_Slate"
    },
    {
      "x": 2,
      "y": 6,
      "z": 8,
      "name": "Rock_Shale_Brick",
      "rotation": 1
    },
    {
      "x": 2,
      "y": 7,
      "z": 8,
      "name": "Rock_Shale_Brick_Ornate"
    },
    {
      "x": 2,
      "y": 8,
      "z": 8,
      "name": "Rock_Shale_Brick_Pillar_Base"
    },
    {
      "x": 2,
      "y": 9,
      "z": 8,
      "name": "Rock_Shale_Brick_Pillar_Middle"
    },
    {
      "x": 2,
      "y": 5,
      "z": 9,
      "name": "Rock_Slate"
    },
    {
      "x": 3,
      "y": 5,
      "z": -1,
      "name": "Rock_Slate"
    },
    {
      "x": 3,
      "y": 5,
      "z": 0,
      "name": "Rock_Slate"
    },
    {
      "x": 3,
      "y": 5,
      "z": 8,
      "name": "Rock_Slate"
    },
    {
      "x": 3,
      "y": 5,
      "z": 10,
      "name": "Rock_Slate_Cobble"
    }
  ]
}